Workbook
Name маг: NA()

Sheet Ялта, Ленина, 18
B1: =TODAY()-1 -> 46060
B2: (отчетная дата)
C3: Осталось до выполнения плана!!! | I3: =График!B3 -> ул. Набережная Ленина, 18
C4: =I8-D56 -> 1352577.8 | E4: =IF(I8<>0, C4/I8, 0) -> 0.51905954
D5: =C4/(I14-J14) -> #DIV/0!
F6: Целевые показатели
F7: Показатель | I7: План | J7: Факт | K7: % выполнения | L7: Прогноз выполнения | M7: % выполнения по прогнозу | N7: Отклонение | O7: Факт аналогичного месяца прошлого года | P7: Отклонение LFL
F8: Выручка | I8: =I11*I12*I13 -> 2605824 | J8: =D56 -> 1253246.2 | K8: =IF(AND(I8<>"",I8<>0,J8<>""),J8/I8,"") -> 0.48094046 | L8: =IF(SUMIF($D$25:$D$55,">=0",$R$25:$R$55)<>0,I8*D56/SUMIF($D$25:$D$55,">=0",$R$25:$R$55),0) -> 1493405.3 | M8: =IF(AND(I8<>"", I8<>0, L8<>"", L8<>0), L8/I8, "") -> 0.57310289 | N8: =IF(AND(J8<>0, J8<>"", I8<>0, I8<>""), L8-I8, "") -> -1112418.7 | P8: =IF(AND(O8<>"", O8<>0, L8<>"", L8<>0), -O8+L8, "") | Q8: =IF(AND(P8<>"", P8<>0, O8<>0, O8<>""), P8/O8, "")
F9: Кол-во изделий | I9: =I8/I11 -> 334.08 | J9: =E56 -> 143 | K9: =IF(AND(I9<>"", I9<>0, J9<>""), J9/I9, "") -> 0.42804119 | L9: =IF(SUMIF($E$25:$E$55, ">=0", $S$25:$S$55)<>0, I9*E56/SUMIF($E$25:$E$55, ">=0", $S$25:$S$55), 0) -> 170.40303 | M9: =IF(AND(I9<>"", I9<>0, L9<>"", L9<>0), L9/I9, "") -> 0.51006655 | N9: =IF(AND(J9<>0, J9<>"", I9<>0, I9<>""), L9-I9, "") -> -163.67697 | O9: =O8/O11 -> #DIV/0! | P9: =IF(AND(O9<>"", O9<>0, L9<>"", L9<>0), -O9+L9, "") -> #DIV/0! | Q9: =IF(AND(P9<>"", P9<>0, O9<>0, O9<>""), P9/O9, "") -> #DIV/0!
F10: Средний чек | I10: =I11*I12 -> 13572 | J10: =H56 -> 15863.876 | K10: =IF(AND(I10<>"", I10<>0, J10<>""), J10/I10, "") -> 1.168868 | L10: =J10 -> 15863.876 | M10: =IF(AND(I10<>"", I10<>0, L10<>"", L10<>0), L10/I10, "") -> 1.168868 | N10: =IF(AND(J10<>0, J10<>"", I10<>0, I10<>""), L10-I10, "") -> 2291.8759 | O10: =O11*O12 -> 0 | P10: =IF(AND(O10<>"", O10<>0, L10<>"", L10<>0), -O10+L10, "") | Q10: =IF(AND(P10<>"", P10<>0, O10<>0, O10<>""), P10/O10, "") | U10: =L23 -> IS | X10: =M23 -> Agafi
F11: Средняя стоимость изделия | I11: 7800 | J11: =F56 -> 8763.9594 | K11: =IF(AND(I11<>"", I11<>0, J11<>""), J11/I11, "") -> 1.1235845 | L11: =IF(L9>0, L8/L9, "") -> 8763.9594 | M11: =IF(AND(I11<>"", I11<>0, L11<>"", L11<>0), L11/I11, "") -> 1.1235845 | N11: =IF(AND(J11<>0, J11<>"", I11<>0, I11<>""), L11-I11, "") -> 963.95944 | P11: =IF(AND(O11<>"", O11<>0, L11<>"", L11<>0), -O11+L11, "") | Q11: =IF(AND(P11<>"", P11<>0, O11<>0, O11<>""), P11/O11, "")
F12: Длина чека | I12: 1.74 | J12: =J56 -> 1.8101266 | K12: =IF(AND(I12<>"", I12<>0, J12<>""), J12/I12, "") -> 1.0403026 | L12: =J12 -> 1.8101266 | M12: =IF(AND(I12<>"", I12<>0, L12<>"", L12<>0), L12/I12, "") -> 1.0403026 | N12: =IF(AND(J12<>0, J12<>"", I12<>0, I12<>""), L12-I12, "") -> 0.070126582 | P12: =IF(AND(O12<>"", O12<>0, L12<>"", L12<>0), -O12+L12, "") | Q12: =IF(AND(P12<>"", P12<>0, O12<>0, O12<>""), P12/O12, "") | U12: 510000 | V12: =L56 -> 26123 | X12: 480000 | Y12: =M56 -> 50973
F13: Кол-во чеков | I13: =I17*I20 -> 192 | J13: =G56 -> 79 | K13: =IF(AND(I13<>"", I13<>0, J13<>""), J13/I13, "") -> 0.41145833 | L13: =IF(SUMIF($G$25:$G$55, ">=0", $T$25:$T$55)<>0, I13*G56/SUMIF($G$25:$G$55, ">=0", $T$25:$T$55), "") -> 94.138738 | M13: =IF(AND(I13<>"", I13<>0, L13<>"", L13<>0), L13/I13, "") -> 0.49030593 | N13: =IF(AND(J13<>0, J13<>"", I13<>0, I13<>""), L13-I13, "") -> -97.861262 | P13: =IF(AND(O13<>"", O13<>0, L13<>"", L13<>0), -O13+L13, "") | Q13: =IF(AND(P13<>"", P13<>0, O13<>0, O13<>""), P13/O13, "") | U13: =V12/U12 -> 0.051221569 | V13: =U13/J14*I14 -> 0.051221569 | X13: =Y12/X12 -> 0.10619375 | Y13: =X13/J14*I14 -> 0.10619375
F14: Кол-во смен | I14: 31 | J14: 31 | K14: =IF(AND(I14<>"", I14<>0, J14<>""), J14/I14, "") -> 1 | L14: =I14 -> 31 | M14: =IF(AND(I14<>"", I14<>0, L14<>"", L14<>0), L14/I14, "") -> 1 | N14: =IF(AND(J14<>0, J14<>"", I14<>0, I14<>""), L14-I14, "") -> 0 | P14: =IF(AND(O14<>"", O14<>0, L14<>"", L14<>0), -O14+L14, "") | Q14: =IF(AND(P14<>"", P14<>0, O14<>0, O14<>""), P14/O14, "")
F15: Средние продажи в смену | I15: =I8/I14 -> 84058.839 | J15: =J8/J14 -> 40427.297 | K15: =IF(AND(I15<>"", I15<>0, J15<>""), J15/I15, "") -> 0.48094046 | L15: =J15 -> 40427.297 | M15: =IF(AND(I15<>"", I15<>0, L15<>"", L15<>0), L15/I15, "") -> 0.48094046 | N15: =IF(AND(J15<>0, J15<>"", I15<>0, I15<>""), L15-I15, "") -> -43631.542 | P15: =IF(AND(O15<>"", O15<>0, L15<>"", L15<>0), -O15+L15, "") | Q15: =IF(AND(P15<>"", P15<>0, O15<>0, O15<>""), P15/O15, "")
F16: Отставание/Перевыполнение | J16: =J8-I15*J14 -> -1352577.8 | K16: =IF(AND(I16<>"", I16<>0, J16<>""), J16/I16, "") | L16: =J16 -> -1352577.8 | M16: =IF(AND(I16<>"", I16<>0, L16<>"", L16<>0), L16/I16, "") | N16: =IF(AND(J16<>0, J16<>"", I16<>0, I16<>""), L16-I16, "") | P16: =IF(AND(O16<>"", O16<>0, L16<>"", L16<>0), -O16+L16, "") | Q16: =IF(AND(P16<>"", P16<>0, O16<>0, O16<>""), P16/O16, "") | U16: =K23 -> UNOde50
F17: Трафик | I17: 1600 | J17: =I56 -> 912 | K17: =IF(AND(I17<>"", I17<>0, J17<>""), J17/I17, "") -> 0.57 | L17: =J17/J14*I14 -> 912 | M17: =IF(AND(I17<>"", I17<>0, L17<>"", L17<>0), L17/I17, "") -> 0.57 | N17: =IF(AND(J17<>0, J17<>"", I17<>0, I17<>""), L17-I17, "") -> -688 | P17: =IF(AND(O17<>"", O17<>0, L17<>"", L17<>0), -O17+L17, "") | Q17: =IF(AND(P17<>"", P17<>0, O17<>0, O17<>""), P17/O17, "")
K18: =IF(AND(I18<>"", I18<>0, J18<>""), J18/I18, "") | L18: =J18 -> 0 | M18: =IF(AND(I18<>"", I18<>0, L18<>"", L18<>0), L18/I18, "") | N18: =IF(AND(J18<>0, J18<>"", I18<>0, I18<>""), L18-I18, "") | O18: 0 | P18: =IF(AND(O18<>"", O18<>0, L18<>"", L18<>0), -O18+L18, "") | Q18: =IF(AND(P18<>"", P18<>0, O18<>0, O18<>""), P18/O18, "") | U18: 1020000 | V18: =K56 -> 326792
K19: =IF(AND(I19<>"", I19<>0, J19<>""), J19/I19, "") | L19: =J19 -> 0 | M19: =IF(AND(I19<>"", I19<>0, L19<>"", L19<>0), L19/I19, "") | N19: =IF(AND(J19<>0, J19<>"", I19<>0, I19<>""), L19-I19, "") | O19: 0 | P19: =IF(AND(O19<>"", O19<>0, L19<>"", L19<>0), -O19+L19, "") | Q19: =IF(AND(P19<>"", P19<>0, O19<>0, O19<>""), P19/O19, "") | U19: =V18/U18 -> 0.32038431 | V19: =U19/J14*I14 -> 0.32038431
F20: Конверсия план/факт | I20: 0.12 | J20: =P56 -> 0.086622807 | K20: =J20/I20 -> 0.72185673 | L20: =IF(AND(K8<>0, I14<>0, I56<>0), (I56*P56+(I56/K8-I56)*I20)/(I56/K8), 0) -> 0.10394756 | M20: =IF(AND(I20<>"", I20<>0, L20<>"", L20<>0), L20/I20, "") -> 0.86622964 | N20: =IF(AND(J20<>0, J20<>"", I20<>0, I20<>""), L20-I20, "") -> -0.016052443 | P20: =IF(AND(O20<>"", O20<>0, L20<>"", L20<>0), -O20+L20, "") | Q20: =IF(AND(P20<>"", P20<>0, O20<>0, O20<>""), P20/O20, "")
A22: Факт продаж за месяц | Q22: % выполнения дневного плана | R22: Раcпределение плана по дням
A23: Сотрудник | B23: Дата | C23: День недели | D23: Выручка (руб) | E23: Кол-во единиц (шт.) | F23: Средняя стоимость изделия (руб.) | G23: Количество чеков (шт.) | H23: Средняя сумма чека (руб.) | I23: Трафик | J23: Длина чека (шт.) | K23: UNOde50 | L23: IS | M23: Agafi | N23: Kalliope | O23: Raganella | P23: Конверсия (%) | R23: выручка, план | S23: кол-во ед, план | T23: Кол-во чеков, план | U23: выручка, скорректир.план | V23: кол-во ед, скорр. план | W23: кол-во чеков, скорр. план | X23: Коэфф. Дня Недели | Y23: Специфика месяца
B24: 1 | C24: 2 | D24: 3 | E24: 4 | F24: 5 | G24: 6 | H24: 7 | I24: 8 | J24: 9 | K24: 10 | L24: 11 | M24: 12 | N24: 13 | O24: 14 | P24: 15 | R24: 1 | S24: 2 | T24: 3 | U24: 4 | V24: 5 | W24: 6 | X24: 10 | Y24: 11
A25: Уразгильдеева | B25: 45992 | C25: пн | D25: 3293 | E25: 1 | F25: =IF(AND(E25<>"",E25<>0),D25/E25,"") -> 3293 | G25: 1 | H25: =IF(AND(G25<>"",G25<>0),D25/G25,"") -> 3293 | I25: 27 | J25: =IF(AND(G25<>"",G25<>0),E25/G25,"") -> 1 | P25: =IF(AND(I25<>"",I25<>0),G25/I25,"") -> 0.037037037 | Q25: =D25/R25 -> 0.040231815 | R25: =$I$8*X25*Y25/SUMPRODUCT($Y$25:$Y$55,$X$25:$X$55) -> 81850.645 | S25: =$I$9*X25*Y25/SUMPRODUCT($Y$25:$Y$55,$X$25:$X$55) -> 10.493672 | T25: =IF($I$12="","",S25/$I$12) -> 6.0308462 | U25: =IF(D25<>"",D25,R25) -> 3293 | V25: =IF(E25<>"",E25,S25) -> 1 | W25: =IF(G25<>"",G25,T25) -> 1 | X25: 0.9414554 | Y25: 0.9414554
A26: Уразгильдеева,Арапова | B26: 45993 | C26: вт | D26: 3555 | E26: 1 | F26: =IF(AND(E26<>"",E26<>0),D26/E26,"") -> 3555 | G26: 1 | H26: =IF(AND(G26<>"",G26<>0),D26/G26,"") -> 3555 | I26: 35 | J26: =IF(AND(G26<>"",G26<>0),E26/G26,"") -> 1 | P26: =IF(AND(I26<>"",I26<>0),G26/I26,"") -> 0.028571429 | Q26: =D26/R26 -> 0.052895014 | R26: =$I$8*X26*Y26/SUMPRODUCT($Y$25:$Y$55,$X$25:$X$55) -> 67208.603 | S26: =$I$9*X26*Y26/SUMPRODUCT($Y$25:$Y$55,$X$25:$X$55) -> 8.6164875 | T26: =IF($I$12="","",S26/$I$12) -> 4.9520043 | U26: =IF(Y26<>"",IF(D26<>"",D26,($I$8-SUM($U$25:U25))*X26*Y26/SUMPRODUCT($Y26:$Y$55,$X26:$X$55)),"") -> 3555 | V26: =IF(Y26<>"",IF(E26<>"",E26,($I$9-SUM($V$25:V25))*X26*Y26/SUMPRODUCT($Y26:$Y$55,$X26:$X$55)),"") -> 1 | W26: =IF(Y26<>"",IF(E26<>"",E26,($I$9-SUM($V$25:V25))*X26*Y26/SUMPRODUCT($Y26:$Y$55,$X26:$X$55)),"") -> 1 | X26: 0.85310234 | Y26: 0.85310234
A27: Уразгильдеева | B27: 45994 | C27: ср | D27: 47669 | E27: 3 | F27: =IF(AND(E27<>"",E27<>0),D27/E27,"") -> 15889.667 | G27: 2 | H27: =IF(AND(G27<>"",G27<>0),D27/G27,"") -> 23834.5 | I27: 30 | J27: =IF(AND(G27<>"",G27<>0),E27/G27,"") -> 1.5 | K27: 42669 | P27: =IF(AND(I27<>"",I27<>0),G27/I27,"") -> 0.066666667 | Q27: =D27/R27 -> 0.70926932 | R27: =$I$8*X27*Y27/SUMPRODUCT($Y$25:$Y$55,$X$25:$X$55) -> 67208.603 | S27: =$I$9*X27*Y27/SUMPRODUCT($Y$25:$Y$55,$X$25:$X$55) -> 8.6164875 | T27: =IF($I$12="","",S27/$I$12) -> 4.9520043 | U27: =IF(Y27<>"",IF(D27<>"",D27,($I$8-SUM($U$25:U26))*X27*Y27/SUMPRODUCT($Y27:$Y$55,$X27:$X$55)),"") -> 47669 | V27: =IF(Y27<>"",IF(E27<>"",E27,($I$9-SUM($V$25:V26))*X27*Y27/SUMPRODUCT($Y27:$Y$55,$X27:$X$55)),"") -> 3 | W27: =IF(Y27<>"",IF(E27<>"",E27,($I$9-SUM($V$25:V26))*X27*Y27/SUMPRODUCT($Y27:$Y$55,$X27:$X$55)),"") -> 3 | X27: 0.85310234 | Y27: 0.85310234
A28: Уразгильдеева | B28: 45995 | C28: чт | D28: 49966 | E28: 6 | F28: =IF(AND(E28<>"",E28<>0),D28/E28,"") -> 8327.6667 | G28: 3 | H28: =IF(AND(G28<>"",G28<>0),D28/G28,"") -> 16655.333 | I28: 45 | J28: =IF(AND(G28<>"",G28<>0),E28/G28,"") -> 2 | P28: =IF(AND(I28<>"",I28<>0),G28/I28,"") -> 0.066666667 | Q28: =D28/R28 -> 0.7434465 | R28: =$I$8*X28*Y28/SUMPRODUCT($Y$25:$Y$55,$X$25:$X$55) -> 67208.603 | S28: =$I$9*X28*Y28/SUMPRODUCT($Y$25:$Y$55,$X$25:$X$55) -> 8.6164875 | T28: =IF($I$12="","",S28/$I$12) -> 4.9520043 | U28: =IF(Y28<>"",IF(D28<>"",D28,($I$8-SUM($U$25:U27))*X28*Y28/SUMPRODUCT($Y28:$Y$55,$X28:$X$55)),"") -> 49966 | V28: =IF(Y28<>"",IF(E28<>"",E28,($I$9-SUM($V$25:V27))*X28*Y28/SUMPRODUCT($Y28:$Y$55,$X28:$X$55)),"") -> 6 | W28: =IF(Y28<>"",IF(E28<>"",E28,($I$9-SUM($V$25:V27))*X28*Y28/SUMPRODUCT($Y28:$Y$55,$X28:$X$55)),"") -> 6 | X28: 0.85310234 | Y28: 0.85310234
A29: Уразгильдеева,Арапова | B29: 45996 | C29: пт | D29: =40368+26123 -> 66491 | E29: 5 | F29: =IF(AND(E29<>"",E29<>0),D29/E29,"") -> 13298.2 | G29: 4 | H29: =IF(AND(G29<>"",G29<>0),D29/G29,"") -> 16622.75 | I29: 40 | J29: =IF(AND(G29<>"",G29<>0),E29/G29,"") -> 1.25 | K29: 28984 | L29: 26123 | P29: =IF(AND(I29<>"",I29<>0),G29/I29,"") -> 0.1 | Q29: =D29/R29 -> 0.99655761 | R29: =$I$8*X29*Y29/SUMPRODUCT($Y$25:$Y$55,$X$25:$X$55) -> 66720.678 | S29: =$I$9*X29*Y29/SUMPRODUCT($Y$25:$Y$55,$X$25:$X$55) -> 8.5539331 | T29: =IF($I$12="","",S29/$I$12) -> 4.9160535 | U29: =IF(Y29<>"",IF(D29<>"",D29,($I$8-SUM($U$25:U28))*X29*Y29/SUMPRODUCT($Y29:$Y$55,$X29:$X$55)),"") -> 66491 | V29: =IF(Y29<>"",IF(E29<>"",E29,($I$9-SUM($V$25:V28))*X29*Y29/SUMPRODUCT($Y29:$Y$55,$X29:$X$55)),"") -> 5 | W29: =IF(Y29<>"",IF(E29<>"",E29,($I$9-SUM($V$25:V28))*X29*Y29/SUMPRODUCT($Y29:$Y$55,$X29:$X$55)),"") -> 5 | X29: 0.85 | Y29: 0.85
A30: Уразгильдеева,Арапова | B30: 45997 | C30: сб | D30: 5893 | E30: 1 | F30: =IF(AND(E30<>"",E30<>0),D30/E30,"") -> 5893 | G30: 1 | H30: =IF(AND(G30<>"",G30<>0),D30/G30,"") -> 5893 | I30: 62 | J30: =IF(AND(G30<>"",G30<>0),E30/G30,"") -> 1 | P30: =IF(AND(I30<>"",I30<>0),G30/I30,"") -> 0.016129032 | Q30: =D30/R30 -> 0.063813687 | R30: =$I$8*X30*Y30/SUMPRODUCT($Y$25:$Y$55,$X$25:$X$55) -> 92346.96 | S30: =$I$9*X30*Y30/SUMPRODUCT($Y$25:$Y$55,$X$25:$X$55) -> 11.839354 | T30: =IF($I$12="","",S30/$I$12) -> 6.8042263 | U30: =IF(Y30<>"",IF(D30<>"",D30,($I$8-SUM($U$25:U29))*X30*Y30/SUMPRODUCT($Y30:$Y$55,$X30:$X$55)),"") -> 5893 | V30: =IF(Y30<>"",IF(E30<>"",E30,($I$9-SUM($V$25:V29))*X30*Y30/SUMPRODUCT($Y30:$Y$55,$X30:$X$55)),"") -> 1 | W30: =IF(Y30<>"",IF(E30<>"",E30,($I$9-SUM($V$25:V29))*X30*Y30/SUMPRODUCT($Y30:$Y$55,$X30:$X$55)),"") -> 1 | X30: 1 | Y30: 1
A31: Уразгильдеева,Арапова | B31: 45998 | C31: вс | D31: 18884 | E31: 2 | F31: =IF(AND(E31<>"",E31<>0),D31/E31,"") -> 9442 | G31: 1 | H31: =IF(AND(G31<>"",G31<>0),D31/G31,"") -> 18884 | I31: 31 | J31: =IF(AND(G31<>"",G31<>0),E31/G31,"") -> 2 | P31: =IF(AND(I31<>"",I31<>0),G31/I31,"") -> 0.032258065 | Q31: =D31/R31 -> 0.20448968 | R31: =$I$8*X31*Y31/SUMPRODUCT($Y$25:$Y$55,$X$25:$X$55) -> 92346.96 | S31: =$I$9*X31*Y31/SUMPRODUCT($Y$25:$Y$55,$X$25:$X$55) -> 11.839354 | T31: =IF($I$12="","",S31/$I$12) -> 6.8042263 | U31: =IF(Y31<>"",IF(D31<>"",D31,($I$8-SUM($U$25:U30))*X31*Y31/SUMPRODUCT($Y31:$Y$55,$X31:$X$55)),"") -> 18884 | V31: =IF(Y31<>"",IF(E31<>"",E31,($I$9-SUM($V$25:V30))*X31*Y31/SUMPRODUCT($Y31:$Y$55,$X31:$X$55)),"") -> 2 | W31: =IF(Y31<>"",IF(E31<>"",E31,($I$9-SUM($V$25:V30))*X31*Y31/SUMPRODUCT($Y31:$Y$55,$X31:$X$55)),"") -> 2 | X31: 1 | Y31: 1
A32: Уразгильдеева | B32: 45999 | C32: пн | D32: 12484 | E32: 2 | F32: =IF(AND(E32<>"",E32<>0),D32/E32,"") -> 6242 | G32: 1 | H32: =IF(AND(G32<>"",G32<>0),D32/G32,"") -> 12484 | I32: 39 | J32: =IF(AND(G32<>"",G32<>0),E32/G32,"") -> 2 | K32: 8490 | P32: =IF(AND(I32<>"",I32<>0),G32/I32,"") -> 0.025641026 | Q32: =D32/R32 -> 0.18575003 | R32: =$I$8*X32*Y32/SUMPRODUCT($Y$25:$Y$55,$X$25:$X$55) -> 67208.603 | S32: =$I$9*X32*Y32/SUMPRODUCT($Y$25:$Y$55,$X$25:$X$55) -> 8.6164875 | T32: =IF($I$12="","",S32/$I$12) -> 4.9520043 | U32: =IF(Y32<>"",IF(D32<>"",D32,($I$8-SUM($U$25:U31))*X32*Y32/SUMPRODUCT($Y32:$Y$55,$X32:$X$55)),"") -> 12484 | V32: =IF(Y32<>"",IF(E32<>"",E32,($I$9-SUM($V$25:V31))*X32*Y32/SUMPRODUCT($Y32:$Y$55,$X32:$X$55)),"") -> 2 | W32: =IF(Y32<>"",IF(E32<>"",E32,($I$9-SUM($V$25:V31))*X32*Y32/SUMPRODUCT($Y32:$Y$55,$X32:$X$55)),"") -> 2 | X32: 0.85310234 | Y32: 0.85310234
A33: Рогалевич,Арапова | B33: 46000 | C33: вт | F33: =IF(AND(E33<>"",E33<>0),D33/E33,"") | H33: =IF(AND(G33<>"",G33<>0),D33/G33,"") | I33: 13 | J33: =IF(AND(G33<>"",G33<>0),E33/G33,"") | P33: =IF(AND(I33<>"",I33<>0),G33/I33,"") -> 0 | Q33: =D33/R33 -> 0 | R33: =$I$8*X33*Y33/SUMPRODUCT($Y$25:$Y$55,$X$25:$X$55) -> 67208.603 | S33: =$I$9*X33*Y33/SUMPRODUCT($Y$25:$Y$55,$X$25:$X$55) -> 8.6164875 | T33: =IF($I$12="","",S33/$I$12) -> 4.9520043 | U33: =IF(Y33<>"",IF(D33<>"",D33,($I$8-SUM($U$25:U32))*X33*Y33/SUMPRODUCT($Y33:$Y$55,$X33:$X$55)),"") -> 80419.548 | V33: =IF(Y33<>"",IF(E33<>"",E33,($I$9-SUM($V$25:V32))*X33*Y33/SUMPRODUCT($Y33:$Y$55,$X33:$X$55)),"") -> 10.501279 | W33: =IF(Y33<>"",IF(E33<>"",E33,($I$9-SUM($V$25:V32))*X33*Y33/SUMPRODUCT($Y33:$Y$55,$X33:$X$55)),"") -> 10.501279 | X33: 0.85310234 | Y33: 0.85310234
A34: Рогалевич,Арапова | B34: 46001 | C34: ср | D34: 89424 | E34: 9 | F34: =IF(AND(E34<>"",E34<>0),D34/E34,"") -> 9936 | G34: 2 | H34: =IF(AND(G34<>"",G34<>0),D34/G34,"") -> 44712 | I34: 22 | J34: =IF(AND(G34<>"",G34<>0),E34/G34,"") -> 4.5 | K34: 52470 | P34: =IF(AND(I34<>"",I34<>0),G34/I34,"") -> 0.090909091 | Q34: =D34/R34 -> 2.4829438 | R34: =$I$8*X34*Y34/SUMPRODUCT($Y$25:$Y$55,$X$25:$X$55) -> 36015.314 | S34: =$I$9*X34*Y34/SUMPRODUCT($Y$25:$Y$55,$X$25:$X$55) -> 4.617348 | T34: =IF($I$12="","",S34/$I$12) -> 2.6536483 | U34: =IF(Y34<>"",IF(D34<>"",D34,($I$8-SUM($U$25:U33))*X34*Y34/SUMPRODUCT($Y34:$Y$55,$X34:$X$55)),"") -> 89424 | V34: =IF(Y34<>"",IF(E34<>"",E34,($I$9-SUM($V$25:V33))*X34*Y34/SUMPRODUCT($Y34:$Y$55,$X34:$X$55)),"") -> 9 | W34: =IF(Y34<>"",IF(E34<>"",E34,($I$9-SUM($V$25:V33))*X34*Y34/SUMPRODUCT($Y34:$Y$55,$X34:$X$55)),"") -> 9 | X34: 0.65 | Y34: 0.6
A35: Рогалевич,Уразгильдеева | B35: 46002 | C35: чт | D35: 7984 | E35: 2 | F35: =IF(AND(E35<>"",E35<>0),D35/E35,"") -> 3992 | G35: 1 | H35: =IF(AND(G35<>"",G35<>0),D35/G35,"") -> 7984 | I35: 30 | J35: =IF(AND(G35<>"",G35<>0),E35/G35,"") -> 2 | P35: =IF(AND(I35<>"",I35<>0),G35/I35,"") -> 0.033333333 | Q35: =D35/R35 -> 0.16467915 | R35: =$I$8*X35*Y35/SUMPRODUCT($Y$25:$Y$55,$X$25:$X$55) -> 48482.154 | S35: =$I$9*X35*Y35/SUMPRODUCT($Y$25:$Y$55,$X$25:$X$55) -> 6.2156607 | T35: =IF($I$12="","",S35/$I$12) -> 3.5722188 | U35: =IF(Y35<>"",IF(D35<>"",D35,($I$8-SUM($U$25:U34))*X35*Y35/SUMPRODUCT($Y35:$Y$55,$X35:$X$55)),"") -> 7984 | V35: =IF(Y35<>"",IF(E35<>"",E35,($I$9-SUM($V$25:V34))*X35*Y35/SUMPRODUCT($Y35:$Y$55,$X35:$X$55)),"") -> 2 | W35: =IF(Y35<>"",IF(E35<>"",E35,($I$9-SUM($V$25:V34))*X35*Y35/SUMPRODUCT($Y35:$Y$55,$X35:$X$55)),"") -> 2 | X35: 0.75 | Y35: 0.7
A36: Рогалевич,Уразгильдеева | B36: 46003 | C36: пт | D36: 58874 | E36: 7 | F36: =IF(AND(E36<>"",E36<>0),D36/E36,"") -> 8410.5714 | G36: 5 | H36: =IF(AND(G36<>"",G36<>0),D36/G36,"") -> 11774.8 | I36: 39 | J36: =IF(AND(G36<>"",G36<>0),E36/G36,"") -> 1.4 | N36: 22384 | O36: 23381 | P36: =IF(AND(I36<>"",I36<>0),G36/I36,"") -> 0.12820513 | Q36: =D36/R36 -> 0.8823951 | R36: =$I$8*X36*Y36/SUMPRODUCT($Y$25:$Y$55,$X$25:$X$55) -> 66720.678 | S36: =$I$9*X36*Y36/SUMPRODUCT($Y$25:$Y$55,$X$25:$X$55) -> 8.5539331 | T36: =IF($I$12="","",S36/$I$12) -> 4.9160535 | U36: =IF(Y36<>"",IF(D36<>"",D36,($I$8-SUM($U$25:U35))*X36*Y36/SUMPRODUCT($Y36:$Y$55,$X36:$X$55)),"") -> 58874 | V36: =IF(Y36<>"",IF(E36<>"",E36,($I$9-SUM($V$25:V35))*X36*Y36/SUMPRODUCT($Y36:$Y$55,$X36:$X$55)),"") -> 7 | W36: =IF(Y36<>"",IF(E36<>"",E36,($I$9-SUM($V$25:V35))*X36*Y36/SUMPRODUCT($Y36:$Y$55,$X36:$X$55)),"") -> 7 | X36: 0.85 | Y36: 0.85
A37: Рогалевич,Арапова | B37: 46004 | C37: сб | D37: 12384 | E37: 2 | F37: =IF(AND(E37<>"",E37<>0),D37/E37,"") -> 6192 | G37: 1 | H37: =IF(AND(G37<>"",G37<>0),D37/G37,"") -> 12384 | I37: 40 | J37: =IF(AND(G37<>"",G37<>0),E37/G37,"") -> 2 | P37: =IF(AND(I37<>"",I37<>0),G37/I37,"") -> 0.025 | Q37: =D37/R37 -> 0.14859053 | R37: =$I$8*X37*Y37/SUMPRODUCT($Y$25:$Y$55,$X$25:$X$55) -> 83343.131 | S37: =$I$9*X37*Y37/SUMPRODUCT($Y$25:$Y$55,$X$25:$X$55) -> 10.685017 | T37: =IF($I$12="","",S37/$I$12) -> 6.1408143 | U37: =IF(Y37<>"",IF(D37<>"",D37,($I$8-SUM($U$25:U36))*X37*Y37/SUMPRODUCT($Y37:$Y$55,$X37:$X$55)),"") -> 12384 | V37: =IF(Y37<>"",IF(E37<>"",E37,($I$9-SUM($V$25:V36))*X37*Y37/SUMPRODUCT($Y37:$Y$55,$X37:$X$55)),"") -> 2 | W37: =IF(Y37<>"",IF(E37<>"",E37,($I$9-SUM($V$25:V36))*X37*Y37/SUMPRODUCT($Y37:$Y$55,$X37:$X$55)),"") -> 2 | X37: 0.95 | Y37: 0.95
A38: Рогалевич,Арапова | B38: 46005 | C38: вс | D38: 58143 | E38: 7 | F38: =IF(AND(E38<>"",E38<>0),D38/E38,"") -> 8306.1429 | G38: 3 | H38: =IF(AND(G38<>"",G38<>0),D38/G38,"") -> 19381 | I38: 49 | J38: =IF(AND(G38<>"",G38<>0),E38/G38,"") -> 2.3333333 | O38: 34170 | P38: =IF(AND(I38<>"",I38<>0),G38/I38,"") -> 0.06122449 | Q38: =D38/R38 -> 0.69763398 | R38: =$I$8*X38*Y38/SUMPRODUCT($Y$25:$Y$55,$X$25:$X$55) -> 83343.131 | S38: =$I$9*X38*Y38/SUMPRODUCT($Y$25:$Y$55,$X$25:$X$55) -> 10.685017 | T38: =IF($I$12="","",S38/$I$12) -> 6.1408143 | U38: =IF(Y38<>"",IF(D38<>"",D38,($I$8-SUM($U$25:U37))*X38*Y38/SUMPRODUCT($Y38:$Y$55,$X38:$X$55)),"") -> 58143 | V38: =IF(Y38<>"",IF(E38<>"",E38,($I$9-SUM($V$25:V37))*X38*Y38/SUMPRODUCT($Y38:$Y$55,$X38:$X$55)),"") -> 7 | W38: =IF(Y38<>"",IF(E38<>"",E38,($I$9-SUM($V$25:V37))*X38*Y38/SUMPRODUCT($Y38:$Y$55,$X38:$X$55)),"") -> 7 | X38: 0.95 | Y38: 0.95
A39: Уразгильдеева,Арапова | B39: 46006 | C39: пн | D39: 16868 | E39: 3 | F39: =IF(AND(E39<>"",E39<>0),D39/E39,"") -> 5622.6667 | G39: 3 | H39: =IF(AND(G39<>"",G39<>0),D39/G39,"") -> 5622.6667 | I39: 35 | J39: =IF(AND(G39<>"",G39<>0),E39/G39,"") -> 1 | P39: =IF(AND(I39<>"",I39<>0),G39/I39,"") -> 0.085714286 | Q39: =D39/R39 -> 0.43232891 | R39: =$I$8*X39*Y39/SUMPRODUCT($Y$25:$Y$55,$X$25:$X$55) -> 39016.59 | S39: =$I$9*X39*Y39/SUMPRODUCT($Y$25:$Y$55,$X$25:$X$55) -> 5.002127 | T39: =IF($I$12="","",S39/$I$12) -> 2.8747856 | U39: =IF(Y39<>"",IF(D39<>"",D39,($I$8-SUM($U$25:U38))*X39*Y39/SUMPRODUCT($Y39:$Y$55,$X39:$X$55)),"") -> 16868 | V39: =IF(Y39<>"",IF(E39<>"",E39,($I$9-SUM($V$25:V38))*X39*Y39/SUMPRODUCT($Y39:$Y$55,$X39:$X$55)),"") -> 3 | W39: =IF(Y39<>"",IF(E39<>"",E39,($I$9-SUM($V$25:V38))*X39*Y39/SUMPRODUCT($Y39:$Y$55,$X39:$X$55)),"") -> 3 | X39: 0.65 | Y39: 0.65
A40: Рогалевич,Уразгильдеева | B40: 46007 | C40: вт | D40: 4493 | E40: 1 | F40: =IF(AND(E40<>"",E40<>0),D40/E40,"") -> 4493 | G40: 1 | H40: =IF(AND(G40<>"",G40<>0),D40/G40,"") -> 4493 | I40: 30 | J40: =IF(AND(G40<>"",G40<>0),E40/G40,"") -> 1 | P40: =IF(AND(I40<>"",I40<>0),G40/I40,"") -> 0.033333333 | Q40: =D40/R40 -> 0.086495057 | R40: =$I$8*X40*Y40/SUMPRODUCT($Y$25:$Y$55,$X$25:$X$55) -> 51945.165 | S40: =$I$9*X40*Y40/SUMPRODUCT($Y$25:$Y$55,$X$25:$X$55) -> 6.6596365 | T40: =IF($I$12="","",S40/$I$12) -> 3.8273773 | U40: =IF(Y40<>"",IF(D40<>"",D40,($I$8-SUM($U$25:U39))*X40*Y40/SUMPRODUCT($Y40:$Y$55,$X40:$X$55)),"") -> 4493 | V40: =IF(Y40<>"",IF(E40<>"",E40,($I$9-SUM($V$25:V39))*X40*Y40/SUMPRODUCT($Y40:$Y$55,$X40:$X$55)),"") -> 1 | W40: =IF(Y40<>"",IF(E40<>"",E40,($I$9-SUM($V$25:V39))*X40*Y40/SUMPRODUCT($Y40:$Y$55,$X40:$X$55)),"") -> 1 | X40: 0.75 | Y40: 0.75
A41: Рогалевич | B41: 46008 | C41: ср | D41: 42550 | E41: 6 | F41: =IF(AND(E41<>"",E41<>0),D41/E41,"") -> 7091.6667 | G41: 2 | H41: =IF(AND(G41<>"",G41<>0),D41/G41,"") -> 21275 | I41: 33 | J41: =IF(AND(G41<>"",G41<>0),E41/G41,"") -> 3 | O41: 14193 | P41: =IF(AND(I41<>"",I41<>0),G41/I41,"") -> 0.060606061 | Q41: =D41/R41 -> 0.63773332 | R41: =$I$8*X41*Y41/SUMPRODUCT($Y$25:$Y$55,$X$25:$X$55) -> 66720.678 | S41: =$I$9*X41*Y41/SUMPRODUCT($Y$25:$Y$55,$X$25:$X$55) -> 8.5539331 | T41: =IF($I$12="","",S41/$I$12) -> 4.9160535 | U41: =IF(Y41<>"",IF(D41<>"",D41,($I$8-SUM($U$25:U40))*X41*Y41/SUMPRODUCT($Y41:$Y$55,$X41:$X$55)),"") -> 42550 | V41: =IF(Y41<>"",IF(E41<>"",E41,($I$9-SUM($V$25:V40))*X41*Y41/SUMPRODUCT($Y41:$Y$55,$X41:$X$55)),"") -> 6 | W41: =IF(Y41<>"",IF(E41<>"",E41,($I$9-SUM($V$25:V40))*X41*Y41/SUMPRODUCT($Y41:$Y$55,$X41:$X$55)),"") -> 6 | X41: 0.85 | Y41: 0.85
...

Sheet Конкурс
A2: Личный ежедневный КВП, %
A4: Сотруник | B4: 45282 | C4: 45283 | D4: 45284 | E4: 45285 | F4: 45286 | G4: 45287 | H4: 45288 | I4: 45289 | J4: 45290 | K4: 45291 | L4: Итого:
A5: Рогалевич Ирина | E5: 0.57 | F5: 0.73 | G5: 0.88 | H5: 0.98 | I5: 0.69 | J5: 1.82 | K5: 2.89
A6: Арапова Анна | C6: 0 | D6: 0 | E6: 0 | F6: 0 | G6: 0.83 | H6: 0 | I6: 0.28 | J6: 0.46 | K6: 0.89
A7: Уразгильдеева Екатерина | B7: 0.39 | C7: 0 | E7: 0 | F7: 0.49 | G7: 1.19 | H7: 0.69 | J7: 1.63 | K7: 0.81
A9: Личный КВП, баллы
A11: Сотруник | B11: 45282 | C11: 45283 | D11: 45284 | E11: 45285 | F11: 45286 | G11: 45287 | H11: 45288 | I11: 45289 | J11: 45290 | K11: 45291 | L11: Итого:
A12: Рогалевич Ирина | E12: 1 | F12: 1 | G12: 1 | H12: 1 | I12: 1 | J12: 2 | K12: 3 | L12: =SUM(B12:K12) -> 10
A13: Арапова Анна | L13: =SUM(B13:K13) -> 0
A14: Уразгильдеева Екатерина | B14: 1 | F14: 1 | G14: 2 | H14: 1 | J14: 1 | L14: =SUM(B14:K14) -> 6

Sheet Св. по пок.
A1: 1-20.08
A2: Показатель | D2: ='Ялта, Ленина, 18'!I3 -> ул. Набережная Ленина, 18 | G2: =График!B29 -> Рогалевич Ирина | J2: =График!B28 -> Уразгильдеева Екатерина | M2: =График!B27 -> Арапова Анна-Мария
D3: Факт | F3: Прогноз | G3: Факт | I3: Прогноз | J3: Факт | L3: Прогноз | M3: Факт | O3: Прогноз
A4: Выручка | D4: ='Ялта, Ленина, 18'!K8 -> 0.48094046 | E4: ='Ялта, Ленина, 18'!J8 -> 1253246.2 | F4: ='Ялта, Ленина, 18'!M8 -> 0.57310289 | G4: ='Рогалевич И. Е. '!K8 -> 0.74053666 | H4: ='Рогалевич И. Е. '!J8 -> 352381.5 | I4: ='Рогалевич И. Е. '!M8 -> 1.2188958 | J4: ='Уразгильдеева Е. Р. '!K8 -> 0.55855872 | K4: ='Уразгильдеева Е. Р. '!J8 -> 620172 | L4: ='Уразгильдеева Е. Р. '!M8 -> 0.64369128 | M4: ='[1]Яковенко А. К'!K8 -> #REF! | N4: ='[1]Яковенко А. К'!J8 -> #REF! | O4: ='[1]Яковенко А. К'!M8 -> #REF!
A5: Кол-во изделий | D5: ='Ялта, Ленина, 18'!K9 -> 0.42804119 | E5: ='Ялта, Ленина, 18'!J9 -> 143 | F5: ='Ялта, Ленина, 18'!M9 -> 0.51006655 | G5: ='Рогалевич И. Е. '!K9 -> 0.63928229 | H5: ='Рогалевич И. Е. '!J9 -> 39 | I5: ='Рогалевич И. Е. '!M9 -> 1.1408068 | J5: ='Уразгильдеева Е. Р. '!K9 -> 0.49175561 | K5: ='Уразгильдеева Е. Р. '!J9 -> 70 | L5: ='Уразгильдеева Е. Р. '!M9 -> 0.5667064 | M5: ='[1]Яковенко А. К'!K9 -> #REF! | N5: ='[1]Яковенко А. К'!J9 -> #REF! | O5: ='[1]Яковенко А. К'!M9 -> #REF!
A6: Средний чек | D6: ='Ялта, Ленина, 18'!K10 -> 1.168868 | E6: ='Ялта, Ленина, 18'!J10 -> 15863.876 | F6: ='Ялта, Ленина, 18'!M10 -> 1.168868 | G6: ='Рогалевич И. Е. '!K10 -> 1.3665189 | H6: ='Рогалевич И. Е. '!J10 -> 18546.395 | I6: ='Рогалевич И. Е. '!M10 -> 1.3665189 | J6: ='Уразгильдеева Е. Р. '!K10 -> 1.1145112 | K6: ='Уразгильдеева Е. Р. '!J10 -> 15126.146 | L6: ='Уразгильдеева Е. Р. '!M10 -> 1.1145112 | M6: ='[1]Яковенко А. К'!K10 -> #REF! | N6: ='[1]Яковенко А. К'!J10 -> #REF! | O6: ='[1]Яковенко А. К'!M10 -> #REF!
A7: Средняя стоимость изделия | D7: ='Ялта, Ленина, 18'!K11 -> 1.1235845 | E7: ='Ялта, Ленина, 18'!J11 -> 8763.9594 | F7: ='Ялта, Ленина, 18'!M11 -> 1.1235845 | G7: ='Рогалевич И. Е. '!K11 -> 1.1583876 | H7: ='Рогалевич И. Е. '!J11 -> 9035.4231 | I7: ='Рогалевич И. Е. '!M11 -> 1.0684507 | J7: ='Уразгильдеева Е. Р. '!K11 -> 1.1358462 | K7: ='Уразгильдеева Е. Р. '!J11 -> 8859.6 | L7: ='Уразгильдеева Е. Р. '!M11 -> 1.1358462 | M7: ='[1]Яковенко А. К'!K11 -> #REF! | N7: ='[1]Яковенко А. К'!J11 -> #REF! | O7: ='[1]Яковенко А. К'!M11 -> #REF!
A8: Длина чека | D8: ='Ялта, Ленина, 18'!K12 -> 1.0403026 | E8: ='Ялта, Ленина, 18'!J12 -> 1.8101266 | F8: ='Ялта, Ленина, 18'!M12 -> 1.0403026 | G8: ='Рогалевич И. Е. '!K12 -> 1.1796733 | H8: ='Рогалевич И. Е. '!J12 -> 2.0526316 | I8: ='Рогалевич И. Е. '!M12 -> 1.1796733 | J8: ='Уразгильдеева Е. Р. '!K12 -> 0.98121671 | K8: ='Уразгильдеева Е. Р. '!J12 -> 1.7073171 | L8: ='Уразгильдеева Е. Р. '!M12 -> 0.98121671 | M8: ='[1]Яковенко А. К'!K12 -> #REF! | N8: ='[1]Яковенко А. К'!J12 -> #REF! | O8: ='[1]Яковенко А. К'!M12 -> #REF!
A9: Кол-во чеков | D9: ='Ялта, Ленина, 18'!K13 -> 0.41145833 | E9: ='Ялта, Ленина, 18'!J13 -> 79 | F9: ='Ялта, Ленина, 18'!M13 -> 0.49030593 | G9: ='Рогалевич И. Е. '!K13 -> 0.54191468 | H9: ='Рогалевич И. Е. '!J13 -> 19 | I9: ='Рогалевич И. Е. '!M13 -> 0.96705314 | J9: ='Уразгильдеева Е. Р. '!K13 -> 0.50116922 | K9: ='Уразгильдеева Е. Р. '!J13 -> 41 | L9: ='Уразгильдеева Е. Р. '!M13 -> 0.57755478 | M9: ='[1]Яковенко А. К'!K13 -> #REF! | N9: ='[1]Яковенко А. К'!J13 -> #REF! | O9: ='[1]Яковенко А. К'!M13 -> #REF!
A10: Кол-во смен план/отработано | D10: ='Ялта, Ленина, 18'!K14 -> 1 | E10: ='Ялта, Ленина, 18'!J14 -> 31 | G10: ='Рогалевич И. Е. '!K14 -> 1 | H10: ='Рогалевич И. Е. '!J14 -> 12 | J10: ='Уразгильдеева Е. Р. '!K14 -> 1 | K10: ='Уразгильдеева Е. Р. '!J14 -> 23 | M10: ='[1]Яковенко А. К'!K14 -> #REF! | N10: ='[1]Яковенко А. К'!J14 -> #REF!
A11: Средние продажи в смену | D11: ='Ялта, Ленина, 18'!K15 -> 0.48094046 | E11: ='Ялта, Ленина, 18'!J15 -> 40427.297 | F11: ='Ялта, Ленина, 18'!M15 -> 0.48094046 | G11: ='Рогалевич И. Е. '!K15 -> 0.34934012 | H11: ='Рогалевич И. Е. '!J15 -> 29365.125 | I11: ='Рогалевич И. Е. '!M15 -> 0.34934012 | J11: ='Уразгильдеева Е. Р. '!K15 -> 0.32077531 | K11: ='Уразгильдеева Е. Р. '!J15 -> 26964 | L11: ='Уразгильдеева Е. Р. '!M15 -> 0.32077531 | M11: ='[1]Яковенко А. К'!K15 -> #REF! | N11: ='[1]Яковенко А. К'!J15 -> #REF! | O11: ='[1]Яковенко А. К'!M15 -> #REF!
A12: Трафик | D12: ='Ялта, Ленина, 18'!K17 -> 0.57 | E12: ='Ялта, Ленина, 18'!J17 -> 912 | F12: ='Ялта, Ленина, 18'!M17 -> 0.57 | G12: ='Рогалевич И. Е. '!K17 -> 0.54077381 | H12: ='Рогалевич И. Е. '!J17 -> 158 | I12: ='Рогалевич И. Е. '!M17 -> 0.54077381 | J12: ='Уразгильдеева Е. Р. '!K17 -> 0.4752551 | K12: ='Уразгильдеева Е. Р. '!J17 -> 324 | L12: ='Уразгильдеева Е. Р. '!M17 -> 0.4752551 | M12: ='[1]Яковенко А. К'!K17 -> #REF! | N12: ='[1]Яковенко А. К'!J17 -> #REF! | O12: ='[1]Яковенко А. К'!M17 -> #REF!
A13: UNOde50 | D13: ='Ялта, Ленина, 18'!U19 -> 0.32038431 | E13: ='Ялта, Ленина, 18'!V18 -> 326792 | F13: ='Ялта, Ленина, 18'!V19 -> 0.32038431 | G13: ='Рогалевич И. Е. '!S19 -> 0.41586835 | H13: ='Рогалевич И. Е. '!T18 -> 77460 | I13: ='Рогалевич И. Е. '!T19 -> 0.41586835 | J13: ='Уразгильдеева Е. Р. '!S19 -> 0.46331793 | K13: ='Уразгильдеева Е. Р. '!T18 -> 201362 | L13: ='Уразгильдеева Е. Р. '!T19 -> 0.46331793 | M13: ='[1]Яковенко А. К'!S19 -> #REF! | N13: ='[1]Яковенко А. К'!T18 -> #REF! | O13: ='[1]Яковенко А. К'!T19 -> #REF!
A14: IS | D14: ='Ялта, Ленина, 18'!U13 -> 0.051221569 | E14: ='Ялта, Ленина, 18'!V12 -> 26123 | F14: ='Ялта, Ленина, 18'!V13 -> 0.051221569 | G14: ='Рогалевич И. Е. '!S13 -> 0.27813679 | H14: ='Рогалевич И. Е. '!T12 -> 25903 | I14: ='Рогалевич И. Е. '!T13 -> 0.27813679 | J14: ='Уразгильдеева Е. Р. '!S13 -> 0.001012405 | K14: ='Уразгильдеева Е. Р. '!T12 -> 220 | L14: ='Уразгильдеева Е. Р. '!T13 -> 0.001012405 | M14: ='[1]Яковенко А. К'!S13 -> #REF! | N14: ='[1]Яковенко А. К'!T12 -> #REF! | O14: ='[1]Яковенко А. К'!T13 -> #REF!
A15: ='Ялта, Ленина, 18'!M23 -> Agafi | D15: ='Ялта, Ленина, 18'!X13 -> 0.10619375 | E15: ='Ялта, Ленина, 18'!Y12 -> 50973 | F15: ='Ялта, Ленина, 18'!Y13 -> 0.10619375 | G15: ='Рогалевич И. Е. '!V13 -> 0 | H15: ='Рогалевич И. Е. '!W12 -> 0 | I15: ='Рогалевич И. Е. '!W13 -> 0 | J15: ='Уразгильдеева Е. Р. '!V13 -> 0.18178997 | K15: ='Уразгильдеева Е. Р. '!W12 -> 37180 | L15: ='Уразгильдеева Е. Р. '!W13 -> 0.18178997 | M15: ='[1]Яковенко А. К'!V13 -> #REF! | N15: ='[1]Яковенко А. К'!W12 -> #REF! | O15: ='[1]Яковенко А. К'!W13 -> #REF!
A16: Отклонение от плана | D16: ='Ялта, Ленина, 18'!J16 -> -1352577.8 | G16: ='Рогалевич И. Е. '!N8 -> 104160.7 | J16: ='Уразгильдеева Е. Р. '!N8 -> -395612.28 | M16: ='[1]Яковенко А. К'!N8 -> #REF!

Sheet План на день
A1: Выручка | D1: 152000
A2: Кол-во изделий | D2: =D1/D4 -> 19.487179
A3: Средний чек | D3: =D4*D5 -> 13572
A4: Средняя стоимость изделия | D4: ='Ялта, Ленина, 18'!I11 -> 7800
A5: Длина чека | D5: ='Ялта, Ленина, 18'!I12 -> 1.74
A6: Кол-во чеков | D6: =IF(D5<>0,D2/D5,"") -> 11.199528
A7: Конверсия | D7: ='Ялта, Ленина, 18'!I20 -> 0.12
A8: IS | D8: =('Ялта, Ленина, 18'!U12-'Ялта, Ленина, 18'!V12)/('Ялта, Ленина, 18'!I14-'Ялта, Ленина, 18'!J14) -> #DIV/0!
A9: UNOde50 | D9: =('Ялта, Ленина, 18'!U18-'Ялта, Ленина, 18'!V18)/('Ялта, Ленина, 18'!I14-'Ялта, Ленина, 18'!J14) -> #DIV/0!
A10: ='Ялта, Ленина, 18'!M23 -> Agafi | D10: =('Ялта, Ленина, 18'!X12-'Ялта, Ленина, 18'!Y12)/('Ялта, Ленина, 18'!I14-'Ялта, Ленина, 18'!J14) -> #DIV/0!

Sheet Рогалевич И. Е. 
B1: =TODAY()-1 -> 46060
B2: (отчетная дата) | J2: ЕЖЕДНЕВНЫЙ ОТЧЕТ О ПРОДАЖАХ
B3: Осталось до выполнения плана!!! | J3: =График!B29 -> Рогалевич Ирина
C4: =I8-D57 -> 123464.62 | E4: =IF(I8<>0,C4/I8,0) -> 0.25946334
F6: Целевые показатели
F7: Показатель | I7: План | J7: Факт | K7: % выполнения | L7: Прогноз выполнения | M7: % выполнения по прогнозу | N7: Отклонение | O7: Факт аналогичного месяца прошлого года | P7: Отклонение LFL
F8: Выручка | I8: ='Ялта, Ленина, 18'!I8/График!AJ31*График!AJ29 -> 475846.12 | J8: =D57 -> 352381.5 | K8: =IF(AND(I8<>"",I8<>0,J8<>""),J8/I8,"") -> 0.74053666 | L8: =IF(SUMIF($D$25:$D$56,">=0",$P$25:$P$56)<>0,I8*D57/SUMIF($D$25:$D$56,">=0",$P$25:$P$56),0) -> 580006.82 | M8: =IF(AND(I8<>"",I8<>0,L8<>"",L8<>0),L8/I8,"") -> 1.2188958 | N8: =IF(AND(J8<>0,J8<>"",I8<>0,I8<>""),L8-I8,"") -> 104160.7 | P8: =IF(AND(O8<>"",O8<>0,L8<>"",L8<>0),-O8+L8,"") | Q8: =IF(AND(P8<>"",P8<>0,O8<>0,O8<>""),P8/O8,"")
F9: Кол-во изделий | I9: =I8/I11 -> 61.005913 | J9: =E57 -> 39 | K9: =IF(AND(I9<>"",I9<>0,J9<>""),J9/I9,"") -> 0.63928229 | L9: =IF(SUMIF($E$25:$E$54,">=0",$Q$25:$Q$54)<>0,I9*E57/SUMIF($E$25:$E$54,">=0",$Q$25:$Q$54),0) -> 69.59596 | M9: =IF(AND(I9<>"",I9<>0,L9<>"",L9<>0),L9/I9,"") -> 1.1408068 | N9: =IF(AND(J9<>0,J9<>"",I9<>0,I9<>""),L9-I9,"") -> 8.5900466 | O9: =O8/O11 -> #DIV/0! | P9: =IF(AND(O9<>"",O9<>0,L9<>"",L9<>0),-O9+L9,"") -> #DIV/0! | Q9: =IF(AND(P9<>"",P9<>0,O9<>0,O9<>""),P9/O9,"") -> #DIV/0!
F10: Средний чек | I10: =I11*I12 -> 13572 | J10: =H57 -> 18546.395 | K10: =IF(AND(I10<>"",I10<>0,J10<>""),J10/I10,"") -> 1.3665189 | L10: =J10 -> 18546.395 | M10: =IF(AND(I10<>"",I10<>0,L10<>"",L10<>0),L10/I10,"") -> 1.3665189 | N10: =IF(AND(J10<>0,J10<>"",I10<>0,I10<>""),L10-I10,"") -> 4974.3947 | O10: =O11*O12 -> 0 | P10: =IF(AND(O10<>"",O10<>0,L10<>"",L10<>0),-O10+L10,"") | Q10: =IF(AND(P10<>"",P10<>0,O10<>0,O10<>""),P10/O10,"") | S10: IS | V10: =M23 -> Agafi
F11: Средняя стоимость изделия | I11: ='Ялта, Ленина, 18'!I11 -> 7800 | J11: =F57 -> 9035.4231 | K11: =IF(AND(I11<>"",I11<>0,J11<>""),J11/I11,"") -> 1.1583876 | L11: =IF(L9>0,L8/L9,"") -> 8333.9151 | M11: =IF(AND(I11<>"",I11<>0,L11<>"",L11<>0),L11/I11,"") -> 1.0684507 | N11: =IF(AND(J11<>0,J11<>"",I11<>0,I11<>""),L11-I11,"") -> 533.91507 | P11: =IF(AND(O11<>"",O11<>0,L11<>"",L11<>0),-O11+L11,"") | Q11: =IF(AND(P11<>"",P11<>0,O11<>0,O11<>""),P11/O11,"")
F12: Длина чека | I12: ='Ялта, Ленина, 18'!I12 -> 1.74 | J12: =J57 -> 2.0526316 | K12: =IF(AND(I12<>"",I12<>0,J12<>""),J12/I12,"") -> 1.1796733 | L12: =J12 -> 2.0526316 | M12: =IF(AND(I12<>"",I12<>0,L12<>"",L12<>0),L12/I12,"") -> 1.1796733 | N12: =IF(AND(J12<>0,J12<>"",I12<>0,I12<>""),L12-I12,"") -> 0.31263158 | P12: =IF(AND(O12<>"",O12<>0,L12<>"",L12<>0),-O12+L12,"") | Q12: =IF(AND(P12<>"",P12<>0,O12<>0,O12<>""),P12/O12,"") | S12: ='Ялта, Ленина, 18'!U12*График!AJ29/График!AJ31 -> 93130.435 | T12: =L57 -> 25903 | V12: ='Ялта, Ленина, 18'!X12/График!AJ31*График!AJ29 -> 87652.174 | W12: =M57 -> 0
F13: Кол-во чеков | I13: =IF(I12<>0,I9/I12,"") -> 35.06087 | J13: =G57 -> 19 | K13: =IF(AND(I13<>"",I13<>0,J13<>""),J13/I13,"") -> 0.54191468 | L13: =IF(SUMIF($G$25:$G$54,">=0",$R$25:$R$54)<>0,I13*G57/SUMIF($G$25:$G$54,">=0",$R$25:$R$54),"") -> 33.905724 | M13: =IF(AND(I13<>"",I13<>0,L13<>"",L13<>0),L13/I13,"") -> 0.96705314 | N13: =IF(AND(J13<>0,J13<>"",I13<>0,I13<>""),L13-I13,"") -> -1.1551457 | P13: =IF(AND(O13<>"",O13<>0,L13<>"",L13<>0),-O13+L13,"") | Q13: =IF(AND(P13<>"",P13<>0,O13<>0,O13<>""),P13/O13,"") | S13: =T12/S12 -> 0.27813679 | T13: =S13/J14*I14 -> 0.27813679 | V13: =W12/V12 -> 0 | W13: =V13/J14*I14 -> 0
F14: Кол-во смен план/отработано | I14: =График!AI29 -> 12 | J14: 12 | K14: =IF(AND(I14<>"",I14<>0,J14<>""),J14/I14,"") -> 1 | L14: =I14 -> 12 | M14: =IF(AND(I14<>"",I14<>0,L14<>"",L14<>0),L14/I14,"") -> 1 | N14: =IF(AND(J14<>0,J14<>"",I14<>0,I14<>""),L14-I14,"") -> 0 | P14: =IF(AND(O14<>"",O14<>0,L14<>"",L14<>0),-O14+L14,"") | Q14: =IF(AND(P14<>"",P14<>0,O14<>0,O14<>""),P14/O14,"")
F15: Средние продажи в смену | I15: ='Ялта, Ленина, 18'!I15 -> 84058.839 | J15: =J8/J14 -> 29365.125 | K15: =IF(AND(I15<>"",I15<>0,J15<>""),J15/I15,"") -> 0.34934012 | L15: =J15 -> 29365.125 | M15: =IF(AND(I15<>"",I15<>0,L15<>"",L15<>0),L15/I15,"") -> 0.34934012 | N15: =IF(AND(J15<>0,J15<>"",I15<>0,I15<>""),L15-I15,"") -> -54693.714 | P15: =IF(AND(O15<>"",O15<>0,L15<>"",L15<>0),-O15+L15,"") | Q15: =IF(AND(P15<>"",P15<>0,O15<>0,O15<>""),P15/O15,"")
F16: Отставание/Перевыполнение | J16: =J8-I15*J14 -> -656324.56 | K16: =IF(AND(I16<>"",I16<>0,J16<>""),J16/I16,"") | L16: =J16 -> -656324.56 | M16: =IF(AND(I16<>"",I16<>0,L16<>"",L16<>0),L16/I16,"") | N16: =IF(AND(J16<>0,J16<>"",I16<>0,I16<>""),L16-I16,"") | P16: =IF(AND(O16<>"",O16<>0,L16<>"",L16<>0),-O16+L16,"") | Q16: =IF(AND(P16<>"",P16<>0,O16<>0,O16<>""),P16/O16,"") | S16: UNOde50
F17: Трафик | I17: ='Ялта, Ленина, 18'!I17/График!AJ31*График!AJ29 -> 292.17391 | J17: =I57 -> 158 | K17: =IF(AND(I17<>"",I17<>0,J17<>""),J17/I17,"") -> 0.54077381 | L17: =J17/J14*I14 -> 158 | M17: =IF(AND(I17<>"",I17<>0,L17<>"",L17<>0),L17/I17,"") -> 0.54077381 | N17: =IF(AND(J17<>0,J17<>"",I17<>0,I17<>""),L17-I17,"") -> -134.17391 | P17: =IF(AND(O17<>"",O17<>0,L17<>"",L17<>0),-O17+L17,"") | Q17: =IF(AND(P17<>"",P17<>0,O17<>0,O17<>""),P17/O17,"")
K18: =IF(AND(I18<>"",I18<>0,J18<>""),J18/I18,"") | L18: =J18 -> 0 | M18: =IF(AND(I18<>"",I18<>0,L18<>"",L18<>0),L18/I18,"") | N18: =IF(AND(J18<>0,J18<>"",I18<>0,I18<>""),L18-I18,"") | O18: 0 | P18: =IF(AND(O18<>"",O18<>0,L18<>"",L18<>0),-O18+L18,"") | Q18: =IF(AND(P18<>"",P18<>0,O18<>0,O18<>""),P18/O18,"") | S18: ='Ялта, Ленина, 18'!U18*График!AJ29/График!AJ31 -> 186260.87 | T18: =K57 -> 77460
K19: =IF(AND(I19<>"",I19<>0,J19<>""),J19/I19,"") | L19: =J19 -> 0 | M19: =IF(AND(I19<>"",I19<>0,L19<>"",L19<>0),L19/I19,"") | N19: =IF(AND(J19<>0,J19<>"",I19<>0,I19<>""),L19-I19,"") | O19: 0 | P19: =IF(AND(O19<>"",O19<>0,L19<>"",L19<>0),-O19+L19,"") | Q19: =IF(AND(P19<>"",P19<>0,O19<>0,O19<>""),P19/O19,"") | S19: =T18/S18 -> 0.41586835 | T19: =S19/J14*I14 -> 0.41586835
F20: Конверсия план/факт | I20: ='Ялта, Ленина, 18'!I20 -> 0.12 | J20: =N57 -> 0.12025316 | K20: =J20/I20 -> 1.0021097 | L20: =IF(AND(K8<>0,I14<>0,I57<>0),(I57*N57+(I57/K8-I57)*I20)/(I57/K8),0) -> 0.12018748 | M20: =IF(AND(I20<>"",I20<>0,L20<>"",L20<>0),L20/I20,"") -> 1.0015623 | N20: =IF(AND(J20<>0,J20<>"",I20<>0,I20<>""),L20-I20,"") -> 0.00018747764 | P20: =IF(AND(O20<>"",O20<>0,L20<>"",L20<>0),-O20+L20,"") | Q20: =IF(AND(P20<>"",P20<>0,O20<>0,O20<>""),P20/O20,"")
B22: Факт продаж за месяц | O22: % выполнения дневного плана | P22: Раcпределение плана по дням
B23: Дата | C23: День недели | D23: Выручка (руб) | E23: Кол-во единиц (шт.) | F23: Средняя стоимость изделия (руб.) | G23: Количество чеков (шт.) | H23: Средняя сумма чека (руб.) | I23: Трафик | J23: Длина чека (шт.) | K23: UNOde50 | L23: IS | M23: Agafi | N23: Конверсия (%) | P23: выручка, план | Q23: кол-во ед, план | R23: Кол-во чеков, план | S23: выручка, скорректир.план | T23: кол-во ед, скорр. план | U23: кол-во чеков, скорр. план | V23: Коэфф. Дня Недели | W23: Специфика месяца
B24: 1 | C24: 2 | D24: 3 | E24: 4 | F24: 5 | G24: 6 | H24: 7 | I24: 8 | J24: 9 | K24: 10 | L24: 11 | M24: 12 | N24: 13 | P24: 1 | Q24: 2 | R24: 3 | S24: 4 | T24: 5 | U24: 6 | V24: 10 | W24: 11
A25: 1 | B25: 46000 | C25: вт | F25: =IF(AND(E25<>"",E25<>0),D25/E25,"") | H25: =IF(AND(G25<>"",G25<>0),D25/G25,"") | J25: =IF(AND(G25<>"",G25<>0),E25/G25,"") | N25: =IF(AND(I25<>"",I25<>0),G25/I25,"") | O25: =D25/P25 -> 0 | P25: =$I$8*V25*W25/SUMPRODUCT($W$25:$W$56,$V$25:$V$56) -> 22445.572 | Q25: =$I$9*V25*W25/SUMPRODUCT($W$25:$W$56,$V$25:$V$56) -> 2.8776374 | R25: =IF($I$12="","",Q25/$I$12) -> 1.6538146 | S25: =IF(D25<>"",D25,P25) -> 22445.572 | T25: =IF(E25<>"",E25,Q25) -> 2.8776374 | U25: =IF(G25<>"",G25,R25) -> 1.6538146 | V25: 1 | W25: 1
A26: 2 | B26: 46001 | C26: ср | D26: 69549 | E26: 6 | F26: =IF(AND(E26<>"",E26<>0),D26/E26,"") -> 11591.5 | G26: 1 | H26: =IF(AND(G26<>"",G26<>0),D26/G26,"") -> 69549 | I26: 4 | J26: =IF(AND(G26<>"",G26<>0),E26/G26,"") -> 6 | K26: 39980 | N26: =IF(AND(I26<>"",I26<>0),G26/I26,"") -> 0.25 | O26: =D26/P26 -> 3.0985622 | P26: =$I$8*V26*W26/SUMPRODUCT($W$25:$W$56,$V$25:$V$56) -> 22445.572 | Q26: =$I$9*V26*W26/SUMPRODUCT($W$25:$W$58,$V$25:$V$58) -> 2.8776374 | R26: =IF($I$12="","",Q26/$I$12) -> 1.6538146 | S26: =IF(W26<>"",IF(D26<>"",D26,($I$8-SUM($S$25:S25))*V26*W26/SUMPRODUCT($W26:$W$56,$V26:$V$56)),"") -> 69549 | T26: =IF(W26<>"",IF(E26<>"",E26,($I$9-SUM($T$25:T25))*V26*W26/SUMPRODUCT($W26:$W$58,$V26:$V$58)),"") -> 6 | U26: =IF(W26<>"",IF($I$12<>"",IF(G26<>"",G26,($I$9/$I$12-SUM($U$25:U25))*V26*W26/SUMPRODUCT($W26:$W$58,$V26:$V$58)),""),"") -> 1 | V26: 1 | W26: 1
A27: 3 | B27: 46002 | C27: чт | D27: 7984 | E27: 2 | F27: 3992 | G27: 1 | H27: =IF(AND(G27<>"",G27<>0),D27/G27,"") -> 7984 | I27: 6 | J27: =IF(AND(G27<>"",G27<>0),E27/G27,"") -> 2 | N27: =IF(AND(I27<>"",I27<>0),G27/I27,"") -> 0.16666667 | O27: =D27/P27 -> 0.35570491 | P27: =$I$8*V27*W27/SUMPRODUCT($W$25:$W$56,$V$25:$V$56) -> 22445.572 | Q27: =$I$9*V27*W27/SUMPRODUCT($W$25:$W$58,$V$25:$V$58) -> 2.8776374 | R27: =IF($I$12="","",Q27/$I$12) -> 1.6538146 | S27: =IF(W27<>"",IF(D27<>"",D27,($I$8-SUM($S$25:S26))*V27*W27/SUMPRODUCT($W27:$W$58,$V27:$V$58)),"") -> 7984 | T27: =IF(W27<>"",IF(E27<>"",E27,($I$9-SUM($T$25:T26))*V27*W27/SUMPRODUCT($W27:$W$58,$V27:$V$58)),"") -> 2 | U27: =IF(W27<>"",IF($I$12<>"",IF(G27<>"",G27,($I$9/$I$12-SUM($U$25:U26))*V27*W27/SUMPRODUCT($W27:$W$58,$V27:$V$58)),""),"") -> 1 | V27: 1 | W27: 1
A28: 4 | B28: 46003 | C28: пт | D28: 4494 | E28: 1 | F28: =IF(AND(E28<>"",E28<>0),D28/E28,"") -> 4494 | G28: 1 | H28: =IF(AND(G28<>"",G28<>0),D28/G28,"") -> 4494 | I28: 13 | J28: =IF(AND(G28<>"",G28<>0),E28/G28,"") -> 1 | N28: =IF(AND(I28<>"",I28<>0),G28/I28,"") -> 0.076923077 | O28: =D28/P28 -> 0.20021767 | P28: =$I$8*V28*W28/SUMPRODUCT($W$25:$W$56,$V$25:$V$56) -> 22445.572 | Q28: =$I$9*V28*W28/SUMPRODUCT($W$25:$W$58,$V$25:$V$58) -> 2.8776374 | R28: =IF($I$12="","",Q28/$I$12) -> 1.6538146 | S28: =IF(W28<>"",IF(D28<>"",D28,($I$8-SUM($S$25:S27))*V28*W28/SUMPRODUCT($W28:$W$58,$V28:$V$58)),"") -> 4494 | T28: =IF(W28<>"",IF(E28<>"",E28,($I$9-SUM($T$25:T27))*V28*W28/SUMPRODUCT($W28:$W$58,$V28:$V$58)),"") -> 1 | U28: =IF(W28<>"",IF($I$12<>"",IF(G28<>"",G28,($I$9/$I$12-SUM($U$25:U27))*V28*W28/SUMPRODUCT($W28:$W$58,$V28:$V$58)),""),"") -> 1 | V28: 1 | W28: 1
A29: 5 | B29: 46004 | C29: сб | D29: 12384 | E29: 2 | F29: =IF(AND(E29<>"",E29<>0),D29/E29,"") -> 6192 | G29: 1 | H29: =IF(AND(G29<>"",G29<>0),D29/G29,"") -> 12384 | I29: 10 | J29: =IF(AND(G29<>"",G29<>0),E29/G29,"") -> 2 | N29: =IF(AND(I29<>"",I29<>0),G29/I29,"") -> 0.1 | O29: =D29/P29 -> 0.55173466 | P29: =$I$8*V29*W29/SUMPRODUCT($W$25:$W$56,$V$25:$V$56) -> 22445.572 | Q29: =$I$9*V29*W29/SUMPRODUCT($W$25:$W$58,$V$25:$V$58) -> 2.8776374 | R29: =IF($I$12="","",Q29/$I$12) -> 1.6538146 | S29: =IF(W29<>"",IF(D29<>"",D29,($I$8-SUM($S$25:S28))*V29*W29/SUMPRODUCT($W29:$W$58,$V29:$V$58)),"") -> 12384 | T29: =IF(W29<>"",IF(E29<>"",E29,($I$9-SUM($T$25:T28))*V29*W29/SUMPRODUCT($W29:$W$58,$V29:$V$58)),"") -> 2 | U29: =IF(W29<>"",IF($I$12<>"",IF(G29<>"",G29,($I$9/$I$12-SUM($U$25:U28))*V29*W29/SUMPRODUCT($W29:$W$58,$V29:$V$58)),""),"") -> 1 | V29: 1 | W29: 1
A30: 6 | B30: 46005 | C30: вс | D30: 37966 | E30: 4 | F30: =IF(AND(E30<>"",E30<>0),D30/E30,"") -> 9491.5 | G30: 1 | H30: =IF(AND(G30<>"",G30<>0),D30/G30,"") -> 37966 | I30: 18 | J30: =IF(AND(G30<>"",G30<>0),E30/G30,"") -> 4 | N30: =IF(AND(I30<>"",I30<>0),G30/I30,"") -> 0.055555556 | O30: =D30/P30 -> 1.6914695 | P30: =$I$8*V30*W30/SUMPRODUCT($W$25:$W$56,$V$25:$V$56) -> 22445.572 | Q30: =$I$9*V30*W30/SUMPRODUCT($W$25:$W$58,$V$25:$V$58) -> 2.8776374 | R30: =IF($I$12="","",Q30/$I$12) -> 1.6538146 | S30: =IF(W30<>"",IF(D30<>"",D30,($I$8-SUM($S$25:S29))*V30*W30/SUMPRODUCT($W30:$W$58,$V30:$V$58)),"") -> 37966 | T30: =IF(W30<>"",IF(E30<>"",E30,($I$9-SUM($T$25:T29))*V30*W30/SUMPRODUCT($W30:$W$58,$V30:$V$58)),"") -> 4 | U30: =IF(W30<>"",IF($I$12<>"",IF(G30<>"",G30,($I$9/$I$12-SUM($U$25:U29))*V30*W30/SUMPRODUCT($W30:$W$58,$V30:$V$58)),""),"") -> 1 | V30: 1 | W30: 1
A31: 7 | B31: 46007 | C31: вт | D31: 4493 | E31: 1 | F31: =IF(AND(E31<>"",E31<>0),D31/E31,"") -> 4493 | G31: 1 | H31: =IF(AND(G31<>"",G31<>0),D31/G31,"") -> 4493 | I31: 6 | J31: =IF(AND(G31<>"",G31<>0),E31/G31,"") -> 1 | N31: =IF(AND(I31<>"",I31<>0),G31/I31,"") -> 0.16666667 | O31: =D31/P31 -> 0.20017311 | P31: =$I$8*V31*W31/SUMPRODUCT($W$25:$W$56,$V$25:$V$56) -> 22445.572 | Q31: =$I$9*V31*W31/SUMPRODUCT($W$25:$W$58,$V$25:$V$58) -> 2.8776374 | R31: =IF($I$12="","",Q31/$I$12) -> 1.6538146 | S31: =IF(W31<>"",IF(D31<>"",D31,($I$8-SUM($S$25:S30))*V31*W31/SUMPRODUCT($W31:$W$58,$V31:$V$58)),"") -> 4493 | T31: =IF(W31<>"",IF(E31<>"",E31,($I$9-SUM($T$25:T30))*V31*W31/SUMPRODUCT($W31:$W$58,$V31:$V$58)),"") -> 1 | U31: =IF(W31<>"",IF($I$12<>"",IF(G31<>"",G31,($I$9/$I$12-SUM($U$25:U30))*V31*W31/SUMPRODUCT($W31:$W$58,$V31:$V$58)),""),"") -> 1 | V31: 1 | W31: 1
A32: 8 | B32: 46008 | C32: ср | D32: 42550 | E32: 6 | F32: =IF(AND(E32<>"",E32<>0),D32/E32,"") -> 7091.6667 | G32: 2 | H32: =IF(AND(G32<>"",G32<>0),D32/G32,"") -> 21275 | I32: 22 | J32: =IF(AND(G32<>"",G32<>0),E32/G32,"") -> 3 | N32: =IF(AND(I32<>"",I32<>0),G32/I32,"") -> 0.090909091 | O32: =D32/P32 -> 1.8956969 | P32: =$I$8*V32*W32/SUMPRODUCT($W$25:$W$56,$V$25:$V$56) -> 22445.572 | Q32: =$I$9*V32*W32/SUMPRODUCT($W$25:$W$58,$V$25:$V$58) -> 2.8776374 | R32: =IF($I$12="","",Q32/$I$12) -> 1.6538146 | S32: =IF(W32<>"",IF(D32<>"",D32,($I$8-SUM($S$25:S31))*V32*W32/SUMPRODUCT($W32:$W$58,$V32:$V$58)),"") -> 42550 | T32: =IF(W32<>"",IF(E32<>"",E32,($I$9-SUM($T$25:T31))*V32*W32/SUMPRODUCT($W32:$W$58,$V32:$V$58)),"") -> 6 | U32: =IF(W32<>"",IF($I$12<>"",IF(G32<>"",G32,($I$9/$I$12-SUM($U$25:U31))*V32*W32/SUMPRODUCT($W32:$W$58,$V32:$V$58)),""),"") -> 2 | V32: 1 | W32: 1
A33: 9 | B33: 46009 | C33: чт | D33: 0 | E33: 0 | F33: =IF(AND(E33<>"",E33<>0),D33/E33,"") | G33: 0 | H33: =IF(AND(G33<>"",G33<>0),D33/G33,"") | I33: 26 | J33: =IF(AND(G33<>"",G33<>0),E33/G33,"") | N33: =IF(AND(I33<>"",I33<>0),G33/I33,"") -> 0 | O33: =D33/P33 -> 0 | P33: =$I$8*V33*W33/SUMPRODUCT($W$25:$W$56,$V$25:$V$56) -> 22445.572 | Q33: =$I$9*V33*W33/SUMPRODUCT($W$25:$W$58,$V$25:$V$58) -> 2.8776374 | R33: =IF($I$12="","",Q33/$I$12) -> 1.6538146 | S33: =IF(W33<>"",IF(D33<>"",D33,($I$8-SUM($S$25:S32))*V33*W33/SUMPRODUCT($W33:$W$58,$V33:$V$58)),"") -> 0 | T33: =IF(W33<>"",IF(E33<>"",E33,($I$9-SUM($T$25:T32))*V33*W33/SUMPRODUCT($W33:$W$58,$V33:$V$58)),"") -> 0 | U33: =IF(W33<>"",IF($I$12<>"",IF(G33<>"",G33,($I$9/$I$12-SUM($U$25:U32))*V33*W33/SUMPRODUCT($W33:$W$58,$V33:$V$58)),""),"") -> 0 | V33: 1 | W33: 1
A34: 10 | B34: 46010 | C34: пт | F34: =IF(AND(E34<>"",E34<>0),D34/E34,"") | H34: =IF(AND(G34<>"",G34<>0),D34/G34,"") | J34: =IF(AND(G34<>"",G34<>0),E34/G34,"") | N34: =IF(AND(I34<>"",I34<>0),G34/I34,"") | O34: =D34/P34 -> #DIV/0! | P34: =$I$8*V34*W34/SUMPRODUCT($W$25:$W$56,$V$25:$V$56) -> 0 | Q34: =$I$9*V34*W34/SUMPRODUCT($W$25:$W$58,$V$25:$V$58) -> 0 | R34: =IF($I$12="","",Q34/$I$12) -> 0 | S34: =IF(W34<>"",IF(D34<>"",D34,($I$8-SUM($S$25:S33))*V34*W34/SUMPRODUCT($W34:$W$58,$V34:$V$58)),"") | T34: =IF(W34<>"",IF(E34<>"",E34,($I$9-SUM($T$25:T33))*V34*W34/SUMPRODUCT($W34:$W$58,$V34:$V$58)),"") | U34: =IF(W34<>"",IF($I$12<>"",IF(G34<>"",G34,($I$9/$I$12-SUM($U$25:U33))*V34*W34/SUMPRODUCT($W34:$W$58,$V34:$V$58)),""),"")
A35: 11 | B35: 46011 | C35: сб | F35: =IF(AND(E35<>"",E35<>0),D35/E35,"") | H35: =IF(AND(G35<>"",G35<>0),D35/G35,"") | J35: =IF(AND(G35<>"",G35<>0),E35/G35,"") | N35: =IF(AND(I35<>"",I35<>0),G35/I35,"") | O35: =D35/P35 -> #DIV/0! | P35: =$I$8*V35*W35/SUMPRODUCT($W$25:$W$56,$V$25:$V$56) -> 0 | Q35: =$I$9*V35*W35/SUMPRODUCT($W$25:$W$58,$V$25:$V$58) -> 0 | R35: =IF($I$12="","",Q35/$I$12) -> 0 | S35: =IF(W35<>"",IF(D35<>"",D35,($I$8-SUM($S$25:S34))*V35*W35/SUMPRODUCT($W35:$W$58,$V35:$V$58)),"") | T35: =IF(W35<>"",IF(E34<>"",E34,($I$9-SUM($T$25:T34))*V35*W35/SUMPRODUCT($W35:$W$58,$V35:$V$58)),"") | U35: =IF(W35<>"",IF($I$12<>"",IF(G35<>"",G35,($I$9/$I$12-SUM($U$25:U34))*V35*W35/SUMPRODUCT($W35:$W$58,$V35:$V$58)),""),"")
A36: 12 | B36: 46012 | C36: вс | F36: =IF(AND(E36<>"",E36<>0),D36/E36,"") | H36: =IF(AND(G36<>"",G36<>0),D36/G36,"") | J36: =IF(AND(G36<>"",G36<>0),E36/G36,"") | N36: =IF(AND(I36<>"",I36<>0),G36/I36,"") | O36: =D36/P36 -> #DIV/0! | P36: =$I$8*V36*W36/SUMPRODUCT($W$25:$W$56,$V$25:$V$56) -> 0 | Q36: =$I$9*V36*W36/SUMPRODUCT($W$25:$W$58,$V$25:$V$58) -> 0 | R36: =IF($I$12="","",Q36/$I$12) -> 0 | S36: =IF(W36<>"",IF(D36<>"",D36,($I$8-SUM($S$25:S35))*V36*W36/SUMPRODUCT($W36:$W$58,$V36:$V$58)),"") | T36: =IF(W36<>"",IF(E35<>"",E35,($I$9-SUM($T$25:T35))*V36*W36/SUMPRODUCT($W36:$W$58,$V36:$V$58)),"") | U36: =IF(W36<>"",IF($I$12<>"",IF(G36<>"",G36,($I$9/$I$12-SUM($U$25:U35))*V36*W36/SUMPRODUCT($W36:$W$58,$V36:$V$58)),""),"")
A37: 13 | B37: 46013 | C37: пн | F37: =IF(AND(E37<>"",E37<>0),D37/E37,"") | H37: =IF(AND(G37<>"",G37<>0),D37/G37,"") | J37: =IF(AND(G37<>"",G37<>0),E37/G37,"") | N37: =IF(AND(I37<>"",I37<>0),G37/I37,"") | O37: =D37/P37 -> #DIV/0! | P37: =$I$8*V37*W37/SUMPRODUCT($W$25:$W$56,$V$25:$V$56) -> 0 | Q37: =$I$9*V37*W37/SUMPRODUCT($W$25:$W$58,$V$25:$V$58) -> 0 | R37: =IF($I$12="","",Q37/$I$12) -> 0 | S37: =IF(W37<>"",IF(D37<>"",D37,($I$8-SUM($S$25:S36))*V37*W37/SUMPRODUCT($W37:$W$58,$V37:$V$58)),"") | T37: =IF(W37<>"",IF(E37<>"",E37,($I$9-SUM($T$25:T36))*V37*W37/SUMPRODUCT($W37:$W$58,$V37:$V$58)),"") | U37: =IF(W37<>"",IF($I$12<>"",IF(G37<>"",G37,($I$9/$I$12-SUM($U$25:U36))*V37*W37/SUMPRODUCT($W37:$W$58,$V37:$V$58)),""),"")
A38: 14 | B38: 46014 | C38: вт | F38: =IF(AND(E38<>"",E38<>0),D38/E38,"") | H38: =IF(AND(G38<>"",G38<>0),D38/G38,"") | J38: =IF(AND(G38<>"",G38<>0),E38/G38,"") | N38: =IF(AND(I38<>"",I38<>0),G38/I38,"") | O38: =D38/P38 -> 0 | P38: =$I$8*V38*W38/SUMPRODUCT($W$25:$W$56,$V$25:$V$56) -> 22445.572 | Q38: =$I$9*V38*W38/SUMPRODUCT($W$25:$W$58,$V$25:$V$58) -> 2.8776374 | R38: =IF($I$12="","",Q38/$I$12) -> 1.6538146 | S38: =IF(W38<>"",IF(D38<>"",D38,($I$8-SUM($S$25:S37))*V38*W38/SUMPRODUCT($W38:$W$58,$V38:$V$58)),"") -> 22457.422 | T38: =IF(W38<>"",IF(E38<>"",E38,($I$9-SUM($T$25:T37))*V38*W38/SUMPRODUCT($W38:$W$58,$V38:$V$58)),"") -> 2.9613341 | U38: =IF(W38<>"",IF($I$12<>"",IF(G38<>"",G38,($I$9/$I$12-SUM($U$25:U37))*V38*W38/SUMPRODUCT($W38:$W$58,$V38:$V$58)),""),"") -> 2.0825455 | V38: 1 | W38: 1
A39: 15 | B39: 46015 | C39: ср | F39: =IF(AND(E39<>"",E39<>0),D39/E39,"") | H39: =IF(AND(G39<>"",G39<>0),D39/G39,"") | J39: =IF(AND(G39<>"",G39<>0),E39/G39,"") | N39: =IF(AND(I39<>"",I39<>0),G39/I39,"") | O39: =D39/P39 -> 0 | P39: =$I$8*V39*W39/SUMPRODUCT($W$25:$W$56,$V$25:$V$56) -> 22445.572 | Q39: =$I$9*V39*W39/SUMPRODUCT($W$25:$W$58,$V$25:$V$58) -> 2.8776374 | R39: =IF($I$12="","",Q39/$I$12) -> 1.6538146 | S39: =IF(W39<>"",IF(D39<>"",D39,($I$8-SUM($S$25:S38))*V39*W39/SUMPRODUCT($W39:$W$58,$V39:$V$58)),"") -> 22457.422 | T39: =IF(W39<>"",IF(E39<>"",E39,($I$9-SUM($T$25:T38))*V39*W39/SUMPRODUCT($W39:$W$58,$V39:$V$58)),"") -> 2.9613341 | U39: =IF(W39<>"",IF($I$12<>"",IF(G39<>"",G39,($I$9/$I$12-SUM($U$25:U38))*V39*W39/SUMPRODUCT($W39:$W$58,$V39:$V$58)),""),"") -> 2.0825455 | V39: 1 | W39: 1
A40: 16 | B40: 46016 | C40: чт | F40: =IF(AND(E40<>"",E40<>0),D40/E40,"") | H40: =IF(AND(G40<>"",G40<>0),D40/G40,"") | J40: =IF(AND(G40<>"",G40<>0),E40/G40,"") | N40: =IF(AND(I40<>"",I40<>0),G40/I40,"") | O40: =D40/P40 -> 0 | P40: =$I$8*V40*W40/SUMPRODUCT($W$25:$W$56,$V$25:$V$56) -> 22445.572 | Q40: =$I$9*V40*W40/SUMPRODUCT($W$25:$W$58,$V$25:$V$58) -> 2.8776374 | R40: =IF($I$12="","",Q40/$I$12) -> 1.6538146 | S40: =IF(W40<>"",IF(D40<>"",D40,($I$8-SUM($S$25:S39))*V40*W40/SUMPRODUCT($W40:$W$58,$V40:$V$58)),"") -> 22457.422 | T40: =IF(W40<>"",IF(E39<>"",E39,($I$9-SUM($T$25:T39))*V40*W40/SUMPRODUCT($W40:$W$58,$V40:$V$58)),"") -> 2.9613341 | U40: =IF(W40<>"",IF($I$12<>"",IF(G40<>"",G40,($I$9/$I$12-SUM($U$25:U39))*V40*W40/SUMPRODUCT($W40:$W$58,$V40:$V$58)),""),"") -> 2.0825455 | V40: 1 | W40: 1
A41: 17 | B41: 46017 | C41: пт | F41: =IF(AND(E41<>"",E41<>0),D41/E41,"") | H41: =IF(AND(G41<>"",G41<>0),D41/G41,"") | J41: =IF(AND(G41<>"",G41<>0),E41/G41,"") | N41: =IF(AND(I41<>"",I41<>0),G41/I41,"") | O41: =D41/P41 -> 0 | P41: =$I$8*V41*W41/SUMPRODUCT($W$25:$W$56,$V$25:$V$56) -> 32321.623 | Q41: =$I$9*V41*W41/SUMPRODUCT($W$25:$W$58,$V$25:$V$58) -> 4.1437979 | R41: =IF($I$12="","",Q41/$I$12) -> 2.381493 | S41: =IF(W41<>"",IF(D41<>"",D41,($I$8-SUM($S$25:S40))*V41*W41/SUMPRODUCT($W41:$W$58,$V41:$V$58)),"") -> 32338.688 | T41: =IF(W41<>"",IF(E40<>"",E40,($I$9-SUM($T$25:T40))*V41*W41/SUMPRODUCT($W41:$W$58,$V41:$V$58)),"") -> 4.2643211 | U41: =IF(W41<>"",IF($I$12<>"",IF(G41<>"",G41,($I$9/$I$12-SUM($U$25:U40))*V41*W41/SUMPRODUCT($W41:$W$58,$V41:$V$58)),""),"") -> 2.9988655 | V41: 1.2 | W41: 1.2
A42: 18 | B42: 46018 | C42: сб | F42: =IF(AND(E42<>"",E42<>0),D42/E42,"") | H42: =IF(AND(G42<>"",G42<>0),D42/G42,"") | J42: =IF(AND(G42<>"",G42<>0),E42/G42,"") | N42: =IF(AND(I42<>"",I42<>0),G42/I42,"") | O42: =D42/P42 -> 0 | P42: =$I$8*V42*W42/SUMPRODUCT($W$25:$W$56,$V$25:$V$56) -> 32321.623 | Q42: =$I$9*V42*W42/SUMPRODUCT($W$25:$W$58,$V$25:$V$58) -> 4.1437979 | R42: =IF($I$12="","",Q42/$I$12) -> 2.381493 | S42: =IF(W42<>"",IF(D42<>"",D42,($I$8-SUM($S$25:S41))*V42*W42/SUMPRODUCT($W42:$W$58,$V42:$V$58)),"") -> 32338.688 | T42: =IF(W42<>"",IF(E42<>"",E42,($I$9-SUM($T$25:T41))*V42*W42/SUMPRODUCT($W42:$W$58,$V42:$V$58)),"") -> 4.2643211 | U42: =IF(W42<>"",IF($I$12<>"",IF(G42<>"",G42,($I$9/$I$12-SUM($U$25:U41))*V42*W42/SUMPRODUCT($W42:$W$58,$V42:$V$58)),""),"") -> 2.9988655 | V42: 1.2 | W42: 1.2
...

Sheet Уразгильдеева Е. Р. 
B1: =TODAY()-1 -> 46060
B2: (отчетная дата) | J2: ЕЖЕДНЕВНЫЙ ОТЧЕТ О ПРОДАЖАХ
B3: Осталось до выполнения плана!!! | J3: =График!B28 -> Уразгильдеева Екатерина
C4: =I8-D50 -> 1110307.6 | E4: =IF(I8<>0, C4/I8, 0) -> 1
F6: Целевые показатели
F7: Показатель | I7: План | J7: Факт | K7: % выполнения | L7: Прогноз выполнения | M7: % выполнения по прогнозу | N7: Отклонение | O7: Факт аналогичного месяца прошлого года | P7: Отклонение LFL
F8: Выручка | I8: ='Ялта, Ленина, 18'!I8/График!AJ31*График!AJ28 -> 1110307.6 | J8: =D57 -> 620172 | K8: =IF(AND(I8<>"",I8<>0,J8<>""),J8/I8,"") -> 0.55855872 | L8: =IF(SUMIF($D$25:$D$56,">=0",$P$25:$P$56)<>0,I8*D57/SUMIF($D$25:$D$56,">=0",$P$25:$P$56),0) -> 714695.34 | M8: =IF(AND(I8<>"",I8<>0,L8<>"",L8<>0),L8/I8,"") -> 0.64369128 | N8: =IF(AND(J8<>0,J8<>"",I8<>0,I8<>""),L8-I8,"") -> -395612.28 | P8: =IF(AND(O8<>"", O8<>0, L8<>"", L8<>0), -O8+L8, "") | Q8: =IF(AND(P8<>"", P8<>0, O8<>0, O8<>""), P8/O8, "")
F9: Кол-во изделий | I9: =I8/I11 -> 142.34713 | J9: =E57 -> 70 | K9: =IF(AND(I9<>"", I9<>0, J9<>""), J9/I9, "") -> 0.49175561 | L9: =IF(SUMIF($E$25:$E$54,">=0",$Q$25:$Q$54)<>0,I9*E57/SUMIF($E$25:$E$54,">=0",$Q$25:$Q$54),0) -> 80.66903 | M9: =IF(AND(I9<>"",I9<>0,L9<>"",L9<>0),L9/I9,"") -> 0.5667064 | N9: =IF(AND(J9<>0,J9<>"",I9<>0,I9<>""),L9-I9,"") -> -61.678101 | O9: =O8/O11 -> #DIV/0! | P9: =IF(AND(O9<>"", O9<>0, L9<>"", L9<>0), -O9+L9, "") -> #DIV/0! | Q9: =IF(AND(P9<>"", P9<>0, O9<>0, O9<>""), P9/O9, "") -> #DIV/0!
F10: Средний чек | I10: =I11*I12 -> 13572 | J10: =H57 -> 15126.146 | K10: =IF(AND(I10<>"", I10<>0, J10<>""), J10/I10, "") -> 1.1145112 | L10: =J10 -> 15126.146 | M10: =IF(AND(I10<>"",I10<>0,L10<>"",L10<>0),L10/I10,"") -> 1.1145112 | N10: =IF(AND(J10<>0,J10<>"",I10<>0,I10<>""),L10-I10,"") -> 1554.1463 | O10: =O11*O12 -> 0 | P10: =IF(AND(O10<>"", O10<>0, L10<>"", L10<>0), -O10+L10, "") | Q10: =IF(AND(P10<>"", P10<>0, O10<>0, O10<>""), P10/O10, "") | S10: IS | V10: =M23 -> Agafi
F11: Средняя стоимость изделия | I11: ='Ялта, Ленина, 18'!I11 -> 7800 | J11: =F57 -> 8859.6 | K11: =IF(AND(I11<>"", I11<>0, J11<>""), J11/I11, "") -> 1.1358462 | L11: =IF(L9>0,L8/L9,"") -> 8859.6 | M11: =IF(AND(I11<>"",I11<>0,L11<>"",L11<>0),L11/I11,"") -> 1.1358462 | N11: =IF(AND(J11<>0,J11<>"",I11<>0,I11<>""),L11-I11,"") -> 1059.6 | P11: =IF(AND(O11<>"", O11<>0, L11<>"", L11<>0), -O11+L11, "") | Q11: =IF(AND(P11<>"", P11<>0, O11<>0, O11<>""), P11/O11, "")
F12: Длина чека | I12: ='Ялта, Ленина, 18'!I12 -> 1.74 | J12: =J57 -> 1.7073171 | K12: =IF(AND(I12<>"", I12<>0, J12<>""), J12/I12, "") -> 0.98121671 | L12: =J12 -> 1.7073171 | M12: =IF(AND(I12<>"",I12<>0,L12<>"",L12<>0),L12/I12,"") -> 0.98121671 | N12: =IF(AND(J12<>0,J12<>"",I12<>0,I12<>""),L12-I12,"") -> -0.032682927 | P12: =IF(AND(O12<>"", O12<>0, L12<>"", L12<>0), -O12+L12, "") | Q12: =IF(AND(P12<>"", P12<>0, O12<>0, O12<>""), P12/O12, "") | S12: ='Ялта, Ленина, 18'!U12*График!AJ28/График!AJ31 -> 217304.35 | T12: =L57 -> 220 | U12: =S12-T12 -> 217084.35 | V12: ='Ялта, Ленина, 18'!X12/График!AJ31*График!AJ28 -> 204521.74 | W12: =M57 -> 37180 | X12: =V12-W12 -> 167341.74
F13: Кол-во чеков | I13: =IF(I12<>0, I9/I12, "") -> 81.808696 | J13: =G57 -> 41 | K13: =IF(AND(I13<>"", I13<>0, J13<>""), J13/I13, "") -> 0.50116922 | L13: =IF(SUMIF($G$25:$G$54,">=0",$R$25:$R$54)<>0,I13*G57/SUMIF($G$25:$G$54,">=0",$R$25:$R$54),"") -> 47.249003 | M13: =IF(AND(I13<>"",I13<>0,L13<>"",L13<>0),L13/I13,"") -> 0.57755478 | N13: =IF(AND(J13<>0,J13<>"",I13<>0,I13<>""),L13-I13,"") -> -34.559693 | P13: =IF(AND(O13<>"", O13<>0, L13<>"", L13<>0), -O13+L13, "") | Q13: =IF(AND(P13<>"", P13<>0, O13<>0, O13<>""), P13/O13, "") | S13: =T12/S12 -> 0.001012405 | T13: =S13/J14*I14 -> 0.001012405 | V13: =W12/V12 -> 0.18178997 | W13: =V13/J14*I14 -> 0.18178997
F14: Кол-во смен план/отработано | I14: =График!AI28 -> 23 | J14: 23 | K14: =IF(AND(I14<>"", I14<>0, J14<>""), J14/I14, "") -> 1 | L14: =I14 -> 23 | M14: =IF(AND(I14<>"",I14<>0,L14<>"",L14<>0),L14/I14,"") -> 1 | N14: =IF(AND(J14<>0,J14<>"",I14<>0,I14<>""),L14-I14,"") -> 0 | P14: =IF(AND(O14<>"", O14<>0, L14<>"", L14<>0), -O14+L14, "") | Q14: =IF(AND(P14<>"", P14<>0, O14<>0, O14<>""), P14/O14, "")
F15: Средние продажи в смену | I15: ='Ялта, Ленина, 18'!I15 -> 84058.839 | J15: =J8/J14 -> 26964 | K15: =IF(AND(I15<>"", I15<>0, J15<>""), J15/I15, "") -> 0.32077531 | L15: =J15 -> 26964 | M15: =IF(AND(I15<>"",I15<>0,L15<>"",L15<>0),L15/I15,"") -> 0.32077531 | N15: =IF(AND(J15<>0,J15<>"",I15<>0,I15<>""),L15-I15,"") -> -57094.839 | P15: =IF(AND(O15<>"", O15<>0, L15<>"", L15<>0), -O15+L15, "") | Q15: =IF(AND(P15<>"", P15<>0, O15<>0, O15<>""), P15/O15, "")
F16: Отставание/Перевыполнение | J16: =J8-I15*J14 -> -1313181.3 | K16: =IF(AND(I16<>"", I16<>0, J16<>""), J16/I16, "") | L16: =J16 -> -1313181.3 | M16: =IF(AND(I16<>"",I16<>0,L16<>"",L16<>0),L16/I16,"") | N16: =IF(AND(J16<>0,J16<>"",I16<>0,I16<>""),L16-I16,"") | P16: =IF(AND(O16<>"", O16<>0, L16<>"", L16<>0), -O16+L16, "") | Q16: =IF(AND(P16<>"", P16<>0, O16<>0, O16<>""), P16/O16, "") | S16: UNOde50
F17: Трафик | I17: ='Ялта, Ленина, 18'!I17/График!AJ31*График!AJ28 -> 681.73913 | J17: =I57 -> 324 | K17: =IF(AND(I17<>"", I17<>0, J17<>""), J17/I17, "") -> 0.4752551 | L17: =J17/J14*I14 -> 324 | M17: =IF(AND(I17<>"",I17<>0,L17<>"",L17<>0),L17/I17,"") -> 0.4752551 | N17: =IF(AND(J17<>0,J17<>"",I17<>0,I17<>""),L17-I17,"") -> -357.73913 | P17: =IF(AND(O17<>"", O17<>0, L17<>"", L17<>0), -O17+L17, "") | Q17: =IF(AND(P17<>"", P17<>0, O17<>0, O17<>""), P17/O17, "")
K18: =IF(AND(I18<>"", I18<>0, J18<>""), J18/I18, "") | L18: =J18 -> 0 | M18: =IF(AND(I18<>"",I18<>0,L18<>"",L18<>0),L18/I18,"") | N18: =IF(AND(J18<>0,J18<>"",I18<>0,I18<>""),L18-I18,"") | O18: 0 | P18: =IF(AND(O18<>"", O18<>0, L18<>"", L18<>0), -O18+L18, "") | Q18: =IF(AND(P18<>"", P18<>0, O18<>0, O18<>""), P18/O18, "") | S18: ='Ялта, Ленина, 18'!U18*График!AJ28/График!AJ31 -> 434608.7 | T18: =K57 -> 201362
K19: =IF(AND(I19<>"", I19<>0, J19<>""), J19/I19, "") | L19: =J19 -> 0 | M19: =IF(AND(I19<>"",I19<>0,L19<>"",L19<>0),L19/I19,"") | N19: =IF(AND(J19<>0,J19<>"",I19<>0,I19<>""),L19-I19,"") | O19: 0 | P19: =IF(AND(O19<>"", O19<>0, L19<>"", L19<>0), -O19+L19, "") | Q19: =IF(AND(P19<>"", P19<>0, O19<>0, O19<>""), P19/O19, "") | S19: =T18/S18 -> 0.46331793 | T19: =S19/J14*I14 -> 0.46331793
F20: Конверсия план/факт | I20: ='Ялта, Ленина, 18'!I20 -> 0.12 | J20: =N57 -> 0.12654321 | K20: =J20/I20 -> 1.0545267 | L20: =IF(AND(K8<>0,I14<>0,I57<>0),(I57*N57+(I57/K8-I57)*I20)/(I57/K8),0) -> 0.12365477 | M20: =IF(AND(I20<>"",I20<>0,L20<>"",L20<>0),L20/I20,"") -> 1.0304564 | N20: =IF(AND(J20<>0,J20<>"",I20<>0,I20<>""),L20-I20,"") -> 0.0036547669 | P20: =IF(AND(O20<>"", O20<>0, L20<>"", L20<>0), -O20+L20, "") | Q20: =IF(AND(P20<>"", P20<>0, O20<>0, O20<>""), P20/O20, "")
B22: Факт продаж за месяц | O22: % выполнения дневного плана | P22: Раcпределение плана по дням
B23: Дата | C23: День недели | D23: Выручка (руб) | E23: Кол-во единиц (шт.) | F23: Средняя стоимость изделия (руб.) | G23: Количество чеков (шт.) | H23: Средняя сумма чека (руб.) | I23: Трафик | J23: Длина чека (шт.) | K23: UNOde50 | L23: IS | M23: Agafi | N23: Конверсия (%) | P23: выручка, план | Q23: кол-во ед, план | R23: Кол-во чеков, план | S23: выручка, скорректир.план | T23: кол-во ед, скорр. план | U23: кол-во чеков, скорр. план | V23: Коэфф. Дня Недели | W23: Специфика месяца
B24: 1 | C24: 2 | D24: 3 | E24: в | F24: 5 | G24: 6 | H24: 7 | I24: 8 | J24: 9 | K24: 10 | L24: 11 | M24: 12 | N24: 13 | P24: 1 | Q24: 2 | R24: 3 | S24: 4 | T24: 5 | U24: 6 | V24: 10 | W24: 11
