Workbook
Name маг: NA()

Sheet Ялта, Ленина, 18
B1: =TODAY()-1 -> 46171
B2: (отчетная дата)
C3: Осталось до выполнения плана!!! | I3: =График!B3 -> ул. Набережная Ленина, 18
C4: =I8-D56 -> 1831975.4 | E4: =IF(I8<>0, C4/I8, 0) -> 0.42529322
D5: =C4/(I14-J14) -> #DIV/0!
F6: Целевые показатели
F7: Показатель | I7: План | J7: Факт | K7: % выполнения | L7: Прогноз выполнения | M7: % выполнения по прогнозу | N7: Отклонение | O7: Факт аналогичного месяца прошлого года | P7: Отклонение LFL
F8: Выручка | I8: =I11*I12*I13 -> 4307558.4 | J8: =D56 -> 2475583 | K8: =IF(AND(I8<>"", I8<>0, J8<>""), J8/I8, "") -> 0.57470678 | L8: =IF(SUMIF($D$25:$D$55,">=0",$P$25:$P$55)<>0,I8*D56/SUMIF($D$25:$D$55,">=0",$P$25:$P$55),0) -> 2587677.4 | M8: =IF(AND(I8<>"", I8<>0, L8<>"", L8<>0), L8/I8, "") -> 0.60072949 | N8: =IF(AND(J8<>0, J8<>"", I8<>0, I8<>""), L8-I8, "") -> -1719881 | P8: =IF(AND(O8<>"", O8<>0, L8<>"", L8<>0), -O8+L8, "") | Q8: =IF(AND(P8<>"", P8<>0, O8<>0, O8<>""), P8/O8, "")
F9: Кол-во изделий | I9: =I8/I11 -> 747.84 | J9: =E56 -> 464 | K9: =IF(AND(I9<>"", I9<>0, J9<>""), J9/I9, "") -> 0.62045357 | L9: =IF(SUMIF($E$25:$E$55, ">=0", $Q$25:$Q$55)<>0, I9*E56/SUMIF($E$25:$E$55, ">=0", $Q$25:$Q$55), 0) -> 485.00991 | M9: =IF(AND(I9<>"", I9<>0, L9<>"", L9<>0), L9/I9, "") -> 0.6485477 | N9: =IF(AND(J9<>0, J9<>"", I9<>0, I9<>""), L9-I9, "") -> -262.83009 | O9: =O8/O11 -> #DIV/0! | P9: =IF(AND(O9<>"", O9<>0, L9<>"", L9<>0), -O9+L9, "") -> #DIV/0! | Q9: =IF(AND(P9<>"", P9<>0, O9<>0, O9<>""), P9/O9, "") -> #DIV/0!
F10: Средний чек | I10: =I11*I12 -> 10944 | J10: =H56 -> 9168.8259 | K10: =IF(AND(I10<>"", I10<>0, J10<>""), J10/I10, "") -> 0.83779477 | L10: =J10 -> 9168.8259 | M10: =IF(AND(I10<>"", I10<>0, L10<>"", L10<>0), L10/I10, "") -> 0.83779477 | N10: =IF(AND(J10<>0, J10<>"", I10<>0, I10<>""), L10-I10, "") -> -1775.1741 | O10: =O11*O12 -> 0 | P10: =IF(AND(O10<>"", O10<>0, L10<>"", L10<>0), -O10+L10, "") | Q10: =IF(AND(P10<>"", P10<>0, O10<>0, O10<>""), P10/O10, "") | S10: IS
F11: Средняя стоимость изделия | I11: 5760 | J11: =F56 -> 5335.3082 | K11: =IF(AND(I11<>"", I11<>0, J11<>""), J11/I11, "") -> 0.92626878 | L11: =IF(L9>0, L8/L9, "") -> 5335.3082 | M11: =IF(AND(I11<>"", I11<>0, L11<>"", L11<>0), L11/I11, "") -> 0.92626878 | N11: =IF(AND(J11<>0, J11<>"", I11<>0, I11<>""), L11-I11, "") -> -424.69181 | P11: =IF(AND(O11<>"", O11<>0, L11<>"", L11<>0), -O11+L11, "") | Q11: =IF(AND(P11<>"", P11<>0, O11<>0, O11<>""), P11/O11, "")
F12: Длина чека | I12: 1.9 | J12: =J56 -> 1.7185185 | K12: =IF(AND(I12<>"", I12<>0, J12<>""), J12/I12, "") -> 0.90448343 | L12: =J12 -> 1.7185185 | M12: =IF(AND(I12<>"", I12<>0, L12<>"", L12<>0), L12/I12, "") -> 0.90448343 | N12: =IF(AND(J12<>0, J12<>"", I12<>0, I12<>""), L12-I12, "") -> -0.18148148 | P12: =IF(AND(O12<>"", O12<>0, L12<>"", L12<>0), -O12+L12, "") | Q12: =IF(AND(P12<>"", P12<>0, O12<>0, O12<>""), P12/O12, "") | S12: 980000 | T12: =L56 -> 438412
F13: Кол-во чеков | I13: =I17*I20 -> 393.6 | J13: =G56 -> 270 | K13: =IF(AND(I13<>"", I13<>0, J13<>""), J13/I13, "") -> 0.68597561 | L13: =IF(SUMIF($G$25:$G$55, ">=0", $R$25:$R$55)<>0, I13*G56/SUMIF($G$25:$G$55, ">=0", $R$25:$R$55), "") -> 282.2256 | M13: =IF(AND(I13<>"", I13<>0, L13<>"", L13<>0), L13/I13, "") -> 0.71703657 | N13: =IF(AND(J13<>0, J13<>"", I13<>0, I13<>""), L13-I13, "") -> -111.3744 | P13: =IF(AND(O13<>"", O13<>0, L13<>"", L13<>0), -O13+L13, "") | Q13: =IF(AND(P13<>"", P13<>0, O13<>0, O13<>""), P13/O13, "") | S13: =T12/S12 -> 0.44735918 | T13: =S13/J14*I14 -> 0.44735918
F14: Кол-во смен | I14: 30 | J14: 30 | K14: =IF(AND(I14<>"", I14<>0, J14<>""), J14/I14, "") -> 1 | L14: =I14 -> 30 | M14: =IF(AND(I14<>"", I14<>0, L14<>"", L14<>0), L14/I14, "") -> 1 | N14: =IF(AND(J14<>0, J14<>"", I14<>0, I14<>""), L14-I14, "") -> 0 | P14: =IF(AND(O14<>"", O14<>0, L14<>"", L14<>0), -O14+L14, "") | Q14: =IF(AND(P14<>"", P14<>0, O14<>0, O14<>""), P14/O14, "")
F15: Средние продажи в смену | I15: =I8/I14 -> 143585.28 | J15: =J8/J14 -> 82519.433 | K15: =IF(AND(I15<>"", I15<>0, J15<>""), J15/I15, "") -> 0.57470678 | L15: =J15 -> 82519.433 | M15: =IF(AND(I15<>"", I15<>0, L15<>"", L15<>0), L15/I15, "") -> 0.57470678 | N15: =IF(AND(J15<>0, J15<>"", I15<>0, I15<>""), L15-I15, "") -> -61065.847 | P15: =IF(AND(O15<>"", O15<>0, L15<>"", L15<>0), -O15+L15, "") | Q15: =IF(AND(P15<>"", P15<>0, O15<>0, O15<>""), P15/O15, "")
F16: Отставание/Перевыполнение | J16: =J8-I15*J14 -> -1831975.4 | K16: =IF(AND(I16<>"", I16<>0, J16<>""), J16/I16, "") | L16: =J16 -> -1831975.4 | M16: =IF(AND(I16<>"", I16<>0, L16<>"", L16<>0), L16/I16, "") | N16: =IF(AND(J16<>0, J16<>"", I16<>0, I16<>""), L16-I16, "") | P16: =IF(AND(O16<>"", O16<>0, L16<>"", L16<>0), -O16+L16, "") | Q16: =IF(AND(P16<>"", P16<>0, O16<>0, O16<>""), P16/O16, "") | S16: UNOde50
F17: Трафик | I17: 1600 | J17: =I56 -> 1342 | K17: =IF(AND(I17<>"", I17<>0, J17<>""), J17/I17, "") -> 0.83875 | L17: =J17/J14*I14 -> 1342 | M17: =IF(AND(I17<>"", I17<>0, L17<>"", L17<>0), L17/I17, "") -> 0.83875 | N17: =IF(AND(J17<>0, J17<>"", I17<>0, I17<>""), L17-I17, "") -> -258 | P17: =IF(AND(O17<>"", O17<>0, L17<>"", L17<>0), -O17+L17, "") | Q17: =IF(AND(P17<>"", P17<>0, O17<>0, O17<>""), P17/O17, "")
K18: =IF(AND(I18<>"", I18<>0, J18<>""), J18/I18, "") | L18: =J18 -> 0 | M18: =IF(AND(I18<>"", I18<>0, L18<>"", L18<>0), L18/I18, "") | N18: =IF(AND(J18<>0, J18<>"", I18<>0, I18<>""), L18-I18, "") | O18: 0 | P18: =IF(AND(O18<>"", O18<>0, L18<>"", L18<>0), -O18+L18, "") | Q18: =IF(AND(P18<>"", P18<>0, O18<>0, O18<>""), P18/O18, "") | S18: 780000 | T18: =K56 -> 348005
J19: =M56 -> 0 | K19: =IF(AND(I19<>"", I19<>0, J19<>""), J19/I19, "") | L19: =J19 -> 0 | M19: =IF(AND(I19<>"", I19<>0, L19<>"", L19<>0), L19/I19, "") | N19: =IF(AND(J19<>0, J19<>"", I19<>0, I19<>""), L19-I19, "") | O19: 0 | P19: =IF(AND(O19<>"", O19<>0, L19<>"", L19<>0), -O19+L19, "") | Q19: =IF(AND(P19<>"", P19<>0, O19<>0, O19<>""), P19/O19, "") | S19: =T18/S18 -> 0.44616026 | T19: =S19/J14*I14 -> 0.44616026
F20: Конверсия план/факт | I20: 0.246 | J20: =N56 -> 0.20119225 | K20: =J20/I20 -> 0.81785468 | L20: =IF(AND(K8<>0, I14<>0, I56<>0), (I56*N56+(I56/K8-I56)*I20)/(I56/K8), 0) -> 0.22024868 | M20: =IF(AND(I20<>"", I20<>0, L20<>"", L20<>0), L20/I20, "") -> 0.89531985 | N20: =IF(AND(J20<>0, J20<>"", I20<>0, I20<>""), L20-I20, "") -> -0.025751317 | P20: =IF(AND(O20<>"", O20<>0, L20<>"", L20<>0), -O20+L20, "") | Q20: =IF(AND(P20<>"", P20<>0, O20<>0, O20<>""), P20/O20, "")
A22: Факт продаж за месяц | O22: % выполнения дневного плана | P22: Раcпределение плана по дням
A23: Сотрудник | B23: Дата | C23: День недели | D23: Выручка (руб) | E23: Кол-во единиц (шт.) | F23: Средняя стоимость изделия (руб.) | G23: Количество чеков (шт.) | H23: Средняя сумма чека (руб.) | I23: Трафик | J23: Длина чека (шт.) | K23: UNOde50 | L23: IS | M23: Запасной | N23: Конверсия (%) | P23: выручка, план | Q23: кол-во ед, план | R23: Кол-во чеков, план | S23: выручка, скорректир.план | T23: кол-во ед, скорр. план | U23: кол-во чеков, скорр. план | V23: Коэфф. Дня Недели | W23: Специфика месяца
B24: 1 | C24: 2 | D24: 3 | E24: 4 | F24: 5 | G24: 6 | H24: 7 | I24: 8 | J24: 9 | K24: 10 | L24: 11 | M24: 12 | N24: 13 | P24: 1 | Q24: 2 | R24: 3 | S24: 4 | T24: 5 | U24: 6 | V24: 10 | W24: 11
A25: Рогалевич, Вафина | B25: 01.июня | C25: вс | D25: 24398 | E25: 3 | F25: =IF(AND(E25<>"",E25<>0),D25/E25,"") -> 8132.6667 | G25: 4 | H25: =IF(AND(G25<>"",G25<>0),D25/G25,"") -> 6099.5 | I25: 30 | J25: =IF(AND(G25<>"",G25<>0),E25/G25,"") -> 0.75 | K25: 0 | L25: 13123 | N25: =IF(AND(I25<>"",I25<>0),G25/I25,"") -> 0.13333333 | O25: =D25/P25 -> 0.19511095 | P25: =$I$8*V25*W25/SUMPRODUCT($W$25:$W$55,$V$25:$V$55) -> 125046.8 | Q25: =$I$9*V25*W25/SUMPRODUCT($W$25:$W$55,$V$25:$V$55) -> 21.709514 | R25: =IF($I$12="","",Q25/$I$12) -> 11.42606 | S25: =IF(D25<>"",D25,P25) -> 24398 | T25: =IF(E25<>"",E25,Q25) -> 3 | U25: =IF(G25<>"",G25,R25) -> 4 | V25: 0.9004852 | W25: 0.9004852
A26: Рогалевич, Вафина | B26: 02.июня | C26: пн | D26: 51870 | E26: 11 | F26: =IF(AND(E26<>"",E26<>0),D26/E26,"") -> 4715.4545 | G26: 10 | H26: =IF(AND(G26<>"",G26<>0),D26/G26,"") -> 5187 | I26: 34 | J26: =IF(AND(G26<>"",G26<>0),E26/G26,"") -> 1.1 | L26: 7903 | N26: =IF(AND(I26<>"",I26<>0),G26/I26,"") -> 0.29411765 | O26: =D26/P26 -> 0.2986827 | P26: =$I$8*V26*W26/SUMPRODUCT($W$25:$W$55,$V$25:$V$55) -> 173662.55 | Q26: =$I$9*V26*W26/SUMPRODUCT($W$25:$W$55,$V$25:$V$55) -> 30.149749 | R26: =IF($I$12="","",Q26/$I$12) -> 15.868289 | S26: =IF(W26<>"",IF(D26<>"",D26,($I$8-SUM($S$25:S25))*V26*W26/SUMPRODUCT($W26:$W$55,$V26:$V$55)),"") -> 51870 | T26: =IF(W26<>"",IF(E26<>"",E26,($I$9-SUM($T$25:T25))*V26*W26/SUMPRODUCT($W26:$W$55,$V26:$V$55)),"") -> 11 | U26: =IF(W26<>"",IF($I$12<>"",IF(G26<>"",G26,($I$9/$I$12-SUM($U$25:U25))*V26*W26/SUMPRODUCT($W26:$W$55,$V26:$V$55)),""),"") -> 10 | V26: 1.0611906 | W26: 1.0611906
A27: Рогалевич,Уразгильдеева | B27: 03.июня | C27: вт | D27: =55419+99429 -> 154848 | E27: 26 | F27: =IF(AND(E27<>"",E27<>0),D27/E27,"") -> 5955.6923 | G27: 16 | H27: =IF(AND(G27<>"",G27<>0),D27/G27,"") -> 9678 | I27: 50 | J27: =IF(AND(G27<>"",G27<>0),E27/G27,"") -> 1.625 | K27: 31472 | L27: 55419 | N27: =IF(AND(I27<>"",I27<>0),G27/I27,"") -> 0.32 | O27: =D27/P27 -> 0.69940156 | P27: =$I$8*V27*W27/SUMPRODUCT($W$25:$W$55,$V$25:$V$55) -> 221400.71 | Q27: =$I$9*V27*W27/SUMPRODUCT($W$25:$W$55,$V$25:$V$55) -> 38.437623 | R27: =IF($I$12="","",Q27/$I$12) -> 20.230328 | S27: =IF(W27<>"",IF(D27<>"",D27,($I$8-SUM($S$25:S26))*V27*W27/SUMPRODUCT($W27:$W$55,$V27:$V$55)),"") -> 154848 | T27: =IF(W27<>"",IF(E27<>"",E27,($I$9-SUM($T$25:T26))*V27*W27/SUMPRODUCT($W27:$W$55,$V27:$V$55)),"") -> 26 | U27: =IF(W27<>"",IF($I$12<>"",IF(G27<>"",G27,($I$9/$I$12-SUM($U$25:U26))*V27*W27/SUMPRODUCT($W27:$W$55,$V27:$V$55)),""),"") -> 16 | V27: 1.1982013 | W27: 1.1982013
A28: Уразгильдеева,Вафина | B28: 45812 | C28: ср | D28: =23447+21847+21069 -> 66363 | E28: 15 | F28: =IF(AND(E28<>"",E28<>0),D28/E28,"") -> 4424.2 | G28: 10 | H28: =IF(AND(G28<>"",G28<>0),D28/G28,"") -> 6636.3 | I28: 34 | J28: =IF(AND(G28<>"",G28<>0),E28/G28,"") -> 1.5 | L28: 21069 | N28: =IF(AND(I28<>"",I28<>0),G28/I28,"") -> 0.29411765 | O28: =D28/P28 -> 0.70575829 | P28: =$I$8*V28*W28/SUMPRODUCT($W$25:$W$55,$V$25:$V$55) -> 94030.777 | Q28: =$I$9*V28*W28/SUMPRODUCT($W$25:$W$55,$V$25:$V$55) -> 16.324788 | R28: =IF($I$12="","",Q28/$I$12) -> 8.5919935 | S28: =IF(W28<>"",IF(D28<>"",D28,($I$8-SUM($S$25:S27))*V28*W28/SUMPRODUCT($W28:$W$55,$V28:$V$55)),"") -> 66363 | T28: =IF(W28<>"",IF(E28<>"",E28,($I$9-SUM($T$25:T27))*V28*W28/SUMPRODUCT($W28:$W$55,$V28:$V$55)),"") -> 15 | U28: =IF(W28<>"",IF($I$12<>"",IF(G28<>"",G28,($I$9/$I$12-SUM($U$25:U27))*V28*W28/SUMPRODUCT($W28:$W$55,$V28:$V$55)),""),"") -> 10 | V28: 0.78086381 | W28: 0.78086381
A29: Рогалевич,Вафина | B29: 45813 | C29: чт | D29: =50430+46966+74930 -> 172326 | E29: 25 | F29: =IF(AND(E29<>"",E29<>0),D29/E29,"") -> 6893.04 | G29: 12 | H29: =IF(AND(G29<>"",G29<>0),D29/G29,"") -> 14360.5 | I29: 40 | J29: =IF(AND(G29<>"",G29<>0),E29/G29,"") -> 2.0833333 | L29: 74930 | N29: =IF(AND(I29<>"",I29<>0),G29/I29,"") -> 0.3 | O29: =D29/P29 -> 1.0252547 | P29: =$I$8*V29*W29/SUMPRODUCT($W$25:$W$55,$V$25:$V$55) -> 168081.15 | Q29: =$I$9*V29*W29/SUMPRODUCT($W$25:$W$55,$V$25:$V$55) -> 29.180756 | R29: =IF($I$12="","",Q29/$I$12) -> 15.358293 | S29: =IF(W29<>"",IF(D29<>"",D29,($I$8-SUM($S$25:S28))*V29*W29/SUMPRODUCT($W29:$W$55,$V29:$V$55)),"") -> 172326 | T29: =IF(W29<>"",IF(E29<>"",E29,($I$9-SUM($T$25:T28))*V29*W29/SUMPRODUCT($W29:$W$55,$V29:$V$55)),"") -> 25 | U29: =IF(W29<>"",IF($I$12<>"",IF(G29<>"",G29,($I$9/$I$12-SUM($U$25:U28))*V29*W29/SUMPRODUCT($W29:$W$55,$V29:$V$55)),""),"") -> 12 | V29: 1.0439983 | W29: 1.0439983
A30: Рогалевич,Уразгильдеева | B30: 45814 | C30: пт | D30: =18320+11992+6204+32400 -> 68916 | E30: 16 | F30: =IF(AND(E30<>"",E30<>0),D30/E30,"") -> 4307.25 | G30: 11 | H30: =IF(AND(G30<>"",G30<>0),D30/G30,"") -> 6265.0909 | I30: 60 | J30: =IF(AND(G30<>"",G30<>0),E30/G30,"") -> 1.4545455 | K30: 11992 | L30: 6204 | N30: =IF(AND(I30<>"",I30<>0),G30/I30,"") -> 0.18333333 | O30: =D30/P30 -> 0.73290897 | P30: =$I$8*V30*W30/SUMPRODUCT($W$25:$W$55,$V$25:$V$55) -> 94030.777 | Q30: =$I$9*V30*W30/SUMPRODUCT($W$25:$W$55,$V$25:$V$55) -> 16.324788 | R30: =IF($I$12="","",Q30/$I$12) -> 8.5919935 | S30: =IF(W30<>"",IF(D30<>"",D30,($I$8-SUM($S$25:S29))*V30*W30/SUMPRODUCT($W30:$W$55,$V30:$V$55)),"") -> 68916 | T30: =IF(W30<>"",IF(E30<>"",E30,($I$9-SUM($T$25:T29))*V30*W30/SUMPRODUCT($W30:$W$55,$V30:$V$55)),"") -> 16 | U30: =IF(W30<>"",IF($I$12<>"",IF(G30<>"",G30,($I$9/$I$12-SUM($U$25:U29))*V30*W30/SUMPRODUCT($W30:$W$55,$V30:$V$55)),""),"") -> 11 | V30: 0.78086381 | W30: 0.78086381
A31: Рогалевич,Уразгильдеева | B31: 45815 | C31: сб | D31: =27440+37721+7007+24012+28706 -> 124886 | E31: 23 | F31: =IF(AND(E31<>"",E31<>0),D31/E31,"") -> 5429.8261 | G31: 12 | H31: =IF(AND(G31<>"",G31<>0),D31/G31,"") -> 10407.167 | I31: 60 | J31: =IF(AND(G31<>"",G31<>0),E31/G31,"") -> 1.9166667 | K31: 24012 | L31: 28706 | N31: =IF(AND(I31<>"",I31<>0),G31/I31,"") -> 0.2 | O31: =D31/P31 -> 1.2210768 | P31: =$I$8*V31*W31/SUMPRODUCT($W$25:$W$55,$V$25:$V$55) -> 102275.3 | Q31: =$I$9*V31*W31/SUMPRODUCT($W$25:$W$55,$V$25:$V$55) -> 17.756129 | R31: =IF($I$12="","",Q31/$I$12) -> 9.3453312 | S31: =IF(W31<>"",IF(D31<>"",D31,($I$8-SUM($S$25:S30))*V31*W31/SUMPRODUCT($W31:$W$55,$V31:$V$55)),"") -> 124886 | T31: =IF(W31<>"",IF(E31<>"",E31,($I$9-SUM($T$25:T30))*V31*W31/SUMPRODUCT($W31:$W$55,$V31:$V$55)),"") -> 23 | U31: =IF(W31<>"",IF($I$12<>"",IF(G31<>"",G31,($I$9/$I$12-SUM($U$25:U30))*V31*W31/SUMPRODUCT($W31:$W$55,$V31:$V$55)),""),"") -> 12 | V31: 0.81437733 | W31: 0.81437733
A32: Рогалевич,Вафина | B32: 45816 | C32: вс | D32: =71706+39403+30909 -> 142018 | E32: 30 | F32: =IF(AND(E32<>"",E32<>0),D32/E32,"") -> 4733.9333 | G32: 18 | H32: =IF(AND(G32<>"",G32<>0),D32/G32,"") -> 7889.8889 | I32: 70 | J32: =IF(AND(G32<>"",G32<>0),E32/G32,"") -> 1.6666667 | L32: 30909 | N32: =IF(AND(I32<>"",I32<>0),G32/I32,"") -> 0.25714286 | O32: =D32/P32 -> 1.3885854 | P32: =$I$8*V32*W32/SUMPRODUCT($W$25:$W$55,$V$25:$V$55) -> 102275.3 | Q32: =$I$9*V32*W32/SUMPRODUCT($W$25:$W$55,$V$25:$V$55) -> 17.756129 | R32: =IF($I$12="","",Q32/$I$12) -> 9.3453312 | S32: =IF(W32<>"",IF(D32<>"",D32,($I$8-SUM($S$25:S31))*V32*W32/SUMPRODUCT($W32:$W$55,$V32:$V$55)),"") -> 142018 | T32: =IF(W32<>"",IF(E32<>"",E32,($I$9-SUM($T$25:T31))*V32*W32/SUMPRODUCT($W32:$W$55,$V32:$V$55)),"") -> 30 | U32: =IF(W32<>"",IF($I$12<>"",IF(G32<>"",G32,($I$9/$I$12-SUM($U$25:U31))*V32*W32/SUMPRODUCT($W32:$W$55,$V32:$V$55)),""),"") -> 18 | V32: 0.81437733 | W32: 0.81437733
A33: Рогалевич,Вафина | B33: 45817 | C33: пн | D33: =6992+13375+28057 -> 48424 | E33: 10 | F33: =IF(AND(E33<>"",E33<>0),D33/E33,"") -> 4842.4 | G33: 6 | H33: =IF(AND(G33<>"",G33<>0),D33/G33,"") -> 8070.6667 | I33: 34 | J33: =IF(AND(G33<>"",G33<>0),E33/G33,"") -> 1.6666667 | K33: 6992 | N33: =IF(AND(I33<>"",I33<>0),G33/I33,"") -> 0.17647059 | O33: =D33/P33 -> 0.47346718 | P33: =$I$8*V33*W33/SUMPRODUCT($W$25:$W$55,$V$25:$V$55) -> 102275.3 | Q33: =$I$9*V33*W33/SUMPRODUCT($W$25:$W$55,$V$25:$V$55) -> 17.756129 | R33: =IF($I$12="","",Q33/$I$12) -> 9.3453312 | S33: =IF(W33<>"",IF(D33<>"",D33,($I$8-SUM($S$25:S32))*V33*W33/SUMPRODUCT($W33:$W$55,$V33:$V$55)),"") -> 48424 | T33: =IF(W33<>"",IF(E33<>"",E33,($I$9-SUM($T$25:T32))*V33*W33/SUMPRODUCT($W33:$W$55,$V33:$V$55)),"") -> 10 | U33: =IF(W33<>"",IF($I$12<>"",IF(G33<>"",G33,($I$9/$I$12-SUM($U$25:U32))*V33*W33/SUMPRODUCT($W33:$W$55,$V33:$V$55)),""),"") -> 6 | V33: 0.81437733 | W33: 0.81437733
A34: Рогалевич,Уразгильдеева | B34: 45818 | C34: вт | D34: 67757 | E34: 16 | F34: =IF(AND(E34<>"",E34<>0),D34/E34,"") -> 4234.8125 | G34: 13 | H34: =IF(AND(G34<>"",G34<>0),D34/G34,"") -> 5212.0769 | I34: 34 | J34: =IF(AND(G34<>"",G34<>0),E34/G34,"") -> 1.2307692 | N34: =IF(AND(I34<>"",I34<>0),G34/I34,"") -> 0.38235294 | O34: =D34/P34 -> 0.43937439 | P34: =$I$8*V34*W34/SUMPRODUCT($W$25:$W$55,$V$25:$V$55) -> 154212.45 | Q34: =$I$9*V34*W34/SUMPRODUCT($W$25:$W$55,$V$25:$V$55) -> 26.772994 | R34: =IF($I$12="","",Q34/$I$12) -> 14.09105 | S34: =IF(W34<>"",IF(D34<>"",D34,($I$8-SUM($S$25:S33))*V34*W34/SUMPRODUCT($W34:$W$55,$V34:$V$55)),"") -> 67757 | T34: =IF(W34<>"",IF(E34<>"",E34,($I$9-SUM($T$25:T33))*V34*W34/SUMPRODUCT($W34:$W$55,$V34:$V$55)),"") -> 16 | U34: =IF(W34<>"",IF($I$12<>"",IF(G34<>"",G34,($I$9/$I$12-SUM($U$25:U33))*V34*W34/SUMPRODUCT($W34:$W$55,$V34:$V$55)),""),"") -> 13 | V34: 1 | W34: 1
A35: Рогалевич,Уразгильдеева | B35: 45819 | C35: ср | D35: 73975 | E35: 15 | F35: =IF(AND(E35<>"",E35<>0),D35/E35,"") -> 4931.6667 | G35: 5 | H35: =IF(AND(G35<>"",G35<>0),D35/G35,"") -> 14795 | I35: 22 | J35: =IF(AND(G35<>"",G35<>0),E35/G35,"") -> 3 | N35: =IF(AND(I35<>"",I35<>0),G35/I35,"") -> 0.22727273 | O35: =D35/P35 -> 0.66393825 | P35: =$I$8*V35*W35/SUMPRODUCT($W$25:$W$55,$V$25:$V$55) -> 111418.49 | Q35: =$I$9*V35*W35/SUMPRODUCT($W$25:$W$55,$V$25:$V$55) -> 19.343489 | R35: =IF($I$12="","",Q35/$I$12) -> 10.180783 | S35: =IF(W35<>"",IF(D35<>"",D35,($I$8-SUM($S$25:S34))*V35*W35/SUMPRODUCT($W35:$W$55,$V35:$V$55)),"") -> 73975 | T35: =IF(W35<>"",IF(E35<>"",E35,($I$9-SUM($T$25:T34))*V35*W35/SUMPRODUCT($W35:$W$55,$V35:$V$55)),"") -> 15 | U35: =IF(W35<>"",IF($I$12<>"",IF(G35<>"",G35,($I$9/$I$12-SUM($U$25:U34))*V35*W35/SUMPRODUCT($W35:$W$55,$V35:$V$55)),""),"") -> 5 | V35: 0.85 | W35: 0.85
A36: Рогалевич,Вафина | B36: 45820 | C36: чт | D36: =11977+23406+72879 -> 108262 | E36: 20 | F36: =IF(AND(E36<>"",E36<>0),D36/E36,"") -> 5413.1 | G36: 11 | H36: =IF(AND(G36<>"",G36<>0),D36/G36,"") -> 9842 | I36: 60 | J36: =IF(AND(G36<>"",G36<>0),E36/G36,"") -> 1.8181818 | L36: 23406 | N36: =IF(AND(I36<>"",I36<>0),G36/I36,"") -> 0.18333333 | O36: =D36/P36 -> 0.97166993 | P36: =$I$8*V36*W36/SUMPRODUCT($W$25:$W$55,$V$25:$V$55) -> 111418.49 | Q36: =$I$9*V36*W36/SUMPRODUCT($W$25:$W$55,$V$25:$V$55) -> 19.343489 | R36: =IF($I$12="","",Q36/$I$12) -> 10.180783 | S36: =IF(W36<>"",IF(D36<>"",D36,($I$8-SUM($S$25:S35))*V36*W36/SUMPRODUCT($W36:$W$55,$V36:$V$55)),"") -> 108262 | T36: =IF(W36<>"",IF(E36<>"",E36,($I$9-SUM($T$25:T35))*V36*W36/SUMPRODUCT($W36:$W$55,$V36:$V$55)),"") -> 20 | U36: =IF(W36<>"",IF($I$12<>"",IF(G36<>"",G36,($I$9/$I$12-SUM($U$25:U35))*V36*W36/SUMPRODUCT($W36:$W$55,$V36:$V$55)),""),"") -> 11 | V36: 0.85 | W36: 0.85
A37: Уразгильдеева,Вафина | B37: 45821 | C37: пт | D37: =58494+61275+30327+4092 -> 154188 | E37: 32 | F37: =IF(AND(E37<>"",E37<>0),D37/E37,"") -> 4818.375 | G37: 12 | H37: =IF(AND(G37<>"",G37<>0),D37/G37,"") -> 12849 | I37: 100 | J37: =IF(AND(G37<>"",G37<>0),E37/G37,"") -> 2.6666667 | K37: 4092 | L37: 30327 | N37: =IF(AND(I37<>"",I37<>0),G37/I37,"") -> 0.12 | O37: =D37/P37 -> 1.3838636 | P37: =$I$8*V37*W37/SUMPRODUCT($W$25:$W$55,$V$25:$V$55) -> 111418.49 | Q37: =$I$9*V37*W37/SUMPRODUCT($W$25:$W$55,$V$25:$V$55) -> 19.343489 | R37: =IF($I$12="","",Q37/$I$12) -> 10.180783 | S37: =IF(W37<>"",IF(D37<>"",D37,($I$8-SUM($S$25:S36))*V37*W37/SUMPRODUCT($W37:$W$55,$V37:$V$55)),"") -> 154188 | T37: =IF(W37<>"",IF(E37<>"",E37,($I$9-SUM($T$25:T36))*V37*W37/SUMPRODUCT($W37:$W$55,$V37:$V$55)),"") -> 32 | U37: =IF(W37<>"",IF($I$12<>"",IF(G37<>"",G37,($I$9/$I$12-SUM($U$25:U36))*V37*W37/SUMPRODUCT($W37:$W$55,$V37:$V$55)),""),"") -> 12 | V37: 0.85 | W37: 0.85
A38: Рогалевич,Уразгильдеева | B38: 45822 | C38: сб | D38: =45393+7503+70459+8993 -> 132348 | E38: 29 | F38: =IF(AND(E38<>"",E38<>0),D38/E38,"") -> 4563.7241 | G38: 16 | H38: =IF(AND(G38<>"",G38<>0),D38/G38,"") -> 8271.75 | I38: 60 | J38: =IF(AND(G38<>"",G38<>0),E38/G38,"") -> 1.8125 | K38: 8993 | L38: 7503 | N38: =IF(AND(I38<>"",I38<>0),G38/I38,"") -> 0.26666667 | O38: =D38/P38 -> 1.1878459 | P38: =$I$8*V38*W38/SUMPRODUCT($W$25:$W$55,$V$25:$V$55) -> 111418.49 | Q38: =$I$9*V38*W38/SUMPRODUCT($W$25:$W$55,$V$25:$V$55) -> 19.343489 | R38: =IF($I$12="","",Q38/$I$12) -> 10.180783 | S38: =IF(W38<>"",IF(D38<>"",D38,($I$8-SUM($S$25:S37))*V38*W38/SUMPRODUCT($W38:$W$55,$V38:$V$55)),"") -> 132348 | T38: =IF(W38<>"",IF(E38<>"",E38,($I$9-SUM($T$25:T37))*V38*W38/SUMPRODUCT($W38:$W$55,$V38:$V$55)),"") -> 29 | U38: =IF(W38<>"",IF($I$12<>"",IF(G38<>"",G38,($I$9/$I$12-SUM($U$25:U37))*V38*W38/SUMPRODUCT($W38:$W$55,$V38:$V$55)),""),"") -> 16 | V38: 0.85 | W38: 0.85
A39: Рогалевич,Вафина | B39: 45823 | C39: вс | D39: =21526+4092+36910+40831 -> 103359 | E39: 23 | F39: =IF(AND(E39<>"",E39<>0),D39/E39,"") -> 4493.8696 | G39: 13 | H39: =IF(AND(G39<>"",G39<>0),D39/G39,"") -> 7950.6923 | I39: 50 | J39: =IF(AND(G39<>"",G39<>0),E39/G39,"") -> 1.7692308 | K39: 4092 | L39: 21526 | N39: =IF(AND(I39<>"",I39<>0),G39/I39,"") -> 0.26 | O39: =D39/P39 -> 0.92766467 | P39: =$I$8*V39*W39/SUMPRODUCT($W$25:$W$55,$V$25:$V$55) -> 111418.49 | Q39: =$I$9*V39*W39/SUMPRODUCT($W$25:$W$55,$V$25:$V$55) -> 19.343489 | R39: =IF($I$12="","",Q39/$I$12) -> 10.180783 | S39: =IF(W39<>"",IF(D39<>"",D39,($I$8-SUM($S$25:S38))*V39*W39/SUMPRODUCT($W39:$W$55,$V39:$V$55)),"") -> 103359 | T39: =IF(W39<>"",IF(E39<>"",E39,($I$9-SUM($T$25:T38))*V39*W39/SUMPRODUCT($W39:$W$55,$V39:$V$55)),"") -> 23 | U39: =IF(W39<>"",IF($I$12<>"",IF(G39<>"",G39,($I$9/$I$12-SUM($U$25:U38))*V39*W39/SUMPRODUCT($W39:$W$55,$V39:$V$55)),""),"") -> 13 | V39: 0.85 | W39: 0.85
A40: Уразгильдеева,Вафина | B40: 45824 | C40: пн | D40: =18503+7993+4893 -> 31389 | E40: 3 | F40: =IF(AND(E40<>"",E40<>0),D40/E40,"") -> 10463 | G40: 3 | H40: =IF(AND(G40<>"",G40<>0),D40/G40,"") -> 10463 | I40: 32 | J40: =IF(AND(G40<>"",G40<>0),E40/G40,"") -> 1 | L40: 18503 | N40: =IF(AND(I40<>"",I40<>0),G40/I40,"") -> 0.09375 | O40: =D40/P40 -> 0.20354388 | P40: =$I$8*V40*W40/SUMPRODUCT($W$25:$W$55,$V$25:$V$55) -> 154212.45 | Q40: =$I$9*V40*W40/SUMPRODUCT($W$25:$W$55,$V$25:$V$55) -> 26.772994 | R40: =IF($I$12="","",Q40/$I$12) -> 14.09105 | S40: =IF(W40<>"",IF(D40<>"",D40,($I$8-SUM($S$25:S39))*V40*W40/SUMPRODUCT($W40:$W$55,$V40:$V$55)),"") -> 31389 | T40: =IF(W40<>"",IF(E40<>"",E40,($I$9-SUM($T$25:T39))*V40*W40/SUMPRODUCT($W40:$W$55,$V40:$V$55)),"") -> 3 | U40: =IF(W40<>"",IF($I$12<>"",IF(G40<>"",G40,($I$9/$I$12-SUM($U$25:U39))*V40*W40/SUMPRODUCT($W40:$W$55,$V40:$V$55)),""),"") -> 3 | V40: 1 | W40: 1
A41: Рогалевич,Уразгильдеева | B41: 45825 | C41: вт | D41: 58057 | E41: 14 | F41: =IF(AND(E41<>"",E41<>0),D41/E41,"") -> 4146.9286 | G41: 7 | H41: =IF(AND(G41<>"",G41<>0),D41/G41,"") -> 8293.8571 | I41: 40 | J41: =IF(AND(G41<>"",G41<>0),E41/G41,"") -> 2 | N41: =IF(AND(I41<>"",I41<>0),G41/I41,"") -> 0.175 | O41: =D41/P41 -> 0.31113566 | P41: =$I$8*V41*W41/SUMPRODUCT($W$25:$W$55,$V$25:$V$55) -> 186597.06 | Q41: =$I$9*V41*W41/SUMPRODUCT($W$25:$W$55,$V$25:$V$55) -> 32.395323 | R41: =IF($I$12="","",Q41/$I$12) -> 17.05017 | S41: =IF(W41<>"",IF(D41<>"",D41,($I$8-SUM($S$25:S40))*V41*W41/SUMPRODUCT($W41:$W$55,$V41:$V$55)),"") -> 58057 | T41: =IF(W41<>"",IF(E41<>"",E41,($I$9-SUM($T$25:T40))*V41*W41/SUMPRODUCT($W41:$W$55,$V41:$V$55)),"") -> 14 | U41: =IF(W41<>"",IF($I$12<>"",IF(G41<>"",G41,($I$9/$I$12-SUM($U$25:U40))*V41*W41/SUMPRODUCT($W41:$W$55,$V41:$V$55)),""),"") -> 7 | V41: 1.1 | W41: 1.1
...

Sheet Св. по пок.
A2: Показатель | D2: ='Ялта, Ленина, 18'!I3 -> ул. Набережная Ленина, 18 | G2: =График!B29 -> Рогалевич Ирина | J2: =График!B28 -> Уразгильдеева Екатерина | M2: =График!B27 -> Вафина Ляйсан
D3: Факт | F3: Прогноз | G3: Факт | I3: Прогноз | J3: Факт | L3: Прогноз | M3: Факт | O3: Прогноз
A4: Выручка | D4: ='Ялта, Ленина, 18'!K8 -> 0.57470678 | E4: ='Ялта, Ленина, 18'!J8 -> 2475583 | F4: ='Ялта, Ленина, 18'!M8 -> 0.60072949 | G4: ='Рогалевич И. Е.'!K8 -> 0.74993752 | H4: ='Рогалевич И. Е.'!J8 -> 1260025 | I4: ='Рогалевич И. Е.'!M8 -> 0.80993252 | J4: ='Уразгильдеева Е. Р.'!K8 -> 0.46508752 | K4: ='Уразгильдеева Е. Р.'!J8 -> 545426 | L4: ='Уразгильдеева Е. Р.'!M8 -> 0.57868282 | M4: ='Вафина Л. Ф.'!K8 -> 0.4603393 | N4: ='Вафина Л. Ф.'!J8 -> 420466 | O4: ='Вафина Л. Ф.'!M8 -> 0.70009935
A5: Кол-во изделий | D5: ='Ялта, Ленина, 18'!K9 -> 0.62045357 | E5: ='Ялта, Ленина, 18'!J9 -> 464 | F5: ='Ялта, Ленина, 18'!M9 -> 0.6485477 | G5: ='Рогалевич И. Е.'!K9 -> 0.771349 | H5: ='Рогалевич И. Е.'!J9 -> 225 | I5: ='Рогалевич И. Е.'!M9 -> 0.83305692 | J5: ='Уразгильдеева Е. Р.'!K9 -> 0.52062761 | K5: ='Уразгильдеева Е. Р.'!J9 -> 106 | L5: ='Уразгильдеева Е. Р.'!M9 -> 0.52062761 | M5: ='Вафина Л. Ф.'!K9 -> 0.54233559 | N5: ='Вафина Л. Ф.'!J9 -> 86 | O5: ='Вафина Л. Ф.'!M9 -> 0.76768279
A6: Средний чек | D6: ='Ялта, Ленина, 18'!K10 -> 0.83779477 | E6: ='Ялта, Ленина, 18'!J10 -> 9168.8259 | F6: ='Ялта, Ленина, 18'!M10 -> 0.83779477 | G6: ='Рогалевич И. Е.'!K10 -> 0.87222624 | H6: ='Рогалевич И. Е.'!J10 -> 9545.6439 | I6: ='Рогалевич И. Е.'!M10 -> 0.87222624 | J6: ='Уразгильдеева Е. Р.'!K10 -> 0.76673695 | K6: ='Уразгильдеева Е. Р.'!J10 -> 8391.1692 | L6: ='Уразгильдеева Е. Р.'!M10 -> 0.76673695 | M6: ='Вафина Л. Ф.'!K10 -> 0.83521247 | N6: ='Вафина Л. Ф.'!J10 -> 9140.5652 | O6: ='Вафина Л. Ф.'!M10 -> 0.83521247
A7: Средняя стоимость изделия | D7: ='Ялта, Ленина, 18'!K11 -> 0.92626878 | E7: ='Ялта, Ленина, 18'!J11 -> 5335.3082 | F7: ='Ялта, Ленина, 18'!M11 -> 0.92626878 | G7: ='Рогалевич И. Е.'!K11 -> 0.97224151 | H7: ='Рогалевич И. Е.'!J11 -> 5600.1111 | I7: ='Рогалевич И. Е.'!M11 -> 0.97224151 | J7: ='Уразгильдеева Е. Р.'!K11 -> 0.89332089 | K7: ='Уразгильдеева Е. Р.'!J11 -> 5145.5283 | L7: ='Уразгильдеева Е. Р.'!M11 -> 0.89332089 | M7: ='Вафина Л. Ф.'!K11 -> 0.84880895 | N7: ='Вафина Л. Ф.'!J11 -> 4889.1395 | O7: ='Вафина Л. Ф.'!M11 -> 0.91196437
A8: Длина чека | D8: ='Ялта, Ленина, 18'!K12 -> 0.90448343 | E8: ='Ялта, Ленина, 18'!J12 -> 1.7185185 | F8: ='Ялта, Ленина, 18'!M12 -> 0.90448343 | G8: ='Рогалевич И. Е.'!K12 -> 0.89712919 | H8: ='Рогалевич И. Е.'!J12 -> 1.7045455 | I8: ='Рогалевич И. Е.'!M12 -> 0.89712919 | J8: ='Уразгильдеева Е. Р.'!K12 -> 0.8582996 | K8: ='Уразгильдеева Е. Р.'!J12 -> 1.6307692 | L8: ='Уразгильдеева Е. Р.'!M12 -> 0.8582996 | M8: ='Вафина Л. Ф.'!K12 -> 0.98398169 | N8: ='Вафина Л. Ф.'!J12 -> 1.8695652 | O8: ='Вафина Л. Ф.'!M12 -> 0.98398169
A9: Кол-во чеков | D9: ='Ялта, Ленина, 18'!K13 -> 0.68597561 | E9: ='Ялта, Ленина, 18'!J13 -> 270 | F9: ='Ялта, Ленина, 18'!M13 -> 0.71703657 | G9: ='Рогалевич И. Е.'!K13 -> 0.85979702 | H9: ='Рогалевич И. Е.'!J13 -> 132 | I9: ='Рогалевич И. Е.'!M13 -> 0.92858078 | J9: ='Уразгильдеева Е. Р.'!K13 -> 0.60658028 | K9: ='Уразгильдеева Е. Р.'!J13 -> 65 | L9: ='Уразгильдеева Е. Р.'!M13 -> 0.60658028 | M9: ='Вафина Л. Ф.'!K13 -> 0.55116431 | N9: ='Вафина Л. Ф.'!J13 -> 46 | O9: ='Вафина Л. Ф.'!M13 -> 0.78017995
A10: Кол-во смен план/отработано | D10: ='Ялта, Ленина, 18'!K14 -> 1 | E10: ='Ялта, Ленина, 18'!J14 -> 30 | G10: ='Рогалевич И. Е.'!K14 -> 1 | H10: ='Рогалевич И. Е.'!J14 -> 25 | J10: ='Уразгильдеева Е. Р.'!K14 -> 1 | K10: ='Уразгильдеева Е. Р.'!J14 -> 16 | M10: ='Вафина Л. Ф.'!K14 -> 1 | N10: ='Вафина Л. Ф.'!J14 -> 13
A11: Средние продажи в смену | D11: ='Ялта, Ленина, 18'!K15 -> 0.57470678 | E11: ='Ялта, Ленина, 18'!J15 -> 82519.433 | F11: ='Ялта, Ленина, 18'!M15 -> 0.57470678 | G11: ='Рогалевич И. Е.'!K15 -> 0.35101788 | H11: ='Рогалевич И. Е.'!J15 -> 50401 | I11: ='Рогалевич И. Е.'!M15 -> 0.35101788 | J11: ='Уразгильдеева Е. Р.'!K15 -> 0.23741379 | K11: ='Уразгильдеева Е. Р.'!J15 -> 34089.125 | L11: ='Уразгильдеева Е. Р.'!M15 -> 0.23741379 | M11: ='Вафина Л. Ф.'!K15 -> 0.22525665 | N11: ='Вафина Л. Ф.'!J15 -> 32343.538 | O11: ='Вафина Л. Ф.'!M15 -> 0.22525665
A12: Трафик | D12: ='Ялта, Ленина, 18'!K17 -> 0.83875 | E12: ='Ялта, Ленина, 18'!J17 -> 1342 | F12: ='Ялта, Ленина, 18'!M17 -> 0.83875 | G12: ='Рогалевич И. Е.'!K17 -> 0.84924497 | H12: ='Рогалевич И. Е.'!J17 -> 530 | I12: ='Рогалевич И. Е.'!M17 -> 0.84924497 | J12: ='Уразгильдеева Е. Р.'!K17 -> 0.83332933 | K12: ='Уразгильдеева Е. Р.'!J17 -> 363 | L12: ='Уразгильдеева Е. Р.'!M17 -> 0.83332933 | M12: ='Вафина Л. Ф.'!K17 -> 0.88425926 | N12: ='Вафина Л. Ф.'!J17 -> 300 | O12: ='Вафина Л. Ф.'!M17 -> 0.88425926
A13: UNOde50 | D13: ='Ялта, Ленина, 18'!S19 -> 0.44616026 | E13: ='Ялта, Ленина, 18'!T18 -> 348005 | F13: ='Ялта, Ленина, 18'!T19 -> 0.44616026 | G13: ='Рогалевич И. Е.'!S19 -> 0.49913746 | H13: ='Рогалевич И. Е.'!T18 -> 151858 | I13: ='Рогалевич И. Е.'!T19 -> 0.49913746 | J13: ='Уразгильдеева Е. Р.'!S19 -> 0.6127587 | K13: ='Уразгильдеева Е. Р.'!T18 -> 130123 | L13: ='Уразгильдеева Е. Р.'!T19 -> 0.6127587 | M13: ='Вафина Л. Ф.'!S19 -> 0.049482241 | N13: ='Вафина Л. Ф.'!T18 -> 8184 | O13: ='Вафина Л. Ф.'!T19 -> 0.049482241
A14: IS | D14: ='Ялта, Ленина, 18'!S13 -> 0.44735918 | E14: ='Ялта, Ленина, 18'!T12 -> 438412 | F14: ='Ялта, Ленина, 18'!T13 -> 0.44735918 | G14: ='Рогалевич И. Е.'!S13 -> 0.68071448 | H14: ='Рогалевич И. Е.'!T12 -> 260204 | I14: ='Рогалевич И. Е.'!T13 -> 0.68071448 | J14: ='Уразгильдеева Е. Р.'!S13 -> 0.17502586 | K14: ='Уразгильдеева Е. Р.'!T12 -> 46698 | L14: ='Уразгильдеева Е. Р.'!T13 -> 0.17502586 | M14: ='Вафина Л. Ф.'!S13 -> 0.52023318 | N14: ='Вафина Л. Ф.'!T12 -> 108105 | O14: ='Вафина Л. Ф.'!T13 -> 0.52023318
A15: Отклонение от плана | D15: ='Ялта, Ленина, 18'!J16 -> -1831975.4 | G15: ='Рогалевич И. Е.'!N8 -> -319346.3 | J15: ='Уразгильдеева Е. Р.'!N8 -> -494094.84 | M15: ='Вафина Л. Ф.'!N8 -> -273924.09
A37: Показатель | D37: ='Ялта, Ленина, 18'!I38 -> 60 | G37: =График!B64 -> 0 | J37: =График!B63 -> 0 | M37: =График!B62 -> 0
D38: Факт | F38: Прогноз | G38: Факт | I38: Прогноз | J38: Факт | L38: Прогноз | M38: Факт | O38: Прогноз
A39: Выручка | D39: ='Ялта, Ленина, 18'!K43 -> 0 | E39: ='Ялта, Ленина, 18'!J43 -> 1.3333333 | F39: ='Ялта, Ленина, 18'!M43 -> 0 | G39: ='Рогалевич И. Е.'!K43 -> 8881 | H39: ='Рогалевич И. Е.'!J43 -> 1.3333333 | I39: ='Рогалевич И. Е.'!M43 -> 0 | J39: ='Уразгильдеева Е. Р.'!K43 -> 0 | K39: ='Уразгильдеева Е. Р.'!J43 | L39: ='Уразгильдеева Е. Р.'!M43 -> 0 | M39: ='Вафина Л. Ф.'!K43 -> 0 | N39: ='Вафина Л. Ф.'!J43 | O39: ='Вафина Л. Ф.'!M43 -> 0
A40: Кол-во изделий | D40: ='Ялта, Ленина, 18'!K44 -> 0 | E40: ='Ялта, Ленина, 18'!J44 -> 1.25 | F40: ='Ялта, Ленина, 18'!M44 -> 0 | G40: ='Рогалевич И. Е.'!K44 -> 24990 | H40: ='Рогалевич И. Е.'!J44 -> 1 | I40: ='Рогалевич И. Е.'!M44 -> 0 | J40: ='Уразгильдеева Е. Р.'!K44 -> 0 | K40: ='Уразгильдеева Е. Р.'!J44 | L40: ='Уразгильдеева Е. Р.'!M44 -> 0 | M40: ='Вафина Л. Ф.'!K44 -> 0 | N40: ='Вафина Л. Ф.'!J44 -> 1 | O40: ='Вафина Л. Ф.'!M44 -> 0
A41: Средний чек | D41: ='Ялта, Ленина, 18'!K45 -> 6993 | E41: ='Ялта, Ленина, 18'!J45 -> 1.8333333 | F41: ='Ялта, Ленина, 18'!M45 -> 0 | G41: ='Рогалевич И. Е.'!K45 -> 0 | H41: ='Рогалевич И. Е.'!J45 -> 1.6666667 | I41: ='Рогалевич И. Е.'!M45 -> 0 | J41: ='Уразгильдеева Е. Р.'!K45 -> 0 | K41: ='Уразгильдеева Е. Р.'!J45 | L41: ='Уразгильдеева Е. Р.'!M45 -> 0 | M41: ='Вафина Л. Ф.'!K45 -> 0 | N41: ='Вафина Л. Ф.'!J45 -> 1 | O41: ='Вафина Л. Ф.'!M45 -> 0
A42: Средняя стоимость изделия | D42: ='Ялта, Ленина, 18'!K46 -> 0 | E42: ='Ялта, Ленина, 18'!J46 -> 2.0769231 | F42: ='Ялта, Ленина, 18'!M46 -> 0 | G42: ='Рогалевич И. Е.'!K46 -> 46004 | H42: ='Рогалевич И. Е.'!J46 -> 1.8 | I42: ='Рогалевич И. Е.'!M46 -> 0 | J42: ='Уразгильдеева Е. Р.'!K46 -> 0 | K42: ='Уразгильдеева Е. Р.'!J46 -> 1 | L42: ='Уразгильдеева Е. Р.'!M46 -> 0 | M42: ='Вафина Л. Ф.'!K46 -> 0 | N42: ='Вафина Л. Ф.'!J46 -> 2 | O42: ='Вафина Л. Ф.'!M46 -> 0
A43: Длина чека | D43: ='Ялта, Ленина, 18'!K47 -> 82832 | E43: ='Ялта, Ленина, 18'!J47 -> 1.7142857 | F43: ='Ялта, Ленина, 18'!M47 -> 0 | G43: ='Рогалевич И. Е.'!K47 -> 0 | H43: ='Рогалевич И. Е.'!J47 -> 3.3333333 | I43: ='Рогалевич И. Е.'!M47 -> 0 | J43: ='Уразгильдеева Е. Р.'!K47 -> 0 | K43: ='Уразгильдеева Е. Р.'!J47 | L43: ='Уразгильдеева Е. Р.'!M47 -> 0 | M43: ='Вафина Л. Ф.'!K47 -> 0 | N43: ='Вафина Л. Ф.'!J47 -> 1 | O43: ='Вафина Л. Ф.'!M47 -> 0
A44: Кол-во чеков | D44: ='Ялта, Ленина, 18'!K48 -> 59858 | E44: ='Ялта, Ленина, 18'!J48 -> 1.5714286 | F44: ='Ялта, Ленина, 18'!M48 -> 0 | G44: ='Рогалевич И. Е.'!K48 -> 24993 | H44: ='Рогалевич И. Е.'!J48 -> 1.3333333 | I44: ='Рогалевич И. Е.'!M48 -> 0 | J44: ='Уразгильдеева Е. Р.'!K48 -> 0 | K44: ='Уразгильдеева Е. Р.'!J48 | L44: ='Уразгильдеева Е. Р.'!M48 -> 0 | M44: ='Вафина Л. Ф.'!K48 -> 8184 | N44: ='Вафина Л. Ф.'!J48 -> 1.8695652 | O44: ='Вафина Л. Ф.'!M48 -> 0
A45: Кол-во смен план/отработано | D45: ='Ялта, Ленина, 18'!K49 -> 24990 | E45: ='Ялта, Ленина, 18'!J49 -> 1 | G45: ='Рогалевич И. Е.'!K49 -> 0 | H45: ='Рогалевич И. Е.'!J49 -> 1 | J45: ='Уразгильдеева Е. Р.'!K49 -> 0 | K45: ='Уразгильдеева Е. Р.'!J49 | M45: ='Вафина Л. Ф.'!K49 -> 0 | N45: ='Вафина Л. Ф.'!J49 -> 0
A46: Средние продажи в смену | D46: ='Ялта, Ленина, 18'!K50 -> 0 | E46: ='Ялта, Ленина, 18'!J50 -> 1.7 | F46: ='Ялта, Ленина, 18'!M50 -> 0 | G46: ='Рогалевич И. Е.'!K50 -> 0 | H46: ='Рогалевич И. Е.'!J50 | I46: ='Рогалевич И. Е.'!M50 -> 0 | J46: ='Уразгильдеева Е. Р.'!K50 -> 130123 | K46: ='Уразгильдеева Е. Р.'!J50 -> 1.6307692 | L46: ='Уразгильдеева Е. Р.'!M50 -> 0 | M46: ='Вафина Л. Ф.'!K50 -> 0 | N46: ='Вафина Л. Ф.'!J50 -> 0 | O46: ='Вафина Л. Ф.'!M50 -> 0
A47: Трафик | D47: ='Ялта, Ленина, 18'!K52 -> 0 | E47: ='Ялта, Ленина, 18'!J52 -> 2.6 | F47: ='Ялта, Ленина, 18'!M52 -> 0 | G47: ='Рогалевич И. Е.'!K52 -> 0 | H47: ='Рогалевич И. Е.'!J52 -> 2 | I47: ='Рогалевич И. Е.'!M52 -> 0 | J47: ='Уразгильдеева Е. Р.'!K52 -> 0 | K47: ='Уразгильдеева Е. Р.'!J52 -> 0 | L47: ='Уразгильдеева Е. Р.'!M52 -> 0 | M47: ='Вафина Л. Ф.'!K52 -> 0 | N47: ='Вафина Л. Ф.'!J52 -> 0 | O47: ='Вафина Л. Ф.'!M52 -> 0
A48: UNOde50 | D48: ='Ялта, Ленина, 18'!S54 -> 36363 | E48: ='Ялта, Ленина, 18'!T53 -> 11 | F48: ='Ялта, Ленина, 18'!T54 -> 7 | G48: ='Рогалевич И. Е.'!S54 -> 1680173.3 | H48: ='Рогалевич И. Е.'!T53 | I48: ='Рогалевич И. Е.'!T54 -> 291.69675 | J48: ='Уразгильдеева Е. Р.'!S54 -> 0 | K48: ='Уразгильдеева Е. Р.'!T53 -> 0 | L48: ='Уразгильдеева Е. Р.'!T54 -> 0 | M48: ='Вафина Л. Ф.'!S54 -> 0 | N48: ='Вафина Л. Ф.'!T53 -> 0 | O48: ='Вафина Л. Ф.'!T54 -> 0
A49: IS | D49: ='Ялта, Ленина, 18'!S48 -> 100569 | E49: ='Ялта, Ленина, 18'!T47 -> 12 | F49: ='Ялта, Ленина, 18'!T48 -> 11 | G49: ='Рогалевич И. Е.'!S48 -> 54425 | H49: ='Рогалевич И. Е.'!T47 -> 10 | I49: ='Рогалевич И. Е.'!T48 -> 8 | J49: ='Уразгильдеева Е. Р.'!S48 | K49: ='Уразгильдеева Е. Р.'!T47 | L49: ='Уразгильдеева Е. Р.'!T48 | M49: ='Вафина Л. Ф.'!S48 -> 839601.54 | N49: ='Вафина Л. Ф.'!T47 | O49: ='Вафина Л. Ф.'!T48 -> 149.92006
A50: Отклонение от плана | D50: ='Ялта, Ленина, 18'!J51 -> 1.7 | G50: ='Рогалевич И. Е.'!N43 -> 0.15 | J50: ='Уразгильдеева Е. Р.'!N43 | M50: ='Вафина Л. Ф.'!N43

Sheet План на день
A1: Выручка | D1: 154212
A2: Кол-во изделий | D2: =D1/D4 -> 26.772917
A3: Средний чек | D3: =D4*D5 -> 10944
A4: Средняя стоимость изделия | D4: ='Ялта, Ленина, 18'!I11 -> 5760
A5: Длина чека | D5: ='Ялта, Ленина, 18'!I12 -> 1.9
A6: Кол-во чеков | D6: =IF(D5<>0,D2/D5,"") -> 14.091009
A7: Конверсия | D7: ='Ялта, Ленина, 18'!I20 -> 0.246
A8: IS | D8: =('Ялта, Ленина, 18'!S12-'Ялта, Ленина, 18'!T12)/('Ялта, Ленина, 18'!I14-'Ялта, Ленина, 18'!J14) -> #DIV/0!
A9: UNOde50 | D9: =('Ялта, Ленина, 18'!S18-'Ялта, Ленина, 18'!T18)/('Ялта, Ленина, 18'!I14-'Ялта, Ленина, 18'!J14) -> #DIV/0!

Sheet Рогалевич И. Е.
B1: =TODAY()-1 -> 46171
B2: (отчетная дата) | J2: ЕЖЕДНЕВНЫЙ ОТЧЕТ О ПРОДАЖАХ
B3: Осталось до выполнения плана!!! | J3: =График!B29 -> Рогалевич Ирина
C4: =I8-D54 -> 420148.3 | E4: =IF(I8<>0,C4/I8,0) -> 0.25006248
F6: Целевые показатели
F7: Показатель | I7: План | J7: Факт | K7: % выполнения | L7: Прогноз выполнения | M7: % выполнения по прогнозу | N7: Отклонение | O7: Факт аналогичного месяца прошлого года | P7: Отклонение LFL
F8: Выручка | I8: ='Ялта, Ленина, 18'!I8/График!AJ31*График!AJ29 -> 1680173.3 | J8: =D54 -> 1260025 | K8: =IF(AND(I8<>"",I8<>0,J8<>""),J8/I8,"") -> 0.74993752 | L8: =IF(SUMIF($D$25:$D$53,">=0",$P$25:$P$53)<>0,I8*D54/SUMIF($D$25:$D$53,">=0",$P$25:$P$53),0) -> 1360827 | M8: =IF(AND(I8<>"",I8<>0,L8<>"",L8<>0),L8/I8,"") -> 0.80993252 | N8: =IF(AND(J8<>0,J8<>"",I8<>0,I8<>""),L8-I8,"") -> -319346.3 | P8: =IF(AND(O8<>"",O8<>0,L8<>"",L8<>0),-O8+L8,"") | Q8: =IF(AND(P8<>"",P8<>0,O8<>0,O8<>""),P8/O8,"")
F9: Кол-во изделий | I9: =I8/I11 -> 291.69675 | J9: =E54 -> 225 | K9: =IF(AND(I9<>"",I9<>0,J9<>""),J9/I9,"") -> 0.771349 | L9: =IF(SUMIF($E$25:$E$51,">=0",$Q$25:$Q$51)<>0,I9*E54/SUMIF($E$25:$E$51,">=0",$Q$25:$Q$51),0) -> 243 | M9: =IF(AND(I9<>"",I9<>0,L9<>"",L9<>0),L9/I9,"") -> 0.83305692 | N9: =IF(AND(J9<>0,J9<>"",I9<>0,I9<>""),L9-I9,"") -> -48.696754 | O9: =O8/O11 -> #DIV/0! | P9: =IF(AND(O9<>"",O9<>0,L9<>"",L9<>0),-O9+L9,"") -> #DIV/0! | Q9: =IF(AND(P9<>"",P9<>0,O9<>0,O9<>""),P9/O9,"") -> #DIV/0!
F10: Средний чек | I10: =I11*I12 -> 10944 | J10: =H54 -> 9545.6439 | K10: =IF(AND(I10<>"",I10<>0,J10<>""),J10/I10,"") -> 0.87222624 | L10: =J10 -> 9545.6439 | M10: =IF(AND(I10<>"",I10<>0,L10<>"",L10<>0),L10/I10,"") -> 0.87222624 | N10: =IF(AND(J10<>0,J10<>"",I10<>0,I10<>""),L10-I10,"") -> -1398.3561 | O10: =O11*O12 -> 0 | P10: =IF(AND(O10<>"",O10<>0,L10<>"",L10<>0),-O10+L10,"") | Q10: =IF(AND(P10<>"",P10<>0,O10<>0,O10<>""),P10/O10,"") | S10: IS
F11: Средняя стоимость изделия | I11: ='Ялта, Ленина, 18'!I11 -> 5760 | J11: =F54 -> 5600.1111 | K11: =IF(AND(I11<>"",I11<>0,J11<>""),J11/I11,"") -> 0.97224151 | L11: =IF(L9>0,L8/L9,"") -> 5600.1111 | M11: =IF(AND(I11<>"",I11<>0,L11<>"",L11<>0),L11/I11,"") -> 0.97224151 | N11: =IF(AND(J11<>0,J11<>"",I11<>0,I11<>""),L11-I11,"") -> -159.88889 | P11: =IF(AND(O11<>"",O11<>0,L11<>"",L11<>0),-O11+L11,"") | Q11: =IF(AND(P11<>"",P11<>0,O11<>0,O11<>""),P11/O11,"")
F12: Длина чека | I12: ='Ялта, Ленина, 18'!I12 -> 1.9 | J12: =J54 -> 1.7045455 | K12: =IF(AND(I12<>"",I12<>0,J12<>""),J12/I12,"") -> 0.89712919 | L12: =J12 -> 1.7045455 | M12: =IF(AND(I12<>"",I12<>0,L12<>"",L12<>0),L12/I12,"") -> 0.89712919 | N12: =IF(AND(J12<>0,J12<>"",I12<>0,I12<>""),L12-I12,"") -> -0.19545455 | P12: =IF(AND(O12<>"",O12<>0,L12<>"",L12<>0),-O12+L12,"") | Q12: =IF(AND(P12<>"",P12<>0,O12<>0,O12<>""),P12/O12,"") | S12: ='Ялта, Ленина, 18'!S12*График!AJ29/График!AJ31 -> 382251.31 | T12: =L54 -> 260204
F13: Кол-во чеков | I13: =IF(I12<>0,I9/I12,"") -> 153.52461 | J13: =G54 -> 132 | K13: =IF(AND(I13<>"",I13<>0,J13<>""),J13/I13,"") -> 0.85979702 | L13: =IF(SUMIF($G$25:$G$51,">=0",$R$25:$R$51)<>0,I13*G54/SUMIF($G$25:$G$51,">=0",$R$25:$R$51),"") -> 142.56 | M13: =IF(AND(I13<>"",I13<>0,L13<>"",L13<>0),L13/I13,"") -> 0.92858078 | N13: =IF(AND(J13<>0,J13<>"",I13<>0,I13<>""),L13-I13,"") -> -10.964607 | P13: =IF(AND(O13<>"",O13<>0,L13<>"",L13<>0),-O13+L13,"") | Q13: =IF(AND(P13<>"",P13<>0,O13<>0,O13<>""),P13/O13,"") | S13: =T12/S12 -> 0.68071448 | T13: =S13/J14*I14 -> 0.68071448
F14: Кол-во смен план/отработано | I14: =График!AI29 -> 25 | J14: 25 | K14: =IF(AND(I14<>"",I14<>0,J14<>""),J14/I14,"") -> 1 | L14: =I14 -> 25 | M14: =IF(AND(I14<>"",I14<>0,L14<>"",L14<>0),L14/I14,"") -> 1 | N14: =IF(AND(J14<>0,J14<>"",I14<>0,I14<>""),L14-I14,"") -> 0 | P14: =IF(AND(O14<>"",O14<>0,L14<>"",L14<>0),-O14+L14,"") | Q14: =IF(AND(P14<>"",P14<>0,O14<>0,O14<>""),P14/O14,"")
F15: Средние продажи в смену | I15: ='Ялта, Ленина, 18'!I15 -> 143585.28 | J15: =J8/J14 -> 50401 | K15: =IF(AND(I15<>"",I15<>0,J15<>""),J15/I15,"") -> 0.35101788 | L15: =J15 -> 50401 | M15: =IF(AND(I15<>"",I15<>0,L15<>"",L15<>0),L15/I15,"") -> 0.35101788 | N15: =IF(AND(J15<>0,J15<>"",I15<>0,I15<>""),L15-I15,"") -> -93184.28 | P15: =IF(AND(O15<>"",O15<>0,L15<>"",L15<>0),-O15+L15,"") | Q15: =IF(AND(P15<>"",P15<>0,O15<>0,O15<>""),P15/O15,"")
F16: Отставание/Перевыполнение | J16: =J8-I15*J14 -> -2329607 | K16: =IF(AND(I16<>"",I16<>0,J16<>""),J16/I16,"") | L16: =J16 -> -2329607 | M16: =IF(AND(I16<>"",I16<>0,L16<>"",L16<>0),L16/I16,"") | N16: =IF(AND(J16<>0,J16<>"",I16<>0,I16<>""),L16-I16,"") | P16: =IF(AND(O16<>"",O16<>0,L16<>"",L16<>0),-O16+L16,"") | Q16: =IF(AND(P16<>"",P16<>0,O16<>0,O16<>""),P16/O16,"") | S16: UNOde50
F17: Трафик | I17: ='Ялта, Ленина, 18'!I17/График!AJ31*График!AJ29 -> 624.08377 | J17: =I54 -> 530 | K17: =IF(AND(I17<>"",I17<>0,J17<>""),J17/I17,"") -> 0.84924497 | L17: =J17/J14*I14 -> 530 | M17: =IF(AND(I17<>"",I17<>0,L17<>"",L17<>0),L17/I17,"") -> 0.84924497 | N17: =IF(AND(J17<>0,J17<>"",I17<>0,I17<>""),L17-I17,"") -> -94.08377 | P17: =IF(AND(O17<>"",O17<>0,L17<>"",L17<>0),-O17+L17,"") | Q17: =IF(AND(P17<>"",P17<>0,O17<>0,O17<>""),P17/O17,"")
K18: =IF(AND(I18<>"",I18<>0,J18<>""),J18/I18,"") | L18: =J18 -> 0 | M18: =IF(AND(I18<>"",I18<>0,L18<>"",L18<>0),L18/I18,"") | N18: =IF(AND(J18<>0,J18<>"",I18<>0,I18<>""),L18-I18,"") | O18: 0 | P18: =IF(AND(O18<>"",O18<>0,L18<>"",L18<>0),-O18+L18,"") | Q18: =IF(AND(P18<>"",P18<>0,O18<>0,O18<>""),P18/O18,"") | S18: ='Ялта, Ленина, 18'!S18*График!AJ29/График!AJ31 -> 304240.84 | T18: =K54 -> 151858
J19: =M54 -> 0 | K19: =IF(AND(I19<>"",I19<>0,J19<>""),J19/I19,"") | L19: =J19 -> 0 | M19: =IF(AND(I19<>"",I19<>0,L19<>"",L19<>0),L19/I19,"") | N19: =IF(AND(J19<>0,J19<>"",I19<>0,I19<>""),L19-I19,"") | O19: 0 | P19: =IF(AND(O19<>"",O19<>0,L19<>"",L19<>0),-O19+L19,"") | Q19: =IF(AND(P19<>"",P19<>0,O19<>0,O19<>""),P19/O19,"") | S19: =T18/S18 -> 0.49913746 | T19: =S19/J14*I14 -> 0.49913746
F20: Конверсия план/факт | I20: ='Ялта, Ленина, 18'!I20 -> 0.246 | J20: =N54 -> 0.2490566 | K20: =J20/I20 -> 1.0124252 | L20: =IF(AND(K8<>0,I14<>0,I54<>0),(I54*N54+(I54/K8-I54)*I20)/(I54/K8),0) -> 0.24829226 | M20: =IF(AND(I20<>"",I20<>0,L20<>"",L20<>0),L20/I20,"") -> 1.0093181 | N20: =IF(AND(J20<>0,J20<>"",I20<>0,I20<>""),L20-I20,"") -> 0.0022922619 | P20: =IF(AND(O20<>"",O20<>0,L20<>"",L20<>0),-O20+L20,"") | Q20: =IF(AND(P20<>"",P20<>0,O20<>0,O20<>""),P20/O20,"")
B22: Факт продаж за месяц | O22: % выполнения дневного плана | P22: Раcпределение плана по дням
B23: Дата | C23: День недели | D23: Выручка (руб) | E23: Кол-во единиц (шт.) | F23: Средняя стоимость изделия (руб.) | G23: Количество чеков (шт.) | H23: Средняя сумма чека (руб.) | I23: Трафик | J23: Длина чека (шт.) | K23: UNOde50 | L23: IS | M23: Запасной | N23: Конверсия (%) | P23: выручка, план | Q23: кол-во ед, план | R23: Кол-во чеков, план | S23: выручка, скорректир.план | T23: кол-во ед, скорр. план | U23: кол-во чеков, скорр. план | V23: Коэфф. Дня Недели | W23: Специфика месяца
B24: 1 | C24: 2 | D24: 3 | E24: 4 | F24: 5 | G24: 6 | H24: 7 | I24: 8 | J24: 9 | K24: 10 | L24: 11 | M24: 12 | N24: 13 | P24: 1 | Q24: 2 | R24: 3 | S24: 4 | T24: 5 | U24: 6 | V24: 10 | W24: 11
A25: 1 | B25: 45809 | C25: вс | D25: =5392+12903 -> 18295 | E25: 2 | F25: =IF(AND(E25<>"",E25<>0),D25/E25,"") -> 9147.5 | G25: 2 | H25: =IF(AND(G25<>"",G25<>0),D25/G25,"") -> 9147.5 | I25: 15 | J25: =IF(AND(G25<>"",G25<>0),E25/G25,"") -> 1 | K25: 0 | L25: 12903 | N25: =IF(AND(I25<>"",I25<>0),G25/I25,"") -> 0.13333333 | O25: =D25/P25 -> 0.29399646 | P25: =$I$8*V25*W25/SUMPRODUCT($W$25:$W$55,$V$25:$V$55) -> 62228.641 | Q25: =$I$9*V25*W25/SUMPRODUCT($W$25:$W$55,$V$25:$V$55) -> 10.803583 | R25: =IF($I$12="","",Q25/$I$12) -> 5.6860966 | S25: =IF(D25<>"",D25,P25) -> 18295 | T25: =IF(E25<>"",E25,Q25) -> 2 | U25: =IF(G25<>"",G25,R25) -> 2 | V25: 1 | W25: 1
A26: 2 | B26: 45810 | C26: пн | D26: =30102+7903 -> 38005 | E26: 8 | F26: =IF(AND(E26<>"",E26<>0),D26/E26,"") -> 4750.625 | G26: 7 | H26: =IF(AND(G26<>"",G26<>0),D26/G26,"") -> 5429.2857 | I26: 17 | J26: =IF(AND(G26<>"",G26<>0),E26/G26,"") -> 1.1428571 | L26: 7903 | N26: =IF(AND(I26<>"",I26<>0),G26/I26,"") -> 0.41176471 | O26: =D26/P26 -> 0.61073164 | P26: =$I$8*V26*W26/SUMPRODUCT($W$25:$W$55,$V$25:$V$55) -> 62228.641 | Q26: =$I$9*V26*W26/SUMPRODUCT($W$25:$W$55,$V$25:$V$55) -> 10.803583 | R26: =IF($I$12="","",Q26/$I$12) -> 5.6860966 | S26: =IF(W26<>"",IF(D26<>"",D26,($I$8-SUM($S$25:S25))*V26*W26/SUMPRODUCT($W26:$W$55,$V26:$V$55)),"") -> 38005 | T26: =IF(W26<>"",IF(E26<>"",E26,($I$9-SUM($T$25:T25))*V26*W26/SUMPRODUCT($W26:$W$55,$V26:$V$55)),"") -> 8 | U26: =IF(W26<>"",IF($I$12<>"",IF(G26<>"",G26,($I$9/$I$12-SUM($U$25:U25))*V26*W26/SUMPRODUCT($W26:$W$55,$V26:$V$55)),""),"") -> 7 | V26: 1 | W26: 1
A27: 3 | B27: 45811 | C27: вт | D27: =36616+55419 -> 92035 | E27: 15 | F27: =IF(AND(E27<>"",E27<>0),D27/E27,"") -> 6135.6667 | G27: 10 | H27: =IF(AND(G27<>"",G27<>0),D27/G27,"") -> 9203.5 | I27: 25 | J27: =IF(AND(G27<>"",G27<>0),E27/G27,"") -> 1.5 | L27: 55419 | N27: =IF(AND(I27<>"",I27<>0),G27/I27,"") -> 0.4 | O27: =D27/P27 -> 1.4789814 | P27: =$I$8*V27*W27/SUMPRODUCT($W$25:$W$55,$V$25:$V$55) -> 62228.641 | Q27: =$I$9*V27*W27/SUMPRODUCT($W$25:$W$55,$V$25:$V$55) -> 10.803583 | R27: =IF($I$12="","",Q27/$I$12) -> 5.6860966 | S27: =IF(W27<>"",IF(D27<>"",D27,($I$8-SUM($S$25:S26))*V27*W27/SUMPRODUCT($W27:$W$55,$V27:$V$55)),"") -> 92035 | T27: =IF(W27<>"",IF(E27<>"",E27,($I$9-SUM($T$25:T26))*V27*W27/SUMPRODUCT($W27:$W$55,$V27:$V$55)),"") -> 15 | U27: =IF(W27<>"",IF($I$12<>"",IF(G27<>"",G27,($I$9/$I$12-SUM($U$25:U26))*V27*W27/SUMPRODUCT($W27:$W$55,$V27:$V$55)),""),"") -> 10 | V27: 1 | W27: 1
A28: 4 | B28: 45813 | C28: чт | D28: =46966+74930 -> 121896 | E28: 13 | F28: =IF(AND(E28<>"",E28<>0),D28/E28,"") -> 9376.6154 | G28: 8 | H28: =IF(AND(G28<>"",G28<>0),D28/G28,"") -> 15237 | I28: 20 | J28: =IF(AND(G28<>"",G28<>0),E28/G28,"") -> 1.625 | L28: 74930 | N28: =IF(AND(I28<>"",I28<>0),G28/I28,"") -> 0.4 | O28: =D28/P28 -> 1.9588408 | P28: =$I$8*V28*W28/SUMPRODUCT($W$25:$W$55,$V$25:$V$55) -> 62228.641 | Q28: =$I$9*V28*W28/SUMPRODUCT($W$25:$W$55,$V$25:$V$55) -> 10.803583 | R28: =IF($I$12="","",Q28/$I$12) -> 5.6860966 | S28: =IF(W28<>"",IF(D28<>"",D28,($I$8-SUM($S$25:S27))*V28*W28/SUMPRODUCT($W28:$W$55,$V28:$V$55)),"") -> 121896 | T28: =IF(W28<>"",IF(E28<>"",E28,($I$9-SUM($T$25:T27))*V28*W28/SUMPRODUCT($W28:$W$55,$V28:$V$55)),"") -> 13 | U28: =IF(W28<>"",IF($I$12<>"",IF(G28<>"",G28,($I$9/$I$12-SUM($U$25:U27))*V28*W28/SUMPRODUCT($W28:$W$55,$V28:$V$55)),""),"") -> 8 | V28: 1 | W28: 1
A29: 5 | B29: 45814 | C29: пт | D29: =32400+6204 -> 38604 | E29: 9 | F29: =IF(AND(E29<>"",E29<>0),D29/E29,"") -> 4289.3333 | G29: 6 | H29: =IF(AND(G29<>"",G29<>0),D29/G29,"") -> 6434 | I29: 30 | J29: =IF(AND(G29<>"",G29<>0),E29/G29,"") -> 1.5 | L29: 6204 | N29: =IF(AND(I29<>"",I29<>0),G29/I29,"") -> 0.2 | O29: =D29/P29 -> 0.62035743 | P29: =$I$8*V29*W29/SUMPRODUCT($W$25:$W$55,$V$25:$V$55) -> 62228.641 | Q29: =$I$9*V29*W29/SUMPRODUCT($W$25:$W$55,$V$25:$V$55) -> 10.803583 | R29: =IF($I$12="","",Q29/$I$12) -> 5.6860966 | S29: =IF(W29<>"",IF(D29<>"",D29,($I$8-SUM($S$25:S28))*V29*W29/SUMPRODUCT($W29:$W$55,$V29:$V$55)),"") -> 38604 | T29: =IF(W29<>"",IF(E29<>"",E29,($I$9-SUM($T$25:T28))*V29*W29/SUMPRODUCT($W29:$W$55,$V29:$V$55)),"") -> 9 | U29: =IF(W29<>"",IF($I$12<>"",IF(G29<>"",G29,($I$9/$I$12-SUM($U$25:U28))*V29*W29/SUMPRODUCT($W29:$W$55,$V29:$V$55)),""),"") -> 6 | V29: 1 | W29: 1
A30: 6 | B30: 45815 | C30: сб | D30: =27440+24012+21703 -> 73155 | E30: 11 | F30: =IF(AND(E30<>"",E30<>0),D30/E30,"") -> 6650.4545 | G30: 5 | H30: =IF(AND(G30<>"",G30<>0),D30/G30,"") -> 14631 | I30: 30 | J30: =IF(AND(G30<>"",G30<>0),E30/G30,"") -> 2.2 | K30: 24012 | L30: 21703 | N30: =IF(AND(I30<>"",I30<>0),G30/I30,"") -> 0.16666667 | O30: =D30/P30 -> 1.1755841 | P30: =$I$8*V30*W30/SUMPRODUCT($W$25:$W$55,$V$25:$V$55) -> 62228.641 | Q30: =$I$9*V30*W30/SUMPRODUCT($W$25:$W$55,$V$25:$V$55) -> 10.803583 | R30: =IF($I$12="","",Q30/$I$12) -> 5.6860966 | S30: =IF(W30<>"",IF(D30<>"",D30,($I$8-SUM($S$25:S29))*V30*W30/SUMPRODUCT($W30:$W$55,$V30:$V$55)),"") -> 73155 | T30: =IF(W30<>"",IF(E30<>"",E30,($I$9-SUM($T$25:T29))*V30*W30/SUMPRODUCT($W30:$W$55,$V30:$V$55)),"") -> 11 | U30: =IF(W30<>"",IF($I$12<>"",IF(G30<>"",G30,($I$9/$I$12-SUM($U$25:U29))*V30*W30/SUMPRODUCT($W30:$W$55,$V30:$V$55)),""),"") -> 5 | V30: 1 | W30: 1
A31: 7 | B31: 45816 | C31: вс | D31: =71706+7503 -> 79209 | E31: 18 | F31: =IF(AND(E31<>"",E31<>0),D31/E31,"") -> 4400.5 | G31: 11 | H31: =IF(AND(G31<>"",G31<>0),D31/G31,"") -> 7200.8182 | I31: 35 | J31: =IF(AND(G31<>"",G31<>0),E31/G31,"") -> 1.6363636 | L31: 7503 | N31: =IF(AND(I31<>"",I31<>0),G31/I31,"") -> 0.31428571 | O31: =D31/P31 -> 1.2728705 | P31: =$I$8*V31*W31/SUMPRODUCT($W$25:$W$55,$V$25:$V$55) -> 62228.641 | Q31: =$I$9*V31*W31/SUMPRODUCT($W$25:$W$55,$V$25:$V$55) -> 10.803583 | R31: =IF($I$12="","",Q31/$I$12) -> 5.6860966 | S31: =IF(W31<>"",IF(D31<>"",D31,($I$8-SUM($S$25:S30))*V31*W31/SUMPRODUCT($W31:$W$55,$V31:$V$55)),"") -> 79209 | T31: =IF(W31<>"",IF(E31<>"",E31,($I$9-SUM($T$25:T30))*V31*W31/SUMPRODUCT($W31:$W$55,$V31:$V$55)),"") -> 18 | U31: =IF(W31<>"",IF($I$12<>"",IF(G31<>"",G31,($I$9/$I$12-SUM($U$25:U30))*V31*W31/SUMPRODUCT($W31:$W$55,$V31:$V$55)),""),"") -> 11 | V31: 1 | W31: 1
A32: 8 | B32: 45817 | C32: пн | D32: =28057+6992 -> 35049 | E32: 7 | F32: =IF(AND(E32<>"",E32<>0),D32/E32,"") -> 5007 | G32: 4 | H32: =IF(AND(G32<>"",G32<>0),D32/G32,"") -> 8762.25 | I32: 17 | J32: =IF(AND(G32<>"",G32<>0),E32/G32,"") -> 1.75 | K32: 6992 | N32: =IF(AND(I32<>"",I32<>0),G32/I32,"") -> 0.23529412 | O32: =D32/P32 -> 0.5632294 | P32: =$I$8*V32*W32/SUMPRODUCT($W$25:$W$55,$V$25:$V$55) -> 62228.641 | Q32: =$I$9*V32*W32/SUMPRODUCT($W$25:$W$55,$V$25:$V$55) -> 10.803583 | R32: =IF($I$12="","",Q32/$I$12) -> 5.6860966 | S32: =IF(W32<>"",IF(D32<>"",D32,($I$8-SUM($S$25:S31))*V32*W32/SUMPRODUCT($W32:$W$55,$V32:$V$55)),"") -> 35049 | T32: =IF(W32<>"",IF(E32<>"",E32,($I$9-SUM($T$25:T31))*V32*W32/SUMPRODUCT($W32:$W$55,$V32:$V$55)),"") -> 7 | U32: =IF(W32<>"",IF($I$12<>"",IF(G32<>"",G32,($I$9/$I$12-SUM($U$25:U31))*V32*W32/SUMPRODUCT($W32:$W$55,$V32:$V$55)),""),"") -> 4 | V32: 1 | W32: 1
A33: 9 | B33: 45818 | C33: вт | D33: 30540 | E33: 6 | F33: =IF(AND(E33<>"",E33<>0),D33/E33,"") -> 5090 | G33: 6 | H33: =IF(AND(G33<>"",G33<>0),D33/G33,"") -> 5090 | I33: 17 | J33: =IF(AND(G33<>"",G33<>0),E33/G33,"") -> 1 | N33: =IF(AND(I33<>"",I33<>0),G33/I33,"") -> 0.35294118 | O33: =D33/P33 -> 0.4907708 | P33: =$I$8*V33*W33/SUMPRODUCT($W$25:$W$55,$V$25:$V$55) -> 62228.641 | Q33: =$I$9*V33*W33/SUMPRODUCT($W$25:$W$55,$V$25:$V$55) -> 10.803583 | R33: =IF($I$12="","",Q33/$I$12) -> 5.6860966 | S33: =IF(W33<>"",IF(D33<>"",D33,($I$8-SUM($S$25:S32))*V33*W33/SUMPRODUCT($W33:$W$55,$V33:$V$55)),"") -> 30540 | T33: =IF(W33<>"",IF(E33<>"",E33,($I$9-SUM($T$25:T32))*V33*W33/SUMPRODUCT($W33:$W$55,$V33:$V$55)),"") -> 6 | U33: =IF(W33<>"",IF($I$12<>"",IF(G33<>"",G33,($I$9/$I$12-SUM($U$25:U32))*V33*W33/SUMPRODUCT($W33:$W$55,$V33:$V$55)),""),"") -> 6 | V33: 1 | W33: 1
A34: 10 | B34: 45819 | C34: ср | D34: 70982 | E34: 14 | F34: =IF(AND(E34<>"",E34<>0),D34/E34,"") -> 5070.1429 | G34: 4 | H34: =IF(AND(G34<>"",G34<>0),D34/G34,"") -> 17745.5 | I34: 11 | J34: =IF(AND(G34<>"",G34<>0),E34/G34,"") -> 3.5 | N34: =IF(AND(I34<>"",I34<>0),G34/I34,"") -> 0.36363636 | O34: =D34/P34 -> 1.1406645 | P34: =$I$8*V34*W34/SUMPRODUCT($W$25:$W$55,$V$25:$V$55) -> 62228.641 | Q34: =$I$9*V34*W34/SUMPRODUCT($W$25:$W$55,$V$25:$V$55) -> 10.803583 | R34: =IF($I$12="","",Q34/$I$12) -> 5.6860966 | S34: =IF(W34<>"",IF(D34<>"",D34,($I$8-SUM($S$25:S33))*V34*W34/SUMPRODUCT($W34:$W$55,$V34:$V$55)),"") -> 70982 | T34: =IF(W34<>"",IF(E34<>"",E34,($I$9-SUM($T$25:T33))*V34*W34/SUMPRODUCT($W34:$W$55,$V34:$V$55)),"") -> 14 | U34: =IF(W34<>"",IF($I$12<>"",IF(G34<>"",G34,($I$9/$I$12-SUM($U$25:U33))*V34*W34/SUMPRODUCT($W34:$W$55,$V34:$V$55)),""),"") -> 4 | V34: 1 | W34: 1
A35: 11 | B35: 45820 | C35: чт | D35: 72879 | E35: 15 | F35: =IF(AND(E35<>"",E35<>0),D35/E35,"") -> 4858.6 | G35: 7 | H35: =IF(AND(G35<>"",G35<>0),D35/G35,"") -> 10411.286 | I35: 30 | J35: =IF(AND(G35<>"",G35<>0),E35/G35,"") -> 2.1428571 | N35: =IF(AND(I35<>"",I35<>0),G35/I35,"") -> 0.23333333 | O35: =D35/P35 -> 1.1711488 | P35: =$I$8*V35*W35/SUMPRODUCT($W$25:$W$55,$V$25:$V$55) -> 62228.641 | Q35: =$I$9*V35*W35/SUMPRODUCT($W$25:$W$55,$V$25:$V$55) -> 10.803583 | R35: =IF($I$12="","",Q35/$I$12) -> 5.6860966 | S35: =IF(W35<>"",IF(D35<>"",D35,($I$8-SUM($S$25:S34))*V35*W35/SUMPRODUCT($W35:$W$55,$V35:$V$55)),"") -> 72879 | T35: =IF(W35<>"",IF(E34<>"",E34,($I$9-SUM($T$25:T34))*V35*W35/SUMPRODUCT($W35:$W$55,$V35:$V$55)),"") -> 14 | U35: =IF(W35<>"",IF($I$12<>"",IF(G35<>"",G35,($I$9/$I$12-SUM($U$25:U34))*V35*W35/SUMPRODUCT($W35:$W$55,$V35:$V$55)),""),"") -> 7 | V35: 1 | W35: 1
A36: 12 | B36: 45822 | C36: сб | D36: =70459+8993 -> 79452 | E36: 17 | F36: =IF(AND(E36<>"",E36<>0),D36/E36,"") -> 4673.6471 | G36: 9 | H36: =IF(AND(G36<>"",G36<>0),D36/G36,"") -> 8828 | I36: 30 | J36: =IF(AND(G36<>"",G36<>0),E36/G36,"") -> 1.8888889 | K36: 8993 | N36: =IF(AND(I36<>"",I36<>0),G36/I36,"") -> 0.3 | O36: =D36/P36 -> 1.2767754 | P36: =$I$8*V36*W36/SUMPRODUCT($W$25:$W$55,$V$25:$V$55) -> 62228.641 | Q36: =$I$9*V36*W36/SUMPRODUCT($W$25:$W$55,$V$25:$V$55) -> 10.803583 | R36: =IF($I$12="","",Q36/$I$12) -> 5.6860966 | S36: =IF(W36<>"",IF(D36<>"",D36,($I$8-SUM($S$25:S35))*V36*W36/SUMPRODUCT($W36:$W$55,$V36:$V$55)),"") -> 79452 | T36: =IF(W36<>"",IF(E36<>"",E36,($I$9-SUM($T$25:T35))*V36*W36/SUMPRODUCT($W36:$W$55,$V36:$V$55)),"") -> 17 | U36: =IF(W36<>"",IF($I$12<>"",IF(G36<>"",G36,($I$9/$I$12-SUM($U$25:U35))*V36*W36/SUMPRODUCT($W36:$W$55,$V36:$V$55)),""),"") -> 9 | V36: 1 | W36: 1
A37: 13 | B37: 45823 | C37: вс | D37: =40831+8603 -> 49434 | E37: 10 | F37: =IF(AND(E37<>"",E37<>0),D37/E37,"") -> 4943.4 | G37: 7 | H37: =IF(AND(G37<>"",G37<>0),D37/G37,"") -> 7062 | I37: 25 | J37: =IF(AND(G37<>"",G37<>0),E37/G37,"") -> 1.4285714 | L37: 8603 | N37: =IF(AND(I37<>"",I37<>0),G37/I37,"") -> 0.28 | O37: =D37/P37 -> 0.79439305 | P37: =$I$8*V37*W37/SUMPRODUCT($W$25:$W$55,$V$25:$V$55) -> 62228.641 | Q37: =$I$9*V37*W37/SUMPRODUCT($W$25:$W$55,$V$25:$V$55) -> 10.803583 | R37: =IF($I$12="","",Q37/$I$12) -> 5.6860966 | S37: =IF(W37<>"",IF(D37<>"",D37,($I$8-SUM($S$25:S36))*V37*W37/SUMPRODUCT($W37:$W$55,$V37:$V$55)),"") -> 49434 | T37: =IF(W37<>"",IF(E37<>"",E37,($I$9-SUM($T$25:T36))*V37*W37/SUMPRODUCT($W37:$W$55,$V37:$V$55)),"") -> 10 | U37: =IF(W37<>"",IF($I$12<>"",IF(G37<>"",G37,($I$9/$I$12-SUM($U$25:U36))*V37*W37/SUMPRODUCT($W37:$W$55,$V37:$V$55)),""),"") -> 7 | V37: 1 | W37: 1
A38: 14 | B38: 45825 | C38: вт | D38: 36905 | E38: 9 | F38: =IF(AND(E38<>"",E38<>0),D38/E38,"") -> 4100.5556 | G38: 3 | H38: =IF(AND(G38<>"",G38<>0),D38/G38,"") -> 12301.667 | I38: 20 | J38: =IF(AND(G38<>"",G38<>0),E38/G38,"") -> 3 | N38: =IF(AND(I38<>"",I38<>0),G38/I38,"") -> 0.15 | O38: =D38/P38 -> 0.59305489 | P38: =$I$8*V38*W38/SUMPRODUCT($W$25:$W$55,$V$25:$V$55) -> 62228.641 | Q38: =$I$9*V38*W38/SUMPRODUCT($W$25:$W$55,$V$25:$V$55) -> 10.803583 | R38: =IF($I$12="","",Q38/$I$12) -> 5.6860966 | S38: =IF(W38<>"",IF(D38<>"",D38,($I$8-SUM($S$25:S37))*V38*W38/SUMPRODUCT($W38:$W$55,$V38:$V$55)),"") -> 36905 | T38: =IF(W38<>"",IF(E38<>"",E38,($I$9-SUM($T$25:T37))*V38*W38/SUMPRODUCT($W38:$W$55,$V38:$V$55)),"") -> 9 | U38: =IF(W38<>"",IF($I$12<>"",IF(G38<>"",G38,($I$9/$I$12-SUM($U$25:U37))*V38*W38/SUMPRODUCT($W38:$W$55,$V38:$V$55)),""),"") -> 3 | V38: 1 | W38: 1
A39: 13 | B39: 45826 | C39: ср | D39: =4282+11584 -> 15866 | E39: 3 | F39: =IF(AND(E39<>"",E39<>0),D39/E39,"") -> 5288.6667 | G39: 2 | H39: =IF(AND(G39<>"",G39<>0),D39/G39,"") -> 7933 | I39: 12 | J39: =IF(AND(G39<>"",G39<>0),E39/G39,"") -> 1.5 | N39: =IF(AND(I39<>"",I39<>0),G39/I39,"") -> 0.16666667 | O39: =D39/P39 -> 0.25496298 | P39: =$I$8*V39*W39/SUMPRODUCT($W$25:$W$55,$V$25:$V$55) -> 62228.641 | Q39: =$I$9*V39*W39/SUMPRODUCT($W$25:$W$55,$V$25:$V$55) -> 10.803583 | R39: =IF($I$12="","",Q39/$I$12) -> 5.6860966 | S39: =IF(W39<>"",IF(D39<>"",D39,($I$8-SUM($S$25:S38))*V39*W39/SUMPRODUCT($W39:$W$55,$V39:$V$55)),"") -> 15866 | T39: =IF(W39<>"",IF(E39<>"",E39,($I$9-SUM($T$25:T38))*V39*W39/SUMPRODUCT($W39:$W$55,$V39:$V$55)),"") -> 3 | U39: =IF(W39<>"",IF($I$12<>"",IF(G39<>"",G39,($I$9/$I$12-SUM($U$25:U38))*V39*W39/SUMPRODUCT($W39:$W$55,$V39:$V$55)),""),"") -> 2 | V39: 1 | W39: 1
A40: 13 | B40: 45828 | C40: пт | D40: 6578 | E40: 2 | F40: =IF(AND(E40<>"",E40<>0),D40/E40,"") -> 3289 | G40: 2 | H40: =IF(AND(G40<>"",G40<>0),D40/G40,"") -> 3289 | I40: 20 | J40: =IF(AND(G40<>"",G40<>0),E40/G40,"") -> 1 | N40: =IF(AND(I40<>"",I40<>0),G40/I40,"") -> 0.1 | O40: =D40/P40 -> 0.10570695 | P40: =$I$8*V40*W40/SUMPRODUCT($W$25:$W$55,$V$25:$V$55) -> 62228.641 | Q40: =$I$9*V40*W40/SUMPRODUCT($W$25:$W$55,$V$25:$V$55) -> 10.803583 | R40: =IF($I$12="","",Q40/$I$12) -> 5.6860966 | S40: =IF(W40<>"",IF(D40<>"",D40,($I$8-SUM($S$25:S39))*V40*W40/SUMPRODUCT($W40:$W$55,$V40:$V$55)),"") -> 6578 | T40: =IF(W40<>"",IF(E40<>"",E40,($I$9-SUM($T$25:T39))*V40*W40/SUMPRODUCT($W40:$W$55,$V40:$V$55)),"") -> 2 | U40: =IF(W40<>"",IF($I$12<>"",IF(G40<>"",G40,($I$9/$I$12-SUM($U$25:U39))*V40*W40/SUMPRODUCT($W40:$W$55,$V40:$V$55)),""),"") -> 2 | V40: 1 | W40: 1
A41: 17 | B41: 45829 | C41: сб | D41: =6993+8903+14277 -> 30173 | E41: 5 | F41: =IF(AND(E41<>"",E41<>0),D41/E41,"") -> 6034.6 | G41: 4 | H41: =IF(AND(G41<>"",G41<>0),D41/G41,"") -> 7543.25 | I41: 23 | J41: =IF(AND(G41<>"",G41<>0),E41/G41,"") -> 1.25 | K41: 6993 | L41: 8903 | N41: =IF(AND(I41<>"",I41<>0),G41/I41,"") -> 0.17391304 | O41: =D41/P41 -> 0.4848732 | P41: =$I$8*V41*W41/SUMPRODUCT($W$25:$W$55,$V$25:$V$55) -> 62228.641 | Q41: =$I$9*V41*W41/SUMPRODUCT($W$25:$W$55,$V$25:$V$55) -> 10.803583 | R41: =IF($I$12="","",Q41/$I$12) -> 5.6860966 | S41: =IF(W41<>"",IF(D41<>"",D41,($I$8-SUM($S$25:S40))*V41*W41/SUMPRODUCT($W41:$W$55,$V41:$V$55)),"") -> 30173 | T41: =IF(W41<>"",IF(E41<>"",E41,($I$9-SUM($T$25:T40))*V41*W41/SUMPRODUCT($W41:$W$55,$V41:$V$55)),"") -> 5 | U41: =IF(W41<>"",IF($I$12<>"",IF(G41<>"",G41,($I$9/$I$12-SUM($U$25:U40))*V41*W41/SUMPRODUCT($W41:$W$55,$V41:$V$55)),""),"") -> 4 | V41: 1 | W41: 1
A42: 18 | B42: 45830 | C42: вс | D42: =10903+43559 -> 54462 | E42: 12 | F42: =IF(AND(E42<>"",E42<>0),D42/E42,"") -> 4538.5 | G42: 5 | H42: =IF(AND(G42<>"",G42<>0),D42/G42,"") -> 10892.4 | I42: 23 | J42: =IF(AND(G42<>"",G42<>0),E42/G42,"") -> 2.4 | L42: 10903 | N42: =IF(AND(I42<>"",I42<>0),G42/I42,"") -> 0.2173913 | O42: =D42/P42 -> 0.87519186 | P42: =$I$8*V42*W42/SUMPRODUCT($W$25:$W$55,$V$25:$V$55) -> 62228.641 | Q42: =$I$9*V42*W42/SUMPRODUCT($W$25:$W$55,$V$25:$V$55) -> 10.803583 | R42: =IF($I$12="","",Q42/$I$12) -> 5.6860966 | S42: =IF(W42<>"",IF(D42<>"",D42,($I$8-SUM($S$25:S41))*V42*W42/SUMPRODUCT($W42:$W$55,$V42:$V$55)),"") -> 54462 | T42: =IF(W42<>"",IF(E42<>"",E42,($I$9-SUM($T$25:T41))*V42*W42/SUMPRODUCT($W42:$W$55,$V42:$V$55)),"") -> 12 | U42: =IF(W42<>"",IF($I$12<>"",IF(G42<>"",G42,($I$9/$I$12-SUM($U$25:U41))*V42*W42/SUMPRODUCT($W42:$W$55,$V42:$V$55)),""),"") -> 5 | V42: 1 | W42: 1
...

Sheet Уразгильдеева Е. Р.
B1: =TODAY()-1 -> 46171
B2: (отчетная дата) | J2: ЕЖЕДНЕВНЫЙ ОТЧЕТ О ПРОДАЖАХ
B3: Осталось до выполнения плана!!! | J3: =График!B28 -> Уразгильдеева Екатерина
C4: =I8-D50 -> 627312.41 | E4: =IF(I8<>0, C4/I8, 0) -> 0.53491248
F6: Целевые показатели
F7: Показатель | I7: План | J7: Факт | K7: % выполнения | L7: Прогноз выполнения | M7: % выполнения по прогнозу | N7: Отклонение | O7: Факт аналогичного месяца прошлого года | P7: Отклонение LFL
F8: Выручка | I8: ='Ялта, Ленина, 18'!I8/График!AJ31*График!AJ28 -> 1172738.4 | J8: =D50 -> 545426 | K8: =J8/I8 -> 0.46508752 | L8: =IF(SUMIF($D$25:$D$49,">=0",$P$25:$P$49)<>0,I8*D50/SUMIF($D$25:$D$49,">=0",$P$25:$P$49),0) -> 678643.57 | M8: =IF(AND(I8<>"",I8<>0,L8<>"",L8<>0),L8/I8,"") -> 0.57868282 | N8: =IF(AND(J8<>0, J8<>"", I8<>0, I8<>""), L8-I8, "") -> -494094.84 | P8: =IF(AND(O8<>"", O8<>0, L8<>"", L8<>0), -O8+L8, "") | Q8: =IF(AND(P8<>"", P8<>0, O8<>0, O8<>""), P8/O8, "")
F9: Кол-во изделий | I9: =I8/I11 -> 203.60042 | J9: =E50 -> 106 | K9: =IF(AND(I9<>"", I9<>0, J9<>""), J9/I9, "") -> 0.52062761 | L9: =J9 -> 106 | M9: =IF(AND(I9<>"",I9<>0,L9<>"",L9<>0),L9/I9,"") -> 0.52062761 | N9: =IF(AND(J9<>0, J9<>"", I9<>0, I9<>""), L9-I9, "") -> -97.600419 | O9: =O8/O11 -> #DIV/0! | P9: =IF(AND(O9<>"", O9<>0, L9<>"", L9<>0), -O9+L9, "") -> #DIV/0! | Q9: =IF(AND(P9<>"", P9<>0, O9<>0, O9<>""), P9/O9, "") -> #DIV/0!
F10: Средний чек | I10: =I11*I12 -> 10944 | J10: =H50 -> 8391.1692 | K10: =IF(AND(I10<>"", I10<>0, J10<>""), J10/I10, "") -> 0.76673695 | L10: =J10 -> 8391.1692 | M10: =IF(AND(I10<>"",I10<>0,L10<>"",L10<>0),L10/I10,"") -> 0.76673695 | N10: =IF(AND(J10<>0, J10<>"", I10<>0, I10<>""), L10-I10, "") -> -2552.8308 | O10: =O11*O12 -> 0 | P10: =IF(AND(O10<>"", O10<>0, L10<>"", L10<>0), -O10+L10, "") | Q10: =IF(AND(P10<>"", P10<>0, O10<>0, O10<>""), P10/O10, "") | S10: IS
