Workbook
Name маг: NA()

Sheet Ялта, Ленина, 18
B1: =TODAY()-1 -> 45939
B2: (отчетная дата)
C3: Осталось до выполнения плана!!! | I3: =График!B3 -> ул. Набережная Ленина, 18
C4: =I8-D56 -> 332372.92 | E4: =IF(I8<>0, C4/I8, 0) -> 0.095873116
D5: =C4/(I14-J14) -> #DIV/0!
F6: Целевые показатели
F7: Показатель | I7: План | J7: Факт | K7: % выполнения | L7: Прогноз выполнения | M7: % выполнения по прогнозу | N7: Отклонение | O7: Факт аналогичного месяца прошлого года | P7: Отклонение LFL
F8: Выручка | I8: =I11*I12*I13 -> 3466800 | J8: =D56 -> 3134427.1 | K8: =IF(AND(I8<>"",I8<>0,J8<>""),J8/I8,"") -> 0.90412688 | L8: =IF(SUMIF($D$25:$D$55,">=0",$P$25:$P$55)<>0,I8*D56/SUMIF($D$25:$D$55,">=0",$P$25:$P$55),0) -> 3134427.1 | M8: =IF(AND(I8<>"", I8<>0, L8<>"", L8<>0), L8/I8, "") -> 0.90412688 | N8: =IF(AND(J8<>0, J8<>"", I8<>0, I8<>""), L8-I8, "") -> -332372.92 | P8: =IF(AND(O8<>"", O8<>0, L8<>"", L8<>0), -O8+L8, "") | Q8: =IF(AND(P8<>"", P8<>0, O8<>0, O8<>""), P8/O8, "")
F9: Кол-во изделий | I9: =I8/I11 -> 577.8 | J9: =E56 -> 482 | K9: =IF(AND(I9<>"", I9<>0, J9<>""), J9/I9, "") -> 0.83419868 | L9: =IF(SUMIF($E$25:$E$55, ">=0", $Q$25:$Q$55)<>0, I9*E56/SUMIF($E$25:$E$55, ">=0", $Q$25:$Q$55), 0) -> 482 | M9: =IF(AND(I9<>"", I9<>0, L9<>"", L9<>0), L9/I9, "") -> 0.83419868 | N9: =IF(AND(J9<>0, J9<>"", I9<>0, I9<>""), L9-I9, "") -> -95.8 | O9: =O8/O11 -> #DIV/0! | P9: =IF(AND(O9<>"", O9<>0, L9<>"", L9<>0), -O9+L9, "") -> #DIV/0! | Q9: =IF(AND(P9<>"", P9<>0, O9<>0, O9<>""), P9/O9, "") -> #DIV/0!
F10: Средний чек | I10: =I11*I12 -> 10800 | J10: =H56 -> 11481.418 | K10: =IF(AND(I10<>"", I10<>0, J10<>""), J10/I10, "") -> 1.0630942 | L10: =J10 -> 11481.418 | M10: =IF(AND(I10<>"", I10<>0, L10<>"", L10<>0), L10/I10, "") -> 1.0630942 | N10: =IF(AND(J10<>0, J10<>"", I10<>0, I10<>""), L10-I10, "") -> 681.41788 | O10: =O11*O12 -> 0 | P10: =IF(AND(O10<>"", O10<>0, L10<>"", L10<>0), -O10+L10, "") | Q10: =IF(AND(P10<>"", P10<>0, O10<>0, O10<>""), P10/O10, "") | S10: =L23 -> IS | V10: =M23 -> Agafi
F11: Средняя стоимость изделия | I11: 6000 | J11: =F56 -> 6502.9607 | K11: =IF(AND(I11<>"", I11<>0, J11<>""), J11/I11, "") -> 1.0838268 | L11: =IF(L9>0, L8/L9, "") -> 6502.9607 | M11: =IF(AND(I11<>"", I11<>0, L11<>"", L11<>0), L11/I11, "") -> 1.0838268 | N11: =IF(AND(J11<>0, J11<>"", I11<>0, I11<>""), L11-I11, "") -> 502.96075 | P11: =IF(AND(O11<>"", O11<>0, L11<>"", L11<>0), -O11+L11, "") | Q11: =IF(AND(P11<>"", P11<>0, O11<>0, O11<>""), P11/O11, "")
F12: Длина чека | I12: 1.8 | J12: =J56 -> 1.7655678 | K12: =IF(AND(I12<>"", I12<>0, J12<>""), J12/I12, "") -> 0.98087098 | L12: =J12 -> 1.7655678 | M12: =IF(AND(I12<>"", I12<>0, L12<>"", L12<>0), L12/I12, "") -> 0.98087098 | N12: =IF(AND(J12<>0, J12<>"", I12<>0, I12<>""), L12-I12, "") -> -0.034432234 | P12: =IF(AND(O12<>"", O12<>0, L12<>"", L12<>0), -O12+L12, "") | Q12: =IF(AND(P12<>"", P12<>0, O12<>0, O12<>""), P12/O12, "") | S12: 510000 | T12: =L56 -> 167876 | V12: 480000 | W12: =M56 -> 216811
F13: Кол-во чеков | I13: =I17*I20 -> 321 | J13: =G56 -> 273 | K13: =IF(AND(I13<>"", I13<>0, J13<>""), J13/I13, "") -> 0.85046729 | L13: =IF(SUMIF($G$25:$G$55, ">=0", $R$25:$R$55)<>0, I13*G56/SUMIF($G$25:$G$55, ">=0", $R$25:$R$55), "") -> 273 | M13: =IF(AND(I13<>"", I13<>0, L13<>"", L13<>0), L13/I13, "") -> 0.85046729 | N13: =IF(AND(J13<>0, J13<>"", I13<>0, I13<>""), L13-I13, "") -> -48 | P13: =IF(AND(O13<>"", O13<>0, L13<>"", L13<>0), -O13+L13, "") | Q13: =IF(AND(P13<>"", P13<>0, O13<>0, O13<>""), P13/O13, "") | S13: =T12/S12 -> 0.32916863 | T13: =S13/J14*I14 -> 0.32916863 | V13: =W12/V12 -> 0.45168958 | W13: =V13/J14*I14 -> 0.45168958
F14: Кол-во смен | I14: 30 | J14: 30 | K14: =IF(AND(I14<>"", I14<>0, J14<>""), J14/I14, "") -> 1 | L14: =I14 -> 30 | M14: =IF(AND(I14<>"", I14<>0, L14<>"", L14<>0), L14/I14, "") -> 1 | N14: =IF(AND(J14<>0, J14<>"", I14<>0, I14<>""), L14-I14, "") -> 0 | P14: =IF(AND(O14<>"", O14<>0, L14<>"", L14<>0), -O14+L14, "") | Q14: =IF(AND(P14<>"", P14<>0, O14<>0, O14<>""), P14/O14, "")
F15: Средние продажи в смену | I15: =I8/I14 -> 115560 | J15: =J8/J14 -> 104480.9 | K15: =IF(AND(I15<>"", I15<>0, J15<>""), J15/I15, "") -> 0.90412688 | L15: =J15 -> 104480.9 | M15: =IF(AND(I15<>"", I15<>0, L15<>"", L15<>0), L15/I15, "") -> 0.90412688 | N15: =IF(AND(J15<>0, J15<>"", I15<>0, I15<>""), L15-I15, "") -> -11079.097 | P15: =IF(AND(O15<>"", O15<>0, L15<>"", L15<>0), -O15+L15, "") | Q15: =IF(AND(P15<>"", P15<>0, O15<>0, O15<>""), P15/O15, "")
F16: Отставание/Перевыполнение | J16: =J8-I15*J14 -> -332372.92 | K16: =IF(AND(I16<>"", I16<>0, J16<>""), J16/I16, "") | L16: =J16 -> -332372.92 | M16: =IF(AND(I16<>"", I16<>0, L16<>"", L16<>0), L16/I16, "") | N16: =IF(AND(J16<>0, J16<>"", I16<>0, I16<>""), L16-I16, "") | P16: =IF(AND(O16<>"", O16<>0, L16<>"", L16<>0), -O16+L16, "") | Q16: =IF(AND(P16<>"", P16<>0, O16<>0, O16<>""), P16/O16, "") | S16: =K23 -> UNOde50
F17: Трафик | I17: 2140 | J17: =I56 -> 2186 | K17: =IF(AND(I17<>"", I17<>0, J17<>""), J17/I17, "") -> 1.0214953 | L17: =J17/J14*I14 -> 2186 | M17: =IF(AND(I17<>"", I17<>0, L17<>"", L17<>0), L17/I17, "") -> 1.0214953 | N17: =IF(AND(J17<>0, J17<>"", I17<>0, I17<>""), L17-I17, "") -> 46 | P17: =IF(AND(O17<>"", O17<>0, L17<>"", L17<>0), -O17+L17, "") | Q17: =IF(AND(P17<>"", P17<>0, O17<>0, O17<>""), P17/O17, "")
K18: =IF(AND(I18<>"", I18<>0, J18<>""), J18/I18, "") | L18: =J18 -> 0 | M18: =IF(AND(I18<>"", I18<>0, L18<>"", L18<>0), L18/I18, "") | N18: =IF(AND(J18<>0, J18<>"", I18<>0, I18<>""), L18-I18, "") | O18: 0 | P18: =IF(AND(O18<>"", O18<>0, L18<>"", L18<>0), -O18+L18, "") | Q18: =IF(AND(P18<>"", P18<>0, O18<>0, O18<>""), P18/O18, "") | S18: 1020000 | T18: =K56 -> 779065
K19: =IF(AND(I19<>"", I19<>0, J19<>""), J19/I19, "") | L19: =J19 -> 0 | M19: =IF(AND(I19<>"", I19<>0, L19<>"", L19<>0), L19/I19, "") | N19: =IF(AND(J19<>0, J19<>"", I19<>0, I19<>""), L19-I19, "") | O19: 0 | P19: =IF(AND(O19<>"", O19<>0, L19<>"", L19<>0), -O19+L19, "") | Q19: =IF(AND(P19<>"", P19<>0, O19<>0, O19<>""), P19/O19, "") | S19: =T18/S18 -> 0.76378922 | T19: =S19/J14*I14 -> 0.76378922
F20: Конверсия план/факт | I20: 0.15 | J20: =N56 -> 0.12488564 | K20: =J20/I20 -> 0.83257091 | L20: =IF(AND(K8<>0, I14<>0, I56<>0), (I56*N56+(I56/K8-I56)*I20)/(I56/K8), 0) -> 0.12729343 | M20: =IF(AND(I20<>"", I20<>0, L20<>"", L20<>0), L20/I20, "") -> 0.84862285 | N20: =IF(AND(J20<>0, J20<>"", I20<>0, I20<>""), L20-I20, "") -> -0.022706572 | P20: =IF(AND(O20<>"", O20<>0, L20<>"", L20<>0), -O20+L20, "") | Q20: =IF(AND(P20<>"", P20<>0, O20<>0, O20<>""), P20/O20, "")
A22: Факт продаж за месяц | O22: % выполнения дневного плана | P22: Раcпределение плана по дням
A23: Сотрудник | B23: Дата | C23: День недели | D23: Выручка (руб) | E23: Кол-во единиц (шт.) | F23: Средняя стоимость изделия (руб.) | G23: Количество чеков (шт.) | H23: Средняя сумма чека (руб.) | I23: Трафик | J23: Длина чека (шт.) | K23: UNOde50 | L23: IS | M23: Agafi | N23: Конверсия (%) | P23: выручка, план | Q23: кол-во ед, план | R23: Кол-во чеков, план | S23: выручка, скорректир.план | T23: кол-во ед, скорр. план | U23: кол-во чеков, скорр. план | V23: Коэфф. Дня Недели | W23: Специфика месяца
B24: 1 | C24: 2 | D24: 3 | E24: 4 | F24: 5 | G24: 6 | H24: 7 | I24: 8 | J24: 9 | K24: 10 | L24: 11 | M24: 12 | N24: 13 | P24: 1 | Q24: 2 | R24: 3 | S24: 4 | T24: 5 | U24: 6 | V24: 10 | W24: 11
A25: Рогалевич,Уразгильдеева | B25: 45901 | C25: пн | D25: =50580+17748+32073 -> 100401 | E25: 14 | F25: =IF(AND(E25<>"",E25<>0),D25/E25,"") -> 7171.5 | G25: 8 | H25: =IF(AND(G25<>"",G25<>0),D25/G25,"") -> 12550.125 | I25: 101 | J25: =IF(AND(G25<>"",G25<>0),E25/G25,"") -> 1.75 | K25: 17748 | M25: 32073 | N25: =IF(AND(I25<>"",I25<>0),G25/I25,"") -> 0.079207921 | O25: =D25/P25 -> 0.77522329 | P25: =$I$8*V25*W25/SUMPRODUCT($W$25:$W$55,$V$25:$V$55) -> 129512.36 | Q25: =$I$9*V25*W25/SUMPRODUCT($W$25:$W$55,$V$25:$V$55) -> 21.585394 | R25: =IF($I$12="","",Q25/$I$12) -> 11.991886 | S25: =IF(D25<>"",D25,P25) -> 100401 | T25: =IF(E25<>"",E25,Q25) -> 14 | U25: =IF(G25<>"",G25,R25) -> 8 | V25: 0.9414554 | W25: 0.9414554
A26: Рогалевич,Уразгильдеева | B26: 45902 | C26: вт | D26: =10690+13590+27659+42784 -> 94723 | E26: 16 | F26: =IF(AND(E26<>"",E26<>0),D26/E26,"") -> 5920.1875 | G26: 11 | H26: =IF(AND(G26<>"",G26<>0),D26/G26,"") -> 8611.1818 | I26: 77 | J26: =IF(AND(G26<>"",G26<>0),E26/G26,"") -> 1.4545455 | K26: 10690 | M26: 13590 | N26: =IF(AND(I26<>"",I26<>0),G26/I26,"") -> 0.14285714 | O26: =D26/P26 -> 0.89072052 | P26: =$I$8*V26*W26/SUMPRODUCT($W$25:$W$55,$V$25:$V$55) -> 106344.24 | Q26: =$I$9*V26*W26/SUMPRODUCT($W$25:$W$55,$V$25:$V$55) -> 17.724041 | R26: =IF($I$12="","",Q26/$I$12) -> 9.8466893 | S26: =IF(W26<>"",IF(D26<>"",D26,($I$8-SUM($S$25:S25))*V26*W26/SUMPRODUCT($W26:$W$55,$V26:$V$55)),"") -> 94723 | T26: =IF(W26<>"",IF(E26<>"",E26,($I$9-SUM($T$25:T25))*V26*W26/SUMPRODUCT($W26:$W$55,$V26:$V$55)),"") -> 16 | U26: =IF(W26<>"",IF(E26<>"",E26,($I$9-SUM($T$25:T25))*V26*W26/SUMPRODUCT($W26:$W$55,$V26:$V$55)),"") -> 16 | V26: 0.85310234 | W26: 0.85310234
A27: Рогалевич,Уразгильдеева | B27: 45903 | C27: ср | D27: =148210+31329.6+36942 -> 216481.6 | E27: 24 | F27: =IF(AND(E27<>"",E27<>0),D27/E27,"") -> 9020.0667 | G27: 14 | H27: =IF(AND(G27<>"",G27<>0),D27/G27,"") -> 15462.971 | I27: 78 | J27: =IF(AND(G27<>"",G27<>0),E27/G27,"") -> 1.7142857 | K27: 148210 | N27: =IF(AND(I27<>"",I27<>0),G27/I27,"") -> 0.17948718 | O27: =D27/P27 -> 2.0356682 | P27: =$I$8*V27*W27/SUMPRODUCT($W$25:$W$55,$V$25:$V$55) -> 106344.24 | Q27: =$I$9*V27*W27/SUMPRODUCT($W$25:$W$55,$V$25:$V$55) -> 17.724041 | R27: =IF($I$12="","",Q27/$I$12) -> 9.8466893 | S27: =IF(W27<>"",IF(D27<>"",D27,($I$8-SUM($S$25:S26))*V27*W27/SUMPRODUCT($W27:$W$55,$V27:$V$55)),"") -> 216481.6 | T27: =IF(W27<>"",IF(E27<>"",E27,($I$9-SUM($T$25:T26))*V27*W27/SUMPRODUCT($W27:$W$55,$V27:$V$55)),"") -> 24 | U27: =IF(W27<>"",IF(E27<>"",E27,($I$9-SUM($T$25:T26))*V27*W27/SUMPRODUCT($W27:$W$55,$V27:$V$55)),"") -> 24 | V27: 0.85310234 | W27: 0.85310234
A28: Рогалевич | B28: 45904 | C28: чт | D28: =55851+7492+51423 -> 114766 | E28: 16 | F28: =IF(AND(E28<>"",E28<>0),D28/E28,"") -> 7172.875 | G28: 11 | H28: =IF(AND(G28<>"",G28<>0),D28/G28,"") -> 10433.273 | I28: 86 | J28: =IF(AND(G28<>"",G28<>0),E28/G28,"") -> 1.4545455 | K28: 55851 | M28: 7492 | N28: =IF(AND(I28<>"",I28<>0),G28/I28,"") -> 0.12790698 | O28: =D28/P28 -> 1.0791933 | P28: =$I$8*V28*W28/SUMPRODUCT($W$25:$W$55,$V$25:$V$55) -> 106344.24 | Q28: =$I$9*V28*W28/SUMPRODUCT($W$25:$W$55,$V$25:$V$55) -> 17.724041 | R28: =IF($I$12="","",Q28/$I$12) -> 9.8466893 | S28: =IF(W28<>"",IF(D28<>"",D28,($I$8-SUM($S$25:S27))*V28*W28/SUMPRODUCT($W28:$W$55,$V28:$V$55)),"") -> 114766 | T28: =IF(W28<>"",IF(E28<>"",E28,($I$9-SUM($T$25:T27))*V28*W28/SUMPRODUCT($W28:$W$55,$V28:$V$55)),"") -> 16 | U28: =IF(W28<>"",IF(E28<>"",E28,($I$9-SUM($T$25:T27))*V28*W28/SUMPRODUCT($W28:$W$55,$V28:$V$55)),"") -> 16 | V28: 0.85310234 | W28: 0.85310234
A29: Рогалевич, Уразгильдеева | B29: 45905 | C29: пт | D29: =9903+41351 -> 51254 | E29: 7 | F29: =IF(AND(E29<>"",E29<>0),D29/E29,"") -> 7322 | G29: 6 | H29: =IF(AND(G29<>"",G29<>0),D29/G29,"") -> 8542.3333 | I29: 65 | J29: =IF(AND(G29<>"",G29<>0),E29/G29,"") -> 1.1666667 | L29: 9903 | N29: =IF(AND(I29<>"",I29<>0),G29/I29,"") -> 0.092307692 | O29: =D29/P29 -> 0.48548765 | P29: =$I$8*V29*W29/SUMPRODUCT($W$25:$W$55,$V$25:$V$55) -> 105572.2 | Q29: =$I$9*V29*W29/SUMPRODUCT($W$25:$W$55,$V$25:$V$55) -> 17.595367 | R29: =IF($I$12="","",Q29/$I$12) -> 9.7752038 | S29: =IF(W29<>"",IF(D29<>"",D29,($I$8-SUM($S$25:S28))*V29*W29/SUMPRODUCT($W29:$W$55,$V29:$V$55)),"") -> 51254 | T29: =IF(W29<>"",IF(E29<>"",E29,($I$9-SUM($T$25:T28))*V29*W29/SUMPRODUCT($W29:$W$55,$V29:$V$55)),"") -> 7 | U29: =IF(W29<>"",IF(E29<>"",E29,($I$9-SUM($T$25:T28))*V29*W29/SUMPRODUCT($W29:$W$55,$V29:$V$55)),"") -> 7 | V29: 0.85 | W29: 0.85
A30: Рогалевич, Уразгильдеева | B30: 45906 | C30: сб | D30: 44165 | E30: 8 | F30: =IF(AND(E30<>"",E30<>0),D30/E30,"") -> 5520.625 | G30: 5 | H30: =IF(AND(G30<>"",G30<>0),D30/G30,"") -> 8833 | I30: 50 | J30: =IF(AND(G30<>"",G30<>0),E30/G30,"") -> 1.6 | K30: 11992 | N30: =IF(AND(I30<>"",I30<>0),G30/I30,"") -> 0.1 | O30: =D30/P30 -> 0.30225014 | P30: =$I$8*V30*W30/SUMPRODUCT($W$25:$W$55,$V$25:$V$55) -> 146120.69 | Q30: =$I$9*V30*W30/SUMPRODUCT($W$25:$W$55,$V$25:$V$55) -> 24.353449 | R30: =IF($I$12="","",Q30/$I$12) -> 13.529694 | S30: =IF(W30<>"",IF(D30<>"",D30,($I$8-SUM($S$25:S29))*V30*W30/SUMPRODUCT($W30:$W$55,$V30:$V$55)),"") -> 44165 | T30: =IF(W30<>"",IF(E30<>"",E30,($I$9-SUM($T$25:T29))*V30*W30/SUMPRODUCT($W30:$W$55,$V30:$V$55)),"") -> 8 | U30: =IF(W30<>"",IF(E30<>"",E30,($I$9-SUM($T$25:T29))*V30*W30/SUMPRODUCT($W30:$W$55,$V30:$V$55)),"") -> 8 | V30: 1 | W30: 1
A31: Рогалевич,Уразгильдеева | B31: 45907 | C31: вс | D31: 29958 | E31: 5 | F31: =IF(AND(E31<>"",E31<>0),D31/E31,"") -> 5991.6 | G31: 3 | H31: =IF(AND(G31<>"",G31<>0),D31/G31,"") -> 9986 | I31: 45 | J31: =IF(AND(G31<>"",G31<>0),E31/G31,"") -> 1.6666667 | N31: =IF(AND(I31<>"",I31<>0),G31/I31,"") -> 0.066666667 | O31: =D31/P31 -> 0.20502229 | P31: =$I$8*V31*W31/SUMPRODUCT($W$25:$W$55,$V$25:$V$55) -> 146120.69 | Q31: =$I$9*V31*W31/SUMPRODUCT($W$25:$W$55,$V$25:$V$55) -> 24.353449 | R31: =IF($I$12="","",Q31/$I$12) -> 13.529694 | S31: =IF(W31<>"",IF(D31<>"",D31,($I$8-SUM($S$25:S30))*V31*W31/SUMPRODUCT($W31:$W$55,$V31:$V$55)),"") -> 29958 | T31: =IF(W31<>"",IF(E31<>"",E31,($I$9-SUM($T$25:T30))*V31*W31/SUMPRODUCT($W31:$W$55,$V31:$V$55)),"") -> 5 | U31: =IF(W31<>"",IF(E31<>"",E31,($I$9-SUM($T$25:T30))*V31*W31/SUMPRODUCT($W31:$W$55,$V31:$V$55)),"") -> 5 | V31: 1 | W31: 1
A32: Рогалевич,Уразгильдеева | B32: 45908 | C32: пн | D32: =83956+10903+14292+39335+65862 -> 214348 | E32: 28 | F32: =IF(AND(E32<>"",E32<>0),D32/E32,"") -> 7655.2857 | G32: 16 | H32: =IF(AND(G32<>"",G32<>0),D32/G32,"") -> 13396.75 | I32: 100 | J32: =IF(AND(G32<>"",G32<>0),E32/G32,"") -> 1.75 | K32: 83956 | L32: 10903 | M32: 14292 | N32: =IF(AND(I32<>"",I32<>0),G32/I32,"") -> 0.16 | O32: =D32/P32 -> 2.0156051 | P32: =$I$8*V32*W32/SUMPRODUCT($W$25:$W$55,$V$25:$V$55) -> 106344.24 | Q32: =$I$9*V32*W32/SUMPRODUCT($W$25:$W$55,$V$25:$V$55) -> 17.724041 | R32: =IF($I$12="","",Q32/$I$12) -> 9.8466893 | S32: =IF(W32<>"",IF(D32<>"",D32,($I$8-SUM($S$25:S31))*V32*W32/SUMPRODUCT($W32:$W$55,$V32:$V$55)),"") -> 214348 | T32: =IF(W32<>"",IF(E32<>"",E32,($I$9-SUM($T$25:T31))*V32*W32/SUMPRODUCT($W32:$W$55,$V32:$V$55)),"") -> 28 | U32: =IF(W32<>"",IF(E32<>"",E32,($I$9-SUM($T$25:T31))*V32*W32/SUMPRODUCT($W32:$W$55,$V32:$V$55)),"") -> 28 | V32: 0.85310234 | W32: 0.85310234
A33: Рогалевич | B33: 45909 | C33: вт | D33: =24992+65099+23902 -> 113993 | E33: 17 | F33: =IF(AND(E33<>"",E33<>0),D33/E33,"") -> 6705.4706 | G33: 13 | H33: =IF(AND(G33<>"",G33<>0),D33/G33,"") -> 8768.6923 | I33: 80 | J33: =IF(AND(G33<>"",G33<>0),E33/G33,"") -> 1.3076923 | K33: 24992 | L33: 23902 | N33: =IF(AND(I33<>"",I33<>0),G33/I33,"") -> 0.1625 | O33: =D33/P33 -> 1.0719245 | P33: =$I$8*V33*W33/SUMPRODUCT($W$25:$W$55,$V$25:$V$55) -> 106344.24 | Q33: =$I$9*V33*W33/SUMPRODUCT($W$25:$W$55,$V$25:$V$55) -> 17.724041 | R33: =IF($I$12="","",Q33/$I$12) -> 9.8466893 | S33: =IF(W33<>"",IF(D33<>"",D33,($I$8-SUM($S$25:S32))*V33*W33/SUMPRODUCT($W33:$W$55,$V33:$V$55)),"") -> 113993 | T33: =IF(W33<>"",IF(E33<>"",E33,($I$9-SUM($T$25:T32))*V33*W33/SUMPRODUCT($W33:$W$55,$V33:$V$55)),"") -> 17 | U33: =IF(W33<>"",IF(E33<>"",E33,($I$9-SUM($T$25:T32))*V33*W33/SUMPRODUCT($W33:$W$55,$V33:$V$55)),"") -> 17 | V33: 0.85310234 | W33: 0.85310234
A34: Рогалевич,Уразгильдеева | B34: 45910 | C34: ср | D34: =9992+4892+16403+7990+28243 -> 67520 | E34: 13 | F34: =IF(AND(E34<>"",E34<>0),D34/E34,"") -> 5193.8462 | G34: 7 | H34: =IF(AND(G34<>"",G34<>0),D34/G34,"") -> 9645.7143 | I34: =13+74 -> 87 | J34: =IF(AND(G34<>"",G34<>0),E34/G34,"") -> 1.8571429 | K34: 17982 | L34: 16403 | N34: =IF(AND(I34<>"",I34<>0),G34/I34,"") -> 0.08045977 | O34: =D34/P34 -> 0.63491918 | P34: =$I$8*V34*W34/SUMPRODUCT($W$25:$W$55,$V$25:$V$55) -> 106344.24 | Q34: =$I$9*V34*W34/SUMPRODUCT($W$25:$W$55,$V$25:$V$55) -> 17.724041 | R34: =IF($I$12="","",Q34/$I$12) -> 9.8466893 | S34: =IF(W34<>"",IF(D34<>"",D34,($I$8-SUM($S$25:S33))*V34*W34/SUMPRODUCT($W34:$W$55,$V34:$V$55)),"") -> 67520 | T34: =IF(W34<>"",IF(E34<>"",E34,($I$9-SUM($T$25:T33))*V34*W34/SUMPRODUCT($W34:$W$55,$V34:$V$55)),"") -> 13 | U34: =IF(W34<>"",IF(E34<>"",E34,($I$9-SUM($T$25:T33))*V34*W34/SUMPRODUCT($W34:$W$55,$V34:$V$55)),"") -> 13 | V34: 0.85310234 | W34: 0.85310234
A35: Рогалевич,Уразгильдеева | B35: 45911 | C35: чт | D35: 149353 | E35: 17 | F35: =IF(AND(E35<>"",E35<>0),D35/E35,"") -> 8785.4706 | G35: 6 | H35: =IF(AND(G35<>"",G35<>0),D35/G35,"") -> 24892.167 | I35: =12+79 -> 91 | J35: =IF(AND(G35<>"",G35<>0),E35/G35,"") -> 2.8333333 | K35: 70336 | N35: =IF(AND(I35<>"",I35<>0),G35/I35,"") -> 0.065934066 | O35: =D35/P35 -> 1.4044296 | P35: =$I$8*V35*W35/SUMPRODUCT($W$25:$W$55,$V$25:$V$55) -> 106344.24 | Q35: =$I$9*V35*W35/SUMPRODUCT($W$25:$W$55,$V$25:$V$55) -> 17.724041 | R35: =IF($I$12="","",Q35/$I$12) -> 9.8466893 | S35: =IF(W35<>"",IF(D35<>"",D35,($I$8-SUM($S$25:S34))*V35*W35/SUMPRODUCT($W35:$W$55,$V35:$V$55)),"") -> 149353 | T35: =IF(W35<>"",IF(E35<>"",E35,($I$9-SUM($T$25:T34))*V35*W35/SUMPRODUCT($W35:$W$55,$V35:$V$55)),"") -> 17 | U35: =IF(W35<>"",IF(E35<>"",E35,($I$9-SUM($T$25:T34))*V35*W35/SUMPRODUCT($W35:$W$55,$V35:$V$55)),"") -> 17 | V35: 0.85310234 | W35: 0.85310234
A36: Рогалевич | B36: 45912 | C36: пт | D36: =109604+20000+32175+102415 -> 264194 | E36: 31 | F36: =IF(AND(E36<>"",E36<>0),D36/E36,"") -> 8522.3871 | G36: 20 | H36: =IF(AND(G36<>"",G36<>0),D36/G36,"") -> 13209.7 | I36: 131 | J36: =IF(AND(G36<>"",G36<>0),E36/G36,"") -> 1.55 | K36: 109604 | L36: 20000 | M36: 32175 | N36: =IF(AND(I36<>"",I36<>0),G36/I36,"") -> 0.15267176 | O36: =D36/P36 -> 1.8080533 | P36: =$I$8*V36*W36/SUMPRODUCT($W$25:$W$55,$V$25:$V$55) -> 146120.69 | Q36: =$I$9*V36*W36/SUMPRODUCT($W$25:$W$55,$V$25:$V$55) -> 24.353449 | R36: =IF($I$12="","",Q36/$I$12) -> 13.529694 | S36: =IF(W36<>"",IF(D36<>"",D36,($I$8-SUM($S$25:S35))*V36*W36/SUMPRODUCT($W36:$W$55,$V36:$V$55)),"") -> 264194 | T36: =IF(W36<>"",IF(E36<>"",E36,($I$9-SUM($T$25:T35))*V36*W36/SUMPRODUCT($W36:$W$55,$V36:$V$55)),"") -> 31 | U36: =IF(W36<>"",IF(E36<>"",E36,($I$9-SUM($T$25:T35))*V36*W36/SUMPRODUCT($W36:$W$55,$V36:$V$55)),"") -> 31 | V36: 1 | W36: 1
A37: Рогалевич,Уразгильдеева | B37: 45913 | C37: сб | D37: =7992+68071+53126 -> 129189 | E37: 26 | F37: =IF(AND(E37<>"",E37<>0),D37/E37,"") -> 4968.8077 | G37: 15 | H37: =IF(AND(G37<>"",G37<>0),D37/G37,"") -> 8612.6 | I37: =55+93 -> 148 | J37: =IF(AND(G37<>"",G37<>0),E37/G37,"") -> 1.7333333 | K37: 7992 | N37: =IF(AND(I37<>"",I37<>0),G37/I37,"") -> 0.10135135 | O37: =D37/P37 -> 0.88412528 | P37: =$I$8*V37*W37/SUMPRODUCT($W$25:$W$55,$V$25:$V$55) -> 146120.69 | Q37: =$I$9*V37*W37/SUMPRODUCT($W$25:$W$55,$V$25:$V$55) -> 24.353449 | R37: =IF($I$12="","",Q37/$I$12) -> 13.529694 | S37: =IF(W37<>"",IF(D37<>"",D37,($I$8-SUM($S$25:S36))*V37*W37/SUMPRODUCT($W37:$W$55,$V37:$V$55)),"") -> 129189 | T37: =IF(W37<>"",IF(E37<>"",E37,($I$9-SUM($T$25:T36))*V37*W37/SUMPRODUCT($W37:$W$55,$V37:$V$55)),"") -> 26 | U37: =IF(W37<>"",IF(E37<>"",E37,($I$9-SUM($T$25:T36))*V37*W37/SUMPRODUCT($W37:$W$55,$V37:$V$55)),"") -> 26 | V37: 1 | W37: 1
A38: Рогалевич,Уразгильдеева | B38: 45914 | C38: вс | D38: 135071 | E38: 22 | F38: =IF(AND(E38<>"",E38<>0),D38/E38,"") -> 6139.5909 | G38: 14 | H38: =IF(AND(G38<>"",G38<>0),D38/G38,"") -> 9647.9286 | I38: =7+92 -> 99 | J38: =IF(AND(G38<>"",G38<>0),E38/G38,"") -> 1.5714286 | K38: 36719 | M38: 12384 | N38: =IF(AND(I38<>"",I38<>0),G38/I38,"") -> 0.14141414 | O38: =D38/P38 -> 0.92437968 | P38: =$I$8*V38*W38/SUMPRODUCT($W$25:$W$55,$V$25:$V$55) -> 146120.69 | Q38: =$I$9*V38*W38/SUMPRODUCT($W$25:$W$55,$V$25:$V$55) -> 24.353449 | R38: =IF($I$12="","",Q38/$I$12) -> 13.529694 | S38: =IF(W38<>"",IF(D38<>"",D38,($I$8-SUM($S$25:S37))*V38*W38/SUMPRODUCT($W38:$W$55,$V38:$V$55)),"") -> 135071 | T38: =IF(W38<>"",IF(E38<>"",E38,($I$9-SUM($T$25:T37))*V38*W38/SUMPRODUCT($W38:$W$55,$V38:$V$55)),"") -> 22 | U38: =IF(W38<>"",IF(E38<>"",E38,($I$9-SUM($T$25:T37))*V38*W38/SUMPRODUCT($W38:$W$55,$V38:$V$55)),"") -> 22 | V38: 1 | W38: 1
A39: Рогалевич,Уразгильдеева | B39: 45915 | C39: пн | D39: 14503 | E39: 1 | F39: =IF(AND(E39<>"",E39<>0),D39/E39,"") -> 14503 | G39: 1 | H39: =IF(AND(G39<>"",G39<>0),D39/G39,"") -> 14503 | I39: =8+41 -> 49 | J39: =IF(AND(G39<>"",G39<>0),E39/G39,"") -> 1 | L39: 14503 | N39: =IF(AND(I39<>"",I39<>0),G39/I39,"") -> 0.020408163 | O39: =D39/P39 -> 0.13637786 | P39: =$I$8*V39*W39/SUMPRODUCT($W$25:$W$55,$V$25:$V$55) -> 106344.24 | Q39: =$I$9*V39*W39/SUMPRODUCT($W$25:$W$55,$V$25:$V$55) -> 17.724041 | R39: =IF($I$12="","",Q39/$I$12) -> 9.8466893 | S39: =IF(W39<>"",IF(D39<>"",D39,($I$8-SUM($S$25:S38))*V39*W39/SUMPRODUCT($W39:$W$55,$V39:$V$55)),"") -> 14503 | T39: =IF(W39<>"",IF(E39<>"",E39,($I$9-SUM($T$25:T38))*V39*W39/SUMPRODUCT($W39:$W$55,$V39:$V$55)),"") -> 1 | U39: =IF(W39<>"",IF(E39<>"",E39,($I$9-SUM($T$25:T38))*V39*W39/SUMPRODUCT($W39:$W$55,$V39:$V$55)),"") -> 1 | V39: 0.85310234 | W39: 0.85310234
A40: Рогалевич,Уразгильдеева | B40: 45916 | C40: вт | D40: 40364 | E40: 8 | F40: =IF(AND(E40<>"",E40<>0),D40/E40,"") -> 5045.5 | G40: 6 | H40: =IF(AND(G40<>"",G40<>0),D40/G40,"") -> 6727.3333 | I40: =7+74 -> 81 | J40: =IF(AND(G40<>"",G40<>0),E40/G40,"") -> 1.3333333 | N40: =IF(AND(I40<>"",I40<>0),G40/I40,"") -> 0.074074074 | O40: =D40/P40 -> 0.3795598 | P40: =$I$8*V40*W40/SUMPRODUCT($W$25:$W$55,$V$25:$V$55) -> 106344.24 | Q40: =$I$9*V40*W40/SUMPRODUCT($W$25:$W$55,$V$25:$V$55) -> 17.724041 | R40: =IF($I$12="","",Q40/$I$12) -> 9.8466893 | S40: =IF(W40<>"",IF(D40<>"",D40,($I$8-SUM($S$25:S39))*V40*W40/SUMPRODUCT($W40:$W$55,$V40:$V$55)),"") -> 40364 | T40: =IF(W40<>"",IF(E40<>"",E40,($I$9-SUM($T$25:T39))*V40*W40/SUMPRODUCT($W40:$W$55,$V40:$V$55)),"") -> 8 | U40: =IF(W40<>"",IF(E40<>"",E40,($I$9-SUM($T$25:T39))*V40*W40/SUMPRODUCT($W40:$W$55,$V40:$V$55)),"") -> 8 | V40: 0.85310234 | W40: 0.85310234
A41: Рогалевич | B41: 45917 | C41: ср | D41: =8992+70868 -> 79860 | E41: 15 | F41: =IF(AND(E41<>"",E41<>0),D41/E41,"") -> 5324 | G41: 6 | H41: =IF(AND(G41<>"",G41<>0),D41/G41,"") -> 13310 | I41: 70 | J41: =IF(AND(G41<>"",G41<>0),E41/G41,"") -> 2.5 | K41: 8992 | N41: =IF(AND(I41<>"",I41<>0),G41/I41,"") -> 0.085714286 | O41: =D41/P41 -> 0.75095743 | P41: =$I$8*V41*W41/SUMPRODUCT($W$25:$W$55,$V$25:$V$55) -> 106344.24 | Q41: =$I$9*V41*W41/SUMPRODUCT($W$25:$W$55,$V$25:$V$55) -> 17.724041 | R41: =IF($I$12="","",Q41/$I$12) -> 9.8466893 | S41: =IF(W41<>"",IF(D41<>"",D41,($I$8-SUM($S$25:S40))*V41*W41/SUMPRODUCT($W41:$W$55,$V41:$V$55)),"") -> 79860 | T41: =IF(W41<>"",IF(E41<>"",E41,($I$9-SUM($T$25:T40))*V41*W41/SUMPRODUCT($W41:$W$55,$V41:$V$55)),"") -> 15 | U41: =IF(W41<>"",IF(E41<>"",E41,($I$9-SUM($T$25:T40))*V41*W41/SUMPRODUCT($W41:$W$55,$V41:$V$55)),"") -> 15 | V41: 0.85310234 | W41: 0.85310234
...

Sheet Конкурс
A1: Сотрудник | B1: Длина чека | C1: КВП | Z1: Итого
D2: 9 | E2: 10 | F2: 11 | G2: 12 | H2: 13 | I2: 14 | J2: 15 | K2: 16 | L2: 17 | M2: 18 | N2: 19 | O2: 20 | P2: 21 | Q2: 22 | R2: 23 | S2: 24 | T2: 25 | U2: 26 | V2: 27 | W2: 28 | X2: 29 | Y2: 30
A3: =График!B29 -> Рогалевич Ирина | B3: ='Рогалевич И. Е. '!J12 -> 1.7514793 | C3: ='Рогалевич И. Е. '!K8 -> 0.96303343 | D3: 2 | E3: 2 | F3: 0 | G3: 0 | H3: 0 | I3: 0 | J3: 0 | K3: 0 | L3: 2 | M3: 0 | N3: 1 | O3: 0 | P3: 1 | Q3: 1 | R3: 1 | S3: 1 | T3: 2 | U3: 0 | V3: 0 | W3: 0 | X3: 0 | Y3: 0 | Z3: =SUM(D3:Y3) -> 13
A4: =График!B28 -> Уразгильдеева Екатерина | B4: ='Уразгильдеева Е. Р. '!J12 -> 1.7884615 | C4: ='Уразгильдеева Е. Р. '!K8 -> 0.82921047 | D4: 0 | E4: 0 | F4: 0 | G4: 0 | H4: 1 | I4: 0 | J4: 0 | K4: 0 | L4: 0 | M4: 0 | N4: 0 | O4: 1 | P4: 0 | Q4: 0 | R4: 1 | S4: 0 | T4: 0 | U4: 0 | V4: 0 | W4: 0 | X4: 0 | Y4: 0 | Z4: =SUM(D4:Y4) -> 3
A5: =График!B27 -> 0 | B5: ='[1]Яковенко А. К'!J12 -> #REF! | C5: ='[1]Яковенко А. К'!K8 -> #REF! | Z5: =SUM(D5:Y5) -> 0

Sheet Св. по пок.
A2: Показатель | D2: ='Ялта, Ленина, 18'!I3 -> ул. Набережная Ленина, 18 | G2: =График!B29 -> Рогалевич Ирина | J2: =График!B28 -> Уразгильдеева Екатерина | M2: =График!B27 -> 0
D3: Факт | F3: Прогноз | G3: Факт | I3: Прогноз | J3: Факт | L3: Прогноз | M3: Факт | O3: Прогноз
A4: Выручка | D4: ='Ялта, Ленина, 18'!K8 -> 0.90412688 | E4: ='Ялта, Ленина, 18'!J8 -> 3134427.1 | F4: ='Ялта, Ленина, 18'!M8 -> 0.90412688 | G4: ='Рогалевич И. Е. '!K8 -> 0.96303343 | H4: ='Рогалевич И. Е. '!J8 -> 1869031 | I4: ='Рогалевич И. Е. '!M8 -> 0.96303343 | J4: ='Уразгильдеева Е. Р. '!K8 -> 0.82921047 | K4: ='Уразгильдеева Е. Р. '!J8 -> 1265396.1 | L4: ='Уразгильдеева Е. Р. '!M8 -> 0.90131573 | M4: ='[1]Яковенко А. К'!K8 -> #REF! | N4: ='[1]Яковенко А. К'!J8 -> #REF! | O4: ='[1]Яковенко А. К'!M8 -> #REF!
A5: Кол-во изделий | D5: ='Ялта, Ленина, 18'!K9 -> 0.83419868 | E5: ='Ялта, Ленина, 18'!J9 -> 482 | F5: ='Ялта, Ленина, 18'!M9 -> 0.83419868 | G5: ='Рогалевич И. Е. '!K9 -> 0.91509845 | H5: ='Рогалевич И. Е. '!J9 -> 296 | I5: ='Рогалевич И. Е. '!M9 -> 0.91509845 | J5: ='Уразгильдеева Е. Р. '!K9 -> 0.73131164 | K5: ='Уразгильдеева Е. Р. '!J9 -> 186 | L5: ='Уразгильдеева Е. Р. '!M9 -> 0.83103596 | M5: ='[1]Яковенко А. К'!K9 -> #REF! | N5: ='[1]Яковенко А. К'!J9 -> #REF! | O5: ='[1]Яковенко А. К'!M9 -> #REF!
A6: Средний чек | D6: ='Ялта, Ленина, 18'!K10 -> 1.0630942 | E6: ='Ялта, Ленина, 18'!J10 -> 11481.418 | F6: ='Ялта, Ленина, 18'!M10 -> 1.0630942 | G6: ='Рогалевич И. Е. '!K10 -> 1.0240144 | H6: ='Рогалевич И. Е. '!J10 -> 11059.355 | I6: ='Рогалевич И. Е. '!M10 -> 1.0240144 | J6: ='Уразгильдеева Е. Р. '!K10 -> 1.1265991 | K6: ='Уразгильдеева Е. Р. '!J10 -> 12167.27 | L6: ='Уразгильдеева Е. Р. '!M10 -> 1.1265991 | M6: ='[1]Яковенко А. К'!K10 -> #REF! | N6: ='[1]Яковенко А. К'!J10 -> #REF! | O6: ='[1]Яковенко А. К'!M10 -> #REF!
A7: Средняя стоимость изделия | D7: ='Ялта, Ленина, 18'!K11 -> 1.0838268 | E7: ='Ялта, Ленина, 18'!J11 -> 6502.9607 | F7: ='Ялта, Ленина, 18'!M11 -> 1.0838268 | G7: ='Рогалевич И. Е. '!K11 -> 1.0523823 | H7: ='Рогалевич И. Е. '!J11 -> 6314.2939 | I7: ='Рогалевич И. Е. '!M11 -> 1.0523823 | J7: ='Уразгильдеева Е. Р. '!K11 -> 1.1338675 | K7: ='Уразгильдеева Е. Р. '!J11 -> 6803.2047 | L7: ='Уразгильдеева Е. Р. '!M11 -> 1.0845689 | M7: ='[1]Яковенко А. К'!K11 -> #REF! | N7: ='[1]Яковенко А. К'!J11 -> #REF! | O7: ='[1]Яковенко А. К'!M11 -> #REF!
A8: Длина чека | D8: ='Ялта, Ленина, 18'!K12 -> 0.98087098 | E8: ='Ялта, Ленина, 18'!J12 -> 1.7655678 | F8: ='Ялта, Ленина, 18'!M12 -> 0.98087098 | G8: ='Рогалевич И. Е. '!K12 -> 0.97304405 | H8: ='Рогалевич И. Е. '!J12 -> 1.7514793 | I8: ='Рогалевич И. Е. '!M12 -> 0.97304405 | J8: ='Уразгильдеева Е. Р. '!K12 -> 0.99358974 | K8: ='Уразгильдеева Е. Р. '!J12 -> 1.7884615 | L8: ='Уразгильдеева Е. Р. '!M12 -> 0.99358974 | M8: ='[1]Яковенко А. К'!K12 -> #REF! | N8: ='[1]Яковенко А. К'!J12 -> #REF! | O8: ='[1]Яковенко А. К'!M12 -> #REF!
A9: Кол-во чеков | D9: ='Ялта, Ленина, 18'!K13 -> 0.85046729 | E9: ='Ялта, Ленина, 18'!J13 -> 273 | F9: ='Ялта, Ленина, 18'!M13 -> 0.85046729 | G9: ='Рогалевич И. Е. '!K13 -> 0.94044915 | H9: ='Рогалевич И. Е. '!J13 -> 169 | I9: ='Рогалевич И. Е. '!M13 -> 0.94044915 | J9: ='Уразгильдеева Е. Р. '!K13 -> 0.73602978 | K9: ='Уразгильдеева Е. Р. '!J13 -> 104 | L9: ='Уразгильдеева Е. Р. '!M13 -> 0.83639748 | M9: ='[1]Яковенко А. К'!K13 -> #REF! | N9: ='[1]Яковенко А. К'!J13 -> #REF! | O9: ='[1]Яковенко А. К'!M13 -> #REF!
A10: Кол-во смен план/отработано | D10: ='Ялта, Ленина, 18'!K14 -> 1 | E10: ='Ялта, Ленина, 18'!J14 -> 30 | G10: ='Рогалевич И. Е. '!K14 -> 1 | H10: ='Рогалевич И. Е. '!J14 -> 30 | J10: ='Уразгильдеева Е. Р. '!K14 -> 1 | K10: ='Уразгильдеева Е. Р. '!J14 -> 22 | M10: ='[1]Яковенко А. К'!K14 -> #REF! | N10: ='[1]Яковенко А. К'!J14 -> #REF!
A11: Средние продажи в смену | D11: ='Ялта, Ленина, 18'!K15 -> 0.90412688 | E11: ='Ялта, Ленина, 18'!J15 -> 104480.9 | F11: ='Ялта, Ленина, 18'!M15 -> 0.90412688 | G11: ='Рогалевич И. Е. '!K15 -> 0.53912282 | H11: ='Рогалевич И. Е. '!J15 -> 62301.033 | I11: ='Рогалевич И. Е. '!M15 -> 0.53912282 | J11: ='Уразгильдеева Е. Р. '!K15 -> 0.49773281 | K11: ='Уразгильдеева Е. Р. '!J15 -> 57518.004 | L11: ='Уразгильдеева Е. Р. '!M15 -> 0.49773281 | M11: ='[1]Яковенко А. К'!K15 -> #REF! | N11: ='[1]Яковенко А. К'!J15 -> #REF! | O11: ='[1]Яковенко А. К'!M15 -> #REF!
A12: Трафик | D12: ='Ялта, Ленина, 18'!K17 -> 1.0214953 | E12: ='Ялта, Ленина, 18'!J17 -> 2186 | F12: ='Ялта, Ленина, 18'!M17 -> 1.0214953 | G12: ='Рогалевич И. Е. '!K17 -> 1.0680219 | H12: ='Рогалевич И. Е. '!J17 -> 1279.5 | I12: ='Рогалевич И. Е. '!M17 -> 1.0680219 | J12: ='Уразгильдеева Е. Р. '!K17 -> 0.96232355 | K12: ='Уразгильдеева Е. Р. '!J17 -> 906.5 | L12: ='Уразгильдеева Е. Р. '!M17 -> 0.96232355 | M12: ='[1]Яковенко А. К'!K17 -> #REF! | N12: ='[1]Яковенко А. К'!J17 -> #REF! | O12: ='[1]Яковенко А. К'!M17 -> #REF!
A13: UNOde50 | D13: ='Ялта, Ленина, 18'!S19 -> 0.76378922 | E13: ='Ялта, Ленина, 18'!T18 -> 779065 | F13: ='Ялта, Ленина, 18'!T19 -> 0.76378922 | G13: ='Рогалевич И. Е. '!S19 -> 0.70517047 | H13: ='Рогалевич И. Е. '!T18 -> 402662 | I13: ='Рогалевич И. Е. '!T19 -> 0.70517047 | J13: ='Уразгильдеева Е. Р. '!S19 -> 0.83833961 | K13: ='Уразгильдеева Е. Р. '!T18 -> 376403 | L13: ='Уразгильдеева Е. Р. '!T19 -> 0.83833961 | M13: ='[1]Яковенко А. К'!S19 -> #REF! | N13: ='[1]Яковенко А. К'!T18 -> #REF! | O13: ='[1]Яковенко А. К'!T19 -> #REF!
A14: IS | D14: ='Ялта, Ленина, 18'!S13 -> 0.32916863 | E14: ='Ялта, Ленина, 18'!T12 -> 167876 | F14: ='Ялта, Ленина, 18'!T13 -> 0.32916863 | G14: ='Рогалевич И. Е. '!S13 -> 0.38955633 | H14: ='Рогалевич И. Е. '!T12 -> 111221 | I14: ='Рогалевич И. Е. '!T13 -> 0.38955633 | J14: ='Уразгильдеева Е. Р. '!S13 -> 0.2523685 | K14: ='Уразгильдеева Е. Р. '!T12 -> 56655 | L14: ='Уразгильдеева Е. Р. '!T13 -> 0.2523685 | M14: ='[1]Яковенко А. К'!S13 -> #REF! | N14: ='[1]Яковенко А. К'!T12 -> #REF! | O14: ='[1]Яковенко А. К'!T13 -> #REF!
A15: ='Ялта, Ленина, 18'!M23 -> Agafi | D15: ='Ялта, Ленина, 18'!V13 -> 0.45168958 | E15: ='Ялта, Ленина, 18'!W12 -> 216811 | F15: ='Ялта, Ленина, 18'!W13 -> 0.45168958 | G15: ='Рогалевич И. Е. '!V13 -> 0.46554247 | H15: ='Рогалевич И. Е. '!W12 -> 125097 | I15: ='Рогалевич И. Е. '!W13 -> 0.46554247 | J15: ='Уразгильдеева Е. Р. '!V13 -> 0.43407171 | K15: ='Уразгильдеева Е. Р. '!W12 -> 91714 | L15: ='Уразгильдеева Е. Р. '!W13 -> 0.43407171 | M15: ='[1]Яковенко А. К'!V13 -> #REF! | N15: ='[1]Яковенко А. К'!W12 -> #REF! | O15: ='[1]Яковенко А. К'!W13 -> #REF!
A16: Отклонение от плана | D16: ='Ялта, Ленина, 18'!J16 -> -332372.92 | G16: ='Рогалевич И. Е. '!N8 -> -71743.795 | J16: ='Уразгильдеева Е. Р. '!N8 -> -150594.68 | M16: ='[1]Яковенко А. К'!N8 -> #REF!

Sheet План на день
A1: Выручка | D1: 135000
A2: Кол-во изделий | D2: =D1/D4 -> 22.5
A3: Средний чек | D3: =D4*D5 -> 10800
A4: Средняя стоимость изделия | D4: ='Ялта, Ленина, 18'!I11 -> 6000
A5: Длина чека | D5: ='Ялта, Ленина, 18'!I12 -> 1.8
A6: Кол-во чеков | D6: =IF(D5<>0,D2/D5,"") -> 12.5
A7: Конверсия | D7: ='Ялта, Ленина, 18'!I20 -> 0.15
A8: IS | D8: =('Ялта, Ленина, 18'!S12-'Ялта, Ленина, 18'!T12)/('Ялта, Ленина, 18'!I14-'Ялта, Ленина, 18'!J14) -> #DIV/0!
A9: UNOde50 | D9: =('Ялта, Ленина, 18'!S18-'Ялта, Ленина, 18'!T18)/('Ялта, Ленина, 18'!I14-'Ялта, Ленина, 18'!J14) -> #DIV/0!
A10: ='Ялта, Ленина, 18'!M23 -> Agafi | D10: =('Ялта, Ленина, 18'!V12-'Ялта, Ленина, 18'!W12)/('Ялта, Ленина, 18'!I14-'Ялта, Ленина, 18'!J14) -> #DIV/0!

Sheet Рогалевич И. Е. 
B1: =TODAY()-1 -> 45939
B2: (отчетная дата) | J2: ЕЖЕДНЕВНЫЙ ОТЧЕТ О ПРОДАЖАХ
B3: Осталось до выполнения плана!!! | J3: =График!B29 -> Рогалевич Ирина
C4: =I8-D57 -> 71743.795 | E4: =IF(I8<>0,C4/I8,0) -> 0.036966574
F6: Целевые показатели
F7: Показатель | I7: План | J7: Факт | K7: % выполнения | L7: Прогноз выполнения | M7: % выполнения по прогнозу | N7: Отклонение | O7: Факт аналогичного месяца прошлого года | P7: Отклонение LFL
F8: Выручка | I8: ='Ялта, Ленина, 18'!I8/График!AJ31*График!AJ29 -> 1940774.8 | J8: =D57 -> 1869031 | K8: =IF(AND(I8<>"",I8<>0,J8<>""),J8/I8,"") -> 0.96303343 | L8: =IF(SUMIF($D$25:$D$56,">=0",$P$25:$P$56)<>0,I8*D57/SUMIF($D$25:$D$56,">=0",$P$25:$P$56),0) -> 1869031 | M8: =IF(AND(I8<>"",I8<>0,L8<>"",L8<>0),L8/I8,"") -> 0.96303343 | N8: =IF(AND(J8<>0,J8<>"",I8<>0,I8<>""),L8-I8,"") -> -71743.795 | P8: =IF(AND(O8<>"",O8<>0,L8<>"",L8<>0),-O8+L8,"") | Q8: =IF(AND(P8<>"",P8<>0,O8<>0,O8<>""),P8/O8,"")
F9: Кол-во изделий | I9: =I8/I11 -> 323.46247 | J9: =E57 -> 296 | K9: =IF(AND(I9<>"",I9<>0,J9<>""),J9/I9,"") -> 0.91509845 | L9: =IF(SUMIF($E$25:$E$54,">=0",$Q$25:$Q$54)<>0,I9*E57/SUMIF($E$25:$E$54,">=0",$Q$25:$Q$54),0) -> 296 | M9: =IF(AND(I9<>"",I9<>0,L9<>"",L9<>0),L9/I9,"") -> 0.91509845 | N9: =IF(AND(J9<>0,J9<>"",I9<>0,I9<>""),L9-I9,"") -> -27.462466 | O9: =O8/O11 -> #DIV/0! | P9: =IF(AND(O9<>"",O9<>0,L9<>"",L9<>0),-O9+L9,"") -> #DIV/0! | Q9: =IF(AND(P9<>"",P9<>0,O9<>0,O9<>""),P9/O9,"") -> #DIV/0!
F10: Средний чек | I10: =I11*I12 -> 10800 | J10: =H57 -> 11059.355 | K10: =IF(AND(I10<>"",I10<>0,J10<>""),J10/I10,"") -> 1.0240144 | L10: =J10 -> 11059.355 | M10: =IF(AND(I10<>"",I10<>0,L10<>"",L10<>0),L10/I10,"") -> 1.0240144 | N10: =IF(AND(J10<>0,J10<>"",I10<>0,I10<>""),L10-I10,"") -> 259.35503 | O10: =O11*O12 -> 0 | P10: =IF(AND(O10<>"",O10<>0,L10<>"",L10<>0),-O10+L10,"") | Q10: =IF(AND(P10<>"",P10<>0,O10<>0,O10<>""),P10/O10,"") | S10: IS | V10: =M23 -> Agafi
F11: Средняя стоимость изделия | I11: ='Ялта, Ленина, 18'!I11 -> 6000 | J11: =F57 -> 6314.2939 | K11: =IF(AND(I11<>"",I11<>0,J11<>""),J11/I11,"") -> 1.0523823 | L11: =IF(L9>0,L8/L9,"") -> 6314.2939 | M11: =IF(AND(I11<>"",I11<>0,L11<>"",L11<>0),L11/I11,"") -> 1.0523823 | N11: =IF(AND(J11<>0,J11<>"",I11<>0,I11<>""),L11-I11,"") -> 314.29392 | P11: =IF(AND(O11<>"",O11<>0,L11<>"",L11<>0),-O11+L11,"") | Q11: =IF(AND(P11<>"",P11<>0,O11<>0,O11<>""),P11/O11,"")
F12: Длина чека | I12: ='Ялта, Ленина, 18'!I12 -> 1.8 | J12: =J57 -> 1.7514793 | K12: =IF(AND(I12<>"",I12<>0,J12<>""),J12/I12,"") -> 0.97304405 | L12: =J12 -> 1.7514793 | M12: =IF(AND(I12<>"",I12<>0,L12<>"",L12<>0),L12/I12,"") -> 0.97304405 | N12: =IF(AND(J12<>0,J12<>"",I12<>0,I12<>""),L12-I12,"") -> -0.04852071 | P12: =IF(AND(O12<>"",O12<>0,L12<>"",L12<>0),-O12+L12,"") | Q12: =IF(AND(P12<>"",P12<>0,O12<>0,O12<>""),P12/O12,"") | S12: ='Ялта, Ленина, 18'!S12*График!AJ29/График!AJ31 -> 285506.85 | T12: =L57 -> 111221 | V12: ='Ялта, Ленина, 18'!V12/График!AJ31*График!AJ29 -> 268712.33 | W12: =M57 -> 125097
F13: Кол-во чеков | I13: =IF(I12<>0,I9/I12,"") -> 179.70137 | J13: =G57 -> 169 | K13: =IF(AND(I13<>"",I13<>0,J13<>""),J13/I13,"") -> 0.94044915 | L13: =IF(SUMIF($G$25:$G$54,">=0",$R$25:$R$54)<>0,I13*G57/SUMIF($G$25:$G$54,">=0",$R$25:$R$54),"") -> 169 | M13: =IF(AND(I13<>"",I13<>0,L13<>"",L13<>0),L13/I13,"") -> 0.94044915 | N13: =IF(AND(J13<>0,J13<>"",I13<>0,I13<>""),L13-I13,"") -> -10.70137 | P13: =IF(AND(O13<>"",O13<>0,L13<>"",L13<>0),-O13+L13,"") | Q13: =IF(AND(P13<>"",P13<>0,O13<>0,O13<>""),P13/O13,"") | S13: =T12/S12 -> 0.38955633 | T13: =S13/J14*I14 -> 0.38955633 | V13: =W12/V12 -> 0.46554247 | W13: =V13/J14*I14 -> 0.46554247
F14: Кол-во смен план/отработано | I14: =График!AI29 -> 30 | J14: 30 | K14: =IF(AND(I14<>"",I14<>0,J14<>""),J14/I14,"") -> 1 | L14: =I14 -> 30 | M14: =IF(AND(I14<>"",I14<>0,L14<>"",L14<>0),L14/I14,"") -> 1 | N14: =IF(AND(J14<>0,J14<>"",I14<>0,I14<>""),L14-I14,"") -> 0 | P14: =IF(AND(O14<>"",O14<>0,L14<>"",L14<>0),-O14+L14,"") | Q14: =IF(AND(P14<>"",P14<>0,O14<>0,O14<>""),P14/O14,"")
F15: Средние продажи в смену | I15: ='Ялта, Ленина, 18'!I15 -> 115560 | J15: =J8/J14 -> 62301.033 | K15: =IF(AND(I15<>"",I15<>0,J15<>""),J15/I15,"") -> 0.53912282 | L15: =J15 -> 62301.033 | M15: =IF(AND(I15<>"",I15<>0,L15<>"",L15<>0),L15/I15,"") -> 0.53912282 | N15: =IF(AND(J15<>0,J15<>"",I15<>0,I15<>""),L15-I15,"") -> -53258.967 | P15: =IF(AND(O15<>"",O15<>0,L15<>"",L15<>0),-O15+L15,"") | Q15: =IF(AND(P15<>"",P15<>0,O15<>0,O15<>""),P15/O15,"")
F16: Отставание/Перевыполнение | J16: =J8-I15*J14 -> -1597769 | K16: =IF(AND(I16<>"",I16<>0,J16<>""),J16/I16,"") | L16: =J16 -> -1597769 | M16: =IF(AND(I16<>"",I16<>0,L16<>"",L16<>0),L16/I16,"") | N16: =IF(AND(J16<>0,J16<>"",I16<>0,I16<>""),L16-I16,"") | P16: =IF(AND(O16<>"",O16<>0,L16<>"",L16<>0),-O16+L16,"") | Q16: =IF(AND(P16<>"",P16<>0,O16<>0,O16<>""),P16/O16,"") | S16: UNOde50
F17: Трафик | I17: ='Ялта, Ленина, 18'!I17/График!AJ31*График!AJ29 -> 1198.0091 | J17: =I57 -> 1279.5 | K17: =IF(AND(I17<>"",I17<>0,J17<>""),J17/I17,"") -> 1.0680219 | L17: =J17/J14*I14 -> 1279.5 | M17: =IF(AND(I17<>"",I17<>0,L17<>"",L17<>0),L17/I17,"") -> 1.0680219 | N17: =IF(AND(J17<>0,J17<>"",I17<>0,I17<>""),L17-I17,"") -> 81.490868 | P17: =IF(AND(O17<>"",O17<>0,L17<>"",L17<>0),-O17+L17,"") | Q17: =IF(AND(P17<>"",P17<>0,O17<>0,O17<>""),P17/O17,"")
K18: =IF(AND(I18<>"",I18<>0,J18<>""),J18/I18,"") | L18: =J18 -> 0 | M18: =IF(AND(I18<>"",I18<>0,L18<>"",L18<>0),L18/I18,"") | N18: =IF(AND(J18<>0,J18<>"",I18<>0,I18<>""),L18-I18,"") | O18: 0 | P18: =IF(AND(O18<>"",O18<>0,L18<>"",L18<>0),-O18+L18,"") | Q18: =IF(AND(P18<>"",P18<>0,O18<>0,O18<>""),P18/O18,"") | S18: ='Ялта, Ленина, 18'!S18*График!AJ29/График!AJ31 -> 571013.7 | T18: =K57 -> 402662
K19: =IF(AND(I19<>"",I19<>0,J19<>""),J19/I19,"") | L19: =J19 -> 0 | M19: =IF(AND(I19<>"",I19<>0,L19<>"",L19<>0),L19/I19,"") | N19: =IF(AND(J19<>0,J19<>"",I19<>0,I19<>""),L19-I19,"") | O19: 0 | P19: =IF(AND(O19<>"",O19<>0,L19<>"",L19<>0),-O19+L19,"") | Q19: =IF(AND(P19<>"",P19<>0,O19<>0,O19<>""),P19/O19,"") | S19: =T18/S18 -> 0.70517047 | T19: =S19/J14*I14 -> 0.70517047
F20: Конверсия план/факт | I20: ='Ялта, Ленина, 18'!I20 -> 0.15 | J20: =N57 -> 0.13208284 | K20: =J20/I20 -> 0.8805523 | L20: =IF(AND(K8<>0,I14<>0,I57<>0),(I57*N57+(I57/K8-I57)*I20)/(I57/K8),0) -> 0.13274518 | M20: =IF(AND(I20<>"",I20<>0,L20<>"",L20<>0),L20/I20,"") -> 0.88496787 | N20: =IF(AND(J20<>0,J20<>"",I20<>0,I20<>""),L20-I20,"") -> -0.017254819 | P20: =IF(AND(O20<>"",O20<>0,L20<>"",L20<>0),-O20+L20,"") | Q20: =IF(AND(P20<>"",P20<>0,O20<>0,O20<>""),P20/O20,"")
B22: Факт продаж за месяц | O22: % выполнения дневного плана | P22: Раcпределение плана по дням
B23: Дата | C23: День недели | D23: Выручка (руб) | E23: Кол-во единиц (шт.) | F23: Средняя стоимость изделия (руб.) | G23: Количество чеков (шт.) | H23: Средняя сумма чека (руб.) | I23: Трафик | J23: Длина чека (шт.) | K23: UNOde50 | L23: IS | M23: Agafi | N23: Конверсия (%) | P23: выручка, план | Q23: кол-во ед, план | R23: Кол-во чеков, план | S23: выручка, скорректир.план | T23: кол-во ед, скорр. план | U23: кол-во чеков, скорр. план | V23: Коэфф. Дня Недели | W23: Специфика месяца
B24: 1 | C24: 2 | D24: 3 | E24: 4 | F24: 5 | G24: 6 | H24: 7 | I24: 8 | J24: 9 | K24: 10 | L24: 11 | M24: 12 | N24: 13 | P24: 1 | Q24: 2 | R24: 3 | S24: 4 | T24: 5 | U24: 6 | V24: 10 | W24: 11
A25: 1 | B25: 45901 | C25: пн | D25: =8592+36205 -> 44797 | E25: 7 | F25: =IF(AND(E25<>"",E25<>0),D25/E25,"") -> 6399.5714 | G25: 4 | H25: =IF(AND(G25<>"",G25<>0),D25/G25,"") -> 11199.25 | I25: 50 | J25: =IF(AND(G25<>"",G25<>0),E25/G25,"") -> 1.75 | K25: 8592 | N25: =IF(AND(I25<>"",I25<>0),G25/I25,"") -> 0.08 | O25: =D25/P25 -> 0.57705047 | P25: =$I$8*V25*W25/SUMPRODUCT($W$25:$W$56,$V$25:$V$56) -> 77630.992 | Q25: =$I$9*V25*W25/SUMPRODUCT($W$25:$W$56,$V$25:$V$56) -> 12.938499 | R25: =IF($I$12="","",Q25/$I$12) -> 7.1880548 | S25: =IF(D25<>"",D25,P25) -> 44797 | T25: =IF(E25<>"",E25,Q25) -> 7 | U25: =IF(G25<>"",G25,R25) -> 4 | V25: 1 | W25: 1
A26: 2 | B26: 45902 | C26: вт | D26: =13590+10690+42784 -> 67064 | E26: 11 | F26: =IF(AND(E26<>"",E26<>0),D26/E26,"") -> 6096.7273 | G26: 7 | H26: =IF(AND(G26<>"",G26<>0),D26/G26,"") -> 9580.5714 | I26: 40 | J26: =IF(AND(G26<>"",G26<>0),E26/G26,"") -> 1.5714286 | K26: 10690 | M26: 13590 | N26: =IF(AND(I26<>"",I26<>0),G26/I26,"") -> 0.175 | O26: =D26/P26 -> 0.86388179 | P26: =$I$8*V26*W26/SUMPRODUCT($W$25:$W$56,$V$25:$V$56) -> 77630.992 | Q26: =$I$9*V26*W26/SUMPRODUCT($W$25:$W$58,$V$25:$V$58) -> 12.938499 | R26: =IF($I$12="","",Q26/$I$12) -> 7.1880548 | S26: =IF(W26<>"",IF(D26<>"",D26,($I$8-SUM($S$25:S25))*V26*W26/SUMPRODUCT($W26:$W$56,$V26:$V$56)),"") -> 67064 | T26: =IF(W26<>"",IF(E26<>"",E26,($I$9-SUM($T$25:T25))*V26*W26/SUMPRODUCT($W26:$W$58,$V26:$V$58)),"") -> 11 | U26: =IF(W26<>"",IF($I$12<>"",IF(G26<>"",G26,($I$9/$I$12-SUM($U$25:U25))*V26*W26/SUMPRODUCT($W26:$W$58,$V26:$V$58)),""),"") -> 7 | V26: 1 | W26: 1
A27: 3 | B27: 45903 | C27: ср | D27: =35475+36942 -> 72417 | E27: 10 | F27: =IF(AND(E27<>"",E27<>0),D27/E27,"") -> 7241.7 | G27: 7 | H27: =IF(AND(G27<>"",G27<>0),D27/G27,"") -> 10345.286 | I27: 35 | J27: =IF(AND(G27<>"",G27<>0),E27/G27,"") -> 1.4285714 | K27: 35475 | N27: =IF(AND(I27<>"",I27<>0),G27/I27,"") -> 0.2 | O27: =D27/P27 -> 0.93283621 | P27: =$I$8*V27*W27/SUMPRODUCT($W$25:$W$56,$V$25:$V$56) -> 77630.992 | Q27: =$I$9*V27*W27/SUMPRODUCT($W$25:$W$58,$V$25:$V$58) -> 12.938499 | R27: =IF($I$12="","",Q27/$I$12) -> 7.1880548 | S27: =IF(W27<>"",IF(D27<>"",D27,($I$8-SUM($S$25:S26))*V27*W27/SUMPRODUCT($W27:$W$58,$V27:$V$58)),"") -> 72417 | T27: =IF(W27<>"",IF(E27<>"",E27,($I$9-SUM($T$25:T26))*V27*W27/SUMPRODUCT($W27:$W$58,$V27:$V$58)),"") -> 10 | U27: =IF(W27<>"",IF($I$12<>"",IF(G27<>"",G27,($I$9/$I$12-SUM($U$25:U26))*V27*W27/SUMPRODUCT($W27:$W$58,$V27:$V$58)),""),"") -> 7 | V27: 1 | W27: 1
A28: 4 | B28: 45904 | C28: чт | D28: =55851+7492+51423 -> 114766 | E28: 16 | F28: =IF(AND(E28<>"",E28<>0),D28/E28,"") -> 7172.875 | G28: 11 | H28: =IF(AND(G28<>"",G28<>0),D28/G28,"") -> 10433.273 | I28: 86 | J28: =IF(AND(G28<>"",G28<>0),E28/G28,"") -> 1.4545455 | K28: 55851 | M28: 7492 | N28: =IF(AND(I28<>"",I28<>0),G28/I28,"") -> 0.12790698 | O28: =D28/P28 -> 1.4783529 | P28: =$I$8*V28*W28/SUMPRODUCT($W$25:$W$56,$V$25:$V$56) -> 77630.992 | Q28: =$I$9*V28*W28/SUMPRODUCT($W$25:$W$58,$V$25:$V$58) -> 12.938499 | R28: =IF($I$12="","",Q28/$I$12) -> 7.1880548 | S28: =IF(W28<>"",IF(D28<>"",D28,($I$8-SUM($S$25:S27))*V28*W28/SUMPRODUCT($W28:$W$58,$V28:$V$58)),"") -> 114766 | T28: =IF(W28<>"",IF(E28<>"",E28,($I$9-SUM($T$25:T27))*V28*W28/SUMPRODUCT($W28:$W$58,$V28:$V$58)),"") -> 16 | U28: =IF(W28<>"",IF($I$12<>"",IF(G28<>"",G28,($I$9/$I$12-SUM($U$25:U27))*V28*W28/SUMPRODUCT($W28:$W$58,$V28:$V$58)),""),"") -> 11 | V28: 1 | W28: 1
A29: 5 | B29: 45905 | C29: пт | D29: =16476+9903 -> 26379 | E29: 4 | F29: =IF(AND(E29<>"",E29<>0),D29/E29,"") -> 6594.75 | G29: 4 | H29: =IF(AND(G29<>"",G29<>0),D29/G29,"") -> 6594.75 | I29: 26 | J29: =IF(AND(G29<>"",G29<>0),E29/G29,"") -> 1 | L29: 9903 | N29: =IF(AND(I29<>"",I29<>0),G29/I29,"") -> 0.15384615 | O29: =D29/P29 -> 0.33979986 | P29: =$I$8*V29*W29/SUMPRODUCT($W$25:$W$56,$V$25:$V$56) -> 77630.992 | Q29: =$I$9*V29*W29/SUMPRODUCT($W$25:$W$58,$V$25:$V$58) -> 12.938499 | R29: =IF($I$12="","",Q29/$I$12) -> 7.1880548 | S29: =IF(W29<>"",IF(D29<>"",D29,($I$8-SUM($S$25:S28))*V29*W29/SUMPRODUCT($W29:$W$58,$V29:$V$58)),"") -> 26379 | T29: =IF(W29<>"",IF(E29<>"",E29,($I$9-SUM($T$25:T28))*V29*W29/SUMPRODUCT($W29:$W$58,$V29:$V$58)),"") -> 4 | U29: =IF(W29<>"",IF($I$12<>"",IF(G29<>"",G29,($I$9/$I$12-SUM($U$25:U28))*V29*W29/SUMPRODUCT($W29:$W$58,$V29:$V$58)),""),"") -> 4 | V29: 1 | W29: 1
A30: 6 | B30: 45906 | C30: сб | D30: 27581 | E30: 6 | F30: =IF(AND(E30<>"",E30<>0),D30/E30,"") -> 4596.8333 | G30: 3 | H30: =IF(AND(G30<>"",G30<>0),D30/G30,"") -> 9193.6667 | I30: 27 | J30: =IF(AND(G30<>"",G30<>0),E30/G30,"") -> 2 | N30: =IF(AND(I30<>"",I30<>0),G30/I30,"") -> 0.11111111 | O30: =D30/P30 -> 0.35528337 | P30: =$I$8*V30*W30/SUMPRODUCT($W$25:$W$56,$V$25:$V$56) -> 77630.992 | Q30: =$I$9*V30*W30/SUMPRODUCT($W$25:$W$58,$V$25:$V$58) -> 12.938499 | R30: =IF($I$12="","",Q30/$I$12) -> 7.1880548 | S30: =IF(W30<>"",IF(D30<>"",D30,($I$8-SUM($S$25:S29))*V30*W30/SUMPRODUCT($W30:$W$58,$V30:$V$58)),"") -> 27581 | T30: =IF(W30<>"",IF(E30<>"",E30,($I$9-SUM($T$25:T29))*V30*W30/SUMPRODUCT($W30:$W$58,$V30:$V$58)),"") -> 6 | U30: =IF(W30<>"",IF($I$12<>"",IF(G30<>"",G30,($I$9/$I$12-SUM($U$25:U29))*V30*W30/SUMPRODUCT($W30:$W$58,$V30:$V$58)),""),"") -> 3 | V30: 1 | W30: 1
A31: 7 | B31: 45907 | C31: вс | D31: 19075 | E31: 3 | F31: =IF(AND(E31<>"",E31<>0),D31/E31,"") -> 6358.3333 | G31: 2 | H31: =IF(AND(G31<>"",G31<>0),D31/G31,"") -> 9537.5 | I31: 20 | J31: =IF(AND(G31<>"",G31<>0),E31/G31,"") -> 1.5 | N31: =IF(AND(I31<>"",I31<>0),G31/I31,"") -> 0.1 | O31: =D31/P31 -> 0.24571372 | P31: =$I$8*V31*W31/SUMPRODUCT($W$25:$W$56,$V$25:$V$56) -> 77630.992 | Q31: =$I$9*V31*W31/SUMPRODUCT($W$25:$W$58,$V$25:$V$58) -> 12.938499 | R31: =IF($I$12="","",Q31/$I$12) -> 7.1880548 | S31: =IF(W31<>"",IF(D31<>"",D31,($I$8-SUM($S$25:S30))*V31*W31/SUMPRODUCT($W31:$W$58,$V31:$V$58)),"") -> 19075 | T31: =IF(W31<>"",IF(E31<>"",E31,($I$9-SUM($T$25:T30))*V31*W31/SUMPRODUCT($W31:$W$58,$V31:$V$58)),"") -> 3 | U31: =IF(W31<>"",IF($I$12<>"",IF(G31<>"",G31,($I$9/$I$12-SUM($U$25:U30))*V31*W31/SUMPRODUCT($W31:$W$58,$V31:$V$58)),""),"") -> 2 | V31: 1 | W31: 1
A32: 8 | B32: 45908 | C32: пн | D32: =10903+65862 -> 76765 | E32: 14 | F32: =IF(AND(E32<>"",E32<>0),D32/E32,"") -> 5483.2143 | G32: 7 | H32: =IF(AND(G32<>"",G32<>0),D32/G32,"") -> 10966.429 | I32: 45 | J32: =IF(AND(G32<>"",G32<>0),E32/G32,"") -> 2 | L32: 10903 | N32: =IF(AND(I32<>"",I32<>0),G32/I32,"") -> 0.15555556 | O32: =D32/P32 -> 0.98884477 | P32: =$I$8*V32*W32/SUMPRODUCT($W$25:$W$56,$V$25:$V$56) -> 77630.992 | Q32: =$I$9*V32*W32/SUMPRODUCT($W$25:$W$58,$V$25:$V$58) -> 12.938499 | R32: =IF($I$12="","",Q32/$I$12) -> 7.1880548 | S32: =IF(W32<>"",IF(D32<>"",D32,($I$8-SUM($S$25:S31))*V32*W32/SUMPRODUCT($W32:$W$58,$V32:$V$58)),"") -> 76765 | T32: =IF(W32<>"",IF(E32<>"",E32,($I$9-SUM($T$25:T31))*V32*W32/SUMPRODUCT($W32:$W$58,$V32:$V$58)),"") -> 14 | U32: =IF(W32<>"",IF($I$12<>"",IF(G32<>"",G32,($I$9/$I$12-SUM($U$25:U31))*V32*W32/SUMPRODUCT($W32:$W$58,$V32:$V$58)),""),"") -> 7 | V32: 1 | W32: 1
A33: 9 | B33: 45909 | C33: вт | D33: =24992+23902+65099 -> 113993 | E33: 17 | F33: =IF(AND(E33<>"",E33<>0),D33/E33,"") -> 6705.4706 | G33: 13 | H33: =IF(AND(G33<>"",G33<>0),D33/G33,"") -> 8768.6923 | I33: 80 | J33: =IF(AND(G33<>"",G33<>0),E33/G33,"") -> 1.3076923 | K33: 24992 | L33: 23902 | N33: =IF(AND(I33<>"",I33<>0),G33/I33,"") -> 0.1625 | O33: =D33/P33 -> 1.4683955 | P33: =$I$8*V33*W33/SUMPRODUCT($W$25:$W$56,$V$25:$V$56) -> 77630.992 | Q33: =$I$9*V33*W33/SUMPRODUCT($W$25:$W$58,$V$25:$V$58) -> 12.938499 | R33: =IF($I$12="","",Q33/$I$12) -> 7.1880548 | S33: =IF(W33<>"",IF(D33<>"",D33,($I$8-SUM($S$25:S32))*V33*W33/SUMPRODUCT($W33:$W$58,$V33:$V$58)),"") -> 113993 | T33: =IF(W33<>"",IF(E33<>"",E33,($I$9-SUM($T$25:T32))*V33*W33/SUMPRODUCT($W33:$W$58,$V33:$V$58)),"") -> 17 | U33: =IF(W33<>"",IF($I$12<>"",IF(G33<>"",G33,($I$9/$I$12-SUM($U$25:U32))*V33*W33/SUMPRODUCT($W33:$W$58,$V33:$V$58)),""),"") -> 13 | V33: 1 | W33: 1
A34: 10 | B34: 45910 | C34: ср | D34: =7990+28243 -> 36233 | E34: 9 | F34: =IF(AND(E34<>"",E34<>0),D34/E34,"") -> 4025.8889 | G34: 4 | H34: =IF(AND(G34<>"",G34<>0),D34/G34,"") -> 9058.25 | I34: =74/2 -> 37 | J34: =IF(AND(G34<>"",G34<>0),E34/G34,"") -> 2.25 | K34: 7990 | N34: =IF(AND(I34<>"",I34<>0),G34/I34,"") -> 0.10810811 | O34: =D34/P34 -> 0.4667337 | P34: =$I$8*V34*W34/SUMPRODUCT($W$25:$W$56,$V$25:$V$56) -> 77630.992 | Q34: =$I$9*V34*W34/SUMPRODUCT($W$25:$W$58,$V$25:$V$58) -> 12.938499 | R34: =IF($I$12="","",Q34/$I$12) -> 7.1880548 | S34: =IF(W34<>"",IF(D34<>"",D34,($I$8-SUM($S$25:S33))*V34*W34/SUMPRODUCT($W34:$W$58,$V34:$V$58)),"") -> 36233 | T34: =IF(W34<>"",IF(E34<>"",E34,($I$9-SUM($T$25:T33))*V34*W34/SUMPRODUCT($W34:$W$58,$V34:$V$58)),"") -> 9 | U34: =IF(W34<>"",IF($I$12<>"",IF(G34<>"",G34,($I$9/$I$12-SUM($U$25:U33))*V34*W34/SUMPRODUCT($W34:$W$58,$V34:$V$58)),""),"") -> 4 | V34: 1 | W34: 1
A35: 11 | B35: 45911 | C35: чт | D35: 35549 | E35: 6 | F35: =IF(AND(E35<>"",E35<>0),D35/E35,"") -> 5924.8333 | G35: 3 | H35: =IF(AND(G35<>"",G35<>0),D35/G35,"") -> 11849.667 | I35: =79/2 -> 39.5 | J35: =IF(AND(G35<>"",G35<>0),E35/G35,"") -> 2 | N35: =IF(AND(I35<>"",I35<>0),G35/I35,"") -> 0.075949367 | O35: =D35/P35 -> 0.45792279 | P35: =$I$8*V35*W35/SUMPRODUCT($W$25:$W$56,$V$25:$V$56) -> 77630.992 | Q35: =$I$9*V35*W35/SUMPRODUCT($W$25:$W$58,$V$25:$V$58) -> 12.938499 | R35: =IF($I$12="","",Q35/$I$12) -> 7.1880548 | S35: =IF(W35<>"",IF(D35<>"",D35,($I$8-SUM($S$25:S34))*V35*W35/SUMPRODUCT($W35:$W$58,$V35:$V$58)),"") -> 35549 | T35: =IF(W35<>"",IF(E34<>"",E34,($I$9-SUM($T$25:T34))*V35*W35/SUMPRODUCT($W35:$W$58,$V35:$V$58)),"") -> 9 | U35: =IF(W35<>"",IF($I$12<>"",IF(G35<>"",G35,($I$9/$I$12-SUM($U$25:U34))*V35*W35/SUMPRODUCT($W35:$W$58,$V35:$V$58)),""),"") -> 3 | V35: 1 | W35: 1
A36: 11 | B36: 45912 | C36: пт | D36: =109604+20000+32175+102415 -> 264194 | E36: 31 | F36: =IF(AND(E36<>"",E36<>0),D36/E36,"") -> 8522.3871 | G36: 20 | H36: =IF(AND(G36<>"",G36<>0),D36/G36,"") -> 13209.7 | I36: 131 | J36: =IF(AND(G36<>"",G36<>0),E36/G36,"") -> 1.55 | K36: 109604 | L36: 20000 | M36: 32175 | N36: =IF(AND(I36<>"",I36<>0),G36/I36,"") -> 0.15267176 | O36: =D36/P36 -> 3.4032027 | P36: =$I$8*V36*W36/SUMPRODUCT($W$25:$W$56,$V$25:$V$56) -> 77630.992 | Q36: =$I$9*V36*W36/SUMPRODUCT($W$25:$W$58,$V$25:$V$58) -> 12.938499 | R36: =IF($I$12="","",Q36/$I$12) -> 7.1880548 | S36: =IF(W36<>"",IF(D36<>"",D36,($I$8-SUM($S$25:S35))*V36*W36/SUMPRODUCT($W36:$W$58,$V36:$V$58)),"") -> 264194 | T36: =IF(W36<>"",IF(E35<>"",E35,($I$9-SUM($T$25:T35))*V36*W36/SUMPRODUCT($W36:$W$58,$V36:$V$58)),"") -> 6 | U36: =IF(W36<>"",IF($I$12<>"",IF(G36<>"",G36,($I$9/$I$12-SUM($U$25:U35))*V36*W36/SUMPRODUCT($W36:$W$58,$V36:$V$58)),""),"") -> 20 | V36: 1 | W36: 1
A37: 13 | B37: 45913 | C37: сб | D37: =7992+53126 -> 61118 | E37: 12 | F37: =IF(AND(E37<>"",E37<>0),D37/E37,"") -> 5093.1667 | G37: 7 | H37: =IF(AND(G37<>"",G37<>0),D37/G37,"") -> 8731.1429 | I37: =93/2 -> 46.5 | J37: =IF(AND(G37<>"",G37<>0),E37/G37,"") -> 1.7142857 | K37: 7992 | N37: =IF(AND(I37<>"",I37<>0),G37/I37,"") -> 0.15053763 | O37: =D37/P37 -> 0.78728867 | P37: =$I$8*V37*W37/SUMPRODUCT($W$25:$W$56,$V$25:$V$56) -> 77630.992 | Q37: =$I$9*V37*W37/SUMPRODUCT($W$25:$W$58,$V$25:$V$58) -> 12.938499 | R37: =IF($I$12="","",Q37/$I$12) -> 7.1880548 | S37: =IF(W37<>"",IF(D37<>"",D37,($I$8-SUM($S$25:S36))*V37*W37/SUMPRODUCT($W37:$W$58,$V37:$V$58)),"") -> 61118 | T37: =IF(W37<>"",IF(E37<>"",E37,($I$9-SUM($T$25:T36))*V37*W37/SUMPRODUCT($W37:$W$58,$V37:$V$58)),"") -> 12 | U37: =IF(W37<>"",IF($I$12<>"",IF(G37<>"",G37,($I$9/$I$12-SUM($U$25:U36))*V37*W37/SUMPRODUCT($W37:$W$58,$V37:$V$58)),""),"") -> 7 | V37: 1 | W37: 1
A38: 14 | B38: 45914 | C38: вс | D38: 62462 | E38: 10 | F38: =IF(AND(E38<>"",E38<>0),D38/E38,"") -> 6246.2 | G38: 7 | H38: =IF(AND(G38<>"",G38<>0),D38/G38,"") -> 8923.1429 | I38: =7+92/2 -> 53 | J38: =IF(AND(G38<>"",G38<>0),E38/G38,"") -> 1.4285714 | K38: 11637 | N38: =IF(AND(I38<>"",I38<>0),G38/I38,"") -> 0.13207547 | O38: =D38/P38 -> 0.80460134 | P38: =$I$8*V38*W38/SUMPRODUCT($W$25:$W$56,$V$25:$V$56) -> 77630.992 | Q38: =$I$9*V38*W38/SUMPRODUCT($W$25:$W$58,$V$25:$V$58) -> 12.938499 | R38: =IF($I$12="","",Q38/$I$12) -> 7.1880548 | S38: =IF(W38<>"",IF(D38<>"",D38,($I$8-SUM($S$25:S37))*V38*W38/SUMPRODUCT($W38:$W$58,$V38:$V$58)),"") -> 62462 | T38: =IF(W38<>"",IF(E38<>"",E38,($I$9-SUM($T$25:T37))*V38*W38/SUMPRODUCT($W38:$W$58,$V38:$V$58)),"") -> 10 | U38: =IF(W38<>"",IF($I$12<>"",IF(G38<>"",G38,($I$9/$I$12-SUM($U$25:U37))*V38*W38/SUMPRODUCT($W38:$W$58,$V38:$V$58)),""),"") -> 7 | V38: 1 | W38: 1
A39: 15 | B39: 45915 | C39: пн | D39: 14503 | E39: 1 | F39: =IF(AND(E39<>"",E39<>0),D39/E39,"") -> 14503 | G39: 1 | H39: =IF(AND(G39<>"",G39<>0),D39/G39,"") -> 14503 | I39: =41/2 -> 20.5 | J39: =IF(AND(G39<>"",G39<>0),E39/G39,"") -> 1 | L39: 14503 | N39: =IF(AND(I39<>"",I39<>0),G39/I39,"") -> 0.048780488 | O39: =D39/P39 -> 0.18681972 | P39: =$I$8*V39*W39/SUMPRODUCT($W$25:$W$56,$V$25:$V$56) -> 77630.992 | Q39: =$I$9*V39*W39/SUMPRODUCT($W$25:$W$58,$V$25:$V$58) -> 12.938499 | R39: =IF($I$12="","",Q39/$I$12) -> 7.1880548 | S39: =IF(W39<>"",IF(D39<>"",D39,($I$8-SUM($S$25:S38))*V39*W39/SUMPRODUCT($W39:$W$58,$V39:$V$58)),"") -> 14503 | T39: =IF(W39<>"",IF(E39<>"",E39,($I$9-SUM($T$25:T38))*V39*W39/SUMPRODUCT($W39:$W$58,$V39:$V$58)),"") -> 1 | U39: =IF(W39<>"",IF($I$12<>"",IF(G39<>"",G39,($I$9/$I$12-SUM($U$25:U38))*V39*W39/SUMPRODUCT($W39:$W$58,$V39:$V$58)),""),"") -> 1 | V39: 1 | W39: 1
A40: 16 | B40: 45916 | C40: вт | D40: 17275 | E40: 3 | F40: =IF(AND(E40<>"",E40<>0),D40/E40,"") -> 5758.3333 | G40: 2 | H40: =IF(AND(G40<>"",G40<>0),D40/G40,"") -> 8637.5 | I40: =74/2 -> 37 | J40: =IF(AND(G40<>"",G40<>0),E40/G40,"") -> 1.5 | N40: =IF(AND(I40<>"",I40<>0),G40/I40,"") -> 0.054054054 | O40: =D40/P40 -> 0.22252711 | P40: =$I$8*V40*W40/SUMPRODUCT($W$25:$W$56,$V$25:$V$56) -> 77630.992 | Q40: =$I$9*V40*W40/SUMPRODUCT($W$25:$W$58,$V$25:$V$58) -> 12.938499 | R40: =IF($I$12="","",Q40/$I$12) -> 7.1880548 | S40: =IF(W40<>"",IF(D40<>"",D40,($I$8-SUM($S$25:S39))*V40*W40/SUMPRODUCT($W40:$W$58,$V40:$V$58)),"") -> 17275 | T40: =IF(W40<>"",IF(E40<>"",E40,($I$9-SUM($T$25:T39))*V40*W40/SUMPRODUCT($W40:$W$58,$V40:$V$58)),"") -> 3 | U40: =IF(W40<>"",IF($I$12<>"",IF(G40<>"",G40,($I$9/$I$12-SUM($U$25:U39))*V40*W40/SUMPRODUCT($W40:$W$58,$V40:$V$58)),""),"") -> 2 | V40: 1 | W40: 1
A41: 17 | B41: 45917 | C41: ср | D41: =8992+70868 -> 79860 | E41: 15 | F41: =IF(AND(E41<>"",E41<>0),D41/E41,"") -> 5324 | G41: 6 | H41: =IF(AND(G41<>"",G41<>0),D41/G41,"") -> 13310 | I41: 70 | J41: =IF(AND(G41<>"",G41<>0),E41/G41,"") -> 2.5 | K41: 8992 | N41: =IF(AND(I41<>"",I41<>0),G41/I41,"") -> 0.085714286 | O41: =D41/P41 -> 1.0287129 | P41: =$I$8*V41*W41/SUMPRODUCT($W$25:$W$56,$V$25:$V$56) -> 77630.992 | Q41: =$I$9*V41*W41/SUMPRODUCT($W$25:$W$58,$V$25:$V$58) -> 12.938499 | R41: =IF($I$12="","",Q41/$I$12) -> 7.1880548 | S41: =IF(W41<>"",IF(D41<>"",D41,($I$8-SUM($S$25:S40))*V41*W41/SUMPRODUCT($W41:$W$58,$V41:$V$58)),"") -> 79860 | T41: =IF(W41<>"",IF(E41<>"",E41,($I$9-SUM($T$25:T40))*V41*W41/SUMPRODUCT($W41:$W$58,$V41:$V$58)),"") -> 15 | U41: =IF(W41<>"",IF($I$12<>"",IF(G41<>"",G41,($I$9/$I$12-SUM($U$25:U40))*V41*W41/SUMPRODUCT($W41:$W$58,$V41:$V$58)),""),"") -> 6 | V41: 1 | W41: 1
A42: 18 | B42: 45918 | C42: чт | D42: 48423 | E42: 9 | F42: =IF(AND(E42<>"",E42<>0),D42/E42,"") -> 5380.3333 | G42: 4 | H42: =IF(AND(G42<>"",G42<>0),D42/G42,"") -> 12105.75 | I42: 29 | J42: =IF(AND(G42<>"",G42<>0),E42/G42,"") -> 2.25 | N42: =IF(AND(I42<>"",I42<>0),G42/I42,"") -> 0.13793103 | O42: =D42/P42 -> 0.62375862 | P42: =$I$8*V42*W42/SUMPRODUCT($W$25:$W$56,$V$25:$V$56) -> 77630.992 | Q42: =$I$9*V42*W42/SUMPRODUCT($W$25:$W$58,$V$25:$V$58) -> 12.938499 | R42: =IF($I$12="","",Q42/$I$12) -> 7.1880548 | S42: =IF(W42<>"",IF(D42<>"",D42,($I$8-SUM($S$25:S41))*V42*W42/SUMPRODUCT($W42:$W$58,$V42:$V$58)),"") -> 48423 | T42: =IF(W42<>"",IF(E42<>"",E42,($I$9-SUM($T$25:T41))*V42*W42/SUMPRODUCT($W42:$W$58,$V42:$V$58)),"") -> 9 | U42: =IF(W42<>"",IF($I$12<>"",IF(G42<>"",G42,($I$9/$I$12-SUM($U$25:U41))*V42*W42/SUMPRODUCT($W42:$W$58,$V42:$V$58)),""),"") -> 4 | V42: 1 | W42: 1
...

Sheet Уразгильдеева Е. Р. 
B1: =TODAY()-1 -> 45939
B2: (отчетная дата) | J2: ЕЖЕДНЕВНЫЙ ОТЧЕТ О ПРОДАЖАХ
B3: Осталось до выполнения плана!!! | J3: =График!B28 -> Уразгильдеева Екатерина
C4: =I8-D50 -> 1526025.2 | E4: =IF(I8<>0, C4/I8, 0) -> 1
F6: Целевые показатели
F7: Показатель | I7: План | J7: Факт | K7: % выполнения | L7: Прогноз выполнения | M7: % выполнения по прогнозу | N7: Отклонение | O7: Факт аналогичного месяца прошлого года | P7: Отклонение LFL
F8: Выручка | I8: ='Ялта, Ленина, 18'!I8/График!AJ31*График!AJ28 -> 1526025.2 | J8: =D57 -> 1265396.1 | K8: =IF(AND(I8<>"",I8<>0,J8<>""),J8/I8,"") -> 0.82921047 | L8: =IF(SUMIF($D$25:$D$56,">=0",$P$25:$P$56)<>0,I8*D57/SUMIF($D$25:$D$56,">=0",$P$25:$P$56),0) -> 1375430.5 | M8: =IF(AND(I8<>"",I8<>0,L8<>"",L8<>0),L8/I8,"") -> 0.90131573 | N8: =IF(AND(J8<>0,J8<>"",I8<>0,I8<>""),L8-I8,"") -> -150594.68 | P8: =IF(AND(O8<>"", O8<>0, L8<>"", L8<>0), -O8+L8, "") | Q8: =IF(AND(P8<>"", P8<>0, O8<>0, O8<>""), P8/O8, "")
F9: Кол-во изделий | I9: =I8/I11 -> 254.33753 | J9: =E57 -> 186 | K9: =IF(AND(I9<>"", I9<>0, J9<>""), J9/I9, "") -> 0.73131164 | L9: =IF(SUMIF($E$25:$E$54,">=0",$Q$25:$Q$54)<>0,I9*E57/SUMIF($E$25:$E$54,">=0",$Q$25:$Q$54),0) -> 211.36364 | M9: =IF(AND(I9<>"",I9<>0,L9<>"",L9<>0),L9/I9,"") -> 0.83103596 | N9: =IF(AND(J9<>0,J9<>"",I9<>0,I9<>""),L9-I9,"") -> -42.973898 | O9: =O8/O11 -> #DIV/0! | P9: =IF(AND(O9<>"", O9<>0, L9<>"", L9<>0), -O9+L9, "") -> #DIV/0! | Q9: =IF(AND(P9<>"", P9<>0, O9<>0, O9<>""), P9/O9, "") -> #DIV/0!
F10: Средний чек | I10: =I11*I12 -> 10800 | J10: =H57 -> 12167.27 | K10: =IF(AND(I10<>"", I10<>0, J10<>""), J10/I10, "") -> 1.1265991 | L10: =J10 -> 12167.27 | M10: =IF(AND(I10<>"",I10<>0,L10<>"",L10<>0),L10/I10,"") -> 1.1265991 | N10: =IF(AND(J10<>0,J10<>"",I10<>0,I10<>""),L10-I10,"") -> 1367.27 | O10: =O11*O12 -> 0 | P10: =IF(AND(O10<>"", O10<>0, L10<>"", L10<>0), -O10+L10, "") | Q10: =IF(AND(P10<>"", P10<>0, O10<>0, O10<>""), P10/O10, "") | S10: IS | V10: =M23 -> Agafi
F11: Средняя стоимость изделия | I11: ='Ялта, Ленина, 18'!I11 -> 6000 | J11: =F57 -> 6803.2047 | K11: =IF(AND(I11<>"", I11<>0, J11<>""), J11/I11, "") -> 1.1338675 | L11: =IF(L9>0,L8/L9,"") -> 6507.4132 | M11: =IF(AND(I11<>"",I11<>0,L11<>"",L11<>0),L11/I11,"") -> 1.0845689 | N11: =IF(AND(J11<>0,J11<>"",I11<>0,I11<>""),L11-I11,"") -> 507.41322 | P11: =IF(AND(O11<>"", O11<>0, L11<>"", L11<>0), -O11+L11, "") | Q11: =IF(AND(P11<>"", P11<>0, O11<>0, O11<>""), P11/O11, "")
F12: Длина чека | I12: ='Ялта, Ленина, 18'!I12 -> 1.8 | J12: =J57 -> 1.7884615 | K12: =IF(AND(I12<>"", I12<>0, J12<>""), J12/I12, "") -> 0.99358974 | L12: =J12 -> 1.7884615 | M12: =IF(AND(I12<>"",I12<>0,L12<>"",L12<>0),L12/I12,"") -> 0.99358974 | N12: =IF(AND(J12<>0,J12<>"",I12<>0,I12<>""),L12-I12,"") -> -0.011538462 | P12: =IF(AND(O12<>"", O12<>0, L12<>"", L12<>0), -O12+L12, "") | Q12: =IF(AND(P12<>"", P12<>0, O12<>0, O12<>""), P12/O12, "") | S12: ='Ялта, Ленина, 18'!S12*График!AJ28/График!AJ31 -> 224493.15 | T12: =L57 -> 56655 | U12: =S12-T12 -> 167838.15 | V12: ='Ялта, Ленина, 18'!V12/График!AJ31*График!AJ28 -> 211287.67 | W12: =M57 -> 91714 | X12: =V12-W12 -> 119573.67
F13: Кол-во чеков | I13: =IF(I12<>0, I9/I12, "") -> 141.29863 | J13: =G57 -> 104 | K13: =IF(AND(I13<>"", I13<>0, J13<>""), J13/I13, "") -> 0.73602978 | L13: =IF(SUMIF($G$25:$G$54,">=0",$R$25:$R$54)<>0,I13*G57/SUMIF($G$25:$G$54,">=0",$R$25:$R$54),"") -> 118.18182 | M13: =IF(AND(I13<>"",I13<>0,L13<>"",L13<>0),L13/I13,"") -> 0.83639748 | N13: =IF(AND(J13<>0,J13<>"",I13<>0,I13<>""),L13-I13,"") -> -23.116812 | P13: =IF(AND(O13<>"", O13<>0, L13<>"", L13<>0), -O13+L13, "") | Q13: =IF(AND(P13<>"", P13<>0, O13<>0, O13<>""), P13/O13, "") | S13: =T12/S12 -> 0.2523685 | T13: =S13/J14*I14 -> 0.2523685 | V13: =W12/V12 -> 0.43407171 | W13: =V13/J14*I14 -> 0.43407171
F14: Кол-во смен план/отработано | I14: =График!AI28 -> 22 | J14: 22 | K14: =IF(AND(I14<>"", I14<>0, J14<>""), J14/I14, "") -> 1 | L14: =I14 -> 22 | M14: =IF(AND(I14<>"",I14<>0,L14<>"",L14<>0),L14/I14,"") -> 1 | N14: =IF(AND(J14<>0,J14<>"",I14<>0,I14<>""),L14-I14,"") -> 0 | P14: =IF(AND(O14<>"", O14<>0, L14<>"", L14<>0), -O14+L14, "") | Q14: =IF(AND(P14<>"", P14<>0, O14<>0, O14<>""), P14/O14, "")
F15: Средние продажи в смену | I15: ='Ялта, Ленина, 18'!I15 -> 115560 | J15: =J8/J14 -> 57518.004 | K15: =IF(AND(I15<>"", I15<>0, J15<>""), J15/I15, "") -> 0.49773281 | L15: =J15 -> 57518.004 | M15: =IF(AND(I15<>"",I15<>0,L15<>"",L15<>0),L15/I15,"") -> 0.49773281 | N15: =IF(AND(J15<>0,J15<>"",I15<>0,I15<>""),L15-I15,"") -> -58041.996 | P15: =IF(AND(O15<>"", O15<>0, L15<>"", L15<>0), -O15+L15, "") | Q15: =IF(AND(P15<>"", P15<>0, O15<>0, O15<>""), P15/O15, "")
F16: Отставание/Перевыполнение | J16: =J8-I15*J14 -> -1276923.9 | K16: =IF(AND(I16<>"", I16<>0, J16<>""), J16/I16, "") | L16: =J16 -> -1276923.9 | M16: =IF(AND(I16<>"",I16<>0,L16<>"",L16<>0),L16/I16,"") | N16: =IF(AND(J16<>0,J16<>"",I16<>0,I16<>""),L16-I16,"") | P16: =IF(AND(O16<>"", O16<>0, L16<>"", L16<>0), -O16+L16, "") | Q16: =IF(AND(P16<>"", P16<>0, O16<>0, O16<>""), P16/O16, "") | S16: UNOde50
