Workbook
Name маг: NA()

Sheet Ялта, Ленина, 18
A1: Рогалевич, | B1: =TODAY()-1 -> 46171
B2: (отчетная дата)
C3: Осталось до выполнения плана!!! | I3: =График!B3 -> ул. Набережная Ленина, 18
C4: =I8-D56 -> 798212 | E4: =IF(I8<>0, C4/I8, 0) -> 0.39574062
D5: =C4/(I14-J14) -> #DIV/0!
F6: Целевые показатели
F7: Показатель | I7: План | J7: Факт | K7: % выполнения | L7: Прогноз выполнения | M7: % выполнения по прогнозу | N7: Отклонение | O7: Факт аналогичного месяца прошлого года | P7: Отклонение LFL
F8: Выручка | I8: =I11*I12*I13 -> 2017008 | J8: =D56 -> 1218796 | K8: =IF(AND(I8<>"",I8<>0,J8<>""),J8/I8,"") -> 0.60425938 | L8: =IF(SUMIF($D$25:$D$55,">=0",$U$25:$U$55)<>0,I8*D56/SUMIF($D$25:$D$55,">=0",$U$25:$U$55),0) -> 1218796 | M8: =IF(AND(I8<>"", I8<>0, L8<>"", L8<>0), L8/I8, "") -> 0.60425938 | N8: =IF(AND(J8<>0, J8<>"", I8<>0, I8<>""), L8-I8, "") -> -798212 | O8: 1482639 | P8: =IF(AND(O8<>"", O8<>0, L8<>"", L8<>0), -O8+L8, "") -> -263843 | Q8: =IF(AND(P8<>"",P8<>0,O8<>0,O8<>""),P8/O8,"") -> -0.17795498
F9: Кол-во изделий | I9: =I8/I11 -> 292.32 | J9: =E56 -> 178 | K9: =IF(AND(I9<>"", I9<>0, J9<>""), J9/I9, "") -> 0.60892173 | L9: =IF(SUMIF($E$25:$E$55,">=0",$V$25:$V$55)<>0,I9*E56/SUMIF($E$25:$E$55,">=0",$V$25:$V$55),0) -> 178 | M9: =IF(AND(I9<>"", I9<>0, L9<>"", L9<>0), L9/I9, "") -> 0.60892173 | N9: =IF(AND(J9<>0, J9<>"", I9<>0, I9<>""), L9-I9, "") -> -114.32 | O9: =O8/O11 -> 315.92563 | P9: =IF(AND(O9<>"", O9<>0, L9<>"", L9<>0), -O9+L9, "") -> -137.92563 | Q9: =IF(AND(P9<>"",P9<>0,O9<>0,O9<>""),P9/O9,"") -> -0.43657627
F10: Средний чек | I10: =I11*I12 -> 12006 | J10: =H56 -> 11285.148 | K10: =IF(AND(I10<>"", I10<>0, J10<>""), J10/I10, "") -> 0.93995903 | L10: =J10 -> 11285.148 | M10: =IF(AND(I10<>"", I10<>0, L10<>"", L10<>0), L10/I10, "") -> 0.93995903 | N10: =IF(AND(J10<>0, J10<>"", I10<>0, I10<>""), L10-I10, "") -> -720.85185 | O10: =O11*O12 -> 8306.61 | P10: =IF(AND(O10<>"", O10<>0, L10<>"", L10<>0), -O10+L10, "") -> 2978.5381 | Q10: =IF(AND(P10<>"",P10<>0,O10<>0,O10<>""),P10/O10,"") -> 0.35857445
F11: Средняя стоимость изделия | I11: 6900 | J11: =F56 -> 6847.1685 | K11: =IF(AND(I11<>"", I11<>0, J11<>""), J11/I11, "") -> 0.99234327 | L11: =IF(L9>0, L8/L9, "") -> 6847.1685 | M11: =IF(AND(I11<>"", I11<>0, L11<>"", L11<>0), L11/I11, "") -> 0.99234327 | N11: =IF(AND(J11<>0, J11<>"", I11<>0, I11<>""), L11-I11, "") -> -52.831461 | O11: 4693 | P11: =IF(AND(O11<>"", O11<>0, L11<>"", L11<>0), -O11+L11, "") -> 2154.1685 | Q11: =IF(AND(P11<>"",P11<>0,O11<>0,O11<>""),P11/O11,"") -> 0.45901737
F12: Длина чека | I12: 1.74 | J12: =J56 -> 1.6481481 | K12: =IF(AND(I12<>"", I12<>0, J12<>""), J12/I12, "") -> 0.94721158 | L12: =J12 -> 1.6481481 | M12: =IF(AND(I12<>"", I12<>0, L12<>"", L12<>0), L12/I12, "") -> 0.94721158 | N12: =IF(AND(J12<>0, J12<>"", I12<>0, I12<>""), L12-I12, "") -> -0.091851852 | O12: 1.77 | P12: =IF(AND(O12<>"", O12<>0, L12<>"", L12<>0), -O12+L12, "") -> -0.12185185 | Q12: =IF(AND(P12<>"",P12<>0,O12<>0,O12<>""),P12/O12,"") -> -0.068842854
F13: Кол-во чеков | I13: =I17*I20 -> 168 | J13: =G56 -> 108 | K13: =IF(AND(I13<>"", I13<>0, J13<>""), J13/I13, "") -> 0.64285714 | L13: =IF(SUMIF($G$25:$G$55,">=0",$W$25:$W$55)<>0,I13*G56/SUMIF($G$25:$G$55,">=0",$W$25:$W$55),"") -> 108 | M13: =IF(AND(I13<>"", I13<>0, L13<>"", L13<>0), L13/I13, "") -> 0.64285714 | N13: =IF(AND(J13<>0, J13<>"", I13<>0, I13<>""), L13-I13, "") -> -60 | O13: 181 | P13: =IF(AND(O13<>"", O13<>0, L13<>"", L13<>0), -O13+L13, "") -> -73 | Q13: =IF(AND(P13<>"",P13<>0,O13<>0,O13<>""),P13/O13,"") -> -0.40331492
F14: Кол-во смен | I14: =График!AK6 -> 31 | J14: 31 | K14: =IF(AND(I14<>"", I14<>0, J14<>""), J14/I14, "") -> 1 | L14: =I14 -> 31 | M14: =IF(AND(I14<>"", I14<>0, L14<>"", L14<>0), L14/I14, "") -> 1 | N14: =IF(AND(J14<>0, J14<>"", I14<>0, I14<>""), L14-I14, "") -> 0 | O14: 31 | P14: =IF(AND(O14<>"", O14<>0, L14<>"", L14<>0), -O14+L14, "") -> 0 | Q14: =IF(AND(P14<>"",P14<>0,O14<>0,O14<>""),P14/O14,"")
F15: Средние продажи в смену | I15: =I8/I14 -> 65064.774 | J15: =J8/J14 -> 39316 | K15: =IF(AND(I15<>"", I15<>0, J15<>""), J15/I15, "") -> 0.60425938 | L15: =J15 -> 39316 | M15: =IF(AND(I15<>"", I15<>0, L15<>"", L15<>0), L15/I15, "") -> 0.60425938 | N15: =IF(AND(J15<>0, J15<>"", I15<>0, I15<>""), L15-I15, "") -> -25748.774 | O15: =O8/O14 -> 47827.065 | P15: =IF(AND(O15<>"", O15<>0, L15<>"", L15<>0), -O15+L15, "") -> -8511.0645 | Q15: =IF(AND(P15<>"",P15<>0,O15<>0,O15<>""),P15/O15,"") -> -0.17795498
F16: Отставание/Перевыполнение | J16: =J8-I15*J14 -> -798212 | K16: =IF(AND(I16<>"", I16<>0, J16<>""), J16/I16, "") | L16: =J16 -> -798212 | M16: =IF(AND(I16<>"", I16<>0, L16<>"", L16<>0), L16/I16, "") | N16: =IF(AND(J16<>0, J16<>"", I16<>0, I16<>""), L16-I16, "") | O16: -173502 | P16: =IF(AND(O16<>"", O16<>0, L16<>"", L16<>0), -O16+L16, "") -> -624710 | Q16: =IF(AND(P16<>"",P16<>0,O16<>0,O16<>""),P16/O16,"") -> 3.6005925
F17: Трафик | I17: 1400 | J17: =I56 -> 1312.8 | K17: =IF(AND(I17<>"", I17<>0, J17<>""), J17/I17, "") -> 0.93771429 | L17: =J17/J14*I14 -> 1312.8 | M17: =IF(AND(I17<>"", I17<>0, L17<>"", L17<>0), L17/I17, "") -> 0.93771429 | N17: =IF(AND(J17<>0, J17<>"", I17<>0, I17<>""), L17-I17, "") -> -87.2 | O17: 780 | P17: =IF(AND(O17<>"", O17<>0, L17<>"", L17<>0), -O17+L17, "") -> 532.8 | Q17: =IF(AND(P17<>"",P17<>0,O17<>0,O17<>""),P17/O17,"") -> 0.68307692
F18: Выручка на вошедшего | I18: =I8/I17 -> 1440.72 | J18: =J8/J17 -> 928.39427 | K18: =IF(AND(I18<>"", I18<>0, J18<>""), J18/I18, "") -> 0.64439605 | L18: =J18 -> 928.39427 | M18: =IF(AND(I18<>"", I18<>0, L18<>"", L18<>0), L18/I18, "") -> 0.64439605 | N18: =IF(AND(J18<>0, J18<>"", I18<>0, I18<>""), L18-I18, "") -> -512.32573 | O18: =O8/O17 -> 1900.8192 | P18: =IF(AND(O18<>"", O18<>0, L18<>"", L18<>0), -O18+L18, "") -> -972.42496 | Q18: =IF(AND(P18<>"",P18<>0,O18<>0,O18<>""),P18/O18,"") -> -0.51158203
K19: =IF(AND(I19<>"", I19<>0, J19<>""), J19/I19, "") | L19: =J19 -> 0 | M19: =IF(AND(I19<>"", I19<>0, L19<>"", L19<>0), L19/I19, "") | N19: =IF(AND(J19<>0, J19<>"", I19<>0, I19<>""), L19-I19, "") | O19: 0 | P19: =IF(AND(O19<>"", O19<>0, L19<>"", L19<>0), -O19+L19, "") | Q19: =IF(AND(P19<>"",P19<>0,O19<>0,O19<>""),P19/O19,"")
F20: Конверсия план/факт | I20: 0.12 | J20: =S56 -> 0.08226691 | K20: =J20/I20 -> 0.68555759 | L20: =IF(AND(K8<>0,I14<>0,I56<>0),(I56*S56+(I56/K8-I56)*I20)/(I56/K8),0) -> 0.097199427 | M20: =IF(AND(I20<>"", I20<>0, L20<>"", L20<>0), L20/I20, "") -> 0.80999522 | N20: =IF(AND(J20<>0, J20<>"", I20<>0, I20<>""), L20-I20, "") -> -0.022800573 | O20: =O13/O17 -> 0.23205128 | P20: =IF(AND(O20<>"", O20<>0, L20<>"", L20<>0), -O20+L20, "") -> -0.13485186 | Q20: =IF(AND(P20<>"",P20<>0,O20<>0,O20<>""),P20/O20,"") -> -0.58112954
A22: Факт продаж за месяц | R22: Раcпределение плана по дням
A23: Сотрудник | B23: Дата | C23: День недели | D23: Выручка (руб) | E23: Кол-во единиц (шт.) | F23: Средняя стоимость изделия (руб.) | G23: Количество чеков (шт.) | H23: Средняя сумма чека (руб.) | I23: Трафик | J23: Длина чека (шт.) | K23: UNOde50 | L23: IS | M23: Agafi | N23: Kalliope | O23: Raganella | P23: CC/MP | Q23: Antyra | R23: SALE | S23: Конверсия | T23: % выполнения дневного плана | U23: выручка, план | V23: кол-во ед, план | W23: Кол-во чеков, план | X23: выручка, скорректир.план | Y23: кол-во ед, скорр. план | Z23: кол-во чеков, скорр. план | AA23: Коэфф. Дня Недели | AB23: Специфика месяца
B24: 1 | C24: 2 | D24: 3 | E24: 4 | F24: 5 | G24: 6 | H24: 7 | I24: 8 | J24: 9 | K24: 10 | L24: 11 | M24: 12 | N24: 13 | O24: 14 | P24: 15 | Q24: 16 | R24: 17 | S24: 17 | U24: 1 | V24: 2 | W24: 3 | X24: 4 | Y24: 5 | Z24: 6 | AA24: 10 | AB24: 11
A25: Рогалевич,Уразгильдеева | B25: 46082 | C25: вс | D25: 89496 | E25: 12 | F25: =IF(AND(E25<>"",E25<>0),D25/E25,"") -> 7458 | G25: 8 | H25: =IF(AND(G25<>"",G25<>0),D25/G25,"") -> 11187 | I25: 57 | J25: =IF(AND(G25<>"",G25<>0),E25/G25,"") -> 1.5 | Q25: 32552 | R25: 7690 | S25: =IF(AND(I25<>"",I25<>0),G25/I25,"") -> 0.14035088 | T25: =D25/U25 -> 1.8191975 | U25: =$I$8*AA25*AB25/SUMPRODUCT($AB$25:$AB$55,$AA$25:$AA$55) -> 49195.317 | V25: =$I$9*AA25*AB25/SUMPRODUCT($AB$25:$AB$55,$AA$25:$AA$55) -> 7.1297561 | W25: =IF($I$12="","",V25/$I$12) -> 4.097561 | X25: =IF(D25<>"",D25,U25) -> 89496 | Y25: =IF(E25<>"",E25,V25) -> 12 | Z25: =IF(G25<>"",G25,W25) -> 8 | AA25: 1 | AB25: 1
A26: Рогалевич | B26: 46083 | C26: пн | D26: 12184 | E26: 2 | F26: =IF(AND(E26<>"",E26<>0),D26/E26,"") -> 6092 | G26: 1 | H26: =IF(AND(G26<>"",G26<>0),D26/G26,"") -> 12184 | I26: 43 | J26: =IF(AND(G26<>"",G26<>0),E26/G26,"") -> 2 | S26: =IF(AND(I26<>"",I26<>0),G26/I26,"") -> 0.023255814 | T26: =D26/U26 -> 0.24766585 | U26: =$I$8*AA26*AB26/SUMPRODUCT($AB$25:$AB$55,$AA$25:$AA$55) -> 49195.317 | V26: =$I$9*AA26*AB26/SUMPRODUCT($AB$25:$AB$55,$AA$25:$AA$55) -> 7.1297561 | W26: =IF($I$12="","",V26/$I$12) -> 4.097561 | X26: =IF(AB26<>"",IF(D26<>"",D26,($I$8-SUM($X$25:X25))*AA26*AB26/SUMPRODUCT($AB26:$AB$55,$AA26:$AA$55)),"") -> 12184 | Y26: =IF(AB26<>"",IF(E26<>"",E26,($I$9-SUM($Y$25:Y25))*AA26*AB26/SUMPRODUCT($AB26:$AB$55,$AA26:$AA$55)),"") -> 2 | Z26: =IF(AB26<>"",IF(E26<>"",E26,($I$9-SUM($Y$25:Y25))*AA26*AB26/SUMPRODUCT($AB26:$AB$55,$AA26:$AA$55)),"") -> 2 | AA26: 1 | AB26: 1
A27: Рогалевич | B27: 46084 | C27: вт | D27: 6593 | E27: 1 | F27: =IF(AND(E27<>"",E27<>0),D27/E27,"") -> 6593 | G27: 1 | H27: =IF(AND(G27<>"",G27<>0),D27/G27,"") -> 6593 | I27: 22 | J27: =IF(AND(G27<>"",G27<>0),E27/G27,"") -> 1 | S27: =IF(AND(I27<>"",I27<>0),G27/I27,"") -> 0.045454545 | T27: =D27/U27 -> 0.13401682 | U27: =$I$8*AA27*AB27/SUMPRODUCT($AB$25:$AB$55,$AA$25:$AA$55) -> 49195.317 | V27: =$I$9*AA27*AB27/SUMPRODUCT($AB$25:$AB$55,$AA$25:$AA$55) -> 7.1297561 | W27: =IF($I$12="","",V27/$I$12) -> 4.097561 | X27: =IF(AB27<>"",IF(D27<>"",D27,($I$8-SUM($X$25:X26))*AA27*AB27/SUMPRODUCT($AB27:$AB$55,$AA27:$AA$55)),"") -> 6593 | Y27: =IF(AB27<>"",IF(E27<>"",E27,($I$9-SUM($Y$25:Y26))*AA27*AB27/SUMPRODUCT($AB27:$AB$55,$AA27:$AA$55)),"") -> 1 | Z27: =IF(AB27<>"",IF(E27<>"",E27,($I$9-SUM($Y$25:Y26))*AA27*AB27/SUMPRODUCT($AB27:$AB$55,$AA27:$AA$55)),"") -> 1 | AA27: 1 | AB27: 1
A28: Рогалевич.Уразгильдеева | B28: 46085 | C28: ср | D28: 0 | E28: 0 | F28: 0 | G28: 0 | H28: 0 | I28: 50 | J28: =IF(AND(G28<>"",G28<>0),E28/G28,"") | S28: =IF(AND(I28<>"",I28<>0),G28/I28,"") -> 0 | T28: =D28/U28 -> 0 | U28: =$I$8*AA28*AB28/SUMPRODUCT($AB$25:$AB$55,$AA$25:$AA$55) -> 49195.317 | V28: =$I$9*AA28*AB28/SUMPRODUCT($AB$25:$AB$55,$AA$25:$AA$55) -> 7.1297561 | W28: =IF($I$12="","",V28/$I$12) -> 4.097561 | X28: =IF(AB28<>"",IF(D28<>"",D28,($I$8-SUM($X$25:X27))*AA28*AB28/SUMPRODUCT($AB28:$AB$55,$AA28:$AA$55)),"") -> 0 | Y28: =IF(AB28<>"",IF(E28<>"",E28,($I$9-SUM($Y$25:Y27))*AA28*AB28/SUMPRODUCT($AB28:$AB$55,$AA28:$AA$55)),"") -> 0 | Z28: =IF(AB28<>"",IF(E28<>"",E28,($I$9-SUM($Y$25:Y27))*AA28*AB28/SUMPRODUCT($AB28:$AB$55,$AA28:$AA$55)),"") -> 0 | AA28: 1 | AB28: 1
A29: Рогалевич,Уразгильдеева | B29: 46086 | C29: чт | D29: 55266 | E29: 10 | F29: =IF(AND(E29<>"",E29<>0),D29/E29,"") -> 5526.6 | G29: 4 | H29: =IF(AND(G29<>"",G29<>0),D29/G29,"") -> 13816.5 | I29: 55 | J29: =IF(AND(G29<>"",G29<>0),E29/G29,"") -> 2.5 | Q29: 8790 | R29: 4753 | S29: =IF(AND(I29<>"",I29<>0),G29/I29,"") -> 0.072727273 | T29: =D29/U29 -> 1.1233996 | U29: =$I$8*AA29*AB29/SUMPRODUCT($AB$25:$AB$55,$AA$25:$AA$55) -> 49195.317 | V29: =$I$9*AA29*AB29/SUMPRODUCT($AB$25:$AB$55,$AA$25:$AA$55) -> 7.1297561 | W29: =IF($I$12="","",V29/$I$12) -> 4.097561 | X29: =IF(AB29<>"",IF(D29<>"",D29,($I$8-SUM($X$25:X28))*AA29*AB29/SUMPRODUCT($AB29:$AB$55,$AA29:$AA$55)),"") -> 55266 | Y29: =IF(AB29<>"",IF(E29<>"",E29,($I$9-SUM($Y$25:Y28))*AA29*AB29/SUMPRODUCT($AB29:$AB$55,$AA29:$AA$55)),"") -> 10 | Z29: =IF(AB29<>"",IF(E29<>"",E29,($I$9-SUM($Y$25:Y28))*AA29*AB29/SUMPRODUCT($AB29:$AB$55,$AA29:$AA$55)),"") -> 10 | AA29: 1 | AB29: 1
A30: Рогалевич,Уразгильдеева | B30: 46087 | C30: пт | D30: 34354 | E30: 6 | F30: =IF(AND(E30<>"",E30<>0),D30/E30,"") -> 5725.6667 | G30: 3 | H30: =IF(AND(G30<>"",G30<>0),D30/G30,"") -> 11451.333 | I30: 50 | J30: =IF(AND(G30<>"",G30<>0),E30/G30,"") -> 2 | S30: =IF(AND(I30<>"",I30<>0),G30/I30,"") -> 0.06 | T30: =D30/U30 -> 0.6983185 | U30: =$I$8*AA30*AB30/SUMPRODUCT($AB$25:$AB$55,$AA$25:$AA$55) -> 49195.317 | V30: =$I$9*AA30*AB30/SUMPRODUCT($AB$25:$AB$55,$AA$25:$AA$55) -> 7.1297561 | W30: =IF($I$12="","",V30/$I$12) -> 4.097561 | X30: =IF(AB30<>"",IF(D30<>"",D30,($I$8-SUM($X$25:X29))*AA30*AB30/SUMPRODUCT($AB30:$AB$55,$AA30:$AA$55)),"") -> 34354 | Y30: =IF(AB30<>"",IF(E30<>"",E30,($I$9-SUM($Y$25:Y29))*AA30*AB30/SUMPRODUCT($AB30:$AB$55,$AA30:$AA$55)),"") -> 6 | Z30: =IF(AB30<>"",IF(E30<>"",E30,($I$9-SUM($Y$25:Y29))*AA30*AB30/SUMPRODUCT($AB30:$AB$55,$AA30:$AA$55)),"") -> 6 | AA30: 1 | AB30: 1
A31: Рогалевич,Уразгильдеева | B31: 46088 | C31: сб | D31: 81583 | E31: 15 | F31: =IF(AND(E31<>"",E31<>0),D31/E31,"") -> 5438.8667 | G31: 10 | H31: =IF(AND(G31<>"",G31<>0),D31/G31,"") -> 8158.3 | I31: 82 | J31: =IF(AND(G31<>"",G31<>0),E31/G31,"") -> 1.5 | R31: 2793 | S31: =IF(AND(I31<>"",I31<>0),G31/I31,"") -> 0.12195122 | T31: =D31/U31 -> 1.6583489 | U31: =$I$8*AA31*AB31/SUMPRODUCT($AB$25:$AB$55,$AA$25:$AA$55) -> 49195.317 | V31: =$I$9*AA31*AB31/SUMPRODUCT($AB$25:$AB$55,$AA$25:$AA$55) -> 7.1297561 | W31: =IF($I$12="","",V31/$I$12) -> 4.097561 | X31: =IF(AB31<>"",IF(D31<>"",D31,($I$8-SUM($X$25:X30))*AA31*AB31/SUMPRODUCT($AB31:$AB$55,$AA31:$AA$55)),"") -> 81583 | Y31: =IF(AB31<>"",IF(E31<>"",E31,($I$9-SUM($Y$25:Y30))*AA31*AB31/SUMPRODUCT($AB31:$AB$55,$AA31:$AA$55)),"") -> 15 | Z31: =IF(AB31<>"",IF(E31<>"",E31,($I$9-SUM($Y$25:Y30))*AA31*AB31/SUMPRODUCT($AB31:$AB$55,$AA31:$AA$55)),"") -> 15 | AA31: 1 | AB31: 1
A32: Рогалевич,Уразгильдеева | B32: 46089 | C32: вс | D32: 185650 | E32: 17 | F32: =IF(AND(E32<>"",E32<>0),D32/E32,"") -> 10920.588 | G32: 11 | H32: =IF(AND(G32<>"",G32<>0),D32/G32,"") -> 16877.273 | I32: 148 | J32: =IF(AND(G32<>"",G32<>0),E32/G32,"") -> 1.5454545 | K32: 124299 | N32: 6191 | S32: =IF(AND(I32<>"",I32<>0),G32/I32,"") -> 0.074324324 | T32: =D32/U32 -> 3.7737332 | U32: =$I$8*AA32*AB32/SUMPRODUCT($AB$25:$AB$55,$AA$25:$AA$55) -> 49195.317 | V32: =$I$9*AA32*AB32/SUMPRODUCT($AB$25:$AB$55,$AA$25:$AA$55) -> 7.1297561 | W32: =IF($I$12="","",V32/$I$12) -> 4.097561 | X32: =IF(AB32<>"",IF(D32<>"",D32,($I$8-SUM($X$25:X31))*AA32*AB32/SUMPRODUCT($AB32:$AB$55,$AA32:$AA$55)),"") -> 185650 | Y32: =IF(AB32<>"",IF(E32<>"",E32,($I$9-SUM($Y$25:Y31))*AA32*AB32/SUMPRODUCT($AB32:$AB$55,$AA32:$AA$55)),"") -> 17 | Z32: =IF(AB32<>"",IF(E32<>"",E32,($I$9-SUM($Y$25:Y31))*AA32*AB32/SUMPRODUCT($AB32:$AB$55,$AA32:$AA$55)),"") -> 17 | AA32: 1 | AB32: 1
A33: Рогалевич | B33: 46090 | C33: пн | D33: 20092 | E33: 3 | F33: =IF(AND(E33<>"",E33<>0),D33/E33,"") -> 6697.3333 | G33: 2 | H33: =IF(AND(G33<>"",G33<>0),D33/G33,"") -> 10046 | I33: 66 | J33: =IF(AND(G33<>"",G33<>0),E33/G33,"") -> 1.5 | S33: =IF(AND(I33<>"",I33<>0),G33/I33,"") -> 0.03030303 | T33: =D33/U33 -> 0.40841286 | U33: =$I$8*AA33*AB33/SUMPRODUCT($AB$25:$AB$55,$AA$25:$AA$55) -> 49195.317 | V33: =$I$9*AA33*AB33/SUMPRODUCT($AB$25:$AB$55,$AA$25:$AA$55) -> 7.1297561 | W33: =IF($I$12="","",V33/$I$12) -> 4.097561 | X33: =IF(AB33<>"",IF(D33<>"",D33,($I$8-SUM($X$25:X32))*AA33*AB33/SUMPRODUCT($AB33:$AB$55,$AA33:$AA$55)),"") -> 20092 | Y33: =IF(AB33<>"",IF(E33<>"",E33,($I$9-SUM($Y$25:Y32))*AA33*AB33/SUMPRODUCT($AB33:$AB$55,$AA33:$AA$55)),"") -> 3 | Z33: =IF(AB33<>"",IF(E33<>"",E33,($I$9-SUM($Y$25:Y32))*AA33*AB33/SUMPRODUCT($AB33:$AB$55,$AA33:$AA$55)),"") -> 3 | AA33: 1 | AB33: 1
A34: Рогалевич | B34: 46091 | C34: вт | D34: 38929 | E34: 7 | F34: =IF(AND(E34<>"",E34<>0),D34/E34,"") -> 5561.2857 | G34: 6 | H34: =IF(AND(G34<>"",G34<>0),D34/G34,"") -> 6488.1667 | I34: 75 | J34: =IF(AND(G34<>"",G34<>0),E34/G34,"") -> 1.1666667 | K34: 9493 | S34: =IF(AND(I34<>"",I34<>0),G34/I34,"") -> 0.08 | T34: =D34/U34 -> 0.79131516 | U34: =$I$8*AA34*AB34/SUMPRODUCT($AB$25:$AB$55,$AA$25:$AA$55) -> 49195.317 | V34: =$I$9*AA34*AB34/SUMPRODUCT($AB$25:$AB$55,$AA$25:$AA$55) -> 7.1297561 | W34: =IF($I$12="","",V34/$I$12) -> 4.097561 | X34: =IF(AB34<>"",IF(D34<>"",D34,($I$8-SUM($X$25:X33))*AA34*AB34/SUMPRODUCT($AB34:$AB$55,$AA34:$AA$55)),"") -> 38929 | Y34: =IF(AB34<>"",IF(E34<>"",E34,($I$9-SUM($Y$25:Y33))*AA34*AB34/SUMPRODUCT($AB34:$AB$55,$AA34:$AA$55)),"") -> 7 | Z34: =IF(AB34<>"",IF(E34<>"",E34,($I$9-SUM($Y$25:Y33))*AA34*AB34/SUMPRODUCT($AB34:$AB$55,$AA34:$AA$55)),"") -> 7 | AA34: 1 | AB34: 1
A35: Уразгильдеева | B35: 46092 | C35: ср | D35: 21079 | E35: 3 | F35: =IF(AND(E35<>"",E35<>0),D35/E35,"") -> 7026.3333 | G35: 3 | H35: =IF(AND(G35<>"",G35<>0),D35/G35,"") -> 7026.3333 | I35: 52 | J35: =IF(AND(G35<>"",G35<>0),E35/G35,"") -> 1 | K35: 9993 | S35: =IF(AND(I35<>"",I35<>0),G35/I35,"") -> 0.057692308 | T35: =D35/U35 -> 0.42847574 | U35: =$I$8*AA35*AB35/SUMPRODUCT($AB$25:$AB$55,$AA$25:$AA$55) -> 49195.317 | V35: =$I$9*AA35*AB35/SUMPRODUCT($AB$25:$AB$55,$AA$25:$AA$55) -> 7.1297561 | W35: =IF($I$12="","",V35/$I$12) -> 4.097561 | X35: =IF(AB35<>"",IF(D35<>"",D35,($I$8-SUM($X$25:X34))*AA35*AB35/SUMPRODUCT($AB35:$AB$55,$AA35:$AA$55)),"") -> 21079 | Y35: =IF(AB35<>"",IF(E35<>"",E35,($I$9-SUM($Y$25:Y34))*AA35*AB35/SUMPRODUCT($AB35:$AB$55,$AA35:$AA$55)),"") -> 3 | Z35: =IF(AB35<>"",IF(E35<>"",E35,($I$9-SUM($Y$25:Y34))*AA35*AB35/SUMPRODUCT($AB35:$AB$55,$AA35:$AA$55)),"") -> 3 | AA35: 1 | AB35: 1
A36: Рогалевич,Уразгильдеева | B36: 46093 | C36: чт | D36: 50652 | E36: 6 | F36: =IF(AND(E36<>"",E36<>0),D36/E36,"") -> 8442 | G36: 3 | H36: =IF(AND(G36<>"",G36<>0),D36/G36,"") -> 16884 | I36: 45 | J36: =IF(AND(G36<>"",G36<>0),E36/G36,"") -> 2 | P36: 7093 | Q36: 16890 | R36: 6490 | S36: =IF(AND(I36<>"",I36<>0),G36/I36,"") -> 0.066666667 | T36: =D36/U36 -> 1.0296102 | U36: =$I$8*AA36*AB36/SUMPRODUCT($AB$25:$AB$55,$AA$25:$AA$55) -> 49195.317 | V36: =$I$9*AA36*AB36/SUMPRODUCT($AB$25:$AB$55,$AA$25:$AA$55) -> 7.1297561 | W36: =IF($I$12="","",V36/$I$12) -> 4.097561 | X36: =IF(AB36<>"",IF(D36<>"",D36,($I$8-SUM($X$25:X35))*AA36*AB36/SUMPRODUCT($AB36:$AB$55,$AA36:$AA$55)),"") -> 50652 | Y36: =IF(AB36<>"",IF(E36<>"",E36,($I$9-SUM($Y$25:Y35))*AA36*AB36/SUMPRODUCT($AB36:$AB$55,$AA36:$AA$55)),"") -> 6 | Z36: =IF(AB36<>"",IF(E36<>"",E36,($I$9-SUM($Y$25:Y35))*AA36*AB36/SUMPRODUCT($AB36:$AB$55,$AA36:$AA$55)),"") -> 6 | AA36: 1 | AB36: 1
A37: Рогалевич,Самошкина | B37: 46094 | C37: пт | D37: 18979 | E37: 3 | F37: =IF(AND(E37<>"",E37<>0),D37/E37,"") -> 6326.3333 | G37: 3 | H37: =IF(AND(G37<>"",G37<>0),D37/G37,"") -> 6326.3333 | I37: 39 | J37: =IF(AND(G37<>"",G37<>0),E37/G37,"") -> 1 | S37: =IF(AND(I37<>"",I37<>0),G37/I37,"") -> 0.076923077 | T37: =D37/U37 -> 0.38578875 | U37: =$I$8*AA37*AB37/SUMPRODUCT($AB$25:$AB$55,$AA$25:$AA$55) -> 49195.317 | V37: =$I$9*AA37*AB37/SUMPRODUCT($AB$25:$AB$55,$AA$25:$AA$55) -> 7.1297561 | W37: =IF($I$12="","",V37/$I$12) -> 4.097561 | X37: =IF(AB37<>"",IF(D37<>"",D37,($I$8-SUM($X$25:X36))*AA37*AB37/SUMPRODUCT($AB37:$AB$55,$AA37:$AA$55)),"") -> 18979 | Y37: =IF(AB37<>"",IF(E37<>"",E37,($I$9-SUM($Y$25:Y36))*AA37*AB37/SUMPRODUCT($AB37:$AB$55,$AA37:$AA$55)),"") -> 3 | Z37: =IF(AB37<>"",IF(E37<>"",E37,($I$9-SUM($Y$25:Y36))*AA37*AB37/SUMPRODUCT($AB37:$AB$55,$AA37:$AA$55)),"") -> 3 | AA37: 1 | AB37: 1
A38: Рогалевич,Самошкина | B38: 46095 | C38: сб | D38: 54282 | E38: 6 | F38: =IF(AND(E38<>"",E38<>0),D38/E38,"") -> 9047 | G38: 3 | H38: =IF(AND(G38<>"",G38<>0),D38/G38,"") -> 18094 | I38: 40 | J38: =IF(AND(G38<>"",G38<>0),E38/G38,"") -> 2 | P38: 41805 | S38: =IF(AND(I38<>"",I38<>0),G38/I38,"") -> 0.075 | T38: =D38/U38 -> 1.1033977 | U38: =$I$8*AA38*AB38/SUMPRODUCT($AB$25:$AB$55,$AA$25:$AA$55) -> 49195.317 | V38: =$I$9*AA38*AB38/SUMPRODUCT($AB$25:$AB$55,$AA$25:$AA$55) -> 7.1297561 | W38: =IF($I$12="","",V38/$I$12) -> 4.097561 | X38: =IF(AB38<>"",IF(D38<>"",D38,($I$8-SUM($X$25:X37))*AA38*AB38/SUMPRODUCT($AB38:$AB$55,$AA38:$AA$55)),"") -> 54282 | Y38: =IF(AB38<>"",IF(E38<>"",E38,($I$9-SUM($Y$25:Y37))*AA38*AB38/SUMPRODUCT($AB38:$AB$55,$AA38:$AA$55)),"") -> 6 | Z38: =IF(AB38<>"",IF(E38<>"",E38,($I$9-SUM($Y$25:Y37))*AA38*AB38/SUMPRODUCT($AB38:$AB$55,$AA38:$AA$55)),"") -> 6 | AA38: 1 | AB38: 1
A39: Рогалевич,Самошкина | B39: 46096 | C39: вс | D39: 19385 | E39: 2 | F39: =IF(AND(E39<>"",E39<>0),D39/E39,"") -> 9692.5 | G39: 1 | H39: =IF(AND(G39<>"",G39<>0),D39/G39,"") -> 19385 | I39: 44 | J39: =IF(AND(G39<>"",G39<>0),E39/G39,"") -> 2 | O39: 15390 | S39: =IF(AND(I39<>"",I39<>0),G39/I39,"") -> 0.022727273 | T39: =D39/U39 -> 0.39404157 | U39: =$I$8*AA39*AB39/SUMPRODUCT($AB$25:$AB$55,$AA$25:$AA$55) -> 49195.317 | V39: =$I$9*AA39*AB39/SUMPRODUCT($AB$25:$AB$55,$AA$25:$AA$55) -> 7.1297561 | W39: =IF($I$12="","",V39/$I$12) -> 4.097561 | X39: =IF(AB39<>"",IF(D39<>"",D39,($I$8-SUM($X$25:X38))*AA39*AB39/SUMPRODUCT($AB39:$AB$55,$AA39:$AA$55)),"") -> 19385 | Y39: =IF(AB39<>"",IF(E39<>"",E39,($I$9-SUM($Y$25:Y38))*AA39*AB39/SUMPRODUCT($AB39:$AB$55,$AA39:$AA$55)),"") -> 2 | Z39: =IF(AB39<>"",IF(E39<>"",E39,($I$9-SUM($Y$25:Y38))*AA39*AB39/SUMPRODUCT($AB39:$AB$55,$AA39:$AA$55)),"") -> 2 | AA39: 1 | AB39: 1
A40: Уразгильдеева | B40: 46097 | C40: пн | D40: 92945 | E40: 15 | F40: =IF(AND(E40<>"",E40<>0),D40/E40,"") -> 6196.3333 | G40: 8 | H40: =IF(AND(G40<>"",G40<>0),D40/G40,"") -> 11618.125 | I40: 50 | J40: =IF(AND(G40<>"",G40<>0),E40/G40,"") -> 1.875 | K40: 17593 | P40: 7259 | Q40: 8240 | S40: =IF(AND(I40<>"",I40<>0),G40/I40,"") -> 0.16 | T40: =D40/U40 -> 1.8893058 | U40: =$I$8*AA40*AB40/SUMPRODUCT($AB$25:$AB$55,$AA$25:$AA$55) -> 49195.317 | V40: =$I$9*AA40*AB40/SUMPRODUCT($AB$25:$AB$55,$AA$25:$AA$55) -> 7.1297561 | W40: =IF($I$12="","",V40/$I$12) -> 4.097561 | X40: =IF(AB40<>"",IF(D40<>"",D40,($I$8-SUM($X$25:X39))*AA40*AB40/SUMPRODUCT($AB40:$AB$55,$AA40:$AA$55)),"") -> 92945 | Y40: =IF(AB40<>"",IF(E40<>"",E40,($I$9-SUM($Y$25:Y39))*AA40*AB40/SUMPRODUCT($AB40:$AB$55,$AA40:$AA$55)),"") -> 15 | Z40: =IF(AB40<>"",IF(E40<>"",E40,($I$9-SUM($Y$25:Y39))*AA40*AB40/SUMPRODUCT($AB40:$AB$55,$AA40:$AA$55)),"") -> 15 | AA40: 1 | AB40: 1
A41: Уразгильдеева | B41: 46098 | C41: вт | D41: 11392 | E41: 3 | F41: =IF(AND(E41<>"",E41<>0),D41/E41,"") -> 3797.3333 | G41: 2 | H41: =IF(AND(G41<>"",G41<>0),D41/G41,"") -> 5696 | I41: 30 | J41: =IF(AND(G41<>"",G41<>0),E41/G41,"") -> 1.5 | R41: 4190 | S41: =IF(AND(I41<>"",I41<>0),G41/I41,"") -> 0.066666667 | T41: =D41/U41 -> 0.23156676 | U41: =$I$8*AA41*AB41/SUMPRODUCT($AB$25:$AB$55,$AA$25:$AA$55) -> 49195.317 | V41: =$I$9*AA41*AB41/SUMPRODUCT($AB$25:$AB$55,$AA$25:$AA$55) -> 7.1297561 | W41: =IF($I$12="","",V41/$I$12) -> 4.097561 | X41: =IF(AB41<>"",IF(D41<>"",D41,($I$8-SUM($X$25:X40))*AA41*AB41/SUMPRODUCT($AB41:$AB$55,$AA41:$AA$55)),"") -> 11392 | Y41: =IF(AB41<>"",IF(E41<>"",E41,($I$9-SUM($Y$25:Y40))*AA41*AB41/SUMPRODUCT($AB41:$AB$55,$AA41:$AA$55)),"") -> 3 | Z41: =IF(AB41<>"",IF(E41<>"",E41,($I$9-SUM($Y$25:Y40))*AA41*AB41/SUMPRODUCT($AB41:$AB$55,$AA41:$AA$55)),"") -> 3 | AA41: 1 | AB41: 1
...

Sheet Конкурс
A2: Личный ежедневный КВП, %
A4: Сотруник | B4: 45282 | C4: 45283 | D4: 45284 | E4: 45285 | F4: 45286 | G4: 45287 | H4: 45288 | I4: 45289 | J4: 45290 | K4: 45291 | L4: Итого:
A5: Рогалевич Ирина | E5: 0.57 | F5: 0.73 | G5: 0.88 | H5: 0.98 | I5: 0.69 | J5: 1.82 | K5: 2.89
A6: Арапова Анна | C6: 0 | D6: 0 | E6: 0 | F6: 0 | G6: 0.83 | H6: 0 | I6: 0.28 | J6: 0.46 | K6: 0.89
A7: Уразгильдеева Екатерина | B7: 0.39 | C7: 0 | E7: 0 | F7: 0.49 | G7: 1.19 | H7: 0.69 | J7: 1.63 | K7: 0.81
A9: Личный КВП, баллы
A11: Сотруник | B11: 45282 | C11: 45283 | D11: 45284 | E11: 45285 | F11: 45286 | G11: 45287 | H11: 45288 | I11: 45289 | J11: 45290 | K11: 45291 | L11: Итого:
A12: Рогалевич Ирина | E12: 1 | F12: 1 | G12: 1 | H12: 1 | I12: 1 | J12: 2 | K12: 3 | L12: =SUM(B12:K12) -> 10
A13: Арапова Анна | L13: =SUM(B13:K13) -> 0
A14: Уразгильдеева Екатерина | B14: 1 | F14: 1 | G14: 2 | H14: 1 | J14: 1 | L14: =SUM(B14:K14) -> 6

Sheet Св. по пок.
A1: 1-20.08
A2: Показатель | D2: ='Ялта, Ленина, 18'!I3 -> ул. Набережная Ленина, 18 | G2: =График!B29 -> Рогалевич Ирина | J2: =График!B28 -> Уразгильдеева Екатерина | M2: =График!B27 -> Самошкина Алина
D3: Факт | F3: Прогноз | G3: Факт | I3: Прогноз | J3: Факт | L3: Прогноз | M3: Факт | O3: Прогноз
A4: Выручка | D4: ='Ялта, Ленина, 18'!K8 -> 0.60425938 | E4: ='Ялта, Ленина, 18'!J8 -> 1218796 | F4: ='Ялта, Ленина, 18'!M8 -> 0.60425938 | G4: =Рогалевич!N8 -> 0.75636055 | H4: =Рогалевич!M8 -> 474399 | I4: =Рогалевич!P8 -> 0.75636055 | J4: =Уразгильдеева!N8 -> 0.68291551 | K4: =Уразгильдеева!M8 -> 576247 | L4: =Уразгильдеева!P8 -> 0.68291551 | M4: ='[2]Яковенко А. К'!K8 -> #REF! | N4: ='[2]Яковенко А. К'!J8 -> #REF! | O4: ='[2]Яковенко А. К'!M8 -> #REF!
A5: Кол-во изделий | D5: ='Ялта, Ленина, 18'!K9 -> 0.60892173 | E5: ='Ялта, Ленина, 18'!J9 -> 178 | F5: ='Ялта, Ленина, 18'!M9 -> 0.60892173 | G5: =Рогалевич!N9 -> 0.69306624 | H5: =Рогалевич!M9 -> 63 | I5: =Рогалевич!P9 -> 0.69306624 | J5: =Уразгильдеева!N9 -> 0.77683895 | K5: =Уразгильдеева!M9 -> 95 | L5: =Уразгильдеева!P9 -> 0.77683895 | M5: ='[2]Яковенко А. К'!K9 -> #REF! | N5: ='[2]Яковенко А. К'!J9 -> #REF! | O5: ='[2]Яковенко А. К'!M9 -> #REF!
A6: Средний чек | D6: ='Ялта, Ленина, 18'!K10 -> 0.93995903 | E6: ='Ялта, Ленина, 18'!J10 -> 11285.148 | F6: ='Ялта, Ленина, 18'!M10 -> 0.93995903 | G6: =Рогалевич!N10 -> 0.94079746 | H6: =Рогалевич!M10 -> 11295.214 | I6: =Рогалевич!P10 -> 0.94079746 | J6: =Уразгильдеева!N10 -> 0.9599317 | K6: =Уразгильдеева!M10 -> 11524.94 | L6: =Уразгильдеева!P10 -> 0.9599317 | M6: ='[2]Яковенко А. К'!K10 -> #REF! | N6: ='[2]Яковенко А. К'!J10 -> #REF! | O6: ='[2]Яковенко А. К'!M10 -> #REF!
A7: Средняя стоимость изделия | D7: ='Ялта, Ленина, 18'!K11 -> 0.99234327 | E7: ='Ялта, Ленина, 18'!J11 -> 6847.1685 | F7: ='Ялта, Ленина, 18'!M11 -> 0.99234327 | G7: =Рогалевич!N11 -> 1.0913251 | H7: =Рогалевич!M11 -> 7530.1429 | I7: =Рогалевич!P11 -> 1.0913251 | J7: =Уразгильдеева!N11 -> 0.87909535 | K7: =Уразгильдеева!M11 -> 6065.7579 | L7: =Уразгильдеева!P11 -> 0.87909535 | M7: ='[2]Яковенко А. К'!K11 -> #REF! | N7: ='[2]Яковенко А. К'!J11 -> #REF! | O7: ='[2]Яковенко А. К'!M11 -> #REF!
A8: Длина чека | D8: ='Ялта, Ленина, 18'!K12 -> 0.94721158 | E8: ='Ялта, Ленина, 18'!J12 -> 1.6481481 | F8: ='Ялта, Ленина, 18'!M12 -> 0.94721158 | G8: =Рогалевич!N12 -> 0.86206897 | H8: =Рогалевич!M12 -> 1.5 | I8: =Рогалевич!P12 -> 0.86206897 | J8: =Уразгильдеева!N12 -> 1.091954 | K8: =Уразгильдеева!M12 -> 1.9 | L8: =Уразгильдеева!P12 -> 1.091954 | M8: ='[2]Яковенко А. К'!K12 -> #REF! | N8: ='[2]Яковенко А. К'!J12 -> #REF! | O8: ='[2]Яковенко А. К'!M12 -> #REF!
A9: Кол-во чеков | D9: ='Ялта, Ленина, 18'!K13 -> 0.64285714 | E9: ='Ялта, Ленина, 18'!J13 -> 108 | F9: ='Ялта, Ленина, 18'!M13 -> 0.64285714 | G9: =Рогалевич!N13 -> 0.80395683 | H9: =Рогалевич!M13 -> 42 | I9: =Рогалевич!P13 -> 0.80395683 | J9: =Уразгильдеева!N13 -> 0.71142093 | K9: =Уразгильдеева!M13 -> 50 | L9: =Уразгильдеева!P13 -> 0.71142093 | M9: ='[2]Яковенко А. К'!K13 -> #REF! | N9: ='[2]Яковенко А. К'!J13 -> #REF! | O9: ='[2]Яковенко А. К'!M13 -> #REF!
A10: Кол-во смен план/отработано | D10: ='Ялта, Ленина, 18'!K14 -> 1 | E10: ='Ялта, Ленина, 18'!J14 -> 31 | G10: =Рогалевич!N14 -> 1 | H10: =Рогалевич!M14 -> 14 | J10: =Уразгильдеева!N14 -> 1 | K10: =Уразгильдеева!M14 -> 17 | M10: ='[2]Яковенко А. К'!K14 -> #REF! | N10: ='[2]Яковенко А. К'!J14 -> #REF!
A11: Средние продажи в смену | D11: ='Ялта, Ленина, 18'!K15 -> 0.60425938 | E11: ='Ялта, Ленина, 18'!J15 -> 39316 | F11: ='Ялта, Ленина, 18'!M15 -> 0.60425938 | G11: =Рогалевич!N15 -> 0.52079859 | H11: =Рогалевич!M15 -> 33885.643 | I11: =Рогалевич!P15 -> 0.52079859 | J11: =Уразгильдеева!N15 -> 0.52097134 | K11: =Уразгильдеева!M15 -> 33896.882 | L11: =Уразгильдеева!P15 -> 0.52097134 | M11: ='[2]Яковенко А. К'!K15 -> #REF! | N11: ='[2]Яковенко А. К'!J15 -> #REF! | O11: ='[2]Яковенко А. К'!M15 -> #REF!
A12: Трафик | D12: ='Ялта, Ленина, 18'!K17 -> 0.93771429 | E12: ='Ялта, Ленина, 18'!J17 -> 1312.8 | F12: ='Ялта, Ленина, 18'!M17 -> 0.93771429 | G12: =Рогалевич!N17 -> 0.68451182 | H12: =Рогалевич!M17 -> 298 | I12: =Рогалевич!P17 -> 0.68451182 | J12: =Уразгильдеева!N17 -> 1.0500573 | K12: =Уразгильдеева!M17 -> 615 | L12: =Уразгильдеева!P17 -> 1.0500573 | M12: ='[2]Яковенко А. К'!K17 -> #REF! | N12: ='[2]Яковенко А. К'!J17 -> #REF! | O12: ='[2]Яковенко А. К'!M17 -> #REF!
A13: UNOde50 | D13: ='Ялта, Ленина, 18'!R19 -> 0 | E13: ='Ялта, Ленина, 18'!S18 -> 0 | F13: ='Ялта, Ленина, 18'!S19 -> 0 | G13: =Рогалевич!X19 -> 0 | H13: =Рогалевич!Y18 -> 0 | I13: =Рогалевич!Y19 -> 0 | J13: =Уразгильдеева!U19 -> 0 | K13: =Уразгильдеева!V18 -> 0 | L13: =Уразгильдеева!V19 -> 0 | M13: ='[2]Яковенко А. К'!S19 -> #REF! | N13: ='[2]Яковенко А. К'!T18 -> #REF! | O13: ='[2]Яковенко А. К'!T19 -> #REF!
A14: IS | D14: ='Ялта, Ленина, 18'!R13 -> 0 | E14: ='Ялта, Ленина, 18'!S12 -> 0 | F14: ='Ялта, Ленина, 18'!S13 -> 0 | G14: =Рогалевич!Y13 -> 0 | H14: =Рогалевич!Y12 -> 0 | I14: =Рогалевич!Z13 -> 0 | J14: =Уразгильдеева!U13 -> 0 | K14: =Уразгильдеева!V12 -> 0 | L14: =Уразгильдеева!V13 -> 0 | M14: ='[2]Яковенко А. К'!S13 -> #REF! | N14: ='[2]Яковенко А. К'!T12 -> #REF! | O14: ='[2]Яковенко А. К'!T13 -> #REF!
A15: ='Ялта, Ленина, 18'!M23 -> Agafi | D15: ='Ялта, Ленина, 18'!U13 -> 0 | E15: ='Ялта, Ленина, 18'!V12 -> 0 | F15: ='Ялта, Ленина, 18'!V13 -> 0 | G15: =Рогалевич!AB13 -> 0 | H15: =Рогалевич!AB12 -> 0 | I15: =Рогалевич!AC13 -> 0 | J15: =Уразгильдеева!X13 -> 0 | K15: =Уразгильдеева!Y12 -> 0 | L15: =Уразгильдеева!Y13 -> 0 | M15: ='[2]Яковенко А. К'!V13 -> #REF! | N15: ='[2]Яковенко А. К'!W12 -> #REF! | O15: ='[2]Яковенко А. К'!W13 -> #REF!
A16: Отклонение от плана | D16: ='Ялта, Ленина, 18'!J16 -> -798212 | G16: =Рогалевич!Q8 -> -152813.78 | J16: =Уразгильдеева!Q8 -> -267557.24 | M16: ='[2]Яковенко А. К'!N8 -> #REF!

Sheet План на день
A1: Выручка | B1: 73000
A2: Кол-во изделий | B2: =B1/B4 -> 10.57971
A3: Средний чек | B3: =B4*B5 -> 12006
A4: Средняя стоимость изделия | B4: ='Ялта, Ленина, 18'!I11 -> 6900
A5: Длина чека | B5: ='Ялта, Ленина, 18'!I12 -> 1.74
A6: Кол-во чеков | B6: =IF(B5<>0,B2/B5,"") -> 6.0802932
A7: Конверсия | B7: ='Ялта, Ленина, 18'!I20 -> 0.12
A8: IS | B8: =('Ялта, Ленина, 18'!R12-'Ялта, Ленина, 18'!S12)/('Ялта, Ленина, 18'!I14-'Ялта, Ленина, 18'!J14) -> #DIV/0!
A9: UNOde50 | B9: =('Ялта, Ленина, 18'!R18-'Ялта, Ленина, 18'!S18)/('Ялта, Ленина, 18'!I14-'Ялта, Ленина, 18'!J14) -> #DIV/0!
A10: ='Ялта, Ленина, 18'!M23 -> Agafi | B10: =('Ялта, Ленина, 18'!U12-'Ялта, Ленина, 18'!V12)/('Ялта, Ленина, 18'!I14-'Ялта, Ленина, 18'!J14) -> #DIV/0!

Sheet Рогалевич
B1: Специфика месяца
B2: (отчетная дата) | J2: ЕЖЕДНЕВНЫЙ ОТЧЕТ О ПРОДАЖАХ
B3: Осталось до выполнения плана!!! | J3: =График!B29 -> Рогалевич Ирина
C4: =L8-D57 -> 152813.78 | E4: =IF(L8<>0,C4/L8,0) -> 0.24363945
I6: Целевые показатели
I7: Показатель | L7: План | M7: Факт | N7: % выполнения | O7: Прогноз выполнения | P7: % выполнения по прогнозу | Q7: Отклонение | R7: Факт аналогичного месяца прошлого года | S7: Отклонение LFL
I8: Выручка | L8: ='Ялта, Ленина, 18'!I8/График!AJ30*График!AJ29 -> 627212.78 | M8: =D57 -> 474399 | N8: =IF(AND(L8<>"",L8<>0,M8<>""),M8/L8,"") -> 0.75636055 | O8: =IF(SUMIF($D$25:$D$56,">=0",$U$25:$U$56)<>0,L8*D57/SUMIF($D$25:$D$56,">=0",$U$25:$U$56),0) -> 474399 | P8: =IF(AND(L8<>"",L8<>0,O8<>"",O8<>0),O8/L8,"") -> 0.75636055 | Q8: =IF(AND(M8<>0,M8<>"",L8<>0,L8<>""),O8-L8,"") -> -152813.78 | S8: =IF(AND(R8<>"",R8<>0,O8<>"",O8<>0),-R8+O8,"") | T8: =IF(AND(S8<>"",S8<>0,R8<>0,R8<>""),S8/R8,"")
I9: Кол-во изделий | L9: =L8/L11 -> 90.900403 | M9: =E57 -> 63 | N9: =IF(AND(L9<>"",L9<>0,M9<>""),M9/L9,"") -> 0.69306624 | O9: =IF(SUMIF($E$25:$E$54,">=0",$V$25:$V$54)<>0,L9*E57/SUMIF($E$25:$E$54,">=0",$V$25:$V$54),0) -> 63 | P9: =IF(AND(L9<>"",L9<>0,O9<>"",O9<>0),O9/L9,"") -> 0.69306624 | Q9: =IF(AND(M9<>0,M9<>"",L9<>0,L9<>""),O9-L9,"") -> -27.900403 | R9: =R8/R11 -> #DIV/0! | S9: =IF(AND(R9<>"",R9<>0,O9<>"",O9<>0),-R9+O9,"") -> #DIV/0! | T9: =IF(AND(S9<>"",S9<>0,R9<>0,R9<>""),S9/R9,"") -> #DIV/0!
I10: Средний чек | L10: =L11*L12 -> 12006 | M10: =H57 -> 11295.214 | N10: =IF(AND(L10<>"",L10<>0,M10<>""),M10/L10,"") -> 0.94079746 | O10: =M10 -> 11295.214 | P10: =IF(AND(L10<>"",L10<>0,O10<>"",O10<>0),O10/L10,"") -> 0.94079746 | Q10: =IF(AND(M10<>0,M10<>"",L10<>0,L10<>""),O10-L10,"") -> -710.78571 | R10: =R11*R12 -> 0 | S10: =IF(AND(R10<>"",R10<>0,O10<>"",O10<>0),-R10+O10,"") | T10: =IF(AND(S10<>"",S10<>0,R10<>0,R10<>""),S10/R10,"")
I11: Средняя стоимость изделия | L11: ='Ялта, Ленина, 18'!I11 -> 6900 | M11: =F57 -> 7530.1429 | N11: =IF(AND(L11<>"",L11<>0,M11<>""),M11/L11,"") -> 1.0913251 | O11: =IF(O9>0,O8/O9,"") -> 7530.1429 | P11: =IF(AND(L11<>"",L11<>0,O11<>"",O11<>0),O11/L11,"") -> 1.0913251 | Q11: =IF(AND(M11<>0,M11<>"",L11<>0,L11<>""),O11-L11,"") -> 630.14286 | S11: =IF(AND(R11<>"",R11<>0,O11<>"",O11<>0),-R11+O11,"") | T11: =IF(AND(S11<>"",S11<>0,R11<>0,R11<>""),S11/R11,"")
I12: Длина чека | L12: ='Ялта, Ленина, 18'!I12 -> 1.74 | M12: =J57 -> 1.5 | N12: =IF(AND(L12<>"",L12<>0,M12<>""),M12/L12,"") -> 0.86206897 | O12: =M12 -> 1.5 | P12: =IF(AND(L12<>"",L12<>0,O12<>"",O12<>0),O12/L12,"") -> 0.86206897 | Q12: =IF(AND(M12<>0,M12<>"",L12<>0,L12<>""),O12-L12,"") -> -0.24 | S12: =IF(AND(R12<>"",R12<>0,O12<>"",O12<>0),-R12+O12,"") | T12: =IF(AND(S12<>"",S12<>0,R12<>0,R12<>""),S12/R12,"")
I13: Кол-во чеков | L13: =IF(L12<>0,L9/L12,"") -> 52.241611 | M13: =G57 -> 42 | N13: =IF(AND(L13<>"",L13<>0,M13<>""),M13/L13,"") -> 0.80395683 | O13: =IF(SUMIF($G$25:$G$54,">=0",$W$25:$W$54)<>0,L13*G57/SUMIF($G$25:$G$54,">=0",$W$25:$W$54),"") -> 42 | P13: =IF(AND(L13<>"",L13<>0,O13<>"",O13<>0),O13/L13,"") -> 0.80395683 | Q13: =IF(AND(M13<>0,M13<>"",L13<>0,L13<>""),O13-L13,"") -> -10.241611 | S13: =IF(AND(R13<>"",R13<>0,O13<>"",O13<>0),-R13+O13,"")
I14: Кол-во смен план/отработано | L14: =График!AI29 -> 14 | M14: 14 | N14: =IF(AND(L14<>"",L14<>0,M14<>""),M14/L14,"") -> 1 | O14: =L14 -> 14 | P14: =IF(AND(L14<>"",L14<>0,O14<>"",O14<>0),O14/L14,"") -> 1 | Q14: =IF(AND(M14<>0,M14<>"",L14<>0,L14<>""),O14-L14,"") -> 0 | S14: =IF(AND(R14<>"",R14<>0,O14<>"",O14<>0),-R14+O14,"") | T14: =IF(AND(S14<>"",S14<>0,R14<>0,R14<>""),S14/R14,"")
I15: Средние продажи в смену | L15: ='Ялта, Ленина, 18'!I15 -> 65064.774 | M15: =M8/M14 -> 33885.643 | N15: =IF(AND(L15<>"",L15<>0,M15<>""),M15/L15,"") -> 0.52079859 | O15: =M15 -> 33885.643 | P15: =IF(AND(L15<>"",L15<>0,O15<>"",O15<>0),O15/L15,"") -> 0.52079859 | Q15: =IF(AND(M15<>0,M15<>"",L15<>0,L15<>""),O15-L15,"") -> -31179.131 | S15: =IF(AND(R15<>"",R15<>0,O15<>"",O15<>0),-R15+O15,"") | T15: =IF(AND(S15<>"",S15<>0,R15<>0,R15<>""),S15/R15,"")
I16: Отставание/Перевыполнение | M16: =M8-L15*M14 -> -436507.84 | N16: =IF(AND(L16<>"",L16<>0,M16<>""),M16/L16,"") | O16: =M16 -> -436507.84 | P16: =IF(AND(L16<>"",L16<>0,O16<>"",O16<>0),O16/L16,"") | Q16: =IF(AND(M16<>0,M16<>"",L16<>0,L16<>""),O16-L16,"") | S16: =IF(AND(R16<>"",R16<>0,O16<>"",O16<>0),-R16+O16,"") | T16: =IF(AND(S16<>"",S16<>0,R16<>0,R16<>""),S16/R16,"")
I17: Трафик | L17: ='Ялта, Ленина, 18'!I17/График!AJ30*График!AJ29 -> 435.34676 | M17: =I57 -> 298 | N17: =IF(AND(L17<>"",L17<>0,M17<>""),M17/L17,"") -> 0.68451182 | O17: =M17/M14*L14 -> 298 | P17: =IF(AND(L17<>"",L17<>0,O17<>"",O17<>0),O17/L17,"") -> 0.68451182 | Q17: =IF(AND(M17<>0,M17<>"",L17<>0,L17<>""),O17-L17,"") -> -137.34676 | S17: =IF(AND(R17<>"",R17<>0,O17<>"",O17<>0),-R17+O17,"") | T17: =IF(AND(S17<>"",S17<>0,R17<>0,R17<>""),S17/R17,"")
N18: =IF(AND(L18<>"",L18<>0,M18<>""),M18/L18,"") | O18: =M18 -> 0 | P18: =IF(AND(L18<>"",L18<>0,O18<>"",O18<>0),O18/L18,"") | Q18: =IF(AND(M18<>0,M18<>"",L18<>0,L18<>""),O18-L18,"") | R18: 0 | S18: =IF(AND(R18<>"",R18<>0,O18<>"",O18<>0),-R18+O18,"") | T18: =IF(AND(S18<>"",S18<>0,R18<>0,R18<>""),S18/R18,"")
N19: =IF(AND(L19<>"",L19<>0,M19<>""),M19/L19,"") | O19: =M19 -> 0 | P19: =IF(AND(L19<>"",L19<>0,O19<>"",O19<>0),O19/L19,"") | Q19: =IF(AND(M19<>0,M19<>"",L19<>0,L19<>""),O19-L19,"") | R19: 0 | S19: =IF(AND(R19<>"",R19<>0,O19<>"",O19<>0),-R19+O19,"") | T19: =IF(AND(S19<>"",S19<>0,R19<>0,R19<>""),S19/R19,"")
I20: Конверсия план/факт | L20: ='Ялта, Ленина, 18'!I20 -> 0.12 | M20: =S57 -> 0.1409396 | N20: =M20/L20 -> 1.1744966 | O20: =IF(AND(N8<>0,L14<>0,I57<>0),(I57*S57+(I57/N8-I57)*L20)/(I57/N8),0) -> 0.13583789 | P20: =IF(AND(L20<>"",L20<>0,O20<>"",O20<>0),O20/L20,"") -> 1.1319824 | Q20: =IF(AND(M20<>0,M20<>"",L20<>0,L20<>""),O20-L20,"") -> 0.015837885 | S20: =IF(AND(R20<>"",R20<>0,O20<>"",O20<>0),-R20+O20,"") | T20: =IF(AND(S20<>"",S20<>0,R20<>0,R20<>""),S20/R20,"")
B22: Факт продаж за месяц | T22: % выполнения дневного плана | U22: Раcпределение плана по дням
B23: Дата | C23: День недели | D23: Выручка (руб) | E23: Кол-во единиц (шт.) | F23: Средняя стоимость изделия (руб.) | G23: Количество чеков (шт.) | H23: Средняя сумма чека (руб.) | I23: Трафик | J23: Длина чека (шт.) | K23: UNOde50 | L23: IS | M23: Agafi | N23: Kalliope | O23: Raganella | P23: CC\MP | Q23: Antura | R23: SALE | S23: Конверсия (%) | U23: выручка, план | V23: кол-во ед, план | W23: Кол-во чеков, план | X23: выручка, скорректир.план | Y23: кол-во ед, скорр. план | Z23: кол-во чеков, скорр. план | AA23: Коэфф. Дня Недели | AB23: Специфика месяца
B24: 1 | C24: 2 | D24: 3 | E24: 4 | F24: 5 | G24: 6 | H24: 7 | I24: 8 | J24: 9 | K24: 10 | L24: 11 | M24: 12 | N24: 13 | O24: 14 | Q24: 15 | R24: 16 | S24: 17 | U24: 1 | V24: 2 | W24: 3 | X24: 4 | Y24: 5 | Z24: 6 | AA24: 10 | AB24: 11
A25: 1 | B25: 46082 | C25: вс | D25: 70021 | E25: 9 | F25: =IF(AND(E25<>"",E25<>0),D25/E25,"") -> 7780.1111 | G25: 7 | H25: =IF(AND(G25<>"",G25<>0),D25/G25,"") -> 10003 | I25: 20 | J25: =IF(AND(G25<>"",G25<>0),E25/G25,"") -> 1.2857143 | Q25: 32552 | S25: =IF(AND(I25<>"",I25<>0),G25/I25,"") -> 0.35 | T25: =D25/U25 -> 1.5629369 | U25: =$L$8*AA25*AB25/SUMPRODUCT($AB$25:$AB$56,$AA$25:$AA$56) -> 44800.913 | V25: =$L$9*AA25*AB25/SUMPRODUCT($AB$25:$AB$56,$AA$25:$AA$56) -> 6.4928859 | W25: =IF($L$12="","",V25/$L$12) -> 3.7315436 | X25: =IF(D25<>"",D25,U25) -> 70021 | Y25: =IF(E25<>"",E25,V25) -> 9 | Z25: =IF(G25<>"",G25,W25) -> 7 | AA25: 1 | AB25: 1
A26: 2 | B26: 46083 | C26: пн | D26: 12184 | E26: 2 | F26: =IF(AND(E26<>"",E26<>0),D26/E26,"") -> 6092 | G26: 1 | H26: =IF(AND(G26<>"",G26<>0),D26/G26,"") -> 12184 | I26: 13 | J26: =IF(AND(G26<>"",G26<>0),E26/G26,"") -> 2 | S26: =IF(AND(I26<>"",I26<>0),G26/I26,"") -> 0.076923077 | T26: =D26/U26 -> 0.27195874 | U26: =$L$8*AA26*AB26/SUMPRODUCT($AB$25:$AB$56,$AA$25:$AA$56) -> 44800.913 | V26: =$L$9*AA26*AB26/SUMPRODUCT($AB$25:$AB$58,$AA$25:$AA$58) -> 6.4928859 | W26: =IF($L$12="","",V26/$L$12) -> 3.7315436 | X26: =IF(AB26<>"",IF(D26<>"",D26,($L$8-SUM($X$25:X25))*AA26*AB26/SUMPRODUCT($AB26:$AB$56,$AA26:$AA$56)),"") -> 12184 | Y26: =IF(AB26<>"",IF(E26<>"",E26,($L$9-SUM($Y$25:Y25))*AA26*AB26/SUMPRODUCT($AB26:$AB$58,$AA26:$AA$58)),"") -> 2 | Z26: =IF(AB26<>"",IF($L$12<>"",IF(G26<>"",G26,($L$9/$L$12-SUM($Z$25:Z25))*AA26*AB26/SUMPRODUCT($AB26:$AB$58,$AA26:$AA$58)),""),"") -> 1 | AA26: 1 | AB26: 1
A27: 3 | B27: 46084 | C27: вт | D27: 6593 | E27: 1 | F27: 6593 | G27: 1 | H27: =IF(AND(G27<>"",G27<>0),D27/G27,"") -> 6593 | I27: 10 | J27: =IF(AND(G27<>"",G27<>0),E27/G27,"") -> 1 | S27: =IF(AND(I27<>"",I27<>0),G27/I27,"") -> 0.1 | T27: =D27/U27 -> 0.14716218 | U27: =$L$8*AA27*AB27/SUMPRODUCT($AB$25:$AB$56,$AA$25:$AA$56) -> 44800.913 | V27: =$L$9*AA27*AB27/SUMPRODUCT($AB$25:$AB$58,$AA$25:$AA$58) -> 6.4928859 | W27: =IF($L$12="","",V27/$L$12) -> 3.7315436 | X27: =IF(AB27<>"",IF(D27<>"",D27,($L$8-SUM($X$25:X26))*AA27*AB27/SUMPRODUCT($AB27:$AB$58,$AA27:$AA$58)),"") -> 6593 | Y27: =IF(AB27<>"",IF(E27<>"",E27,($L$9-SUM($Y$25:Y26))*AA27*AB27/SUMPRODUCT($AB27:$AB$58,$AA27:$AA$58)),"") -> 1 | Z27: =IF(AB27<>"",IF($L$12<>"",IF(G27<>"",G27,($L$9/$L$12-SUM($Z$25:Z26))*AA27*AB27/SUMPRODUCT($AB27:$AB$58,$AA27:$AA$58)),""),"") -> 1 | AA27: 1 | AB27: 1
A28: 4 | B28: 46085 | C28: ср | D28: 0 | E28: 0 | F28: 0 | G28: 0 | H28: 0 | I28: 10 | J28: =IF(AND(G28<>"",G28<>0),E28/G28,"") | S28: =IF(AND(I28<>"",I28<>0),G28/I28,"") -> 0 | T28: =D28/U28 -> 0 | U28: =$L$8*AA28*AB28/SUMPRODUCT($AB$25:$AB$56,$AA$25:$AA$56) -> 44800.913 | V28: =$L$9*AA28*AB28/SUMPRODUCT($AB$25:$AB$58,$AA$25:$AA$58) -> 6.4928859 | W28: =IF($L$12="","",V28/$L$12) -> 3.7315436 | X28: =IF(AB28<>"",IF(D28<>"",D28,($L$8-SUM($X$25:X27))*AA28*AB28/SUMPRODUCT($AB28:$AB$58,$AA28:$AA$58)),"") -> 0 | Y28: =IF(AB28<>"",IF(E28<>"",E28,($L$9-SUM($Y$25:Y27))*AA28*AB28/SUMPRODUCT($AB28:$AB$58,$AA28:$AA$58)),"") -> 0 | Z28: =IF(AB28<>"",IF($L$12<>"",IF(G28<>"",G28,($L$9/$L$12-SUM($Z$25:Z27))*AA28*AB28/SUMPRODUCT($AB28:$AB$58,$AA28:$AA$58)),""),"") -> 0 | AA28: 1 | AB28: 1
A29: 5 | B29: 46086 | C29: чт | D29: 20466 | E29: 4 | F29: =IF(AND(E29<>"",E29<>0),D29/E29,"") -> 5116.5 | G29: 1 | H29: =IF(AND(G29<>"",G29<>0),D29/G29,"") -> 20466 | I29: 15 | J29: =IF(AND(G29<>"",G29<>0),E29/G29,"") -> 4 | Q29: 8790 | S29: =IF(AND(I29<>"",I29<>0),G29/I29,"") -> 0.066666667 | T29: =D29/U29 -> 0.45682105 | U29: =$L$8*AA29*AB29/SUMPRODUCT($AB$25:$AB$56,$AA$25:$AA$56) -> 44800.913 | V29: =$L$9*AA29*AB29/SUMPRODUCT($AB$25:$AB$58,$AA$25:$AA$58) -> 6.4928859 | W29: =IF($L$12="","",V29/$L$12) -> 3.7315436 | X29: =IF(AB29<>"",IF(D29<>"",D29,($L$8-SUM($X$25:X28))*AA29*AB29/SUMPRODUCT($AB29:$AB$58,$AA29:$AA$58)),"") -> 20466 | Y29: =IF(AB29<>"",IF(E29<>"",E29,($L$9-SUM($Y$25:Y28))*AA29*AB29/SUMPRODUCT($AB29:$AB$58,$AA29:$AA$58)),"") -> 4 | Z29: =IF(AB29<>"",IF($L$12<>"",IF(G29<>"",G29,($L$9/$L$12-SUM($Z$25:Z28))*AA29*AB29/SUMPRODUCT($AB29:$AB$58,$AA29:$AA$58)),""),"") -> 1 | AA29: 1 | AB29: 1
A30: 6 | B30: 46087 | C30: пт | D30: 21978 | E30: 3 | F30: =IF(AND(E30<>"",E30<>0),D30/E30,"") -> 7326 | G30: 2 | H30: =IF(AND(G30<>"",G30<>0),D30/G30,"") -> 10989 | I30: 10 | J30: =IF(AND(G30<>"",G30<>0),E30/G30,"") -> 1.5 | S30: =IF(AND(I30<>"",I30<>0),G30/I30,"") -> 0.2 | T30: =D30/U30 -> 0.49057036 | U30: =$L$8*AA30*AB30/SUMPRODUCT($AB$25:$AB$56,$AA$25:$AA$56) -> 44800.913 | V30: =$L$9*AA30*AB30/SUMPRODUCT($AB$25:$AB$58,$AA$25:$AA$58) -> 6.4928859 | W30: =IF($L$12="","",V30/$L$12) -> 3.7315436 | X30: =IF(AB30<>"",IF(D30<>"",D30,($L$8-SUM($X$25:X29))*AA30*AB30/SUMPRODUCT($AB30:$AB$58,$AA30:$AA$58)),"") -> 21978 | Y30: =IF(AB30<>"",IF(E30<>"",E30,($L$9-SUM($Y$25:Y29))*AA30*AB30/SUMPRODUCT($AB30:$AB$58,$AA30:$AA$58)),"") -> 3 | Z30: =IF(AB30<>"",IF($L$12<>"",IF(G30<>"",G30,($L$9/$L$12-SUM($Z$25:Z29))*AA30*AB30/SUMPRODUCT($AB30:$AB$58,$AA30:$AA$58)),""),"") -> 2 | AA30: 1 | AB30: 1
A31: 7 | B31: 46088 | C31: сб | D31: 34746 | E31: 7 | F31: =IF(AND(E31<>"",E31<>0),D31/E31,"") -> 4963.7143 | G31: 6 | H31: =IF(AND(G31<>"",G31<>0),D31/G31,"") -> 5791 | I31: 25 | J31: =IF(AND(G31<>"",G31<>0),E31/G31,"") -> 1.1666667 | R31: 2793 | S31: =IF(AND(I31<>"",I31<>0),G31/I31,"") -> 0.24 | T31: =D31/U31 -> 0.77556456 | U31: =$L$8*AA31*AB31/SUMPRODUCT($AB$25:$AB$56,$AA$25:$AA$56) -> 44800.913 | V31: =$L$9*AA31*AB31/SUMPRODUCT($AB$25:$AB$58,$AA$25:$AA$58) -> 6.4928859 | W31: =IF($L$12="","",V31/$L$12) -> 3.7315436 | X31: =IF(AB31<>"",IF(D31<>"",D31,($L$8-SUM($X$25:X30))*AA31*AB31/SUMPRODUCT($AB31:$AB$58,$AA31:$AA$58)),"") -> 34746 | Y31: =IF(AB31<>"",IF(E31<>"",E31,($L$9-SUM($Y$25:Y30))*AA31*AB31/SUMPRODUCT($AB31:$AB$58,$AA31:$AA$58)),"") -> 7 | Z31: =IF(AB31<>"",IF($L$12<>"",IF(G31<>"",G31,($L$9/$L$12-SUM($Z$25:Z30))*AA31*AB31/SUMPRODUCT($AB31:$AB$58,$AA31:$AA$58)),""),"") -> 6 | AA31: 1 | AB31: 1
A32: 8 | B32: 46089 | C32: вс | D32: =28093+100576+6191 -> 134860 | E32: 12 | F32: =IF(AND(E32<>"",E32<>0),D32/E32,"") -> 11238.333 | G32: 8 | H32: =IF(AND(G32<>"",G32<>0),D32/G32,"") -> 16857.5 | I32: 40 | J32: =IF(AND(G32<>"",G32<>0),E32/G32,"") -> 1.5 | K32: 100576 | N32: 6191 | S32: =IF(AND(I32<>"",I32<>0),G32/I32,"") -> 0.2 | T32: =D32/U32 -> 3.0102065 | U32: =$L$8*AA32*AB32/SUMPRODUCT($AB$25:$AB$56,$AA$25:$AA$56) -> 44800.913 | V32: =$L$9*AA32*AB32/SUMPRODUCT($AB$25:$AB$58,$AA$25:$AA$58) -> 6.4928859 | W32: =IF($L$12="","",V32/$L$12) -> 3.7315436 | X32: =IF(AB32<>"",IF(D32<>"",D32,($L$8-SUM($X$25:X31))*AA32*AB32/SUMPRODUCT($AB32:$AB$58,$AA32:$AA$58)),"") -> 134860 | Y32: =IF(AB32<>"",IF(E32<>"",E32,($L$9-SUM($Y$25:Y31))*AA32*AB32/SUMPRODUCT($AB32:$AB$58,$AA32:$AA$58)),"") -> 12 | Z32: =IF(AB32<>"",IF($L$12<>"",IF(G32<>"",G32,($L$9/$L$12-SUM($Z$25:Z31))*AA32*AB32/SUMPRODUCT($AB32:$AB$58,$AA32:$AA$58)),""),"") -> 8 | AA32: 1 | AB32: 1
A33: 9 | B33: 46090 | C33: пн | D33: 20092 | E33: 3 | F33: =IF(AND(E33<>"",E33<>0),D33/E33,"") -> 6697.3333 | G33: 2 | H33: =IF(AND(G33<>"",G33<>0),D33/G33,"") -> 10046 | I33: 40 | J33: =IF(AND(G33<>"",G33<>0),E33/G33,"") -> 1.5 | S33: =IF(AND(I33<>"",I33<>0),G33/I33,"") -> 0.05 | T33: =D33/U33 -> 0.44847301 | U33: =$L$8*AA33*AB33/SUMPRODUCT($AB$25:$AB$56,$AA$25:$AA$56) -> 44800.913 | V33: =$L$9*AA33*AB33/SUMPRODUCT($AB$25:$AB$58,$AA$25:$AA$58) -> 6.4928859 | W33: =IF($L$12="","",V33/$L$12) -> 3.7315436 | X33: =IF(AB33<>"",IF(D33<>"",D33,($L$8-SUM($X$25:X32))*AA33*AB33/SUMPRODUCT($AB33:$AB$58,$AA33:$AA$58)),"") -> 20092 | Y33: =IF(AB33<>"",IF(E33<>"",E33,($L$9-SUM($Y$25:Y32))*AA33*AB33/SUMPRODUCT($AB33:$AB$58,$AA33:$AA$58)),"") -> 3 | Z33: =IF(AB33<>"",IF($L$12<>"",IF(G33<>"",G33,($L$9/$L$12-SUM($Z$25:Z32))*AA33*AB33/SUMPRODUCT($AB33:$AB$58,$AA33:$AA$58)),""),"") -> 2 | AA33: 1 | AB33: 1
A34: 10 | B34: 46091 | C34: вт | D34: 38929 | E34: 7 | F34: =IF(AND(E34<>"",E34<>0),D34/E34,"") -> 5561.2857 | G34: 6 | H34: =IF(AND(G34<>"",G34<>0),D34/G34,"") -> 6488.1667 | I34: 40 | J34: =IF(AND(G34<>"",G34<>0),E34/G34,"") -> 1.1666667 | K34: 9493 | S34: =IF(AND(I34<>"",I34<>0),G34/I34,"") -> 0.15 | T34: =D34/U34 -> 0.86893319 | U34: =$L$8*AA34*AB34/SUMPRODUCT($AB$25:$AB$56,$AA$25:$AA$56) -> 44800.913 | V34: =$L$9*AA34*AB34/SUMPRODUCT($AB$25:$AB$58,$AA$25:$AA$58) -> 6.4928859 | W34: =IF($L$12="","",V34/$L$12) -> 3.7315436 | X34: =IF(AB34<>"",IF(D34<>"",D34,($L$8-SUM($X$25:X33))*AA34*AB34/SUMPRODUCT($AB34:$AB$58,$AA34:$AA$58)),"") -> 38929 | Y34: =IF(AB34<>"",IF(E34<>"",E34,($L$9-SUM($Y$25:Y33))*AA34*AB34/SUMPRODUCT($AB34:$AB$58,$AA34:$AA$58)),"") -> 7 | Z34: =IF(AB34<>"",IF($L$12<>"",IF(G34<>"",G34,($L$9/$L$12-SUM($Z$25:Z33))*AA34*AB34/SUMPRODUCT($AB34:$AB$58,$AA34:$AA$58)),""),"") -> 6 | AA34: 1 | AB34: 1
A35: 11 | B35: 46093 | C35: чт | D35: 32075 | E35: 3 | F35: =IF(AND(E35<>"",E35<>0),D35/E35,"") -> 10691.667 | G35: 1 | H35: =IF(AND(G35<>"",G35<>0),D35/G35,"") -> 32075 | I35: 18 | J35: =IF(AND(G35<>"",G35<>0),E35/G35,"") -> 3 | Q35: 16890 | S35: =IF(AND(I35<>"",I35<>0),G35/I35,"") -> 0.055555556 | T35: =D35/U35 -> 0.71594523 | U35: =$L$8*AA35*AB35/SUMPRODUCT($AB$25:$AB$56,$AA$25:$AA$56) -> 44800.913 | V35: =$L$9*AA35*AB35/SUMPRODUCT($AB$25:$AB$58,$AA$25:$AA$58) -> 6.4928859 | W35: =IF($L$12="","",V35/$L$12) -> 3.7315436 | X35: =IF(AB35<>"",IF(D35<>"",D35,($L$8-SUM($X$25:X34))*AA35*AB35/SUMPRODUCT($AB35:$AB$58,$AA35:$AA$58)),"") -> 32075 | Y35: =IF(AB35<>"",IF(E34<>"",E34,($L$9-SUM($Y$25:Y34))*AA35*AB35/SUMPRODUCT($AB35:$AB$58,$AA35:$AA$58)),"") -> 7 | Z35: =IF(AB35<>"",IF($L$12<>"",IF(G35<>"",G35,($L$9/$L$12-SUM($Z$25:Z34))*AA35*AB35/SUMPRODUCT($AB35:$AB$58,$AA35:$AA$58)),""),"") -> 1 | AA35: 1 | AB35: 1
A36: 12 | B36: 46094 | C36: пт | D36: 4693 | E36: 1 | F36: =IF(AND(E36<>"",E36<>0),D36/E36,"") -> 4693 | G36: 1 | H36: =IF(AND(G36<>"",G36<>0),D36/G36,"") -> 4693 | I36: 20 | J36: =IF(AND(G36<>"",G36<>0),E36/G36,"") -> 1 | S36: =IF(AND(I36<>"",I36<>0),G36/I36,"") -> 0.05 | T36: =D36/U36 -> 0.10475233 | U36: =$L$8*AA36*AB36/SUMPRODUCT($AB$25:$AB$56,$AA$25:$AA$56) -> 44800.913 | V36: =$L$9*AA36*AB36/SUMPRODUCT($AB$25:$AB$58,$AA$25:$AA$58) -> 6.4928859 | W36: =IF($L$12="","",V36/$L$12) -> 3.7315436 | X36: =IF(AB36<>"",IF(D36<>"",D36,($L$8-SUM($X$25:X35))*AA36*AB36/SUMPRODUCT($AB36:$AB$58,$AA36:$AA$58)),"") -> 4693 | Y36: =IF(AB36<>"",IF(E35<>"",E35,($L$9-SUM($Y$25:Y35))*AA36*AB36/SUMPRODUCT($AB36:$AB$58,$AA36:$AA$58)),"") -> 3 | Z36: =IF(AB36<>"",IF($L$12<>"",IF(G36<>"",G36,($L$9/$L$12-SUM($Z$25:Z35))*AA36*AB36/SUMPRODUCT($AB36:$AB$58,$AA36:$AA$58)),""),"") -> 1 | AA36: 1 | AB36: 1
A37: 13 | B37: 46095 | C37: сб | D37: =41805+4893 -> 46698 | E37: 4 | F37: =IF(AND(E37<>"",E37<>0),D37/E37,"") -> 11674.5 | G37: 2 | H37: =IF(AND(G37<>"",G37<>0),D37/G37,"") -> 23349 | I37: 15 | J37: =IF(AND(G37<>"",G37<>0),E37/G37,"") -> 2 | P37: 41805 | S37: =IF(AND(I37<>"",I37<>0),G37/I37,"") -> 0.13333333 | T37: =D37/U37 -> 1.0423448 | U37: =$L$8*AA37*AB37/SUMPRODUCT($AB$25:$AB$56,$AA$25:$AA$56) -> 44800.913 | V37: =$L$9*AA37*AB37/SUMPRODUCT($AB$25:$AB$58,$AA$25:$AA$58) -> 6.4928859 | W37: =IF($L$12="","",V37/$L$12) -> 3.7315436 | X37: =IF(AB37<>"",IF(D37<>"",D37,($L$8-SUM($X$25:X36))*AA37*AB37/SUMPRODUCT($AB37:$AB$58,$AA37:$AA$58)),"") -> 46698 | Y37: =IF(AB37<>"",IF(E37<>"",E37,($L$9-SUM($Y$25:Y36))*AA37*AB37/SUMPRODUCT($AB37:$AB$58,$AA37:$AA$58)),"") -> 4 | Z37: =IF(AB37<>"",IF($L$12<>"",IF(G37<>"",G37,($L$9/$L$12-SUM($Z$25:Z36))*AA37*AB37/SUMPRODUCT($AB37:$AB$58,$AA37:$AA$58)),""),"") -> 2 | AA37: 1 | AB37: 1
A38: .22 | B38: 46096 | C38: вс | D38: 19385 | E38: 2 | F38: =IF(AND(E38<>"",E38<>0),D38/E38,"") -> 9692.5 | G38: 1 | H38: =IF(AND(G38<>"",G38<>0),D38/G38,"") -> 19385 | I38: 22 | J38: =IF(AND(G38<>"",G38<>0),E38/G38,"") -> 2 | O38: 15390 | S38: =IF(AND(I38<>"",I38<>0),G38/I38,"") -> 0.045454545 | T38: =D38/U38 -> 0.43269208 | U38: =$L$8*AA38*AB38/SUMPRODUCT($AB$25:$AB$56,$AA$25:$AA$56) -> 44800.913 | V38: =$L$9*AA38*AB38/SUMPRODUCT($AB$25:$AB$58,$AA$25:$AA$58) -> 6.4928859 | W38: =IF($L$12="","",V38/$L$12) -> 3.7315436 | X38: =IF(AB38<>"",IF(D38<>"",D38,($L$8-SUM($X$25:X37))*AA38*AB38/SUMPRODUCT($AB38:$AB$58,$AA38:$AA$58)),"") -> 19385 | Y38: =IF(AB38<>"",IF(E38<>"",E38,($L$9-SUM($Y$25:Y37))*AA38*AB38/SUMPRODUCT($AB38:$AB$58,$AA38:$AA$58)),"") -> 2 | Z38: =IF(AB38<>"",IF($L$12<>"",IF(G38<>"",G38,($L$9/$L$12-SUM($Z$25:Z37))*AA38*AB38/SUMPRODUCT($AB38:$AB$58,$AA38:$AA$58)),""),"") -> 1 | AA38: 1 | AB38: 1
A39: 15 | F39: =IF(AND(E39<>"",E39<>0),D39/E39,"") | H39: =IF(AND(G39<>"",G39<>0),D39/G39,"") | J39: =IF(AND(G39<>"",G39<>0),E39/G39,"") | S39: =IF(AND(I39<>"",I39<>0),G39/I39,"") | T39: =D39/U39 -> #DIV/0! | U39: =$L$8*AA39*AB39/SUMPRODUCT($AB$25:$AB$56,$AA$25:$AA$56) -> 0 | V39: =$L$9*AA39*AB39/SUMPRODUCT($AB$25:$AB$58,$AA$25:$AA$58) -> 0 | W39: =IF($L$12="","",V39/$L$12) -> 0 | X39: =IF(AB39<>"",IF(D39<>"",D39,($L$8-SUM($X$25:X38))*AA39*AB39/SUMPRODUCT($AB39:$AB$58,$AA39:$AA$58)),"") | Y39: =IF(AB39<>"",IF(E39<>"",E39,($L$9-SUM($Y$25:Y38))*AA39*AB39/SUMPRODUCT($AB39:$AB$58,$AA39:$AA$58)),"") | Z39: =IF(AB39<>"",IF($L$12<>"",IF(G39<>"",G39,($L$9/$L$12-SUM($Z$25:Z38))*AA39*AB39/SUMPRODUCT($AB39:$AB$58,$AA39:$AA$58)),""),"")
A40: 16 | F40: =IF(AND(E40<>"",E40<>0),D40/E40,"") | H40: =IF(AND(G40<>"",G40<>0),D40/G40,"") | J40: =IF(AND(G40<>"",G40<>0),E40/G40,"") | S40: =IF(AND(I40<>"",I40<>0),G40/I40,"") | T40: =D40/U40 -> #DIV/0! | U40: =$L$8*AA40*AB40/SUMPRODUCT($AB$25:$AB$56,$AA$25:$AA$56) -> 0 | V40: =$L$9*AA40*AB40/SUMPRODUCT($AB$25:$AB$58,$AA$25:$AA$58) -> 0 | W40: =IF($L$12="","",V40/$L$12) -> 0 | X40: =IF(AB40<>"",IF(D40<>"",D40,($L$8-SUM($X$25:X39))*AA40*AB40/SUMPRODUCT($AB40:$AB$58,$AA40:$AA$58)),"") | Y40: =IF(AB40<>"",IF(E39<>"",E39,($L$9-SUM($Y$25:Y39))*AA40*AB40/SUMPRODUCT($AB40:$AB$58,$AA40:$AA$58)),"") | Z40: =IF(AB40<>"",IF($L$12<>"",IF(G40<>"",G40,($L$9/$L$12-SUM($Z$25:Z39))*AA40*AB40/SUMPRODUCT($AB40:$AB$58,$AA40:$AA$58)),""),"")
A41: 17 | F41: =IF(AND(E41<>"",E41<>0),D41/E41,"") | H41: =IF(AND(G41<>"",G41<>0),D41/G41,"") | J41: =IF(AND(G41<>"",G41<>0),E41/G41,"") | S41: =IF(AND(I41<>"",I41<>0),G41/I41,"") | T41: =D41/U41 -> #DIV/0! | U41: =$L$8*AA41*AB41/SUMPRODUCT($AB$25:$AB$56,$AA$25:$AA$56) -> 0 | V41: =$L$9*AA41*AB41/SUMPRODUCT($AB$25:$AB$58,$AA$25:$AA$58) -> 0 | W41: =IF($L$12="","",V41/$L$12) -> 0 | X41: =IF(AB41<>"",IF(D41<>"",D41,($L$8-SUM($X$25:X40))*AA41*AB41/SUMPRODUCT($AB41:$AB$58,$AA41:$AA$58)),"") | Y41: =IF(AB41<>"",IF(E40<>"",E40,($L$9-SUM($Y$25:Y40))*AA41*AB41/SUMPRODUCT($AB41:$AB$58,$AA41:$AA$58)),"") | Z41: =IF(AB41<>"",IF($L$12<>"",IF(G41<>"",G41,($L$9/$L$12-SUM($Z$25:Z40))*AA41*AB41/SUMPRODUCT($AB41:$AB$58,$AA41:$AA$58)),""),"")
A42: 18 | F42: =IF(AND(E42<>"",E42<>0),D42/E42,"") | H42: =IF(AND(G42<>"",G42<>0),D42/G42,"") | J42: =IF(AND(G42<>"",G42<>0),E42/G42,"") | S42: =IF(AND(I42<>"",I42<>0),G42/I42,"") | T42: =D42/U42 -> #DIV/0! | U42: =$L$8*AA42*AB42/SUMPRODUCT($AB$25:$AB$56,$AA$25:$AA$56) -> 0 | V42: =$L$9*AA42*AB42/SUMPRODUCT($AB$25:$AB$58,$AA$25:$AA$58) -> 0 | W42: =IF($L$12="","",V42/$L$12) -> 0 | X42: =IF(AB42<>"",IF(D42<>"",D42,($L$8-SUM($X$25:X41))*AA42*AB42/SUMPRODUCT($AB42:$AB$58,$AA42:$AA$58)),"") | Y42: =IF(AB42<>"",IF(E42<>"",E42,($L$9-SUM($Y$25:Y41))*AA42*AB42/SUMPRODUCT($AB42:$AB$58,$AA42:$AA$58)),"") | Z42: =IF(AB42<>"",IF($L$12<>"",IF(G42<>"",G42,($L$9/$L$12-SUM($Z$25:Z41))*AA42*AB42/SUMPRODUCT($AB42:$AB$58,$AA42:$AA$58)),""),"")
...

Sheet Уразгильдеева
B1: =TODAY()-1 -> 46171
B2: (отчетная дата) | J2: ЕЖЕДНЕВНЫЙ ОТЧЕТ О ПРОДАЖАХ
B3: Осталось до выполнения плана!!! | J3: =График!B28 -> Уразгильдеева Екатерина
C4: =L8-D50 -> 843804.24 | E4: =IF(L8<>0,C4/L8,0) -> 1
I6: Целевые показатели
I7: Показатель | L7: План | M7: Факт | N7: % выполнения | O7: Прогноз выполнения | P7: % выполнения по прогнозу | Q7: Отклонение | R7: Факт аналогичного месяца прошлого года | S7: Отклонение LFL
I8: Выручка | L8: ='Ялта, Ленина, 18'!I8/График!AJ30*График!AJ28 -> 843804.24 | M8: =D57 -> 576247 | N8: =IF(AND(L8<>"",L8<>0,M8<>""),M8/L8,"") -> 0.68291551 | O8: =IF(SUMIF($D$25:$D$56,">=0",$U$25:$U$56)<>0,L8*D57/SUMIF($D$25:$D$56,">=0",$U$25:$U$56),0) -> 576247 | P8: =IF(AND(L8<>"",L8<>0,O8<>"",O8<>0),O8/L8,"") -> 0.68291551 | Q8: =IF(AND(M8<>0,M8<>"",L8<>0,L8<>""),O8-L8,"") -> -267557.24 | S8: =IF(AND(R8<>"",R8<>0,O8<>"",O8<>0),-R8+O8,"") | T8: =IF(AND(S8<>"",S8<>0,R8<>0,R8<>""),S8/R8,"")
I9: Кол-во изделий | L9: =L8/L11 -> 122.29047 | M9: =E57 -> 95 | N9: =IF(AND(L9<>"",L9<>0,M9<>""),M9/L9,"") -> 0.77683895 | O9: =IF(SUMIF($E$25:$E$54,">=0",$V$25:$V$54)<>0,L9*E57/SUMIF($E$25:$E$54,">=0",$V$25:$V$54),0) -> 95 | P9: =IF(AND(L9<>"",L9<>0,O9<>"",O9<>0),O9/L9,"") -> 0.77683895 | Q9: =IF(AND(M9<>0,M9<>"",L9<>0,L9<>""),O9-L9,"") -> -27.29047 | R9: =R8/R11 -> #DIV/0! | S9: =IF(AND(R9<>"",R9<>0,O9<>"",O9<>0),-R9+O9,"") -> #DIV/0! | T9: =IF(AND(S9<>"",S9<>0,R9<>0,R9<>""),S9/R9,"") -> #DIV/0!
I10: Средний чек | L10: =L11*L12 -> 12006 | M10: =H57 -> 11524.94 | N10: =IF(AND(L10<>"",L10<>0,M10<>""),M10/L10,"") -> 0.9599317 | O10: =M10 -> 11524.94 | P10: =IF(AND(L10<>"",L10<>0,O10<>"",O10<>0),O10/L10,"") -> 0.9599317 | Q10: =IF(AND(M10<>0,M10<>"",L10<>0,L10<>""),O10-L10,"") -> -481.06 | R10: =R11*R12 -> 0 | S10: =IF(AND(R10<>"",R10<>0,O10<>"",O10<>0),-R10+O10,"") | T10: =IF(AND(S10<>"",S10<>0,R10<>0,R10<>""),S10/R10,"")
I11: Средняя стоимость изделия | L11: ='Ялта, Ленина, 18'!I11 -> 6900 | M11: =F57 -> 6065.7579 | N11: =IF(AND(L11<>"",L11<>0,M11<>""),M11/L11,"") -> 0.87909535 | O11: =IF(O9>0,O8/O9,"") -> 6065.7579 | P11: =IF(AND(L11<>"",L11<>0,O11<>"",O11<>0),O11/L11,"") -> 0.87909535 | Q11: =IF(AND(M11<>0,M11<>"",L11<>0,L11<>""),O11-L11,"") -> -834.24211 | S11: =IF(AND(R11<>"",R11<>0,O11<>"",O11<>0),-R11+O11,"") | T11: =IF(AND(S11<>"",S11<>0,R11<>0,R11<>""),S11/R11,"")
I12: Длина чека | L12: ='Ялта, Ленина, 18'!I12 -> 1.74 | M12: =J57 -> 1.9 | N12: =IF(AND(L12<>"",L12<>0,M12<>""),M12/L12,"") -> 1.091954 | O12: =M12 -> 1.9 | P12: =IF(AND(L12<>"",L12<>0,O12<>"",O12<>0),O12/L12,"") -> 1.091954 | Q12: =IF(AND(M12<>0,M12<>"",L12<>0,L12<>""),O12-L12,"") -> 0.16 | S12: =IF(AND(R12<>"",R12<>0,O12<>"",O12<>0),-R12+O12,"") | T12: =IF(AND(S12<>"",S12<>0,R12<>0,R12<>""),S12/R12,"")
I13: Кол-во чеков | L13: =IF(L12<>0,L9/L12,"") -> 70.281879 | M13: =G57 -> 50 | N13: =IF(AND(L13<>"",L13<>0,M13<>""),M13/L13,"") -> 0.71142093 | O13: =IF(SUMIF($G$25:$G$54,">=0",$W$25:$W$54)<>0,L13*G57/SUMIF($G$25:$G$54,">=0",$W$25:$W$54),"") -> 50 | P13: =IF(AND(L13<>"",L13<>0,O13<>"",O13<>0),O13/L13,"") -> 0.71142093 | Q13: =IF(AND(M13<>0,M13<>"",L13<>0,L13<>""),O13-L13,"") -> -20.281879 | S13: =IF(AND(R13<>"",R13<>0,O13<>"",O13<>0),-R13+O13,"") | T13: =IF(AND(S13<>"",S13<>0,R13<>0,R13<>""),S13/R13,"")
I14: Кол-во смен план/отработано | L14: =График!AI28 -> 17 | M14: 17 | N14: =IF(AND(L14<>"",L14<>0,M14<>""),M14/L14,"") -> 1 | O14: =L14 -> 17 | P14: =IF(AND(L14<>"",L14<>0,O14<>"",O14<>0),O14/L14,"") -> 1 | Q14: =IF(AND(M14<>0,M14<>"",L14<>0,L14<>""),O14-L14,"") -> 0 | S14: =IF(AND(R14<>"",R14<>0,O14<>"",O14<>0),-R14+O14,"") | T14: =IF(AND(S14<>"",S14<>0,R14<>0,R14<>""),S14/R14,"")
I15: Средние продажи в смену | L15: ='Ялта, Ленина, 18'!I15 -> 65064.774 | M15: =M8/M14 -> 33896.882 | N15: =IF(AND(L15<>"",L15<>0,M15<>""),M15/L15,"") -> 0.52097134 | O15: =M15 -> 33896.882 | P15: =IF(AND(L15<>"",L15<>0,O15<>"",O15<>0),O15/L15,"") -> 0.52097134 | Q15: =IF(AND(M15<>0,M15<>"",L15<>0,L15<>""),O15-L15,"") -> -31167.892 | S15: =IF(AND(R15<>"",R15<>0,O15<>"",O15<>0),-R15+O15,"") | T15: =IF(AND(S15<>"",S15<>0,R15<>0,R15<>""),S15/R15,"")
I16: Отставание/Перевыполнение | M16: =M8-L15*M14 -> -529854.16 | N16: =IF(AND(L16<>"",L16<>0,M16<>""),M16/L16,"") | O16: =M16 -> -529854.16 | P16: =IF(AND(L16<>"",L16<>0,O16<>"",O16<>0),O16/L16,"") | Q16: =IF(AND(M16<>0,M16<>"",L16<>0,L16<>""),O16-L16,"") | S16: =IF(AND(R16<>"",R16<>0,O16<>"",O16<>0),-R16+O16,"") | T16: =IF(AND(S16<>"",S16<>0,R16<>0,R16<>""),S16/R16,"")
I17: Трафик | L17: ='Ялта, Ленина, 18'!I17/График!AJ30*График!AJ28 -> 585.68233 | M17: =I57 -> 615 | N17: =IF(AND(L17<>"",L17<>0,M17<>""),M17/L17,"") -> 1.0500573 | O17: =M17/M14*L14 -> 615 | P17: =IF(AND(L17<>"",L17<>0,O17<>"",O17<>0),O17/L17,"") -> 1.0500573 | Q17: =IF(AND(M17<>0,M17<>"",L17<>0,L17<>""),O17-L17,"") -> 29.317673 | S17: =IF(AND(R17<>"",R17<>0,O17<>"",O17<>0),-R17+O17,"") | T17: =IF(AND(S17<>"",S17<>0,R17<>0,R17<>""),S17/R17,"")
N18: =IF(AND(L18<>"",L18<>0,M18<>""),M18/L18,"") | O18: =M18 -> 0 | P18: =IF(AND(L18<>"",L18<>0,O18<>"",O18<>0),O18/L18,"") | Q18: =IF(AND(M18<>0,M18<>"",L18<>0,L18<>""),O18-L18,"") | R18: 0 | S18: =IF(AND(R18<>"",R18<>0,O18<>"",O18<>0),-R18+O18,"") | T18: =IF(AND(S18<>"",S18<>0,R18<>0,R18<>""),S18/R18,"")
N19: =IF(AND(L19<>"",L19<>0,M19<>""),M19/L19,"") | O19: =M19 -> 0 | P19: =IF(AND(L19<>"",L19<>0,O19<>"",O19<>0),O19/L19,"") | Q19: =IF(AND(M19<>0,M19<>"",L19<>0,L19<>""),O19-L19,"") | R19: 0 | S19: =IF(AND(R19<>"",R19<>0,O19<>"",O19<>0),-R19+O19,"") | T19: =IF(AND(S19<>"",S19<>0,R19<>0,R19<>""),S19/R19,"")
I20: Конверсия план/факт | L20: ='Ялта, Ленина, 18'!I20 -> 0.12 | M20: =S57 -> 0.081300813 | N20: =M20/L20 -> 0.67750678 | O20: =IF(AND(N8<>0,L14<>0,I57<>0),(I57*S57+(I57/N8-I57)*L20)/(I57/N8),0) -> 0.093571725 | P20: =IF(AND(L20<>"",L20<>0,O20<>"",O20<>0),O20/L20,"") -> 0.77976438 | Q20: =IF(AND(M20<>0,M20<>"",L20<>0,L20<>""),O20-L20,"") -> -0.026428275 | S20: =IF(AND(R20<>"",R20<>0,O20<>"",O20<>0),-R20+O20,"") | T20: =IF(AND(S20<>"",S20<>0,R20<>0,R20<>""),S20/R20,"")
B22: Факт продаж за месяц | T22: % выполнения дневного плана | U22: Раcпределение плана по дням
B23: Дата | C23: День недели | D23: Выручка (руб) | E23: Кол-во единиц (шт.) | F23: Средняя стоимость изделия (руб.) | G23: Количество чеков (шт.) | H23: Средняя сумма чека (руб.) | I23: Трафик | J23: Длина чека (шт.) | K23: UNOde50 | L23: IS | M23: Agafi | N23: Kalliope | O23: Raganella | P23: CC/MP | Q23: Antura | R23: SALE | S23: Конверсия (%) | U23: выручка, план | V23: кол-во ед, план | W23: Кол-во чеков, план | X23: выручка, скорректир.план | Y23: кол-во ед, скорр. план | Z23: кол-во чеков, скорр. план | AA23: Коэфф. Дня Недели | AB23: Специфика месяца
B24: 1 | C24: 2 | D24: 3 | E24: в | F24: 5 | G24: 6 | H24: 7 | I24: 8 | J24: 9 | K24: 10 | L24: 11 | M24: 12 | N24: 13 | P24: 14 | Q24: 15 | R24: 16 | S24: 17 | U24: 1 | V24: 2 | W24: 3 | X24: 4 | Y24: 5 | Z24: 6 | AA24: 10 | AB24: 11
A25: 1 | B25: 46082 | C25: вс | D25: 19475 | E25: 3 | F25: 6492 | G25: 1 | H25: =IF(AND(G25<>"",G25<>0),D25/G25,"") -> 19475 | I25: 20 | J25: =IF(AND(G25<>"",G25<>0),E25/G25,"") -> 3 | R25: 7690 | S25: =IF(AND(I25<>"",I25<>0),G25/I25,"") -> 0.05 | T25: =D25/U25 -> 0.32311997 | U25: =$L$8*AA25*AB25/SUMPRODUCT($AB$25:$AB$56,$AA$25:$AA$56) -> 60271.732 | V25: =$L$9*AA25*AB25/SUMPRODUCT($AB$25:$AB$56,$AA$25:$AA$56) -> 8.7350336 | W25: =IF($L$12="","",V25/$L$12) -> 5.0201342 | X25: =IF(D25<>"",D25,U25) -> 19475 | Y25: =IF(E25<>"",E25,V25) -> 3 | Z25: =IF(G25<>"",G25,W25) -> 1 | AA25: 1 | AB25: 1
