Workbook
Name маг: NA()

Sheet Ялта, Ленина, 18
B1: =TODAY()-1 -> 46138
B2: (отчетная дата)
C3: Осталось до выполнения плана!!! | I3: =График!B3 -> ул. Набережная Ленина, 18
C4: =I8-D56 -> 519369.56 | E4: =IF(I8<>0, C4/I8, 0) -> 0.20067537
D5: =C4/(I14-J14) -> #DIV/0!
F6: Целевые показатели
F7: Показатель | I7: План | J7: Факт | K7: % выполнения | L7: Прогноз выполнения | M7: % выполнения по прогнозу | N7: Отклонение | O7: Факт аналогичного месяца прошлого года | P7: Отклонение LFL
F8: Выручка | I8: =I10*I13 -> 2588108.2 | J8: =D56 -> 2068738.6 | K8: =IF(AND(I8<>"", I8<>0, J8<>""), J8/I8, "") -> 0.79932463 | L8: =IF(SUMIF($D$25:$D$55,">=0",$P$25:$P$55)<>0,I8*D56/SUMIF($D$25:$D$55,">=0",$P$25:$P$55),0) -> 2068738.6 | M8: =IF(AND(I8<>"", I8<>0, L8<>"", L8<>0), L8/I8, "") -> 0.79932463 | N8: =IF(AND(J8<>0, J8<>"", I8<>0, I8<>""), L8-I8, "") -> -519369.56 | P8: =IF(AND(O8<>"", O8<>0, L8<>"", L8<>0), -O8+L8, "") | Q8: =IF(AND(P8<>"", P8<>0, O8<>0, O8<>""), P8/O8, "")
F9: Кол-во изделий | I9: =I8/I11 -> 521.796 | J9: =E56 -> 390 | K9: =IF(AND(I9<>"", I9<>0, J9<>""), J9/I9, "") -> 0.74741853 | L9: =IF(SUMIF($E$25:$E$55, ">=0", $Q$25:$Q$55)<>0, I9*E56/SUMIF($E$25:$E$55, ">=0", $Q$25:$Q$55), 0) -> 390 | M9: =IF(AND(I9<>"", I9<>0, L9<>"", L9<>0), L9/I9, "") -> 0.74741853 | N9: =IF(AND(J9<>0, J9<>"", I9<>0, I9<>""), L9-I9, "") -> -131.796 | O9: =O8/O11 -> #DIV/0! | P9: =IF(AND(O9<>"", O9<>0, L9<>"", L9<>0), -O9+L9, "") -> #DIV/0! | Q9: =IF(AND(P9<>"", P9<>0, O9<>0, O9<>""), P9/O9, "") -> #DIV/0!
F10: Средний чек | I10: =I11*I12 -> 8779.2 | J10: =H56 -> 10608.916 | K10: =IF(AND(I10<>"", I10<>0, J10<>""), J10/I10, "") -> 1.2084149 | L10: =J10 -> 10608.916 | M10: =IF(AND(I10<>"", I10<>0, L10<>"", L10<>0), L10/I10, "") -> 1.2084149 | N10: =IF(AND(J10<>0, J10<>"", I10<>0, I10<>""), L10-I10, "") -> 1829.7159 | O10: =O11*O12 -> 0 | P10: =IF(AND(O10<>"", O10<>0, L10<>"", L10<>0), -O10+L10, "") | Q10: =IF(AND(P10<>"", P10<>0, O10<>0, O10<>""), P10/O10, "") | S10: IS
F11: Средняя стоимость изделия | I11: 4960 | J11: =F56 -> 5304.4579 | K11: =IF(AND(I11<>"", I11<>0, J11<>""), J11/I11, "") -> 1.0694472 | L11: =IF(L9>0, L8/L9, "") -> 5304.4579 | M11: =IF(AND(I11<>"", I11<>0, L11<>"", L11<>0), L11/I11, "") -> 1.0694472 | N11: =IF(AND(J11<>0, J11<>"", I11<>0, I11<>""), L11-I11, "") -> 344.45795 | P11: =IF(AND(O11<>"", O11<>0, L11<>"", L11<>0), -O11+L11, "") | Q11: =IF(AND(P11<>"", P11<>0, O11<>0, O11<>""), P11/O11, "")
F12: Длина чека | I12: 1.77 | J12: =J56 -> 2 | K12: =IF(AND(I12<>"", I12<>0, J12<>""), J12/I12, "") -> 1.1299435 | L12: =J12 -> 2 | M12: =IF(AND(I12<>"", I12<>0, L12<>"", L12<>0), L12/I12, "") -> 1.1299435 | N12: =IF(AND(J12<>0, J12<>"", I12<>0, I12<>""), L12-I12, "") -> 0.23 | P12: =IF(AND(O12<>"", O12<>0, L12<>"", L12<>0), -O12+L12, "") | Q12: =IF(AND(P12<>"", P12<>0, O12<>0, O12<>""), P12/O12, "") | S12: 600000 | T12: =L56 -> 352078
F13: Кол-во чеков | I13: =I17*I20 -> 294.8 | J13: =G56 -> 195 | K13: =IF(AND(I13<>"", I13<>0, J13<>""), J13/I13, "") -> 0.6614654 | L13: =IF(SUMIF($G$25:$G$55, ">=0", $R$25:$R$55)<>0, I13*G56/SUMIF($G$25:$G$55, ">=0", $R$25:$R$55), "") -> 195 | M13: =IF(AND(I13<>"", I13<>0, L13<>"", L13<>0), L13/I13, "") -> 0.6614654 | N13: =IF(AND(J13<>0, J13<>"", I13<>0, I13<>""), L13-I13, "") -> -99.8 | P13: =IF(AND(O13<>"", O13<>0, L13<>"", L13<>0), -O13+L13, "") | Q13: =IF(AND(P13<>"", P13<>0, O13<>0, O13<>""), P13/O13, "") | S13: =T12/S12 -> 0.58679667 | T13: =S13/J14*I14 -> 0.58679667
F14: Кол-во смен | I14: 30 | J14: 30 | K14: =IF(AND(I14<>"", I14<>0, J14<>""), J14/I14, "") -> 1 | L14: =I14 -> 30 | M14: =IF(AND(I14<>"", I14<>0, L14<>"", L14<>0), L14/I14, "") -> 1 | N14: =IF(AND(J14<>0, J14<>"", I14<>0, I14<>""), L14-I14, "") -> 0 | P14: =IF(AND(O14<>"", O14<>0, L14<>"", L14<>0), -O14+L14, "") | Q14: =IF(AND(P14<>"", P14<>0, O14<>0, O14<>""), P14/O14, "")
F15: Средние продажи в смену | I15: =I8/I14 -> 86270.272 | J15: =J8/J14 -> 68957.953 | K15: =IF(AND(I15<>"", I15<>0, J15<>""), J15/I15, "") -> 0.79932463 | L15: =J15 -> 68957.953 | M15: =IF(AND(I15<>"", I15<>0, L15<>"", L15<>0), L15/I15, "") -> 0.79932463 | N15: =IF(AND(J15<>0, J15<>"", I15<>0, I15<>""), L15-I15, "") -> -17312.319 | P15: =IF(AND(O15<>"", O15<>0, L15<>"", L15<>0), -O15+L15, "") | Q15: =IF(AND(P15<>"", P15<>0, O15<>0, O15<>""), P15/O15, "")
F16: Отставание/Перевыполнение | J16: =J8-I15*J14 -> -519369.56 | K16: =IF(AND(I16<>"", I16<>0, J16<>""), J16/I16, "") | L16: =J16 -> -519369.56 | M16: =IF(AND(I16<>"", I16<>0, L16<>"", L16<>0), L16/I16, "") | N16: =IF(AND(J16<>0, J16<>"", I16<>0, I16<>""), L16-I16, "") | P16: =IF(AND(O16<>"", O16<>0, L16<>"", L16<>0), -O16+L16, "") | Q16: =IF(AND(P16<>"", P16<>0, O16<>0, O16<>""), P16/O16, "") | S16: UNOde50
F17: Трафик | I17: 1340 | J17: =I56 -> 893 | K17: =IF(AND(I17<>"", I17<>0, J17<>""), J17/I17, "") -> 0.66641791 | L17: =J17/J14*I14 -> 893 | M17: =IF(AND(I17<>"", I17<>0, L17<>"", L17<>0), L17/I17, "") -> 0.66641791 | N17: =IF(AND(J17<>0, J17<>"", I17<>0, I17<>""), L17-I17, "") -> -447 | P17: =IF(AND(O17<>"", O17<>0, L17<>"", L17<>0), -O17+L17, "") | Q17: =IF(AND(P17<>"", P17<>0, O17<>0, O17<>""), P17/O17, "")
K18: =IF(AND(I18<>"", I18<>0, J18<>""), J18/I18, "") | L18: =J18 -> 0 | M18: =IF(AND(I18<>"", I18<>0, L18<>"", L18<>0), L18/I18, "") | N18: =IF(AND(J18<>0, J18<>"", I18<>0, I18<>""), L18-I18, "") | O18: 0 | P18: =IF(AND(O18<>"", O18<>0, L18<>"", L18<>0), -O18+L18, "") | Q18: =IF(AND(P18<>"", P18<>0, O18<>0, O18<>""), P18/O18, "") | S18: 400000 | T18: =K56 -> 359325
J19: =M56 -> 0 | K19: =IF(AND(I19<>"", I19<>0, J19<>""), J19/I19, "") | L19: =J19 -> 0 | M19: =IF(AND(I19<>"", I19<>0, L19<>"", L19<>0), L19/I19, "") | N19: =IF(AND(J19<>0, J19<>"", I19<>0, I19<>""), L19-I19, "") | O19: 0 | P19: =IF(AND(O19<>"", O19<>0, L19<>"", L19<>0), -O19+L19, "") | Q19: =IF(AND(P19<>"", P19<>0, O19<>0, O19<>""), P19/O19, "") | S19: =T18/S18 -> 0.8983125 | T19: =S19/J14*I14 -> 0.8983125
F20: Конверсия план/факт | I20: 0.22 | J20: =N56 -> 0.21836506 | K20: =J20/I20 -> 0.99256846 | L20: =IF(AND(K8<>0, I14<>0, I56<>0), (I56*N56+(I56/K8-I56)*I20)/(I56/K8), 0) -> 0.21869315 | M20: =IF(AND(I20<>"", I20<>0, L20<>"", L20<>0), L20/I20, "") -> 0.99405979 | N20: =IF(AND(J20<>0, J20<>"", I20<>0, I20<>""), L20-I20, "") -> -0.0013068465 | P20: =IF(AND(O20<>"", O20<>0, L20<>"", L20<>0), -O20+L20, "") | Q20: =IF(AND(P20<>"", P20<>0, O20<>0, O20<>""), P20/O20, "")
A22: Факт продаж за месяц | O22: % выполнения дневного плана | P22: Раcпределение плана по дням
A23: Сотрудник | B23: Дата | C23: День недели | D23: Выручка (руб) | E23: Кол-во единиц (шт.) | F23: Средняя стоимость изделия (руб.) | G23: Количество чеков (шт.) | H23: Средняя сумма чека (руб.) | I23: Трафик | J23: Длина чека (шт.) | K23: UNOde50 | L23: IS | M23: Запасной | N23: Конверсия (%) | P23: выручка, план | Q23: кол-во ед, план | R23: Кол-во чеков, план | S23: выручка, скорректир.план | T23: кол-во ед, скорр. план | U23: кол-во чеков, скорр. план | V23: Коэфф. Дня Недели | W23: Специфика месяца
B24: 1 | C24: 2 | D24: 3 | E24: 4 | F24: 5 | G24: 6 | H24: 7 | I24: 8 | J24: 9 | K24: 10 | L24: 11 | M24: 12 | N24: 13 | P24: 1 | Q24: 2 | R24: 3 | S24: 4 | T24: 5 | U24: 6 | V24: 10 | W24: 11
A25: Рогалевич | B25: 45748 | C25: вт | D25: =25355+16920 -> 42275 | E25: 8 | F25: =IF(AND(E25<>"",E25<>0),D25/E25,"") -> 5284.375 | G25: 6 | H25: =IF(AND(G25<>"",G25<>0),D25/G25,"") -> 7045.8333 | I25: 40 | J25: =IF(AND(G25<>"",G25<>0),E25/G25,"") -> 1.3333333 | K25: 0 | L25: 16920 | N25: =IF(AND(I25<>"",I25<>0),G25/I25,"") -> 0.15 | O25: =D25/P25 -> 0.5591051 | P25: =$I$8*V25*W25/SUMPRODUCT($W$25:$W$55,$V$25:$V$55) -> 75611.901 | Q25: =$I$9*V25*W25/SUMPRODUCT($W$25:$W$55,$V$25:$V$55) -> 15.244335 | R25: =IF($I$12="","",Q25/$I$12) -> 8.6126186 | S25: =IF(D25<>"",D25,P25) -> 42275 | T25: =IF(E25<>"",E25,Q25) -> 8 | U25: =IF(G25<>"",G25,R25) -> 6 | V25: 0.9004852 | W25: 0.9004852
A26: Рогалевич | B26: 45749 | C26: ср | D26: =24542+15120 -> 39662 | E26: 10 | F26: =IF(AND(E26<>"",E26<>0),D26/E26,"") -> 3966.2 | G26: 5 | H26: =IF(AND(G26<>"",G26<>0),D26/G26,"") -> 7932.4 | I26: 20 | J26: =IF(AND(G26<>"",G26<>0),E26/G26,"") -> 2 | K26: 5492 | L26: 15120 | N26: =IF(AND(I26<>"",I26<>0),G26/I26,"") -> 0.25 | O26: =D26/P26 -> 0.37770337 | P26: =$I$8*V26*W26/SUMPRODUCT($W$25:$W$55,$V$25:$V$55) -> 105008.33 | Q26: =$I$9*V26*W26/SUMPRODUCT($W$25:$W$55,$V$25:$V$55) -> 21.171034 | R26: =IF($I$12="","",Q26/$I$12) -> 11.961036 | S26: =IF(W26<>"",IF(D26<>"",D26,($I$8-SUM($S$25:S25))*V26*W26/SUMPRODUCT($W26:$W$55,$V26:$V$55)),"") -> 39662 | T26: =IF(W26<>"",IF(E26<>"",E26,($I$9-SUM($T$25:T25))*V26*W26/SUMPRODUCT($W26:$W$55,$V26:$V$55)),"") -> 10 | U26: =IF(W26<>"",IF($I$12<>"",IF(G26<>"",G26,($I$9/$I$12-SUM($U$25:U25))*V26*W26/SUMPRODUCT($W26:$W$55,$V26:$V$55)),""),"") -> 5 | V26: 1.0611906 | W26: 1.0611906
A27: Орешникова | B27: 45750 | C27: чт | D27: =29335.6+18900 -> 48235.6 | E27: 11 | F27: =IF(AND(E27<>"",E27<>0),D27/E27,"") -> 4385.0545 | G27: 6 | H27: =IF(AND(G27<>"",G27<>0),D27/G27,"") -> 8039.2667 | I27: 30 | J27: =IF(AND(G27<>"",G27<>0),E27/G27,"") -> 1.8333333 | K27: 0 | L27: 18900 | N27: =IF(AND(I27<>"",I27<>0),G27/I27,"") -> 0.2 | O27: =D27/P27 -> 0.36030568 | P27: =$I$8*V27*W27/SUMPRODUCT($W$25:$W$55,$V$25:$V$55) -> 133874.1 | Q27: =$I$9*V27*W27/SUMPRODUCT($W$25:$W$55,$V$25:$V$55) -> 26.990747 | R27: =IF($I$12="","",Q27/$I$12) -> 15.24901 | S27: =IF(W27<>"",IF(D27<>"",D27,($I$8-SUM($S$25:S26))*V27*W27/SUMPRODUCT($W27:$W$55,$V27:$V$55)),"") -> 48235.6 | T27: =IF(W27<>"",IF(E27<>"",E27,($I$9-SUM($T$25:T26))*V27*W27/SUMPRODUCT($W27:$W$55,$V27:$V$55)),"") -> 11 | U27: =IF(W27<>"",IF($I$12<>"",IF(G27<>"",G27,($I$9/$I$12-SUM($U$25:U26))*V27*W27/SUMPRODUCT($W27:$W$55,$V27:$V$55)),""),"") -> 6 | V27: 1.1982013 | W27: 1.1982013
A28: Рогалевич | B28: 45751 | C28: пт | D28: 18259 | E28: 5 | F28: =IF(AND(E28<>"",E28<>0),D28/E28,"") -> 3651.8 | G28: 4 | H28: =IF(AND(G28<>"",G28<>0),D28/G28,"") -> 4564.75 | I28: 17 | J28: =IF(AND(G28<>"",G28<>0),E28/G28,"") -> 1.25 | K28: 0 | L28: 0 | N28: =IF(AND(I28<>"",I28<>0),G28/I28,"") -> 0.23529412 | O28: =D28/P28 -> 0.32113629 | P28: =$I$8*V28*W28/SUMPRODUCT($W$25:$W$55,$V$25:$V$55) -> 56857.479 | Q28: =$I$9*V28*W28/SUMPRODUCT($W$25:$W$55,$V$25:$V$55) -> 11.463201 | R28: =IF($I$12="","",Q28/$I$12) -> 6.4763849 | S28: =IF(W28<>"",IF(D28<>"",D28,($I$8-SUM($S$25:S27))*V28*W28/SUMPRODUCT($W28:$W$55,$V28:$V$55)),"") -> 18259 | T28: =IF(W28<>"",IF(E28<>"",E28,($I$9-SUM($T$25:T27))*V28*W28/SUMPRODUCT($W28:$W$55,$V28:$V$55)),"") -> 5 | U28: =IF(W28<>"",IF($I$12<>"",IF(G28<>"",G28,($I$9/$I$12-SUM($U$25:U27))*V28*W28/SUMPRODUCT($W28:$W$55,$V28:$V$55)),""),"") -> 4 | V28: 0.78086381 | W28: 0.78086381
A29: Рогалевич | B29: 45752 | C29: сб | D29: 47559 | E29: 11 | F29: =IF(AND(E29<>"",E29<>0),D29/E29,"") -> 4323.5455 | G29: 7 | H29: =IF(AND(G29<>"",G29<>0),D29/G29,"") -> 6794.1429 | I29: 26 | J29: =IF(AND(G29<>"",G29<>0),E29/G29,"") -> 1.5714286 | K29: 0 | L29: 0 | N29: =IF(AND(I29<>"",I29<>0),G29/I29,"") -> 0.26923077 | O29: =D29/P29 -> 0.46794641 | P29: =$I$8*V29*W29/SUMPRODUCT($W$25:$W$55,$V$25:$V$55) -> 101633.43 | Q29: =$I$9*V29*W29/SUMPRODUCT($W$25:$W$55,$V$25:$V$55) -> 20.490611 | R29: =IF($I$12="","",Q29/$I$12) -> 11.576617 | S29: =IF(W29<>"",IF(D29<>"",D29,($I$8-SUM($S$25:S28))*V29*W29/SUMPRODUCT($W29:$W$55,$V29:$V$55)),"") -> 47559 | T29: =IF(W29<>"",IF(E29<>"",E29,($I$9-SUM($T$25:T28))*V29*W29/SUMPRODUCT($W29:$W$55,$V29:$V$55)),"") -> 11 | U29: =IF(W29<>"",IF($I$12<>"",IF(G29<>"",G29,($I$9/$I$12-SUM($U$25:U28))*V29*W29/SUMPRODUCT($W29:$W$55,$V29:$V$55)),""),"") -> 7 | V29: 1.0439983 | W29: 1.0439983
A30: Рогалевич | B30: 45753 | C30: вс | D30: =51277+32720 -> 83997 | E30: 17 | F30: =IF(AND(E30<>"",E30<>0),D30/E30,"") -> 4941 | G30: 9 | H30: =IF(AND(G30<>"",G30<>0),D30/G30,"") -> 9333 | I30: 29 | J30: =IF(AND(G30<>"",G30<>0),E30/G30,"") -> 1.8888889 | K30: 0 | L30: 32720 | N30: =IF(AND(I30<>"",I30<>0),G30/I30,"") -> 0.31034483 | O30: =D30/P30 -> 1.4773254 | P30: =$I$8*V30*W30/SUMPRODUCT($W$25:$W$55,$V$25:$V$55) -> 56857.479 | Q30: =$I$9*V30*W30/SUMPRODUCT($W$25:$W$55,$V$25:$V$55) -> 11.463201 | R30: =IF($I$12="","",Q30/$I$12) -> 6.4763849 | S30: =IF(W30<>"",IF(D30<>"",D30,($I$8-SUM($S$25:S29))*V30*W30/SUMPRODUCT($W30:$W$55,$V30:$V$55)),"") -> 83997 | T30: =IF(W30<>"",IF(E30<>"",E30,($I$9-SUM($T$25:T29))*V30*W30/SUMPRODUCT($W30:$W$55,$V30:$V$55)),"") -> 17 | U30: =IF(W30<>"",IF($I$12<>"",IF(G30<>"",G30,($I$9/$I$12-SUM($U$25:U29))*V30*W30/SUMPRODUCT($W30:$W$55,$V30:$V$55)),""),"") -> 9 | V30: 0.78086381 | W30: 0.78086381
A31: Рогалевич | B31: 45754 | C31: пн | D31: 25437 | E31: 6 | F31: =IF(AND(E31<>"",E31<>0),D31/E31,"") -> 4239.5 | G31: 3 | H31: =IF(AND(G31<>"",G31<>0),D31/G31,"") -> 8479 | I31: 5 | J31: =IF(AND(G31<>"",G31<>0),E31/G31,"") -> 2 | K31: 0 | L31: 0 | N31: =IF(AND(I31<>"",I31<>0),G31/I31,"") -> 0.6 | O31: =D31/P31 -> 0.41131783 | P31: =$I$8*V31*W31/SUMPRODUCT($W$25:$W$55,$V$25:$V$55) -> 61842.688 | Q31: =$I$9*V31*W31/SUMPRODUCT($W$25:$W$55,$V$25:$V$55) -> 12.468284 | R31: =IF($I$12="","",Q31/$I$12) -> 7.0442282 | S31: =IF(W31<>"",IF(D31<>"",D31,($I$8-SUM($S$25:S30))*V31*W31/SUMPRODUCT($W31:$W$55,$V31:$V$55)),"") -> 25437 | T31: =IF(W31<>"",IF(E31<>"",E31,($I$9-SUM($T$25:T30))*V31*W31/SUMPRODUCT($W31:$W$55,$V31:$V$55)),"") -> 6 | U31: =IF(W31<>"",IF($I$12<>"",IF(G31<>"",G31,($I$9/$I$12-SUM($U$25:U30))*V31*W31/SUMPRODUCT($W31:$W$55,$V31:$V$55)),""),"") -> 3 | V31: 0.81437733 | W31: 0.81437733
A32: Рогалевич | B32: 45755 | C32: вт | D32: 5483 | E32: 2 | F32: =IF(AND(E32<>"",E32<>0),D32/E32,"") -> 2741.5 | G32: 1 | H32: =IF(AND(G32<>"",G32<>0),D32/G32,"") -> 5483 | I32: 12 | J32: =IF(AND(G32<>"",G32<>0),E32/G32,"") -> 2 | K32: 0 | L32: 0 | N32: =IF(AND(I32<>"",I32<>0),G32/I32,"") -> 0.083333333 | O32: =D32/P32 -> 0.088660441 | P32: =$I$8*V32*W32/SUMPRODUCT($W$25:$W$55,$V$25:$V$55) -> 61842.688 | Q32: =$I$9*V32*W32/SUMPRODUCT($W$25:$W$55,$V$25:$V$55) -> 12.468284 | R32: =IF($I$12="","",Q32/$I$12) -> 7.0442282 | S32: =IF(W32<>"",IF(D32<>"",D32,($I$8-SUM($S$25:S31))*V32*W32/SUMPRODUCT($W32:$W$55,$V32:$V$55)),"") -> 5483 | T32: =IF(W32<>"",IF(E32<>"",E32,($I$9-SUM($T$25:T31))*V32*W32/SUMPRODUCT($W32:$W$55,$V32:$V$55)),"") -> 2 | U32: =IF(W32<>"",IF($I$12<>"",IF(G32<>"",G32,($I$9/$I$12-SUM($U$25:U31))*V32*W32/SUMPRODUCT($W32:$W$55,$V32:$V$55)),""),"") -> 1 | V32: 0.81437733 | W32: 0.81437733
A33: Рогалевич | B33: 45756 | C33: ср | D33: 3792 | E33: 1 | F33: =IF(AND(E33<>"",E33<>0),D33/E33,"") -> 3792 | G33: 1 | H33: =IF(AND(G33<>"",G33<>0),D33/G33,"") -> 3792 | I33: 8 | J33: =IF(AND(G33<>"",G33<>0),E33/G33,"") -> 1 | K33: 0 | L33: 0 | N33: =IF(AND(I33<>"",I33<>0),G33/I33,"") -> 0.125 | O33: =D33/P33 -> 0.061316869 | P33: =$I$8*V33*W33/SUMPRODUCT($W$25:$W$55,$V$25:$V$55) -> 61842.688 | Q33: =$I$9*V33*W33/SUMPRODUCT($W$25:$W$55,$V$25:$V$55) -> 12.468284 | R33: =IF($I$12="","",Q33/$I$12) -> 7.0442282 | S33: =IF(W33<>"",IF(D33<>"",D33,($I$8-SUM($S$25:S32))*V33*W33/SUMPRODUCT($W33:$W$55,$V33:$V$55)),"") -> 3792 | T33: =IF(W33<>"",IF(E33<>"",E33,($I$9-SUM($T$25:T32))*V33*W33/SUMPRODUCT($W33:$W$55,$V33:$V$55)),"") -> 1 | U33: =IF(W33<>"",IF($I$12<>"",IF(G33<>"",G33,($I$9/$I$12-SUM($U$25:U32))*V33*W33/SUMPRODUCT($W33:$W$55,$V33:$V$55)),""),"") -> 1 | V33: 0.81437733 | W33: 0.81437733
A34: Рогалевич | B34: 45757 | C34: чт | D34: =37704+7803 -> 45507 | E34: 9 | F34: =IF(AND(E34<>"",E34<>0),D34/E34,"") -> 5056.3333 | G34: 4 | H34: =IF(AND(G34<>"",G34<>0),D34/G34,"") -> 11376.75 | I34: 10 | J34: =IF(AND(G34<>"",G34<>0),E34/G34,"") -> 2.25 | K34: 0 | L34: 7803 | N34: =IF(AND(I34<>"",I34<>0),G34/I34,"") -> 0.4 | O34: =D34/P34 -> 0.48802402 | P34: =$I$8*V34*W34/SUMPRODUCT($W$25:$W$55,$V$25:$V$55) -> 93247.459 | Q34: =$I$9*V34*W34/SUMPRODUCT($W$25:$W$55,$V$25:$V$55) -> 18.799891 | R34: =IF($I$12="","",Q34/$I$12) -> 10.621407 | S34: =IF(W34<>"",IF(D34<>"",D34,($I$8-SUM($S$25:S33))*V34*W34/SUMPRODUCT($W34:$W$55,$V34:$V$55)),"") -> 45507 | T34: =IF(W34<>"",IF(E34<>"",E34,($I$9-SUM($T$25:T33))*V34*W34/SUMPRODUCT($W34:$W$55,$V34:$V$55)),"") -> 9 | U34: =IF(W34<>"",IF($I$12<>"",IF(G34<>"",G34,($I$9/$I$12-SUM($U$25:U33))*V34*W34/SUMPRODUCT($W34:$W$55,$V34:$V$55)),""),"") -> 4 | V34: 1 | W34: 1
A35: Рогалевич | B35: 45758 | C35: пт | D35: 4192 | E35: 1 | F35: =IF(AND(E35<>"",E35<>0),D35/E35,"") -> 4192 | G35: 1 | H35: =IF(AND(G35<>"",G35<>0),D35/G35,"") -> 4192 | I35: 10 | J35: =IF(AND(G35<>"",G35<>0),E35/G35,"") -> 1 | K35: 0 | L35: 0 | N35: =IF(AND(I35<>"",I35<>0),G35/I35,"") -> 0.1 | O35: =D35/P35 -> 0.073728208 | P35: =$I$8*V35*W35/SUMPRODUCT($W$25:$W$55,$V$25:$V$55) -> 56857.479 | Q35: =$I$9*V35*W35/SUMPRODUCT($W$25:$W$55,$V$25:$V$55) -> 11.463201 | R35: =IF($I$12="","",Q35/$I$12) -> 6.4763849 | S35: =IF(W35<>"",IF(D35<>"",D35,($I$8-SUM($S$25:S34))*V35*W35/SUMPRODUCT($W35:$W$55,$V35:$V$55)),"") -> 4192 | T35: =IF(W35<>"",IF(E35<>"",E35,($I$9-SUM($T$25:T34))*V35*W35/SUMPRODUCT($W35:$W$55,$V35:$V$55)),"") -> 1 | U35: =IF(W35<>"",IF($I$12<>"",IF(G35<>"",G35,($I$9/$I$12-SUM($U$25:U34))*V35*W35/SUMPRODUCT($W35:$W$55,$V35:$V$55)),""),"") -> 1 | V35: 0.78086381 | W35: 0.78086381
A36: Рогалевич | B36: 45759 | C36: сб | D36: =12474+37008 -> 49482 | E36: 7 | F36: =IF(AND(E36<>"",E36<>0),D36/E36,"") -> 7068.8571 | G36: 3 | H36: =IF(AND(G36<>"",G36<>0),D36/G36,"") -> 16494 | I36: 7 | J36: =IF(AND(G36<>"",G36<>0),E36/G36,"") -> 2.3333333 | K36: 0 | L36: 37008 | N36: =IF(AND(I36<>"",I36<>0),G36/I36,"") -> 0.42857143 | O36: =D36/P36 -> 0.87028129 | P36: =$I$8*V36*W36/SUMPRODUCT($W$25:$W$55,$V$25:$V$55) -> 56857.479 | Q36: =$I$9*V36*W36/SUMPRODUCT($W$25:$W$55,$V$25:$V$55) -> 11.463201 | R36: =IF($I$12="","",Q36/$I$12) -> 6.4763849 | S36: =IF(W36<>"",IF(D36<>"",D36,($I$8-SUM($S$25:S35))*V36*W36/SUMPRODUCT($W36:$W$55,$V36:$V$55)),"") -> 49482 | T36: =IF(W36<>"",IF(E35<>"",E35,($I$9-SUM($T$25:T35))*V36*W36/SUMPRODUCT($W36:$W$55,$V36:$V$55)),"") -> 1 | U36: =IF(W36<>"",IF($I$12<>"",IF(G36<>"",G36,($I$9/$I$12-SUM($U$25:U35))*V36*W36/SUMPRODUCT($W36:$W$55,$V36:$V$55)),""),"") -> 3 | V36: 0.78086381 | W36: 0.78086381
A37: Рогалевич | B37: 45760 | C37: вс | D37: 42990 | E37: 8 | F37: =IF(AND(E37<>"",E37<>0),D37/E37,"") -> 5373.75 | G37: 7 | H37: =IF(AND(G37<>"",G37<>0),D37/G37,"") -> 6141.4286 | I37: 30 | J37: =IF(AND(G37<>"",G37<>0),E37/G37,"") -> 1.1428571 | K37: =11993+5493 -> 17486 | N37: =IF(AND(I37<>"",I37<>0),G37/I37,"") -> 0.23333333 | O37: =D37/P37 -> 0.75610106 | P37: =$I$8*V37*W37/SUMPRODUCT($W$25:$W$55,$V$25:$V$55) -> 56857.479 | Q37: =$I$9*V37*W37/SUMPRODUCT($W$25:$W$55,$V$25:$V$55) -> 11.463201 | R37: =IF($I$12="","",Q37/$I$12) -> 6.4763849 | S37: =IF(W37<>"",IF(D37<>"",D37,($I$8-SUM($S$25:S36))*V37*W37/SUMPRODUCT($W37:$W$55,$V37:$V$55)),"") -> 42990 | T37: =IF(W37<>"",IF(E37<>"",E37,($I$9-SUM($T$25:T36))*V37*W37/SUMPRODUCT($W37:$W$55,$V37:$V$55)),"") -> 8 | U37: =IF(W37<>"",IF($I$12<>"",IF(G37<>"",G37,($I$9/$I$12-SUM($U$25:U36))*V37*W37/SUMPRODUCT($W37:$W$55,$V37:$V$55)),""),"") -> 7 | V37: 0.78086381 | W37: 0.78086381
A38: Рогалевич | B38: 45761 | C38: пн | D38: =84715+10903 -> 95618 | E38: 22 | F38: =IF(AND(E38<>"",E38<>0),D38/E38,"") -> 4346.2727 | G38: 11 | H38: =IF(AND(G38<>"",G38<>0),D38/G38,"") -> 8692.5455 | I38: 40 | J38: =IF(AND(G38<>"",G38<>0),E38/G38,"") -> 2 | L38: 10903 | N38: =IF(AND(I38<>"",I38<>0),G38/I38,"") -> 0.275 | O38: =D38/P38 -> 1.0767173 | P38: =$I$8*V38*W38/SUMPRODUCT($W$25:$W$55,$V$25:$V$55) -> 88805.115 | Q38: =$I$9*V38*W38/SUMPRODUCT($W$25:$W$55,$V$25:$V$55) -> 17.904257 | R38: =IF($I$12="","",Q38/$I$12) -> 10.115399 | S38: =IF(W38<>"",IF(D38<>"",D38,($I$8-SUM($S$25:S37))*V38*W38/SUMPRODUCT($W38:$W$55,$V38:$V$55)),"") -> 95618 | T38: =IF(W38<>"",IF(E38<>"",E38,($I$9-SUM($T$25:T37))*V38*W38/SUMPRODUCT($W38:$W$55,$V38:$V$55)),"") -> 22 | U38: =IF(W38<>"",IF($I$12<>"",IF(G38<>"",G38,($I$9/$I$12-SUM($U$25:U37))*V38*W38/SUMPRODUCT($W38:$W$55,$V38:$V$55)),""),"") -> 11 | V38: 0.97588915 | W38: 0.97588915
A39: Рогалевич | B39: 45762 | C39: вт | D39: 59588 | E39: 12 | F39: =IF(AND(E39<>"",E39<>0),D39/E39,"") -> 4965.6667 | G39: 4 | H39: =IF(AND(G39<>"",G39<>0),D39/G39,"") -> 14897 | I39: 30 | J39: =IF(AND(G39<>"",G39<>0),E39/G39,"") -> 3 | K39: 23982 | N39: =IF(AND(I39<>"",I39<>0),G39/I39,"") -> 0.13333333 | O39: =D39/P39 -> 0.67099739 | P39: =$I$8*V39*W39/SUMPRODUCT($W$25:$W$55,$V$25:$V$55) -> 88805.115 | Q39: =$I$9*V39*W39/SUMPRODUCT($W$25:$W$55,$V$25:$V$55) -> 17.904257 | R39: =IF($I$12="","",Q39/$I$12) -> 10.115399 | S39: =IF(W39<>"",IF(D39<>"",D39,($I$8-SUM($S$25:S38))*V39*W39/SUMPRODUCT($W39:$W$55,$V39:$V$55)),"") -> 59588 | T39: =IF(W39<>"",IF(E39<>"",E39,($I$9-SUM($T$25:T38))*V39*W39/SUMPRODUCT($W39:$W$55,$V39:$V$55)),"") -> 12 | U39: =IF(W39<>"",IF($I$12<>"",IF(G39<>"",G39,($I$9/$I$12-SUM($U$25:U38))*V39*W39/SUMPRODUCT($W39:$W$55,$V39:$V$55)),""),"") -> 4 | V39: 0.97588915 | W39: 0.97588915
A40: Рогалевич, Уразгильдеева | B40: 45763 | C40: ср | D40: 40943 | E40: 7 | F40: =IF(AND(E40<>"",E40<>0),D40/E40,"") -> 5849 | G40: 6 | H40: =IF(AND(G40<>"",G40<>0),D40/G40,"") -> 6823.8333 | I40: 30 | J40: =IF(AND(G40<>"",G40<>0),E40/G40,"") -> 1.1666667 | K40: 13993 | N40: =IF(AND(I40<>"",I40<>0),G40/I40,"") -> 0.2 | O40: =D40/P40 -> 0.46104326 | P40: =$I$8*V40*W40/SUMPRODUCT($W$25:$W$55,$V$25:$V$55) -> 88805.115 | Q40: =$I$9*V40*W40/SUMPRODUCT($W$25:$W$55,$V$25:$V$55) -> 17.904257 | R40: =IF($I$12="","",Q40/$I$12) -> 10.115399 | S40: =IF(W40<>"",IF(D40<>"",D40,($I$8-SUM($S$25:S39))*V40*W40/SUMPRODUCT($W40:$W$55,$V40:$V$55)),"") -> 40943 | T40: =IF(W40<>"",IF(E40<>"",E40,($I$9-SUM($T$25:T39))*V40*W40/SUMPRODUCT($W40:$W$55,$V40:$V$55)),"") -> 7 | U40: =IF(W40<>"",IF($I$12<>"",IF(G40<>"",G40,($I$9/$I$12-SUM($U$25:U39))*V40*W40/SUMPRODUCT($W40:$W$55,$V40:$V$55)),""),"") -> 6 | V40: 0.97588915 | W40: 0.97588915
A41: Рогалевич, Афанасьева | B41: 45764 | C41: чт | D41: =88340+7903 -> 96243 | E41: 13 | F41: =IF(AND(E41<>"",E41<>0),D41/E41,"") -> 7403.3077 | G41: 9 | H41: =IF(AND(G41<>"",G41<>0),D41/G41,"") -> 10693.667 | I41: 40 | J41: =IF(AND(G41<>"",G41<>0),E41/G41,"") -> 1.4444444 | K41: 47425 | L41: 7903 | N41: =IF(AND(I41<>"",I41<>0),G41/I41,"") -> 0.225 | O41: =D41/P41 -> 1.0321246 | P41: =$I$8*V41*W41/SUMPRODUCT($W$25:$W$55,$V$25:$V$55) -> 93247.459 | Q41: =$I$9*V41*W41/SUMPRODUCT($W$25:$W$55,$V$25:$V$55) -> 18.799891 | R41: =IF($I$12="","",Q41/$I$12) -> 10.621407 | S41: =IF(W41<>"",IF(D41<>"",D41,($I$8-SUM($S$25:S40))*V41*W41/SUMPRODUCT($W41:$W$55,$V41:$V$55)),"") -> 96243 | T41: =IF(W41<>"",IF(E41<>"",E41,($I$9-SUM($T$25:T40))*V41*W41/SUMPRODUCT($W41:$W$55,$V41:$V$55)),"") -> 13 | U41: =IF(W41<>"",IF($I$12<>"",IF(G41<>"",G41,($I$9/$I$12-SUM($U$25:U40))*V41*W41/SUMPRODUCT($W41:$W$55,$V41:$V$55)),""),"") -> 9 | V41: 1 | W41: 1
...

Sheet Св. по пок.
A2: Показатель | D2: ='Ялта, Ленина, 18'!I3 -> ул. Набережная Ленина, 18 | G2: =График!B29 -> Рогалевич Ирина | J2: =График!B28 -> Уразгильдеева Екатерина | M2: =График!B27 -> Афанасьева Алевтина
D3: Факт | F3: Прогноз | G3: Факт | I3: Прогноз | J3: Факт | L3: Прогноз | M3: Факт | O3: Прогноз
A4: Выручка | D4: ='Ялта, Ленина, 18'!K8 -> 0.79932463 | E4: ='Ялта, Ленина, 18'!J8 -> 2068738.6 | F4: ='Ялта, Ленина, 18'!M8 -> 0.79932463 | G4: ='Рогалевич И. Е.'!K8 -> 0.93913249 | H4: ='Рогалевич И. Е.'!J8 -> 1663026 | I4: ='Рогалевич И. Е.'!M8 -> 0.90984636 | J4: ='Уразгильдеева Е. Р.'!K8 -> 0.48207115 | K4: ='Уразгильдеева Е. Р.'!J8 -> 240775 | L4: ='Уразгильдеева Е. Р.'!M8 -> 0.45166906 | M4: ='Афанасьева А. М.'!K8 -> 0.24625021 | N4: ='Афанасьева А. М.'!J8 -> 61496 | O4: ='Афанасьева А. М.'!M8 -> 0.46057464
A5: Кол-во изделий | D5: ='Ялта, Ленина, 18'!K9 -> 0.74741853 | E5: ='Ялта, Ленина, 18'!J9 -> 390 | F5: ='Ялта, Ленина, 18'!M9 -> 0.74741853 | G5: ='Рогалевич И. Е.'!K9 -> 0.88230767 | H5: ='Рогалевич И. Е.'!J9 -> 315 | I5: ='Рогалевич И. Е.'!M9 -> 0.92135948 | J5: ='Уразгильдеева Е. Р.'!K9 -> 0.50646752 | K5: ='Уразгильдеева Е. Р.'!J9 -> 51 | L5: ='Уразгильдеева Е. Р.'!M9 -> 0.50646752 | M5: ='Афанасьева А. М.'!K9 -> 0.29792207 | N5: ='Афанасьева А. М.'!J9 -> 15 | O5: ='Афанасьева А. М.'!M9 -> 0.55721922
A6: Средний чек | D6: ='Ялта, Ленина, 18'!K10 -> 1.2084149 | E6: ='Ялта, Ленина, 18'!J10 -> 10608.916 | F6: ='Ялта, Ленина, 18'!M10 -> 1.2084149 | G6: ='Рогалевич И. Е.'!K10 -> 1.2380913 | H6: ='Рогалевич И. Е.'!J10 -> 10869.451 | I6: ='Рогалевич И. Е.'!M10 -> 1.2380913 | J6: ='Уразгильдеева Е. Р.'!K10 -> 1.0157637 | K6: ='Уразгильдеева Е. Р.'!J10 -> 8917.5926 | L6: ='Уразгильдеева Е. Р.'!M10 -> 1.0157637 | M6: ='Афанасьева А. М.'!K10 -> 0.63679441 | N6: ='Афанасьева А. М.'!J10 -> 5590.5455 | O6: ='Афанасьева А. М.'!M10 -> 0.63679441
A7: Средняя стоимость изделия | D7: ='Ялта, Ленина, 18'!K11 -> 1.0694472 | E7: ='Ялта, Ленина, 18'!J11 -> 5304.4579 | F7: ='Ялта, Ленина, 18'!M11 -> 1.0694472 | G7: ='Рогалевич И. Е.'!K11 -> 1.0644048 | H7: ='Рогалевич И. Е.'!J11 -> 5279.4476 | I7: ='Рогалевич И. Е.'!M11 -> 0.9875042 | J7: ='Уразгильдеева Е. Р.'!K11 -> 0.95183033 | K7: ='Уразгильдеева Е. Р.'!J11 -> 4721.0784 | L7: ='Уразгильдеева Е. Р.'!M11 -> 0.95183033 | M7: ='Афанасьева А. М.'!K11 -> 0.82655914 | N7: ='Афанасьева А. М.'!J11 -> 4099.7333 | O7: ='Афанасьева А. М.'!M11 -> 0.82655914
A8: Длина чека | D8: ='Ялта, Ленина, 18'!K12 -> 1.1299435 | E8: ='Ялта, Ленина, 18'!J12 -> 2 | F8: ='Ялта, Ленина, 18'!M12 -> 1.1299435 | G8: ='Рогалевич И. Е.'!K12 -> 1.1631771 | H8: ='Рогалевич И. Е.'!J12 -> 2.0588235 | I8: ='Рогалевич И. Е.'!M12 -> 1.1631771 | J8: ='Уразгильдеева Е. Р.'!K12 -> 1.0671689 | K8: ='Уразгильдеева Е. Р.'!J12 -> 1.8888889 | L8: ='Уразгильдеева Е. Р.'!M12 -> 1.0671689 | M8: ='Афанасьева А. М.'!K12 -> 0.77041602 | N8: ='Афанасьева А. М.'!J12 -> 1.3636364 | O8: ='Афанасьева А. М.'!M12 -> 0.77041602
A9: Кол-во чеков | D9: ='Ялта, Ленина, 18'!K13 -> 0.6614654 | E9: ='Ялта, Ленина, 18'!J13 -> 195 | F9: ='Ялта, Ленина, 18'!M13 -> 0.6614654 | G9: ='Рогалевич И. Е.'!K13 -> 0.75853251 | H9: ='Рогалевич И. Е.'!J13 -> 153 | I9: ='Рогалевич И. Е.'!M13 -> 0.79171223 | J9: ='Уразгильдеева Е. Р.'!K13 -> 0.47458986 | K9: ='Уразгильдеева Е. Р.'!J13 -> 27 | L9: ='Уразгильдеева Е. Р.'!M13 -> 0.47458986 | M9: ='Афанасьева А. М.'!K13 -> 0.38670285 | N9: ='Афанасьева А. М.'!J13 -> 11 | O9: ='Афанасьева А. М.'!M13 -> 0.72327054
A10: Кол-во смен план/отработано | D10: ='Ялта, Ленина, 18'!K14 -> 1 | E10: ='Ялта, Ленина, 18'!J14 -> 30 | G10: ='Рогалевич И. Е.'!K14 -> 1 | H10: ='Рогалевич И. Е.'!J14 -> 29 | J10: ='Уразгильдеева Е. Р.'!K14 -> 0.875 | K10: ='Уразгильдеева Е. Р.'!J14 -> 7 | M10: ='Афанасьева А. М.'!K14 -> 1 | N10: ='Афанасьева А. М.'!J14 -> 4
A11: Средние продажи в смену | D11: ='Ялта, Ленина, 18'!K15 -> 0.79932463 | E11: ='Ялта, Ленина, 18'!J15 -> 68957.953 | F11: ='Ялта, Ленина, 18'!M15 -> 0.79932463 | G11: ='Рогалевич И. Е.'!K15 -> 0.66472173 | H11: ='Рогалевич И. Е.'!J15 -> 57345.724 | I11: ='Рогалевич И. Е.'!M15 -> 0.66472173 | J11: ='Уразгильдеева Е. Р.'!K15 -> 0.39870546 | K11: ='Уразгильдеева Е. Р.'!J15 -> 34396.429 | L11: ='Уразгильдеева Е. Р.'!M15 -> 0.39870546 | M11: ='Афанасьева А. М.'!K15 -> 0.17820739 | N11: ='Афанасьева А. М.'!J15 -> 15374 | O11: ='Афанасьева А. М.'!M15 -> 0.17820739
A12: Трафик | D12: ='Ялта, Ленина, 18'!K17 -> 0.66641791 | E12: ='Ялта, Ленина, 18'!J17 -> 893 | F12: ='Ялта, Ленина, 18'!M17 -> 0.66641791 | G12: ='Рогалевич И. Е.'!K17 -> 0.69804822 | H12: ='Рогалевич И. Е.'!J17 -> 640 | I12: ='Рогалевич И. Е.'!M17 -> 0.69804822 | J12: ='Уразгильдеева Е. Р.'!K17 -> 0.61872456 | K12: ='Уразгильдеева Е. Р.'!J17 -> 160 | L12: ='Уразгильдеева Е. Р.'!M17 -> 0.70711378 | M12: ='Афанасьева А. М.'!K17 -> 0.49497965 | N12: ='Афанасьева А. М.'!J17 -> 64 | O12: ='Афанасьева А. М.'!M17 -> 0.49497965
A13: UNOde50 | D13: ='Ялта, Ленина, 18'!S19 -> 0.8983125 | E13: ='Ялта, Ленина, 18'!T18 -> 359325 | F13: ='Ялта, Ленина, 18'!T19 -> 0.8983125 | G13: ='Рогалевич И. Е.'!S19 -> 0.93511423 | H13: ='Рогалевич И. Е.'!T18 -> 255926 | I13: ='Рогалевич И. Е.'!T19 -> 0.93511423 | J13: ='Уразгильдеева Е. Р.'!S19 -> 0.20716909 | K13: ='Уразгильдеева Е. Р.'!T18 -> 15992 | L13: ='Уразгильдеева Е. Р.'!T19 -> 0.23676468 | M13: ='Афанасьева А. М.'!S19 -> 0 | N13: ='Афанасьева А. М.'!T18 -> 0 | O13: ='Афанасьева А. М.'!T19 -> 0
A14: IS | D14: ='Ялта, Ленина, 18'!S13 -> 0.58679667 | E14: ='Ялта, Ленина, 18'!T12 -> 352078 | F14: ='Ялта, Ленина, 18'!T13 -> 0.58679667 | G14: ='Рогалевич И. Е.'!S13 -> 0.43557256 | H14: ='Рогалевич И. Е.'!T12 -> 178814 | I14: ='Рогалевич И. Е.'!T13 -> 0.43557256 | J14: ='Уразгильдеева Е. Р.'!S13 -> 0.55473091 | K14: ='Уразгильдеева Е. Р.'!T12 -> 64232 | L14: ='Уразгильдеева Е. Р.'!T13 -> 0.63397818 | M14: ='Афанасьева А. М.'!S13 -> 0.23674 | N14: ='Афанасьева А. М.'!T12 -> 13706 | O14: ='Афанасьева А. М.'!T13 -> 0.23674
A15: Отклонение от плана | D15: ='Ялта, Ленина, 18'!J16 -> -519369.56 | G15: ='Рогалевич И. Е.'!N8 -> -159645.05 | J15: ='Уразгильдеева Е. Р.'!N8 -> -273869.08 | M15: ='Афанасьева А. М.'!N8 -> -134710.55
A18: 01-13.04
A19: Показатель | D19: ул. Набережная Ленина, 18 | G19: Рогалевич Ирина
D20: Факт | F20: Прогноз | G20: Факт | I20: Прогноз
A21: Выручка | D21: 0.17652686 | E21: 456870.6 | F21: 0.44569361 | G21: 0.16382888 | H21: 408635 | I21: 0.16382888
A22: Кол-во изделий | D22: 0.18397995 | E22: 96 | F22: 0.46451111 | G22: 0.16902677 | H22: 85 | I22: 0.16902677
A23: Средний чек | D23: 0.91298452 | E23: 8015.2737 | F23: 0.91298452 | G23: 0.912663 | H23: 8012.451 | I23: 0.912663
A24: Средняя стоимость изделия | D24: 0.95948967 | E24: 4759.0687 | F24: 0.95948967 | G24: 0.9692481 | H24: 4807.4706 | I24: 0.9692481
A25: Длина чека | D25: 0.95153137 | E25: 1.6842105 | F25: 0.95153137 | G25: 0.94161959 | H25: 1.6666667 | I25: 0.94161959
A26: Кол-во чеков | D26: 0.19335142 | E26: 57 | F26: 0.48817214 | G26: 0.17950643 | H26: 51 | I26: 0.17950643
A27: Кол-во смен план/отработано | D27: 0.43333333 | E27: 13 | F27: 1 | G27: 0.4137931 | H27: 12 | I27: 1
A28: Средние продажи в смену | D28: 0.40736967 | E28: 35143.892 | F28: 0.40736967 | G28: 0.39472365 | H28: 34052.917 | I28: 0.39472365
A29: UNOde50 | D29: 0.057445 | E29: 22978 | F29: 0.13256538 | G29: 0.05960594 | H29: 22978 | I29: 0.14404769
A30: IS | D30: 0.21411833 | E30: 128471 | F30: 0.49411923 | G30: 0.18948799 | H30: 109571 | I30: 0.45792931
A31: Отставание/Перевыполнение | D31: -664642.94 | G31: -626608.26
A33: 14-20.04
A34: Показатель | D34: ул. Набережная Ленина, 18 | G34: Рогалевич Ирина | J34: Уразгильдеева Екатерина | M34: Афанасьева Алевтина
D35: Факт | F35: Прогноз | G35: Факт | I35: Прогноз | J35: Факт | L35: Прогноз | M35: Факт | O35: Прогноз
A36: Выручка | D36: 0.42180563 | E36: 1091678.6 | F36: 0.65230114 | G36: 0.53584219 | H36: 891925 | I36: 0.80385184 | J36: 0.1840795 | K36: 73960 | L36: 0.56677998 | M36: 0.065623434 | N36: 30133 | O36: 0.23116454
A37: Кол-во изделий | D37: 0.40053967 | E37: 209 | F37: 0.61941441 | G37: 0.5125293 | H37: 172 | I37: 0.76990141 | J37: 0.18517462 | K37: 15 | L37: 0.18517462 | M37: 0.086414823 | N37: 8 | O37: 0.3044041
A38: Средний чек | D38: 1.0719681 | E38: 9411.0224 | F38: 1.0719681 | G38: 1.0694237 | H38: 9388.6842 | I38: 1.0694237 | J38: 1.0530572 | K38: 9245 | L38: 1.0530572 | M38: 0.57205288 | N38: 5022.1667 | O38: 0.57205288
A39: Средняя стоимость изделия | D39: 1.0530933 | E39: 5223.3426 | F39: 1.0530933 | G39: 1.045486 | H39: 5185.6105 | I39: 1.0440971 | J39: 0.99408602 | K39: 4930.6667 | L39: 0.99408602 | M39: 0.7594002 | N39: 3766.625 | O39: 0.7594002
A40: Длина чека | D40: 1.0179232 | E40: 1.8017241 | F40: 1.0179232 | G40: 1.0228962 | H40: 1.8105263 | I40: 1.0228962 | J40: 1.059322 | K40: 1.875 | L40: 1.059322 | M40: 0.75329567 | N40: 1.3333333 | O40: 0.75329567
A41: Кол-во чеков | D41: 0.39348711 | E41: 116 | F41: 0.60850797 | G41: 0.50105698 | H41: 95 | I41: 0.75209585 | J41: 0.17480484 | K41: 8 | L41: 0.17480484 | M41: 0.11471568 | N41: 6 | O41: 0.40409645
A42: Кол-во смен план/отработано | D42: 0.66666667 | E42: 20 | G42: 0.65517241 | H42: 19 | J42: 0.42857143 | K42: 3 | M42: 0.25 | N42: 2
A43: Средние продажи в смену | D43: 0.63270845 | E43: 54583.93 | F43: 0.63270845 | G43: 0.54414365 | H43: 46943.421 | I43: 0.54414365 | J43: 0.28576858 | K43: 24653.333 | L43: 0.28576858 | M43: 0.17464301 | N43: 15066.5 | O43: 0.17464301
A44: Трафик | D44: 0.38283582 | E44: 513 | F44: 0.57425373 | G44: 0.44673186 | H44: 385 | I44: 0.68185389 | J44: 0.31246366 | K44: 65 | L44: 0.72908186 | M44: 0.14301221 | N44: 34 | O44: 0.57204885
...

Sheet План на день
A1: Выручка | D1: 287799
A2: Кол-во изделий | D2: =D1/D4 -> 58.023992
A3: Средний чек | D3: =D4*D5 -> 8779.2
A4: Средняя стоимость изделия | D4: ='Ялта, Ленина, 18'!I11 -> 4960
A5: Длина чека | D5: ='Ялта, Ленина, 18'!I12 -> 1.77
A6: Кол-во чеков | D6: =IF(D5<>0,D2/D5,"") -> 32.781916
A7: Конверсия | D7: ='Ялта, Ленина, 18'!I20 -> 0.22
A8: IS | D8: =('Ялта, Ленина, 18'!S12-'Ялта, Ленина, 18'!T12)/('Ялта, Ленина, 18'!I14-'Ялта, Ленина, 18'!J14) -> #DIV/0!
A9: UNOde50 | D9: =('Ялта, Ленина, 18'!S18-'Ялта, Ленина, 18'!T18)/('Ялта, Ленина, 18'!I14-'Ялта, Ленина, 18'!J14) -> #DIV/0!

Sheet Рогалевич И. Е.
B1: =TODAY()-1 -> 46138
B2: (отчетная дата) | J2: ЕЖЕДНЕВНЫЙ ОТЧЕТ О ПРОДАЖАХ
B3: Осталось до выполнения плана!!! | J3: =График!B29 -> Рогалевич Ирина
C4: =I8-D54 -> 107784.85 | E4: =IF(I8<>0,C4/I8,0) -> 0.06086751
F6: Целевые показатели
F7: Показатель | I7: План | J7: Факт | K7: % выполнения | L7: Прогноз выполнения | M7: % выполнения по прогнозу | N7: Отклонение | O7: Факт аналогичного месяца прошлого года | P7: Отклонение LFL
F8: Выручка | I8: ='Ялта, Ленина, 18'!I8/График!AJ31*График!AJ29 -> 1770810.8 | J8: =D54 -> 1663026 | K8: =IF(AND(I8<>"",I8<>0,J8<>""),J8/I8,"") -> 0.93913249 | L8: =IF(SUMIF($D$25:$D$53,">=0",$P$25:$P$53)<>0,I8*D54/SUMIF($D$25:$D$53,">=0",$P$25:$P$53),0) -> 1611165.8 | M8: =IF(AND(I8<>"",I8<>0,L8<>"",L8<>0),L8/I8,"") -> 0.90984636 | N8: =IF(AND(J8<>0,J8<>"",I8<>0,I8<>""),L8-I8,"") -> -159645.05 | P8: =IF(AND(O8<>"",O8<>0,L8<>"",L8<>0),-O8+L8,"") | Q8: =IF(AND(P8<>"",P8<>0,O8<>0,O8<>""),P8/O8,"")
F9: Кол-во изделий | I9: =I8/I11 -> 357.01832 | J9: =E54 -> 315 | K9: =IF(AND(I9<>"",I9<>0,J9<>""),J9/I9,"") -> 0.88230767 | L9: =IF(SUMIF($E$25:$E$51,">=0",$Q$25:$Q$51)<>0,I9*E54/SUMIF($E$25:$E$51,">=0",$Q$25:$Q$51),0) -> 328.94221 | M9: =IF(AND(I9<>"",I9<>0,L9<>"",L9<>0),L9/I9,"") -> 0.92135948 | N9: =IF(AND(J9<>0,J9<>"",I9<>0,I9<>""),L9-I9,"") -> -28.076107 | O9: =O8/O11 -> #DIV/0! | P9: =IF(AND(O9<>"",O9<>0,L9<>"",L9<>0),-O9+L9,"") -> #DIV/0! | Q9: =IF(AND(P9<>"",P9<>0,O9<>0,O9<>""),P9/O9,"") -> #DIV/0!
F10: Средний чек | I10: =I11*I12 -> 8779.2 | J10: =H54 -> 10869.451 | K10: =IF(AND(I10<>"",I10<>0,J10<>""),J10/I10,"") -> 1.2380913 | L10: =J10 -> 10869.451 | M10: =IF(AND(I10<>"",I10<>0,L10<>"",L10<>0),L10/I10,"") -> 1.2380913 | N10: =IF(AND(J10<>0,J10<>"",I10<>0,I10<>""),L10-I10,"") -> 2090.251 | O10: =O11*O12 -> 0 | P10: =IF(AND(O10<>"",O10<>0,L10<>"",L10<>0),-O10+L10,"") | Q10: =IF(AND(P10<>"",P10<>0,O10<>0,O10<>""),P10/O10,"") | S10: IS
F11: Средняя стоимость изделия | I11: ='Ялта, Ленина, 18'!I11 -> 4960 | J11: =F54 -> 5279.4476 | K11: =IF(AND(I11<>"",I11<>0,J11<>""),J11/I11,"") -> 1.0644048 | L11: =IF(L9>0,L8/L9,"") -> 4898.0209 | M11: =IF(AND(I11<>"",I11<>0,L11<>"",L11<>0),L11/I11,"") -> 0.9875042 | N11: =IF(AND(J11<>0,J11<>"",I11<>0,I11<>""),L11-I11,"") -> -61.979149 | P11: =IF(AND(O11<>"",O11<>0,L11<>"",L11<>0),-O11+L11,"") | Q11: =IF(AND(P11<>"",P11<>0,O11<>0,O11<>""),P11/O11,"")
F12: Длина чека | I12: ='Ялта, Ленина, 18'!I12 -> 1.77 | J12: =J54 -> 2.0588235 | K12: =IF(AND(I12<>"",I12<>0,J12<>""),J12/I12,"") -> 1.1631771 | L12: =J12 -> 2.0588235 | M12: =IF(AND(I12<>"",I12<>0,L12<>"",L12<>0),L12/I12,"") -> 1.1631771 | N12: =IF(AND(J12<>0,J12<>"",I12<>0,I12<>""),L12-I12,"") -> 0.28882353 | P12: =IF(AND(O12<>"",O12<>0,L12<>"",L12<>0),-O12+L12,"") | Q12: =IF(AND(P12<>"",P12<>0,O12<>0,O12<>""),P12/O12,"") | S12: ='Ялта, Ленина, 18'!S12*График!AJ29/График!AJ31 -> 410526.32 | T12: =L54 -> 178814
F13: Кол-во чеков | I13: =IF(I12<>0,I9/I12,"") -> 201.70526 | J13: =G54 -> 153 | K13: =IF(AND(I13<>"",I13<>0,J13<>""),J13/I13,"") -> 0.75853251 | L13: =IF(SUMIF($G$25:$G$51,">=0",$R$25:$R$51)<>0,I13*G54/SUMIF($G$25:$G$51,">=0",$R$25:$R$51),"") -> 159.69252 | M13: =IF(AND(I13<>"",I13<>0,L13<>"",L13<>0),L13/I13,"") -> 0.79171223 | N13: =IF(AND(J13<>0,J13<>"",I13<>0,I13<>""),L13-I13,"") -> -42.012739 | P13: =IF(AND(O13<>"",O13<>0,L13<>"",L13<>0),-O13+L13,"") | Q13: =IF(AND(P13<>"",P13<>0,O13<>0,O13<>""),P13/O13,"") | S13: =T12/S12 -> 0.43557256 | T13: =S13/J14*I14 -> 0.43557256
F14: Кол-во смен план/отработано | I14: =График!AI29 -> 29 | J14: 29 | K14: =IF(AND(I14<>"",I14<>0,J14<>""),J14/I14,"") -> 1 | L14: =I14 -> 29 | M14: =IF(AND(I14<>"",I14<>0,L14<>"",L14<>0),L14/I14,"") -> 1 | N14: =IF(AND(J14<>0,J14<>"",I14<>0,I14<>""),L14-I14,"") -> 0 | P14: =IF(AND(O14<>"",O14<>0,L14<>"",L14<>0),-O14+L14,"") | Q14: =IF(AND(P14<>"",P14<>0,O14<>0,O14<>""),P14/O14,"")
F15: Средние продажи в смену | I15: ='Ялта, Ленина, 18'!I15 -> 86270.272 | J15: =J8/J14 -> 57345.724 | K15: =IF(AND(I15<>"",I15<>0,J15<>""),J15/I15,"") -> 0.66472173 | L15: =J15 -> 57345.724 | M15: =IF(AND(I15<>"",I15<>0,L15<>"",L15<>0),L15/I15,"") -> 0.66472173 | N15: =IF(AND(J15<>0,J15<>"",I15<>0,I15<>""),L15-I15,"") -> -28924.548 | P15: =IF(AND(O15<>"",O15<>0,L15<>"",L15<>0),-O15+L15,"") | Q15: =IF(AND(P15<>"",P15<>0,O15<>0,O15<>""),P15/O15,"")
F16: Отставание/Перевыполнение | J16: =J8-I15*J14 -> -838811.89 | K16: =IF(AND(I16<>"",I16<>0,J16<>""),J16/I16,"") | L16: =J16 -> -838811.89 | M16: =IF(AND(I16<>"",I16<>0,L16<>"",L16<>0),L16/I16,"") | N16: =IF(AND(J16<>0,J16<>"",I16<>0,I16<>""),L16-I16,"") | P16: =IF(AND(O16<>"",O16<>0,L16<>"",L16<>0),-O16+L16,"") | Q16: =IF(AND(P16<>"",P16<>0,O16<>0,O16<>""),P16/O16,"") | S16: UNOde50
F17: Трафик | I17: ='Ялта, Ленина, 18'!I17/График!AJ31*График!AJ29 -> 916.84211 | J17: =I54 -> 640 | K17: =IF(AND(I17<>"",I17<>0,J17<>""),J17/I17,"") -> 0.69804822 | L17: =J17/J14*I14 -> 640 | M17: =IF(AND(I17<>"",I17<>0,L17<>"",L17<>0),L17/I17,"") -> 0.69804822 | N17: =IF(AND(J17<>0,J17<>"",I17<>0,I17<>""),L17-I17,"") -> -276.84211 | P17: =IF(AND(O17<>"",O17<>0,L17<>"",L17<>0),-O17+L17,"") | Q17: =IF(AND(P17<>"",P17<>0,O17<>0,O17<>""),P17/O17,"")
K18: =IF(AND(I18<>"",I18<>0,J18<>""),J18/I18,"") | L18: =J18 -> 0 | M18: =IF(AND(I18<>"",I18<>0,L18<>"",L18<>0),L18/I18,"") | N18: =IF(AND(J18<>0,J18<>"",I18<>0,I18<>""),L18-I18,"") | O18: 0 | P18: =IF(AND(O18<>"",O18<>0,L18<>"",L18<>0),-O18+L18,"") | Q18: =IF(AND(P18<>"",P18<>0,O18<>0,O18<>""),P18/O18,"") | S18: ='Ялта, Ленина, 18'!S18*График!AJ29/График!AJ31 -> 273684.21 | T18: =K54 -> 255926
J19: =M54 -> 0 | K19: =IF(AND(I19<>"",I19<>0,J19<>""),J19/I19,"") | L19: =J19 -> 0 | M19: =IF(AND(I19<>"",I19<>0,L19<>"",L19<>0),L19/I19,"") | N19: =IF(AND(J19<>0,J19<>"",I19<>0,I19<>""),L19-I19,"") | O19: 0 | P19: =IF(AND(O19<>"",O19<>0,L19<>"",L19<>0),-O19+L19,"") | Q19: =IF(AND(P19<>"",P19<>0,O19<>0,O19<>""),P19/O19,"") | S19: =T18/S18 -> 0.93511423 | T19: =S19/J14*I14 -> 0.93511423
F20: Конверсия план/факт | I20: ='Ялта, Ленина, 18'!I20 -> 0.22 | J20: =N54 -> 0.2390625 | K20: =J20/I20 -> 1.0866477 | L20: =IF(AND(K8<>0,I14<>0,I54<>0),(I54*N54+(I54/K8-I54)*I20)/(I54/K8),0) -> 0.23790221 | M20: =IF(AND(I20<>"",I20<>0,L20<>"",L20<>0),L20/I20,"") -> 1.0813737 | N20: =IF(AND(J20<>0,J20<>"",I20<>0,I20<>""),L20-I20,"") -> 0.017902213 | P20: =IF(AND(O20<>"",O20<>0,L20<>"",L20<>0),-O20+L20,"") | Q20: =IF(AND(P20<>"",P20<>0,O20<>0,O20<>""),P20/O20,"")
B22: Факт продаж за месяц | O22: % выполнения дневного плана | P22: Раcпределение плана по дням
B23: Дата | C23: День недели | D23: Выручка (руб) | E23: Кол-во единиц (шт.) | F23: Средняя стоимость изделия (руб.) | G23: Количество чеков (шт.) | H23: Средняя сумма чека (руб.) | I23: Трафик | J23: Длина чека (шт.) | K23: UNOde50 | L23: IS | M23: Запасной | N23: Конверсия (%) | P23: выручка, план | Q23: кол-во ед, план | R23: Кол-во чеков, план | S23: выручка, скорректир.план | T23: кол-во ед, скорр. план | U23: кол-во чеков, скорр. план | V23: Коэфф. Дня Недели | W23: Специфика месяца
B24: 1 | C24: 2 | D24: 3 | E24: 4 | F24: 5 | G24: 6 | H24: 7 | I24: 8 | J24: 9 | K24: 10 | L24: 11 | M24: 12 | N24: 13 | P24: 1 | Q24: 2 | R24: 3 | S24: 4 | T24: 5 | U24: 6 | V24: 10 | W24: 11
A25: 1 | B25: 45748 | C25: вт | D25: =25355+16920 -> 42275 | E25: 8 | F25: =IF(AND(E25<>"",E25<>0),D25/E25,"") -> 5284.375 | G25: 6 | H25: =IF(AND(G25<>"",G25<>0),D25/G25,"") -> 7045.8333 | I25: 40 | J25: =IF(AND(G25<>"",G25<>0),E25/G25,"") -> 1.3333333 | K25: 0 | L25: 16920 | N25: =IF(AND(I25<>"",I25<>0),G25/I25,"") -> 0.15 | O25: =D25/P25 -> 0.79851241 | P25: =$I$8*V25*W25/SUMPRODUCT($W$25:$W$55,$V$25:$V$55) -> 52942.196 | Q25: =$I$9*V25*W25/SUMPRODUCT($W$25:$W$55,$V$25:$V$55) -> 10.67383 | R25: =IF($I$12="","",Q25/$I$12) -> 6.0304123 | S25: =IF(D25<>"",D25,P25) -> 42275 | T25: =IF(E25<>"",E25,Q25) -> 8 | U25: =IF(G25<>"",G25,R25) -> 6 | V25: 0.9004852 | W25: 0.9004852
A26: 2 | B26: 45749 | C26: ср | D26: =24542+15120 -> 39662 | E26: 10 | F26: =IF(AND(E26<>"",E26<>0),D26/E26,"") -> 3966.2 | G26: 5 | H26: =IF(AND(G26<>"",G26<>0),D26/G26,"") -> 7932.4 | I26: 20 | J26: =IF(AND(G26<>"",G26<>0),E26/G26,"") -> 2 | K26: 5492 | L26: 15120 | N26: =IF(AND(I26<>"",I26<>0),G26/I26,"") -> 0.25 | O26: =D26/P26 -> 0.53943493 | P26: =$I$8*V26*W26/SUMPRODUCT($W$25:$W$55,$V$25:$V$55) -> 73525.086 | Q26: =$I$9*V26*W26/SUMPRODUCT($W$25:$W$55,$V$25:$V$55) -> 14.823606 | R26: =IF($I$12="","",Q26/$I$12) -> 8.3749187 | S26: =IF(W26<>"",IF(D26<>"",D26,($I$8-SUM($S$25:S25))*V26*W26/SUMPRODUCT($W26:$W$55,$V26:$V$55)),"") -> 39662 | T26: =IF(W26<>"",IF(E26<>"",E26,($I$9-SUM($T$25:T25))*V26*W26/SUMPRODUCT($W26:$W$55,$V26:$V$55)),"") -> 10 | U26: =IF(W26<>"",IF($I$12<>"",IF(G26<>"",G26,($I$9/$I$12-SUM($U$25:U25))*V26*W26/SUMPRODUCT($W26:$W$55,$V26:$V$55)),""),"") -> 5 | V26: 1.0611906 | W26: 1.0611906
A27: 3 | B27: 45751 | C27: пт | D27: 18259 | E27: 5 | F27: =IF(AND(E27<>"",E27<>0),D27/E27,"") -> 3651.8 | G27: 4 | H27: =IF(AND(G27<>"",G27<>0),D27/G27,"") -> 4564.75 | I27: 17 | J27: =IF(AND(G27<>"",G27<>0),E27/G27,"") -> 1.25 | N27: =IF(AND(I27<>"",I27<>0),G27/I27,"") -> 0.23529412 | O27: =D27/P27 -> 0.45864599 | P27: =$I$8*V27*W27/SUMPRODUCT($W$25:$W$55,$V$25:$V$55) -> 39810.661 | Q27: =$I$9*V27*W27/SUMPRODUCT($W$25:$W$55,$V$25:$V$55) -> 8.0263429 | R27: =IF($I$12="","",Q27/$I$12) -> 4.534657 | S27: =IF(W27<>"",IF(D27<>"",D27,($I$8-SUM($S$25:S26))*V27*W27/SUMPRODUCT($W27:$W$55,$V27:$V$55)),"") -> 18259 | T27: =IF(W27<>"",IF(E27<>"",E27,($I$9-SUM($T$25:T26))*V27*W27/SUMPRODUCT($W27:$W$55,$V27:$V$55)),"") -> 5 | U27: =IF(W27<>"",IF($I$12<>"",IF(G27<>"",G27,($I$9/$I$12-SUM($U$25:U26))*V27*W27/SUMPRODUCT($W27:$W$55,$V27:$V$55)),""),"") -> 4 | V27: 0.78086381 | W27: 0.78086381
A28: 4 | B28: 45752 | C28: сб | D28: 47559 | E28: 11 | F28: =IF(AND(E28<>"",E28<>0),D28/E28,"") -> 4323.5455 | G28: 7 | H28: =IF(AND(G28<>"",G28<>0),D28/G28,"") -> 6794.1429 | I28: 26 | J28: =IF(AND(G28<>"",G28<>0),E28/G28,"") -> 1.5714286 | N28: =IF(AND(I28<>"",I28<>0),G28/I28,"") -> 0.26923077 | O28: =D28/P28 -> 0.66831981 | P28: =$I$8*V28*W28/SUMPRODUCT($W$25:$W$55,$V$25:$V$55) -> 71162.039 | Q28: =$I$9*V28*W28/SUMPRODUCT($W$25:$W$55,$V$25:$V$55) -> 14.347185 | R28: =IF($I$12="","",Q28/$I$12) -> 8.1057543 | S28: =IF(W28<>"",IF(D28<>"",D28,($I$8-SUM($S$25:S27))*V28*W28/SUMPRODUCT($W28:$W$55,$V28:$V$55)),"") -> 47559 | T28: =IF(W28<>"",IF(E28<>"",E28,($I$9-SUM($T$25:T27))*V28*W28/SUMPRODUCT($W28:$W$55,$V28:$V$55)),"") -> 11 | U28: =IF(W28<>"",IF($I$12<>"",IF(G28<>"",G28,($I$9/$I$12-SUM($U$25:U27))*V28*W28/SUMPRODUCT($W28:$W$55,$V28:$V$55)),""),"") -> 7 | V28: 1.0439983 | W28: 1.0439983
A29: 5 | B29: 45753 | C29: вс | D29: =51277+32720 -> 83997 | E29: 17 | F29: =IF(AND(E29<>"",E29<>0),D29/E29,"") -> 4941 | G29: 9 | H29: =IF(AND(G29<>"",G29<>0),D29/G29,"") -> 9333 | I29: 30 | J29: =IF(AND(G29<>"",G29<>0),E29/G29,"") -> 1.8888889 | K29: 0 | L29: 32720 | N29: =IF(AND(I29<>"",I29<>0),G29/I29,"") -> 0.3 | O29: =D29/P29 -> 2.1099122 | P29: =$I$8*V29*W29/SUMPRODUCT($W$25:$W$55,$V$25:$V$55) -> 39810.661 | Q29: =$I$9*V29*W29/SUMPRODUCT($W$25:$W$55,$V$25:$V$55) -> 8.0263429 | R29: =IF($I$12="","",Q29/$I$12) -> 4.534657 | S29: =IF(W29<>"",IF(D29<>"",D29,($I$8-SUM($S$25:S28))*V29*W29/SUMPRODUCT($W29:$W$55,$V29:$V$55)),"") -> 83997 | T29: =IF(W29<>"",IF(E29<>"",E29,($I$9-SUM($T$25:T28))*V29*W29/SUMPRODUCT($W29:$W$55,$V29:$V$55)),"") -> 17 | U29: =IF(W29<>"",IF($I$12<>"",IF(G29<>"",G29,($I$9/$I$12-SUM($U$25:U28))*V29*W29/SUMPRODUCT($W29:$W$55,$V29:$V$55)),""),"") -> 9 | V29: 0.78086381 | W29: 0.78086381
A30: 6 | B30: 45754 | C30: пн | D30: 25437 | E30: 6 | F30: =IF(AND(E30<>"",E30<>0),D30/E30,"") -> 4239.5 | G30: 3 | H30: =IF(AND(G30<>"",G30<>0),D30/G30,"") -> 8479 | I30: 5 | J30: =IF(AND(G30<>"",G30<>0),E30/G30,"") -> 2 | K30: 0 | L30: 0 | N30: =IF(AND(I30<>"",I30<>0),G30/I30,"") -> 0.6 | O30: =D30/P30 -> 0.58744302 | P30: =$I$8*V30*W30/SUMPRODUCT($W$25:$W$55,$V$25:$V$55) -> 43301.221 | Q30: =$I$9*V30*W30/SUMPRODUCT($W$25:$W$55,$V$25:$V$55) -> 8.7300849 | R30: =IF($I$12="","",Q30/$I$12) -> 4.9322514 | S30: =IF(W30<>"",IF(D30<>"",D30,($I$8-SUM($S$25:S29))*V30*W30/SUMPRODUCT($W30:$W$55,$V30:$V$55)),"") -> 25437 | T30: =IF(W30<>"",IF(E30<>"",E30,($I$9-SUM($T$25:T29))*V30*W30/SUMPRODUCT($W30:$W$55,$V30:$V$55)),"") -> 6 | U30: =IF(W30<>"",IF($I$12<>"",IF(G30<>"",G30,($I$9/$I$12-SUM($U$25:U29))*V30*W30/SUMPRODUCT($W30:$W$55,$V30:$V$55)),""),"") -> 3 | V30: 0.81437733 | W30: 0.81437733
A31: 7 | B31: 45755 | C31: вт | D31: 5483 | E31: 2 | F31: =IF(AND(E31<>"",E31<>0),D31/E31,"") -> 2741.5 | G31: 1 | H31: =IF(AND(G31<>"",G31<>0),D31/G31,"") -> 5483 | I31: 12 | J31: =IF(AND(G31<>"",G31<>0),E31/G31,"") -> 2 | K31: 0 | L31: 0 | N31: =IF(AND(I31<>"",I31<>0),G31/I31,"") -> 0.083333333 | O31: =D31/P31 -> 0.1266246 | P31: =$I$8*V31*W31/SUMPRODUCT($W$25:$W$55,$V$25:$V$55) -> 43301.221 | Q31: =$I$9*V31*W31/SUMPRODUCT($W$25:$W$55,$V$25:$V$55) -> 8.7300849 | R31: =IF($I$12="","",Q31/$I$12) -> 4.9322514 | S31: =IF(W31<>"",IF(D31<>"",D31,($I$8-SUM($S$25:S30))*V31*W31/SUMPRODUCT($W31:$W$55,$V31:$V$55)),"") -> 5483 | T31: =IF(W31<>"",IF(E31<>"",E31,($I$9-SUM($T$25:T30))*V31*W31/SUMPRODUCT($W31:$W$55,$V31:$V$55)),"") -> 2 | U31: =IF(W31<>"",IF($I$12<>"",IF(G31<>"",G31,($I$9/$I$12-SUM($U$25:U30))*V31*W31/SUMPRODUCT($W31:$W$55,$V31:$V$55)),""),"") -> 1 | V31: 0.81437733 | W31: 0.81437733
A32: 8 | B32: 45756 | C32: ср | D32: 3792 | E32: 1 | F32: =IF(AND(E32<>"",E32<>0),D32/E32,"") -> 3792 | G32: 1 | H32: =IF(AND(G32<>"",G32<>0),D32/G32,"") -> 3792 | I32: 8 | J32: =IF(AND(G32<>"",G32<>0),E32/G32,"") -> 1 | K32: 0 | L32: 0 | N32: =IF(AND(I32<>"",I32<>0),G32/I32,"") -> 0.125 | O32: =D32/P32 -> 0.087572588 | P32: =$I$8*V32*W32/SUMPRODUCT($W$25:$W$55,$V$25:$V$55) -> 43301.221 | Q32: =$I$9*V32*W32/SUMPRODUCT($W$25:$W$55,$V$25:$V$55) -> 8.7300849 | R32: =IF($I$12="","",Q32/$I$12) -> 4.9322514 | S32: =IF(W32<>"",IF(D32<>"",D32,($I$8-SUM($S$25:S31))*V32*W32/SUMPRODUCT($W32:$W$55,$V32:$V$55)),"") -> 3792 | T32: =IF(W32<>"",IF(E32<>"",E32,($I$9-SUM($T$25:T31))*V32*W32/SUMPRODUCT($W32:$W$55,$V32:$V$55)),"") -> 1 | U32: =IF(W32<>"",IF($I$12<>"",IF(G32<>"",G32,($I$9/$I$12-SUM($U$25:U31))*V32*W32/SUMPRODUCT($W32:$W$55,$V32:$V$55)),""),"") -> 1 | V32: 0.81437733 | W32: 0.81437733
A33: 9 | B33: 45757 | C33: чт | D33: =37704+7803 -> 45507 | E33: 9 | F33: =IF(AND(E33<>"",E33<>0),D33/E33,"") -> 5056.3333 | G33: 4 | H33: =IF(AND(G33<>"",G33<>0),D33/G33,"") -> 11376.75 | I33: 10 | J33: =IF(AND(G33<>"",G33<>0),E33/G33,"") -> 2.25 | K33: 0 | L33: 7803 | N33: =IF(AND(I33<>"",I33<>0),G33/I33,"") -> 0.4 | O33: =D33/P33 -> 0.6969946 | P33: =$I$8*V33*W33/SUMPRODUCT($W$25:$W$55,$V$25:$V$55) -> 65290.319 | Q33: =$I$9*V33*W33/SUMPRODUCT($W$25:$W$55,$V$25:$V$55) -> 13.163371 | R33: =IF($I$12="","",Q33/$I$12) -> 7.4369327 | S33: =IF(W33<>"",IF(D33<>"",D33,($I$8-SUM($S$25:S32))*V33*W33/SUMPRODUCT($W33:$W$55,$V33:$V$55)),"") -> 45507 | T33: =IF(W33<>"",IF(E33<>"",E33,($I$9-SUM($T$25:T32))*V33*W33/SUMPRODUCT($W33:$W$55,$V33:$V$55)),"") -> 9 | U33: =IF(W33<>"",IF($I$12<>"",IF(G33<>"",G33,($I$9/$I$12-SUM($U$25:U32))*V33*W33/SUMPRODUCT($W33:$W$55,$V33:$V$55)),""),"") -> 4 | V33: 1 | W33: 1
A34: 10 | B34: 45758 | C34: пт | D34: 4192 | E34: 1 | F34: =IF(AND(E34<>"",E34<>0),D34/E34,"") -> 4192 | G34: 1 | H34: =IF(AND(G34<>"",G34<>0),D34/G34,"") -> 4192 | I34: 10 | J34: =IF(AND(G34<>"",G34<>0),E34/G34,"") -> 1 | K34: 0 | L34: 0 | N34: =IF(AND(I34<>"",I34<>0),G34/I34,"") -> 0.1 | O34: =D34/P34 -> 0.10529843 | P34: =$I$8*V34*W34/SUMPRODUCT($W$25:$W$55,$V$25:$V$55) -> 39810.661 | Q34: =$I$9*V34*W34/SUMPRODUCT($W$25:$W$55,$V$25:$V$55) -> 8.0263429 | R34: =IF($I$12="","",Q34/$I$12) -> 4.534657 | S34: =IF(W34<>"",IF(D34<>"",D34,($I$8-SUM($S$25:S33))*V34*W34/SUMPRODUCT($W34:$W$55,$V34:$V$55)),"") -> 4192 | T34: =IF(W34<>"",IF(E34<>"",E34,($I$9-SUM($T$25:T33))*V34*W34/SUMPRODUCT($W34:$W$55,$V34:$V$55)),"") -> 1 | U34: =IF(W34<>"",IF($I$12<>"",IF(G34<>"",G34,($I$9/$I$12-SUM($U$25:U33))*V34*W34/SUMPRODUCT($W34:$W$55,$V34:$V$55)),""),"") -> 1 | V34: 0.78086381 | W34: 0.78086381
A35: 11 | B35: 45759 | C35: сб | D35: =12474+37008 -> 49482 | E35: 7 | F35: =IF(AND(E35<>"",E35<>0),D35/E35,"") -> 7068.8571 | G35: 3 | H35: =IF(AND(G35<>"",G35<>0),D35/G35,"") -> 16494 | I35: 7 | J35: =IF(AND(G35<>"",G35<>0),E35/G35,"") -> 2.3333333 | K35: 0 | L35: 37008 | N35: =IF(AND(I35<>"",I35<>0),G35/I35,"") -> 0.42857143 | O35: =D35/P35 -> 1.2429334 | P35: =$I$8*V35*W35/SUMPRODUCT($W$25:$W$55,$V$25:$V$55) -> 39810.661 | Q35: =$I$9*V35*W35/SUMPRODUCT($W$25:$W$55,$V$25:$V$55) -> 8.0263429 | R35: =IF($I$12="","",Q35/$I$12) -> 4.534657 | S35: =IF(W35<>"",IF(D35<>"",D35,($I$8-SUM($S$25:S34))*V35*W35/SUMPRODUCT($W35:$W$55,$V35:$V$55)),"") -> 49482 | T35: =IF(W35<>"",IF(E34<>"",E34,($I$9-SUM($T$25:T34))*V35*W35/SUMPRODUCT($W35:$W$55,$V35:$V$55)),"") -> 1 | U35: =IF(W35<>"",IF($I$12<>"",IF(G35<>"",G35,($I$9/$I$12-SUM($U$25:U34))*V35*W35/SUMPRODUCT($W35:$W$55,$V35:$V$55)),""),"") -> 3 | V35: 0.78086381 | W35: 0.78086381
A36: 12 | B36: 45760 | C36: вс | D36: 42990 | E36: 8 | F36: =IF(AND(E36<>"",E36<>0),D36/E36,"") -> 5373.75 | G36: 7 | H36: =IF(AND(G36<>"",G36<>0),D36/G36,"") -> 6141.4286 | I36: 30 | J36: =IF(AND(G36<>"",G36<>0),E36/G36,"") -> 1.1428571 | K36: =11993+5493 -> 17486 | N36: =IF(AND(I36<>"",I36<>0),G36/I36,"") -> 0.23333333 | O36: =D36/P36 -> 1.0798615 | P36: =$I$8*V36*W36/SUMPRODUCT($W$25:$W$55,$V$25:$V$55) -> 39810.661 | Q36: =$I$9*V36*W36/SUMPRODUCT($W$25:$W$55,$V$25:$V$55) -> 8.0263429 | R36: =IF($I$12="","",Q36/$I$12) -> 4.534657 | S36: =IF(W36<>"",IF(D36<>"",D36,($I$8-SUM($S$25:S35))*V36*W36/SUMPRODUCT($W36:$W$55,$V36:$V$55)),"") -> 42990 | T36: =IF(W36<>"",IF(E36<>"",E36,($I$9-SUM($T$25:T35))*V36*W36/SUMPRODUCT($W36:$W$55,$V36:$V$55)),"") -> 8 | U36: =IF(W36<>"",IF($I$12<>"",IF(G36<>"",G36,($I$9/$I$12-SUM($U$25:U35))*V36*W36/SUMPRODUCT($W36:$W$55,$V36:$V$55)),""),"") -> 7 | V36: 0.78086381 | W36: 0.78086381
A37: 13 | B37: 45761 | C37: пн | D37: =84715+10903 -> 95618 | E37: 22 | F37: =IF(AND(E37<>"",E37<>0),D37/E37,"") -> 4346.2727 | G37: 11 | H37: =IF(AND(G37<>"",G37<>0),D37/G37,"") -> 8692.5455 | I37: 40 | J37: =IF(AND(G37<>"",G37<>0),E37/G37,"") -> 2 | L37: 10903 | N37: =IF(AND(I37<>"",I37<>0),G37/I37,"") -> 0.275 | O37: =D37/P37 -> 1.5377647 | P37: =$I$8*V37*W37/SUMPRODUCT($W$25:$W$55,$V$25:$V$55) -> 62179.864 | Q37: =$I$9*V37*W37/SUMPRODUCT($W$25:$W$55,$V$25:$V$55) -> 12.536263 | R37: =IF($I$12="","",Q37/$I$12) -> 7.0826344 | S37: =IF(W37<>"",IF(D37<>"",D37,($I$8-SUM($S$25:S36))*V37*W37/SUMPRODUCT($W37:$W$55,$V37:$V$55)),"") -> 95618 | T37: =IF(W37<>"",IF(E37<>"",E37,($I$9-SUM($T$25:T36))*V37*W37/SUMPRODUCT($W37:$W$55,$V37:$V$55)),"") -> 22 | U37: =IF(W37<>"",IF($I$12<>"",IF(G37<>"",G37,($I$9/$I$12-SUM($U$25:U36))*V37*W37/SUMPRODUCT($W37:$W$55,$V37:$V$55)),""),"") -> 11 | V37: 0.97588915 | W37: 0.97588915
A38: 14 | B38: 45762 | C38: вт | D38: 59588 | E38: 12 | F38: =IF(AND(E38<>"",E38<>0),D38/E38,"") -> 4965.6667 | G38: 4 | H38: =IF(AND(G38<>"",G38<>0),D38/G38,"") -> 14897 | I38: 30 | J38: =IF(AND(G38<>"",G38<>0),E38/G38,"") -> 3 | K38: 23982 | N38: =IF(AND(I38<>"",I38<>0),G38/I38,"") -> 0.13333333 | O38: =D38/P38 -> 0.95831666 | P38: =$I$8*V38*W38/SUMPRODUCT($W$25:$W$55,$V$25:$V$55) -> 62179.864 | Q38: =$I$9*V38*W38/SUMPRODUCT($W$25:$W$55,$V$25:$V$55) -> 12.536263 | R38: =IF($I$12="","",Q38/$I$12) -> 7.0826344 | S38: =IF(W38<>"",IF(D38<>"",D38,($I$8-SUM($S$25:S37))*V38*W38/SUMPRODUCT($W38:$W$55,$V38:$V$55)),"") -> 59588 | T38: =IF(W38<>"",IF(E38<>"",E38,($I$9-SUM($T$25:T37))*V38*W38/SUMPRODUCT($W38:$W$55,$V38:$V$55)),"") -> 12 | U38: =IF(W38<>"",IF($I$12<>"",IF(G38<>"",G38,($I$9/$I$12-SUM($U$25:U37))*V38*W38/SUMPRODUCT($W38:$W$55,$V38:$V$55)),""),"") -> 4 | V38: 0.97588915 | W38: 0.97588915
A39: 15 | B39: 45763 | C39: ср | D39: =40943-6484 -> 34459 | E39: 5 | F39: 5849 | G39: 4 | H39: 6824 | I39: 15 | J39: 1.17 | K39: 13993 | N39: 0.2 | O39: 0.46 | P39: 89681 | Q39: 18 | R39: 10 | S39: 40943 | T39: 7 | U39: 6 | V39: 0.98 | W39: 0.98
A40: 16 | B40: 45764 | C40: чт | D40: =96243-47425-15867-7903 -> 25048 | E40: 6 | F40: 7403 | G40: 4 | H40: 10694 | I40: 20 | J40: 1.44 | N40: 0.225 | O40: 1.01 | P40: 95313 | Q40: 19 | R40: 11 | S40: 96243 | T40: 13 | U40: 9 | V40: 1 | W40: 1
A41: 17 | B41: 45765 | C41: пт | D41: =124304 -> 124304 | E41: 14 | F41: =IF(AND(E41<>"",E41<>0),D41/E41,"") -> 8878.8571 | G41: 6 | H41: =IF(AND(G41<>"",G41<>0),D41/G41,"") -> 20717.333 | I41: 15 | J41: =IF(AND(G41<>"",G41<>0),E41/G41,"") -> 2.3333333 | K41: 64967 | N41: =IF(AND(I41<>"",I41<>0),G41/I41,"") -> 0.4 | O41: =D41/P41 -> 1.3811075 | P41: =$I$8*V41*W41/SUMPRODUCT($W$25:$W$55,$V$25:$V$55) -> 90003.135 | Q41: =$I$9*V41*W41/SUMPRODUCT($W$25:$W$55,$V$25:$V$55) -> 18.145793 | R41: =IF($I$12="","",Q41/$I$12) -> 10.251861 | S41: =IF(W41<>"",IF(D41<>"",D41,($I$8-SUM($S$25:S40))*V41*W41/SUMPRODUCT($W41:$W$55,$V41:$V$55)),"") -> 124304 | T41: =IF(W41<>"",IF(E41<>"",E41,($I$9-SUM($T$25:T40))*V41*W41/SUMPRODUCT($W41:$W$55,$V41:$V$55)),"") -> 14 | U41: =IF(W41<>"",IF($I$12<>"",IF(G41<>"",G41,($I$9/$I$12-SUM($U$25:U40))*V41*W41/SUMPRODUCT($W41:$W$55,$V41:$V$55)),""),"") -> 6 | V41: 1.1740982 | W41: 1.1740982
A42: 18 | B42: 45766 | C42: сб | D42: 45289 | E42: 10 | F42: =IF(AND(E42<>"",E42<>0),D42/E42,"") -> 4528.9 | G42: 6 | H42: =IF(AND(G42<>"",G42<>0),D42/G42,"") -> 7548.1667 | I42: 25 | J42: =IF(AND(G42<>"",G42<>0),E42/G42,"") -> 1.6666667 | K42: 12992 | N42: =IF(AND(I42<>"",I42<>0),G42/I42,"") -> 0.24 | O42: =D42/P42 -> 0.50319359 | P42: =$I$8*V42*W42/SUMPRODUCT($W$25:$W$55,$V$25:$V$55) -> 90003.135 | Q42: =$I$9*V42*W42/SUMPRODUCT($W$25:$W$55,$V$25:$V$55) -> 18.145793 | R42: =IF($I$12="","",Q42/$I$12) -> 10.251861 | S42: =IF(W42<>"",IF(D42<>"",D42,($I$8-SUM($S$25:S41))*V42*W42/SUMPRODUCT($W42:$W$55,$V42:$V$55)),"") -> 45289 | T42: =IF(W42<>"",IF(E42<>"",E42,($I$9-SUM($T$25:T41))*V42*W42/SUMPRODUCT($W42:$W$55,$V42:$V$55)),"") -> 10 | U42: =IF(W42<>"",IF($I$12<>"",IF(G42<>"",G42,($I$9/$I$12-SUM($U$25:U41))*V42*W42/SUMPRODUCT($W42:$W$55,$V42:$V$55)),""),"") -> 6 | V42: 1.1740982 | W42: 1.1740982
...

Sheet Уразгильдеева Е. Р.
B1: =TODAY()-1 -> 46138
B2: (отчетная дата) | J2: ЕЖЕДНЕВНЫЙ ОТЧЕТ О ПРОДАЖАХ
B3: Осталось до выполнения плана!!! | J3: =График!B28 -> Уразгильдеева Екатерина
C4: =I8-D50 -> 258684.47 | E4: =IF(I8<>0, C4/I8, 0) -> 0.51792885
F6: Целевые показатели
F7: Показатель | I7: План | J7: Факт | K7: % выполнения | L7: Прогноз выполнения | M7: % выполнения по прогнозу | N7: Отклонение | O7: Факт аналогичного месяца прошлого года | P7: Отклонение LFL
F8: Выручка | I8: ='Ялта, Ленина, 18'!I8/График!AJ31*График!AJ28 -> 499459.47 | J8: =D50 -> 240775 | K8: =J8/I8 -> 0.48207115 | L8: =IF(SUMIF($D$25:$D$49,">=0",$P$25:$P$49)<>0,I8*D50/SUMIF($D$25:$D$49,">=0",$P$25:$P$49),0) -> 225590.39 | M8: =IF(AND(I8<>"",I8<>0,L8<>"",L8<>0),L8/I8,"") -> 0.45166906 | N8: =IF(AND(J8<>0, J8<>"", I8<>0, I8<>""), L8-I8, "") -> -273869.08 | P8: =IF(AND(O8<>"", O8<>0, L8<>"", L8<>0), -O8+L8, "") | Q8: =IF(AND(P8<>"", P8<>0, O8<>0, O8<>""), P8/O8, "")
F9: Кол-во изделий | I9: =I8/I11 -> 100.69747 | J9: =E50 -> 51 | K9: =IF(AND(I9<>"", I9<>0, J9<>""), J9/I9, "") -> 0.50646752 | L9: =J9 -> 51 | M9: =IF(AND(I9<>"",I9<>0,L9<>"",L9<>0),L9/I9,"") -> 0.50646752 | N9: =IF(AND(J9<>0, J9<>"", I9<>0, I9<>""), L9-I9, "") -> -49.697474 | O9: =O8/O11 -> #DIV/0! | P9: =IF(AND(O9<>"", O9<>0, L9<>"", L9<>0), -O9+L9, "") -> #DIV/0! | Q9: =IF(AND(P9<>"", P9<>0, O9<>0, O9<>""), P9/O9, "") -> #DIV/0!
F10: Средний чек | I10: =I11*I12 -> 8779.2 | J10: =H50 -> 8917.5926 | K10: =IF(AND(I10<>"", I10<>0, J10<>""), J10/I10, "") -> 1.0157637 | L10: =J10 -> 8917.5926 | M10: =IF(AND(I10<>"",I10<>0,L10<>"",L10<>0),L10/I10,"") -> 1.0157637 | N10: =IF(AND(J10<>0, J10<>"", I10<>0, I10<>""), L10-I10, "") -> 138.39259 | O10: =O11*O12 -> 0 | P10: =IF(AND(O10<>"", O10<>0, L10<>"", L10<>0), -O10+L10, "") | Q10: =IF(AND(P10<>"", P10<>0, O10<>0, O10<>""), P10/O10, "") | S10: IS
F11: Средняя стоимость изделия | I11: ='Ялта, Ленина, 18'!I11 -> 4960 | J11: =F50 -> 4721.0784 | K11: =IF(AND(I11<>"", I11<>0, J11<>""), J11/I11, "") -> 0.95183033 | L11: =J11 -> 4721.0784 | M11: =IF(AND(I11<>"",I11<>0,L11<>"",L11<>0),L11/I11,"") -> 0.95183033 | N11: =IF(AND(J11<>0, J11<>"", I11<>0, I11<>""), L11-I11, "") -> -238.92157 | P11: =IF(AND(O11<>"", O11<>0, L11<>"", L11<>0), -O11+L11, "") | Q11: =IF(AND(P11<>"", P11<>0, O11<>0, O11<>""), P11/O11, "")
F12: Длина чека | I12: ='Ялта, Ленина, 18'!I12 -> 1.77 | J12: =J50 -> 1.8888889 | K12: =IF(AND(I12<>"", I12<>0, J12<>""), J12/I12, "") -> 1.0671689 | L12: =J12 -> 1.8888889 | M12: =IF(AND(I12<>"",I12<>0,L12<>"",L12<>0),L12/I12,"") -> 1.0671689 | N12: =IF(AND(J12<>0, J12<>"", I12<>0, I12<>""), L12-I12, "") -> 0.11888889 | P12: =IF(AND(O12<>"", O12<>0, L12<>"", L12<>0), -O12+L12, "") | Q12: =IF(AND(P12<>"", P12<>0, O12<>0, O12<>""), P12/O12, "") | S12: ='Ялта, Ленина, 18'!S12*График!AJ28/График!AJ31 -> 115789.47 | T12: =L50 -> 64232
F13: Кол-во чеков | I13: =IF(I12<>0, I9/I12, "") -> 56.891228 | J13: =G50 -> 27 | K13: =IF(AND(I13<>"", I13<>0, J13<>""), J13/I13, "") -> 0.47458986 | L13: =J13 -> 27 | M13: =IF(AND(I13<>"",I13<>0,L13<>"",L13<>0),L13/I13,"") -> 0.47458986 | N13: =IF(AND(J13<>0, J13<>"", I13<>0, I13<>""), L13-I13, "") -> -29.891228 | P13: =IF(AND(O13<>"", O13<>0, L13<>"", L13<>0), -O13+L13, "") | Q13: =IF(AND(P13<>"", P13<>0, O13<>0, O13<>""), P13/O13, "") | S13: =T12/S12 -> 0.55473091 | T13: =S13/J14*I14 -> 0.63397818
F14: Кол-во смен план/отработано | I14: =График!AI28 -> 8 | J14: 7 | K14: =IF(AND(I14<>"", I14<>0, J14<>""), J14/I14, "") -> 0.875 | L14: =I14 -> 8 | M14: =IF(AND(I14<>"",I14<>0,L14<>"",L14<>0),L14/I14,"") -> 1 | N14: =IF(AND(J14<>0, J14<>"", I14<>0, I14<>""), L14-I14, "") -> 0 | P14: =IF(AND(O14<>"", O14<>0, L14<>"", L14<>0), -O14+L14, "") | Q14: =IF(AND(P14<>"", P14<>0, O14<>0, O14<>""), P14/O14, "")
F15: Средние продажи в смену | I15: ='Ялта, Ленина, 18'!I15 -> 86270.272 | J15: =J8/J14 -> 34396.429 | K15: =IF(AND(I15<>"", I15<>0, J15<>""), J15/I15, "") -> 0.39870546 | L15: =J15 -> 34396.429 | M15: =IF(AND(I15<>"",I15<>0,L15<>"",L15<>0),L15/I15,"") -> 0.39870546 | N15: =IF(AND(J15<>0, J15<>"", I15<>0, I15<>""), L15-I15, "") -> -51873.843 | P15: =IF(AND(O15<>"", O15<>0, L15<>"", L15<>0), -O15+L15, "") | Q15: =IF(AND(P15<>"", P15<>0, O15<>0, O15<>""), P15/O15, "")
F16: Отставание/Перевыполнение | J16: =J8-I15*J14 -> -363116.9 | K16: =IF(AND(I16<>"", I16<>0, J16<>""), J16/I16, "") | L16: =J16 -> -363116.9 | M16: =IF(AND(I16<>"",I16<>0,L16<>"",L16<>0),L16/I16,"") | N16: =IF(AND(J16<>0, J16<>"", I16<>0, I16<>""), L16-I16, "") | P16: =IF(AND(O16<>"", O16<>0, L16<>"", L16<>0), -O16+L16, "") | Q16: =IF(AND(P16<>"", P16<>0, O16<>0, O16<>""), P16/O16, "") | S16: UNOde50
F17: Трафик | I17: ='Ялта, Ленина, 18'!I17/График!AJ31*График!AJ28 -> 258.59649 | J17: =I50 -> 160 | K17: =IF(AND(I17<>"", I17<>0, J17<>""), J17/I17, "") -> 0.61872456 | L17: =J17/J14*I14 -> 182.85714 | M17: =IF(AND(I17<>"",I17<>0,L17<>"",L17<>0),L17/I17,"") -> 0.70711378 | N17: =IF(AND(J17<>0, J17<>"", I17<>0, I17<>""), L17-I17, "") -> -75.739348 | P17: =IF(AND(O17<>"", O17<>0, L17<>"", L17<>0), -O17+L17, "") | Q17: =IF(AND(P17<>"", P17<>0, O17<>0, O17<>""), P17/O17, "")
