Workbook
Name маг: NA()

Sheet Ялта, Ленина, 18
B1: =TODAY()-1 -> 46171
B2: (отчетная дата)
C3: Осталось до выполнения плана!!! | I3: =График!B3 -> ул. Набережная Ленина, 18
C4: =I8-D56 -> 2009785.6 | E4: =IF(I8<>0, C4/I8, 0) -> 0.41924532
D5: =C4/(I14-J14) -> #DIV/0!
F6: Целевые показатели
F7: Показатель | I7: План | J7: Факт | K7: % выполнения | L7: Прогноз выполнения | M7: % выполнения по прогнозу | N7: Отклонение | O7: Факт аналогичного месяца прошлого года | P7: Отклонение LFL
F8: Выручка | I8: =I11*I12*I13 -> 4793817.6 | J8: =D56 -> 2784032 | K8: =IF(AND(I8<>"", I8<>0, J8<>""), J8/I8, "") -> 0.58075468 | L8: =IF(SUMIF($D$25:$D$55,">=0",$P$25:$P$55)<>0,I8*D56/SUMIF($D$25:$D$55,">=0",$P$25:$P$55),0) -> 2784032 | M8: =IF(AND(I8<>"", I8<>0, L8<>"", L8<>0), L8/I8, "") -> 0.58075468 | N8: =IF(AND(J8<>0, J8<>"", I8<>0, I8<>""), L8-I8, "") -> -2009785.6 | P8: =IF(AND(O8<>"", O8<>0, L8<>"", L8<>0), -O8+L8, "") | Q8: =IF(AND(P8<>"", P8<>0, O8<>0, O8<>""), P8/O8, "")
F9: Кол-во изделий | I9: =I8/I11 -> 921.888 | J9: =E56 -> 493 | K9: =IF(AND(I9<>"", I9<>0, J9<>""), J9/I9, "") -> 0.53477212 | L9: =IF(SUMIF($E$25:$E$55, ">=0", $Q$25:$Q$55)<>0, I9*E56/SUMIF($E$25:$E$55, ">=0", $Q$25:$Q$55), 0) -> 493 | M9: =IF(AND(I9<>"", I9<>0, L9<>"", L9<>0), L9/I9, "") -> 0.53477212 | N9: =IF(AND(J9<>0, J9<>"", I9<>0, I9<>""), L9-I9, "") -> -428.888 | O9: =O8/O11 -> #DIV/0! | P9: =IF(AND(O9<>"", O9<>0, L9<>"", L9<>0), -O9+L9, "") -> #DIV/0! | Q9: =IF(AND(P9<>"", P9<>0, O9<>0, O9<>""), P9/O9, "") -> #DIV/0!
F10: Средний чек | I10: =I11*I12 -> 10088 | J10: =H56 -> 10160.701 | K10: =IF(AND(I10<>"", I10<>0, J10<>""), J10/I10, "") -> 1.0072067 | L10: =J10 -> 10160.701 | M10: =IF(AND(I10<>"", I10<>0, L10<>"", L10<>0), L10/I10, "") -> 1.0072067 | N10: =IF(AND(J10<>0, J10<>"", I10<>0, I10<>""), L10-I10, "") -> 72.70073 | O10: =O11*O12 -> 0 | P10: =IF(AND(O10<>"", O10<>0, L10<>"", L10<>0), -O10+L10, "") | Q10: =IF(AND(P10<>"", P10<>0, O10<>0, O10<>""), P10/O10, "") | S10: IS
F11: Средняя стоимость изделия | I11: 5200 | J11: =F56 -> 5647.1237 | K11: =IF(AND(I11<>"", I11<>0, J11<>""), J11/I11, "") -> 1.0859853 | L11: =IF(L9>0, L8/L9, "") -> 5647.1237 | M11: =IF(AND(I11<>"", I11<>0, L11<>"", L11<>0), L11/I11, "") -> 1.0859853 | N11: =IF(AND(J11<>0, J11<>"", I11<>0, I11<>""), L11-I11, "") -> 447.12373 | P11: =IF(AND(O11<>"", O11<>0, L11<>"", L11<>0), -O11+L11, "") | Q11: =IF(AND(P11<>"", P11<>0, O11<>0, O11<>""), P11/O11, "")
F12: Длина чека | I12: 1.94 | J12: =J56 -> 1.7992701 | K12: =IF(AND(I12<>"", I12<>0, J12<>""), J12/I12, "") -> 0.9274588 | L12: =J12 -> 1.7992701 | M12: =IF(AND(I12<>"", I12<>0, L12<>"", L12<>0), L12/I12, "") -> 0.9274588 | N12: =IF(AND(J12<>0, J12<>"", I12<>0, I12<>""), L12-I12, "") -> -0.14072993 | P12: =IF(AND(O12<>"", O12<>0, L12<>"", L12<>0), -O12+L12, "") | Q12: =IF(AND(P12<>"", P12<>0, O12<>0, O12<>""), P12/O12, "") | S12: 680000 | T12: =L56 -> 573273
F13: Кол-во чеков | I13: =I17*I20 -> 475.2 | J13: =G56 -> 274 | K13: =IF(AND(I13<>"", I13<>0, J13<>""), J13/I13, "") -> 0.57659933 | L13: =IF(SUMIF($G$25:$G$55, ">=0", $R$25:$R$55)<>0, I13*G56/SUMIF($G$25:$G$55, ">=0", $R$25:$R$55), "") -> 274 | M13: =IF(AND(I13<>"", I13<>0, L13<>"", L13<>0), L13/I13, "") -> 0.57659933 | N13: =IF(AND(J13<>0, J13<>"", I13<>0, I13<>""), L13-I13, "") -> -201.2 | P13: =IF(AND(O13<>"", O13<>0, L13<>"", L13<>0), -O13+L13, "") | Q13: =IF(AND(P13<>"", P13<>0, O13<>0, O13<>""), P13/O13, "") | S13: =T12/S12 -> 0.84304853 | T13: =S13/J14*I14 -> 0.84304853
F14: Кол-во смен | I14: 31 | J14: 31 | K14: =IF(AND(I14<>"", I14<>0, J14<>""), J14/I14, "") -> 1 | L14: =I14 -> 31 | M14: =IF(AND(I14<>"", I14<>0, L14<>"", L14<>0), L14/I14, "") -> 1 | N14: =IF(AND(J14<>0, J14<>"", I14<>0, I14<>""), L14-I14, "") -> 0 | P14: =IF(AND(O14<>"", O14<>0, L14<>"", L14<>0), -O14+L14, "") | Q14: =IF(AND(P14<>"", P14<>0, O14<>0, O14<>""), P14/O14, "")
F15: Средние продажи в смену | I15: =I8/I14 -> 154639.28 | J15: =J8/J14 -> 89807.484 | K15: =IF(AND(I15<>"", I15<>0, J15<>""), J15/I15, "") -> 0.58075468 | L15: =J15 -> 89807.484 | M15: =IF(AND(I15<>"", I15<>0, L15<>"", L15<>0), L15/I15, "") -> 0.58075468 | N15: =IF(AND(J15<>0, J15<>"", I15<>0, I15<>""), L15-I15, "") -> -64831.794 | P15: =IF(AND(O15<>"", O15<>0, L15<>"", L15<>0), -O15+L15, "") | Q15: =IF(AND(P15<>"", P15<>0, O15<>0, O15<>""), P15/O15, "")
F16: Отставание/Перевыполнение | J16: =J8-I15*J14 -> -2009785.6 | K16: =IF(AND(I16<>"", I16<>0, J16<>""), J16/I16, "") | L16: =J16 -> -2009785.6 | M16: =IF(AND(I16<>"", I16<>0, L16<>"", L16<>0), L16/I16, "") | N16: =IF(AND(J16<>0, J16<>"", I16<>0, I16<>""), L16-I16, "") | P16: =IF(AND(O16<>"", O16<>0, L16<>"", L16<>0), -O16+L16, "") | Q16: =IF(AND(P16<>"", P16<>0, O16<>0, O16<>""), P16/O16, "") | S16: UNOde50
F17: Трафик | I17: 2160 | J17: =I56 -> 1195 | K17: =IF(AND(I17<>"", I17<>0, J17<>""), J17/I17, "") -> 0.55324074 | L17: =J17/J14*I14 -> 1195 | M17: =IF(AND(I17<>"", I17<>0, L17<>"", L17<>0), L17/I17, "") -> 0.55324074 | N17: =IF(AND(J17<>0, J17<>"", I17<>0, I17<>""), L17-I17, "") -> -965 | P17: =IF(AND(O17<>"", O17<>0, L17<>"", L17<>0), -O17+L17, "") | Q17: =IF(AND(P17<>"", P17<>0, O17<>0, O17<>""), P17/O17, "")
K18: =IF(AND(I18<>"", I18<>0, J18<>""), J18/I18, "") | L18: =J18 -> 0 | M18: =IF(AND(I18<>"", I18<>0, L18<>"", L18<>0), L18/I18, "") | N18: =IF(AND(J18<>0, J18<>"", I18<>0, I18<>""), L18-I18, "") | O18: 0 | P18: =IF(AND(O18<>"", O18<>0, L18<>"", L18<>0), -O18+L18, "") | Q18: =IF(AND(P18<>"", P18<>0, O18<>0, O18<>""), P18/O18, "") | S18: 480000 | T18: =K56 -> 535497
J19: =M56 -> 0 | K19: =IF(AND(I19<>"", I19<>0, J19<>""), J19/I19, "") | L19: =J19 -> 0 | M19: =IF(AND(I19<>"", I19<>0, L19<>"", L19<>0), L19/I19, "") | N19: =IF(AND(J19<>0, J19<>"", I19<>0, I19<>""), L19-I19, "") | O19: 0 | P19: =IF(AND(O19<>"", O19<>0, L19<>"", L19<>0), -O19+L19, "") | Q19: =IF(AND(P19<>"", P19<>0, O19<>0, O19<>""), P19/O19, "") | S19: =T18/S18 -> 1.1156188 | T19: =S19/J14*I14 -> 1.1156188
F20: Конверсия план/факт | I20: 0.22 | J20: =N56 -> 0.2292887 | K20: =J20/I20 -> 1.0422214 | L20: =IF(AND(K8<>0, I14<>0, I56<>0), (I56*N56+(I56/K8-I56)*I20)/(I56/K8), 0) -> 0.22539446 | M20: =IF(AND(I20<>"", I20<>0, L20<>"", L20<>0), L20/I20, "") -> 1.0245203 | N20: =IF(AND(J20<>0, J20<>"", I20<>0, I20<>""), L20-I20, "") -> 0.0053944577 | P20: =IF(AND(O20<>"", O20<>0, L20<>"", L20<>0), -O20+L20, "") | Q20: =IF(AND(P20<>"", P20<>0, O20<>0, O20<>""), P20/O20, "")
A22: Факт продаж за месяц | O22: % выполнения дневного плана | P22: Раcпределение плана по дням
A23: Сотрудник | B23: Дата | C23: День недели | D23: Выручка (руб) | E23: Кол-во единиц (шт.) | F23: Средняя стоимость изделия (руб.) | G23: Количество чеков (шт.) | H23: Средняя сумма чека (руб.) | I23: Трафик | J23: Длина чека (шт.) | K23: UNOde50 | L23: IS | M23: Запасной | N23: Конверсия (%) | P23: выручка, план | Q23: кол-во ед, план | R23: Кол-во чеков, план | S23: выручка, скорректир.план | T23: кол-во ед, скорр. план | U23: кол-во чеков, скорр. план | V23: Коэфф. Дня Недели | W23: Специфика месяца
B24: 1 | C24: 2 | D24: 3 | E24: 4 | F24: 5 | G24: 6 | H24: 7 | I24: 8 | J24: 9 | K24: 10 | L24: 11 | M24: 12 | N24: 13 | P24: 1 | Q24: 2 | R24: 3 | S24: 4 | T24: 5 | U24: 6 | V24: 10 | W24: 11
A25: Рогалевич, Уразгильдеева | B25: 45778 | C25: чт | D25: =104329+L25 -> 157504 | E25: 30 | F25: =IF(AND(E25<>"",E25<>0),D25/E25,"") -> 5250.1333 | G25: 19 | H25: =IF(AND(G25<>"",G25<>0),D25/G25,"") -> 8289.6842 | I25: 70 | J25: =IF(AND(G25<>"",G25<>0),E25/G25,"") -> 1.5789474 | K25: 0 | L25: 53175 | N25: =IF(AND(I25<>"",I25<>0),G25/I25,"") -> 0.27142857 | O25: =D25/P25 -> 1.1317973 | P25: =$I$8*V25*W25/SUMPRODUCT($W$25:$W$55,$V$25:$V$55) -> 139162.72 | Q25: =$I$9*V25*W25/SUMPRODUCT($W$25:$W$55,$V$25:$V$55) -> 26.762062 | R25: =IF($I$12="","",Q25/$I$12) -> 13.794877 | S25: =IF(D25<>"",D25,P25) -> 157504 | T25: =IF(E25<>"",E25,Q25) -> 30 | U25: =IF(G25<>"",G25,R25) -> 19 | V25: 0.9004852 | W25: 0.9004852
A26: Рогалевич, Уразгильдеева | B26: 45779 | C26: пт | D26: 133314 | E26: 31 | F26: =IF(AND(E26<>"",E26<>0),D26/E26,"") -> 4300.4516 | G26: 15 | H26: =IF(AND(G26<>"",G26<>0),D26/G26,"") -> 8887.6 | I26: 70 | J26: =IF(AND(G26<>"",G26<>0),E26/G26,"") -> 2.0666667 | N26: =IF(AND(I26<>"",I26<>0),G26/I26,"") -> 0.21428571 | O26: =D26/P26 -> 0.68979374 | P26: =$I$8*V26*W26/SUMPRODUCT($W$25:$W$55,$V$25:$V$55) -> 193266.47 | Q26: =$I$9*V26*W26/SUMPRODUCT($W$25:$W$55,$V$25:$V$55) -> 37.166629 | R26: =IF($I$12="","",Q26/$I$12) -> 19.158056 | S26: =IF(W26<>"",IF(D26<>"",D26,($I$8-SUM($S$25:S25))*V26*W26/SUMPRODUCT($W26:$W$55,$V26:$V$55)),"") -> 133314 | T26: =IF(W26<>"",IF(E26<>"",E26,($I$9-SUM($T$25:T25))*V26*W26/SUMPRODUCT($W26:$W$55,$V26:$V$55)),"") -> 31 | U26: =IF(W26<>"",IF($I$12<>"",IF(G26<>"",G26,($I$9/$I$12-SUM($U$25:U25))*V26*W26/SUMPRODUCT($W26:$W$55,$V26:$V$55)),""),"") -> 15 | V26: 1.0611906 | W26: 1.0611906
A27: Рогалевич, Уразгильдеева, Вафина | B27: 45780 | C27: сб | D27: =160306+L27 -> 195921 | E27: 36 | F27: =IF(AND(E27<>"",E27<>0),D27/E27,"") -> 5442.25 | G27: 21 | H27: =IF(AND(G27<>"",G27<>0),D27/G27,"") -> 9329.5714 | I27: 70 | J27: =IF(AND(G27<>"",G27<>0),E27/G27,"") -> 1.7142857 | K27: 42464 | L27: 35615 | N27: =IF(AND(I27<>"",I27<>0),G27/I27,"") -> 0.3 | O27: =D27/P27 -> 0.79515474 | P27: =$I$8*V27*W27/SUMPRODUCT($W$25:$W$55,$V$25:$V$55) -> 246393.55 | Q27: =$I$9*V27*W27/SUMPRODUCT($W$25:$W$55,$V$25:$V$55) -> 47.383375 | R27: =IF($I$12="","",Q27/$I$12) -> 24.42442 | S27: =IF(W27<>"",IF(D27<>"",D27,($I$8-SUM($S$25:S26))*V27*W27/SUMPRODUCT($W27:$W$55,$V27:$V$55)),"") -> 195921 | T27: =IF(W27<>"",IF(E27<>"",E27,($I$9-SUM($T$25:T26))*V27*W27/SUMPRODUCT($W27:$W$55,$V27:$V$55)),"") -> 36 | U27: =IF(W27<>"",IF($I$12<>"",IF(G27<>"",G27,($I$9/$I$12-SUM($U$25:U26))*V27*W27/SUMPRODUCT($W27:$W$55,$V27:$V$55)),""),"") -> 21 | V27: 1.1982013 | W27: 1.1982013
A28: Рогалевич,Вафина | B28: 45781 | C28: вс | D28: 91670 | E28: 20 | F28: =IF(AND(E28<>"",E28<>0),D28/E28,"") -> 4583.5 | G28: 9 | H28: =IF(AND(G28<>"",G28<>0),D28/G28,"") -> 10185.556 | I28: 40 | J28: =IF(AND(G28<>"",G28<>0),E28/G28,"") -> 2.2222222 | K28: 12992 | N28: =IF(AND(I28<>"",I28<>0),G28/I28,"") -> 0.225 | O28: =D28/P28 -> 0.87600559 | P28: =$I$8*V28*W28/SUMPRODUCT($W$25:$W$55,$V$25:$V$55) -> 104645.45 | Q28: =$I$9*V28*W28/SUMPRODUCT($W$25:$W$55,$V$25:$V$55) -> 20.124125 | R28: =IF($I$12="","",Q28/$I$12) -> 10.37326 | S28: =IF(W28<>"",IF(D28<>"",D28,($I$8-SUM($S$25:S27))*V28*W28/SUMPRODUCT($W28:$W$55,$V28:$V$55)),"") -> 91670 | T28: =IF(W28<>"",IF(E28<>"",E28,($I$9-SUM($T$25:T27))*V28*W28/SUMPRODUCT($W28:$W$55,$V28:$V$55)),"") -> 20 | U28: =IF(W28<>"",IF($I$12<>"",IF(G28<>"",G28,($I$9/$I$12-SUM($U$25:U27))*V28*W28/SUMPRODUCT($W28:$W$55,$V28:$V$55)),""),"") -> 9 | V28: 0.78086381 | W28: 0.78086381
A29: Рогалевич,Вафина | B29: 45782 | C29: пн | D29: 189255 | E29: 34 | F29: =IF(AND(E29<>"",E29<>0),D29/E29,"") -> 5566.3235 | G29: 13 | H29: =IF(AND(G29<>"",G29<>0),D29/G29,"") -> 14558.077 | I29: 70 | J29: =IF(AND(G29<>"",G29<>0),E29/G29,"") -> 2.6153846 | L29: 57708 | N29: =IF(AND(I29<>"",I29<>0),G29/I29,"") -> 0.18571429 | O29: =D29/P29 -> 1.0117612 | P29: =$I$8*V29*W29/SUMPRODUCT($W$25:$W$55,$V$25:$V$55) -> 187055.01 | Q29: =$I$9*V29*W29/SUMPRODUCT($W$25:$W$55,$V$25:$V$55) -> 35.972118 | R29: =IF($I$12="","",Q29/$I$12) -> 18.542329 | S29: =IF(W29<>"",IF(D29<>"",D29,($I$8-SUM($S$25:S28))*V29*W29/SUMPRODUCT($W29:$W$55,$V29:$V$55)),"") -> 189255 | T29: =IF(W29<>"",IF(E29<>"",E29,($I$9-SUM($T$25:T28))*V29*W29/SUMPRODUCT($W29:$W$55,$V29:$V$55)),"") -> 34 | U29: =IF(W29<>"",IF($I$12<>"",IF(G29<>"",G29,($I$9/$I$12-SUM($U$25:U28))*V29*W29/SUMPRODUCT($W29:$W$55,$V29:$V$55)),""),"") -> 13 | V29: 1.0439983 | W29: 1.0439983
A30: Рогалевич, Уразгильдеева | B30: 45783 | C30: вт | D30: 66218 | E30: 12 | F30: =IF(AND(E30<>"",E30<>0),D30/E30,"") -> 5518.1667 | G30: 8 | H30: =IF(AND(G30<>"",G30<>0),D30/G30,"") -> 8277.25 | I30: 40 | J30: =IF(AND(G30<>"",G30<>0),E30/G30,"") -> 1.5 | L30: 25902 | N30: =IF(AND(I30<>"",I30<>0),G30/I30,"") -> 0.2 | O30: =D30/P30 -> 0.63278431 | P30: =$I$8*V30*W30/SUMPRODUCT($W$25:$W$55,$V$25:$V$55) -> 104645.45 | Q30: =$I$9*V30*W30/SUMPRODUCT($W$25:$W$55,$V$25:$V$55) -> 20.124125 | R30: =IF($I$12="","",Q30/$I$12) -> 10.37326 | S30: =IF(W30<>"",IF(D30<>"",D30,($I$8-SUM($S$25:S29))*V30*W30/SUMPRODUCT($W30:$W$55,$V30:$V$55)),"") -> 66218 | T30: =IF(W30<>"",IF(E30<>"",E30,($I$9-SUM($T$25:T29))*V30*W30/SUMPRODUCT($W30:$W$55,$V30:$V$55)),"") -> 12 | U30: =IF(W30<>"",IF($I$12<>"",IF(G30<>"",G30,($I$9/$I$12-SUM($U$25:U29))*V30*W30/SUMPRODUCT($W30:$W$55,$V30:$V$55)),""),"") -> 8 | V30: 0.78086381 | W30: 0.78086381
A31: Рогалевич, Уразгильдеева | B31: 45784 | C31: ср | D31: 123218 | E31: 20 | F31: =IF(AND(E31<>"",E31<>0),D31/E31,"") -> 6160.9 | G31: 10 | H31: =IF(AND(G31<>"",G31<>0),D31/G31,"") -> 12321.8 | I31: 40 | J31: =IF(AND(G31<>"",G31<>0),E31/G31,"") -> 2 | K31: 45563 | L31: 24026 | N31: =IF(AND(I31<>"",I31<>0),G31/I31,"") -> 0.25 | O31: =D31/P31 -> 1.0825627 | P31: =$I$8*V31*W31/SUMPRODUCT($W$25:$W$55,$V$25:$V$55) -> 113820.66 | Q31: =$I$9*V31*W31/SUMPRODUCT($W$25:$W$55,$V$25:$V$55) -> 21.888589 | R31: =IF($I$12="","",Q31/$I$12) -> 11.282778 | S31: =IF(W31<>"",IF(D31<>"",D31,($I$8-SUM($S$25:S30))*V31*W31/SUMPRODUCT($W31:$W$55,$V31:$V$55)),"") -> 123218 | T31: =IF(W31<>"",IF(E31<>"",E31,($I$9-SUM($T$25:T30))*V31*W31/SUMPRODUCT($W31:$W$55,$V31:$V$55)),"") -> 20 | U31: =IF(W31<>"",IF($I$12<>"",IF(G31<>"",G31,($I$9/$I$12-SUM($U$25:U30))*V31*W31/SUMPRODUCT($W31:$W$55,$V31:$V$55)),""),"") -> 10 | V31: 0.81437733 | W31: 0.81437733
A32: Рогалевич,Вафина | B32: 45785 | C32: чт | D32: 91261 | E32: 20 | F32: =IF(AND(E32<>"",E32<>0),D32/E32,"") -> 4563.05 | G32: 11 | H32: =IF(AND(G32<>"",G32<>0),D32/G32,"") -> 8296.4545 | I32: 40 | J32: =IF(AND(G32<>"",G32<>0),E32/G32,"") -> 1.8181818 | K32: 11693 | L32: 8423 | N32: =IF(AND(I32<>"",I32<>0),G32/I32,"") -> 0.275 | O32: =D32/P32 -> 0.80179641 | P32: =$I$8*V32*W32/SUMPRODUCT($W$25:$W$55,$V$25:$V$55) -> 113820.66 | Q32: =$I$9*V32*W32/SUMPRODUCT($W$25:$W$55,$V$25:$V$55) -> 21.888589 | R32: =IF($I$12="","",Q32/$I$12) -> 11.282778 | S32: =IF(W32<>"",IF(D32<>"",D32,($I$8-SUM($S$25:S31))*V32*W32/SUMPRODUCT($W32:$W$55,$V32:$V$55)),"") -> 91261 | T32: =IF(W32<>"",IF(E32<>"",E32,($I$9-SUM($T$25:T31))*V32*W32/SUMPRODUCT($W32:$W$55,$V32:$V$55)),"") -> 20 | U32: =IF(W32<>"",IF($I$12<>"",IF(G32<>"",G32,($I$9/$I$12-SUM($U$25:U31))*V32*W32/SUMPRODUCT($W32:$W$55,$V32:$V$55)),""),"") -> 11 | V32: 0.81437733 | W32: 0.81437733
A33: Рогалевич,Уразгильдеева,Вафина | B33: 45786 | C33: пт | D33: =51383+106583+40551 -> 198517 | E33: 26 | F33: =IF(AND(E33<>"",E33<>0),D33/E33,"") -> 7635.2692 | G33: 11 | H33: =IF(AND(G33<>"",G33<>0),D33/G33,"") -> 18047 | I33: 60 | J33: =IF(AND(G33<>"",G33<>0),E33/G33,"") -> 2.3636364 | K33: 106583 | L33: 40551 | N33: =IF(AND(I33<>"",I33<>0),G33/I33,"") -> 0.18333333 | O33: =D33/P33 -> 1.7441209 | P33: =$I$8*V33*W33/SUMPRODUCT($W$25:$W$55,$V$25:$V$55) -> 113820.66 | Q33: =$I$9*V33*W33/SUMPRODUCT($W$25:$W$55,$V$25:$V$55) -> 21.888589 | R33: =IF($I$12="","",Q33/$I$12) -> 11.282778 | S33: =IF(W33<>"",IF(D33<>"",D33,($I$8-SUM($S$25:S32))*V33*W33/SUMPRODUCT($W33:$W$55,$V33:$V$55)),"") -> 198517 | T33: =IF(W33<>"",IF(E33<>"",E33,($I$9-SUM($T$25:T32))*V33*W33/SUMPRODUCT($W33:$W$55,$V33:$V$55)),"") -> 26 | U33: =IF(W33<>"",IF($I$12<>"",IF(G33<>"",G33,($I$9/$I$12-SUM($U$25:U32))*V33*W33/SUMPRODUCT($W33:$W$55,$V33:$V$55)),""),"") -> 11 | V33: 0.81437733 | W33: 0.81437733
A34: Рогалевич,Уразгильдеева,Вафина | B34: 45787 | C34: сб | D34: 77537 | E34: 12 | F34: =IF(AND(E34<>"",E34<>0),D34/E34,"") -> 6461.4167 | G34: 8 | H34: =IF(AND(G34<>"",G34<>0),D34/G34,"") -> 9692.125 | I34: 30 | J34: =IF(AND(G34<>"",G34<>0),E34/G34,"") -> 1.5 | L34: 42966 | N34: =IF(AND(I34<>"",I34<>0),G34/I34,"") -> 0.26666667 | O34: =D34/P34 -> 0.45179272 | P34: =$I$8*V34*W34/SUMPRODUCT($W$25:$W$55,$V$25:$V$55) -> 171620.74 | Q34: =$I$9*V34*W34/SUMPRODUCT($W$25:$W$55,$V$25:$V$55) -> 33.003988 | R34: =IF($I$12="","",Q34/$I$12) -> 17.012365 | S34: =IF(W34<>"",IF(D34<>"",D34,($I$8-SUM($S$25:S33))*V34*W34/SUMPRODUCT($W34:$W$55,$V34:$V$55)),"") -> 77537 | T34: =IF(W34<>"",IF(E34<>"",E34,($I$9-SUM($T$25:T33))*V34*W34/SUMPRODUCT($W34:$W$55,$V34:$V$55)),"") -> 12 | U34: =IF(W34<>"",IF($I$12<>"",IF(G34<>"",G34,($I$9/$I$12-SUM($U$25:U33))*V34*W34/SUMPRODUCT($W34:$W$55,$V34:$V$55)),""),"") -> 8 | V34: 1 | W34: 1
A35: Рогалевич,Уразгильдеева | B35: 45788 | C35: вс | D35: 123397 | E35: 17 | F35: =IF(AND(E35<>"",E35<>0),D35/E35,"") -> 7258.6471 | G35: 12 | H35: =IF(AND(G35<>"",G35<>0),D35/G35,"") -> 10283.083 | I35: 50 | J35: =IF(AND(G35<>"",G35<>0),E35/G35,"") -> 1.4166667 | K35: 63468 | L35: 20229 | N35: =IF(AND(I35<>"",I35<>0),G35/I35,"") -> 0.24 | O35: =D35/P35 -> 0.99516934 | P35: =$I$8*V35*W35/SUMPRODUCT($W$25:$W$55,$V$25:$V$55) -> 123995.98 | Q35: =$I$9*V35*W35/SUMPRODUCT($W$25:$W$55,$V$25:$V$55) -> 23.845381 | R35: =IF($I$12="","",Q35/$I$12) -> 12.291434 | S35: =IF(W35<>"",IF(D35<>"",D35,($I$8-SUM($S$25:S34))*V35*W35/SUMPRODUCT($W35:$W$55,$V35:$V$55)),"") -> 123397 | T35: =IF(W35<>"",IF(E35<>"",E35,($I$9-SUM($T$25:T34))*V35*W35/SUMPRODUCT($W35:$W$55,$V35:$V$55)),"") -> 17 | U35: =IF(W35<>"",IF($I$12<>"",IF(G35<>"",G35,($I$9/$I$12-SUM($U$25:U34))*V35*W35/SUMPRODUCT($W35:$W$55,$V35:$V$55)),""),"") -> 12 | V35: 0.85 | W35: 0.85
A36: Рогалевич,Вафина | B36: 45789 | C36: пн | D36: =46553+8903 -> 55456 | E36: 13 | F36: =IF(AND(E36<>"",E36<>0),D36/E36,"") -> 4265.8462 | G36: 6 | H36: =IF(AND(G36<>"",G36<>0),D36/G36,"") -> 9242.6667 | I36: 30 | J36: =IF(AND(G36<>"",G36<>0),E36/G36,"") -> 2.1666667 | L36: 8903 | N36: =IF(AND(I36<>"",I36<>0),G36/I36,"") -> 0.2 | O36: =D36/P36 -> 0.4472403 | P36: =$I$8*V36*W36/SUMPRODUCT($W$25:$W$55,$V$25:$V$55) -> 123995.98 | Q36: =$I$9*V36*W36/SUMPRODUCT($W$25:$W$55,$V$25:$V$55) -> 23.845381 | R36: =IF($I$12="","",Q36/$I$12) -> 12.291434 | S36: =IF(W36<>"",IF(D36<>"",D36,($I$8-SUM($S$25:S35))*V36*W36/SUMPRODUCT($W36:$W$55,$V36:$V$55)),"") -> 55456 | T36: =IF(W36<>"",IF(E36<>"",E36,($I$9-SUM($T$25:T35))*V36*W36/SUMPRODUCT($W36:$W$55,$V36:$V$55)),"") -> 13 | U36: =IF(W36<>"",IF($I$12<>"",IF(G36<>"",G36,($I$9/$I$12-SUM($U$25:U35))*V36*W36/SUMPRODUCT($W36:$W$55,$V36:$V$55)),""),"") -> 6 | V36: 0.85 | W36: 0.85
A37: Рогалевич,Вафина | B37: 45790 | C37: вт | D37: 46762 | E37: 2 | F37: =IF(AND(E37<>"",E37<>0),D37/E37,"") -> 23381 | G37: 3 | H37: =IF(AND(G37<>"",G37<>0),D37/G37,"") -> 15587.333 | I37: 22 | J37: =IF(AND(G37<>"",G37<>0),E37/G37,"") -> 0.66666667 | K37: 17469 | N37: =IF(AND(I37<>"",I37<>0),G37/I37,"") -> 0.13636364 | O37: =D37/P37 -> 0.37712512 | P37: =$I$8*V37*W37/SUMPRODUCT($W$25:$W$55,$V$25:$V$55) -> 123995.98 | Q37: =$I$9*V37*W37/SUMPRODUCT($W$25:$W$55,$V$25:$V$55) -> 23.845381 | R37: =IF($I$12="","",Q37/$I$12) -> 12.291434 | S37: =IF(W37<>"",IF(D37<>"",D37,($I$8-SUM($S$25:S36))*V37*W37/SUMPRODUCT($W37:$W$55,$V37:$V$55)),"") -> 46762 | T37: =IF(W37<>"",IF(E37<>"",E37,($I$9-SUM($T$25:T36))*V37*W37/SUMPRODUCT($W37:$W$55,$V37:$V$55)),"") -> 2 | U37: =IF(W37<>"",IF($I$12<>"",IF(G37<>"",G37,($I$9/$I$12-SUM($U$25:U36))*V37*W37/SUMPRODUCT($W37:$W$55,$V37:$V$55)),""),"") -> 3 | V37: 0.85 | W37: 0.85
A38: Уразгильдеева, Вафина | B38: 45791 | C38: ср | D38: =38738+67970+15403 -> 122111 | E38: 15 | F38: =IF(AND(E38<>"",E38<>0),D38/E38,"") -> 8140.7333 | G38: 8 | H38: =IF(AND(G38<>"",G38<>0),D38/G38,"") -> 15263.875 | I38: 20 | J38: =IF(AND(G38<>"",G38<>0),E38/G38,"") -> 1.875 | K38: 67970 | L38: 15403 | N38: =IF(AND(I38<>"",I38<>0),G38/I38,"") -> 0.4 | O38: =D38/P38 -> 0.98479803 | P38: =$I$8*V38*W38/SUMPRODUCT($W$25:$W$55,$V$25:$V$55) -> 123995.98 | Q38: =$I$9*V38*W38/SUMPRODUCT($W$25:$W$55,$V$25:$V$55) -> 23.845381 | R38: =IF($I$12="","",Q38/$I$12) -> 12.291434 | S38: =IF(W38<>"",IF(D38<>"",D38,($I$8-SUM($S$25:S37))*V38*W38/SUMPRODUCT($W38:$W$55,$V38:$V$55)),"") -> 122111 | T38: =IF(W38<>"",IF(E38<>"",E38,($I$9-SUM($T$25:T37))*V38*W38/SUMPRODUCT($W38:$W$55,$V38:$V$55)),"") -> 15 | U38: =IF(W38<>"",IF($I$12<>"",IF(G38<>"",G38,($I$9/$I$12-SUM($U$25:U37))*V38*W38/SUMPRODUCT($W38:$W$55,$V38:$V$55)),""),"") -> 8 | V38: 0.85 | W38: 0.85
A39: Рогалевич,Уразгильдеева | B39: 45792 | C39: чт | D39: =53662+7903 -> 61565 | E39: 17 | F39: =IF(AND(E39<>"",E39<>0),D39/E39,"") -> 3621.4706 | G39: 7 | H39: =IF(AND(G39<>"",G39<>0),D39/G39,"") -> 8795 | I39: 30 | J39: =IF(AND(G39<>"",G39<>0),E39/G39,"") -> 2.4285714 | L39: 7903 | N39: =IF(AND(I39<>"",I39<>0),G39/I39,"") -> 0.23333333 | O39: =D39/P39 -> 0.49650802 | P39: =$I$8*V39*W39/SUMPRODUCT($W$25:$W$55,$V$25:$V$55) -> 123995.98 | Q39: =$I$9*V39*W39/SUMPRODUCT($W$25:$W$55,$V$25:$V$55) -> 23.845381 | R39: =IF($I$12="","",Q39/$I$12) -> 12.291434 | S39: =IF(W39<>"",IF(D39<>"",D39,($I$8-SUM($S$25:S38))*V39*W39/SUMPRODUCT($W39:$W$55,$V39:$V$55)),"") -> 61565 | T39: =IF(W39<>"",IF(E39<>"",E39,($I$9-SUM($T$25:T38))*V39*W39/SUMPRODUCT($W39:$W$55,$V39:$V$55)),"") -> 17 | U39: =IF(W39<>"",IF($I$12<>"",IF(G39<>"",G39,($I$9/$I$12-SUM($U$25:U38))*V39*W39/SUMPRODUCT($W39:$W$55,$V39:$V$55)),""),"") -> 7 | V39: 0.85 | W39: 0.85
A40: Рогалевич,Уразгильдеева | B40: 45793 | C40: пт | D40: 82307 | E40: 11 | F40: =IF(AND(E40<>"",E40<>0),D40/E40,"") -> 7482.4545 | G40: 5 | H40: =IF(AND(G40<>"",G40<>0),D40/G40,"") -> 16461.4 | I40: 30 | J40: =IF(AND(G40<>"",G40<>0),E40/G40,"") -> 2.2 | K40: 55166 | N40: =IF(AND(I40<>"",I40<>0),G40/I40,"") -> 0.16666667 | O40: =D40/P40 -> 0.47958657 | P40: =$I$8*V40*W40/SUMPRODUCT($W$25:$W$55,$V$25:$V$55) -> 171620.74 | Q40: =$I$9*V40*W40/SUMPRODUCT($W$25:$W$55,$V$25:$V$55) -> 33.003988 | R40: =IF($I$12="","",Q40/$I$12) -> 17.012365 | S40: =IF(W40<>"",IF(D40<>"",D40,($I$8-SUM($S$25:S39))*V40*W40/SUMPRODUCT($W40:$W$55,$V40:$V$55)),"") -> 82307 | T40: =IF(W40<>"",IF(E40<>"",E40,($I$9-SUM($T$25:T39))*V40*W40/SUMPRODUCT($W40:$W$55,$V40:$V$55)),"") -> 11 | U40: =IF(W40<>"",IF($I$12<>"",IF(G40<>"",G40,($I$9/$I$12-SUM($U$25:U39))*V40*W40/SUMPRODUCT($W40:$W$55,$V40:$V$55)),""),"") -> 5 | V40: 1 | W40: 1
A41: Рогалевич,Вафина | B41: 45794 | C41: сб | D41: 41508 | E41: 11 | F41: =IF(AND(E41<>"",E41<>0),D41/E41,"") -> 3773.4545 | G41: 6 | H41: =IF(AND(G41<>"",G41<>0),D41/G41,"") -> 6918 | I41: 50 | J41: =IF(AND(G41<>"",G41<>0),E41/G41,"") -> 1.8333333 | K41: 5493 | N41: =IF(AND(I41<>"",I41<>0),G41/I41,"") -> 0.12 | O41: =D41/P41 -> 0.19988338 | P41: =$I$8*V41*W41/SUMPRODUCT($W$25:$W$55,$V$25:$V$55) -> 207661.09 | Q41: =$I$9*V41*W41/SUMPRODUCT($W$25:$W$55,$V$25:$V$55) -> 39.934825 | R41: =IF($I$12="","",Q41/$I$12) -> 20.584962 | S41: =IF(W41<>"",IF(D41<>"",D41,($I$8-SUM($S$25:S40))*V41*W41/SUMPRODUCT($W41:$W$55,$V41:$V$55)),"") -> 41508 | T41: =IF(W41<>"",IF(E41<>"",E41,($I$9-SUM($T$25:T40))*V41*W41/SUMPRODUCT($W41:$W$55,$V41:$V$55)),"") -> 11 | U41: =IF(W41<>"",IF($I$12<>"",IF(G41<>"",G41,($I$9/$I$12-SUM($U$25:U40))*V41*W41/SUMPRODUCT($W41:$W$55,$V41:$V$55)),""),"") -> 6 | V41: 1.1 | W41: 1.1
...

Sheet Св. по пок.
A2: Показатель | D2: ='Ялта, Ленина, 18'!I3 -> ул. Набережная Ленина, 18 | G2: =График!B29 -> Рогалевич Ирина | J2: =График!B28 -> Уразгильдеева Екатерина | M2: =График!B27 -> Вафина Ляйсан
D3: Факт | F3: Прогноз | G3: Факт | I3: Прогноз | J3: Факт | L3: Прогноз | M3: Факт | O3: Прогноз
A4: Выручка | D4: ='Ялта, Ленина, 18'!K8 -> 0.58075468 | E4: ='Ялта, Ленина, 18'!J8 -> 2784032 | F4: ='Ялта, Ленина, 18'!M8 -> 0.58075468 | G4: ='Рогалевич И. Е.'!K8 -> 0.72556134 | H4: ='Рогалевич И. Е.'!J8 -> 1358537 | I4: ='Рогалевич И. Е.'!M8 -> 0.75339644 | J4: ='Уразгильдеева Е. Р.'!K8 -> 0.4785407 | K4: ='Уразгильдеева Е. Р.'!J8 -> 717981 | L4: ='Уразгильдеева Е. Р.'!M8 -> 0.4785407 | M4: ='Вафина Л. Ф.'!K8 -> 0.49787481 | N4: ='Вафина Л. Ф.'!J8 -> 707514 | O4: ='Вафина Л. Ф.'!M8 -> 0.52642268
A5: Кол-во изделий | D5: ='Ялта, Ленина, 18'!K9 -> 0.53477212 | E5: ='Ялта, Ленина, 18'!J9 -> 493 | F5: ='Ялта, Ленина, 18'!M9 -> 0.53477212 | G5: ='Рогалевич И. Е.'!K9 -> 0.63319993 | H5: ='Рогалевич И. Е.'!J9 -> 228 | I5: ='Рогалевич И. Е.'!M9 -> 0.68372169 | J5: ='Уразгильдеева Е. Р.'!K9 -> 0.46442338 | K5: ='Уразгильдеева Е. Р.'!J9 -> 134 | L5: ='Уразгильдеева Е. Р.'!M9 -> 0.46442338 | M5: ='Вафина Л. Ф.'!K9 -> 0.48301698 | N5: ='Вафина Л. Ф.'!J9 -> 132 | O5: ='Вафина Л. Ф.'!M9 -> 0.48301698
A6: Средний чек | D6: ='Ялта, Ленина, 18'!K10 -> 1.0072067 | E6: ='Ялта, Ленина, 18'!J10 -> 10160.701 | F6: ='Ялта, Ленина, 18'!M10 -> 1.0072067 | G6: ='Рогалевич И. Е.'!K10 -> 1.0603828 | H6: ='Рогалевич И. Е.'!J10 -> 10697.142 | I6: ='Рогалевич И. Е.'!M10 -> 1.0603828 | J6: ='Уразгильдеева Е. Р.'!K10 -> 0.88964735 | K6: ='Уразгильдеева Е. Р.'!J10 -> 8974.7625 | L6: ='Уразгильдеева Е. Р.'!M10 -> 0.88964735 | M6: ='Вафина Л. Ф.'!K10 -> 1.016438 | N6: ='Вафина Л. Ф.'!J10 -> 10253.826 | O6: ='Вафина Л. Ф.'!M10 -> 1.016438
A7: Средняя стоимость изделия | D7: ='Ялта, Ленина, 18'!K11 -> 1.0859853 | E7: ='Ялта, Ленина, 18'!J11 -> 5647.1237 | F7: ='Ялта, Ленина, 18'!M11 -> 1.0859853 | G7: ='Рогалевич И. Е.'!K11 -> 1.1458645 | H7: ='Рогалевич И. Е.'!J11 -> 5958.4956 | I7: ='Рогалевич И. Е.'!M11 -> 1.1019051 | J7: ='Уразгильдеева Е. Р.'!K11 -> 1.0303975 | K7: ='Уразгильдеева Е. Р.'!J11 -> 5358.0672 | L7: ='Уразгильдеева Е. Р.'!M11 -> 1.0303975 | M7: ='Вафина Л. Ф.'!K11 -> 1.0307605 | N7: ='Вафина Л. Ф.'!J11 -> 5359.9545 | O7: ='Вафина Л. Ф.'!M11 -> 1.0898637
A8: Длина чека | D8: ='Ялта, Ленина, 18'!K12 -> 0.9274588 | E8: ='Ялта, Ленина, 18'!J12 -> 1.7992701 | F8: ='Ялта, Ленина, 18'!M12 -> 0.9274588 | G8: ='Рогалевич И. Е.'!K12 -> 0.92539979 | H8: ='Рогалевич И. Е.'!J12 -> 1.7952756 | I8: ='Рогалевич И. Е.'!M12 -> 0.92539979 | J8: ='Уразгильдеева Е. Р.'!K12 -> 0.86340206 | K8: ='Уразгильдеева Е. Р.'!J12 -> 1.675 | L8: ='Уразгильдеева Е. Р.'!M12 -> 0.86340206 | M8: ='Вафина Л. Ф.'!K12 -> 0.98610489 | N8: ='Вафина Л. Ф.'!J12 -> 1.9130435 | O8: ='Вафина Л. Ф.'!M12 -> 0.98610489
A9: Кол-во чеков | D9: ='Ялта, Ленина, 18'!K13 -> 0.57659933 | E9: ='Ялта, Ленина, 18'!J13 -> 274 | F9: ='Ялта, Ленина, 18'!M13 -> 0.57659933 | G9: ='Рогалевич И. Е.'!K13 -> 0.68424473 | H9: ='Рогалевич И. Е.'!J13 -> 127 | I9: ='Рогалевич И. Е.'!M13 -> 0.73883925 | J9: ='Уразгильдеева Е. Р.'!K13 -> 0.53789932 | K9: ='Уразгильдеева Е. Р.'!J13 -> 80 | L9: ='Уразгильдеева Е. Р.'!M13 -> 0.53789932 | M9: ='Вафина Л. Ф.'!K13 -> 0.48982312 | N9: ='Вафина Л. Ф.'!J13 -> 69 | O9: ='Вафина Л. Ф.'!M13 -> 0.48982312
A10: Кол-во смен план/отработано | D10: ='Ялта, Ленина, 18'!K14 -> 1 | E10: ='Ялта, Ленина, 18'!J14 -> 31 | G10: ='Рогалевич И. Е.'!K14 -> 1 | H10: ='Рогалевич И. Е.'!J14 -> 28 | J10: ='Уразгильдеева Е. Р.'!K14 -> 1 | K10: ='Уразгильдеева Е. Р.'!J14 -> 20 | M10: ='Вафина Л. Ф.'!K14 -> 1 | N10: ='Вафина Л. Ф.'!J14 -> 19
A11: Средние продажи в смену | D11: ='Ялта, Ленина, 18'!K15 -> 0.58075468 | E11: ='Ялта, Ленина, 18'!J15 -> 89807.484 | F11: ='Ялта, Ленина, 18'!M15 -> 0.58075468 | G11: ='Рогалевич И. Е.'!K15 -> 0.31375715 | H11: ='Рогалевич И. Е.'!J15 -> 48519.179 | I11: ='Рогалевич И. Е.'!M15 -> 0.31375715 | J11: ='Уразгильдеева Е. Р.'!K15 -> 0.23214704 | K11: ='Уразгильдеева Е. Р.'!J15 -> 35899.05 | L11: ='Уразгильдеева Е. Р.'!M15 -> 0.23214704 | M11: ='Вафина Л. Ф.'!K15 -> 0.24080285 | N11: ='Вафина Л. Ф.'!J15 -> 37237.579 | O11: ='Вафина Л. Ф.'!M15 -> 0.24080285
A12: Трафик | D12: ='Ялта, Ленина, 18'!K17 -> 0.55324074 | E12: ='Ялта, Ленина, 18'!J17 -> 1195 | F12: ='Ялта, Ленина, 18'!M17 -> 0.55324074 | G12: ='Рогалевич И. Е.'!K17 -> 0.61872964 | H12: ='Рогалевич И. Е.'!J17 -> 522 | I12: ='Рогалевич И. Е.'!M17 -> 0.61872964 | J12: ='Уразгильдеева Е. Р.'!K17 -> 0.5310411 | K12: ='Уразгильдеева Е. Р.'!J17 -> 359 | L12: ='Уразгильдеева Е. Р.'!M17 -> 0.5310411 | M12: ='Вафина Л. Ф.'!K17 -> 0.48882928 | N12: ='Вафина Л. Ф.'!J17 -> 313 | O12: ='Вафина Л. Ф.'!M17 -> 0.48882928
A13: UNOde50 | D13: ='Ялта, Ленина, 18'!S19 -> 1.1156188 | E13: ='Ялта, Ленина, 18'!T18 -> 535497 | F13: ='Ялта, Ленина, 18'!T19 -> 1.1156188 | G13: ='Рогалевич И. Е.'!S19 -> 1.3200064 | H13: ='Рогалевич И. Е.'!T18 -> 247476 | I13: ='Рогалевич И. Е.'!T19 -> 1.3200064 | J13: ='Уразгильдеева Е. Р.'!S19 -> 0.98598135 | K13: ='Уразгильдеева Е. Р.'!T18 -> 148123 | L13: ='Уразгильдеева Е. Р.'!T19 -> 0.98598135 | M13: ='Вафина Л. Ф.'!S19 -> 0.85346078 | N13: ='Вафина Л. Ф.'!T18 -> 121439 | O13: ='Вафина Л. Ф.'!T19 -> 0.85346078
A14: IS | D14: ='Ялта, Ленина, 18'!S13 -> 0.84304853 | E14: ='Ялта, Ленина, 18'!T12 -> 573273 | F14: ='Ялта, Ленина, 18'!T13 -> 0.84304853 | G14: ='Рогалевич И. Е.'!S13 -> 1.0983443 | H14: ='Рогалевич И. Е.'!T12 -> 291718 | I14: ='Рогалевич И. Е.'!T13 -> 1.0983443 | J14: ='Уразгильдеева Е. Р.'!S13 -> 0.60182941 | K14: ='Уразгильдеева Е. Р.'!T12 -> 128084 | L14: ='Уразгильдеева Е. Р.'!T13 -> 0.60182941 | M14: ='Вафина Л. Ф.'!S13 -> 0.76134944 | N14: ='Вафина Л. Ф.'!T12 -> 153471 | O14: ='Вафина Л. Ф.'!T13 -> 0.76134944
A15: Отклонение от плана | D15: ='Ялта, Ленина, 18'!J16 -> -2009785.6 | G15: ='Рогалевич И. Е.'!N8 -> -461739.13 | J15: ='Уразгильдеева Е. Р.'!N8 -> -782374.13 | M15: ='Вафина Л. Ф.'!N8 -> -672985.6
A37: Показатель | D37: ='Ялта, Ленина, 18'!I38 -> 20 | G37: =График!#REF! -> #REF! | J37: =График!#REF! -> #REF! | M37: =График!#REF! -> #REF!
D38: Факт | F38: Прогноз | G38: Факт | I38: Прогноз | J38: Факт | L38: Прогноз | M38: Факт | O38: Прогноз
A39: Выручка | D39: ='Ялта, Ленина, 18'!K43 -> 0 | E39: ='Ялта, Ленина, 18'!J43 -> 2 | F39: ='Ялта, Ленина, 18'!M43 -> 0 | G39: ='Рогалевич И. Е.'!K43 -> 0 | H39: ='Рогалевич И. Е.'!J43 -> 1.3333333 | I39: ='Рогалевич И. Е.'!M43 -> 0 | J39: ='Уразгильдеева Е. Р.'!K43 -> 0 | K39: ='Уразгильдеева Е. Р.'!J43 -> 1.5 | L39: ='Уразгильдеева Е. Р.'!M43 -> 0 | M39: ='Вафина Л. Ф.'!K43 -> 0 | N39: ='Вафина Л. Ф.'!J43 -> 1 | O39: ='Вафина Л. Ф.'!M43 -> 0
A40: Кол-во изделий | D40: ='Ялта, Ленина, 18'!K44 -> 0 | E40: ='Ялта, Ленина, 18'!J44 -> 2 | F40: ='Ялта, Ленина, 18'!M44 -> 0 | G40: ='Рогалевич И. Е.'!K44 -> 0 | H40: ='Рогалевич И. Е.'!J44 -> 1.5 | I40: ='Рогалевич И. Е.'!M44 -> 0 | J40: ='Уразгильдеева Е. Р.'!K44 -> 16991 | K40: ='Уразгильдеева Е. Р.'!J44 -> 1.8333333 | L40: ='Уразгильдеева Е. Р.'!M44 -> 0 | M40: ='Вафина Л. Ф.'!K44 -> 0 | N40: ='Вафина Л. Ф.'!J44 | O40: ='Вафина Л. Ф.'!M44 -> 0
A41: Средний чек | D41: ='Ялта, Ленина, 18'!K45 -> 0 | E41: ='Ялта, Ленина, 18'!J45 -> 1.3333333 | F41: ='Ялта, Ленина, 18'!M45 -> 0 | G41: ='Рогалевич И. Е.'!K45 -> 0 | H41: ='Рогалевич И. Е.'!J45 -> 1 | I41: ='Рогалевич И. Е.'!M45 -> 0 | J41: ='Уразгильдеева Е. Р.'!K45 -> 0 | K41: ='Уразгильдеева Е. Р.'!J45 | L41: ='Уразгильдеева Е. Р.'!M45 -> 0 | M41: ='Вафина Л. Ф.'!K45 -> 0 | N41: ='Вафина Л. Ф.'!J45 -> 1 | O41: ='Вафина Л. Ф.'!M45 -> 0
A42: Средняя стоимость изделия | D42: ='Ялта, Ленина, 18'!K46 -> 0 | E42: ='Ялта, Ленина, 18'!J46 -> 2 | F42: ='Ялта, Ленина, 18'!M46 -> 0 | G42: ='Рогалевич И. Е.'!K46 -> 25684 | H42: ='Рогалевич И. Е.'!J46 -> 1.6 | I42: ='Рогалевич И. Е.'!M46 -> 0 | J42: ='Уразгильдеева Е. Р.'!K46 -> 0 | K42: ='Уразгильдеева Е. Р.'!J46 | L42: ='Уразгильдеева Е. Р.'!M46 -> 0 | M42: ='Вафина Л. Ф.'!K46 -> 0 | N42: ='Вафина Л. Ф.'!J46 -> 2 | O42: ='Вафина Л. Ф.'!M46 -> 0
A43: Длина чека | D43: ='Ялта, Ленина, 18'!K47 -> 0 | E43: ='Ялта, Ленина, 18'!J47 -> 1 | F43: ='Ялта, Ленина, 18'!M47 -> 0 | G43: ='Рогалевич И. Е.'!K47 -> 8993 | H43: ='Рогалевич И. Е.'!J47 -> 1 | I43: ='Рогалевич И. Е.'!M47 -> 0 | J43: ='Уразгильдеева Е. Р.'!K47 -> 0 | K43: ='Уразгильдеева Е. Р.'!J47 | L43: ='Уразгильдеева Е. Р.'!M47 -> 0 | M43: ='Вафина Л. Ф.'!K47 -> 0 | N43: ='Вафина Л. Ф.'!J47 -> 2 | O43: ='Вафина Л. Ф.'!M47 -> 0
A44: Кол-во чеков | D44: ='Ялта, Ленина, 18'!K48 -> 25684 | E44: ='Ялта, Ленина, 18'!J48 -> 1.5384615 | F44: ='Ялта, Ленина, 18'!M48 -> 0 | G44: ='Рогалевич И. Е.'!K48 -> 31985 | H44: ='Рогалевич И. Е.'!J48 -> 1.5714286 | I44: ='Рогалевич И. Е.'!M48 -> 0 | J44: ='Уразгильдеева Е. Р.'!K48 -> 0 | K44: ='Уразгильдеева Е. Р.'!J48 | L44: ='Уразгильдеева Е. Р.'!M48 -> 0 | M44: ='Вафина Л. Ф.'!K48 -> 121439 | N44: ='Вафина Л. Ф.'!J48 -> 1.9130435 | O44: ='Вафина Л. Ф.'!M48 -> 0
A45: Кол-во смен план/отработано | D45: ='Ялта, Ленина, 18'!K49 -> 8993 | E45: ='Ялта, Ленина, 18'!J49 -> 1 | G45: ='Рогалевич И. Е.'!K49 -> 0 | H45: ='Рогалевич И. Е.'!J49 -> 2 | J45: ='Уразгильдеева Е. Р.'!K49 -> 0 | K45: ='Уразгильдеева Е. Р.'!J49 -> 3 | M45: ='Вафина Л. Ф.'!K49 -> 0 | N45: ='Вафина Л. Ф.'!J49 -> 0
A46: Средние продажи в смену | D46: ='Ялта, Ленина, 18'!K50 -> 0 | E46: ='Ялта, Ленина, 18'!J50 -> 1.25 | F46: ='Ялта, Ленина, 18'!M50 -> 0 | G46: ='Рогалевич И. Е.'!K50 -> 0 | H46: ='Рогалевич И. Е.'!J50 -> 2.4 | I46: ='Рогалевич И. Е.'!M50 -> 0 | J46: ='Уразгильдеева Е. Р.'!K50 -> 148123 | K46: ='Уразгильдеева Е. Р.'!J50 -> 1.675 | L46: ='Уразгильдеева Е. Р.'!M50 -> 0 | M46: ='Вафина Л. Ф.'!K50 -> 0 | N46: ='Вафина Л. Ф.'!J50 -> 0 | O46: ='Вафина Л. Ф.'!M50 -> 0
A47: Трафик | D47: ='Ялта, Ленина, 18'!K52 -> 0 | E47: ='Ялта, Ленина, 18'!J52 -> 1.4 | F47: ='Ялта, Ленина, 18'!M52 -> 0 | G47: ='Рогалевич И. Е.'!K52 -> 0 | H47: ='Рогалевич И. Е.'!J52 -> 1.6666667 | I47: ='Рогалевич И. Е.'!M52 -> 0 | J47: ='Уразгильдеева Е. Р.'!K52 -> 0 | K47: ='Уразгильдеева Е. Р.'!J52 -> 0 | L47: ='Уразгильдеева Е. Р.'!M52 -> 0 | M47: ='Вафина Л. Ф.'!K52 -> 0 | N47: ='Вафина Л. Ф.'!J52 -> 0 | O47: ='Вафина Л. Ф.'!M52 -> 0
A48: UNOde50 | D48: ='Ялта, Ленина, 18'!S54 -> 66874 | E48: ='Ялта, Ленина, 18'!T53 -> 18 | F48: ='Ялта, Ленина, 18'!T54 -> 16 | G48: ='Рогалевич И. Е.'!S54 -> 1872394.4 | H48: ='Рогалевич И. Е.'!T53 -> 136.07585 | I48: ='Рогалевич И. Е.'!T54 -> 224 | J48: ='Уразгильдеева Е. Р.'!S54 -> 0 | K48: ='Уразгильдеева Е. Р.'!T53 -> 0 | L48: ='Уразгильдеева Е. Р.'!T54 -> 0 | M48: ='Вафина Л. Ф.'!S54 -> 0 | N48: ='Вафина Л. Ф.'!T53 -> 0 | O48: ='Вафина Л. Ф.'!T54 -> 0
A49: IS | D49: ='Ялта, Ленина, 18'!S48 -> 123588 | E49: ='Ялта, Ленина, 18'!T47 -> 4 | F49: ='Ялта, Ленина, 18'!T48 -> 20 | G49: ='Рогалевич И. Е.'!S48 -> 93287 | H49: ='Рогалевич И. Е.'!T47 -> 4 | I49: ='Рогалевич И. Е.'!T48 -> 11 | J49: ='Уразгильдеева Е. Р.'!S48 | K49: ='Уразгильдеева Е. Р.'!T47 | L49: ='Уразгильдеева Е. Р.'!T48 | M49: ='Вафина Л. Ф.'!S48 -> 659093 | N49: ='Вафина Л. Ф.'!T47 | O49: ='Вафина Л. Ф.'!T48 -> 127
A50: Отклонение от плана | D50: ='Ялта, Ленина, 18'!J51 -> 1.7777778 | G50: ='Рогалевич И. Е.'!N43 -> 0.4 | J50: ='Уразгильдеева Е. Р.'!N43 -> 0.35294118 | M50: ='Вафина Л. Ф.'!N43 -> 0.15

Sheet План на день
A1: Выручка | D1: 207661
A2: Кол-во изделий | D2: =D1/D4 -> 39.934808
A3: Средний чек | D3: =D4*D5 -> 10088
A4: Средняя стоимость изделия | D4: ='Ялта, Ленина, 18'!I11 -> 5200
A5: Длина чека | D5: ='Ялта, Ленина, 18'!I12 -> 1.94
A6: Кол-во чеков | D6: =IF(D5<>0,D2/D5,"") -> 20.584952
A7: Конверсия | D7: ='Ялта, Ленина, 18'!I20 -> 0.22
A8: IS | D8: =('Ялта, Ленина, 18'!S12-'Ялта, Ленина, 18'!T12)/('Ялта, Ленина, 18'!I14-'Ялта, Ленина, 18'!J14) -> #DIV/0!
A9: UNOde50 | D9: =('Ялта, Ленина, 18'!S18-'Ялта, Ленина, 18'!T18)/('Ялта, Ленина, 18'!I14-'Ялта, Ленина, 18'!J14) -> #DIV/0!

Sheet Рогалевич И. Е.
B1: =TODAY()-1 -> 46171
B2: (отчетная дата) | J2: ЕЖЕДНЕВНЫЙ ОТЧЕТ О ПРОДАЖАХ
B3: Осталось до выполнения плана!!! | J3: =График!B29 -> Рогалевич Ирина
C4: =I8-D54 -> 513857.41 | E4: =IF(I8<>0,C4/I8,0) -> 0.27443866
F6: Целевые показатели
F7: Показатель | I7: План | J7: Факт | K7: % выполнения | L7: Прогноз выполнения | M7: % выполнения по прогнозу | N7: Отклонение | O7: Факт аналогичного месяца прошлого года | P7: Отклонение LFL
F8: Выручка | I8: ='Ялта, Ленина, 18'!I8/График!AJ31*График!AJ29 -> 1872394.4 | J8: =D54 -> 1358537 | K8: =IF(AND(I8<>"",I8<>0,J8<>""),J8/I8,"") -> 0.72556134 | L8: =IF(SUMIF($D$25:$D$53,">=0",$P$25:$P$53)<>0,I8*D54/SUMIF($D$25:$D$53,">=0",$P$25:$P$53),0) -> 1410655.3 | M8: =IF(AND(I8<>"",I8<>0,L8<>"",L8<>0),L8/I8,"") -> 0.75339644 | N8: =IF(AND(J8<>0,J8<>"",I8<>0,I8<>""),L8-I8,"") -> -461739.13 | P8: =IF(AND(O8<>"",O8<>0,L8<>"",L8<>0),-O8+L8,"") | Q8: =IF(AND(P8<>"",P8<>0,O8<>0,O8<>""),P8/O8,"")
F9: Кол-во изделий | I9: =I8/I11 -> 360.07585 | J9: =E54 -> 228 | K9: =IF(AND(I9<>"",I9<>0,J9<>""),J9/I9,"") -> 0.63319993 | L9: =IF(SUMIF($E$25:$E$51,">=0",$Q$25:$Q$51)<>0,I9*E54/SUMIF($E$25:$E$51,">=0",$Q$25:$Q$51),0) -> 246.19167 | M9: =IF(AND(I9<>"",I9<>0,L9<>"",L9<>0),L9/I9,"") -> 0.68372169 | N9: =IF(AND(J9<>0,J9<>"",I9<>0,I9<>""),L9-I9,"") -> -113.88418 | O9: =O8/O11 -> #DIV/0! | P9: =IF(AND(O9<>"",O9<>0,L9<>"",L9<>0),-O9+L9,"") -> #DIV/0! | Q9: =IF(AND(P9<>"",P9<>0,O9<>0,O9<>""),P9/O9,"") -> #DIV/0!
F10: Средний чек | I10: =I11*I12 -> 10088 | J10: =H54 -> 10697.142 | K10: =IF(AND(I10<>"",I10<>0,J10<>""),J10/I10,"") -> 1.0603828 | L10: =J10 -> 10697.142 | M10: =IF(AND(I10<>"",I10<>0,L10<>"",L10<>0),L10/I10,"") -> 1.0603828 | N10: =IF(AND(J10<>0,J10<>"",I10<>0,I10<>""),L10-I10,"") -> 609.14173 | O10: =O11*O12 -> 0 | P10: =IF(AND(O10<>"",O10<>0,L10<>"",L10<>0),-O10+L10,"") | Q10: =IF(AND(P10<>"",P10<>0,O10<>0,O10<>""),P10/O10,"") | S10: IS
F11: Средняя стоимость изделия | I11: ='Ялта, Ленина, 18'!I11 -> 5200 | J11: =F54 -> 5958.4956 | K11: =IF(AND(I11<>"",I11<>0,J11<>""),J11/I11,"") -> 1.1458645 | L11: =IF(L9>0,L8/L9,"") -> 5729.9067 | M11: =IF(AND(I11<>"",I11<>0,L11<>"",L11<>0),L11/I11,"") -> 1.1019051 | N11: =IF(AND(J11<>0,J11<>"",I11<>0,I11<>""),L11-I11,"") -> 529.90669 | P11: =IF(AND(O11<>"",O11<>0,L11<>"",L11<>0),-O11+L11,"") | Q11: =IF(AND(P11<>"",P11<>0,O11<>0,O11<>""),P11/O11,"")
F12: Длина чека | I12: ='Ялта, Ленина, 18'!I12 -> 1.94 | J12: =J54 -> 1.7952756 | K12: =IF(AND(I12<>"",I12<>0,J12<>""),J12/I12,"") -> 0.92539979 | L12: =J12 -> 1.7952756 | M12: =IF(AND(I12<>"",I12<>0,L12<>"",L12<>0),L12/I12,"") -> 0.92539979 | N12: =IF(AND(J12<>0,J12<>"",I12<>0,I12<>""),L12-I12,"") -> -0.14472441 | P12: =IF(AND(O12<>"",O12<>0,L12<>"",L12<>0),-O12+L12,"") | Q12: =IF(AND(P12<>"",P12<>0,O12<>0,O12<>""),P12/O12,"") | S12: ='Ялта, Ленина, 18'!S12*График!AJ29/График!AJ31 -> 265597.96 | T12: =L54 -> 291718
F13: Кол-во чеков | I13: =IF(I12<>0,I9/I12,"") -> 185.60611 | J13: =G54 -> 127 | K13: =IF(AND(I13<>"",I13<>0,J13<>""),J13/I13,"") -> 0.68424473 | L13: =IF(SUMIF($G$25:$G$51,">=0",$R$25:$R$51)<>0,I13*G54/SUMIF($G$25:$G$51,">=0",$R$25:$R$51),"") -> 137.13308 | M13: =IF(AND(I13<>"",I13<>0,L13<>"",L13<>0),L13/I13,"") -> 0.73883925 | N13: =IF(AND(J13<>0,J13<>"",I13<>0,I13<>""),L13-I13,"") -> -48.47303 | P13: =IF(AND(O13<>"",O13<>0,L13<>"",L13<>0),-O13+L13,"") | Q13: =IF(AND(P13<>"",P13<>0,O13<>0,O13<>""),P13/O13,"") | S13: =T12/S12 -> 1.0983443 | T13: =S13/J14*I14 -> 1.0983443
F14: Кол-во смен план/отработано | I14: =График!AI29 -> 28 | J14: 28 | K14: =IF(AND(I14<>"",I14<>0,J14<>""),J14/I14,"") -> 1 | L14: =I14 -> 28 | M14: =IF(AND(I14<>"",I14<>0,L14<>"",L14<>0),L14/I14,"") -> 1 | N14: =IF(AND(J14<>0,J14<>"",I14<>0,I14<>""),L14-I14,"") -> 0 | P14: =IF(AND(O14<>"",O14<>0,L14<>"",L14<>0),-O14+L14,"") | Q14: =IF(AND(P14<>"",P14<>0,O14<>0,O14<>""),P14/O14,"")
F15: Средние продажи в смену | I15: ='Ялта, Ленина, 18'!I15 -> 154639.28 | J15: =J8/J14 -> 48519.179 | K15: =IF(AND(I15<>"",I15<>0,J15<>""),J15/I15,"") -> 0.31375715 | L15: =J15 -> 48519.179 | M15: =IF(AND(I15<>"",I15<>0,L15<>"",L15<>0),L15/I15,"") -> 0.31375715 | N15: =IF(AND(J15<>0,J15<>"",I15<>0,I15<>""),L15-I15,"") -> -106120.1 | P15: =IF(AND(O15<>"",O15<>0,L15<>"",L15<>0),-O15+L15,"") | Q15: =IF(AND(P15<>"",P15<>0,O15<>0,O15<>""),P15/O15,"")
F16: Отставание/Перевыполнение | J16: =J8-I15*J14 -> -2971362.8 | K16: =IF(AND(I16<>"",I16<>0,J16<>""),J16/I16,"") | L16: =J16 -> -2971362.8 | M16: =IF(AND(I16<>"",I16<>0,L16<>"",L16<>0),L16/I16,"") | N16: =IF(AND(J16<>0,J16<>"",I16<>0,I16<>""),L16-I16,"") | P16: =IF(AND(O16<>"",O16<>0,L16<>"",L16<>0),-O16+L16,"") | Q16: =IF(AND(P16<>"",P16<>0,O16<>0,O16<>""),P16/O16,"") | S16: UNOde50
F17: Трафик | I17: ='Ялта, Ленина, 18'!I17/График!AJ31*График!AJ29 -> 843.66412 | J17: =I54 -> 522 | K17: =IF(AND(I17<>"",I17<>0,J17<>""),J17/I17,"") -> 0.61872964 | L17: =J17/J14*I14 -> 522 | M17: =IF(AND(I17<>"",I17<>0,L17<>"",L17<>0),L17/I17,"") -> 0.61872964 | N17: =IF(AND(J17<>0,J17<>"",I17<>0,I17<>""),L17-I17,"") -> -321.66412 | P17: =IF(AND(O17<>"",O17<>0,L17<>"",L17<>0),-O17+L17,"") | Q17: =IF(AND(P17<>"",P17<>0,O17<>0,O17<>""),P17/O17,"")
K18: =IF(AND(I18<>"",I18<>0,J18<>""),J18/I18,"") | L18: =J18 -> 0 | M18: =IF(AND(I18<>"",I18<>0,L18<>"",L18<>0),L18/I18,"") | N18: =IF(AND(J18<>0,J18<>"",I18<>0,I18<>""),L18-I18,"") | O18: 0 | P18: =IF(AND(O18<>"",O18<>0,L18<>"",L18<>0),-O18+L18,"") | Q18: =IF(AND(P18<>"",P18<>0,O18<>0,O18<>""),P18/O18,"") | S18: ='Ялта, Ленина, 18'!S18*График!AJ29/График!AJ31 -> 187480.92 | T18: =K54 -> 247476
J19: =M54 -> 0 | K19: =IF(AND(I19<>"",I19<>0,J19<>""),J19/I19,"") | L19: =J19 -> 0 | M19: =IF(AND(I19<>"",I19<>0,L19<>"",L19<>0),L19/I19,"") | N19: =IF(AND(J19<>0,J19<>"",I19<>0,I19<>""),L19-I19,"") | O19: 0 | P19: =IF(AND(O19<>"",O19<>0,L19<>"",L19<>0),-O19+L19,"") | Q19: =IF(AND(P19<>"",P19<>0,O19<>0,O19<>""),P19/O19,"") | S19: =T18/S18 -> 1.3200064 | T19: =S19/J14*I14 -> 1.3200064
F20: Конверсия план/факт | I20: ='Ялта, Ленина, 18'!I20 -> 0.22 | J20: =N54 -> 0.24329502 | K20: =J20/I20 -> 1.1058865 | L20: =IF(AND(K8<>0,I14<>0,I54<>0),(I54*N54+(I54/K8-I54)*I20)/(I54/K8),0) -> 0.23690197 | M20: =IF(AND(I20<>"",I20<>0,L20<>"",L20<>0),L20/I20,"") -> 1.0768271 | N20: =IF(AND(J20<>0,J20<>"",I20<>0,I20<>""),L20-I20,"") -> 0.016901965 | P20: =IF(AND(O20<>"",O20<>0,L20<>"",L20<>0),-O20+L20,"") | Q20: =IF(AND(P20<>"",P20<>0,O20<>0,O20<>""),P20/O20,"")
B22: Факт продаж за месяц | O22: % выполнения дневного плана | P22: Раcпределение плана по дням
B23: Дата | C23: День недели | D23: Выручка (руб) | E23: Кол-во единиц (шт.) | F23: Средняя стоимость изделия (руб.) | G23: Количество чеков (шт.) | H23: Средняя сумма чека (руб.) | I23: Трафик | J23: Длина чека (шт.) | K23: UNOde50 | L23: IS | M23: Запасной | N23: Конверсия (%) | P23: выручка, план | Q23: кол-во ед, план | R23: Кол-во чеков, план | S23: выручка, скорректир.план | T23: кол-во ед, скорр. план | U23: кол-во чеков, скорр. план | V23: Коэфф. Дня Недели | W23: Специфика месяца
B24: 1 | C24: 2 | D24: 3 | E24: 4 | F24: 5 | G24: 6 | H24: 7 | I24: 8 | J24: 9 | K24: 10 | L24: 11 | M24: 12 | N24: 13 | P24: 1 | Q24: 2 | R24: 3 | S24: 4 | T24: 5 | U24: 6 | V24: 10 | W24: 11
A25: 1 | B25: 45778 | C25: чт | D25: =83582+L25 -> 125351 | E25: 23 | F25: =IF(AND(E25<>"",E25<>0),D25/E25,"") -> 5450.0435 | G25: 14 | H25: =IF(AND(G25<>"",G25<>0),D25/G25,"") -> 8953.6429 | I25: 35 | J25: =IF(AND(G25<>"",G25<>0),E25/G25,"") -> 1.6428571 | K25: 0 | L25: =53175-11406 -> 41769 | N25: =IF(AND(I25<>"",I25<>0),G25/I25,"") -> 0.4 | O25: =D25/P25 -> 2.2346432 | P25: =$I$8*V25*W25/SUMPRODUCT($W$25:$W$55,$V$25:$V$55) -> 56094.414 | Q25: =$I$9*V25*W25/SUMPRODUCT($W$25:$W$55,$V$25:$V$55) -> 10.787387 | R25: =IF($I$12="","",Q25/$I$12) -> 5.5605089 | S25: =IF(D25<>"",D25,P25) -> 125351 | T25: =IF(E25<>"",E25,Q25) -> 23 | U25: =IF(G25<>"",G25,R25) -> 14 | V25: 0.9004852 | W25: 0.9004852
A26: 2 | B26: 45779 | C26: пт | D26: 88513 | E26: 20 | F26: =IF(AND(E26<>"",E26<>0),D26/E26,"") -> 4425.65 | G26: 8 | H26: =IF(AND(G26<>"",G26<>0),D26/G26,"") -> 11064.125 | I26: 35 | J26: =IF(AND(G26<>"",G26<>0),E26/G26,"") -> 2.5 | N26: =IF(AND(I26<>"",I26<>0),G26/I26,"") -> 0.22857143 | O26: =D26/P26 -> 1.1361975 | P26: =$I$8*V26*W26/SUMPRODUCT($W$25:$W$55,$V$25:$V$55) -> 77902.826 | Q26: =$I$9*V26*W26/SUMPRODUCT($W$25:$W$55,$V$25:$V$55) -> 14.981313 | R26: =IF($I$12="","",Q26/$I$12) -> 7.7223261 | S26: =IF(W26<>"",IF(D26<>"",D26,($I$8-SUM($S$25:S25))*V26*W26/SUMPRODUCT($W26:$W$55,$V26:$V$55)),"") -> 88513 | T26: =IF(W26<>"",IF(E26<>"",E26,($I$9-SUM($T$25:T25))*V26*W26/SUMPRODUCT($W26:$W$55,$V26:$V$55)),"") -> 20 | U26: =IF(W26<>"",IF($I$12<>"",IF(G26<>"",G26,($I$9/$I$12-SUM($U$25:U25))*V26*W26/SUMPRODUCT($W26:$W$55,$V26:$V$55)),""),"") -> 8 | V26: 1.0611906 | W26: 1.0611906
A27: 3 | B27: 45780 | C27: сб | D27: 99865 | E27: 16 | F27: =IF(AND(E27<>"",E27<>0),D27/E27,"") -> 6241.5625 | G27: 10 | H27: =IF(AND(G27<>"",G27<>0),D27/G27,"") -> 9986.5 | I27: 23 | J27: =IF(AND(G27<>"",G27<>0),E27/G27,"") -> 1.6 | K27: 31972 | L27: =5803+8903 -> 14706 | N27: =IF(AND(I27<>"",I27<>0),G27/I27,"") -> 0.43478261 | O27: =D27/P27 -> 2.3675341 | P27: =$I$8*V27*W27/SUMPRODUCT($W$25:$W$55,$V$25:$V$55) -> 42181.018 | Q27: =$I$9*V27*W27/SUMPRODUCT($W$25:$W$55,$V$25:$V$55) -> 8.1117342 | R27: =IF($I$12="","",Q27/$I$12) -> 4.1813063 | S27: =IF(W27<>"",IF(D27<>"",D27,($I$8-SUM($S$25:S26))*V27*W27/SUMPRODUCT($W27:$W$55,$V27:$V$55)),"") -> 99865 | T27: =IF(W27<>"",IF(E27<>"",E27,($I$9-SUM($T$25:T26))*V27*W27/SUMPRODUCT($W27:$W$55,$V27:$V$55)),"") -> 16 | U27: =IF(W27<>"",IF($I$12<>"",IF(G27<>"",G27,($I$9/$I$12-SUM($U$25:U26))*V27*W27/SUMPRODUCT($W27:$W$55,$V27:$V$55)),""),"") -> 10 | V27: 0.78086381 | W27: 0.78086381
A28: 4 | B28: 45781 | C28: вс | D28: 46148 | E28: 11 | F28: =IF(AND(E28<>"",E28<>0),D28/E28,"") -> 4195.2727 | G28: 6 | H28: =IF(AND(G28<>"",G28<>0),D28/G28,"") -> 7691.3333 | I28: 20 | J28: =IF(AND(G28<>"",G28<>0),E28/G28,"") -> 1.8333333 | N28: =IF(AND(I28<>"",I28<>0),G28/I28,"") -> 0.3 | O28: =D28/P28 -> 0.6120499 | P28: =$I$8*V28*W28/SUMPRODUCT($W$25:$W$55,$V$25:$V$55) -> 75399.081 | Q28: =$I$9*V28*W28/SUMPRODUCT($W$25:$W$55,$V$25:$V$55) -> 14.499823 | R28: =IF($I$12="","",Q28/$I$12) -> 7.4741357 | S28: =IF(W28<>"",IF(D28<>"",D28,($I$8-SUM($S$25:S27))*V28*W28/SUMPRODUCT($W28:$W$55,$V28:$V$55)),"") -> 46148 | T28: =IF(W28<>"",IF(E28<>"",E28,($I$9-SUM($T$25:T27))*V28*W28/SUMPRODUCT($W28:$W$55,$V28:$V$55)),"") -> 11 | U28: =IF(W28<>"",IF($I$12<>"",IF(G28<>"",G28,($I$9/$I$12-SUM($U$25:U27))*V28*W28/SUMPRODUCT($W28:$W$55,$V28:$V$55)),""),"") -> 6 | V28: 1.0439983 | W28: 1.0439983
A29: 5 | B29: 45782 | C29: пн | D29: =51615+47305 -> 98920 | E29: 16 | F29: =IF(AND(E29<>"",E29<>0),D29/E29,"") -> 6182.5 | G29: 6 | H29: =IF(AND(G29<>"",G29<>0),D29/G29,"") -> 16486.667 | I29: 35 | J29: =IF(AND(G29<>"",G29<>0),E29/G29,"") -> 2.6666667 | L29: 47305 | N29: =IF(AND(I29<>"",I29<>0),G29/I29,"") -> 0.17142857 | O29: =D29/P29 -> 2.3451307 | P29: =$I$8*V29*W29/SUMPRODUCT($W$25:$W$55,$V$25:$V$55) -> 42181.018 | Q29: =$I$9*V29*W29/SUMPRODUCT($W$25:$W$55,$V$25:$V$55) -> 8.1117342 | R29: =IF($I$12="","",Q29/$I$12) -> 4.1813063 | S29: =IF(W29<>"",IF(D29<>"",D29,($I$8-SUM($S$25:S28))*V29*W29/SUMPRODUCT($W29:$W$55,$V29:$V$55)),"") -> 98920 | T29: =IF(W29<>"",IF(E29<>"",E29,($I$9-SUM($T$25:T28))*V29*W29/SUMPRODUCT($W29:$W$55,$V29:$V$55)),"") -> 16 | U29: =IF(W29<>"",IF($I$12<>"",IF(G29<>"",G29,($I$9/$I$12-SUM($U$25:U28))*V29*W29/SUMPRODUCT($W29:$W$55,$V29:$V$55)),""),"") -> 6 | V29: 0.78086381 | W29: 0.78086381
A30: 6 | B30: 45783 | C30: вт | D30: =24394+25902 -> 50296 | E30: 8 | F30: =IF(AND(E30<>"",E30<>0),D30/E30,"") -> 6287 | G30: 6 | H30: =IF(AND(G30<>"",G30<>0),D30/G30,"") -> 8382.6667 | I30: 20 | J30: =IF(AND(G30<>"",G30<>0),E30/G30,"") -> 1.3333333 | L30: 25902 | N30: =IF(AND(I30<>"",I30<>0),G30/I30,"") -> 0.3 | O30: =D30/P30 -> 1.0962652 | P30: =$I$8*V30*W30/SUMPRODUCT($W$25:$W$55,$V$25:$V$55) -> 45879.409 | Q30: =$I$9*V30*W30/SUMPRODUCT($W$25:$W$55,$V$25:$V$55) -> 8.8229633 | R30: =IF($I$12="","",Q30/$I$12) -> 4.5479192 | S30: =IF(W30<>"",IF(D30<>"",D30,($I$8-SUM($S$25:S29))*V30*W30/SUMPRODUCT($W30:$W$55,$V30:$V$55)),"") -> 50296 | T30: =IF(W30<>"",IF(E30<>"",E30,($I$9-SUM($T$25:T29))*V30*W30/SUMPRODUCT($W30:$W$55,$V30:$V$55)),"") -> 8 | U30: =IF(W30<>"",IF($I$12<>"",IF(G30<>"",G30,($I$9/$I$12-SUM($U$25:U29))*V30*W30/SUMPRODUCT($W30:$W$55,$V30:$V$55)),""),"") -> 6 | V30: 0.81437733 | W30: 0.81437733
A31: 7 | B31: 45784 | C31: ср | D31: 64709 | E31: 7 | F31: 9244 | G31: 4 | H31: =IF(AND(G31<>"",G31<>0),D31/G31,"") -> 16177.25 | I31: 20 | J31: =IF(AND(G31<>"",G31<>0),E31/G31,"") -> 1.75 | K31: 45563 | L31: 10623 | N31: =IF(AND(I31<>"",I31<>0),G31/I31,"") -> 0.2 | O31: =D31/P31 -> 1.4104149 | P31: =$I$8*V31*W31/SUMPRODUCT($W$25:$W$55,$V$25:$V$55) -> 45879.409 | Q31: =$I$9*V31*W31/SUMPRODUCT($W$25:$W$55,$V$25:$V$55) -> 8.8229633 | R31: =IF($I$12="","",Q31/$I$12) -> 4.5479192 | S31: =IF(W31<>"",IF(D31<>"",D31,($I$8-SUM($S$25:S30))*V31*W31/SUMPRODUCT($W31:$W$55,$V31:$V$55)),"") -> 64709 | T31: =IF(W31<>"",IF(E31<>"",E31,($I$9-SUM($T$25:T30))*V31*W31/SUMPRODUCT($W31:$W$55,$V31:$V$55)),"") -> 7 | U31: =IF(W31<>"",IF($I$12<>"",IF(G31<>"",G31,($I$9/$I$12-SUM($U$25:U30))*V31*W31/SUMPRODUCT($W31:$W$55,$V31:$V$55)),""),"") -> 4 | V31: 0.81437733 | W31: 0.81437733
A32: 8 | B32: 45785 | C32: чт | D32: =35423+11693+8423 -> 55539 | E32: 11 | F32: =IF(AND(E32<>"",E32<>0),D32/E32,"") -> 5049 | G32: 6 | H32: =IF(AND(G32<>"",G32<>0),D32/G32,"") -> 9256.5 | I32: 20 | J32: =IF(AND(G32<>"",G32<>0),E32/G32,"") -> 1.8333333 | K32: 11693 | L32: 8423 | N32: =IF(AND(I32<>"",I32<>0),G32/I32,"") -> 0.3 | O32: =D32/P32 -> 1.2105431 | P32: =$I$8*V32*W32/SUMPRODUCT($W$25:$W$55,$V$25:$V$55) -> 45879.409 | Q32: =$I$9*V32*W32/SUMPRODUCT($W$25:$W$55,$V$25:$V$55) -> 8.8229633 | R32: =IF($I$12="","",Q32/$I$12) -> 4.5479192 | S32: =IF(W32<>"",IF(D32<>"",D32,($I$8-SUM($S$25:S31))*V32*W32/SUMPRODUCT($W32:$W$55,$V32:$V$55)),"") -> 55539 | T32: =IF(W32<>"",IF(E32<>"",E32,($I$9-SUM($T$25:T31))*V32*W32/SUMPRODUCT($W32:$W$55,$V32:$V$55)),"") -> 11 | U32: =IF(W32<>"",IF($I$12<>"",IF(G32<>"",G32,($I$9/$I$12-SUM($U$25:U31))*V32*W32/SUMPRODUCT($W32:$W$55,$V32:$V$55)),""),"") -> 6 | V32: 0.81437733 | W32: 0.81437733
A33: 9 | B33: 45786 | C33: пт | D33: =3792+61609+12724 -> 78125 | E33: 6 | F33: =IF(AND(E33<>"",E33<>0),D33/E33,"") -> 13020.833 | G33: 4 | H33: =IF(AND(G33<>"",G33<>0),D33/G33,"") -> 19531.25 | I33: 20 | J33: =IF(AND(G33<>"",G33<>0),E33/G33,"") -> 1.5 | K33: 61609 | L33: 12724 | N33: =IF(AND(I33<>"",I33<>0),G33/I33,"") -> 0.2 | O33: =D33/P33 -> 1.129337 | P33: =$I$8*V33*W33/SUMPRODUCT($W$25:$W$55,$V$25:$V$55) -> 69177.755 | Q33: =$I$9*V33*W33/SUMPRODUCT($W$25:$W$55,$V$25:$V$55) -> 13.303414 | R33: =IF($I$12="","",Q33/$I$12) -> 6.8574301 | S33: =IF(W33<>"",IF(D33<>"",D33,($I$8-SUM($S$25:S32))*V33*W33/SUMPRODUCT($W33:$W$55,$V33:$V$55)),"") -> 78125 | T33: =IF(W33<>"",IF(E33<>"",E33,($I$9-SUM($T$25:T32))*V33*W33/SUMPRODUCT($W33:$W$55,$V33:$V$55)),"") -> 6 | U33: =IF(W33<>"",IF($I$12<>"",IF(G33<>"",G33,($I$9/$I$12-SUM($U$25:U32))*V33*W33/SUMPRODUCT($W33:$W$55,$V33:$V$55)),""),"") -> 4 | V33: 1 | W33: 1
A34: 10 | B34: 45787 | C34: сб | D34: =7739+31843 -> 39582 | E34: 3 | F34: =IF(AND(E34<>"",E34<>0),D34/E34,"") -> 13194 | G34: 3 | H34: =IF(AND(G34<>"",G34<>0),D34/G34,"") -> 13194 | I34: 10 | J34: =IF(AND(G34<>"",G34<>0),E34/G34,"") -> 1 | L34: 31843 | N34: =IF(AND(I34<>"",I34<>0),G34/I34,"") -> 0.3 | O34: =D34/P34 -> 0.93838418 | P34: =$I$8*V34*W34/SUMPRODUCT($W$25:$W$55,$V$25:$V$55) -> 42181.018 | Q34: =$I$9*V34*W34/SUMPRODUCT($W$25:$W$55,$V$25:$V$55) -> 8.1117342 | R34: =IF($I$12="","",Q34/$I$12) -> 4.1813063 | S34: =IF(W34<>"",IF(D34<>"",D34,($I$8-SUM($S$25:S33))*V34*W34/SUMPRODUCT($W34:$W$55,$V34:$V$55)),"") -> 39582 | T34: =IF(W34<>"",IF(E34<>"",E34,($I$9-SUM($T$25:T33))*V34*W34/SUMPRODUCT($W34:$W$55,$V34:$V$55)),"") -> 3 | U34: =IF(W34<>"",IF($I$12<>"",IF(G34<>"",G34,($I$9/$I$12-SUM($U$25:U33))*V34*W34/SUMPRODUCT($W34:$W$55,$V34:$V$55)),""),"") -> 3 | V34: 0.78086381 | W34: 0.78086381
A35: 11 | B35: 45788 | C35: вс | D35: =18549+24484+6203 -> 49236 | E35: 7 | F35: =IF(AND(E35<>"",E35<>0),D35/E35,"") -> 7033.7143 | G35: 4 | H35: =IF(AND(G35<>"",G35<>0),D35/G35,"") -> 12309 | I35: 25 | J35: =IF(AND(G35<>"",G35<>0),E35/G35,"") -> 1.75 | K35: 24484 | L35: 6203 | N35: =IF(AND(I35<>"",I35<>0),G35/I35,"") -> 0.16 | O35: =D35/P35 -> 1.1672549 | P35: =$I$8*V35*W35/SUMPRODUCT($W$25:$W$55,$V$25:$V$55) -> 42181.018 | Q35: =$I$9*V35*W35/SUMPRODUCT($W$25:$W$55,$V$25:$V$55) -> 8.1117342 | R35: =IF($I$12="","",Q35/$I$12) -> 4.1813063 | S35: =IF(W35<>"",IF(D35<>"",D35,($I$8-SUM($S$25:S34))*V35*W35/SUMPRODUCT($W35:$W$55,$V35:$V$55)),"") -> 49236 | T35: =IF(W35<>"",IF(E34<>"",E34,($I$9-SUM($T$25:T34))*V35*W35/SUMPRODUCT($W35:$W$55,$V35:$V$55)),"") -> 3 | U35: =IF(W35<>"",IF($I$12<>"",IF(G35<>"",G35,($I$9/$I$12-SUM($U$25:U34))*V35*W35/SUMPRODUCT($W35:$W$55,$V35:$V$55)),""),"") -> 4 | V35: 0.78086381 | W35: 0.78086381
A36: 12 | B36: 45789 | C36: пн | D36: =30795+8903 -> 39698 | E36: 8 | F36: =IF(AND(E36<>"",E36<>0),D36/E36,"") -> 4962.25 | G36: 3 | H36: =IF(AND(G36<>"",G36<>0),D36/G36,"") -> 13232.667 | I36: 15 | J36: =IF(AND(G36<>"",G36<>0),E36/G36,"") -> 2.6666667 | L36: 8903 | N36: =IF(AND(I36<>"",I36<>0),G36/I36,"") -> 0.2 | O36: =D36/P36 -> 0.94113424 | P36: =$I$8*V36*W36/SUMPRODUCT($W$25:$W$55,$V$25:$V$55) -> 42181.018 | Q36: =$I$9*V36*W36/SUMPRODUCT($W$25:$W$55,$V$25:$V$55) -> 8.1117342 | R36: =IF($I$12="","",Q36/$I$12) -> 4.1813063 | S36: =IF(W36<>"",IF(D36<>"",D36,($I$8-SUM($S$25:S35))*V36*W36/SUMPRODUCT($W36:$W$55,$V36:$V$55)),"") -> 39698 | T36: =IF(W36<>"",IF(E36<>"",E36,($I$9-SUM($T$25:T35))*V36*W36/SUMPRODUCT($W36:$W$55,$V36:$V$55)),"") -> 8 | U36: =IF(W36<>"",IF($I$12<>"",IF(G36<>"",G36,($I$9/$I$12-SUM($U$25:U35))*V36*W36/SUMPRODUCT($W36:$W$55,$V36:$V$55)),""),"") -> 3 | V36: 0.78086381 | W36: 0.78086381
A37: 13 | B37: 45790 | C37: вт | D37: 46762 | E37: 2 | F37: =IF(AND(E37<>"",E37<>0),D37/E37,"") -> 23381 | G37: 3 | H37: =IF(AND(G37<>"",G37<>0),D37/G37,"") -> 15587.333 | I37: 11 | J37: =IF(AND(G37<>"",G37<>0),E37/G37,"") -> 0.66666667 | N37: =IF(AND(I37<>"",I37<>0),G37/I37,"") -> 0.27272727 | O37: =D37/P37 -> 0.70978307 | P37: =$I$8*V37*W37/SUMPRODUCT($W$25:$W$55,$V$25:$V$55) -> 65882.101 | Q37: =$I$9*V37*W37/SUMPRODUCT($W$25:$W$55,$V$25:$V$55) -> 12.669635 | R37: =IF($I$12="","",Q37/$I$12) -> 6.5307396 | S37: =IF(W37<>"",IF(D37<>"",D37,($I$8-SUM($S$25:S36))*V37*W37/SUMPRODUCT($W37:$W$55,$V37:$V$55)),"") -> 46762 | T37: =IF(W37<>"",IF(E37<>"",E37,($I$9-SUM($T$25:T36))*V37*W37/SUMPRODUCT($W37:$W$55,$V37:$V$55)),"") -> 2 | U37: =IF(W37<>"",IF($I$12<>"",IF(G37<>"",G37,($I$9/$I$12-SUM($U$25:U36))*V37*W37/SUMPRODUCT($W37:$W$55,$V37:$V$55)),""),"") -> 3 | V37: 0.97588915 | W37: 0.97588915
A38: 14 | B38: 45792 | C38: чт | D38: 19949 | E38: 6 | F38: =IF(AND(E38<>"",E38<>0),D38/E38,"") -> 3324.8333 | G38: 3 | H38: =IF(AND(G38<>"",G38<>0),D38/G38,"") -> 6649.6667 | I38: 15 | J38: =IF(AND(G38<>"",G38<>0),E38/G38,"") -> 2 | N38: =IF(AND(I38<>"",I38<>0),G38/I38,"") -> 0.2 | O38: =D38/P38 -> 0.30279848 | P38: =$I$8*V38*W38/SUMPRODUCT($W$25:$W$55,$V$25:$V$55) -> 65882.101 | Q38: =$I$9*V38*W38/SUMPRODUCT($W$25:$W$55,$V$25:$V$55) -> 12.669635 | R38: =IF($I$12="","",Q38/$I$12) -> 6.5307396 | S38: =IF(W38<>"",IF(D38<>"",D38,($I$8-SUM($S$25:S37))*V38*W38/SUMPRODUCT($W38:$W$55,$V38:$V$55)),"") -> 19949 | T38: =IF(W38<>"",IF(E38<>"",E38,($I$9-SUM($T$25:T37))*V38*W38/SUMPRODUCT($W38:$W$55,$V38:$V$55)),"") -> 6 | U38: =IF(W38<>"",IF($I$12<>"",IF(G38<>"",G38,($I$9/$I$12-SUM($U$25:U37))*V38*W38/SUMPRODUCT($W38:$W$55,$V38:$V$55)),""),"") -> 3 | V38: 0.97588915 | W38: 0.97588915
A39: 13 | B39: 45793 | C39: пт | D39: 15866 | E39: 4 | F39: =IF(AND(E39<>"",E39<>0),D39/E39,"") -> 3966.5 | G39: 2 | H39: =IF(AND(G39<>"",G39<>0),D39/G39,"") -> 7933 | I39: 15 | J39: =IF(AND(G39<>"",G39<>0),E39/G39,"") -> 2 | N39: =IF(AND(I39<>"",I39<>0),G39/I39,"") -> 0.13333333 | O39: =D39/P39 -> 0.24082414 | P39: =$I$8*V39*W39/SUMPRODUCT($W$25:$W$55,$V$25:$V$55) -> 65882.101 | Q39: =$I$9*V39*W39/SUMPRODUCT($W$25:$W$55,$V$25:$V$55) -> 12.669635 | R39: =IF($I$12="","",Q39/$I$12) -> 6.5307396 | S39: =IF(W39<>"",IF(D39<>"",D39,($I$8-SUM($S$25:S38))*V39*W39/SUMPRODUCT($W39:$W$55,$V39:$V$55)),"") -> 15866 | T39: =IF(W39<>"",IF(E39<>"",E39,($I$9-SUM($T$25:T38))*V39*W39/SUMPRODUCT($W39:$W$55,$V39:$V$55)),"") -> 4 | U39: =IF(W39<>"",IF($I$12<>"",IF(G39<>"",G39,($I$9/$I$12-SUM($U$25:U38))*V39*W39/SUMPRODUCT($W39:$W$55,$V39:$V$55)),""),"") -> 2 | V39: 0.97588915 | W39: 0.97588915
A40: 13 | B40: 45794 | C40: сб | D40: =5083+5493 -> 10576 | E40: 3 | F40: =IF(AND(E40<>"",E40<>0),D40/E40,"") -> 3525.3333 | G40: 2 | H40: =IF(AND(G40<>"",G40<>0),D40/G40,"") -> 5288 | I40: 25 | J40: =IF(AND(G40<>"",G40<>0),E40/G40,"") -> 1.5 | K40: 5493 | N40: =IF(AND(I40<>"",I40<>0),G40/I40,"") -> 0.08 | O40: =D40/P40 -> 0.16052919 | P40: =$I$8*V40*W40/SUMPRODUCT($W$25:$W$55,$V$25:$V$55) -> 65882.101 | Q40: =$I$9*V40*W40/SUMPRODUCT($W$25:$W$55,$V$25:$V$55) -> 12.669635 | R40: =IF($I$12="","",Q40/$I$12) -> 6.5307396 | S40: =IF(W40<>"",IF(D40<>"",D40,($I$8-SUM($S$25:S39))*V40*W40/SUMPRODUCT($W40:$W$55,$V40:$V$55)),"") -> 10576 | T40: =IF(W40<>"",IF(E40<>"",E40,($I$9-SUM($T$25:T39))*V40*W40/SUMPRODUCT($W40:$W$55,$V40:$V$55)),"") -> 3 | U40: =IF(W40<>"",IF($I$12<>"",IF(G40<>"",G40,($I$9/$I$12-SUM($U$25:U39))*V40*W40/SUMPRODUCT($W40:$W$55,$V40:$V$55)),""),"") -> 2 | V40: 0.97588915 | W40: 0.97588915
A41: 17 | B41: 45795 | C41: вс | D41: =29229+5501 -> 34730 | E41: 7 | F41: =IF(AND(E41<>"",E41<>0),D41/E41,"") -> 4961.4286 | G41: 4 | H41: =IF(AND(G41<>"",G41<>0),D41/G41,"") -> 8682.5 | I41: 17 | J41: =IF(AND(G41<>"",G41<>0),E41/G41,"") -> 1.75 | L41: 5501 | N41: =IF(AND(I41<>"",I41<>0),G41/I41,"") -> 0.23529412 | O41: =D41/P41 -> 0.36419123 | P41: =$I$8*V41*W41/SUMPRODUCT($W$25:$W$55,$V$25:$V$55) -> 95361.99 | Q41: =$I$9*V41*W41/SUMPRODUCT($W$25:$W$55,$V$25:$V$55) -> 18.338844 | R41: =IF($I$12="","",Q41/$I$12) -> 9.4530125 | S41: =IF(W41<>"",IF(D41<>"",D41,($I$8-SUM($S$25:S40))*V41*W41/SUMPRODUCT($W41:$W$55,$V41:$V$55)),"") -> 34730 | T41: =IF(W41<>"",IF(E41<>"",E41,($I$9-SUM($T$25:T40))*V41*W41/SUMPRODUCT($W41:$W$55,$V41:$V$55)),"") -> 7 | U41: =IF(W41<>"",IF($I$12<>"",IF(G41<>"",G41,($I$9/$I$12-SUM($U$25:U40))*V41*W41/SUMPRODUCT($W41:$W$55,$V41:$V$55)),""),"") -> 4 | V41: 1.1740982 | W41: 1.1740982
A42: 18 | B42: 45797 | C42: вт | D42: 24248 | E42: 6 | F42: =IF(AND(E42<>"",E42<>0),D42/E42,"") -> 4041.3333 | G42: 2 | H42: =IF(AND(G42<>"",G42<>0),D42/G42,"") -> 12124 | I42: 7 | J42: =IF(AND(G42<>"",G42<>0),E42/G42,"") -> 3 | N42: =IF(AND(I42<>"",I42<>0),G42/I42,"") -> 0.28571429 | O42: =D42/P42 -> 0.25427322 | P42: =$I$8*V42*W42/SUMPRODUCT($W$25:$W$55,$V$25:$V$55) -> 95361.99 | Q42: =$I$9*V42*W42/SUMPRODUCT($W$25:$W$55,$V$25:$V$55) -> 18.338844 | R42: =IF($I$12="","",Q42/$I$12) -> 9.4530125 | S42: =IF(W42<>"",IF(D42<>"",D42,($I$8-SUM($S$25:S41))*V42*W42/SUMPRODUCT($W42:$W$55,$V42:$V$55)),"") -> 24248 | T42: =IF(W42<>"",IF(E42<>"",E42,($I$9-SUM($T$25:T41))*V42*W42/SUMPRODUCT($W42:$W$55,$V42:$V$55)),"") -> 6 | U42: =IF(W42<>"",IF($I$12<>"",IF(G42<>"",G42,($I$9/$I$12-SUM($U$25:U41))*V42*W42/SUMPRODUCT($W42:$W$55,$V42:$V$55)),""),"") -> 2 | V42: 1.1740982 | W42: 1.1740982
...

Sheet Уразгильдеева Е. Р.
B1: =TODAY()-1 -> 46171
B2: (отчетная дата) | J2: ЕЖЕДНЕВНЫЙ ОТЧЕТ О ПРОДАЖАХ
B3: Осталось до выполнения плана!!! | J3: =График!B28 -> Уразгильдеева Екатерина
C4: =I8-D50 -> 782374.13 | E4: =IF(I8<>0, C4/I8, 0) -> 0.5214593
F6: Целевые показатели
F7: Показатель | I7: План | J7: Факт | K7: % выполнения | L7: Прогноз выполнения | M7: % выполнения по прогнозу | N7: Отклонение | O7: Факт аналогичного месяца прошлого года | P7: Отклонение LFL
F8: Выручка | I8: ='Ялта, Ленина, 18'!I8/График!AJ31*График!AJ28 -> 1500355.1 | J8: =D50 -> 717981 | K8: =J8/I8 -> 0.4785407 | L8: =IF(SUMIF($D$25:$D$49,">=0",$P$25:$P$49)<>0,I8*D50/SUMIF($D$25:$D$49,">=0",$P$25:$P$49),0) -> 717981 | M8: =IF(AND(I8<>"",I8<>0,L8<>"",L8<>0),L8/I8,"") -> 0.4785407 | N8: =IF(AND(J8<>0, J8<>"", I8<>0, I8<>""), L8-I8, "") -> -782374.13 | P8: =IF(AND(O8<>"", O8<>0, L8<>"", L8<>0), -O8+L8, "") | Q8: =IF(AND(P8<>"", P8<>0, O8<>0, O8<>""), P8/O8, "")
F9: Кол-во изделий | I9: =I8/I11 -> 288.52983 | J9: =E50 -> 134 | K9: =IF(AND(I9<>"", I9<>0, J9<>""), J9/I9, "") -> 0.46442338 | L9: =J9 -> 134 | M9: =IF(AND(I9<>"",I9<>0,L9<>"",L9<>0),L9/I9,"") -> 0.46442338 | N9: =IF(AND(J9<>0, J9<>"", I9<>0, I9<>""), L9-I9, "") -> -154.52983 | O9: =O8/O11 -> #DIV/0! | P9: =IF(AND(O9<>"", O9<>0, L9<>"", L9<>0), -O9+L9, "") -> #DIV/0! | Q9: =IF(AND(P9<>"", P9<>0, O9<>0, O9<>""), P9/O9, "") -> #DIV/0!
F10: Средний чек | I10: =I11*I12 -> 10088 | J10: =H50 -> 8974.7625 | K10: =IF(AND(I10<>"", I10<>0, J10<>""), J10/I10, "") -> 0.88964735 | L10: =J10 -> 8974.7625 | M10: =IF(AND(I10<>"",I10<>0,L10<>"",L10<>0),L10/I10,"") -> 0.88964735 | N10: =IF(AND(J10<>0, J10<>"", I10<>0, I10<>""), L10-I10, "") -> -1113.2375 | O10: =O11*O12 -> 0 | P10: =IF(AND(O10<>"", O10<>0, L10<>"", L10<>0), -O10+L10, "") | Q10: =IF(AND(P10<>"", P10<>0, O10<>0, O10<>""), P10/O10, "") | S10: IS
