Workbook
Name маг: NA()

Sheet Ялта, Ленина, 18
B1: =TODAY()-1 -> 46000
B2: (отчетная дата)
C3: Осталось до выполнения плана!!! | I3: =График!B3 -> ул. Набережная Ленина, 18
C4: =I8-D56 -> 946704 | E4: =IF(I8<>0, C4/I8, 0) -> 0.45815278
D5: =C4/(I14-J14) -> #DIV/0!
F6: Целевые показатели
F7: Показатель | I7: План | J7: Факт | K7: % выполнения | L7: Прогноз выполнения | M7: % выполнения по прогнозу | N7: Отклонение | O7: Факт аналогичного месяца прошлого года | P7: Отклонение LFL
F8: Выручка | I8: =I11*I12*I13 -> 2066350 | J8: =D56 -> 1119646 | K8: =IF(AND(I8<>"",I8<>0,J8<>""),J8/I8,"") -> 0.54184722 | L8: =IF(SUMIF($D$25:$D$55,">=0",$P$25:$P$55)<>0,I8*D56/SUMIF($D$25:$D$55,">=0",$P$25:$P$55),0) -> 1181910.8 | M8: =IF(AND(I8<>"", I8<>0, L8<>"", L8<>0), L8/I8, "") -> 0.57197998 | N8: =IF(AND(J8<>0, J8<>"", I8<>0, I8<>""), L8-I8, "") -> -884439.17 | P8: =IF(AND(O8<>"", O8<>0, L8<>"", L8<>0), -O8+L8, "") | Q8: =IF(AND(P8<>"", P8<>0, O8<>0, O8<>""), P8/O8, "")
F9: Кол-во изделий | I9: =I8/I11 -> 317.9 | J9: =E56 -> 152 | K9: =IF(AND(I9<>"", I9<>0, J9<>""), J9/I9, "") -> 0.47813778 | L9: =IF(SUMIF($E$25:$E$55, ">=0", $Q$25:$Q$55)<>0, I9*E56/SUMIF($E$25:$E$55, ">=0", $Q$25:$Q$55), 0) -> 171.28476 | M9: =IF(AND(I9<>"", I9<>0, L9<>"", L9<>0), L9/I9, "") -> 0.53880075 | N9: =IF(AND(J9<>0, J9<>"", I9<>0, I9<>""), L9-I9, "") -> -146.61524 | O9: =O8/O11 -> #DIV/0! | P9: =IF(AND(O9<>"", O9<>0, L9<>"", L9<>0), -O9+L9, "") -> #DIV/0! | Q9: =IF(AND(P9<>"", P9<>0, O9<>0, O9<>""), P9/O9, "") -> #DIV/0!
F10: Средний чек | I10: =I11*I12 -> 11050 | J10: =H56 -> 11542.742 | K10: =IF(AND(I10<>"", I10<>0, J10<>""), J10/I10, "") -> 1.0445921 | L10: =J10 -> 11542.742 | M10: =IF(AND(I10<>"", I10<>0, L10<>"", L10<>0), L10/I10, "") -> 1.0445921 | N10: =IF(AND(J10<>0, J10<>"", I10<>0, I10<>""), L10-I10, "") -> 492.74227 | O10: =O11*O12 -> 0 | P10: =IF(AND(O10<>"", O10<>0, L10<>"", L10<>0), -O10+L10, "") | Q10: =IF(AND(P10<>"", P10<>0, O10<>0, O10<>""), P10/O10, "") | S10: =L23 -> IS | V10: =M23 -> Agafi
F11: Средняя стоимость изделия | I11: 6500 | J11: =F56 -> 7366.0921 | K11: =IF(AND(I11<>"", I11<>0, J11<>""), J11/I11, "") -> 1.1332449 | L11: =IF(L9>0, L8/L9, "") -> 6900.2685 | M11: =IF(AND(I11<>"", I11<>0, L11<>"", L11<>0), L11/I11, "") -> 1.0615798 | N11: =IF(AND(J11<>0, J11<>"", I11<>0, I11<>""), L11-I11, "") -> 400.26851 | P11: =IF(AND(O11<>"", O11<>0, L11<>"", L11<>0), -O11+L11, "") | Q11: =IF(AND(P11<>"", P11<>0, O11<>0, O11<>""), P11/O11, "")
F12: Длина чека | I12: 1.7 | J12: =J56 -> 1.5670103 | K12: =IF(AND(I12<>"", I12<>0, J12<>""), J12/I12, "") -> 0.92177077 | L12: =J12 -> 1.5670103 | M12: =IF(AND(I12<>"", I12<>0, L12<>"", L12<>0), L12/I12, "") -> 0.92177077 | N12: =IF(AND(J12<>0, J12<>"", I12<>0, I12<>""), L12-I12, "") -> -0.13298969 | P12: =IF(AND(O12<>"", O12<>0, L12<>"", L12<>0), -O12+L12, "") | Q12: =IF(AND(P12<>"", P12<>0, O12<>0, O12<>""), P12/O12, "") | S12: 510000 | T12: =L56 -> 46449 | V12: 480000 | W12: =M56 -> 72847
F13: Кол-во чеков | I13: =I17*I20 -> 187 | J13: =G56 -> 97 | K13: =IF(AND(I13<>"", I13<>0, J13<>""), J13/I13, "") -> 0.51871658 | L13: =IF(SUMIF($G$25:$G$55, ">=0", $R$25:$R$55)<>0, I13*G56/SUMIF($G$25:$G$55, ">=0", $R$25:$R$55), "") -> 109.30672 | M13: =IF(AND(I13<>"", I13<>0, L13<>"", L13<>0), L13/I13, "") -> 0.58452792 | N13: =IF(AND(J13<>0, J13<>"", I13<>0, I13<>""), L13-I13, "") -> -77.693279 | P13: =IF(AND(O13<>"", O13<>0, L13<>"", L13<>0), -O13+L13, "") | Q13: =IF(AND(P13<>"", P13<>0, O13<>0, O13<>""), P13/O13, "") | S13: =T12/S12 -> 0.091076471 | T13: =S13/J14*I14 -> 0.091076471 | V13: =W12/V12 -> 0.15176458 | W13: =V13/J14*I14 -> 0.15176458
F14: Кол-во смен | I14: 30 | J14: 30 | K14: =IF(AND(I14<>"", I14<>0, J14<>""), J14/I14, "") -> 1 | L14: =I14 -> 30 | M14: =IF(AND(I14<>"", I14<>0, L14<>"", L14<>0), L14/I14, "") -> 1 | N14: =IF(AND(J14<>0, J14<>"", I14<>0, I14<>""), L14-I14, "") -> 0 | P14: =IF(AND(O14<>"", O14<>0, L14<>"", L14<>0), -O14+L14, "") | Q14: =IF(AND(P14<>"", P14<>0, O14<>0, O14<>""), P14/O14, "")
F15: Средние продажи в смену | I15: =I8/I14 -> 68878.333 | J15: =J8/J14 -> 37321.533 | K15: =IF(AND(I15<>"", I15<>0, J15<>""), J15/I15, "") -> 0.54184722 | L15: =J15 -> 37321.533 | M15: =IF(AND(I15<>"", I15<>0, L15<>"", L15<>0), L15/I15, "") -> 0.54184722 | N15: =IF(AND(J15<>0, J15<>"", I15<>0, I15<>""), L15-I15, "") -> -31556.8 | P15: =IF(AND(O15<>"", O15<>0, L15<>"", L15<>0), -O15+L15, "") | Q15: =IF(AND(P15<>"", P15<>0, O15<>0, O15<>""), P15/O15, "")
F16: Отставание/Перевыполнение | J16: =J8-I15*J14 -> -946704 | K16: =IF(AND(I16<>"", I16<>0, J16<>""), J16/I16, "") | L16: =J16 -> -946704 | M16: =IF(AND(I16<>"", I16<>0, L16<>"", L16<>0), L16/I16, "") | N16: =IF(AND(J16<>0, J16<>"", I16<>0, I16<>""), L16-I16, "") | P16: =IF(AND(O16<>"", O16<>0, L16<>"", L16<>0), -O16+L16, "") | Q16: =IF(AND(P16<>"", P16<>0, O16<>0, O16<>""), P16/O16, "") | S16: =K23 -> UNOde50
F17: Трафик | I17: 1700 | J17: =I56 -> 1555.2 | K17: =IF(AND(I17<>"", I17<>0, J17<>""), J17/I17, "") -> 0.91482353 | L17: =J17/J14*I14 -> 1555.2 | M17: =IF(AND(I17<>"", I17<>0, L17<>"", L17<>0), L17/I17, "") -> 0.91482353 | N17: =IF(AND(J17<>0, J17<>"", I17<>0, I17<>""), L17-I17, "") -> -144.8 | P17: =IF(AND(O17<>"", O17<>0, L17<>"", L17<>0), -O17+L17, "") | Q17: =IF(AND(P17<>"", P17<>0, O17<>0, O17<>""), P17/O17, "")
K18: =IF(AND(I18<>"", I18<>0, J18<>""), J18/I18, "") | L18: =J18 -> 0 | M18: =IF(AND(I18<>"", I18<>0, L18<>"", L18<>0), L18/I18, "") | N18: =IF(AND(J18<>0, J18<>"", I18<>0, I18<>""), L18-I18, "") | O18: 0 | P18: =IF(AND(O18<>"", O18<>0, L18<>"", L18<>0), -O18+L18, "") | Q18: =IF(AND(P18<>"", P18<>0, O18<>0, O18<>""), P18/O18, "") | S18: 1020000 | T18: =K56 -> 416418
K19: =IF(AND(I19<>"", I19<>0, J19<>""), J19/I19, "") | L19: =J19 -> 0 | M19: =IF(AND(I19<>"", I19<>0, L19<>"", L19<>0), L19/I19, "") | N19: =IF(AND(J19<>0, J19<>"", I19<>0, I19<>""), L19-I19, "") | O19: 0 | P19: =IF(AND(O19<>"", O19<>0, L19<>"", L19<>0), -O19+L19, "") | Q19: =IF(AND(P19<>"", P19<>0, O19<>0, O19<>""), P19/O19, "") | S19: =T18/S18 -> 0.40825294 | T19: =S19/J14*I14 -> 0.40825294
F20: Конверсия план/факт | I20: 0.11 | J20: =N56 -> 0.062371399 | K20: =J20/I20 -> 0.56701272 | L20: =IF(AND(K8<>0, I14<>0, I56<>0), (I56*N56+(I56/K8-I56)*I20)/(I56/K8), 0) -> 0.084192575 | M20: =IF(AND(I20<>"", I20<>0, L20<>"", L20<>0), L20/I20, "") -> 0.76538705 | N20: =IF(AND(J20<>0, J20<>"", I20<>0, I20<>""), L20-I20, "") -> -0.025807425 | P20: =IF(AND(O20<>"", O20<>0, L20<>"", L20<>0), -O20+L20, "") | Q20: =IF(AND(P20<>"", P20<>0, O20<>0, O20<>""), P20/O20, "")
A22: Факт продаж за месяц | O22: % выполнения дневного плана | P22: Раcпределение плана по дням
A23: Сотрудник | B23: Дата | C23: День недели | D23: Выручка (руб) | E23: Кол-во единиц (шт.) | F23: Средняя стоимость изделия (руб.) | G23: Количество чеков (шт.) | H23: Средняя сумма чека (руб.) | I23: Трафик | J23: Длина чека (шт.) | K23: UNOde50 | L23: IS | M23: Agafi | N23: Конверсия (%) | P23: выручка, план | Q23: кол-во ед, план | R23: Кол-во чеков, план | S23: выручка, скорректир.план | T23: кол-во ед, скорр. план | U23: кол-во чеков, скорр. план | V23: Коэфф. Дня Недели | W23: Специфика месяца
B24: 1 | C24: 2 | D24: 3 | E24: 4 | F24: 5 | G24: 6 | H24: 7 | I24: 8 | J24: 9 | K24: 10 | L24: 11 | M24: 12 | N24: 13 | P24: 1 | Q24: 2 | R24: 3 | S24: 4 | T24: 5 | U24: 6 | V24: 10 | W24: 11
A25: Рогалевич,Уразгильдеева,Арапова | B25: 45962 | C25: сб | D25: =29951+10268+6992+20506 -> 67717 | E25: 12 | F25: =IF(AND(E25<>"",E25<>0),D25/E25,"") -> 5643.0833 | G25: 9 | H25: =IF(AND(G25<>"",G25<>0),D25/G25,"") -> 7524.1111 | I25: 103 | J25: =IF(AND(G25<>"",G25<>0),E25/G25,"") -> 1.3333333 | K25: 10268 | L25: 20506 | M25: 6992 | N25: =IF(AND(I25<>"",I25<>0),G25/I25,"") -> 0.087378641 | O25: =D25/P25 -> 0.89835134 | P25: =$I$8*V25*W25/SUMPRODUCT($W$25:$W$55,$V$25:$V$55) -> 75379.194 | Q25: =$I$9*V25*W25/SUMPRODUCT($W$25:$W$55,$V$25:$V$55) -> 11.596799 | R25: =IF($I$12="","",Q25/$I$12) -> 6.8216465 | S25: =IF(D25<>"",D25,P25) -> 67717 | T25: =IF(E25<>"",E25,Q25) -> 12 | U25: =IF(G25<>"",G25,R25) -> 9 | V25: 0.9414554 | W25: 0.9414554
A26: Рогалевич,Уразгильдеева | B26: 45963 | C26: вс | D26: 147496 | E26: 19 | F26: =IF(AND(E26<>"",E26<>0),D26/E26,"") -> 7762.9474 | G26: 11 | H26: =IF(AND(G26<>"",G26<>0),D26/G26,"") -> 13408.727 | I26: 131 | J26: =IF(AND(G26<>"",G26<>0),E26/G26,"") -> 1.7272727 | K26: 63254 | M26: 31287 | N26: =IF(AND(I26<>"",I26<>0),G26/I26,"") -> 0.083969466 | O26: =D26/P26 -> 2.3830107 | P26: =$I$8*V26*W26/SUMPRODUCT($W$25:$W$55,$V$25:$V$55) -> 61894.812 | Q26: =$I$9*V26*W26/SUMPRODUCT($W$25:$W$55,$V$25:$V$55) -> 9.5222788 | R26: =IF($I$12="","",Q26/$I$12) -> 5.6013404 | S26: =IF(W26<>"",IF(D26<>"",D26,($I$8-SUM($S$25:S25))*V26*W26/SUMPRODUCT($W26:$W$55,$V26:$V$55)),"") -> 147496 | T26: =IF(W26<>"",IF(E26<>"",E26,($I$9-SUM($T$25:T25))*V26*W26/SUMPRODUCT($W26:$W$55,$V26:$V$55)),"") -> 19 | U26: =IF(W26<>"",IF(E26<>"",E26,($I$9-SUM($T$25:T25))*V26*W26/SUMPRODUCT($W26:$W$55,$V26:$V$55)),"") -> 19 | V26: 0.85310234 | W26: 0.85310234
A27: Рогалевич,Арапова | B27: 45964 | C27: пн | D27: 8692 | E27: 1 | F27: =IF(AND(E27<>"",E27<>0),D27/E27,"") -> 8692 | G27: 1 | H27: =IF(AND(G27<>"",G27<>0),D27/G27,"") -> 8692 | I27: 81 | J27: =IF(AND(G27<>"",G27<>0),E27/G27,"") -> 1 | K27: 8692 | N27: =IF(AND(I27<>"",I27<>0),G27/I27,"") -> 0.012345679 | O27: =D27/P27 -> 0.1404318 | P27: =$I$8*V27*W27/SUMPRODUCT($W$25:$W$55,$V$25:$V$55) -> 61894.812 | Q27: =$I$9*V27*W27/SUMPRODUCT($W$25:$W$55,$V$25:$V$55) -> 9.5222788 | R27: =IF($I$12="","",Q27/$I$12) -> 5.6013404 | S27: =IF(W27<>"",IF(D27<>"",D27,($I$8-SUM($S$25:S26))*V27*W27/SUMPRODUCT($W27:$W$55,$V27:$V$55)),"") -> 8692 | T27: =IF(W27<>"",IF(E27<>"",E27,($I$9-SUM($T$25:T26))*V27*W27/SUMPRODUCT($W27:$W$55,$V27:$V$55)),"") -> 1 | U27: =IF(W27<>"",IF(E27<>"",E27,($I$9-SUM($T$25:T26))*V27*W27/SUMPRODUCT($W27:$W$55,$V27:$V$55)),"") -> 1 | V27: 0.85310234 | W27: 0.85310234
A28: Рогалевич,Арапова | B28: 45965 | C28: вт | D28: 30422 | E28: 4 | F28: =IF(AND(E28<>"",E28<>0),D28/E28,"") -> 7605.5 | G28: 3 | H28: =IF(AND(G28<>"",G28<>0),D28/G28,"") -> 10140.667 | I28: 92 | J28: =IF(AND(G28<>"",G28<>0),E28/G28,"") -> 1.3333333 | K28: 16490 | N28: =IF(AND(I28<>"",I28<>0),G28/I28,"") -> 0.032608696 | O28: =D28/P28 -> 0.49151131 | P28: =$I$8*V28*W28/SUMPRODUCT($W$25:$W$55,$V$25:$V$55) -> 61894.812 | Q28: =$I$9*V28*W28/SUMPRODUCT($W$25:$W$55,$V$25:$V$55) -> 9.5222788 | R28: =IF($I$12="","",Q28/$I$12) -> 5.6013404 | S28: =IF(W28<>"",IF(D28<>"",D28,($I$8-SUM($S$25:S27))*V28*W28/SUMPRODUCT($W28:$W$55,$V28:$V$55)),"") -> 30422 | T28: =IF(W28<>"",IF(E28<>"",E28,($I$9-SUM($T$25:T27))*V28*W28/SUMPRODUCT($W28:$W$55,$V28:$V$55)),"") -> 4 | U28: =IF(W28<>"",IF(E28<>"",E28,($I$9-SUM($T$25:T27))*V28*W28/SUMPRODUCT($W28:$W$55,$V28:$V$55)),"") -> 4 | V28: 0.85310234 | W28: 0.85310234
A29: Рогалевич | B29: 45966 | C29: ср | D29: 28069 | E29: 6 | F29: =IF(AND(E29<>"",E29<>0),D29/E29,"") -> 4678.1667 | G29: 2 | H29: =IF(AND(G29<>"",G29<>0),D29/G29,"") -> 14034.5 | I29: 46 | J29: =IF(AND(G29<>"",G29<>0),E29/G29,"") -> 3 | N29: =IF(AND(I29<>"",I29<>0),G29/I29,"") -> 0.043478261 | O29: =D29/P29 -> 0.45681158 | P29: =$I$8*V29*W29/SUMPRODUCT($W$25:$W$55,$V$25:$V$55) -> 61445.465 | Q29: =$I$9*V29*W29/SUMPRODUCT($W$25:$W$55,$V$25:$V$55) -> 9.4531485 | R29: =IF($I$12="","",Q29/$I$12) -> 5.5606756 | S29: =IF(W29<>"",IF(D29<>"",D29,($I$8-SUM($S$25:S28))*V29*W29/SUMPRODUCT($W29:$W$55,$V29:$V$55)),"") -> 28069 | T29: =IF(W29<>"",IF(E29<>"",E29,($I$9-SUM($T$25:T28))*V29*W29/SUMPRODUCT($W29:$W$55,$V29:$V$55)),"") -> 6 | U29: =IF(W29<>"",IF(E29<>"",E29,($I$9-SUM($T$25:T28))*V29*W29/SUMPRODUCT($W29:$W$55,$V29:$V$55)),"") -> 6 | V29: 0.85 | W29: 0.85
A30: Рогалевич,Арапова | B30: 45967 | C30: чт | D30: 14400 | E30: 4 | F30: =IF(AND(E30<>"",E30<>0),D30/E30,"") -> 3600 | G30: 2 | H30: =IF(AND(G30<>"",G30<>0),D30/G30,"") -> 7200 | I30: 49 | J30: =IF(AND(G30<>"",G30<>0),E30/G30,"") -> 2 | N30: =IF(AND(I30<>"",I30<>0),G30/I30,"") -> 0.040816327 | O30: =D30/P30 -> 0.16932088 | P30: =$I$8*V30*W30/SUMPRODUCT($W$25:$W$55,$V$25:$V$55) -> 85045.626 | Q30: =$I$9*V30*W30/SUMPRODUCT($W$25:$W$55,$V$25:$V$55) -> 13.083943 | R30: =IF($I$12="","",Q30/$I$12) -> 7.6964368 | S30: =IF(W30<>"",IF(D30<>"",D30,($I$8-SUM($S$25:S29))*V30*W30/SUMPRODUCT($W30:$W$55,$V30:$V$55)),"") -> 14400 | T30: =IF(W30<>"",IF(E30<>"",E30,($I$9-SUM($T$25:T29))*V30*W30/SUMPRODUCT($W30:$W$55,$V30:$V$55)),"") -> 4 | U30: =IF(W30<>"",IF(E30<>"",E30,($I$9-SUM($T$25:T29))*V30*W30/SUMPRODUCT($W30:$W$55,$V30:$V$55)),"") -> 4 | V30: 1 | W30: 1
A31: Рогалевич,Арапова | B31: 45968 | C31: пт | D31: 40625 | E31: 9 | F31: =IF(AND(E31<>"",E31<>0),D31/E31,"") -> 4513.8889 | G31: 6 | H31: =IF(AND(G31<>"",G31<>0),D31/G31,"") -> 6770.8333 | I31: 64 | J31: =IF(AND(G31<>"",G31<>0),E31/G31,"") -> 1.5 | N31: =IF(AND(I31<>"",I31<>0),G31/I31,"") -> 0.09375 | O31: =D31/P31 -> 0.47768476 | P31: =$I$8*V31*W31/SUMPRODUCT($W$25:$W$55,$V$25:$V$55) -> 85045.626 | Q31: =$I$9*V31*W31/SUMPRODUCT($W$25:$W$55,$V$25:$V$55) -> 13.083943 | R31: =IF($I$12="","",Q31/$I$12) -> 7.6964368 | S31: =IF(W31<>"",IF(D31<>"",D31,($I$8-SUM($S$25:S30))*V31*W31/SUMPRODUCT($W31:$W$55,$V31:$V$55)),"") -> 40625 | T31: =IF(W31<>"",IF(E31<>"",E31,($I$9-SUM($T$25:T30))*V31*W31/SUMPRODUCT($W31:$W$55,$V31:$V$55)),"") -> 9 | U31: =IF(W31<>"",IF(E31<>"",E31,($I$9-SUM($T$25:T30))*V31*W31/SUMPRODUCT($W31:$W$55,$V31:$V$55)),"") -> 9 | V31: 1 | W31: 1
A32: Рогалевич,Арапова | B32: 45969 | C32: сб | D32: 46958 | E32: 8 | F32: =IF(AND(E32<>"",E32<>0),D32/E32,"") -> 5869.75 | G32: 6 | H32: =IF(AND(G32<>"",G32<>0),D32/G32,"") -> 7826.3333 | I32: 101 | J32: =IF(AND(G32<>"",G32<>0),E32/G32,"") -> 1.3333333 | K32: 20809 | N32: =IF(AND(I32<>"",I32<>0),G32/I32,"") -> 0.059405941 | O32: =D32/P32 -> 0.75867425 | P32: =$I$8*V32*W32/SUMPRODUCT($W$25:$W$55,$V$25:$V$55) -> 61894.812 | Q32: =$I$9*V32*W32/SUMPRODUCT($W$25:$W$55,$V$25:$V$55) -> 9.5222788 | R32: =IF($I$12="","",Q32/$I$12) -> 5.6013404 | S32: =IF(W32<>"",IF(D32<>"",D32,($I$8-SUM($S$25:S31))*V32*W32/SUMPRODUCT($W32:$W$55,$V32:$V$55)),"") -> 46958 | T32: =IF(W32<>"",IF(E32<>"",E32,($I$9-SUM($T$25:T31))*V32*W32/SUMPRODUCT($W32:$W$55,$V32:$V$55)),"") -> 8 | U32: =IF(W32<>"",IF(E32<>"",E32,($I$9-SUM($T$25:T31))*V32*W32/SUMPRODUCT($W32:$W$55,$V32:$V$55)),"") -> 8 | V32: 0.85310234 | W32: 0.85310234
A33: Рогалевич | B33: 45970 | C33: вс | D33: 6992 | E33: 1 | F33: =IF(AND(E33<>"",E33<>0),D33/E33,"") -> 6992 | G33: 1 | H33: =IF(AND(G33<>"",G33<>0),D33/G33,"") -> 6992 | I33: 84 | J33: =IF(AND(G33<>"",G33<>0),E33/G33,"") -> 1 | M33: 6992 | N33: =IF(AND(I33<>"",I33<>0),G33/I33,"") -> 0.011904762 | O33: =D33/P33 -> 0.11296585 | P33: =$I$8*V33*W33/SUMPRODUCT($W$25:$W$55,$V$25:$V$55) -> 61894.812 | Q33: =$I$9*V33*W33/SUMPRODUCT($W$25:$W$55,$V$25:$V$55) -> 9.5222788 | R33: =IF($I$12="","",Q33/$I$12) -> 5.6013404 | S33: =IF(W33<>"",IF(D33<>"",D33,($I$8-SUM($S$25:S32))*V33*W33/SUMPRODUCT($W33:$W$55,$V33:$V$55)),"") -> 6992 | T33: =IF(W33<>"",IF(E33<>"",E33,($I$9-SUM($T$25:T32))*V33*W33/SUMPRODUCT($W33:$W$55,$V33:$V$55)),"") -> 1 | U33: =IF(W33<>"",IF(E33<>"",E33,($I$9-SUM($T$25:T32))*V33*W33/SUMPRODUCT($W33:$W$55,$V33:$V$55)),"") -> 1 | V33: 0.85310234 | W33: 0.85310234
A34: Рогалевич | B34: 45971 | C34: пн | D34: 30575 | E34: 3 | F34: =IF(AND(E34<>"",E34<>0),D34/E34,"") -> 10191.667 | G34: 2 | H34: =IF(AND(G34<>"",G34<>0),D34/G34,"") -> 15287.5 | I34: 58 | J34: =IF(AND(G34<>"",G34<>0),E34/G34,"") -> 1.5 | K34: 15292 | N34: =IF(AND(I34<>"",I34<>0),G34/I34,"") -> 0.034482759 | O34: =D34/P34 -> 0.49398324 | P34: =$I$8*V34*W34/SUMPRODUCT($W$25:$W$55,$V$25:$V$55) -> 61894.812 | Q34: =$I$9*V34*W34/SUMPRODUCT($W$25:$W$55,$V$25:$V$55) -> 9.5222788 | R34: =IF($I$12="","",Q34/$I$12) -> 5.6013404 | S34: =IF(W34<>"",IF(D34<>"",D34,($I$8-SUM($S$25:S33))*V34*W34/SUMPRODUCT($W34:$W$55,$V34:$V$55)),"") -> 30575 | T34: =IF(W34<>"",IF(E34<>"",E34,($I$9-SUM($T$25:T33))*V34*W34/SUMPRODUCT($W34:$W$55,$V34:$V$55)),"") -> 3 | U34: =IF(W34<>"",IF(E34<>"",E34,($I$9-SUM($T$25:T33))*V34*W34/SUMPRODUCT($W34:$W$55,$V34:$V$55)),"") -> 3 | V34: 0.85310234 | W34: 0.85310234
A35: Рогалевич,Арапова | B35: 45972 | C35: вт | D35: 71465 | E35: 4 | F35: =IF(AND(E35<>"",E35<>0),D35/E35,"") -> 17866.25 | G35: 2 | H35: =IF(AND(G35<>"",G35<>0),D35/G35,"") -> 35732.5 | I35: 64 | J35: =IF(AND(G35<>"",G35<>0),E35/G35,"") -> 2 | K35: 68170 | N35: =IF(AND(I35<>"",I35<>0),G35/I35,"") -> 0.03125 | O35: =D35/P35 -> 0.58355114 | P35: =$I$8*V35*W35/SUMPRODUCT($W$25:$W$55,$V$25:$V$55) -> 122465.7 | Q35: =$I$9*V35*W35/SUMPRODUCT($W$25:$W$55,$V$25:$V$55) -> 18.840877 | R35: =IF($I$12="","",Q35/$I$12) -> 11.082869 | S35: =IF(W35<>"",IF(D35<>"",D35,($I$8-SUM($S$25:S34))*V35*W35/SUMPRODUCT($W35:$W$55,$V35:$V$55)),"") -> 71465 | T35: =IF(W35<>"",IF(E35<>"",E35,($I$9-SUM($T$25:T34))*V35*W35/SUMPRODUCT($W35:$W$55,$V35:$V$55)),"") -> 4 | U35: =IF(W35<>"",IF(E35<>"",E35,($I$9-SUM($T$25:T34))*V35*W35/SUMPRODUCT($W35:$W$55,$V35:$V$55)),"") -> 4 | V35: 1.2 | W35: 1.2
A36: Рогалевич,Арапова | B36: 45973 | C36: ср | D36: 56481 | E36: 5 | F36: =IF(AND(E36<>"",E36<>0),D36/E36,"") -> 11296.2 | G36: 3 | H36: =IF(AND(G36<>"",G36<>0),D36/G36,"") -> 18827 | I36: 69 | J36: =IF(AND(G36<>"",G36<>0),E36/G36,"") -> 1.6666667 | K36: 36977 | L36: 16902 | N36: =IF(AND(I36<>"",I36<>0),G36/I36,"") -> 0.043478261 | O36: =D36/P36 -> 0.91253206 | P36: =$I$8*V36*W36/SUMPRODUCT($W$25:$W$55,$V$25:$V$55) -> 61894.812 | Q36: =$I$9*V36*W36/SUMPRODUCT($W$25:$W$55,$V$25:$V$55) -> 9.5222788 | R36: =IF($I$12="","",Q36/$I$12) -> 5.6013404 | S36: =IF(W36<>"",IF(D36<>"",D36,($I$8-SUM($S$25:S35))*V36*W36/SUMPRODUCT($W36:$W$55,$V36:$V$55)),"") -> 56481 | T36: =IF(W36<>"",IF(E36<>"",E36,($I$9-SUM($T$25:T35))*V36*W36/SUMPRODUCT($W36:$W$55,$V36:$V$55)),"") -> 5 | U36: =IF(W36<>"",IF(E36<>"",E36,($I$9-SUM($T$25:T35))*V36*W36/SUMPRODUCT($W36:$W$55,$V36:$V$55)),"") -> 5 | V36: 0.85310234 | W36: 0.85310234
A37: Рогалевич | B37: 45974 | C37: чт | D37: 0 | H37: 0 | I37: 50 | J37: =IF(AND(G37<>"",G37<>0),E37/G37,"") | N37: =IF(AND(I37<>"",I37<>0),G37/I37,"") -> 0 | O37: =D37/P37 -> 0 | P37: =$I$8*V37*W37/SUMPRODUCT($W$25:$W$55,$V$25:$V$55) -> 61894.812 | Q37: =$I$9*V37*W37/SUMPRODUCT($W$25:$W$55,$V$25:$V$55) -> 9.5222788 | R37: =IF($I$12="","",Q37/$I$12) -> 5.6013404 | S37: =IF(W37<>"",IF(D37<>"",D37,($I$8-SUM($S$25:S36))*V37*W37/SUMPRODUCT($W37:$W$55,$V37:$V$55)),"") -> 0 | T37: =IF(W37<>"",IF(E37<>"",E37,($I$9-SUM($T$25:T36))*V37*W37/SUMPRODUCT($W37:$W$55,$V37:$V$55)),"") -> 12.438562 | U37: =IF(W37<>"",IF(E37<>"",E37,($I$9-SUM($T$25:T36))*V37*W37/SUMPRODUCT($W37:$W$55,$V37:$V$55)),"") -> 12.438562 | V37: 0.85310234 | W37: 0.85310234
A38: Рогалевич,Арапова | B38: 45975 | C38: пт | D38: 56141 | E38: 7 | F38: =IF(AND(E38<>"",E38<>0),D38/E38,"") -> 8020.1429 | G38: 4 | H38: =IF(AND(G38<>"",G38<>0),D38/G38,"") -> 14035.25 | I38: 72 | J38: =IF(AND(G38<>"",G38<>0),E38/G38,"") -> 1.75 | M38: 19883 | N38: =IF(AND(I38<>"",I38<>0),G38/I38,"") -> 0.055555556 | O38: =D38/P38 -> 0.81497285 | P38: =$I$8*V38*W38/SUMPRODUCT($W$25:$W$55,$V$25:$V$55) -> 68886.957 | Q38: =$I$9*V38*W38/SUMPRODUCT($W$25:$W$55,$V$25:$V$55) -> 10.597993 | R38: =IF($I$12="","",Q38/$I$12) -> 6.2341138 | S38: =IF(W38<>"",IF(D38<>"",D38,($I$8-SUM($S$25:S37))*V38*W38/SUMPRODUCT($W38:$W$55,$V38:$V$55)),"") -> 56141 | T38: =IF(W38<>"",IF(E38<>"",E38,($I$9-SUM($T$25:T37))*V38*W38/SUMPRODUCT($W38:$W$55,$V38:$V$55)),"") -> 7 | U38: =IF(W38<>"",IF(E38<>"",E38,($I$9-SUM($T$25:T37))*V38*W38/SUMPRODUCT($W38:$W$55,$V38:$V$55)),"") -> 7 | V38: 0.9 | W38: 0.9
A39: Рогалевич,Уразгильдеева | B39: 45976 | C39: сб | D39: 32254 | E39: 4 | F39: =IF(AND(E39<>"",E39<>0),D39/E39,"") -> 8063.5 | G39: 2 | H39: =IF(AND(G39<>"",G39<>0),D39/G39,"") -> 16127 | I39: 66 | J39: =IF(AND(G39<>"",G39<>0),E39/G39,"") -> 2 | K39: 19147 | N39: =IF(AND(I39<>"",I39<>0),G39/I39,"") -> 0.03030303 | O39: =D39/P39 -> 0.31343409 | P39: =$I$8*V39*W39/SUMPRODUCT($W$25:$W$55,$V$25:$V$55) -> 102905.21 | Q39: =$I$9*V39*W39/SUMPRODUCT($W$25:$W$55,$V$25:$V$55) -> 15.83157 | R39: =IF($I$12="","",Q39/$I$12) -> 9.3126885 | S39: =IF(W39<>"",IF(D39<>"",D39,($I$8-SUM($S$25:S38))*V39*W39/SUMPRODUCT($W39:$W$55,$V39:$V$55)),"") -> 32254 | T39: =IF(W39<>"",IF(E39<>"",E39,($I$9-SUM($T$25:T38))*V39*W39/SUMPRODUCT($W39:$W$55,$V39:$V$55)),"") -> 4 | U39: =IF(W39<>"",IF(E39<>"",E39,($I$9-SUM($T$25:T38))*V39*W39/SUMPRODUCT($W39:$W$55,$V39:$V$55)),"") -> 4 | V39: 1.1 | W39: 1.1
A40: Уразгильдеева,Арапова | B40: 45977 | C40: вс | D40: 25235 | E40: 5 | F40: =IF(AND(E40<>"",E40<>0),D40/E40,"") -> 5047 | G40: 4 | H40: =IF(AND(G40<>"",G40<>0),D40/G40,"") -> 6308.75 | I40: 70 | J40: =IF(AND(G40<>"",G40<>0),E40/G40,"") -> 1.25 | N40: =IF(AND(I40<>"",I40<>0),G40/I40,"") -> 0.057142857 | O40: =D40/P40 -> 0.29672308 | P40: =$I$8*V40*W40/SUMPRODUCT($W$25:$W$55,$V$25:$V$55) -> 85045.626 | Q40: =$I$9*V40*W40/SUMPRODUCT($W$25:$W$55,$V$25:$V$55) -> 13.083943 | R40: =IF($I$12="","",Q40/$I$12) -> 7.6964368 | S40: =IF(W40<>"",IF(D40<>"",D40,($I$8-SUM($S$25:S39))*V40*W40/SUMPRODUCT($W40:$W$55,$V40:$V$55)),"") -> 25235 | T40: =IF(W40<>"",IF(E40<>"",E40,($I$9-SUM($T$25:T39))*V40*W40/SUMPRODUCT($W40:$W$55,$V40:$V$55)),"") -> 5 | U40: =IF(W40<>"",IF(E40<>"",E40,($I$9-SUM($T$25:T39))*V40*W40/SUMPRODUCT($W40:$W$55,$V40:$V$55)),"") -> 5 | V40: 1 | W40: 1
A41: Уразгильдеева,Арапова | B41: 45978 | C41: пн | D41: 76121 | E41: 8 | F41: =IF(AND(E41<>"",E41<>0),D41/E41,"") -> 9515.125 | G41: 2 | H41: =IF(AND(G41<>"",G41<>0),D41/G41,"") -> 38060.5 | I41: 51 | J41: =IF(AND(G41<>"",G41<>0),E41/G41,"") -> 4 | K41: 45170 | N41: =IF(AND(I41<>"",I41<>0),G41/I41,"") -> 0.039215686 | O41: =D41/P41 -> 1.2298446 | P41: =$I$8*V41*W41/SUMPRODUCT($W$25:$W$55,$V$25:$V$55) -> 61894.812 | Q41: =$I$9*V41*W41/SUMPRODUCT($W$25:$W$55,$V$25:$V$55) -> 9.5222788 | R41: =IF($I$12="","",Q41/$I$12) -> 5.6013404 | S41: =IF(W41<>"",IF(D41<>"",D41,($I$8-SUM($S$25:S40))*V41*W41/SUMPRODUCT($W41:$W$55,$V41:$V$55)),"") -> 76121 | T41: =IF(W41<>"",IF(E41<>"",E41,($I$9-SUM($T$25:T40))*V41*W41/SUMPRODUCT($W41:$W$55,$V41:$V$55)),"") -> 8 | U41: =IF(W41<>"",IF(E41<>"",E41,($I$9-SUM($T$25:T40))*V41*W41/SUMPRODUCT($W41:$W$55,$V41:$V$55)),"") -> 8 | V41: 0.85310234 | W41: 0.85310234
...

Sheet Конкурс
A1: Сотрудник | B1: Длина чека | C1: КВП
D2: 9 | E2: 10 | F2: 11 | G2: 12 | H2: 13 | I2: 14 | J2: 15 | K2: 16 | L2: 17 | M2: 18 | N2: 19 | O2: 20 | P2: 21 | Q2: 22 | R2: 23 | S2: 24 | T2: 25 | U2: 26 | V2: 27 | W2: 28 | X2: 29 | Y2: 30 | Z2: Итого
A3: =График!B29 -> Рогалевич Ирина | B3: ='Рогалевич И. Е. '!J12 -> 1.62 | C3: ='Рогалевич И. Е. '!K8 -> 0.76619217 | Z3: =SUM(D3:Y3) -> 0
A4: =График!B28 -> Уразгильдеева Екатерина | B4: ='Уразгильдеева Е. Р. '!J12 -> 1.6818182 | C4: ='Уразгильдеева Е. Р. '!K8 -> 0.56110975 | Z4: =SUM(D4:Y4) -> 0
A5: =График!B27 -> Арапова Анна-Мария | B5: ='[1]Яковенко А. К'!J12 -> #REF! | C5: ='[1]Яковенко А. К'!K8 -> #REF! | Z5: =SUM(D5:Y5) -> 0

Sheet Св. по пок.
A1: 1-20.08
A2: Показатель | D2: ='Ялта, Ленина, 18'!I3 -> ул. Набережная Ленина, 18 | G2: =График!B29 -> Рогалевич Ирина | J2: =График!B28 -> Уразгильдеева Екатерина | M2: =График!B27 -> Арапова Анна-Мария
D3: Факт | F3: Прогноз | G3: Факт | I3: Прогноз | J3: Факт | L3: Прогноз | M3: Факт | O3: Прогноз
A4: Выручка | D4: ='Ялта, Ленина, 18'!K8 -> 0.54184722 | E4: ='Ялта, Ленина, 18'!J8 -> 1119646 | F4: ='Ялта, Ленина, 18'!M8 -> 0.57197998 | G4: ='Рогалевич И. Е. '!K8 -> 0.76619217 | H4: ='Рогалевич И. Е. '!J8 -> 641915 | I4: ='Рогалевич И. Е. '!M8 -> 1.0081476 | J4: ='Уразгильдеева Е. Р. '!K8 -> 0.56110975 | K4: ='Уразгильдеева Е. Р. '!J8 -> 263849 | L4: ='Уразгильдеева Е. Р. '!M8 -> 0.72944267 | M4: ='[1]Яковенко А. К'!K8 -> #REF! | N4: ='[1]Яковенко А. К'!J8 -> #REF! | O4: ='[1]Яковенко А. К'!M8 -> #REF!
A5: Кол-во изделий | D5: ='Ялта, Ленина, 18'!K9 -> 0.47813778 | E5: ='Ялта, Ленина, 18'!J9 -> 152 | F5: ='Ялта, Ленина, 18'!M9 -> 0.53880075 | G5: ='Рогалевич И. Е. '!K9 -> 0.62843239 | H5: ='Рогалевич И. Е. '!J9 -> 81 | I5: ='Рогалевич И. Е. '!M9 -> 0.82688472 | J5: ='Уразгильдеева Е. Р. '!K9 -> 0.51145502 | K5: ='Уразгильдеева Е. Р. '!J9 -> 37 | L5: ='Уразгильдеева Е. Р. '!M9 -> 0.66489152 | M5: ='[1]Яковенко А. К'!K9 -> #REF! | N5: ='[1]Яковенко А. К'!J9 -> #REF! | O5: ='[1]Яковенко А. К'!M9 -> #REF!
A6: Средний чек | D6: ='Ялта, Ленина, 18'!K10 -> 1.0445921 | E6: ='Ялта, Ленина, 18'!J10 -> 11542.742 | F6: ='Ялта, Ленина, 18'!M10 -> 1.0445921 | G6: ='Рогалевич И. Е. '!K10 -> 1.1618371 | H6: ='Рогалевич И. Е. '!J10 -> 12838.3 | I6: ='Рогалевич И. Е. '!M10 -> 1.1618371 | J6: ='Уразгильдеева Е. Р. '!K10 -> 1.0853517 | K6: ='Уразгильдеева Е. Р. '!J10 -> 11993.136 | L6: ='Уразгильдеева Е. Р. '!M10 -> 1.0853517 | M6: ='[1]Яковенко А. К'!K10 -> #REF! | N6: ='[1]Яковенко А. К'!J10 -> #REF! | O6: ='[1]Яковенко А. К'!M10 -> #REF!
A7: Средняя стоимость изделия | D7: ='Ялта, Ленина, 18'!K11 -> 1.1332449 | E7: ='Ялта, Ленина, 18'!J11 -> 7366.0921 | F7: ='Ялта, Ленина, 18'!M11 -> 1.0615798 | G7: ='Рогалевич И. Е. '!K11 -> 1.2192118 | H7: ='Рогалевич И. Е. '!J11 -> 7924.8765 | I7: ='Рогалевич И. Е. '!M11 -> 1.2192118 | J7: ='Уразгильдеева Е. Р. '!K11 -> 1.0970852 | K7: ='Уразгильдеева Е. Р. '!J11 -> 7131.0541 | L7: ='Уразгильдеева Е. Р. '!M11 -> 1.0970852 | M7: ='[1]Яковенко А. К'!K11 -> #REF! | N7: ='[1]Яковенко А. К'!J11 -> #REF! | O7: ='[1]Яковенко А. К'!M11 -> #REF!
A8: Длина чека | D8: ='Ялта, Ленина, 18'!K12 -> 0.92177077 | E8: ='Ялта, Ленина, 18'!J12 -> 1.5670103 | F8: ='Ялта, Ленина, 18'!M12 -> 0.92177077 | G8: ='Рогалевич И. Е. '!K12 -> 0.95294118 | H8: ='Рогалевич И. Е. '!J12 -> 1.62 | I8: ='Рогалевич И. Е. '!M12 -> 0.95294118 | J8: ='Уразгильдеева Е. Р. '!K12 -> 0.98930481 | K8: ='Уразгильдеева Е. Р. '!J12 -> 1.6818182 | L8: ='Уразгильдеева Е. Р. '!M12 -> 0.98930481 | M8: ='[1]Яковенко А. К'!K12 -> #REF! | N8: ='[1]Яковенко А. К'!J12 -> #REF! | O8: ='[1]Яковенко А. К'!M12 -> #REF!
A9: Кол-во чеков | D9: ='Ялта, Ленина, 18'!K13 -> 0.51871658 | E9: ='Ялта, Ленина, 18'!J13 -> 97 | F9: ='Ялта, Ленина, 18'!M13 -> 0.58452792 | G9: ='Рогалевич И. Е. '!K13 -> 0.65946609 | H9: ='Рогалевич И. Е. '!J13 -> 50 | I9: ='Рогалевич И. Е. '!M13 -> 0.86771853 | J9: ='Уразгильдеева Е. Р. '!K13 -> 0.51698426 | K9: ='Уразгильдеева Е. Р. '!J13 -> 22 | L9: ='Уразгильдеева Е. Р. '!M13 -> 0.67207954 | M9: ='[1]Яковенко А. К'!K13 -> #REF! | N9: ='[1]Яковенко А. К'!J13 -> #REF! | O9: ='[1]Яковенко А. К'!M13 -> #REF!
A10: Кол-во смен план/отработано | D10: ='Ялта, Ленина, 18'!K14 -> 1 | E10: ='Ялта, Ленина, 18'!J14 -> 30 | G10: ='Рогалевич И. Е. '!K14 -> 1 | H10: ='Рогалевич И. Е. '!J14 -> 25 | J10: ='Уразгильдеева Е. Р. '!K14 -> 1 | K10: ='Уразгильдеева Е. Р. '!J14 -> 13 | M10: ='[1]Яковенко А. К'!K14 -> #REF! | N10: ='[1]Яковенко А. К'!J14 -> #REF!
A11: Средние продажи в смену | D11: ='Ялта, Ленина, 18'!K15 -> 0.54184722 | E11: ='Ялта, Ленина, 18'!J15 -> 37321.533 | F11: ='Ялта, Ленина, 18'!M15 -> 0.54184722 | G11: ='Рогалевич И. Е. '!K15 -> 0.37278196 | H11: ='Рогалевич И. Е. '!J15 -> 25676.6 | I11: ='Рогалевич И. Е. '!M15 -> 0.37278196 | J11: ='Уразгильдеева Е. Р. '!K15 -> 0.29466562 | K11: ='Уразгильдеева Е. Р. '!J15 -> 20296.077 | L11: ='Уразгильдеева Е. Р. '!M15 -> 0.29466562 | M11: ='[1]Яковенко А. К'!K15 -> #REF! | N11: ='[1]Яковенко А. К'!J15 -> #REF! | O11: ='[1]Яковенко А. К'!M15 -> #REF!
A12: Трафик | D12: ='Ялта, Ленина, 18'!K17 -> 0.91482353 | E12: ='Ялта, Ленина, 18'!J17 -> 1555.2 | F12: ='Ялта, Ленина, 18'!M17 -> 0.91482353 | G12: ='Рогалевич И. Е. '!K17 -> 0.73556847 | H12: ='Рогалевич И. Е. '!J17 -> 507 | I12: ='Рогалевич И. Е. '!M17 -> 0.73556847 | J12: ='Уразгильдеева Е. Р. '!K17 -> 0.61262635 | K12: ='Уразгильдеева Е. Р. '!J17 -> 237 | L12: ='Уразгильдеева Е. Р. '!M17 -> 0.61262635 | M12: ='[1]Яковенко А. К'!K17 -> #REF! | N12: ='[1]Яковенко А. К'!J17 -> #REF! | O12: ='[1]Яковенко А. К'!M17 -> #REF!
A13: UNOde50 | D13: ='Ялта, Ленина, 18'!S19 -> 0.40825294 | E13: ='Ялта, Ленина, 18'!T18 -> 416418 | F13: ='Ялта, Ленина, 18'!T19 -> 0.40825294 | G13: ='Рогалевич И. Е. '!S19 -> 0.71370212 | H13: ='Рогалевич И. Е. '!T18 -> 295157 | I13: ='Рогалевич И. Е. '!T19 -> 0.71370212 | J13: ='Уразгильдеева Е. Р. '!S19 -> 0.39326993 | K13: ='Уразгильдеева Е. Р. '!T18 -> 91284 | L13: ='Уразгильдеева Е. Р. '!T19 -> 0.39326993 | M13: ='[1]Яковенко А. К'!S19 -> #REF! | N13: ='[1]Яковенко А. К'!T18 -> #REF! | O13: ='[1]Яковенко А. К'!T19 -> #REF!
A14: IS | D14: ='Ялта, Ленина, 18'!S13 -> 0.091076471 | E14: ='Ялта, Ленина, 18'!T12 -> 46449 | F14: ='Ялта, Ленина, 18'!T13 -> 0.091076471 | G14: ='Рогалевич И. Е. '!S13 -> 0.058531132 | H14: ='Рогалевич И. Е. '!T12 -> 12103 | I14: ='Рогалевич И. Е. '!T13 -> 0.058531132 | J14: ='Уразгильдеева Е. Р. '!S13 -> 0 | K14: ='Уразгильдеева Е. Р. '!T12 -> 0 | L14: ='Уразгильдеева Е. Р. '!T13 -> 0 | M14: ='[1]Яковенко А. К'!S13 -> #REF! | N14: ='[1]Яковенко А. К'!T12 -> #REF! | O14: ='[1]Яковенко А. К'!T13 -> #REF!
A15: ='Ялта, Ленина, 18'!M23 -> Agafi | D15: ='Ялта, Ленина, 18'!V13 -> 0.15176458 | E15: ='Ялта, Ленина, 18'!W12 -> 72847 | F15: ='Ялта, Ленина, 18'!W13 -> 0.15176458 | G15: ='Рогалевич И. Е. '!V13 -> 0.37431265 | H15: ='Рогалевич И. Е. '!W12 -> 72847 | I15: ='Рогалевич И. Е. '!W13 -> 0.37431265 | J15: ='Уразгильдеева Е. Р. '!V13 -> 0 | K15: ='Уразгильдеева Е. Р. '!W12 -> 0 | L15: ='Уразгильдеева Е. Р. '!W13 -> 0 | M15: ='[1]Яковенко А. К'!V13 -> #REF! | N15: ='[1]Яковенко А. К'!W12 -> #REF! | O15: ='[1]Яковенко А. К'!W13 -> #REF!
A16: Отклонение от плана | D16: ='Ялта, Ленина, 18'!J16 -> -946704 | G16: ='Рогалевич И. Е. '!N8 -> 6826.0417 | J16: ='Уразгильдеева Е. Р. '!N8 -> -127223.38 | M16: ='[1]Яковенко А. К'!N8 -> #REF!

Sheet План на день
A1: Выручка | D1: 85046
A2: Кол-во изделий | D2: =D1/D4 -> 13.084
A3: Средний чек | D3: =D4*D5 -> 11050
A4: Средняя стоимость изделия | D4: ='Ялта, Ленина, 18'!I11 -> 6500
A5: Длина чека | D5: ='Ялта, Ленина, 18'!I12 -> 1.7
A6: Кол-во чеков | D6: =IF(D5<>0,D2/D5,"") -> 7.6964706
A7: Конверсия | D7: ='Ялта, Ленина, 18'!I20 -> 0.11
A8: IS | D8: =('Ялта, Ленина, 18'!S12-'Ялта, Ленина, 18'!T12)/('Ялта, Ленина, 18'!I14-'Ялта, Ленина, 18'!J14) -> #DIV/0!
A9: UNOde50 | D9: =('Ялта, Ленина, 18'!S18-'Ялта, Ленина, 18'!T18)/('Ялта, Ленина, 18'!I14-'Ялта, Ленина, 18'!J14) -> #DIV/0!
A10: ='Ялта, Ленина, 18'!M23 -> Agafi | D10: =('Ялта, Ленина, 18'!V12-'Ялта, Ленина, 18'!W12)/('Ялта, Ленина, 18'!I14-'Ялта, Ленина, 18'!J14) -> #DIV/0!

Sheet Рогалевич И. Е. 
B1: =TODAY()-1 -> 46000
B2: (отчетная дата) | J2: ЕЖЕДНЕВНЫЙ ОТЧЕТ О ПРОДАЖАХ
B3: Осталось до выполнения плана!!! | J3: =График!B29 -> Рогалевич Ирина
C4: =I8-D57 -> 195883.96 | E4: =IF(I8<>0,C4/I8,0) -> 0.23380783
F6: Целевые показатели
F7: Показатель | I7: План | J7: Факт | K7: % выполнения | L7: Прогноз выполнения | M7: % выполнения по прогнозу | N7: Отклонение | O7: Факт аналогичного месяца прошлого года | P7: Отклонение LFL
F8: Выручка | I8: ='Ялта, Ленина, 18'!I8/График!AJ31*График!AJ29 -> 837798.96 | J8: =D57 -> 641915 | K8: =IF(AND(I8<>"",I8<>0,J8<>""),J8/I8,"") -> 0.76619217 | L8: =IF(SUMIF($D$25:$D$56,">=0",$P$25:$P$56)<>0,I8*D57/SUMIF($D$25:$D$56,">=0",$P$25:$P$56),0) -> 844625 | M8: =IF(AND(I8<>"",I8<>0,L8<>"",L8<>0),L8/I8,"") -> 1.0081476 | N8: =IF(AND(J8<>0,J8<>"",I8<>0,I8<>""),L8-I8,"") -> 6826.0417 | P8: =IF(AND(O8<>"",O8<>0,L8<>"",L8<>0),-O8+L8,"") | Q8: =IF(AND(P8<>"",P8<>0,O8<>0,O8<>""),P8/O8,"")
F9: Кол-во изделий | I9: =I8/I11 -> 128.89215 | J9: =E57 -> 81 | K9: =IF(AND(I9<>"",I9<>0,J9<>""),J9/I9,"") -> 0.62843239 | L9: =IF(SUMIF($E$25:$E$54,">=0",$Q$25:$Q$54)<>0,I9*E57/SUMIF($E$25:$E$54,">=0",$Q$25:$Q$54),0) -> 106.57895 | M9: =IF(AND(I9<>"",I9<>0,L9<>"",L9<>0),L9/I9,"") -> 0.82688472 | N9: =IF(AND(J9<>0,J9<>"",I9<>0,I9<>""),L9-I9,"") -> -22.3132 | O9: =O8/O11 -> #DIV/0! | P9: =IF(AND(O9<>"",O9<>0,L9<>"",L9<>0),-O9+L9,"") -> #DIV/0! | Q9: =IF(AND(P9<>"",P9<>0,O9<>0,O9<>""),P9/O9,"") -> #DIV/0!
F10: Средний чек | I10: =I11*I12 -> 11050 | J10: =H57 -> 12838.3 | K10: =IF(AND(I10<>"",I10<>0,J10<>""),J10/I10,"") -> 1.1618371 | L10: =J10 -> 12838.3 | M10: =IF(AND(I10<>"",I10<>0,L10<>"",L10<>0),L10/I10,"") -> 1.1618371 | N10: =IF(AND(J10<>0,J10<>"",I10<>0,I10<>""),L10-I10,"") -> 1788.3 | O10: =O11*O12 -> 0 | P10: =IF(AND(O10<>"",O10<>0,L10<>"",L10<>0),-O10+L10,"") | Q10: =IF(AND(P10<>"",P10<>0,O10<>0,O10<>""),P10/O10,"") | S10: IS | V10: =M23 -> Agafi
F11: Средняя стоимость изделия | I11: ='Ялта, Ленина, 18'!I11 -> 6500 | J11: =F57 -> 7924.8765 | K11: =IF(AND(I11<>"",I11<>0,J11<>""),J11/I11,"") -> 1.2192118 | L11: =IF(L9>0,L8/L9,"") -> 7924.8765 | M11: =IF(AND(I11<>"",I11<>0,L11<>"",L11<>0),L11/I11,"") -> 1.2192118 | N11: =IF(AND(J11<>0,J11<>"",I11<>0,I11<>""),L11-I11,"") -> 1424.8765 | P11: =IF(AND(O11<>"",O11<>0,L11<>"",L11<>0),-O11+L11,"") | Q11: =IF(AND(P11<>"",P11<>0,O11<>0,O11<>""),P11/O11,"")
F12: Длина чека | I12: ='Ялта, Ленина, 18'!I12 -> 1.7 | J12: =J57 -> 1.62 | K12: =IF(AND(I12<>"",I12<>0,J12<>""),J12/I12,"") -> 0.95294118 | L12: =J12 -> 1.62 | M12: =IF(AND(I12<>"",I12<>0,L12<>"",L12<>0),L12/I12,"") -> 0.95294118 | N12: =IF(AND(J12<>0,J12<>"",I12<>0,I12<>""),L12-I12,"") -> -0.08 | P12: =IF(AND(O12<>"",O12<>0,L12<>"",L12<>0),-O12+L12,"") | Q12: =IF(AND(P12<>"",P12<>0,O12<>0,O12<>""),P12/O12,"") | S12: ='Ялта, Ленина, 18'!S12*График!AJ29/График!AJ31 -> 206778.85 | T12: =L57 -> 12103 | V12: ='Ялта, Ленина, 18'!V12/График!AJ31*График!AJ29 -> 194615.38 | W12: =M57 -> 72847
F13: Кол-во чеков | I13: =IF(I12<>0,I9/I12,"") -> 75.81891 | J13: =G57 -> 50 | K13: =IF(AND(I13<>"",I13<>0,J13<>""),J13/I13,"") -> 0.65946609 | L13: =IF(SUMIF($G$25:$G$54,">=0",$R$25:$R$54)<>0,I13*G57/SUMIF($G$25:$G$54,">=0",$R$25:$R$54),"") -> 65.789474 | M13: =IF(AND(I13<>"",I13<>0,L13<>"",L13<>0),L13/I13,"") -> 0.86771853 | N13: =IF(AND(J13<>0,J13<>"",I13<>0,I13<>""),L13-I13,"") -> -10.029437 | P13: =IF(AND(O13<>"",O13<>0,L13<>"",L13<>0),-O13+L13,"") | Q13: =IF(AND(P13<>"",P13<>0,O13<>0,O13<>""),P13/O13,"") | S13: =T12/S12 -> 0.058531132 | T13: =S13/J14*I14 -> 0.058531132 | V13: =W12/V12 -> 0.37431265 | W13: =V13/J14*I14 -> 0.37431265
F14: Кол-во смен план/отработано | I14: =График!AI29 -> 25 | J14: 25 | K14: =IF(AND(I14<>"",I14<>0,J14<>""),J14/I14,"") -> 1 | L14: =I14 -> 25 | M14: =IF(AND(I14<>"",I14<>0,L14<>"",L14<>0),L14/I14,"") -> 1 | N14: =IF(AND(J14<>0,J14<>"",I14<>0,I14<>""),L14-I14,"") -> 0 | P14: =IF(AND(O14<>"",O14<>0,L14<>"",L14<>0),-O14+L14,"") | Q14: =IF(AND(P14<>"",P14<>0,O14<>0,O14<>""),P14/O14,"")
F15: Средние продажи в смену | I15: ='Ялта, Ленина, 18'!I15 -> 68878.333 | J15: =J8/J14 -> 25676.6 | K15: =IF(AND(I15<>"",I15<>0,J15<>""),J15/I15,"") -> 0.37278196 | L15: =J15 -> 25676.6 | M15: =IF(AND(I15<>"",I15<>0,L15<>"",L15<>0),L15/I15,"") -> 0.37278196 | N15: =IF(AND(J15<>0,J15<>"",I15<>0,I15<>""),L15-I15,"") -> -43201.733 | P15: =IF(AND(O15<>"",O15<>0,L15<>"",L15<>0),-O15+L15,"") | Q15: =IF(AND(P15<>"",P15<>0,O15<>0,O15<>""),P15/O15,"")
F16: Отставание/Перевыполнение | J16: =J8-I15*J14 -> -1080043.3 | K16: =IF(AND(I16<>"",I16<>0,J16<>""),J16/I16,"") | L16: =J16 -> -1080043.3 | M16: =IF(AND(I16<>"",I16<>0,L16<>"",L16<>0),L16/I16,"") | N16: =IF(AND(J16<>0,J16<>"",I16<>0,I16<>""),L16-I16,"") | P16: =IF(AND(O16<>"",O16<>0,L16<>"",L16<>0),-O16+L16,"") | Q16: =IF(AND(P16<>"",P16<>0,O16<>0,O16<>""),P16/O16,"") | S16: UNOde50
F17: Трафик | I17: ='Ялта, Ленина, 18'!I17/График!AJ31*График!AJ29 -> 689.26282 | J17: =I57 -> 507 | K17: =IF(AND(I17<>"",I17<>0,J17<>""),J17/I17,"") -> 0.73556847 | L17: =J17/J14*I14 -> 507 | M17: =IF(AND(I17<>"",I17<>0,L17<>"",L17<>0),L17/I17,"") -> 0.73556847 | N17: =IF(AND(J17<>0,J17<>"",I17<>0,I17<>""),L17-I17,"") -> -182.26282 | P17: =IF(AND(O17<>"",O17<>0,L17<>"",L17<>0),-O17+L17,"") | Q17: =IF(AND(P17<>"",P17<>0,O17<>0,O17<>""),P17/O17,"")
K18: =IF(AND(I18<>"",I18<>0,J18<>""),J18/I18,"") | L18: =J18 -> 0 | M18: =IF(AND(I18<>"",I18<>0,L18<>"",L18<>0),L18/I18,"") | N18: =IF(AND(J18<>0,J18<>"",I18<>0,I18<>""),L18-I18,"") | O18: 0 | P18: =IF(AND(O18<>"",O18<>0,L18<>"",L18<>0),-O18+L18,"") | Q18: =IF(AND(P18<>"",P18<>0,O18<>0,O18<>""),P18/O18,"") | S18: ='Ялта, Ленина, 18'!S18*График!AJ29/График!AJ31 -> 413557.69 | T18: =K57 -> 295157
K19: =IF(AND(I19<>"",I19<>0,J19<>""),J19/I19,"") | L19: =J19 -> 0 | M19: =IF(AND(I19<>"",I19<>0,L19<>"",L19<>0),L19/I19,"") | N19: =IF(AND(J19<>0,J19<>"",I19<>0,I19<>""),L19-I19,"") | O19: 0 | P19: =IF(AND(O19<>"",O19<>0,L19<>"",L19<>0),-O19+L19,"") | Q19: =IF(AND(P19<>"",P19<>0,O19<>0,O19<>""),P19/O19,"") | S19: =T18/S18 -> 0.71370212 | T19: =S19/J14*I14 -> 0.71370212
F20: Конверсия план/факт | I20: ='Ялта, Ленина, 18'!I20 -> 0.11 | J20: =N57 -> 0.098619329 | K20: =J20/I20 -> 0.89653936 | L20: =IF(AND(K8<>0,I14<>0,I57<>0),(I57*N57+(I57/K8-I57)*I20)/(I57/K8),0) -> 0.10128022 | M20: =IF(AND(I20<>"",I20<>0,L20<>"",L20<>0),L20/I20,"") -> 0.92072927 | N20: =IF(AND(J20<>0,J20<>"",I20<>0,I20<>""),L20-I20,"") -> -0.0087197807 | P20: =IF(AND(O20<>"",O20<>0,L20<>"",L20<>0),-O20+L20,"") | Q20: =IF(AND(P20<>"",P20<>0,O20<>0,O20<>""),P20/O20,"")
B22: Факт продаж за месяц | O22: % выполнения дневного плана | P22: Раcпределение плана по дням
B23: Дата | C23: День недели | D23: Выручка (руб) | E23: Кол-во единиц (шт.) | F23: Средняя стоимость изделия (руб.) | G23: Количество чеков (шт.) | H23: Средняя сумма чека (руб.) | I23: Трафик | J23: Длина чека (шт.) | K23: UNOde50 | L23: IS | M23: Agafi | N23: Конверсия (%) | P23: выручка, план | Q23: кол-во ед, план | R23: Кол-во чеков, план | S23: выручка, скорректир.план | T23: кол-во ед, скорр. план | U23: кол-во чеков, скорр. план | V23: Коэфф. Дня Недели | W23: Специфика месяца
B24: 1 | C24: 2 | D24: 3 | E24: 4 | F24: 5 | G24: 6 | H24: 7 | I24: 8 | J24: 9 | K24: 10 | L24: 11 | M24: 12 | N24: 13 | P24: 1 | Q24: 2 | R24: 3 | S24: 4 | T24: 5 | U24: 6 | V24: 10 | W24: 11
A25: 1 | B25: 45962 | C25: сб | D25: =6983+10268+6992+12103 -> 36346 | E25: 6 | F25: =IF(AND(E25<>"",E25<>0),D25/E25,"") -> 6057.6667 | G25: 4 | H25: =IF(AND(G25<>"",G25<>0),D25/G25,"") -> 9086.5 | I25: 20 | J25: =IF(AND(G25<>"",G25<>0),E25/G25,"") -> 1.5 | K25: 10268 | L25: 12103 | M25: 6992 | N25: =IF(AND(I25<>"",I25<>0),G25/I25,"") -> 0.2 | O25: =D25/P25 -> 1.0845681 | P25: =$I$8*V25*W25/SUMPRODUCT($W$25:$W$56,$V$25:$V$56) -> 33511.958 | Q25: =$I$9*V25*W25/SUMPRODUCT($W$25:$W$56,$V$25:$V$56) -> 5.1556859 | R25: =IF($I$12="","",Q25/$I$12) -> 3.0327564 | S25: =IF(D25<>"",D25,P25) -> 36346 | T25: =IF(E25<>"",E25,Q25) -> 6 | U25: =IF(G25<>"",G25,R25) -> 4 | V25: 1 | W25: 1
A26: 2 | B26: 45963 | C26: вс | D26: =63254+31287+32389 -> 126930 | E26: 15 | F26: =IF(AND(E26<>"",E26<>0),D26/E26,"") -> 8462 | G26: 8 | H26: =IF(AND(G26<>"",G26<>0),D26/G26,"") -> 15866.25 | I26: 40 | J26: =IF(AND(G26<>"",G26<>0),E26/G26,"") -> 1.875 | K26: 63254 | M26: 31287 | N26: =IF(AND(I26<>"",I26<>0),G26/I26,"") -> 0.2 | O26: =D26/P26 -> 3.7876032 | P26: =$I$8*V26*W26/SUMPRODUCT($W$25:$W$56,$V$25:$V$56) -> 33511.958 | Q26: =$I$9*V26*W26/SUMPRODUCT($W$25:$W$58,$V$25:$V$58) -> 5.1556859 | R26: =IF($I$12="","",Q26/$I$12) -> 3.0327564 | S26: =IF(W26<>"",IF(D26<>"",D26,($I$8-SUM($S$25:S25))*V26*W26/SUMPRODUCT($W26:$W$56,$V26:$V$56)),"") -> 126930 | T26: =IF(W26<>"",IF(E26<>"",E26,($I$9-SUM($T$25:T25))*V26*W26/SUMPRODUCT($W26:$W$58,$V26:$V$58)),"") -> 15 | U26: =IF(W26<>"",IF($I$12<>"",IF(G26<>"",G26,($I$9/$I$12-SUM($U$25:U25))*V26*W26/SUMPRODUCT($W26:$W$58,$V26:$V$58)),""),"") -> 8 | V26: 1 | W26: 1
A27: 3 | B27: 45964 | C27: пн | D27: 8692 | E27: 1 | F27: 8692 | G27: 1 | H27: =IF(AND(G27<>"",G27<>0),D27/G27,"") -> 8692 | I27: 25 | J27: =IF(AND(G27<>"",G27<>0),E27/G27,"") -> 1 | K27: 8692 | N27: =IF(AND(I27<>"",I27<>0),G27/I27,"") -> 0.04 | O27: =D27/P27 -> 0.2593701 | P27: =$I$8*V27*W27/SUMPRODUCT($W$25:$W$56,$V$25:$V$56) -> 33511.958 | Q27: =$I$9*V27*W27/SUMPRODUCT($W$25:$W$58,$V$25:$V$58) -> 5.1556859 | R27: =IF($I$12="","",Q27/$I$12) -> 3.0327564 | S27: =IF(W27<>"",IF(D27<>"",D27,($I$8-SUM($S$25:S26))*V27*W27/SUMPRODUCT($W27:$W$58,$V27:$V$58)),"") -> 8692 | T27: =IF(W27<>"",IF(E27<>"",E27,($I$9-SUM($T$25:T26))*V27*W27/SUMPRODUCT($W27:$W$58,$V27:$V$58)),"") -> 1 | U27: =IF(W27<>"",IF($I$12<>"",IF(G27<>"",G27,($I$9/$I$12-SUM($U$25:U26))*V27*W27/SUMPRODUCT($W27:$W$58,$V27:$V$58)),""),"") -> 1 | V27: 1 | W27: 1
A28: 4 | B28: 45965 | C28: вт | D28: =8539+16490 -> 25029 | E28: 3 | F28: =IF(AND(E28<>"",E28<>0),D28/E28,"") -> 8343 | G28: 3 | H28: =IF(AND(G28<>"",G28<>0),D28/G28,"") -> 8343 | I28: 30 | J28: =IF(AND(G28<>"",G28<>0),E28/G28,"") -> 1 | K28: 16490 | N28: =IF(AND(I28<>"",I28<>0),G28/I28,"") -> 0.1 | O28: =D28/P28 -> 0.74686772 | P28: =$I$8*V28*W28/SUMPRODUCT($W$25:$W$56,$V$25:$V$56) -> 33511.958 | Q28: =$I$9*V28*W28/SUMPRODUCT($W$25:$W$58,$V$25:$V$58) -> 5.1556859 | R28: =IF($I$12="","",Q28/$I$12) -> 3.0327564 | S28: =IF(W28<>"",IF(D28<>"",D28,($I$8-SUM($S$25:S27))*V28*W28/SUMPRODUCT($W28:$W$58,$V28:$V$58)),"") -> 25029 | T28: =IF(W28<>"",IF(E28<>"",E28,($I$9-SUM($T$25:T27))*V28*W28/SUMPRODUCT($W28:$W$58,$V28:$V$58)),"") -> 3 | U28: =IF(W28<>"",IF($I$12<>"",IF(G28<>"",G28,($I$9/$I$12-SUM($U$25:U27))*V28*W28/SUMPRODUCT($W28:$W$58,$V28:$V$58)),""),"") -> 3 | V28: 1 | W28: 1
A29: 5 | B29: 45966 | C29: ср | D29: 28069 | E29: 6 | F29: =IF(AND(E29<>"",E29<>0),D29/E29,"") -> 4678.1667 | G29: 2 | H29: =IF(AND(G29<>"",G29<>0),D29/G29,"") -> 14034.5 | I29: 35 | J29: =IF(AND(G29<>"",G29<>0),E29/G29,"") -> 3 | N29: =IF(AND(I29<>"",I29<>0),G29/I29,"") -> 0.057142857 | O29: =D29/P29 -> 0.83758161 | P29: =$I$8*V29*W29/SUMPRODUCT($W$25:$W$56,$V$25:$V$56) -> 33511.958 | Q29: =$I$9*V29*W29/SUMPRODUCT($W$25:$W$58,$V$25:$V$58) -> 5.1556859 | R29: =IF($I$12="","",Q29/$I$12) -> 3.0327564 | S29: =IF(W29<>"",IF(D29<>"",D29,($I$8-SUM($S$25:S28))*V29*W29/SUMPRODUCT($W29:$W$58,$V29:$V$58)),"") -> 28069 | T29: =IF(W29<>"",IF(E29<>"",E29,($I$9-SUM($T$25:T28))*V29*W29/SUMPRODUCT($W29:$W$58,$V29:$V$58)),"") -> 6 | U29: =IF(W29<>"",IF($I$12<>"",IF(G29<>"",G29,($I$9/$I$12-SUM($U$25:U28))*V29*W29/SUMPRODUCT($W29:$W$58,$V29:$V$58)),""),"") -> 2 | V29: 1 | W29: 1
A30: 6 | B30: 45967 | C30: чт | D30: 14400 | E30: 4 | F30: =IF(AND(E30<>"",E30<>0),D30/E30,"") -> 3600 | G30: 2 | H30: =IF(AND(G30<>"",G30<>0),D30/G30,"") -> 7200 | I30: 30 | J30: =IF(AND(G30<>"",G30<>0),E30/G30,"") -> 2 | N30: =IF(AND(I30<>"",I30<>0),G30/I30,"") -> 0.066666667 | O30: =D30/P30 -> 0.42969736 | P30: =$I$8*V30*W30/SUMPRODUCT($W$25:$W$56,$V$25:$V$56) -> 33511.958 | Q30: =$I$9*V30*W30/SUMPRODUCT($W$25:$W$58,$V$25:$V$58) -> 5.1556859 | R30: =IF($I$12="","",Q30/$I$12) -> 3.0327564 | S30: =IF(W30<>"",IF(D30<>"",D30,($I$8-SUM($S$25:S29))*V30*W30/SUMPRODUCT($W30:$W$58,$V30:$V$58)),"") -> 14400 | T30: =IF(W30<>"",IF(E30<>"",E30,($I$9-SUM($T$25:T29))*V30*W30/SUMPRODUCT($W30:$W$58,$V30:$V$58)),"") -> 4 | U30: =IF(W30<>"",IF($I$12<>"",IF(G30<>"",G30,($I$9/$I$12-SUM($U$25:U29))*V30*W30/SUMPRODUCT($W30:$W$58,$V30:$V$58)),""),"") -> 2 | V30: 1 | W30: 1
A31: 7 | B31: 45968 | C31: пт | D31: 25849 | E31: 6 | F31: =IF(AND(E31<>"",E31<>0),D31/E31,"") -> 4308.1667 | G31: 3 | H31: =IF(AND(G31<>"",G31<>0),D31/G31,"") -> 8616.3333 | I31: 20 | J31: =IF(AND(G31<>"",G31<>0),E31/G31,"") -> 2 | N31: =IF(AND(I31<>"",I31<>0),G31/I31,"") -> 0.15 | O31: =D31/P31 -> 0.7713366 | P31: =$I$8*V31*W31/SUMPRODUCT($W$25:$W$56,$V$25:$V$56) -> 33511.958 | Q31: =$I$9*V31*W31/SUMPRODUCT($W$25:$W$58,$V$25:$V$58) -> 5.1556859 | R31: =IF($I$12="","",Q31/$I$12) -> 3.0327564 | S31: =IF(W31<>"",IF(D31<>"",D31,($I$8-SUM($S$25:S30))*V31*W31/SUMPRODUCT($W31:$W$58,$V31:$V$58)),"") -> 25849 | T31: =IF(W31<>"",IF(E31<>"",E31,($I$9-SUM($T$25:T30))*V31*W31/SUMPRODUCT($W31:$W$58,$V31:$V$58)),"") -> 6 | U31: =IF(W31<>"",IF($I$12<>"",IF(G31<>"",G31,($I$9/$I$12-SUM($U$25:U30))*V31*W31/SUMPRODUCT($W31:$W$58,$V31:$V$58)),""),"") -> 3 | V31: 1 | W31: 1
A32: 8 | B32: 45969 | C32: сб | D32: =20809+5892 -> 26701 | E32: 3 | F32: =IF(AND(E32<>"",E32<>0),D32/E32,"") -> 8900.3333 | G32: 3 | H32: =IF(AND(G32<>"",G32<>0),D32/G32,"") -> 8900.3333 | I32: 20 | J32: =IF(AND(G32<>"",G32<>0),E32/G32,"") -> 1 | K32: 20809 | N32: =IF(AND(I32<>"",I32<>0),G32/I32,"") -> 0.15 | O32: =D32/P32 -> 0.79676036 | P32: =$I$8*V32*W32/SUMPRODUCT($W$25:$W$56,$V$25:$V$56) -> 33511.958 | Q32: =$I$9*V32*W32/SUMPRODUCT($W$25:$W$58,$V$25:$V$58) -> 5.1556859 | R32: =IF($I$12="","",Q32/$I$12) -> 3.0327564 | S32: =IF(W32<>"",IF(D32<>"",D32,($I$8-SUM($S$25:S31))*V32*W32/SUMPRODUCT($W32:$W$58,$V32:$V$58)),"") -> 26701 | T32: =IF(W32<>"",IF(E32<>"",E32,($I$9-SUM($T$25:T31))*V32*W32/SUMPRODUCT($W32:$W$58,$V32:$V$58)),"") -> 3 | U32: =IF(W32<>"",IF($I$12<>"",IF(G32<>"",G32,($I$9/$I$12-SUM($U$25:U31))*V32*W32/SUMPRODUCT($W32:$W$58,$V32:$V$58)),""),"") -> 3 | V32: 1 | W32: 1
A33: 9 | B33: 45970 | C33: вс | D33: 6992 | E33: 1 | F33: =IF(AND(E33<>"",E33<>0),D33/E33,"") -> 6992 | G33: 1 | H33: =IF(AND(G33<>"",G33<>0),D33/G33,"") -> 6992 | I33: 35 | J33: =IF(AND(G33<>"",G33<>0),E33/G33,"") -> 1 | M33: 6992 | N33: =IF(AND(I33<>"",I33<>0),G33/I33,"") -> 0.028571429 | O33: =D33/P33 -> 0.20864194 | P33: =$I$8*V33*W33/SUMPRODUCT($W$25:$W$56,$V$25:$V$56) -> 33511.958 | Q33: =$I$9*V33*W33/SUMPRODUCT($W$25:$W$58,$V$25:$V$58) -> 5.1556859 | R33: =IF($I$12="","",Q33/$I$12) -> 3.0327564 | S33: =IF(W33<>"",IF(D33<>"",D33,($I$8-SUM($S$25:S32))*V33*W33/SUMPRODUCT($W33:$W$58,$V33:$V$58)),"") -> 6992 | T33: =IF(W33<>"",IF(E33<>"",E33,($I$9-SUM($T$25:T32))*V33*W33/SUMPRODUCT($W33:$W$58,$V33:$V$58)),"") -> 1 | U33: =IF(W33<>"",IF($I$12<>"",IF(G33<>"",G33,($I$9/$I$12-SUM($U$25:U32))*V33*W33/SUMPRODUCT($W33:$W$58,$V33:$V$58)),""),"") -> 1 | V33: 1 | W33: 1
A34: 10 | B34: 45971 | C34: пн | D34: 30575 | E34: 3 | F34: =IF(AND(E34<>"",E34<>0),D34/E34,"") -> 10191.667 | G34: 2 | H34: =IF(AND(G34<>"",G34<>0),D34/G34,"") -> 15287.5 | I34: 20 | J34: =IF(AND(G34<>"",G34<>0),E34/G34,"") -> 1.5 | K34: 15292 | N34: =IF(AND(I34<>"",I34<>0),G34/I34,"") -> 0.1 | O34: =D34/P34 -> 0.91236089 | P34: =$I$8*V34*W34/SUMPRODUCT($W$25:$W$56,$V$25:$V$56) -> 33511.958 | Q34: =$I$9*V34*W34/SUMPRODUCT($W$25:$W$58,$V$25:$V$58) -> 5.1556859 | R34: =IF($I$12="","",Q34/$I$12) -> 3.0327564 | S34: =IF(W34<>"",IF(D34<>"",D34,($I$8-SUM($S$25:S33))*V34*W34/SUMPRODUCT($W34:$W$58,$V34:$V$58)),"") -> 30575 | T34: =IF(W34<>"",IF(E34<>"",E34,($I$9-SUM($T$25:T33))*V34*W34/SUMPRODUCT($W34:$W$58,$V34:$V$58)),"") -> 3 | U34: =IF(W34<>"",IF($I$12<>"",IF(G34<>"",G34,($I$9/$I$12-SUM($U$25:U33))*V34*W34/SUMPRODUCT($W34:$W$58,$V34:$V$58)),""),"") -> 2 | V34: 1 | W34: 1
A35: 11 | B35: 45972 | C35: вт | D35: 71465 | E35: 4 | F35: =IF(AND(E35<>"",E35<>0),D35/E35,"") -> 17866.25 | G35: 2 | H35: =IF(AND(G35<>"",G35<>0),D35/G35,"") -> 35732.5 | I35: 20 | J35: =IF(AND(G35<>"",G35<>0),E35/G35,"") -> 2 | K35: 68170 | N35: =IF(AND(I35<>"",I35<>0),G35/I35,"") -> 0.1 | O35: =D35/P35 -> 2.1325223 | P35: =$I$8*V35*W35/SUMPRODUCT($W$25:$W$56,$V$25:$V$56) -> 33511.958 | Q35: =$I$9*V35*W35/SUMPRODUCT($W$25:$W$58,$V$25:$V$58) -> 5.1556859 | R35: =IF($I$12="","",Q35/$I$12) -> 3.0327564 | S35: =IF(W35<>"",IF(D35<>"",D35,($I$8-SUM($S$25:S34))*V35*W35/SUMPRODUCT($W35:$W$58,$V35:$V$58)),"") -> 71465 | T35: =IF(W35<>"",IF(E34<>"",E34,($I$9-SUM($T$25:T34))*V35*W35/SUMPRODUCT($W35:$W$58,$V35:$V$58)),"") -> 3 | U35: =IF(W35<>"",IF($I$12<>"",IF(G35<>"",G35,($I$9/$I$12-SUM($U$25:U34))*V35*W35/SUMPRODUCT($W35:$W$58,$V35:$V$58)),""),"") -> 2 | V35: 1 | W35: 1
A36: 11 | B36: 45973 | C36: ср | D36: 39579 | E36: 4 | F36: =IF(AND(E36<>"",E36<>0),D36/E36,"") -> 9894.75 | G36: 2 | H36: =IF(AND(G36<>"",G36<>0),D36/G36,"") -> 19789.5 | I36: 15 | J36: =IF(AND(G36<>"",G36<>0),E36/G36,"") -> 2 | K36: 36977 | N36: =IF(AND(I36<>"",I36<>0),G36/I36,"") -> 0.13333333 | O36: =D36/P36 -> 1.1810411 | P36: =$I$8*V36*W36/SUMPRODUCT($W$25:$W$56,$V$25:$V$56) -> 33511.958 | Q36: =$I$9*V36*W36/SUMPRODUCT($W$25:$W$58,$V$25:$V$58) -> 5.1556859 | R36: =IF($I$12="","",Q36/$I$12) -> 3.0327564 | S36: =IF(W36<>"",IF(D36<>"",D36,($I$8-SUM($S$25:S35))*V36*W36/SUMPRODUCT($W36:$W$58,$V36:$V$58)),"") -> 39579 | T36: =IF(W36<>"",IF(E35<>"",E35,($I$9-SUM($T$25:T35))*V36*W36/SUMPRODUCT($W36:$W$58,$V36:$V$58)),"") -> 4 | U36: =IF(W36<>"",IF($I$12<>"",IF(G36<>"",G36,($I$9/$I$12-SUM($U$25:U35))*V36*W36/SUMPRODUCT($W36:$W$58,$V36:$V$58)),""),"") -> 2 | V36: 1 | W36: 1
A37: 13 | B37: 45974 | C37: чт | F37: =IF(AND(E37<>"",E37<>0),D37/E37,"") | H37: =IF(AND(G37<>"",G37<>0),D37/G37,"") | I37: 15 | J37: =IF(AND(G37<>"",G37<>0),E37/G37,"") | N37: =IF(AND(I37<>"",I37<>0),G37/I37,"") -> 0 | O37: =D37/P37 -> 0 | P37: =$I$8*V37*W37/SUMPRODUCT($W$25:$W$56,$V$25:$V$56) -> 33511.958 | Q37: =$I$9*V37*W37/SUMPRODUCT($W$25:$W$58,$V$25:$V$58) -> 5.1556859 | R37: =IF($I$12="","",Q37/$I$12) -> 3.0327564 | S37: =IF(W37<>"",IF(D37<>"",D37,($I$8-SUM($S$25:S36))*V37*W37/SUMPRODUCT($W37:$W$58,$V37:$V$58)),"") -> 30551.689 | T37: =IF(W37<>"",IF(E37<>"",E37,($I$9-SUM($T$25:T36))*V37*W37/SUMPRODUCT($W37:$W$58,$V37:$V$58)),"") -> 5.6840113 | U37: =IF(W37<>"",IF($I$12<>"",IF(G37<>"",G37,($I$9/$I$12-SUM($U$25:U36))*V37*W37/SUMPRODUCT($W37:$W$58,$V37:$V$58)),""),"") -> 3.2937623 | V37: 1 | W37: 1
A38: 14 | B38: 45975 | C38: пт | D38: 24575 | E38: 3 | F38: =IF(AND(E38<>"",E38<>0),D38/E38,"") -> 8191.6667 | G38: 2 | H38: =IF(AND(G38<>"",G38<>0),D38/G38,"") -> 12287.5 | I38: 20 | J38: =IF(AND(G38<>"",G38<>0),E38/G38,"") -> 1.5 | M38: 19883 | N38: =IF(AND(I38<>"",I38<>0),G38/I38,"") -> 0.1 | O38: =D38/P38 -> 0.73332032 | P38: =$I$8*V38*W38/SUMPRODUCT($W$25:$W$56,$V$25:$V$56) -> 33511.958 | Q38: =$I$9*V38*W38/SUMPRODUCT($W$25:$W$58,$V$25:$V$58) -> 5.1556859 | R38: =IF($I$12="","",Q38/$I$12) -> 3.0327564 | S38: =IF(W38<>"",IF(D38<>"",D38,($I$8-SUM($S$25:S37))*V38*W38/SUMPRODUCT($W38:$W$58,$V38:$V$58)),"") -> 24575 | T38: =IF(W38<>"",IF(E38<>"",E38,($I$9-SUM($T$25:T37))*V38*W38/SUMPRODUCT($W38:$W$58,$V38:$V$58)),"") -> 3 | U38: =IF(W38<>"",IF($I$12<>"",IF(G38<>"",G38,($I$9/$I$12-SUM($U$25:U37))*V38*W38/SUMPRODUCT($W38:$W$58,$V38:$V$58)),""),"") -> 2 | V38: 1 | W38: 1
A39: 15 | B39: 45976 | C39: сб | D39: 24262 | E39: 3 | F39: =IF(AND(E39<>"",E39<>0),D39/E39,"") -> 8087.3333 | G39: 1 | H39: =IF(AND(G39<>"",G39<>0),D39/G39,"") -> 24262 | I39: 15 | J39: =IF(AND(G39<>"",G39<>0),E39/G39,"") -> 3 | K39: 11155 | N39: =IF(AND(I39<>"",I39<>0),G39/I39,"") -> 0.066666667 | O39: =D39/P39 -> 0.72398037 | P39: =$I$8*V39*W39/SUMPRODUCT($W$25:$W$56,$V$25:$V$56) -> 33511.958 | Q39: =$I$9*V39*W39/SUMPRODUCT($W$25:$W$58,$V$25:$V$58) -> 5.1556859 | R39: =IF($I$12="","",Q39/$I$12) -> 3.0327564 | S39: =IF(W39<>"",IF(D39<>"",D39,($I$8-SUM($S$25:S38))*V39*W39/SUMPRODUCT($W39:$W$58,$V39:$V$58)),"") -> 24262 | T39: =IF(W39<>"",IF(E39<>"",E39,($I$9-SUM($T$25:T38))*V39*W39/SUMPRODUCT($W39:$W$58,$V39:$V$58)),"") -> 3 | U39: =IF(W39<>"",IF($I$12<>"",IF(G39<>"",G39,($I$9/$I$12-SUM($U$25:U38))*V39*W39/SUMPRODUCT($W39:$W$58,$V39:$V$58)),""),"") -> 1 | V39: 1 | W39: 1
A40: 16 | B40: 45979 | C40: вт | D40: 25769 | E40: 4 | F40: =IF(AND(E40<>"",E40<>0),D40/E40,"") -> 6442.25 | G40: 3 | H40: =IF(AND(G40<>"",G40<>0),D40/G40,"") -> 8589.6667 | I40: 11 | J40: =IF(AND(G40<>"",G40<>0),E40/G40,"") -> 1.3333333 | K40: 6890 | N40: =IF(AND(I40<>"",I40<>0),G40/I40,"") -> 0.27272727 | O40: =D40/P40 -> 0.76894939 | P40: =$I$8*V40*W40/SUMPRODUCT($W$25:$W$56,$V$25:$V$56) -> 33511.958 | Q40: =$I$9*V40*W40/SUMPRODUCT($W$25:$W$58,$V$25:$V$58) -> 5.1556859 | R40: =IF($I$12="","",Q40/$I$12) -> 3.0327564 | S40: =IF(W40<>"",IF(D40<>"",D40,($I$8-SUM($S$25:S39))*V40*W40/SUMPRODUCT($W40:$W$58,$V40:$V$58)),"") -> 25769 | T40: =IF(W40<>"",IF(E40<>"",E40,($I$9-SUM($T$25:T39))*V40*W40/SUMPRODUCT($W40:$W$58,$V40:$V$58)),"") -> 4 | U40: =IF(W40<>"",IF($I$12<>"",IF(G40<>"",G40,($I$9/$I$12-SUM($U$25:U39))*V40*W40/SUMPRODUCT($W40:$W$58,$V40:$V$58)),""),"") -> 3 | V40: 1 | W40: 1
A41: 17 | B41: 45980 | C41: ср | D41: =6993+6393 -> 13386 | E41: 2 | F41: =IF(AND(E41<>"",E41<>0),D41/E41,"") -> 6693 | G41: 2 | H41: =IF(AND(G41<>"",G41<>0),D41/G41,"") -> 6693 | I41: 10 | J41: =IF(AND(G41<>"",G41<>0),E41/G41,"") -> 1 | K41: 6993 | N41: =IF(AND(I41<>"",I41<>0),G41/I41,"") -> 0.2 | O41: =D41/P41 -> 0.3994395 | P41: =$I$8*V41*W41/SUMPRODUCT($W$25:$W$56,$V$25:$V$56) -> 33511.958 | Q41: =$I$9*V41*W41/SUMPRODUCT($W$25:$W$58,$V$25:$V$58) -> 5.1556859 | R41: =IF($I$12="","",Q41/$I$12) -> 3.0327564 | S41: =IF(W41<>"",IF(D41<>"",D41,($I$8-SUM($S$25:S40))*V41*W41/SUMPRODUCT($W41:$W$58,$V41:$V$58)),"") -> 13386 | T41: =IF(W41<>"",IF(E41<>"",E41,($I$9-SUM($T$25:T40))*V41*W41/SUMPRODUCT($W41:$W$58,$V41:$V$58)),"") -> 2 | U41: =IF(W41<>"",IF($I$12<>"",IF(G41<>"",G41,($I$9/$I$12-SUM($U$25:U40))*V41*W41/SUMPRODUCT($W41:$W$58,$V41:$V$58)),""),"") -> 2 | V41: 1 | W41: 1
A42: 18 | B42: 45981 | C42: чт | F42: =IF(AND(E42<>"",E42<>0),D42/E42,"") | H42: =IF(AND(G42<>"",G42<>0),D42/G42,"") | I42: 10 | J42: =IF(AND(G42<>"",G42<>0),E42/G42,"") | N42: =IF(AND(I42<>"",I42<>0),G42/I42,"") -> 0 | O42: =D42/P42 -> 0 | P42: =$I$8*V42*W42/SUMPRODUCT($W$25:$W$56,$V$25:$V$56) -> 33511.958 | Q42: =$I$9*V42*W42/SUMPRODUCT($W$25:$W$58,$V$25:$V$58) -> 5.1556859 | R42: =IF($I$12="","",Q42/$I$12) -> 3.0327564 | S42: =IF(W42<>"",IF(D42<>"",D42,($I$8-SUM($S$25:S41))*V42*W42/SUMPRODUCT($W42:$W$58,$V42:$V$58)),"") -> 34828.534 | T42: =IF(W42<>"",IF(E42<>"",E42,($I$9-SUM($T$25:T41))*V42*W42/SUMPRODUCT($W42:$W$58,$V42:$V$58)),"") -> 7.026017 | U42: =IF(W42<>"",IF($I$12<>"",IF(G42<>"",G42,($I$9/$I$12-SUM($U$25:U41))*V42*W42/SUMPRODUCT($W42:$W$58,$V42:$V$58)),""),"") -> 3.9406435 | V42: 1 | W42: 1
...

Sheet Уразгильдеева Е. Р. 
B1: =TODAY()-1 -> 46000
B2: (отчетная дата) | J2: ЕЖЕДНЕВНЫЙ ОТЧЕТ О ПРОДАЖАХ
B3: Осталось до выполнения плана!!! | J3: =График!B28 -> Уразгильдеева Екатерина
C4: =I8-D50 -> 470227.08 | E4: =IF(I8<>0, C4/I8, 0) -> 1
F6: Целевые показатели
F7: Показатель | I7: План | J7: Факт | K7: % выполнения | L7: Прогноз выполнения | M7: % выполнения по прогнозу | N7: Отклонение | O7: Факт аналогичного месяца прошлого года | P7: Отклонение LFL
F8: Выручка | I8: ='Ялта, Ленина, 18'!I8/График!AJ31*График!AJ28 -> 470227.08 | J8: =D57 -> 263849 | K8: =IF(AND(I8<>"",I8<>0,J8<>""),J8/I8,"") -> 0.56110975 | L8: =IF(SUMIF($D$25:$D$56,">=0",$P$25:$P$56)<>0,I8*D57/SUMIF($D$25:$D$56,">=0",$P$25:$P$56),0) -> 343003.7 | M8: =IF(AND(I8<>"",I8<>0,L8<>"",L8<>0),L8/I8,"") -> 0.72944267 | N8: =IF(AND(J8<>0,J8<>"",I8<>0,I8<>""),L8-I8,"") -> -127223.38 | P8: =IF(AND(O8<>"", O8<>0, L8<>"", L8<>0), -O8+L8, "") | Q8: =IF(AND(P8<>"", P8<>0, O8<>0, O8<>""), P8/O8, "")
F9: Кол-во изделий | I9: =I8/I11 -> 72.342628 | J9: =E57 -> 37 | K9: =IF(AND(I9<>"", I9<>0, J9<>""), J9/I9, "") -> 0.51145502 | L9: =IF(SUMIF($E$25:$E$54,">=0",$Q$25:$Q$54)<>0,I9*E57/SUMIF($E$25:$E$54,">=0",$Q$25:$Q$54),0) -> 48.1 | M9: =IF(AND(I9<>"",I9<>0,L9<>"",L9<>0),L9/I9,"") -> 0.66489152 | N9: =IF(AND(J9<>0,J9<>"",I9<>0,I9<>""),L9-I9,"") -> -24.242628 | O9: =O8/O11 -> #DIV/0! | P9: =IF(AND(O9<>"", O9<>0, L9<>"", L9<>0), -O9+L9, "") -> #DIV/0! | Q9: =IF(AND(P9<>"", P9<>0, O9<>0, O9<>""), P9/O9, "") -> #DIV/0!
F10: Средний чек | I10: =I11*I12 -> 11050 | J10: =H57 -> 11993.136 | K10: =IF(AND(I10<>"", I10<>0, J10<>""), J10/I10, "") -> 1.0853517 | L10: =J10 -> 11993.136 | M10: =IF(AND(I10<>"",I10<>0,L10<>"",L10<>0),L10/I10,"") -> 1.0853517 | N10: =IF(AND(J10<>0,J10<>"",I10<>0,I10<>""),L10-I10,"") -> 943.13636 | O10: =O11*O12 -> 0 | P10: =IF(AND(O10<>"", O10<>0, L10<>"", L10<>0), -O10+L10, "") | Q10: =IF(AND(P10<>"", P10<>0, O10<>0, O10<>""), P10/O10, "") | S10: IS | V10: =M23 -> Agafi
F11: Средняя стоимость изделия | I11: ='Ялта, Ленина, 18'!I11 -> 6500 | J11: =F57 -> 7131.0541 | K11: =IF(AND(I11<>"", I11<>0, J11<>""), J11/I11, "") -> 1.0970852 | L11: =IF(L9>0,L8/L9,"") -> 7131.0541 | M11: =IF(AND(I11<>"",I11<>0,L11<>"",L11<>0),L11/I11,"") -> 1.0970852 | N11: =IF(AND(J11<>0,J11<>"",I11<>0,I11<>""),L11-I11,"") -> 631.05405 | P11: =IF(AND(O11<>"", O11<>0, L11<>"", L11<>0), -O11+L11, "") | Q11: =IF(AND(P11<>"", P11<>0, O11<>0, O11<>""), P11/O11, "")
F12: Длина чека | I12: ='Ялта, Ленина, 18'!I12 -> 1.7 | J12: =J57 -> 1.6818182 | K12: =IF(AND(I12<>"", I12<>0, J12<>""), J12/I12, "") -> 0.98930481 | L12: =J12 -> 1.6818182 | M12: =IF(AND(I12<>"",I12<>0,L12<>"",L12<>0),L12/I12,"") -> 0.98930481 | N12: =IF(AND(J12<>0,J12<>"",I12<>0,I12<>""),L12-I12,"") -> -0.018181818 | P12: =IF(AND(O12<>"", O12<>0, L12<>"", L12<>0), -O12+L12, "") | Q12: =IF(AND(P12<>"", P12<>0, O12<>0, O12<>""), P12/O12, "") | S12: ='Ялта, Ленина, 18'!S12*График!AJ28/График!AJ31 -> 116057.69 | T12: =L57 -> 0 | U12: =S12-T12 -> 116057.69 | V12: ='Ялта, Ленина, 18'!V12/График!AJ31*График!AJ28 -> 109230.77 | W12: =M57 -> 0 | X12: =V12-W12 -> 109230.77
F13: Кол-во чеков | I13: =IF(I12<>0, I9/I12, "") -> 42.554487 | J13: =G57 -> 22 | K13: =IF(AND(I13<>"", I13<>0, J13<>""), J13/I13, "") -> 0.51698426 | L13: =IF(SUMIF($G$25:$G$54,">=0",$R$25:$R$54)<>0,I13*G57/SUMIF($G$25:$G$54,">=0",$R$25:$R$54),"") -> 28.6 | M13: =IF(AND(I13<>"",I13<>0,L13<>"",L13<>0),L13/I13,"") -> 0.67207954 | N13: =IF(AND(J13<>0,J13<>"",I13<>0,I13<>""),L13-I13,"") -> -13.954487 | P13: =IF(AND(O13<>"", O13<>0, L13<>"", L13<>0), -O13+L13, "") | Q13: =IF(AND(P13<>"", P13<>0, O13<>0, O13<>""), P13/O13, "") | S13: =T12/S12 -> 0 | T13: =S13/J14*I14 -> 0 | V13: =W12/V12 -> 0 | W13: =V13/J14*I14 -> 0
F14: Кол-во смен план/отработано | I14: =График!AI28 -> 13 | J14: 13 | K14: =IF(AND(I14<>"", I14<>0, J14<>""), J14/I14, "") -> 1 | L14: =I14 -> 13 | M14: =IF(AND(I14<>"",I14<>0,L14<>"",L14<>0),L14/I14,"") -> 1 | N14: =IF(AND(J14<>0,J14<>"",I14<>0,I14<>""),L14-I14,"") -> 0 | P14: =IF(AND(O14<>"", O14<>0, L14<>"", L14<>0), -O14+L14, "") | Q14: =IF(AND(P14<>"", P14<>0, O14<>0, O14<>""), P14/O14, "")
F15: Средние продажи в смену | I15: ='Ялта, Ленина, 18'!I15 -> 68878.333 | J15: =J8/J14 -> 20296.077 | K15: =IF(AND(I15<>"", I15<>0, J15<>""), J15/I15, "") -> 0.29466562 | L15: =J15 -> 20296.077 | M15: =IF(AND(I15<>"",I15<>0,L15<>"",L15<>0),L15/I15,"") -> 0.29466562 | N15: =IF(AND(J15<>0,J15<>"",I15<>0,I15<>""),L15-I15,"") -> -48582.256 | P15: =IF(AND(O15<>"", O15<>0, L15<>"", L15<>0), -O15+L15, "") | Q15: =IF(AND(P15<>"", P15<>0, O15<>0, O15<>""), P15/O15, "")
F16: Отставание/Перевыполнение | J16: =J8-I15*J14 -> -631569.33 | K16: =IF(AND(I16<>"", I16<>0, J16<>""), J16/I16, "") | L16: =J16 -> -631569.33 | M16: =IF(AND(I16<>"",I16<>0,L16<>"",L16<>0),L16/I16,"") | N16: =IF(AND(J16<>0,J16<>"",I16<>0,I16<>""),L16-I16,"") | P16: =IF(AND(O16<>"", O16<>0, L16<>"", L16<>0), -O16+L16, "") | Q16: =IF(AND(P16<>"", P16<>0, O16<>0, O16<>""), P16/O16, "") | S16: UNOde50
F17: Трафик | I17: ='Ялта, Ленина, 18'!I17/График!AJ31*График!AJ28 -> 386.85897 | J17: =I57 -> 237 | K17: =IF(AND(I17<>"", I17<>0, J17<>""), J17/I17, "") -> 0.61262635 | L17: =J17/J14*I14 -> 237 | M17: =IF(AND(I17<>"",I17<>0,L17<>"",L17<>0),L17/I17,"") -> 0.61262635 | N17: =IF(AND(J17<>0,J17<>"",I17<>0,I17<>""),L17-I17,"") -> -149.85897 | P17: =IF(AND(O17<>"", O17<>0, L17<>"", L17<>0), -O17+L17, "") | Q17: =IF(AND(P17<>"", P17<>0, O17<>0, O17<>""), P17/O17, "")
K18: =IF(AND(I18<>"", I18<>0, J18<>""), J18/I18, "") | L18: =J18 -> 0 | M18: =IF(AND(I18<>"",I18<>0,L18<>"",L18<>0),L18/I18,"") | N18: =IF(AND(J18<>0,J18<>"",I18<>0,I18<>""),L18-I18,"") | O18: 0 | P18: =IF(AND(O18<>"", O18<>0, L18<>"", L18<>0), -O18+L18, "") | Q18: =IF(AND(P18<>"", P18<>0, O18<>0, O18<>""), P18/O18, "") | S18: ='Ялта, Ленина, 18'!S18*График!AJ28/График!AJ31 -> 232115.38 | T18: =K57 -> 91284
K19: =IF(AND(I19<>"", I19<>0, J19<>""), J19/I19, "") | L19: =J19 -> 0 | M19: =IF(AND(I19<>"",I19<>0,L19<>"",L19<>0),L19/I19,"") | N19: =IF(AND(J19<>0,J19<>"",I19<>0,I19<>""),L19-I19,"") | O19: 0 | P19: =IF(AND(O19<>"", O19<>0, L19<>"", L19<>0), -O19+L19, "") | Q19: =IF(AND(P19<>"", P19<>0, O19<>0, O19<>""), P19/O19, "") | S19: =T18/S18 -> 0.39326993 | T19: =S19/J14*I14 -> 0.39326993
F20: Конверсия план/факт | I20: ='Ялта, Ленина, 18'!I20 -> 0.11 | J20: =N57 -> 0.092827004 | K20: =J20/I20 -> 0.84388186 | L20: =IF(AND(K8<>0,I14<>0,I57<>0),(I57*N57+(I57/K8-I57)*I20)/(I57/K8),0) -> 0.10036406 | M20: =IF(AND(I20<>"",I20<>0,L20<>"",L20<>0),L20/I20,"") -> 0.91240059 | N20: =IF(AND(J20<>0,J20<>"",I20<>0,I20<>""),L20-I20,"") -> -0.0096359353 | P20: =IF(AND(O20<>"", O20<>0, L20<>"", L20<>0), -O20+L20, "") | Q20: =IF(AND(P20<>"", P20<>0, O20<>0, O20<>""), P20/O20, "")
B22: Факт продаж за месяц | O22: % выполнения дневного плана | P22: Раcпределение плана по дням
