Workbook
Name маг: NA()

Sheet Ялта, Ленина, 18
B1: =TODAY()-1 -> 46171
B2: (отчетная дата)
C3: Осталось до выполнения плана!!! | I3: =График!B3 -> ул. Набережная Ленина, 18
C4: =I8-D56 -> 698754.6 | E4: =IF(I8<>0, C4/I8, 0) -> 0.28416607
D5: =C4/(I14-J14) -> #DIV/0!
F6: Целевые показатели
F7: Показатель | I7: План | J7: Факт | K7: % выполнения | L7: Прогноз выполнения | M7: % выполнения по прогнозу | N7: Отклонение | O7: Факт аналогичного месяца прошлого года | P7: Отклонение LFL
F8: Выручка | I8: =I11*I12*I13 -> 2458965.6 | J8: =D56 -> 1760211 | K8: =IF(AND(I8<>"",I8<>0,J8<>""),J8/I8,"") -> 0.71583393 | L8: =IF(SUMIF($D$25:$D$55,">=0",$U$25:$U$55)<>0,I8*D56/SUMIF($D$25:$D$55,">=0",$U$25:$U$55),0) -> 1760211 | M8: =IF(AND(I8<>"", I8<>0, L8<>"", L8<>0), L8/I8, "") -> 0.71583393 | N8: =IF(AND(J8<>0, J8<>"", I8<>0, I8<>""), L8-I8, "") -> -698754.6 | O8: 2068738.6 | P8: =IF(AND(O8<>"", O8<>0, L8<>"", L8<>0), -O8+L8, "") -> -308527.6 | Q8: =IF(AND(P8<>"",P8<>0,O8<>0,O8<>""),P8/O8,"") -> -0.14913803
F9: Кол-во изделий | I9: =I8/I11 -> 353.808 | J9: =E56 -> 230 | K9: =IF(AND(I9<>"", I9<>0, J9<>""), J9/I9, "") -> 0.65007009 | L9: =IF(SUMIF($E$25:$E$55,">=0",$V$25:$V$55)<>0,I9*E56/SUMIF($E$25:$E$55,">=0",$V$25:$V$55),0) -> 230 | M9: =IF(AND(I9<>"", I9<>0, L9<>"", L9<>0), L9/I9, "") -> 0.65007009 | N9: =IF(AND(J9<>0, J9<>"", I9<>0, I9<>""), L9-I9, "") -> -123.808 | O9: 390 | P9: =IF(AND(O9<>"", O9<>0, L9<>"", L9<>0), -O9+L9, "") -> -160 | Q9: =IF(AND(P9<>"",P9<>0,O9<>0,O9<>""),P9/O9,"") -> -0.41025641
F10: Средний чек | I10: =I11*I12 -> 12649 | J10: =H56 -> 13234.669 | K10: =IF(AND(I10<>"", I10<>0, J10<>""), J10/I10, "") -> 1.0463016 | L10: =J10 -> 13234.669 | M10: =IF(AND(I10<>"", I10<>0, L10<>"", L10<>0), L10/I10, "") -> 1.0463016 | N10: =IF(AND(J10<>0, J10<>"", I10<>0, I10<>""), L10-I10, "") -> 585.66917 | O10: 10608.916 | P10: =IF(AND(O10<>"", O10<>0, L10<>"", L10<>0), -O10+L10, "") -> 2625.7533 | Q10: =IF(AND(P10<>"",P10<>0,O10<>0,O10<>""),P10/O10,"") -> 0.24750439
F11: Средняя стоимость изделия | I11: 6950 | J11: =F56 -> 7653.0913 | K11: =IF(AND(I11<>"", I11<>0, J11<>""), J11/I11, "") -> 1.1011642 | L11: =IF(L9>0, L8/L9, "") -> 7653.0913 | M11: =IF(AND(I11<>"", I11<>0, L11<>"", L11<>0), L11/I11, "") -> 1.1011642 | N11: =IF(AND(J11<>0, J11<>"", I11<>0, I11<>""), L11-I11, "") -> 703.0913 | O11: 5304.4579 | P11: =IF(AND(O11<>"", O11<>0, L11<>"", L11<>0), -O11+L11, "") -> 2348.6334 | Q11: =IF(AND(P11<>"",P11<>0,O11<>0,O11<>""),P11/O11,"") -> 0.44276595
F12: Длина чека | I12: 1.82 | J12: =J56 -> 1.7293233 | K12: =IF(AND(I12<>"", I12<>0, J12<>""), J12/I12, "") -> 0.95017764 | L12: =J12 -> 1.7293233 | M12: =IF(AND(I12<>"", I12<>0, L12<>"", L12<>0), L12/I12, "") -> 0.95017764 | N12: =IF(AND(J12<>0, J12<>"", I12<>0, I12<>""), L12-I12, "") -> -0.090676692 | O12: 2 | P12: =IF(AND(O12<>"", O12<>0, L12<>"", L12<>0), -O12+L12, "") -> -0.27067669 | Q12: =IF(AND(P12<>"",P12<>0,O12<>0,O12<>""),P12/O12,"") -> -0.13533835
F13: Кол-во чеков | I13: =I17*I20 -> 194.4 | J13: =G56 -> 133 | K13: =IF(AND(I13<>"", I13<>0, J13<>""), J13/I13, "") -> 0.68415638 | L13: =IF(SUMIF($G$25:$G$55,">=0",$W$25:$W$55)<>0,I13*G56/SUMIF($G$25:$G$55,">=0",$W$25:$W$55),"") -> 133 | M13: =IF(AND(I13<>"", I13<>0, L13<>"", L13<>0), L13/I13, "") -> 0.68415638 | N13: =IF(AND(J13<>0, J13<>"", I13<>0, I13<>""), L13-I13, "") -> -61.4 | O13: 195 | P13: =IF(AND(O13<>"", O13<>0, L13<>"", L13<>0), -O13+L13, "") -> -62 | Q13: =IF(AND(P13<>"",P13<>0,O13<>0,O13<>""),P13/O13,"") -> -0.31794872
F14: Кол-во смен | I14: =График!AK6 -> 30 | J14: 30 | K14: =IF(AND(I14<>"", I14<>0, J14<>""), J14/I14, "") -> 1 | L14: =I14 -> 30 | M14: =IF(AND(I14<>"", I14<>0, L14<>"", L14<>0), L14/I14, "") -> 1 | N14: =IF(AND(J14<>0, J14<>"", I14<>0, I14<>""), L14-I14, "") -> 0 | O14: 30 | P14: =IF(AND(O14<>"", O14<>0, L14<>"", L14<>0), -O14+L14, "") -> 0 | Q14: =IF(AND(P14<>"",P14<>0,O14<>0,O14<>""),P14/O14,"")
F15: Средние продажи в смену | I15: =I8/I14 -> 81965.52 | J15: =J8/J14 -> 58673.7 | K15: =IF(AND(I15<>"", I15<>0, J15<>""), J15/I15, "") -> 0.71583393 | L15: =J15 -> 58673.7 | M15: =IF(AND(I15<>"", I15<>0, L15<>"", L15<>0), L15/I15, "") -> 0.71583393 | N15: =IF(AND(J15<>0, J15<>"", I15<>0, I15<>""), L15-I15, "") -> -23291.82 | O15: 68957.953 | P15: =IF(AND(O15<>"", O15<>0, L15<>"", L15<>0), -O15+L15, "") -> -10284.253 | Q15: =IF(AND(P15<>"",P15<>0,O15<>0,O15<>""),P15/O15,"") -> -0.14913803
F16: Отставание/Перевыполнение | J16: =J8-I15*J14 -> -698754.6 | K16: =IF(AND(I16<>"", I16<>0, J16<>""), J16/I16, "") | L16: =J16 -> -698754.6 | M16: =IF(AND(I16<>"", I16<>0, L16<>"", L16<>0), L16/I16, "") | N16: =IF(AND(J16<>0, J16<>"", I16<>0, I16<>""), L16-I16, "") | O16: -519369.56 | P16: =IF(AND(O16<>"", O16<>0, L16<>"", L16<>0), -O16+L16, "") -> -179385.04 | Q16: =IF(AND(P16<>"",P16<>0,O16<>0,O16<>""),P16/O16,"") -> 0.34538998
F17: Трафик | I17: 1800 | J17: =I56 -> 1591.2 | K17: =IF(AND(I17<>"", I17<>0, J17<>""), J17/I17, "") -> 0.884 | L17: =J17/J14*I14 -> 1591.2 | M17: =IF(AND(I17<>"", I17<>0, L17<>"", L17<>0), L17/I17, "") -> 0.884 | N17: =IF(AND(J17<>0, J17<>"", I17<>0, I17<>""), L17-I17, "") -> -208.8 | O17: 893 | P17: =IF(AND(O17<>"", O17<>0, L17<>"", L17<>0), -O17+L17, "") -> 698.2 | Q17: =IF(AND(P17<>"",P17<>0,O17<>0,O17<>""),P17/O17,"") -> 0.7818589
F18: Выручка на вошедшего | I18: =I8/I17 -> 1366.092 | J18: =J8/J17 -> 1106.2161 | K18: =IF(AND(I18<>"", I18<>0, J18<>""), J18/I18, "") -> 0.80976688 | L18: =J18 -> 1106.2161 | M18: =IF(AND(I18<>"", I18<>0, L18<>"", L18<>0), L18/I18, "") -> 0.80976688 | N18: =IF(AND(J18<>0, J18<>"", I18<>0, I18<>""), L18-I18, "") -> -259.87594 | P18: =IF(AND(O18<>"", O18<>0, L18<>"", L18<>0), -O18+L18, "") | Q18: =IF(AND(P18<>"",P18<>0,O18<>0,O18<>""),P18/O18,"")
K19: =IF(AND(I19<>"", I19<>0, J19<>""), J19/I19, "") | L19: =J19 -> 0 | M19: =IF(AND(I19<>"", I19<>0, L19<>"", L19<>0), L19/I19, "") | N19: =IF(AND(J19<>0, J19<>"", I19<>0, I19<>""), L19-I19, "") | O19: 0 | P19: =IF(AND(O19<>"", O19<>0, L19<>"", L19<>0), -O19+L19, "") | Q19: =IF(AND(P19<>"",P19<>0,O19<>0,O19<>""),P19/O19,"")
F20: Конверсия план/факт | I20: 0.108 | J20: =S56 -> 0.083584716 | K20: =J20/I20 -> 0.77393255 | L20: =IF(AND(K8<>0,I14<>0,I56<>0),(I56*S56+(I56/K8-I56)*I20)/(I56/K8),0) -> 0.090522711 | M20: =IF(AND(I20<>"", I20<>0, L20<>"", L20<>0), L20/I20, "") -> 0.83817325 | N20: =IF(AND(J20<>0, J20<>"", I20<>0, I20<>""), L20-I20, "") -> -0.017477289 | O20: 0.21836506 | P20: =IF(AND(O20<>"", O20<>0, L20<>"", L20<>0), -O20+L20, "") -> -0.12784235 | Q20: =IF(AND(P20<>"",P20<>0,O20<>0,O20<>""),P20/O20,"") -> -0.5854524
A22: Факт продаж за месяц | T22: % выполнения дневного плана | U22: Раcпределение плана по дням
A23: Сотрудник | B23: Дата | C23: День недели | D23: Выручка (руб) | E23: Кол-во единиц (шт.) | F23: Средняя стоимость изделия (руб.) | G23: Количество чеков (шт.) | H23: Средняя сумма чека (руб.) | I23: Трафик | J23: Длина чека (шт.) | K23: UNOde50 | L23: IS | M23: Agafi | N23: Kalliope | O23: Raganella | P23: CC/MP | Q23: Antyra | R23: SALE | S23: Конверсия | U23: выручка, план | V23: кол-во ед, план | W23: Кол-во чеков, план | X23: выручка, скорректир.план | Y23: кол-во ед, скорр. план | Z23: кол-во чеков, скорр. план | AA23: Коэфф. Дня Недели | AB23: Специфика месяца
B24: 1 | C24: 2 | D24: 3 | E24: 4 | F24: 5 | G24: 6 | H24: 7 | I24: 8 | J24: 9 | K24: 10 | L24: 11 | M24: 12 | N24: 13 | O24: 14 | P24: 15 | Q24: 16 | R24: 17 | S24: 17 | U24: 1 | V24: 2 | W24: 3 | X24: 4 | Y24: 5 | Z24: 6 | AA24: 10 | AB24: 11
A25: Рогалевич,Уразгильдеева | B25: 46113 | C25: ср | D25: 125962 | E25: 13 | F25: =IF(AND(E25<>"",E25<>0),D25/E25,"") -> 9689.3846 | G25: 6 | H25: =IF(AND(G25<>"",G25<>0),D25/G25,"") -> 20993.667 | I25: 74 | J25: =IF(AND(G25<>"",G25<>0),E25/G25,"") -> 2.1666667 | K25: 24291 | N25: 34542 | Q25: 21343 | S25: =IF(AND(I25<>"",I25<>0),G25/I25,"") -> 0.081081081 | T25: =D25/U25 -> 0.87086174 | U25: =$I$8*AA25*AB25/SUMPRODUCT($AB$25:$AB$55,$AA$25:$AA$55) -> 144640.64 | V25: =$I$9*AA25*AB25/SUMPRODUCT($AB$25:$AB$55,$AA$25:$AA$55) -> 20.811603 | W25: =IF($I$12="","",V25/$I$12) -> 11.434947 | X25: =IF(D25<>"",D25,U25) -> 125962 | Y25: =IF(E25<>"",E25,V25) -> 13 | Z25: =IF(G25<>"",G25,W25) -> 6 | AA25: 1 | AB25: 1.51
A26: Рогалевич,Уразгильдеева | B26: 46114 | C26: чт | D26: 19644 | E26: 4 | F26: =IF(AND(E26<>"",E26<>0),D26/E26,"") -> 4911 | G26: 2 | H26: =IF(AND(G26<>"",G26<>0),D26/G26,"") -> 9822 | I26: 39 | J26: =IF(AND(G26<>"",G26<>0),E26/G26,"") -> 2 | S26: =IF(AND(I26<>"",I26<>0),G26/I26,"") -> 0.051282051 | T26: =D26/U26 -> 0.89163826 | U26: =$I$8*AA26*AB26/SUMPRODUCT($AB$25:$AB$55,$AA$25:$AA$55) -> 22031.356 | V26: =$I$9*AA26*AB26/SUMPRODUCT($AB$25:$AB$55,$AA$25:$AA$55) -> 3.1699793 | W26: =IF($I$12="","",V26/$I$12) -> 1.7417469 | X26: =IF(AB26<>"",IF(D26<>"",D26,($I$8-SUM($X$25:X25))*AA26*AB26/SUMPRODUCT($AB26:$AB$55,$AA26:$AA$55)),"") -> 19644 | Y26: =IF(AB26<>"",IF(E26<>"",E26,($I$9-SUM($Y$25:Y25))*AA26*AB26/SUMPRODUCT($AB26:$AB$55,$AA26:$AA$55)),"") -> 4 | Z26: =IF(AB26<>"",IF(E26<>"",E26,($I$9-SUM($Y$25:Y25))*AA26*AB26/SUMPRODUCT($AB26:$AB$55,$AA26:$AA$55)),"") -> 4 | AA26: 1 | AB26: 0.23
A27: Рогалевич.Самошкина | B27: 46115 | C27: пт | D27: 25357 | E27: 6 | F27: =IF(AND(E27<>"",E27<>0),D27/E27,"") -> 4226.1667 | G27: 3 | H27: =IF(AND(G27<>"",G27<>0),D27/G27,"") -> 8452.3333 | I27: 53 | J27: =IF(AND(G27<>"",G27<>0),E27/G27,"") -> 2 | R27: 3795 | S27: =IF(AND(I27<>"",I27<>0),G27/I27,"") -> 0.056603774 | T27: =D27/U27 -> 0.88239538 | U27: =$I$8*AA27*AB27/SUMPRODUCT($AB$25:$AB$55,$AA$25:$AA$55) -> 28736.551 | V27: =$I$9*AA27*AB27/SUMPRODUCT($AB$25:$AB$55,$AA$25:$AA$55) -> 4.1347556 | W27: =IF($I$12="","",V27/$I$12) -> 2.2718437 | X27: =IF(AB27<>"",IF(D27<>"",D27,($I$8-SUM($X$25:X26))*AA27*AB27/SUMPRODUCT($AB27:$AB$55,$AA27:$AA$55)),"") -> 25357 | Y27: =IF(AB27<>"",IF(E27<>"",E27,($I$9-SUM($Y$25:Y26))*AA27*AB27/SUMPRODUCT($AB27:$AB$55,$AA27:$AA$55)),"") -> 6 | Z27: =IF(AB27<>"",IF(E27<>"",E27,($I$9-SUM($Y$25:Y26))*AA27*AB27/SUMPRODUCT($AB27:$AB$55,$AA27:$AA$55)),"") -> 6 | AA27: 1 | AB27: 0.3
A28: Рогалевич,Самошкина | B28: 46116 | C28: сб | D28: 29169 | E28: 4 | F28: 7292 | G28: 3 | H28: 9723 | I28: 53 | J28: =IF(AND(G28<>"",G28<>0),E28/G28,"") -> 1.3333333 | Q28: 14093 | S28: =IF(AND(I28<>"",I28<>0),G28/I28,"") -> 0.056603774 | T28: =D28/U28 -> 0.55366295 | U28: =$I$8*AA28*AB28/SUMPRODUCT($AB$25:$AB$55,$AA$25:$AA$55) -> 52683.677 | V28: =$I$9*AA28*AB28/SUMPRODUCT($AB$25:$AB$55,$AA$25:$AA$55) -> 7.5803852 | W28: =IF($I$12="","",V28/$I$12) -> 4.1650468 | X28: =IF(AB28<>"",IF(D28<>"",D28,($I$8-SUM($X$25:X27))*AA28*AB28/SUMPRODUCT($AB28:$AB$55,$AA28:$AA$55)),"") -> 29169 | Y28: =IF(AB28<>"",IF(E28<>"",E28,($I$9-SUM($Y$25:Y27))*AA28*AB28/SUMPRODUCT($AB28:$AB$55,$AA28:$AA$55)),"") -> 4 | Z28: =IF(AB28<>"",IF(E28<>"",E28,($I$9-SUM($Y$25:Y27))*AA28*AB28/SUMPRODUCT($AB28:$AB$55,$AA28:$AA$55)),"") -> 4 | AA28: 1 | AB28: 0.55
A29: Рогалевич.Уразгильеева | B29: 46117 | C29: вс | D29: 92463 | E29: 16 | F29: =IF(AND(E29<>"",E29<>0),D29/E29,"") -> 5778.9375 | G29: 6 | H29: =IF(AND(G29<>"",G29<>0),D29/G29,"") -> 15410.5 | I29: 69 | J29: =IF(AND(G29<>"",G29<>0),E29/G29,"") -> 2.6666667 | K29: 12293 | N29: 33570 | R29: =7380+6490 -> 13870 | S29: =IF(AND(I29<>"",I29<>0),G29/I29,"") -> 0.086956522 | T29: =D29/U29 -> 0.99513695 | U29: =$I$8*AA29*AB29/SUMPRODUCT($AB$25:$AB$55,$AA$25:$AA$55) -> 92914.849 | V29: =$I$9*AA29*AB29/SUMPRODUCT($AB$25:$AB$55,$AA$25:$AA$55) -> 13.369043 | W29: =IF($I$12="","",V29/$I$12) -> 7.345628 | X29: =IF(AB29<>"",IF(D29<>"",D29,($I$8-SUM($X$25:X28))*AA29*AB29/SUMPRODUCT($AB29:$AB$55,$AA29:$AA$55)),"") -> 92463 | Y29: =IF(AB29<>"",IF(E29<>"",E29,($I$9-SUM($Y$25:Y28))*AA29*AB29/SUMPRODUCT($AB29:$AB$55,$AA29:$AA$55)),"") -> 16 | Z29: =IF(AB29<>"",IF(E29<>"",E29,($I$9-SUM($Y$25:Y28))*AA29*AB29/SUMPRODUCT($AB29:$AB$55,$AA29:$AA$55)),"") -> 16 | AA29: 1 | AB29: 0.97
A30: Уразгильдеева | B30: 46118 | C30: пн | D30: 31933 | E30: 8 | F30: =IF(AND(E30<>"",E30<>0),D30/E30,"") -> 3991.625 | G30: 6 | H30: =IF(AND(G30<>"",G30<>0),D30/G30,"") -> 5322.1667 | I30: 53 | J30: =IF(AND(G30<>"",G30<>0),E30/G30,"") -> 1.3333333 | S30: =IF(AND(I30<>"",I30<>0),G30/I30,"") -> 0.11320755 | T30: =D30/U30 -> 1.1306329 | U30: =$I$8*AA30*AB30/SUMPRODUCT($AB$25:$AB$55,$AA$25:$AA$55) -> 28243.474 | V30: =$I$9*AA30*AB30/SUMPRODUCT($AB$25:$AB$55,$AA$25:$AA$55) -> 4.0638092 | W30: =IF($I$12="","",V30/$I$12) -> 2.2328622 | X30: =IF(AB30<>"",IF(D30<>"",D30,($I$8-SUM($X$25:X29))*AA30*AB30/SUMPRODUCT($AB30:$AB$55,$AA30:$AA$55)),"") -> 31933 | Y30: =IF(AB30<>"",IF(E30<>"",E30,($I$9-SUM($Y$25:Y29))*AA30*AB30/SUMPRODUCT($AB30:$AB$55,$AA30:$AA$55)),"") -> 8 | Z30: =IF(AB30<>"",IF(E30<>"",E30,($I$9-SUM($Y$25:Y29))*AA30*AB30/SUMPRODUCT($AB30:$AB$55,$AA30:$AA$55)),"") -> 8 | AA30: 1 | AB30: 0.29485244
A31: Самошкина | B31: 46119 | C31: вт | D31: 10534 | E31: 2 | F31: =IF(AND(E31<>"",E31<>0),D31/E31,"") -> 5267 | G31: 1 | H31: =IF(AND(G31<>"",G31<>0),D31/G31,"") -> 10534 | I31: 30 | J31: =IF(AND(G31<>"",G31<>0),E31/G31,"") -> 2 | S31: =IF(AND(I31<>"",I31<>0),G31/I31,"") -> 0.033333333 | T31: =D31/U31 -> 1.7303057 | U31: =$I$8*AA31*AB31/SUMPRODUCT($AB$25:$AB$55,$AA$25:$AA$55) -> 6087.9415 | V31: =$I$9*AA31*AB31/SUMPRODUCT($AB$25:$AB$55,$AA$25:$AA$55) -> 0.87596281 | W31: =IF($I$12="","",V31/$I$12) -> 0.48129824 | X31: =IF(AB31<>"",IF(D31<>"",D31,($I$8-SUM($X$25:X30))*AA31*AB31/SUMPRODUCT($AB31:$AB$55,$AA31:$AA$55)),"") -> 10534 | Y31: =IF(AB31<>"",IF(E31<>"",E31,($I$9-SUM($Y$25:Y30))*AA31*AB31/SUMPRODUCT($AB31:$AB$55,$AA31:$AA$55)),"") -> 2 | Z31: =IF(AB31<>"",IF(E31<>"",E31,($I$9-SUM($Y$25:Y30))*AA31*AB31/SUMPRODUCT($AB31:$AB$55,$AA31:$AA$55)),"") -> 2 | AA31: 1 | AB31: 0.063556076
A32: Самошкина | B32: 46120 | C32: ср | D32: 47300 | E32: 8 | F32: =IF(AND(E32<>"",E32<>0),D32/E32,"") -> 5912.5 | G32: 6 | H32: =IF(AND(G32<>"",G32<>0),D32/G32,"") -> 7883.3333 | I32: 52 | J32: =IF(AND(G32<>"",G32<>0),E32/G32,"") -> 1.3333333 | R32: 3514 | S32: =IF(AND(I32<>"",I32<>0),G32/I32,"") -> 0.11538462 | T32: =D32/U32 -> 11.23416 | U32: =$I$8*AA32*AB32/SUMPRODUCT($AB$25:$AB$55,$AA$25:$AA$55) -> 4210.3728 | V32: =$I$9*AA32*AB32/SUMPRODUCT($AB$25:$AB$55,$AA$25:$AA$55) -> 0.60580904 | W32: =IF($I$12="","",V32/$I$12) -> 0.33286211 | X32: =IF(AB32<>"",IF(D32<>"",D32,($I$8-SUM($X$25:X31))*AA32*AB32/SUMPRODUCT($AB32:$AB$55,$AA32:$AA$55)),"") -> 47300 | Y32: =IF(AB32<>"",IF(E32<>"",E32,($I$9-SUM($Y$25:Y31))*AA32*AB32/SUMPRODUCT($AB32:$AB$55,$AA32:$AA$55)),"") -> 8 | Z32: =IF(AB32<>"",IF(E32<>"",E32,($I$9-SUM($Y$25:Y31))*AA32*AB32/SUMPRODUCT($AB32:$AB$55,$AA32:$AA$55)),"") -> 8 | AA32: 1 | AB32: 0.043954886
A33: Уразгильдеева | B33: 46121 | C33: чт | D33: 50991 | E33: 7 | F33: =IF(AND(E33<>"",E33<>0),D33/E33,"") -> 7284.4286 | G33: 2 | H33: =IF(AND(G33<>"",G33<>0),D33/G33,"") -> 25495.5 | I33: 28 | J33: =IF(AND(G33<>"",G33<>0),E33/G33,"") -> 3.5 | R33: 5130 | S33: =IF(AND(I33<>"",I33<>0),G33/I33,"") -> 0.071428571 | T33: =D33/U33 -> 0.47529376 | U33: =$I$8*AA33*AB33/SUMPRODUCT($AB$25:$AB$55,$AA$25:$AA$55) -> 107283.12 | V33: =$I$9*AA33*AB33/SUMPRODUCT($AB$25:$AB$55,$AA$25:$AA$55) -> 15.436421 | W33: =IF($I$12="","",V33/$I$12) -> 8.4815499 | X33: =IF(AB33<>"",IF(D33<>"",D33,($I$8-SUM($X$25:X32))*AA33*AB33/SUMPRODUCT($AB33:$AB$55,$AA33:$AA$55)),"") -> 50991 | Y33: =IF(AB33<>"",IF(E33<>"",E33,($I$9-SUM($Y$25:Y32))*AA33*AB33/SUMPRODUCT($AB33:$AB$55,$AA33:$AA$55)),"") -> 7 | Z33: =IF(AB33<>"",IF(E33<>"",E33,($I$9-SUM($Y$25:Y32))*AA33*AB33/SUMPRODUCT($AB33:$AB$55,$AA33:$AA$55)),"") -> 7 | AA33: 1 | AB33: 1.12
A34: Уразгильдеева | B34: 46122 | C34: пт | D34: 4693 | E34: 1 | F34: =IF(AND(E34<>"",E34<>0),D34/E34,"") -> 4693 | G34: 1 | H34: =IF(AND(G34<>"",G34<>0),D34/G34,"") -> 4693 | I34: 27 | J34: =IF(AND(G34<>"",G34<>0),E34/G34,"") -> 1 | S34: =IF(AND(I34<>"",I34<>0),G34/I34,"") -> 0.037037037 | T34: =D34/U34 -> 0.029337337 | U34: =$I$8*AA34*AB34/SUMPRODUCT($AB$25:$AB$55,$AA$25:$AA$55) -> 159966.8 | V34: =$I$9*AA34*AB34/SUMPRODUCT($AB$25:$AB$55,$AA$25:$AA$55) -> 23.016806 | W34: =IF($I$12="","",V34/$I$12) -> 12.646597 | X34: =IF(AB34<>"",IF(D34<>"",D34,($I$8-SUM($X$25:X33))*AA34*AB34/SUMPRODUCT($AB34:$AB$55,$AA34:$AA$55)),"") -> 4693 | Y34: =IF(AB34<>"",IF(E34<>"",E34,($I$9-SUM($Y$25:Y33))*AA34*AB34/SUMPRODUCT($AB34:$AB$55,$AA34:$AA$55)),"") -> 1 | Z34: =IF(AB34<>"",IF(E34<>"",E34,($I$9-SUM($Y$25:Y33))*AA34*AB34/SUMPRODUCT($AB34:$AB$55,$AA34:$AA$55)),"") -> 1 | AA34: 1 | AB34: 1.67
A35: Рогалевич.Самошкина | B35: 46123 | C35: сб | D35: 68315 | E35: 10 | F35: =IF(AND(E35<>"",E35<>0),D35/E35,"") -> 6831.5 | G35: 3 | H35: =IF(AND(G35<>"",G35<>0),D35/G35,"") -> 22771.667 | I35: 44 | J35: =IF(AND(G35<>"",G35<>0),E35/G35,"") -> 3.3333333 | P35: 11893 | Q35: 20780 | R35: 7980 | S35: =IF(AND(I35<>"",I35<>0),G35/I35,"") -> 0.068181818 | T35: =D35/U35 -> 0.40066617 | U35: =$I$8*AA35*AB35/SUMPRODUCT($AB$25:$AB$55,$AA$25:$AA$55) -> 170503.54 | V35: =$I$9*AA35*AB35/SUMPRODUCT($AB$25:$AB$55,$AA$25:$AA$55) -> 24.532883 | W35: =IF($I$12="","",V35/$I$12) -> 13.479606 | X35: =IF(AB35<>"",IF(D35<>"",D35,($I$8-SUM($X$25:X34))*AA35*AB35/SUMPRODUCT($AB35:$AB$55,$AA35:$AA$55)),"") -> 68315 | Y35: =IF(AB35<>"",IF(E35<>"",E35,($I$9-SUM($Y$25:Y34))*AA35*AB35/SUMPRODUCT($AB35:$AB$55,$AA35:$AA$55)),"") -> 10 | Z35: =IF(AB35<>"",IF(E35<>"",E35,($I$9-SUM($Y$25:Y34))*AA35*AB35/SUMPRODUCT($AB35:$AB$55,$AA35:$AA$55)),"") -> 10 | AA35: 1 | AB35: 1.78
A36: Рогалевич,Самошкина | B36: 46124 | C36: вс | D36: =65297+L36 -> 110299 | E36: 9 | F36: =IF(AND(E36<>"",E36<>0),D36/E36,"") -> 12255.444 | G36: 5 | H36: =IF(AND(G36<>"",G36<>0),D36/G36,"") -> 22059.8 | I36: 51 | J36: =IF(AND(G36<>"",G36<>0),E36/G36,"") -> 1.8 | K36: 22931 | L36: 45002 | S36: =IF(AND(I36<>"",I36<>0),G36/I36,"") -> 0.098039216 | T36: =D36/U36 -> 0.75755574 | U36: =$I$8*AA36*AB36/SUMPRODUCT($AB$25:$AB$55,$AA$25:$AA$55) -> 145598.53 | V36: =$I$9*AA36*AB36/SUMPRODUCT($AB$25:$AB$55,$AA$25:$AA$55) -> 20.949428 | W36: =IF($I$12="","",V36/$I$12) -> 11.510675 | X36: =IF(AB36<>"",IF(D36<>"",D36,($I$8-SUM($X$25:X35))*AA36*AB36/SUMPRODUCT($AB36:$AB$55,$AA36:$AA$55)),"") -> 110299 | Y36: =IF(AB36<>"",IF(E36<>"",E36,($I$9-SUM($Y$25:Y35))*AA36*AB36/SUMPRODUCT($AB36:$AB$55,$AA36:$AA$55)),"") -> 9 | Z36: =IF(AB36<>"",IF(E36<>"",E36,($I$9-SUM($Y$25:Y35))*AA36*AB36/SUMPRODUCT($AB36:$AB$55,$AA36:$AA$55)),"") -> 9 | AA36: 1 | AB36: 1.52
A37: Рогалевич,Уразгильдеева | B37: 46125 | C37: пн | D37: 65616 | E37: 10 | F37: =IF(AND(E37<>"",E37<>0),D37/E37,"") -> 6561.6 | G37: 7 | H37: =IF(AND(G37<>"",G37<>0),D37/G37,"") -> 9373.7143 | I37: 75 | J37: =IF(AND(G37<>"",G37<>0),E37/G37,"") -> 1.4285714 | K37: 31984 | R37: 3245 | S37: =IF(AND(I37<>"",I37<>0),G37/I37,"") -> 0.093333333 | T37: =D37/U37 -> 0.73656896 | U37: =$I$8*AA37*AB37/SUMPRODUCT($AB$25:$AB$55,$AA$25:$AA$55) -> 89083.309 | V37: =$I$9*AA37*AB37/SUMPRODUCT($AB$25:$AB$55,$AA$25:$AA$55) -> 12.817742 | W37: =IF($I$12="","",V37/$I$12) -> 7.0427155 | X37: =IF(AB37<>"",IF(D37<>"",D37,($I$8-SUM($X$25:X36))*AA37*AB37/SUMPRODUCT($AB37:$AB$55,$AA37:$AA$55)),"") -> 65616 | Y37: =IF(AB37<>"",IF(E37<>"",E37,($I$9-SUM($Y$25:Y36))*AA37*AB37/SUMPRODUCT($AB37:$AB$55,$AA37:$AA$55)),"") -> 10 | Z37: =IF(AB37<>"",IF(E37<>"",E37,($I$9-SUM($Y$25:Y36))*AA37*AB37/SUMPRODUCT($AB37:$AB$55,$AA37:$AA$55)),"") -> 10 | AA37: 1 | AB37: 0.93
A38: Рогалевич.Уразгильдеева | B38: 46126 | C38: вт | D38: 49181 | E38: 8 | F38: =IF(AND(E38<>"",E38<>0),D38/E38,"") -> 6147.625 | G38: 7 | H38: =IF(AND(G38<>"",G38<>0),D38/G38,"") -> 7025.8571 | I38: 66 | J38: =IF(AND(G38<>"",G38<>0),E38/G38,"") -> 1.1428571 | K38: 11592 | S38: =IF(AND(I38<>"",I38<>0),G38/I38,"") -> 0.10606061 | T38: =D38/U38 -> 0.74333798 | U38: =$I$8*AA38*AB38/SUMPRODUCT($AB$25:$AB$55,$AA$25:$AA$55) -> 66162.367 | V38: =$I$9*AA38*AB38/SUMPRODUCT($AB$25:$AB$55,$AA$25:$AA$55) -> 9.519765 | W38: =IF($I$12="","",V38/$I$12) -> 5.2306401 | X38: =IF(AB38<>"",IF(D38<>"",D38,($I$8-SUM($X$25:X37))*AA38*AB38/SUMPRODUCT($AB38:$AB$55,$AA38:$AA$55)),"") -> 49181 | Y38: =IF(AB38<>"",IF(E38<>"",E38,($I$9-SUM($Y$25:Y37))*AA38*AB38/SUMPRODUCT($AB38:$AB$55,$AA38:$AA$55)),"") -> 8 | Z38: =IF(AB38<>"",IF(E38<>"",E38,($I$9-SUM($Y$25:Y37))*AA38*AB38/SUMPRODUCT($AB38:$AB$55,$AA38:$AA$55)),"") -> 8 | AA38: 1 | AB38: 0.69071302
A39: Самошкина,Уразгильдеева | B39: 46127 | C39: ср | D39: 61823 | E39: 9 | F39: =IF(AND(E39<>"",E39<>0),D39/E39,"") -> 6869.2222 | G39: 6 | H39: =IF(AND(G39<>"",G39<>0),D39/G39,"") -> 10303.833 | I39: 69 | J39: =IF(AND(G39<>"",G39<>0),E39/G39,"") -> 1.5 | Q39: 26072 | R39: 2095 | S39: =IF(AND(I39<>"",I39<>0),G39/I39,"") -> 0.086956522 | T39: =D39/U39 -> 1.3599351 | U39: =$I$8*AA39*AB39/SUMPRODUCT($AB$25:$AB$55,$AA$25:$AA$55) -> 45460.257 | V39: =$I$9*AA39*AB39/SUMPRODUCT($AB$25:$AB$55,$AA$25:$AA$55) -> 6.5410442 | W39: =IF($I$12="","",V39/$I$12) -> 3.5939803 | X39: =IF(AB39<>"",IF(D39<>"",D39,($I$8-SUM($X$25:X38))*AA39*AB39/SUMPRODUCT($AB39:$AB$55,$AA39:$AA$55)),"") -> 61823 | Y39: =IF(AB39<>"",IF(E39<>"",E39,($I$9-SUM($Y$25:Y38))*AA39*AB39/SUMPRODUCT($AB39:$AB$55,$AA39:$AA$55)),"") -> 9 | Z39: =IF(AB39<>"",IF(E39<>"",E39,($I$9-SUM($Y$25:Y38))*AA39*AB39/SUMPRODUCT($AB39:$AB$55,$AA39:$AA$55)),"") -> 9 | AA39: 1 | AB39: 0.4745899
A40: Рогалевич,Самошкина | B40: 46128 | C40: чт | D40: =154905+L40 -> 172712 | E40: 14 | F40: =IF(AND(E40<>"",E40<>0),D40/E40,"") -> 12336.571 | G40: 7 | H40: =IF(AND(G40<>"",G40<>0),D40/G40,"") -> 24673.143 | I40: 56 | J40: =IF(AND(G40<>"",G40<>0),E40/G40,"") -> 2 | K40: =37294+8792 -> 46086 | L40: 17807 | P40: 37998 | Q40: 57515 | R40: 5890 | S40: =IF(AND(I40<>"",I40<>0),G40/I40,"") -> 0.125 | T40: =D40/U40 -> 1.6162225 | U40: =$I$8*AA40*AB40/SUMPRODUCT($AB$25:$AB$55,$AA$25:$AA$55) -> 106861.53 | V40: =$I$9*AA40*AB40/SUMPRODUCT($AB$25:$AB$55,$AA$25:$AA$55) -> 15.375759 | W40: =IF($I$12="","",V40/$I$12) -> 8.4482194 | X40: =IF(AB40<>"",IF(D40<>"",D40,($I$8-SUM($X$25:X39))*AA40*AB40/SUMPRODUCT($AB40:$AB$55,$AA40:$AA$55)),"") -> 172712 | Y40: =IF(AB40<>"",IF(E40<>"",E40,($I$9-SUM($Y$25:Y39))*AA40*AB40/SUMPRODUCT($AB40:$AB$55,$AA40:$AA$55)),"") -> 14 | Z40: =IF(AB40<>"",IF(E40<>"",E40,($I$9-SUM($Y$25:Y39))*AA40*AB40/SUMPRODUCT($AB40:$AB$55,$AA40:$AA$55)),"") -> 14 | AA40: 1 | AB40: 1.1155987
A41: Рогалевич,Уразгильдеева | B41: 46129 | C41: пт | D41: 51060 | E41: 5 | F41: =IF(AND(E41<>"",E41<>0),D41/E41,"") -> 10212 | G41: 4 | H41: =IF(AND(G41<>"",G41<>0),D41/G41,"") -> 12765 | I41: 64 | J41: =IF(AND(G41<>"",G41<>0),E41/G41,"") -> 1.25 | K41: 8992 | P41: 32284 | R41: 5490 | S41: =IF(AND(I41<>"",I41<>0),G41/I41,"") -> 0.0625 | T41: =D41/U41 -> 0.31852433 | U41: =$I$8*AA41*AB41/SUMPRODUCT($AB$25:$AB$55,$AA$25:$AA$55) -> 160301.73 | V41: =$I$9*AA41*AB41/SUMPRODUCT($AB$25:$AB$55,$AA$25:$AA$55) -> 23.064997 | W41: =IF($I$12="","",V41/$I$12) -> 12.673075 | X41: =IF(AB41<>"",IF(D41<>"",D41,($I$8-SUM($X$25:X40))*AA41*AB41/SUMPRODUCT($AB41:$AB$55,$AA41:$AA$55)),"") -> 51060 | Y41: =IF(AB41<>"",IF(E41<>"",E41,($I$9-SUM($Y$25:Y40))*AA41*AB41/SUMPRODUCT($AB41:$AB$55,$AA41:$AA$55)),"") -> 5 | Z41: =IF(AB41<>"",IF(E41<>"",E41,($I$9-SUM($Y$25:Y40))*AA41*AB41/SUMPRODUCT($AB41:$AB$55,$AA41:$AA$55)),"") -> 5 | AA41: 1 | AB41: 1.6734965
...

Sheet Св. по пок.
A2: Показатель | D2: ='Ялта, Ленина, 18'!I3 -> ул. Набережная Ленина, 18 | G2: =График!B28 -> Рогалевич Ирина | J2: =График!B27 -> Уразгильдеева Екатерина | M2: =График!B26 -> Самошкина Алина
D3: Факт | F3: Прогноз | G3: Факт | I3: Прогноз | J3: Факт | L3: Прогноз | M3: Факт | O3: Прогноз
A4: Выручка | D4: ='Ялта, Ленина, 18'!K8 -> 0.71583393 | E4: ='Ялта, Ленина, 18'!J8 -> 1760211 | F4: ='Ялта, Ленина, 18'!M8 -> 0.71583393 | G4: =Рогалевич!N8 -> 0.87196753 | H4: =Рогалевич!M8 -> 792102 | I4: =Рогалевич!P8 -> 0.87196753 | J4: =Уразгильдеева!N8 -> 0.7155404 | K4: =Уразгильдеева!M8 -> 780750 | L4: =Уразгильдеева!P8 -> 0.7155404 | M4: =Самошкина!N8 -> 0.40781232 | N4: =Самошкина!M8 -> 187359 | O4: =Самошкина!P8 -> 0.81562464
A5: Кол-во изделий | D5: ='Ялта, Ленина, 18'!K9 -> 0.65007009 | E5: ='Ялта, Ленина, 18'!J9 -> 230 | F5: ='Ялта, Ленина, 18'!M9 -> 0.65007009 | G5: =Рогалевич!N9 -> 0.6885675 | H5: =Рогалевич!M9 -> 90 | I5: =Рогалевич!P9 -> 0.6885675 | J5: =Уразгильдеева!N9 -> 0.68153906 | K5: =Уразгильдеева!M9 -> 107 | L5: =Уразгильдеева!P9 -> 0.68153906 | M5: =Самошкина!N9 -> 0.49921144 | N5: =Самошкина!M9 -> 33 | O5: =Самошкина!P9 -> 0.99842287
A6: Средний чек | D6: ='Ялта, Ленина, 18'!K10 -> 1.0463016 | E6: ='Ялта, Ленина, 18'!J10 -> 13234.669 | F6: ='Ялта, Ленина, 18'!M10 -> 1.0463016 | G6: =Рогалевич!N10 -> 1.2042636 | H6: =Рогалевич!M10 -> 15232.731 | I6: =Рогалевич!P10 -> 1.2042636 | J6: =Уразгильдеева!N10 -> 0.97974995 | K6: =Уразгильдеева!M10 -> 12392.857 | L6: =Уразгильдеева!P10 -> 0.97974995 | M6: =Самошкина!N10 -> 0.87130347 | N6: =Самошкина!M10 -> 11021.118 | O6: =Самошкина!P10 -> 0.87130347
A7: Средняя стоимость изделия | D7: ='Ялта, Ленина, 18'!K11 -> 1.1011642 | E7: ='Ялта, Ленина, 18'!J11 -> 7653.0913 | F7: ='Ялта, Ленина, 18'!M11 -> 1.1011642 | G7: =Рогалевич!N11 -> 1.2663501 | H7: =Рогалевич!M11 -> 8801.1333 | I7: =Рогалевич!P11 -> 1.2663501 | J7: =Уразгильдеева!N11 -> 1.0498891 | K7: =Уразгильдеева!M11 -> 7296.729 | L7: =Уразгильдеева!P11 -> 1.0498891 | M7: =Самошкина!N11 -> 0.81691302 | N7: =Самошкина!M11 -> 5677.5455 | O7: =Самошкина!P11 -> 0.81691302
A8: Длина чека | D8: ='Ялта, Ленина, 18'!K12 -> 0.95017764 | E8: ='Ялта, Ленина, 18'!J12 -> 1.7293233 | F8: ='Ялта, Ленина, 18'!M12 -> 0.95017764 | G8: =Рогалевич!N12 -> 0.9509721 | H8: =Рогалевич!M12 -> 1.7307692 | I8: =Рогалевич!P12 -> 0.9509721 | J8: =Уразгильдеева!N12 -> 0.93319379 | K8: =Уразгильдеева!M12 -> 1.6984127 | L8: =Уразгильдеева!P12 -> 0.93319379 | M8: =Самошкина!N12 -> 1.0665805 | N8: =Самошкина!M12 -> 1.9411765 | O8: =Самошкина!P12 -> 1.0665805
A9: Кол-во чеков | D9: ='Ялта, Ленина, 18'!K13 -> 0.68415638 | E9: ='Ялта, Ленина, 18'!J13 -> 133 | F9: ='Ялта, Ленина, 18'!M13 -> 0.68415638 | G9: =Рогалевич!N13 -> 0.72406698 | H9: =Рогалевич!M13 -> 52 | I9: =Рогалевич!P13 -> 0.72406698 | J9: =Уразгильдеева!N13 -> 0.73032961 | K9: =Уразгильдеева!M13 -> 63 | L9: =Уразгильдеева!P13 -> 0.73032961 | M9: =Самошкина!N13 -> 0.46804854 | N9: =Самошкина!M13 -> 17 | O9: =Самошкина!P13 -> 0.93609708
A10: Кол-во смен план/отработано | D10: ='Ялта, Ленина, 18'!K14 -> 1 | E10: ='Ялта, Ленина, 18'!J14 -> 30 | G10: =Рогалевич!N14 -> 1 | H10: =Рогалевич!M14 -> 19 | I10: =Рогалевич!P14 -> 1 | J10: =Уразгильдеева!N14 -> 0.95 | K10: =Уразгильдеева!M14 -> 19 | M10: =Самошкина!N14 -> 1 | N10: =Самошкина!M14 -> 8 | O10: =Самошкина!P14 -> 1
A11: Средние продажи в смену | D11: ='Ялта, Ленина, 18'!K15 -> 0.71583393 | E11: ='Ялта, Ленина, 18'!J15 -> 58673.7 | F11: ='Ялта, Ленина, 18'!M15 -> 0.71583393 | G11: =Рогалевич!N15 -> 0.50862337 | H11: =Рогалевич!M15 -> 41689.579 | I11: =Рогалевич!P15 -> 0.50862337 | J11: =Уразгильдеева!N15 -> 0.50133404 | K11: =Уразгильдеева!M15 -> 41092.105 | L11: =Уразгильдеева!P15 -> 0.50133404 | M11: =Самошкина!N15 -> 0.28572838 | N11: =Самошкина!M15 -> 23419.875 | O11: =Самошкина!P15 -> 0.28572838
A12: Трафик | D12: ='Ялта, Ленина, 18'!K17 -> 0.884 | E12: ='Ялта, Ленина, 18'!J17 -> 1591.2 | F12: ='Ялта, Ленина, 18'!M17 -> 0.884 | G12: =Рогалевич!N17 -> 0.89778736 | H12: =Рогалевич!M17 -> 597 | I12: =Рогалевич!P17 -> 0.89778736 | J12: =Уразгильдеева!N17 -> 1.0003429 | K12: =Уразгильдеева!M17 -> 799 | L12: =Уразгильдеева!P17 -> 1.0529925 | M12: =Самошкина!N17 -> 0.82662879 | N12: =Самошкина!M17 -> 278 | O12: =Самошкина!P17 -> 0.82662879
A13: ='Ялта, Ленина, 18'!F18 -> Выручка на вошедшего | D13: ='Ялта, Ленина, 18'!K18 -> 0.80976688 | E13: ='Ялта, Ленина, 18'!J18 -> 1106.2161 | F13: ='Ялта, Ленина, 18'!M18 -> 0.80976688 | G13: =Рогалевич!N18 -> 0.9712406 | H13: =Рогалевич!M18 -> 1326.804 | I13: =Рогалевич!P18 -> 0.9712406 | J13: =Уразгильдеева!N18 -> 0.71529513 | K13: =Уразгильдеева!M18 -> 977.15895 | L13: =Уразгильдеева!P18 -> 0.71529513 | M13: =Самошкина!N18 -> 0.49334396 | N13: =Самошкина!M18 -> 673.95324 | O13: =Самошкина!P18 -> 0.49334396
A14: ='Ялта, Ленина, 18'!F20 -> Конверсия план/факт | D14: ='Ялта, Ленина, 18'!K20 -> 0.77393255 | E14: ='Ялта, Ленина, 18'!J20 -> 0.083584716 | G14: =Рогалевич!N20 -> 0.80650164 | H14: =Рогалевич!M20 -> 0.087102178 | J14: =Уразгильдеева!N20 -> 0.73007927 | K14: =Уразгильдеева!M20 -> 0.078848561 | L14: =Уразгильдеева!T13 -> 1.3333333 | M14: =Самошкина!N20 -> 0.5662137 | N14: =Самошкина!M20 -> 0.061151079
A15: Доп. KPI | D15: ='Ялта, Ленина, 18'!R56 -> 102140 | G15: =Рогалевич!R56 -> 30605 | J15: =Уразгильдеева!R57 -> 48260.58 | M15: =Самошкина!R57 -> 23274

Sheet План на день
A1: Выручка | B1: 73000
A2: Кол-во изделий | B2: =B1/B4 -> 10.503597
A3: Средний чек | B3: =B4*B5 -> 12649
A4: Средняя стоимость изделия | B4: ='Ялта, Ленина, 18'!I11 -> 6950
A5: Длина чека | B5: ='Ялта, Ленина, 18'!I12 -> 1.82
A6: Кол-во чеков | B6: =IF(B5<>0,B2/B5,"") -> 5.7712072
A7: Конверсия | B7: ='Ялта, Ленина, 18'!I20 -> 0.108
A8: IS | B8: =('Ялта, Ленина, 18'!R12-'Ялта, Ленина, 18'!S12)/('Ялта, Ленина, 18'!I14-'Ялта, Ленина, 18'!J14) -> #DIV/0!
A9: UNOde50 | B9: =('Ялта, Ленина, 18'!R18-'Ялта, Ленина, 18'!S18)/('Ялта, Ленина, 18'!I14-'Ялта, Ленина, 18'!J14) -> #DIV/0!
A10: ='Ялта, Ленина, 18'!M23 -> Agafi | B10: =('Ялта, Ленина, 18'!U12-'Ялта, Ленина, 18'!V12)/('Ялта, Ленина, 18'!I14-'Ялта, Ленина, 18'!J14) -> #DIV/0!

Sheet Рогалевич
B2: (отчетная дата) | J2: ЕЖЕДНЕВНЫЙ ОТЧЕТ О ПРОДАЖАХ
B3: Осталось до выполнения плана!!! | J3: =График!B28 -> Рогалевич Ирина
C4: =L8-D56 -> 116305.67 | E4: =IF(L8<>0,C4/L8,0) -> 0.12803247
I6: Целевые показатели
I7: Показатель | L7: План | M7: Факт | N7: % выполнения | O7: Прогноз выполнения | P7: % выполнения по прогнозу | Q7: Отклонение | R7: Факт аналогичного месяца прошлого года | S7: Отклонение LFL
I8: Выручка | L8: ='Ялта, Ленина, 18'!I8/График!AJ29*График!AJ28 -> 908407.67 | M8: =D56 -> 792102 | N8: =IF(AND(L8<>"",L8<>0,M8<>""),M8/L8,"") -> 0.87196753 | O8: =IF(SUMIF($D$25:$D$55,">=0",$U$24:$U$55)<>0,L8*D56/SUMIF($D$25:$D$55,">=0",$U$24:$U$55),0) -> 792102 | P8: =IF(AND(L8<>"",L8<>0,O8<>"",O8<>0),O8/L8,"") -> 0.87196753 | Q8: =IF(AND(M8<>0,M8<>"",L8<>0,L8<>""),O8-L8,"") -> -116305.67 | R8: 1663026 | S8: =IF(AND(R8<>"",R8<>0,O8<>"",O8<>0),-R8+O8,"") -> -870924 | T8: =IF(AND(S8<>"",S8<>0,R8<>0,R8<>""),S8/R8,"") -> -0.52369837
I9: Кол-во изделий | L9: =L8/L11 -> 130.70614 | M9: =E56 -> 90 | N9: =IF(AND(L9<>"",L9<>0,M9<>""),M9/L9,"") -> 0.6885675 | O9: =IF(SUMIF($E$25:$E$53,">=0",$V$24:$V$53)<>0,L9*E56/SUMIF($E$25:$E$53,">=0",$V$24:$V$53),0) -> 90 | P9: =IF(AND(L9<>"",L9<>0,O9<>"",O9<>0),O9/L9,"") -> 0.6885675 | Q9: =IF(AND(M9<>0,M9<>"",L9<>0,L9<>""),O9-L9,"") -> -40.70614 | R9: 315 | S9: =IF(AND(R9<>"",R9<>0,O9<>"",O9<>0),-R9+O9,"") -> -225 | T9: =IF(AND(S9<>"",S9<>0,R9<>0,R9<>""),S9/R9,"") -> -0.71428571
I10: Средний чек | L10: =L11*L12 -> 12649 | M10: =H56 -> 15232.731 | N10: =IF(AND(L10<>"",L10<>0,M10<>""),M10/L10,"") -> 1.2042636 | O10: =M10 -> 15232.731 | P10: =IF(AND(L10<>"",L10<>0,O10<>"",O10<>0),O10/L10,"") -> 1.2042636 | Q10: =IF(AND(M10<>0,M10<>"",L10<>0,L10<>""),O10-L10,"") -> 2583.7308 | R10: 10869.451 | S10: =IF(AND(R10<>"",R10<>0,O10<>"",O10<>0),-R10+O10,"") -> 4363.2798 | T10: =IF(AND(S10<>"",S10<>0,R10<>0,R10<>""),S10/R10,"") -> 0.40142596
I11: Средняя стоимость изделия | L11: ='Ялта, Ленина, 18'!I11 -> 6950 | M11: =F56 -> 8801.1333 | N11: =IF(AND(L11<>"",L11<>0,M11<>""),M11/L11,"") -> 1.2663501 | O11: =IF(O9>0,O8/O9,"") -> 8801.1333 | P11: =IF(AND(L11<>"",L11<>0,O11<>"",O11<>0),O11/L11,"") -> 1.2663501 | Q11: =IF(AND(M11<>0,M11<>"",L11<>0,L11<>""),O11-L11,"") -> 1851.1333 | R11: 5279.4476 | S11: =IF(AND(R11<>"",R11<>0,O11<>"",O11<>0),-R11+O11,"") -> 3521.6857 | T11: =IF(AND(S12<>"",S12<>0,R12<>0,R12<>""),S12/R12,"") -> -0.15934066
I12: Длина чека | L12: ='Ялта, Ленина, 18'!I12 -> 1.82 | M12: =J56 -> 1.7307692 | N12: =IF(AND(L12<>"",L12<>0,M12<>""),M12/L12,"") -> 0.9509721 | O12: =M12 -> 1.7307692 | P12: =IF(AND(L12<>"",L12<>0,O12<>"",O12<>0),O12/L12,"") -> 0.9509721 | Q12: =IF(AND(M12<>0,M12<>"",L12<>0,L12<>""),O12-L12,"") -> -0.089230769 | R12: 2.0588235 | S12: =IF(AND(R12<>"",R12<>0,O12<>"",O12<>0),-R12+O12,"") -> -0.3280543
I13: Кол-во чеков | L13: =IF(L12<>0,L9/L12,"") -> 71.816561 | M13: =G56 -> 52 | N13: =IF(AND(L13<>"",L13<>0,M13<>""),M13/L13,"") -> 0.72406698 | O13: =IF(SUMIF($G$25:$G$53,">=0",$W$24:$W$53)<>0,L13*G56/SUMIF($G$25:$G$53,">=0",$W$24:$W$53),"") -> 52 | P13: =IF(AND(L13<>"",L13<>0,O13<>"",O13<>0),O13/L13,"") -> 0.72406698 | Q13: =IF(AND(M13<>0,M13<>"",L13<>0,L13<>""),O13-L13,"") -> -19.816561 | R13: 153 | S13: =IF(AND(R13<>"",R13<>0,O13<>"",O13<>0),-R13+O13,"") -> -101 | T13: =IF(AND(S14<>"",S14<>0,R14<>0,R14<>""),S14/R14,"") -> -0.34482759
I14: Кол-во смен план/отработано | L14: =График!AI28 -> 19 | M14: 19 | N14: =IF(AND(L14<>"",L14<>0,M14<>""),M14/L14,"") -> 1 | O14: =L14 -> 19 | P14: =IF(AND(L14<>"",L14<>0,O14<>"",O14<>0),O14/L14,"") -> 1 | Q14: =IF(AND(M14<>0,M14<>"",L14<>0,L14<>""),O14-L14,"") -> 0 | R14: 29 | S14: =IF(AND(R14<>"",R14<>0,O14<>"",O14<>0),-R14+O14,"") -> -10 | T14: =IF(AND(S15<>"",S15<>0,R15<>0,R15<>""),S15/R15,"") -> -0.2730133
I15: Средние продажи в смену | L15: ='Ялта, Ленина, 18'!I15 -> 81965.52 | M15: =M8/M14 -> 41689.579 | N15: =IF(AND(L15<>"",L15<>0,M15<>""),M15/L15,"") -> 0.50862337 | O15: =M15 -> 41689.579 | P15: =IF(AND(L15<>"",L15<>0,O15<>"",O15<>0),O15/L15,"") -> 0.50862337 | Q15: =IF(AND(M15<>0,M15<>"",L15<>0,L15<>""),O15-L15,"") -> -40275.941 | R15: 57345.724 | S15: =IF(AND(R15<>"",R15<>0,O15<>"",O15<>0),-R15+O15,"") -> -15656.145 | T15: =IF(AND(S16<>"",S16<>0,R16<>0,R16<>""),S16/R16,"")
I16: Отставание/Перевыполнение | N16: =IF(AND(L16<>"",L16<>0,M16<>""),M16/L16,"") | O16: =M16 -> 0 | P16: =IF(AND(L16<>"",L16<>0,O16<>"",O16<>0),O16/L16,"") | Q16: =IF(AND(M16<>0,M16<>"",L16<>0,L16<>""),O16-L16,"") | R16: -838811.89 | S16: =IF(AND(R16<>"",R16<>0,O16<>"",O16<>0),-R16+O16,"") | T16: =IF(AND(S17<>"",S17<>0,R17<>0,R17<>""),S17/R17,"") -> -0.0671875
I17: Трафик | L17: ='Ялта, Ленина, 18'!I17/График!AJ29*График!AJ28 -> 664.96815 | M17: =I56 -> 597 | N17: =IF(AND(L17<>"",L17<>0,M17<>""),M17/L17,"") -> 0.89778736 | O17: =M17/M14*L14 -> 597 | P17: =IF(AND(L17<>"",L17<>0,O17<>"",O17<>0),O17/L17,"") -> 0.89778736 | Q17: =IF(AND(M17<>0,M17<>"",L17<>0,L17<>""),O17-L17,"") -> -67.968153 | R17: 640 | S17: =IF(AND(R17<>"",R17<>0,O17<>"",O17<>0),-R17+O17,"") -> -43 | T17: =IF(AND(S18<>"",S18<>0,R18<>0,R18<>""),S18/R18,"")
I18: Выручка на вошедшего | L18: =L8/L17 -> 1366.092 | M18: =M8/M17 -> 1326.804 | N18: =IF(AND(L18<>"", L18<>0, M18<>""), M18/L18, "") -> 0.9712406 | O18: =M18 -> 1326.804 | P18: =IF(AND(L18<>"", L18<>0, O18<>"", O18<>0), O18/L18, "") -> 0.9712406 | Q18: =IF(AND(M18<>0, M18<>"", L18<>0, L18<>""), O18-L18, "") -> -39.28798 | S18: =IF(AND(R18<>"",R18<>0,O18<>"",O18<>0),-R18+O18,"") | T18: =IF(AND(S19<>"",S19<>0,R19<>0,R19<>""),S19/R19,"")
N19: =IF(AND(L19<>"",L19<>0,M19<>""),M19/L19,"") | O19: =M19 -> 0 | P19: =IF(AND(L19<>"",L19<>0,O19<>"",O19<>0),O19/L19,"") | Q19: =IF(AND(M19<>0,M19<>"",L19<>0,L19<>""),O19-L19,"") | R19: 0 | S19: =IF(AND(R19<>"",R19<>0,O19<>"",O19<>0),-R19+O19,"") | T19: =IF(AND(S20<>"",S20<>0,R20<>0,R20<>""),S20/R20,"") -> -0.62445897
I20: Конверсия план/факт | L20: ='Ялта, Ленина, 18'!I20 -> 0.108 | M20: =S56 -> 0.087102178 | N20: =M20/L20 -> 0.80650164 | O20: =IF(AND(N8<>0,L14<>0,I56<>0),(I56*S56+(I56/N8-I56)*L20)/(I56/N8),0) -> 0.089777777 | P20: =IF(AND(L20<>"",L20<>0,O20<>"",O20<>0),O20/L20,"") -> 0.83127572 | Q20: =IF(AND(M20<>0,M20<>"",L20<>0,L20<>""),O20-L20,"") -> -0.018222223 | R20: 0.2390625 | S20: =IF(AND(R20<>"",R20<>0,O20<>"",O20<>0),-R20+O20,"") -> -0.14928472
T21: % выполнения дневного плана | U21: Раcпределение плана по дням
B22: Факт продаж за месяц | U22: выручка, план | V22: кол-во ед, план | W22: Кол-во чеков, план | X22: выручка, скорректир.план | Y22: кол-во ед, скорр. план | Z22: кол-во чеков, скорр. план | AA22: Коэфф. Дня Недели | AB22: Специфика месяца
B23: Дата | C23: День недели | D23: Выручка (руб) | E23: Кол-во единиц (шт.) | F23: Средняя стоимость изделия (руб.) | G23: Количество чеков (шт.) | H23: Средняя сумма чека (руб.) | I23: Трафик | J23: Длина чека (шт.) | K23: UNOde50 | L23: IS | M23: Agafi | N23: Kalliope | O23: Raganella | P23: CC\MP | Q23: Antura | R23: SALE | S23: Конверсия (%) | U23: 1 | V23: 2 | W23: 3 | X23: 4 | Y23: 5 | Z23: 6 | AA23: 10 | AB23: 11
A24: 1 | B24: 1 | C24: 2 | D24: 3 | E24: 4 | F24: 5 | G24: 6 | H24: 7 | I24: 8 | J24: 9 | K24: 10 | L24: 11 | M24: 12 | N24: 13 | O24: 14 | Q24: 15 | R24: 16 | S24: 17 | T24: =D25/U24 -> 1.2568641 | U24: =$L$8*AA24*AB24/SUMPRODUCT($AB$24:$AB$55,$AA$24:$AA$55) -> 82582.516 | V24: =$L$9*AA24*AB24/SUMPRODUCT($AB$24:$AB$55,$AA$24:$AA$55) -> 11.882376 | W24: =IF($L$12="","",V24/$L$12) -> 6.5287782 | X24: =IF(D25<>"",D25,U24) -> 103795 | Y24: =IF(E25<>"",E25,V24) -> 9 | Z24: =IF(G25<>"",G25,W24) -> 4 | AA24: 1 | AB24: 1
A25: 2 | B25: 46113 | C25: ср | D25: =4393+85786+6723+6893 -> 103795 | E25: 9 | F25: =IF(AND(E25<>"",E25<>0),D25/E25,"") -> 11532.778 | G25: 4 | H25: =IF(AND(G25<>"",G25<>0),D25/G25,"") -> 25948.75 | I25: 37 | J25: =IF(AND(G25<>"",G25<>0),E25/G25,"") -> 2.25 | K25: 24291 | N25: 34542 | Q25: 21343 | S25: =IF(AND(I25<>"",I25<>0),G25/I25,"") -> 0.10810811 | T25: =D26/U25 -> 0.11605362 | U25: =$L$8*AA25*AB25/SUMPRODUCT($AB$24:$AB$55,$AA$24:$AA$55) -> 82582.516 | V25: =$L$9*AA25*AB25/SUMPRODUCT($AB$24:$AB$57,$AA$24:$AA$57) -> 11.882376 | W25: =IF($L$12="","",V25/$L$12) -> 6.5287782 | X25: =IF(AB25<>"",IF(D26<>"",D26,($L$8-SUM($X$24:X24))*AA25*AB25/SUMPRODUCT($AB25:$AB$55,$AA25:$AA$55)),"") -> 9584 | Y25: =IF(AB25<>"",IF(E26<>"",E26,($L$9-SUM($Y$24:Y24))*AA25*AB25/SUMPRODUCT($AB25:$AB$57,$AA25:$AA$57)),"") -> 2 | Z25: =IF(AB25<>"",IF($L$12<>"",IF(G26<>"",G26,($L$9/$L$12-SUM($Z$24:Z24))*AA25*AB25/SUMPRODUCT($AB25:$AB$57,$AA25:$AA$57)),""),"") -> 1 | AA25: 1 | AB25: 1
A26: 3 | B26: 46114 | C26: чт | D26: 9584 | E26: 2 | F26: =IF(AND(E26<>"",E26<>0),D26/E26,"") -> 4792 | G26: 1 | H26: =IF(AND(G26<>"",G26<>0),D26/G26,"") -> 9584 | I26: 15 | J26: =IF(AND(G26<>"",G26<>0),E26/G26,"") -> 2 | S26: =IF(AND(I26<>"",I26<>0),G26/I26,"") -> 0.066666667 | T26: =D27/U26 -> 0.053195279 | U26: =$L$8*AA26*AB26/SUMPRODUCT($AB$24:$AB$55,$AA$24:$AA$55) -> 82582.516 | V26: =$L$9*AA26*AB26/SUMPRODUCT($AB$24:$AB$57,$AA$24:$AA$57) -> 11.882376 | W26: =IF($L$12="","",V26/$L$12) -> 6.5287782 | X26: =IF(AB26<>"",IF(D27<>"",D27,($L$8-SUM($X$24:X25))*AA26*AB26/SUMPRODUCT($AB26:$AB$57,$AA26:$AA$57)),"") -> 4393 | Y26: =IF(AB26<>"",IF(E27<>"",E27,($L$9-SUM($Y$24:Y25))*AA26*AB26/SUMPRODUCT($AB26:$AB$57,$AA26:$AA$57)),"") -> 1 | Z26: =IF(AB26<>"",IF($L$12<>"",IF(G27<>"",G27,($L$9/$L$12-SUM($Z$24:Z25))*AA26*AB26/SUMPRODUCT($AB26:$AB$57,$AA26:$AA$57)),""),"") -> 1 | AA26: 1 | AB26: 1
A27: 4 | B27: 46115 | C27: пт | D27: 4393 | E27: 1 | F27: 4393 | G27: 1 | H27: =IF(AND(G27<>"",G27<>0),D27/G27,"") -> 4393 | I27: 20 | J27: =IF(AND(G27<>"",G27<>0),E27/G27,"") -> 1 | S27: =IF(AND(I27<>"",I27<>0),G27/I27,"") -> 0.05 | T27: =D28/U27 -> 0.22746946 | U27: =$L$8*AA27*AB27/SUMPRODUCT($AB$24:$AB$55,$AA$24:$AA$55) -> 82582.516 | V27: =$L$9*AA27*AB27/SUMPRODUCT($AB$24:$AB$57,$AA$24:$AA$57) -> 11.882376 | W27: =IF($L$12="","",V27/$L$12) -> 6.5287782 | X27: =IF(AB27<>"",IF(D28<>"",D28,($L$8-SUM($X$24:X26))*AA27*AB27/SUMPRODUCT($AB27:$AB$57,$AA27:$AA$57)),"") -> 18785 | Y27: =IF(AB27<>"",IF(E28<>"",E28,($L$9-SUM($Y$24:Y26))*AA27*AB27/SUMPRODUCT($AB27:$AB$57,$AA27:$AA$57)),"") -> 2 | Z27: =IF(AB27<>"",IF($L$12<>"",IF(G28<>"",G28,($L$9/$L$12-SUM($Z$24:Z26))*AA27*AB27/SUMPRODUCT($AB27:$AB$57,$AA27:$AA$57)),""),"") -> 2 | AA27: 1 | AB27: 1
A28: 5 | B28: 46116 | C28: сб | D28: 18785 | E28: 2 | F28: 9392 | G28: 2 | H28: 9392 | I28: 23 | J28: =IF(AND(G28<>"",G28<>0),E28/G28,"") -> 1 | Q28: 14093 | S28: =IF(AND(I28<>"",I28<>0),G28/I28,"") -> 0.086956522 | T28: =D29/U28 -> 0.78619547 | U28: =$L$8*AA28*AB28/SUMPRODUCT($AB$24:$AB$55,$AA$24:$AA$55) -> 82582.516 | V28: =$L$9*AA28*AB28/SUMPRODUCT($AB$24:$AB$57,$AA$24:$AA$57) -> 11.882376 | W28: =IF($L$12="","",V28/$L$12) -> 6.5287782 | X28: =IF(AB28<>"",IF(D29<>"",D29,($L$8-SUM($X$24:X27))*AA28*AB28/SUMPRODUCT($AB28:$AB$57,$AA28:$AA$57)),"") -> 64926 | Y28: =IF(AB28<>"",IF(E29<>"",E29,($L$9-SUM($Y$24:Y27))*AA28*AB28/SUMPRODUCT($AB28:$AB$57,$AA28:$AA$57)),"") -> 10 | Z28: =IF(AB28<>"",IF($L$12<>"",IF(G29<>"",G29,($L$9/$L$12-SUM($Z$24:Z27))*AA28*AB28/SUMPRODUCT($AB28:$AB$57,$AA28:$AA$57)),""),"") -> 3 | AA28: 1 | AB28: 1
A29: 6 | B29: 46117 | C29: вс | D29: 64926 | E29: 10 | F29: =IF(AND(E29<>"",E29<>0),D29/E29,"") -> 6492.6 | G29: 3 | H29: =IF(AND(G29<>"",G29<>0),D29/G29,"") -> 21642 | I29: 30 | J29: =IF(AND(G29<>"",G29<>0),E29/G29,"") -> 3.3333333 | N29: 33570 | R29: 6490 | S29: =IF(AND(I29<>"",I29<>0),G29/I29,"") -> 0.1 | T29: =D30/U29 -> 0.34477032 | U29: =$L$8*AA29*AB29/SUMPRODUCT($AB$24:$AB$55,$AA$24:$AA$55) -> 82582.516 | V29: =$L$9*AA29*AB29/SUMPRODUCT($AB$24:$AB$57,$AA$24:$AA$57) -> 11.882376 | W29: =IF($L$12="","",V29/$L$12) -> 6.5287782 | X29: =IF(AB29<>"",IF(D30<>"",D30,($L$8-SUM($X$24:X28))*AA29*AB29/SUMPRODUCT($AB29:$AB$57,$AA29:$AA$57)),"") -> 28472 | Y29: =IF(AB29<>"",IF(E30<>"",E30,($L$9-SUM($Y$24:Y28))*AA29*AB29/SUMPRODUCT($AB29:$AB$57,$AA29:$AA$57)),"") -> 3 | Z29: =IF(AB29<>"",IF($L$12<>"",IF(G30<>"",G30,($L$9/$L$12-SUM($Z$24:Z28))*AA29*AB29/SUMPRODUCT($AB29:$AB$57,$AA29:$AA$57)),""),"") -> 1 | AA29: 1 | AB29: 1
A30: 7 | B30: 46123 | C30: сб | D30: 28472 | E30: 3 | F30: =IF(AND(E30<>"",E30<>0),D30/E30,"") -> 9490.6667 | G30: 1 | H30: =IF(AND(G30<>"",G30<>0),D30/G30,"") -> 28472 | I30: 15 | J30: =IF(AND(G30<>"",G30<>0),E30/G30,"") -> 3 | Q30: 20780 | S30: =IF(AND(I30<>"",I30<>0),G30/I30,"") -> 0.066666667 | T30: =D31/U30 -> 1.3356217 | U30: =$L$8*AA30*AB30/SUMPRODUCT($AB$24:$AB$55,$AA$24:$AA$55) -> 82582.516 | V30: =$L$9*AA30*AB30/SUMPRODUCT($AB$24:$AB$57,$AA$24:$AA$57) -> 11.882376 | W30: =IF($L$12="","",V30/$L$12) -> 6.5287782 | X30: =IF(AB30<>"",IF(D31<>"",D31,($L$8-SUM($X$24:X29))*AA30*AB30/SUMPRODUCT($AB30:$AB$57,$AA30:$AA$57)),"") -> 110299 | Y30: =IF(AB30<>"",IF(E31<>"",E31,($L$9-SUM($Y$24:Y29))*AA30*AB30/SUMPRODUCT($AB30:$AB$57,$AA30:$AA$57)),"") -> 9 | Z30: =IF(AB30<>"",IF($L$12<>"",IF(G31<>"",G31,($L$9/$L$12-SUM($Z$24:Z29))*AA30*AB30/SUMPRODUCT($AB30:$AB$57,$AA30:$AA$57)),""),"") -> 5 | AA30: 1 | AB30: 1
A31: 8 | B31: 46124 | C31: вс | D31: 110299 | E31: 9 | F31: =IF(AND(E31<>"",E31<>0),D31/E31,"") -> 12255.444 | G31: 5 | H31: =IF(AND(G31<>"",G31<>0),D31/G31,"") -> 22059.8 | I31: 15 | J31: =IF(AND(G31<>"",G31<>0),E31/G31,"") -> 1.8 | K31: 22931 | L31: 45002 | S31: =IF(AND(I31<>"",I31<>0),G31/I31,"") -> 0.33333333 | T31: =D32/U31 -> 0.653177 | U31: =$L$8*AA31*AB31/SUMPRODUCT($AB$24:$AB$55,$AA$24:$AA$55) -> 82582.516 | V31: =$L$9*AA31*AB31/SUMPRODUCT($AB$24:$AB$57,$AA$24:$AA$57) -> 11.882376 | W31: =IF($L$12="","",V31/$L$12) -> 6.5287782 | X31: =IF(AB31<>"",IF(D32<>"",D32,($L$8-SUM($X$24:X30))*AA31*AB31/SUMPRODUCT($AB31:$AB$57,$AA31:$AA$57)),"") -> 53941 | Y31: =IF(AB31<>"",IF(E32<>"",E32,($L$9-SUM($Y$24:Y30))*AA31*AB31/SUMPRODUCT($AB31:$AB$57,$AA31:$AA$57)),"") -> 7 | Z31: =IF(AB31<>"",IF($L$12<>"",IF(G32<>"",G32,($L$9/$L$12-SUM($Z$24:Z30))*AA31*AB31/SUMPRODUCT($AB31:$AB$57,$AA31:$AA$57)),""),"") -> 5 | AA31: 1 | AB31: 1
A32: 9 | B32: 46125 | C32: пн | D32: 53941 | E32: 7 | F32: =IF(AND(E32<>"",E32<>0),D32/E32,"") -> 7705.8571 | G32: 5 | H32: =IF(AND(G32<>"",G32<>0),D32/G32,"") -> 10788.2 | I32: 25 | J32: =IF(AND(G32<>"",G32<>0),E32/G32,"") -> 1.4 | K32: 31984 | R32: 3245 | S32: =IF(AND(I32<>"",I32<>0),G32/I32,"") -> 0.2 | T32: =D33/U32 -> 0.3380982 | U32: =$L$8*AA32*AB32/SUMPRODUCT($AB$24:$AB$55,$AA$24:$AA$55) -> 82582.516 | V32: =$L$9*AA32*AB32/SUMPRODUCT($AB$24:$AB$57,$AA$24:$AA$57) -> 11.882376 | W32: =IF($L$12="","",V32/$L$12) -> 6.5287782 | X32: =IF(AB32<>"",IF(D33<>"",D33,($L$8-SUM($X$24:X31))*AA32*AB32/SUMPRODUCT($AB32:$AB$57,$AA32:$AA$57)),"") -> 27921 | Y32: =IF(AB32<>"",IF(E33<>"",E33,($L$9-SUM($Y$24:Y31))*AA32*AB32/SUMPRODUCT($AB32:$AB$57,$AA32:$AA$57)),"") -> 3 | Z32: =IF(AB32<>"",IF($L$12<>"",IF(G33<>"",G33,($L$9/$L$12-SUM($Z$24:Z31))*AA32*AB32/SUMPRODUCT($AB32:$AB$57,$AA32:$AA$57)),""),"") -> 3 | AA32: 1 | AB32: 1
A33: 10 | B33: 46126 | C33: вт | D33: 27921 | E33: 3 | F33: 9307 | G33: 3 | H33: =IF(AND(G33<>"",G33<>0),D33/G33,"") -> 9307 | I33: 33 | J33: =IF(AND(G33<>"",G33<>0),E33/G33,"") -> 1 | K33: 11592 | S33: =IF(AND(I33<>"",I33<>0),G33/I33,"") -> 0.090909091 | T33: =D34/U33 -> 1.7067293 | U33: =$L$8*AA33*AB33/SUMPRODUCT($AB$24:$AB$55,$AA$24:$AA$55) -> 82582.516 | V33: =$L$9*AA33*AB33/SUMPRODUCT($AB$24:$AB$57,$AA$24:$AA$57) -> 11.882376 | W33: =IF($L$12="","",V33/$L$12) -> 6.5287782 | X33: =IF(AB33<>"",IF(D34<>"",D34,($L$8-SUM($X$24:X32))*AA33*AB33/SUMPRODUCT($AB33:$AB$57,$AA33:$AA$57)),"") -> 140946 | Y33: =IF(AB33<>"",IF(E34<>"",E34,($L$9-SUM($Y$24:Y32))*AA33*AB33/SUMPRODUCT($AB33:$AB$57,$AA33:$AA$57)),"") -> 10 | Z33: =IF(AB33<>"",IF($L$12<>"",IF(G34<>"",G34,($L$9/$L$12-SUM($Z$24:Z32))*AA33*AB33/SUMPRODUCT($AB33:$AB$57,$AA33:$AA$57)),""),"") -> 6 | AA33: 1 | AB33: 1
A34: 11 | B34: 46128 | C34: чт | D34: 140946 | E34: 10 | F34: =IF(AND(E34<>"",E34<>0),D34/E34,"") -> 14094.6 | G34: 6 | H34: =IF(AND(G34<>"",G34<>0),D34/G34,"") -> 23491 | I34: 28 | J34: =IF(AND(G34<>"",G34<>0),E34/G34,"") -> 1.6666667 | K34: 46086 | L34: 17807 | P34: 37998 | Q34: 35635 | S34: =IF(AND(I34<>"",I34<>0),G34/I34,"") -> 0.21428571 | T34: =D35/U34 -> 0.066503181 | U34: =$L$8*AA34*AB34/SUMPRODUCT($AB$24:$AB$55,$AA$24:$AA$55) -> 82582.516 | V34: =$L$9*AA34*AB34/SUMPRODUCT($AB$24:$AB$57,$AA$24:$AA$57) -> 11.882376 | W34: =IF($L$12="","",V34/$L$12) -> 6.5287782 | X34: =IF(AB34<>"",IF(D35<>"",D35,($L$8-SUM($X$24:X33))*AA34*AB34/SUMPRODUCT($AB34:$AB$57,$AA34:$AA$57)),"") -> 5492 | Y34: =IF(AB34<>"",IF(E34<>"",E34,($L$9-SUM($Y$24:Y33))*AA34*AB34/SUMPRODUCT($AB34:$AB$57,$AA34:$AA$57)),"") -> 10 | Z34: =IF(AB34<>"",IF($L$12<>"",IF(G35<>"",G35,($L$9/$L$12-SUM($Z$24:Z33))*AA34*AB34/SUMPRODUCT($AB34:$AB$57,$AA34:$AA$57)),""),"") -> 1 | AA34: 1 | AB34: 1
A35: 12 | B35: 46129 | C35: пт | D35: 5492 | E35: 1 | F35: =IF(AND(E35<>"",E35<>0),D35/E35,"") -> 5492 | G35: 1 | H35: =IF(AND(G35<>"",G35<>0),D35/G35,"") -> 5492 | I35: 32 | J35: =IF(AND(G35<>"",G35<>0),E35/G35,"") -> 1 | R35: 5490 | S35: =IF(AND(I35<>"",I35<>0),G35/I35,"") -> 0.03125 | T35: =D36/U35 -> #DIV/0! | U35: =$L$8*AA35*AB35/SUMPRODUCT($AB$24:$AB$55,$AA$24:$AA$55) -> 0 | V35: =$L$9*AA35*AB35/SUMPRODUCT($AB$24:$AB$57,$AA$24:$AA$57) -> 0 | W35: =IF($L$12="","",V35/$L$12) -> 0 | X35: =IF(AB35<>"",IF(D36<>"",D36,($L$8-SUM($X$24:X34))*AA35*AB35/SUMPRODUCT($AB35:$AB$57,$AA35:$AA$57)),"") | Y35: =IF(AB35<>"",IF(E35<>"",E35,($L$9-SUM($Y$24:Y34))*AA35*AB35/SUMPRODUCT($AB35:$AB$57,$AA35:$AA$57)),"") | Z35: =IF(AB35<>"",IF($L$12<>"",IF(G36<>"",G36,($L$9/$L$12-SUM($Z$24:Z34))*AA35*AB35/SUMPRODUCT($AB35:$AB$57,$AA35:$AA$57)),""),"")
A36: 13 | B36: 46130 | C36: сб | D36: 64469 | E36: 7 | F36: =IF(AND(E36<>"",E36<>0),D36/E36,"") -> 9209.8571 | G36: 4 | H36: =IF(AND(G36<>"",G36<>0),D36/G36,"") -> 16117.25 | I36: 51 | J36: =IF(AND(G36<>"",G36<>0),E36/G36,"") -> 1.75 | L36: 8702 | P36: 17390 | R36: 5890 | S36: =IF(AND(I36<>"",I36<>0),G36/I36,"") -> 0.078431373 | T36: =D37/U36 -> #DIV/0! | U36: =$L$8*AA36*AB36/SUMPRODUCT($AB$24:$AB$55,$AA$24:$AA$55) -> 0 | V36: =$L$9*AA36*AB36/SUMPRODUCT($AB$24:$AB$57,$AA$24:$AA$57) -> 0 | W36: =IF($L$12="","",V36/$L$12) -> 0 | X36: =IF(AB36<>"",IF(D37<>"",D37,($L$8-SUM($X$24:X35))*AA36*AB36/SUMPRODUCT($AB36:$AB$57,$AA36:$AA$57)),"") | Y36: =IF(AB36<>"",IF(E37<>"",E37,($L$9-SUM($Y$24:Y35))*AA36*AB36/SUMPRODUCT($AB36:$AB$57,$AA36:$AA$57)),"") | Z36: =IF(AB36<>"",IF($L$12<>"",IF(G37<>"",G37,($L$9/$L$12-SUM($Z$24:Z35))*AA36*AB36/SUMPRODUCT($AB36:$AB$57,$AA36:$AA$57)),""),"")
A37: .22 | B37: 46131 | C37: вс | D37: 89569 | E37: 16 | F37: =IF(AND(E37<>"",E37<>0),D37/E37,"") -> 5598.0625 | G37: 8 | H37: =IF(AND(G37<>"",G37<>0),D37/G37,"") -> 11196.125 | I37: 82 | J37: =IF(AND(G37<>"",G37<>0),E37/G37,"") -> 2 | L37: 28903 | P37: -17390 | Q37: 36786 | R37: 5990 | S37: =IF(AND(I37<>"",I37<>0),G37/I37,"") -> 0.097560976 | T37: =D38/U37 -> #DIV/0! | U37: =$L$8*AA37*AB37/SUMPRODUCT($AB$24:$AB$55,$AA$24:$AA$55) -> 0 | V37: =$L$9*AA37*AB37/SUMPRODUCT($AB$24:$AB$57,$AA$24:$AA$57) -> 0 | W37: =IF($L$12="","",V37/$L$12) -> 0 | X37: =IF(AB37<>"",IF(D38<>"",D38,($L$8-SUM($X$24:X36))*AA37*AB37/SUMPRODUCT($AB37:$AB$57,$AA37:$AA$57)),"") | Y37: =IF(AB37<>"",IF(E38<>"",E38,($L$9-SUM($Y$24:Y36))*AA37*AB37/SUMPRODUCT($AB37:$AB$57,$AA37:$AA$57)),"") | Z37: =IF(AB37<>"",IF($L$12<>"",IF(G38<>"",G38,($L$9/$L$12-SUM($Z$24:Z36))*AA37*AB37/SUMPRODUCT($AB37:$AB$57,$AA37:$AA$57)),""),"")
A38: 15 | B38: 46136 | C38: пт | D38: 0 | E38: 0 | F38: 0 | G38: 0 | H38: 0 | I38: 62 | J38: =IF(AND(G38<>"",G38<>0),E38/G38,"") | S38: =IF(AND(I38<>"",I38<>0),G38/I38,"") -> 0 | T38: =#REF!/U38 -> #REF! | U38: =$L$8*AA38*AB38/SUMPRODUCT($AB$24:$AB$55,$AA$24:$AA$55) -> 0 | V38: =$L$9*AA38*AB38/SUMPRODUCT($AB$24:$AB$57,$AA$24:$AA$57) -> 0 | W38: =IF($L$12="","",V38/$L$12) -> 0 | X38: =IF(AB38<>"",IF(#REF!<>"",#REF!,($L$8-SUM($X$24:X37))*AA38*AB38/SUMPRODUCT($AB38:$AB$57,$AA38:$AA$57)),"") | Y38: =IF(AB38<>"",IF(#REF!<>"",#REF!,($L$9-SUM($Y$24:Y37))*AA38*AB38/SUMPRODUCT($AB38:$AB$57,$AA38:$AA$57)),"") -> #REF! | Z38: =IF(AB38<>"",IF($L$12<>"",IF(#REF!<>"",#REF!,($L$9/$L$12-SUM($Z$24:Z37))*AA38*AB38/SUMPRODUCT($AB38:$AB$57,$AA38:$AA$57)),""),"") -> #REF!
A39: 16 | B39: 46137 | C39: сб | D39: =7693+6760 -> 14453 | E39: 2 | F39: =IF(AND(E39<>"",E39<>0),D39/E39,"") -> 7226.5 | G39: 2 | H39: =IF(AND(G39<>"",G39<>0),D39/G39,"") -> 7226.5 | I39: 20 | J39: =IF(AND(G39<>"",G39<>0),E39/G39,"") -> 1 | S39: =IF(AND(I39<>"",I39<>0),G39/I39,"") -> 0.1 | T39: =D39/U39 -> #DIV/0! | U39: =$L$8*AA39*AB39/SUMPRODUCT($AB$24:$AB$55,$AA$24:$AA$55) -> 0 | V39: =$L$9*AA39*AB39/SUMPRODUCT($AB$24:$AB$57,$AA$24:$AA$57) -> 0 | W39: =IF($L$12="","",V39/$L$12) -> 0 | X39: =IF(AB39<>"",IF(D39<>"",D39,($L$8-SUM($X$24:X38))*AA39*AB39/SUMPRODUCT($AB39:$AB$57,$AA39:$AA$57)),"") | Y39: =IF(AB39<>"",IF(#REF!<>"",#REF!,($L$9-SUM($Y$24:Y38))*AA39*AB39/SUMPRODUCT($AB39:$AB$57,$AA39:$AA$57)),"") -> #REF! | Z39: =IF(AB39<>"",IF($L$12<>"",IF(G39<>"",G39,($L$9/$L$12-SUM($Z$24:Z38))*AA39*AB39/SUMPRODUCT($AB39:$AB$57,$AA39:$AA$57)),""),"")
A40: 17 | B40: 46138 | C40: вс | D40: 18455 | E40: 3 | F40: =IF(AND(E40<>"",E40<>0),D40/E40,"") -> 6151.6667 | G40: 2 | H40: =IF(AND(G40<>"",G40<>0),D40/G40,"") -> 9227.5 | I40: 18 | J40: =IF(AND(G40<>"",G40<>0),E40/G40,"") -> 1.5 | S40: =IF(AND(I40<>"",I40<>0),G40/I40,"") -> 0.11111111 | T40: =D40/U40 -> #DIV/0! | U40: =$L$8*AA40*AB40/SUMPRODUCT($AB$24:$AB$55,$AA$24:$AA$55) -> 0 | V40: =$L$9*AA40*AB40/SUMPRODUCT($AB$24:$AB$57,$AA$24:$AA$57) -> 0 | W40: =IF($L$12="","",V40/$L$12) -> 0 | X40: =IF(AB40<>"",IF(D40<>"",D40,($L$8-SUM($X$24:X39))*AA40*AB40/SUMPRODUCT($AB40:$AB$57,$AA40:$AA$57)),"") | Y40: =IF(AB40<>"",IF(E39<>"",E39,($L$9-SUM($Y$24:Y39))*AA40*AB40/SUMPRODUCT($AB40:$AB$57,$AA40:$AA$57)),"") | Z40: =IF(AB40<>"",IF($L$12<>"",IF(G40<>"",G40,($L$9/$L$12-SUM($Z$24:Z39))*AA40*AB40/SUMPRODUCT($AB40:$AB$57,$AA40:$AA$57)),""),"")
A41: 18 | B41: 46139 | C41: пн | D41: =11903+4393 -> 16296 | E41: 2 | F41: =IF(AND(E41<>"",E41<>0),D41/E41,"") -> 8148 | G41: 2 | H41: =IF(AND(G41<>"",G41<>0),D41/G41,"") -> 8148 | I41: 46 | J41: =IF(AND(G41<>"",G41<>0),E41/G41,"") -> 1 | L41: 11903 | S41: =IF(AND(I41<>"",I41<>0),G41/I41,"") -> 0.043478261 | T41: =D41/U41 -> #DIV/0! | U41: =$L$8*AA41*AB41/SUMPRODUCT($AB$24:$AB$55,$AA$24:$AA$55) -> 0 | V41: =$L$9*AA41*AB41/SUMPRODUCT($AB$24:$AB$57,$AA$24:$AA$57) -> 0 | W41: =IF($L$12="","",V41/$L$12) -> 0 | X41: =IF(AB41<>"",IF(D41<>"",D41,($L$8-SUM($X$24:X40))*AA41*AB41/SUMPRODUCT($AB41:$AB$57,$AA41:$AA$57)),"") | Y41: =IF(AB41<>"",IF(E41<>"",E41,($L$9-SUM($Y$24:Y40))*AA41*AB41/SUMPRODUCT($AB41:$AB$57,$AA41:$AA$57)),"") | Z41: =IF(AB41<>"",IF($L$12<>"",IF(G41<>"",G41,($L$9/$L$12-SUM($Z$24:Z40))*AA41*AB41/SUMPRODUCT($AB41:$AB$57,$AA41:$AA$57)),""),"")
A42: 19 | B42: 46140 | C42: вт | D42: 16803 | E42: 2 | F42: 7011 | G42: 1 | H42: 9348 | I42: 18 | J42: =IF(AND(G42<>"",G42<>0),E42/G42,"") -> 2 | L42: 16803 | S42: =IF(AND(I42<>"",I42<>0),G42/I42,"") -> 0.055555556 | T42: =D42/U42 -> #DIV/0! | U42: =$L$8*AA42*AB42/SUMPRODUCT($AB$24:$AB$55,$AA$24:$AA$55) -> 0 | V42: =$L$9*AA42*AB42/SUMPRODUCT($AB$24:$AB$57,$AA$24:$AA$57) -> 0 | W42: =IF($L$12="","",V42/$L$12) -> 0 | X42: =IF(AB42<>"",IF(D42<>"",D42,($L$8-SUM($X$24:X41))*AA42*AB42/SUMPRODUCT($AB42:$AB$57,$AA42:$AA$57)),"") | Y42: =IF(AB42<>"",IF(E42<>"",E42,($L$9-SUM($Y$24:Y41))*AA42*AB42/SUMPRODUCT($AB42:$AB$57,$AA42:$AA$57)),"") | Z42: =IF(AB42<>"",IF($L$12<>"",IF(G42<>"",G42,($L$9/$L$12-SUM($Z$24:Z41))*AA42*AB42/SUMPRODUCT($AB42:$AB$57,$AA42:$AA$57)),""),"")
...

Sheet Уразгильдеева
B1: =TODAY()-1 -> 46171
B2: (отчетная дата) | J2: ЕЖЕДНЕВНЫЙ ОТЧЕТ О ПРОДАЖАХ
B3: Осталось до выполнения плана!!! | J3: =График!B27 -> Уразгильдеева Екатерина
C4: =L8-D50 -> 1091133.4 | E4: =IF(L8<>0,C4/L8,0) -> 1
I6: Целевые показатели
I7: Показатель | L7: План | M7: Факт | N7: % выполнения | O7: Прогноз выполнения | P7: % выполнения по прогнозу | Q7: Отклонение | R7: Факт аналогичного месяца прошлого года | S7: Отклонение LFL
I8: Выручка | L8: ='Ялта, Ленина, 18'!I8/График!AJ29*График!AJ27 -> 1091133.4 | M8: =D57 -> 780750 | N8: =IF(AND(L8<>"",L8<>0,M8<>""),M8/L8,"") -> 0.7155404 | O8: =IF(SUMIF($D$25:$D$56,">=0",$U$25:$U$56)<>0,L8*D57/SUMIF($D$25:$D$56,">=0",$U$25:$U$56),0) -> 780750 | P8: =IF(AND(L8<>"",L8<>0,O8<>"",O8<>0),O8/L8,"") -> 0.7155404 | Q8: =IF(AND(M8<>0,M8<>"",L8<>0,L8<>""),O8-L8,"") -> -310383.36 | R8: 240775 | S8: =IF(AND(R8<>"",R8<>0,O8<>"",O8<>0),-R8+O8,"") -> 539975 | T8: =IF(AND(S8<>"",S8<>0,R8<>0,R8<>""),S8/R8,"") -> 2.2426539
I9: Кол-во изделий | L9: =L8/L11 -> 156.99761 | M9: =E57 -> 107 | N9: =IF(AND(L9<>"",L9<>0,M9<>""),M9/L9,"") -> 0.68153906 | O9: =IF(SUMIF($E$25:$E$54,">=0",$V$25:$V$54)<>0,L9*E57/SUMIF($E$25:$E$54,">=0",$V$25:$V$54),0) -> 107 | P9: =IF(AND(L9<>"",L9<>0,O9<>"",O9<>0),O9/L9,"") -> 0.68153906 | Q9: =IF(AND(M9<>0,M9<>"",L9<>0,L9<>""),O9-L9,"") -> -49.997605 | R9: 51 | S9: =IF(AND(R9<>"",R9<>0,O9<>"",O9<>0),-R9+O9,"") -> 56 | T9: =IF(AND(S9<>"",S9<>0,R9<>0,R9<>""),S9/R9,"") -> 1.0980392
I10: Средний чек | L10: =L11*L12 -> 12649 | M10: =H57 -> 12392.857 | N10: =IF(AND(L10<>"",L10<>0,M10<>""),M10/L10,"") -> 0.97974995 | O10: =M10 -> 12392.857 | P10: =IF(AND(L10<>"",L10<>0,O10<>"",O10<>0),O10/L10,"") -> 0.97974995 | Q10: =IF(AND(M10<>0,M10<>"",L10<>0,L10<>""),O10-L10,"") -> -256.14286 | R10: 8917.5926 | S10: =IF(AND(R10<>"",R10<>0,O10<>"",O10<>0),-R10+O10,"") -> 3475.2646 | T10: =IF(AND(S10<>"",S10<>0,R10<>0,R10<>""),S10/R10,"") -> 0.38970883
I11: Средняя стоимость изделия | L11: ='Ялта, Ленина, 18'!I11 -> 6950 | M11: =F57 -> 7296.729 | N11: =IF(AND(L11<>"",L11<>0,M11<>""),M11/L11,"") -> 1.0498891 | O11: =IF(O9>0,O8/O9,"") -> 7296.729 | P11: =IF(AND(L11<>"",L11<>0,O11<>"",O11<>0),O11/L11,"") -> 1.0498891 | Q11: =IF(AND(M11<>0,M11<>"",L11<>0,L11<>""),O11-L11,"") -> 346.72897 | R11: 4721.0784 | S11: =IF(AND(R11<>"",R11<>0,O11<>"",O11<>0),-R11+O11,"") -> 2575.6505 | T11: =IF(AND(S11<>"",S11<>0,R11<>0,R11<>""),S11/R11,"") -> 0.54556402
I12: Длина чека | L12: ='Ялта, Ленина, 18'!I12 -> 1.82 | M12: =J57 -> 1.6984127 | N12: =IF(AND(L12<>"",L12<>0,M12<>""),M12/L12,"") -> 0.93319379 | O12: =M12 -> 1.6984127 | P12: =IF(AND(L12<>"",L12<>0,O12<>"",O12<>0),O12/L12,"") -> 0.93319379 | Q12: =IF(AND(M12<>0,M12<>"",L12<>0,L12<>""),O12-L12,"") -> -0.1215873 | R12: 1.8888889 | S12: =IF(AND(R12<>"",R12<>0,O12<>"",O12<>0),-R12+O12,"") -> -0.19047619 | T12: =IF(AND(S12<>"",S12<>0,R12<>0,R12<>""),S12/R12,"") -> -0.10084034
I13: Кол-во чеков | L13: =IF(L12<>0,L9/L12,"") -> 86.26242 | M13: =G57 -> 63 | N13: =IF(AND(L13<>"",L13<>0,M13<>""),M13/L13,"") -> 0.73032961 | O13: =IF(SUMIF($G$25:$G$54,">=0",$W$25:$W$54)<>0,L13*G57/SUMIF($G$25:$G$54,">=0",$W$25:$W$54),"") -> 63 | P13: =IF(AND(L13<>"",L13<>0,O13<>"",O13<>0),O13/L13,"") -> 0.73032961 | Q13: =IF(AND(M13<>0,M13<>"",L13<>0,L13<>""),O13-L13,"") -> -23.26242 | R13: 27 | S13: =IF(AND(R13<>"",R13<>0,O13<>"",O13<>0),-R13+O13,"") -> 36 | T13: =IF(AND(S13<>"",S13<>0,R13<>0,R13<>""),S13/R13,"") -> 1.3333333
I14: Кол-во смен план/отработано | L14: =График!AI27 -> 20 | M14: 19 | N14: =IF(AND(L14<>"",L14<>0,M14<>""),M14/L14,"") -> 0.95 | O14: =L14 -> 20 | P14: =IF(AND(L14<>"",L14<>0,O14<>"",O14<>0),O14/L14,"") -> 1 | Q14: =IF(AND(M14<>0,M14<>"",L14<>0,L14<>""),O14-L14,"") -> 0 | R14: 8 | S14: =IF(AND(R14<>"",R14<>0,O14<>"",O14<>0),-R14+O14,"") -> 12 | T14: =IF(AND(S14<>"",S14<>0,R14<>0,R14<>""),S14/R14,"") -> 1.5
I15: Средние продажи в смену | L15: ='Ялта, Ленина, 18'!I15 -> 81965.52 | M15: =M8/M14 -> 41092.105 | N15: =IF(AND(L15<>"",L15<>0,M15<>""),M15/L15,"") -> 0.50133404 | O15: =M15 -> 41092.105 | P15: =IF(AND(L15<>"",L15<>0,O15<>"",O15<>0),O15/L15,"") -> 0.50133404 | Q15: =IF(AND(M15<>0,M15<>"",L15<>0,L15<>""),O15-L15,"") -> -40873.415 | R15: 30096.875 | S15: =IF(AND(R15<>"",R15<>0,O15<>"",O15<>0),-R15+O15,"") -> 10995.23 | T15: =IF(AND(S15<>"",S15<>0,R15<>0,R15<>""),S15/R15,"") -> 0.36532797
I16: Отставание/Перевыполнение | M16: =M8-L15*M14 -> -776594.88 | N16: =IF(AND(L16<>"",L16<>0,M16<>""),M16/L16,"") | O16: =M16 -> -776594.88 | P16: =IF(AND(L16<>"",L16<>0,O16<>"",O16<>0),O16/L16,"") | Q16: =IF(AND(M16<>0,M16<>"",L16<>0,L16<>""),O16-L16,"") | R16: -449387.18 | S16: =IF(AND(R16<>"",R16<>0,O16<>"",O16<>0),-R16+O16,"") -> -327207.7 | T16: =IF(AND(S16<>"",S16<>0,R16<>0,R16<>""),S16/R16,"") -> 0.72811981
I17: Трафик | L17: ='Ялта, Ленина, 18'!I17/График!AJ29*График!AJ27 -> 798.72611 | M17: =I57 -> 799 | N17: =IF(AND(L17<>"",L17<>0,M17<>""),M17/L17,"") -> 1.0003429 | O17: =M17/M14*L14 -> 841.05263 | P17: =IF(AND(L17<>"",L17<>0,O17<>"",O17<>0),O17/L17,"") -> 1.0529925 | Q17: =IF(AND(M17<>0,M17<>"",L17<>0,L17<>""),O17-L17,"") -> 42.326517 | R17: 160 | S17: =IF(AND(R17<>"",R17<>0,O17<>"",O17<>0),-R17+O17,"") -> 681.05263 | T17: =IF(AND(S17<>"",S17<>0,R17<>0,R17<>""),S17/R17,"") -> 4.2565789
I18: Выручка на вошедшего | L18: =L8/L17 -> 1366.092 | M18: =M8/M17 -> 977.15895 | N18: =IF(AND(L18<>"", L18<>0, M18<>""), M18/L18, "") -> 0.71529513 | O18: =M18 -> 977.15895 | P18: =IF(AND(L18<>"", L18<>0, O18<>"", O18<>0), O18/L18, "") -> 0.71529513 | Q18: =IF(AND(M18<>0, M18<>"", L18<>0, L18<>""), O18-L18, "") -> -388.93305 | S18: =IF(AND(R18<>"",R18<>0,O18<>"",O18<>0),-R18+O18,"") | T18: =IF(AND(S18<>"",S18<>0,R18<>0,R18<>""),S18/R18,"")
N19: =IF(AND(L19<>"",L19<>0,M19<>""),M19/L19,"") | O19: =M19 -> 0 | P19: =IF(AND(L19<>"",L19<>0,O19<>"",O19<>0),O19/L19,"") | Q19: =IF(AND(M19<>0,M19<>"",L19<>0,L19<>""),O19-L19,"") | R19: 0 | S19: =IF(AND(R19<>"",R19<>0,O19<>"",O19<>0),-R19+O19,"") | T19: =IF(AND(S19<>"",S19<>0,R19<>0,R19<>""),S19/R19,"")
I20: Конверсия план/факт | L20: ='Ялта, Ленина, 18'!I20 -> 0.108 | M20: =S57 -> 0.078848561 | N20: =M20/L20 -> 0.73007927 | O20: =IF(AND(N8<>0,L14<>0,I57<>0),(I57*S57+(I57/N8-I57)*L20)/(I57/N8),0) -> 0.087140967 | P20: =IF(AND(L20<>"",L20<>0,O20<>"",O20<>0),O20/L20,"") -> 0.80686081 | Q20: =IF(AND(M20<>0,M20<>"",L20<>0,L20<>""),O20-L20,"") -> -0.020859033 | R20: 0.16875 | S20: =IF(AND(R20<>"",R20<>0,O20<>"",O20<>0),-R20+O20,"") -> -0.081609033 | T20: =IF(AND(S20<>"",S20<>0,R20<>0,R20<>""),S20/R20,"") -> -0.48360908
B22: Факт продаж за месяц | T22: % выполнения дневного плана | U22: Раcпределение плана по дням
B23: Дата | C23: День недели | D23: Выручка (руб) | E23: Кол-во единиц (шт.) | F23: Средняя стоимость изделия (руб.) | G23: Количество чеков (шт.) | H23: Средняя сумма чека (руб.) | I23: Трафик | J23: Длина чека (шт.) | K23: UNOde50 | L23: IS | M23: Agafi | N23: Kalliope | O23: Raganella | P23: CC/MP | Q23: Antura | R23: SALE | S23: Конверсия (%) | U23: выручка, план | V23: кол-во ед, план | W23: Кол-во чеков, план | X23: выручка, скорректир.план | Y23: кол-во ед, скорр. план | Z23: кол-во чеков, скорр. план | AA23: Коэфф. Дня Недели | AB23: Специфика месяца
