Workbook
Name маг: NA()

Sheet Ялта, Ленина, 18
B1: =TODAY()-1 -> 45879
B2: (отчетная дата)
C3: Осталось до выполнения плана!!! | I3: =График!B3 -> ул. Набережная Ленина, 18
C4: =I8-D56 -> 910348.4 | E4: =IF(I8<>0, C4/I8, 0) -> 0.22312461
D5: =C4/(I14-J14) -> #DIV/0!
F6: Целевые показатели
F7: Показатель | I7: План | J7: Факт | K7: % выполнения | L7: Прогноз выполнения | M7: % выполнения по прогнозу | N7: Отклонение | O7: Факт аналогичного месяца прошлого года | P7: Отклонение LFL
F8: Выручка | I8: =I11*I12*I13 -> 4080000 | J8: =D56 -> 3169651.6 | K8: =IF(AND(I8<>"", I8<>0, J8<>""), J8/I8, "") -> 0.77687539 | L8: =IF(SUMIF($D$25:$D$55,">=0",$P$25:$P$55)<>0,I8*D56/SUMIF($D$25:$D$55,">=0",$P$25:$P$55),0) -> 3169651.6 | M8: =IF(AND(I8<>"", I8<>0, L8<>"", L8<>0), L8/I8, "") -> 0.77687539 | N8: =IF(AND(J8<>0, J8<>"", I8<>0, I8<>""), L8-I8, "") -> -910348.4 | P8: =IF(AND(O8<>"", O8<>0, L8<>"", L8<>0), -O8+L8, "") | Q8: =IF(AND(P8<>"", P8<>0, O8<>0, O8<>""), P8/O8, "")
F9: Кол-во изделий | I9: =I8/I11 -> 680 | J9: =E56 -> 559 | K9: =IF(AND(I9<>"", I9<>0, J9<>""), J9/I9, "") -> 0.82205882 | L9: =IF(SUMIF($E$25:$E$55, ">=0", $Q$25:$Q$55)<>0, I9*E56/SUMIF($E$25:$E$55, ">=0", $Q$25:$Q$55), 0) -> 559 | M9: =IF(AND(I9<>"", I9<>0, L9<>"", L9<>0), L9/I9, "") -> 0.82205882 | N9: =IF(AND(J9<>0, J9<>"", I9<>0, I9<>""), L9-I9, "") -> -121 | O9: =O8/O11 -> #DIV/0! | P9: =IF(AND(O9<>"", O9<>0, L9<>"", L9<>0), -O9+L9, "") -> #DIV/0! | Q9: =IF(AND(P9<>"", P9<>0, O9<>0, O9<>""), P9/O9, "") -> #DIV/0!
F10: Средний чек | I10: =I11*I12 -> 10200 | J10: =H56 -> 9693.1242 | K10: =IF(AND(I10<>"", I10<>0, J10<>""), J10/I10, "") -> 0.95030629 | L10: =J10 -> 9693.1242 | M10: =IF(AND(I10<>"", I10<>0, L10<>"", L10<>0), L10/I10, "") -> 0.95030629 | N10: =IF(AND(J10<>0, J10<>"", I10<>0, I10<>""), L10-I10, "") -> -506.87584 | O10: =O11*O12 -> 0 | P10: =IF(AND(O10<>"", O10<>0, L10<>"", L10<>0), -O10+L10, "") | Q10: =IF(AND(P10<>"", P10<>0, O10<>0, O10<>""), P10/O10, "") | S10: IS
F11: Средняя стоимость изделия | I11: 6000 | J11: =F56 -> 5670.2175 | K11: =IF(AND(I11<>"", I11<>0, J11<>""), J11/I11, "") -> 0.94503626 | L11: =IF(L9>0, L8/L9, "") -> 5670.2175 | M11: =IF(AND(I11<>"", I11<>0, L11<>"", L11<>0), L11/I11, "") -> 0.94503626 | N11: =IF(AND(J11<>0, J11<>"", I11<>0, I11<>""), L11-I11, "") -> -329.78247 | P11: =IF(AND(O11<>"", O11<>0, L11<>"", L11<>0), -O11+L11, "") | Q11: =IF(AND(P11<>"", P11<>0, O11<>0, O11<>""), P11/O11, "")
F12: Длина чека | I12: 1.7 | J12: =J56 -> 1.7094801 | K12: =IF(AND(I12<>"", I12<>0, J12<>""), J12/I12, "") -> 1.0055765 | L12: =J12 -> 1.7094801 | M12: =IF(AND(I12<>"", I12<>0, L12<>"", L12<>0), L12/I12, "") -> 1.0055765 | N12: =IF(AND(J12<>0, J12<>"", I12<>0, I12<>""), L12-I12, "") -> 0.0094801223 | P12: =IF(AND(O12<>"", O12<>0, L12<>"", L12<>0), -O12+L12, "") | Q12: =IF(AND(P12<>"", P12<>0, O12<>0, O12<>""), P12/O12, "") | S12: 860000 | T12: =L56 -> 393831
F13: Кол-во чеков | I13: =I17*I20 -> 400 | J13: =G56 -> 327 | K13: =IF(AND(I13<>"", I13<>0, J13<>""), J13/I13, "") -> 0.8175 | L13: =IF(SUMIF($G$25:$G$55, ">=0", $R$25:$R$55)<>0, I13*G56/SUMIF($G$25:$G$55, ">=0", $R$25:$R$55), "") -> 327 | M13: =IF(AND(I13<>"", I13<>0, L13<>"", L13<>0), L13/I13, "") -> 0.8175 | N13: =IF(AND(J13<>0, J13<>"", I13<>0, I13<>""), L13-I13, "") -> -73 | P13: =IF(AND(O13<>"", O13<>0, L13<>"", L13<>0), -O13+L13, "") | Q13: =IF(AND(P13<>"", P13<>0, O13<>0, O13<>""), P13/O13, "") | S13: =T12/S12 -> 0.45794302 | T13: =S13/J14*I14 -> 0.45794302
F14: Кол-во смен | I14: 31 | J14: 31 | K14: =IF(AND(I14<>"", I14<>0, J14<>""), J14/I14, "") -> 1 | L14: =I14 -> 31 | M14: =IF(AND(I14<>"", I14<>0, L14<>"", L14<>0), L14/I14, "") -> 1 | N14: =IF(AND(J14<>0, J14<>"", I14<>0, I14<>""), L14-I14, "") -> 0 | P14: =IF(AND(O14<>"", O14<>0, L14<>"", L14<>0), -O14+L14, "") | Q14: =IF(AND(P14<>"", P14<>0, O14<>0, O14<>""), P14/O14, "")
F15: Средние продажи в смену | I15: =I8/I14 -> 131612.9 | J15: =J8/J14 -> 102246.83 | K15: =IF(AND(I15<>"", I15<>0, J15<>""), J15/I15, "") -> 0.77687539 | L15: =J15 -> 102246.83 | M15: =IF(AND(I15<>"", I15<>0, L15<>"", L15<>0), L15/I15, "") -> 0.77687539 | N15: =IF(AND(J15<>0, J15<>"", I15<>0, I15<>""), L15-I15, "") -> -29366.077 | P15: =IF(AND(O15<>"", O15<>0, L15<>"", L15<>0), -O15+L15, "") | Q15: =IF(AND(P15<>"", P15<>0, O15<>0, O15<>""), P15/O15, "")
F16: Отставание/Перевыполнение | J16: =J8-I15*J14 -> -910348.4 | K16: =IF(AND(I16<>"", I16<>0, J16<>""), J16/I16, "") | L16: =J16 -> -910348.4 | M16: =IF(AND(I16<>"", I16<>0, L16<>"", L16<>0), L16/I16, "") | N16: =IF(AND(J16<>0, J16<>"", I16<>0, I16<>""), L16-I16, "") | P16: =IF(AND(O16<>"", O16<>0, L16<>"", L16<>0), -O16+L16, "") | Q16: =IF(AND(P16<>"", P16<>0, O16<>0, O16<>""), P16/O16, "") | S16: UNOde50
F17: Трафик | I17: 1600 | J17: =I56 -> 1890 | K17: =IF(AND(I17<>"", I17<>0, J17<>""), J17/I17, "") -> 1.18125 | L17: =J17/J14*I14 -> 1890 | M17: =IF(AND(I17<>"", I17<>0, L17<>"", L17<>0), L17/I17, "") -> 1.18125 | N17: =IF(AND(J17<>0, J17<>"", I17<>0, I17<>""), L17-I17, "") -> 290 | P17: =IF(AND(O17<>"", O17<>0, L17<>"", L17<>0), -O17+L17, "") | Q17: =IF(AND(P17<>"", P17<>0, O17<>0, O17<>""), P17/O17, "")
K18: =IF(AND(I18<>"", I18<>0, J18<>""), J18/I18, "") | L18: =J18 -> 0 | M18: =IF(AND(I18<>"", I18<>0, L18<>"", L18<>0), L18/I18, "") | N18: =IF(AND(J18<>0, J18<>"", I18<>0, I18<>""), L18-I18, "") | O18: 0 | P18: =IF(AND(O18<>"", O18<>0, L18<>"", L18<>0), -O18+L18, "") | Q18: =IF(AND(P18<>"", P18<>0, O18<>0, O18<>""), P18/O18, "") | S18: 780000 | T18: =K56 -> 684518
J19: =M56 -> 0 | K19: =IF(AND(I19<>"", I19<>0, J19<>""), J19/I19, "") | L19: =J19 -> 0 | M19: =IF(AND(I19<>"", I19<>0, L19<>"", L19<>0), L19/I19, "") | N19: =IF(AND(J19<>0, J19<>"", I19<>0, I19<>""), L19-I19, "") | O19: 0 | P19: =IF(AND(O19<>"", O19<>0, L19<>"", L19<>0), -O19+L19, "") | Q19: =IF(AND(P19<>"", P19<>0, O19<>0, O19<>""), P19/O19, "") | S19: =T18/S18 -> 0.87758718 | T19: =S19/J14*I14 -> 0.87758718
F20: Конверсия план/факт | I20: 0.25 | J20: =N56 -> 0.17301587 | K20: =J20/I20 -> 0.69206349 | L20: =IF(AND(K8<>0, I14<>0, I56<>0), (I56*N56+(I56/K8-I56)*I20)/(I56/K8), 0) -> 0.19019293 | M20: =IF(AND(I20<>"", I20<>0, L20<>"", L20<>0), L20/I20, "") -> 0.7607717 | N20: =IF(AND(J20<>0, J20<>"", I20<>0, I20<>""), L20-I20, "") -> -0.059807074 | P20: =IF(AND(O20<>"", O20<>0, L20<>"", L20<>0), -O20+L20, "") | Q20: =IF(AND(P20<>"", P20<>0, O20<>0, O20<>""), P20/O20, "")
A22: Факт продаж за месяц | O22: % выполнения дневного плана | P22: Раcпределение плана по дням
A23: Сотрудник | B23: Дата | C23: День недели | D23: Выручка (руб) | E23: Кол-во единиц (шт.) | F23: Средняя стоимость изделия (руб.) | G23: Количество чеков (шт.) | H23: Средняя сумма чека (руб.) | I23: Трафик | J23: Длина чека (шт.) | K23: UNOde50 | L23: IS | M23: Запасной | N23: Конверсия (%) | P23: выручка, план | Q23: кол-во ед, план | R23: Кол-во чеков, план | S23: выручка, скорректир.план | T23: кол-во ед, скорр. план | U23: кол-во чеков, скорр. план | V23: Коэфф. Дня Недели | W23: Специфика месяца
B24: 1 | C24: 2 | D24: 3 | E24: 4 | F24: 5 | G24: 6 | H24: 7 | I24: 8 | J24: 9 | K24: 10 | L24: 11 | M24: 12 | N24: 13 | P24: 1 | Q24: 2 | R24: 3 | S24: 4 | T24: 5 | U24: 6 | V24: 10 | W24: 11
A25: Уразгильдеева,Яковенко | B25: 45839 | C25: вт | D25: =13986+16599 -> 30585 | E25: 5 | F25: =IF(AND(E25<>"",E25<>0),D25/E25,"") -> 6117 | G25: 7 | H25: =IF(AND(G25<>"",G25<>0),D25/G25,"") -> 4369.2857 | I25: 30 | J25: =IF(AND(G25<>"",G25<>0),E25/G25,"") -> 0.71428571 | K25: 0 | L25: 5720 | N25: =IF(AND(I25<>"",I25<>0),G25/I25,"") -> 0.23333333 | O25: =D25/P25 -> 0.21811301 | P25: =$I$8*V25*W25/SUMPRODUCT($W$25:$W$55,$V$25:$V$55) -> 140225.47 | Q25: =$I$9*V25*W25/SUMPRODUCT($W$25:$W$55,$V$25:$V$55) -> 23.370912 | R25: =IF($I$12="","",Q25/$I$12) -> 13.747595 | S25: =IF(D25<>"",D25,P25) -> 30585 | T25: =IF(E25<>"",E25,Q25) -> 5 | U25: =IF(G25<>"",G25,R25) -> 7 | V25: 0.9414554 | W25: 0.9414554
A26: Рогалевич,Уразгильдеева | B26: 45840 | C26: ср | D26: =27675+32744+12397+40209 -> 113025 | E26: 18 | F26: =IF(AND(E26<>"",E26<>0),D26/E26,"") -> 6279.1667 | G26: 12 | H26: =IF(AND(G26<>"",G26<>0),D26/G26,"") -> 9418.75 | I26: 40 | J26: =IF(AND(G26<>"",G26<>0),E26/G26,"") -> 1.5 | K26: 12397 | L26: 40209 | N26: =IF(AND(I26<>"",I26<>0),G26/I26,"") -> 0.3 | O26: =D26/P26 -> 0.98162328 | P26: =$I$8*V26*W26/SUMPRODUCT($W$25:$W$55,$V$25:$V$55) -> 115140.91 | Q26: =$I$9*V26*W26/SUMPRODUCT($W$25:$W$55,$V$25:$V$55) -> 19.190152 | R26: =IF($I$12="","",Q26/$I$12) -> 11.288325 | S26: =IF(W26<>"",IF(D26<>"",D26,($I$8-SUM($S$25:S25))*V26*W26/SUMPRODUCT($W26:$W$55,$V26:$V$55)),"") -> 113025 | T26: =IF(W26<>"",IF(E26<>"",E26,($I$9-SUM($T$25:T25))*V26*W26/SUMPRODUCT($W26:$W$55,$V26:$V$55)),"") -> 18 | U26: =IF(W26<>"",IF($I$12<>"",IF(G26<>"",G26,($I$9/$I$12-SUM($U$25:U25))*V26*W26/SUMPRODUCT($W26:$W$55,$V26:$V$55)),""),"") -> 12 | V26: 0.85310234 | W26: 0.85310234
A27: Рогалевич,Яковенко | B27: 45841 | C27: чт | D27: =11403+21984+22922+24648 -> 80957 | E27: 18 | F27: =IF(AND(E27<>"",E27<>0),D27/E27,"") -> 4497.6111 | G27: 10 | H27: =IF(AND(G27<>"",G27<>0),D27/G27,"") -> 8095.7 | I27: 40 | J27: =IF(AND(G27<>"",G27<>0),E27/G27,"") -> 1.8 | K27: 21984 | L27: 11403 | N27: =IF(AND(I27<>"",I27<>0),G27/I27,"") -> 0.25 | O27: =D27/P27 -> 0.70311237 | P27: =$I$8*V27*W27/SUMPRODUCT($W$25:$W$55,$V$25:$V$55) -> 115140.91 | Q27: =$I$9*V27*W27/SUMPRODUCT($W$25:$W$55,$V$25:$V$55) -> 19.190152 | R27: =IF($I$12="","",Q27/$I$12) -> 11.288325 | S27: =IF(W27<>"",IF(D27<>"",D27,($I$8-SUM($S$25:S26))*V27*W27/SUMPRODUCT($W27:$W$55,$V27:$V$55)),"") -> 80957 | T27: =IF(W27<>"",IF(E27<>"",E27,($I$9-SUM($T$25:T26))*V27*W27/SUMPRODUCT($W27:$W$55,$V27:$V$55)),"") -> 18 | U27: =IF(W27<>"",IF($I$12<>"",IF(G27<>"",G27,($I$9/$I$12-SUM($U$25:U26))*V27*W27/SUMPRODUCT($W27:$W$55,$V27:$V$55)),""),"") -> 10 | V27: 0.85310234 | W27: 0.85310234
A28: Рогалевич,Уразгильдеева | B28: 45842 | C28: пт | D28: =56696+10503 -> 67199 | E28: 12 | F28: =IF(AND(E28<>"",E28<>0),D28/E28,"") -> 5599.9167 | G28: 6 | H28: =IF(AND(G28<>"",G28<>0),D28/G28,"") -> 11199.833 | I28: 30 | J28: =IF(AND(G28<>"",G28<>0),E28/G28,"") -> 2 | L28: 10503 | N28: =IF(AND(I28<>"",I28<>0),G28/I28,"") -> 0.2 | O28: =D28/P28 -> 0.583624 | P28: =$I$8*V28*W28/SUMPRODUCT($W$25:$W$55,$V$25:$V$55) -> 115140.91 | Q28: =$I$9*V28*W28/SUMPRODUCT($W$25:$W$55,$V$25:$V$55) -> 19.190152 | R28: =IF($I$12="","",Q28/$I$12) -> 11.288325 | S28: =IF(W28<>"",IF(D28<>"",D28,($I$8-SUM($S$25:S27))*V28*W28/SUMPRODUCT($W28:$W$55,$V28:$V$55)),"") -> 67199 | T28: =IF(W28<>"",IF(E28<>"",E28,($I$9-SUM($T$25:T27))*V28*W28/SUMPRODUCT($W28:$W$55,$V28:$V$55)),"") -> 12 | U28: =IF(W28<>"",IF($I$12<>"",IF(G28<>"",G28,($I$9/$I$12-SUM($U$25:U27))*V28*W28/SUMPRODUCT($W28:$W$55,$V28:$V$55)),""),"") -> 6 | V28: 0.85310234 | W28: 0.85310234
A29: Рогалевич,Уразгильдеева | B29: 45843 | C29: сб | D29: =20972+6203+18370+31245 -> 76790 | E29: 14 | F29: =IF(AND(E29<>"",E29<>0),D29/E29,"") -> 5485 | G29: 9 | H29: =IF(AND(G29<>"",G29<>0),D29/G29,"") -> 8532.2222 | I29: 40 | J29: =IF(AND(G29<>"",G29<>0),E29/G29,"") -> 1.5555556 | K29: 20972 | L29: 6203 | N29: =IF(AND(I29<>"",I29<>0),G29/I29,"") -> 0.225 | O29: =D29/P29 -> 0.6717991 | P29: =$I$8*V29*W29/SUMPRODUCT($W$25:$W$55,$V$25:$V$55) -> 114305.01 | Q29: =$I$9*V29*W29/SUMPRODUCT($W$25:$W$55,$V$25:$V$55) -> 19.050834 | R29: =IF($I$12="","",Q29/$I$12) -> 11.206373 | S29: =IF(W29<>"",IF(D29<>"",D29,($I$8-SUM($S$25:S28))*V29*W29/SUMPRODUCT($W29:$W$55,$V29:$V$55)),"") -> 76790 | T29: =IF(W29<>"",IF(E29<>"",E29,($I$9-SUM($T$25:T28))*V29*W29/SUMPRODUCT($W29:$W$55,$V29:$V$55)),"") -> 14 | U29: =IF(W29<>"",IF($I$12<>"",IF(G29<>"",G29,($I$9/$I$12-SUM($U$25:U28))*V29*W29/SUMPRODUCT($W29:$W$55,$V29:$V$55)),""),"") -> 9 | V29: 0.85 | W29: 0.85
A30: Рогалевич,Яковенко | B30: 45844 | C30: вс | D30: =76658+25706+17568+62588 -> 182520 | E30: 26 | F30: =IF(AND(E30<>"",E30<>0),D30/E30,"") -> 7020 | G30: 12 | H30: =IF(AND(G30<>"",G30<>0),D30/G30,"") -> 15210 | I30: 70 | J30: =IF(AND(G30<>"",G30<>0),E30/G30,"") -> 2.1666667 | K30: 76658 | L30: 25706 | N30: =IF(AND(I30<>"",I30<>0),G30/I30,"") -> 0.17142857 | O30: =D30/P30 -> 1.1536739 | P30: =$I$8*V30*W30/SUMPRODUCT($W$25:$W$55,$V$25:$V$55) -> 158207.62 | Q30: =$I$9*V30*W30/SUMPRODUCT($W$25:$W$55,$V$25:$V$55) -> 26.367937 | R30: =IF($I$12="","",Q30/$I$12) -> 15.510551 | S30: =IF(W30<>"",IF(D30<>"",D30,($I$8-SUM($S$25:S29))*V30*W30/SUMPRODUCT($W30:$W$55,$V30:$V$55)),"") -> 182520 | T30: =IF(W30<>"",IF(E30<>"",E30,($I$9-SUM($T$25:T29))*V30*W30/SUMPRODUCT($W30:$W$55,$V30:$V$55)),"") -> 26 | U30: =IF(W30<>"",IF($I$12<>"",IF(G30<>"",G30,($I$9/$I$12-SUM($U$25:U29))*V30*W30/SUMPRODUCT($W30:$W$55,$V30:$V$55)),""),"") -> 12 | V30: 1 | W30: 1
A31: Рогалевич,Яковенко | B31: 45845 | C31: пн | D31: =58719+12068+10874 -> 81661 | E31: 10 | F31: =IF(AND(E31<>"",E31<>0),D31/E31,"") -> 8166.1 | G31: 7 | H31: =IF(AND(G31<>"",G31<>0),D31/G31,"") -> 11665.857 | I31: 50 | J31: =IF(AND(G31<>"",G31<>0),E31/G31,"") -> 1.4285714 | K31: =19984+38735 -> 58719 | N31: =IF(AND(I31<>"",I31<>0),G31/I31,"") -> 0.14 | O31: =D31/P31 -> 0.70922662 | P31: =$I$8*V31*W31/SUMPRODUCT($W$25:$W$55,$V$25:$V$55) -> 115140.91 | Q31: =$I$9*V31*W31/SUMPRODUCT($W$25:$W$55,$V$25:$V$55) -> 19.190152 | R31: =IF($I$12="","",Q31/$I$12) -> 11.288325 | S31: =IF(W31<>"",IF(D31<>"",D31,($I$8-SUM($S$25:S30))*V31*W31/SUMPRODUCT($W31:$W$55,$V31:$V$55)),"") -> 81661 | T31: =IF(W31<>"",IF(E31<>"",E31,($I$9-SUM($T$25:T30))*V31*W31/SUMPRODUCT($W31:$W$55,$V31:$V$55)),"") -> 10 | U31: =IF(W31<>"",IF($I$12<>"",IF(G31<>"",G31,($I$9/$I$12-SUM($U$25:U30))*V31*W31/SUMPRODUCT($W31:$W$55,$V31:$V$55)),""),"") -> 7 | V31: 0.85310234 | W31: 0.85310234
A32: Яковенко,Уразгильдеева | B32: 45846 | C32: вт | D32: =34806+17992+6684+32506 -> 91988 | E32: 15 | F32: =IF(AND(E32<>"",E32<>0),D32/E32,"") -> 6132.5333 | G32: 9 | H32: =IF(AND(G32<>"",G32<>0),D32/G32,"") -> 10220.889 | I32: 50 | J32: =IF(AND(G32<>"",G32<>0),E32/G32,"") -> 1.6666667 | K32: 17992 | L32: =25903+8903 -> 34806 | N32: =IF(AND(I32<>"",I32<>0),G32/I32,"") -> 0.18 | O32: =D32/P32 -> 0.79891672 | P32: =$I$8*V32*W32/SUMPRODUCT($W$25:$W$55,$V$25:$V$55) -> 115140.91 | Q32: =$I$9*V32*W32/SUMPRODUCT($W$25:$W$55,$V$25:$V$55) -> 19.190152 | R32: =IF($I$12="","",Q32/$I$12) -> 11.288325 | S32: =IF(W32<>"",IF(D32<>"",D32,($I$8-SUM($S$25:S31))*V32*W32/SUMPRODUCT($W32:$W$55,$V32:$V$55)),"") -> 91988 | T32: =IF(W32<>"",IF(E32<>"",E32,($I$9-SUM($T$25:T31))*V32*W32/SUMPRODUCT($W32:$W$55,$V32:$V$55)),"") -> 15 | U32: =IF(W32<>"",IF($I$12<>"",IF(G32<>"",G32,($I$9/$I$12-SUM($U$25:U31))*V32*W32/SUMPRODUCT($W32:$W$55,$V32:$V$55)),""),"") -> 9 | V32: 0.85310234 | W32: 0.85310234
A33: Рогалевич,Уразгильдеева | B33: 45847 | C33: ср | D33: =8903+10592+21259+22463 -> 63217 | E33: 12 | F33: =IF(AND(E33<>"",E33<>0),D33/E33,"") -> 5268.0833 | G33: 9 | H33: =IF(AND(G33<>"",G33<>0),D33/G33,"") -> 7024.1111 | I33: 50 | J33: =IF(AND(G33<>"",G33<>0),E33/G33,"") -> 1.3333333 | K33: 10592 | L33: 8903 | N33: =IF(AND(I33<>"",I33<>0),G33/I33,"") -> 0.18 | O33: =D33/P33 -> 0.54904029 | P33: =$I$8*V33*W33/SUMPRODUCT($W$25:$W$55,$V$25:$V$55) -> 115140.91 | Q33: =$I$9*V33*W33/SUMPRODUCT($W$25:$W$55,$V$25:$V$55) -> 19.190152 | R33: =IF($I$12="","",Q33/$I$12) -> 11.288325 | S33: =IF(W33<>"",IF(D33<>"",D33,($I$8-SUM($S$25:S32))*V33*W33/SUMPRODUCT($W33:$W$55,$V33:$V$55)),"") -> 63217 | T33: =IF(W33<>"",IF(E33<>"",E33,($I$9-SUM($T$25:T32))*V33*W33/SUMPRODUCT($W33:$W$55,$V33:$V$55)),"") -> 12 | U33: =IF(W33<>"",IF($I$12<>"",IF(G33<>"",G33,($I$9/$I$12-SUM($U$25:U32))*V33*W33/SUMPRODUCT($W33:$W$55,$V33:$V$55)),""),"") -> 9 | V33: 0.85310234 | W33: 0.85310234
A34: Рогалевич,Яковенко | B34: 45848 | C34: чт | D34: =28836+75897+10491+24903 -> 140127 | E34: 23 | F34: =IF(AND(E34<>"",E34<>0),D34/E34,"") -> 6092.4783 | G34: 12 | H34: =IF(AND(G34<>"",G34<>0),D34/G34,"") -> 11677.25 | I34: 70 | J34: =IF(AND(G34<>"",G34<>0),E34/G34,"") -> 1.9166667 | K34: 10491 | L34: 24903 | N34: =IF(AND(I34<>"",I34<>0),G34/I34,"") -> 0.17142857 | O34: =D34/P34 -> 1.2170044 | P34: =$I$8*V34*W34/SUMPRODUCT($W$25:$W$55,$V$25:$V$55) -> 115140.91 | Q34: =$I$9*V34*W34/SUMPRODUCT($W$25:$W$55,$V$25:$V$55) -> 19.190152 | R34: =IF($I$12="","",Q34/$I$12) -> 11.288325 | S34: =IF(W34<>"",IF(D34<>"",D34,($I$8-SUM($S$25:S33))*V34*W34/SUMPRODUCT($W34:$W$55,$V34:$V$55)),"") -> 140127 | T34: =IF(W34<>"",IF(E34<>"",E34,($I$9-SUM($T$25:T33))*V34*W34/SUMPRODUCT($W34:$W$55,$V34:$V$55)),"") -> 23 | U34: =IF(W34<>"",IF($I$12<>"",IF(G34<>"",G34,($I$9/$I$12-SUM($U$25:U33))*V34*W34/SUMPRODUCT($W34:$W$55,$V34:$V$55)),""),"") -> 12 | V34: 0.85310234 | W34: 0.85310234
A35: Рогалевич,Яковенко | B35: 45849 | C35: пт | D35: =24990+42706+14959 -> 82655 | E35: 14 | F35: =IF(AND(E35<>"",E35<>0),D35/E35,"") -> 5903.9286 | G35: 9 | H35: =IF(AND(G35<>"",G35<>0),D35/G35,"") -> 9183.8889 | I35: 60 | J35: =IF(AND(G35<>"",G35<>0),E35/G35,"") -> 1.5555556 | K35: 24990 | N35: =IF(AND(I35<>"",I35<>0),G35/I35,"") -> 0.15 | O35: =D35/P35 -> 0.52244639 | P35: =$I$8*V35*W35/SUMPRODUCT($W$25:$W$55,$V$25:$V$55) -> 158207.62 | Q35: =$I$9*V35*W35/SUMPRODUCT($W$25:$W$55,$V$25:$V$55) -> 26.367937 | R35: =IF($I$12="","",Q35/$I$12) -> 15.510551 | S35: =IF(W35<>"",IF(D35<>"",D35,($I$8-SUM($S$25:S34))*V35*W35/SUMPRODUCT($W35:$W$55,$V35:$V$55)),"") -> 82655 | T35: =IF(W35<>"",IF(E35<>"",E35,($I$9-SUM($T$25:T34))*V35*W35/SUMPRODUCT($W35:$W$55,$V35:$V$55)),"") -> 14 | U35: =IF(W35<>"",IF($I$12<>"",IF(G35<>"",G35,($I$9/$I$12-SUM($U$25:U34))*V35*W35/SUMPRODUCT($W35:$W$55,$V35:$V$55)),""),"") -> 9 | V35: 1 | W35: 1
A36: Рогалевич,Яковенко,Уразгильдеева | B36: 45850 | C36: сб | D36: =57567+72793+35483.6+16758 -> 182601.6 | E36: 30 | F36: =IF(AND(E36<>"",E36<>0),D36/E36,"") -> 6086.72 | G36: 14 | H36: =IF(AND(G36<>"",G36<>0),D36/G36,"") -> 13042.971 | I36: 90 | J36: =IF(AND(G36<>"",G36<>0),E36/G36,"") -> 2.1428571 | K36: 57567 | N36: =IF(AND(I36<>"",I36<>0),G36/I36,"") -> 0.15555556 | O36: =D36/P36 -> 1.031162 | P36: =$I$8*V36*W36/SUMPRODUCT($W$25:$W$55,$V$25:$V$55) -> 177083.33 | Q36: =$I$9*V36*W36/SUMPRODUCT($W$25:$W$55,$V$25:$V$55) -> 29.513888 | R36: =IF($I$12="","",Q36/$I$12) -> 17.36111 | S36: =IF(W36<>"",IF(D36<>"",D36,($I$8-SUM($S$25:S35))*V36*W36/SUMPRODUCT($W36:$W$55,$V36:$V$55)),"") -> 182601.6 | T36: =IF(W36<>"",IF(E36<>"",E36,($I$9-SUM($T$25:T35))*V36*W36/SUMPRODUCT($W36:$W$55,$V36:$V$55)),"") -> 30 | U36: =IF(W36<>"",IF($I$12<>"",IF(G36<>"",G36,($I$9/$I$12-SUM($U$25:U35))*V36*W36/SUMPRODUCT($W36:$W$55,$V36:$V$55)),""),"") -> 14 | V36: 1.0579743 | W36: 1.0579743
A37: Рогалевич,Уразгильдеева | B37: 45851 | C37: вс | D37: =27565+16368+32106+9993 -> 86032 | E37: 12 | F37: =IF(AND(E37<>"",E37<>0),D37/E37,"") -> 7169.3333 | G37: 10 | H37: =IF(AND(G37<>"",G37<>0),D37/G37,"") -> 8603.2 | I37: 70 | J37: =IF(AND(G37<>"",G37<>0),E37/G37,"") -> 1.2 | K37: 9993 | L37: 32106 | N37: =IF(AND(I37<>"",I37<>0),G37/I37,"") -> 0.14285714 | O37: =D37/P37 -> 0.48582779 | P37: =$I$8*V37*W37/SUMPRODUCT($W$25:$W$55,$V$25:$V$55) -> 177083.33 | Q37: =$I$9*V37*W37/SUMPRODUCT($W$25:$W$55,$V$25:$V$55) -> 29.513888 | R37: =IF($I$12="","",Q37/$I$12) -> 17.36111 | S37: =IF(W37<>"",IF(D37<>"",D37,($I$8-SUM($S$25:S36))*V37*W37/SUMPRODUCT($W37:$W$55,$V37:$V$55)),"") -> 86032 | T37: =IF(W37<>"",IF(E37<>"",E37,($I$9-SUM($T$25:T36))*V37*W37/SUMPRODUCT($W37:$W$55,$V37:$V$55)),"") -> 12 | U37: =IF(W37<>"",IF($I$12<>"",IF(G37<>"",G37,($I$9/$I$12-SUM($U$25:U36))*V37*W37/SUMPRODUCT($W37:$W$55,$V37:$V$55)),""),"") -> 10 | V37: 1.0579743 | W37: 1.0579743
A38: Рогалевич,Яковенко | B38: 45852 | C38: пн | D38: =55154+21805+29881+71171 -> 178011 | E38: 27 | F38: =IF(AND(E38<>"",E38<>0),D38/E38,"") -> 6593 | G38: 20 | H38: =IF(AND(G38<>"",G38<>0),D38/G38,"") -> 8900.55 | I38: 90 | J38: =IF(AND(G38<>"",G38<>0),E38/G38,"") -> 1.35 | K38: 55154 | L38: 21805 | N38: =IF(AND(I38<>"",I38<>0),G38/I38,"") -> 0.22222222 | O38: =D38/P38 -> 1.5460274 | P38: =$I$8*V38*W38/SUMPRODUCT($W$25:$W$55,$V$25:$V$55) -> 115140.91 | Q38: =$I$9*V38*W38/SUMPRODUCT($W$25:$W$55,$V$25:$V$55) -> 19.190152 | R38: =IF($I$12="","",Q38/$I$12) -> 11.288325 | S38: =IF(W38<>"",IF(D38<>"",D38,($I$8-SUM($S$25:S37))*V38*W38/SUMPRODUCT($W38:$W$55,$V38:$V$55)),"") -> 178011 | T38: =IF(W38<>"",IF(E38<>"",E38,($I$9-SUM($T$25:T37))*V38*W38/SUMPRODUCT($W38:$W$55,$V38:$V$55)),"") -> 27 | U38: =IF(W38<>"",IF($I$12<>"",IF(G38<>"",G38,($I$9/$I$12-SUM($U$25:U37))*V38*W38/SUMPRODUCT($W38:$W$55,$V38:$V$55)),""),"") -> 20 | V38: 0.85310234 | W38: 0.85310234
A39: Рогалевич,Яковенко | B39: 45853 | C39: вт | D39: =6203+122902+15666+21450 -> 166221 | E39: 18 | F39: =IF(AND(E39<>"",E39<>0),D39/E39,"") -> 9234.5 | G39: 9 | H39: =IF(AND(G39<>"",G39<>0),D39/G39,"") -> 18469 | I39: 70 | J39: =IF(AND(G39<>"",G39<>0),E39/G39,"") -> 2 | K39: =109909+12993 -> 122902 | L39: 6203 | N39: =IF(AND(I39<>"",I39<>0),G39/I39,"") -> 0.12857143 | O39: =D39/P39 -> 1.4436311 | P39: =$I$8*V39*W39/SUMPRODUCT($W$25:$W$55,$V$25:$V$55) -> 115140.91 | Q39: =$I$9*V39*W39/SUMPRODUCT($W$25:$W$55,$V$25:$V$55) -> 19.190152 | R39: =IF($I$12="","",Q39/$I$12) -> 11.288325 | S39: =IF(W39<>"",IF(D39<>"",D39,($I$8-SUM($S$25:S38))*V39*W39/SUMPRODUCT($W39:$W$55,$V39:$V$55)),"") -> 166221 | T39: =IF(W39<>"",IF(E39<>"",E39,($I$9-SUM($T$25:T38))*V39*W39/SUMPRODUCT($W39:$W$55,$V39:$V$55)),"") -> 18 | U39: =IF(W39<>"",IF($I$12<>"",IF(G39<>"",G39,($I$9/$I$12-SUM($U$25:U38))*V39*W39/SUMPRODUCT($W39:$W$55,$V39:$V$55)),""),"") -> 9 | V39: 0.85310234 | W39: 0.85310234
A40: Уразгильдеева,Яковенко | B40: 45854 | C40: ср | D40: =15184+15796+12069+25450 -> 68499 | E40: 14 | F40: =IF(AND(E40<>"",E40<>0),D40/E40,"") -> 4892.7857 | G40: 8 | H40: =IF(AND(G40<>"",G40<>0),D40/G40,"") -> 8562.375 | I40: 40 | J40: =IF(AND(G40<>"",G40<>0),E40/G40,"") -> 1.75 | K40: 15184 | L40: 15796 | N40: =IF(AND(I40<>"",I40<>0),G40/I40,"") -> 0.2 | O40: =D40/P40 -> 0.59491452 | P40: =$I$8*V40*W40/SUMPRODUCT($W$25:$W$55,$V$25:$V$55) -> 115140.91 | Q40: =$I$9*V40*W40/SUMPRODUCT($W$25:$W$55,$V$25:$V$55) -> 19.190152 | R40: =IF($I$12="","",Q40/$I$12) -> 11.288325 | S40: =IF(W40<>"",IF(D40<>"",D40,($I$8-SUM($S$25:S39))*V40*W40/SUMPRODUCT($W40:$W$55,$V40:$V$55)),"") -> 68499 | T40: =IF(W40<>"",IF(E40<>"",E40,($I$9-SUM($T$25:T39))*V40*W40/SUMPRODUCT($W40:$W$55,$V40:$V$55)),"") -> 14 | U40: =IF(W40<>"",IF($I$12<>"",IF(G40<>"",G40,($I$9/$I$12-SUM($U$25:U39))*V40*W40/SUMPRODUCT($W40:$W$55,$V40:$V$55)),""),"") -> 8 | V40: 0.85310234 | W40: 0.85310234
A41: Рогалевич,Уразгильдеева | B41: 45855 | C41: чт | D41: =51866+8202+42831+32345 -> 135244 | E41: 21 | F41: =IF(AND(E41<>"",E41<>0),D41/E41,"") -> 6440.1905 | G41: 14 | H41: =IF(AND(G41<>"",G41<>0),D41/G41,"") -> 9660.2857 | I41: 70 | J41: =IF(AND(G41<>"",G41<>0),E41/G41,"") -> 1.5 | K41: 51866 | L41: 8202 | N41: =IF(AND(I41<>"",I41<>0),G41/I41,"") -> 0.2 | O41: =D41/P41 -> 1.1745955 | P41: =$I$8*V41*W41/SUMPRODUCT($W$25:$W$55,$V$25:$V$55) -> 115140.91 | Q41: =$I$9*V41*W41/SUMPRODUCT($W$25:$W$55,$V$25:$V$55) -> 19.190152 | R41: =IF($I$12="","",Q41/$I$12) -> 11.288325 | S41: =IF(W41<>"",IF(D41<>"",D41,($I$8-SUM($S$25:S40))*V41*W41/SUMPRODUCT($W41:$W$55,$V41:$V$55)),"") -> 135244 | T41: =IF(W41<>"",IF(E41<>"",E41,($I$9-SUM($T$25:T40))*V41*W41/SUMPRODUCT($W41:$W$55,$V41:$V$55)),"") -> 21 | U41: =IF(W41<>"",IF($I$12<>"",IF(G41<>"",G41,($I$9/$I$12-SUM($U$25:U40))*V41*W41/SUMPRODUCT($W41:$W$55,$V41:$V$55)),""),"") -> 14 | V41: 0.85310234 | W41: 0.85310234
...

Sheet Св. по пок.
A2: Показатель | D2: ='Ялта, Ленина, 18'!I3 -> ул. Набережная Ленина, 18 | G2: =График!B29 -> Рогалевич Ирина | J2: =График!B28 -> Уразгильдеева Екатерина | M2: =График!B27 -> Яковенко Алина
D3: Факт | F3: Прогноз | G3: Факт | I3: Прогноз | J3: Факт | L3: Прогноз | M3: Факт | O3: Прогноз
A4: Выручка | D4: ='Ялта, Ленина, 18'!K8 -> 0.77687539 | E4: ='Ялта, Ленина, 18'!J8 -> 3169651.6 | F4: ='Ялта, Ленина, 18'!M8 -> 0.77687539 | G4: ='Рогалевич И. Е.'!K8 -> 1.0893173 | H4: ='Рогалевич И. Е.'!J8 -> 1740554 | I4: ='Рогалевич И. Е.'!M8 -> 1.0893173 | J4: ='Уразгильдеева Е. Р.'!K8 -> 0.56926097 | K4: ='Уразгильдеева Е. Р.'!J8 -> 801378 | L4: ='Уразгильдеева Е. Р.'!M8 -> 0.56926097 | M4: ='ПК 4'!K8 | N4: ='ПК 4'!J8 -> 0 | O4: ='ПК 4'!M8
A5: Кол-во изделий | D5: ='Ялта, Ленина, 18'!K9 -> 0.82205882 | E5: ='Ялта, Ленина, 18'!J9 -> 559 | F5: ='Ялта, Ленина, 18'!M9 -> 0.82205882 | G5: ='Рогалевич И. Е.'!K9 -> 1.1227662 | H5: ='Рогалевич И. Е.'!J9 -> 299 | I5: ='Рогалевич И. Е.'!M9 -> 1.1227662 | J5: ='Уразгильдеева Е. Р.'!K9 -> 0.66062795 | K5: ='Уразгильдеева Е. Р.'!J9 -> 155 | L5: ='Уразгильдеева Е. Р.'!M9 -> 0.66062795 | M5: ='ПК 4'!K9 | N5: ='ПК 4'!J9 -> 0 | O5: ='ПК 4'!M9
A6: Средний чек | D6: ='Ялта, Ленина, 18'!K10 -> 0.95030629 | E6: ='Ялта, Ленина, 18'!J10 -> 9693.1242 | F6: ='Ялта, Ленина, 18'!M10 -> 0.95030629 | G6: ='Рогалевич И. Е.'!K10 -> 1.0800161 | H6: ='Рогалевич И. Е.'!J10 -> 11016.165 | I6: ='Рогалевич И. Е.'!M10 -> 1.0800161 | J6: ='Уразгильдеева Е. Р.'!K10 -> 0.78566471 | K6: ='Уразгильдеева Е. Р.'!J10 -> 8013.78 | L6: ='Уразгильдеева Е. Р.'!M10 -> 0.78566471 | M6: ='ПК 4'!K10 | N6: ='ПК 4'!J10 | O6: ='ПК 4'!M10
A7: Средняя стоимость изделия | D7: ='Ялта, Ленина, 18'!K11 -> 0.94503626 | E7: ='Ялта, Ленина, 18'!J11 -> 5670.2175 | F7: ='Ялта, Ленина, 18'!M11 -> 0.94503626 | G7: ='Рогалевич И. Е.'!K11 -> 0.97020847 | H7: ='Рогалевич И. Е.'!J11 -> 5821.2508 | I7: ='Рогалевич И. Е.'!M11 -> 0.97020847 | J7: ='Уразгильдеева Е. Р.'!K11 -> 0.86169677 | K7: ='Уразгильдеева Е. Р.'!J11 -> 5170.1806 | L7: ='Уразгильдеева Е. Р.'!M11 -> 0.86169677 | M7: ='ПК 4'!K11 | N7: ='ПК 4'!J11 | O7: ='ПК 4'!M11
A8: Длина чека | D8: ='Ялта, Ленина, 18'!K12 -> 1.0055765 | E8: ='Ялта, Ленина, 18'!J12 -> 1.7094801 | F8: ='Ялта, Ленина, 18'!M12 -> 1.0055765 | G8: ='Рогалевич И. Е.'!K12 -> 1.1131794 | H8: ='Рогалевич И. Е.'!J12 -> 1.8924051 | I8: ='Рогалевич И. Е.'!M12 -> 1.1131794 | J8: ='Уразгильдеева Е. Р.'!K12 -> 0.91176471 | K8: ='Уразгильдеева Е. Р.'!J12 -> 1.55 | L8: ='Уразгильдеева Е. Р.'!M12 -> 0.91176471 | M8: ='ПК 4'!K12 | N8: ='ПК 4'!J12 | O8: ='ПК 4'!M12
A9: Кол-во чеков | D9: ='Ялта, Ленина, 18'!K13 -> 0.8175 | E9: ='Ялта, Ленина, 18'!J13 -> 327 | F9: ='Ялта, Ленина, 18'!M13 -> 0.8175 | G9: ='Рогалевич И. Е.'!K13 -> 1.0086121 | H9: ='Рогалевич И. Е.'!J13 -> 158 | I9: ='Рогалевич И. Е.'!M13 -> 1.0086121 | J9: ='Уразгильдеева Е. Р.'!K13 -> 0.72455969 | K9: ='Уразгильдеева Е. Р.'!J13 -> 100 | L9: ='Уразгильдеева Е. Р.'!M13 -> 0.72455969 | M9: ='ПК 4'!K13 -> 0 | N9: ='ПК 4'!J13 -> 0 | O9: ='ПК 4'!M13
A10: Кол-во смен план/отработано | D10: ='Ялта, Ленина, 18'!K14 -> 1 | E10: ='Ялта, Ленина, 18'!J14 -> 31 | G10: ='Рогалевич И. Е.'!K14 -> 1 | H10: ='Рогалевич И. Е.'!J14 -> 26 | J10: ='Уразгильдеева Е. Р.'!K14 -> 1 | K10: ='Уразгильдеева Е. Р.'!J14 -> 21 | M10: ='ПК 4'!K14 -> 0.92857143 | N10: ='ПК 4'!J14 -> 13
A11: Средние продажи в смену | D11: ='Ялта, Ленина, 18'!K15 -> 0.77687539 | E11: ='Ялта, Ленина, 18'!J15 -> 102246.83 | F11: ='Ялта, Ленина, 18'!M15 -> 0.77687539 | G11: ='Рогалевич И. Е.'!K15 -> 0.50864606 | H11: ='Рогалевич И. Е.'!J15 -> 66944.385 | I11: ='Рогалевич И. Е.'!M15 -> 0.50864606 | J11: ='Уразгильдеева Е. Р.'!K15 -> 0.28994769 | K11: ='Уразгильдеева Е. Р.'!J15 -> 38160.857 | L11: ='Уразгильдеева Е. Р.'!M15 -> 0.28994769 | M11: ='ПК 4'!K15 -> 0 | N11: ='ПК 4'!J15 -> 0 | O11: ='ПК 4'!M15
A12: Трафик | D12: ='Ялта, Ленина, 18'!K17 -> 1.18125 | E12: ='Ялта, Ленина, 18'!J17 -> 1890 | F12: ='Ялта, Ленина, 18'!M17 -> 1.18125 | G12: ='Рогалевич И. Е.'!K17 -> 1.3325808 | H12: ='Рогалевич И. Е.'!J17 -> 835 | I12: ='Рогалевич И. Е.'!M17 -> 1.3325808 | J12: ='Уразгильдеева Е. Р.'!K17 -> 1.0958965 | K12: ='Уразгильдеева Е. Р.'!J17 -> 605 | L12: ='Уразгильдеева Е. Р.'!M17 -> 1.0958965 | M12: ='ПК 4'!K17 -> 0 | N12: ='ПК 4'!J17 -> 0 | O12: ='ПК 4'!M17
A13: UNOde50 | D13: ='Ялта, Ленина, 18'!S19 -> 0.87758718 | E13: ='Ялта, Ленина, 18'!T18 -> 684518 | F13: ='Ялта, Ленина, 18'!T19 -> 0.87758718 | G13: ='Рогалевич И. Е.'!S19 -> 1.4482209 | H13: ='Рогалевич И. Е.'!T18 -> 442387 | I13: ='Рогалевич И. Е.'!T19 -> 1.4482209 | J13: ='Уразгильдеева Е. Р.'!S19 -> 0.22055968 | K13: ='Уразгильдеева Е. Р.'!T18 -> 59359 | L13: ='Уразгильдеева Е. Р.'!T19 -> 0.22055968 | M13: ='ПК 4'!S19 -> 0 | N13: ='ПК 4'!T18 -> 0 | O13: ='ПК 4'!T19 -> 0
A14: IS | D14: ='Ялта, Ленина, 18'!S13 -> 0.45794302 | E14: ='Ялта, Ленина, 18'!T12 -> 393831 | F14: ='Ялта, Ленина, 18'!T13 -> 0.45794302 | G14: ='Рогалевич И. Е.'!S13 -> 0.58327291 | H14: ='Рогалевич И. Е.'!T12 -> 196446 | I14: ='Рогалевич И. Е.'!T13 -> 0.58327291 | J14: ='Уразгильдеева Е. Р.'!S13 -> 0.44377764 | K14: ='Уразгильдеева Е. Р.'!T12 -> 131683 | L14: ='Уразгильдеева Е. Р.'!T13 -> 0.44377764 | M14: ='ПК 4'!S13 -> 0 | N14: ='ПК 4'!T12 -> 0 | O14: ='ПК 4'!T13 -> 0
A15: Отклонение от плана | D15: ='Ялта, Ленина, 18'!J16 -> -910348.4 | G15: ='Рогалевич И. Е.'!N8 -> 142714.7 | J15: ='Уразгильдеева Е. Р.'!N8 -> -606373.52 | M15: ='ПК 4'!N8
A37: Показатель | D37: ='Ялта, Ленина, 18'!I38 -> 90 | G37: =График!B64 -> 0 | J37: =График!B63 -> 0 | M37: =График!B62 -> 0
D38: Факт | F38: Прогноз | G38: Факт | I38: Прогноз | J38: Факт | L38: Прогноз | M38: Факт | O38: Прогноз
A39: Выручка | D39: ='Ялта, Ленина, 18'!K43 -> 18483 | E39: ='Ялта, Ленина, 18'!J43 -> 1.3636364 | F39: ='Ялта, Ленина, 18'!M43 -> 0 | G39: ='Рогалевич И. Е.'!K43 -> 0 | H39: ='Рогалевич И. Е.'!J43 -> 1 | I39: ='Рогалевич И. Е.'!M43 -> 0 | J39: ='Уразгильдеева Е. Р.'!K43 -> 0 | K39: ='Уразгильдеева Е. Р.'!J43 -> 2 | L39: ='Уразгильдеева Е. Р.'!M43 -> 0 | M39: ='ПК 4'!K43 -> 0 | N39: ='ПК 4'!J43 | O39: ='ПК 4'!M43 -> 0
A40: Кол-во изделий | D40: ='Ялта, Ленина, 18'!K44 -> 0 | E40: ='Ялта, Ленина, 18'!J44 -> 1.7777778 | F40: ='Ялта, Ленина, 18'!M44 -> 0 | G40: ='Рогалевич И. Е.'!K44 -> 12242 | H40: ='Рогалевич И. Е.'!J44 -> 2 | I40: ='Рогалевич И. Е.'!M44 -> 0 | J40: ='Уразгильдеева Е. Р.'!K44 -> 0 | K40: ='Уразгильдеева Е. Р.'!J44 -> 2.1 | L40: ='Уразгильдеева Е. Р.'!M44 -> 0 | M40: ='ПК 4'!K44 -> 0 | N40: ='ПК 4'!J44 | O40: ='ПК 4'!M44 -> 0
A41: Средний чек | D41: ='Ялта, Ленина, 18'!K45 -> 54657 | E41: ='Ялта, Ленина, 18'!J45 -> 1.7058824 | F41: ='Ялта, Ленина, 18'!M45 -> 0 | G41: ='Рогалевич И. Е.'!K45 -> 0 | H41: ='Рогалевич И. Е.'!J45 -> 3.3333333 | I41: ='Рогалевич И. Е.'!M45 -> 0 | J41: ='Уразгильдеева Е. Р.'!K45 -> 16991 | K41: ='Уразгильдеева Е. Р.'!J45 -> 1.7777778 | L41: ='Уразгильдеева Е. Р.'!M45 -> 0 | M41: ='ПК 4'!K45 -> 0 | N41: ='ПК 4'!J45 | O41: ='ПК 4'!M45 -> 0
A42: Средняя стоимость изделия | D42: ='Ялта, Ленина, 18'!K46 -> 0 | E42: ='Ялта, Ленина, 18'!J46 -> 1 | F42: ='Ялта, Ленина, 18'!M46 -> 0 | G42: ='Рогалевич И. Е.'!K46 -> 0 | H42: ='Рогалевич И. Е.'!J46 -> 1.6666667 | I42: ='Рогалевич И. Е.'!M46 -> 0 | J42: ='Уразгильдеева Е. Р.'!K46 -> 0 | K42: ='Уразгильдеева Е. Р.'!J46 | L42: ='Уразгильдеева Е. Р.'!M46 -> 0 | M42: ='ПК 4'!K46 -> 0 | N42: ='ПК 4'!J46 | O42: ='ПК 4'!M46 -> 0
A43: Длина чека | D43: ='Ялта, Ленина, 18'!K47 -> 12242 | E43: ='Ялта, Ленина, 18'!J47 -> 2 | F43: ='Ялта, Ленина, 18'!M47 -> 0 | G43: ='Рогалевич И. Е.'!K47 -> 0 | H43: ='Рогалевич И. Е.'!J47 -> 2.4 | I43: ='Рогалевич И. Е.'!M47 -> 0 | J43: ='Уразгильдеева Е. Р.'!K47 -> 0 | K43: ='Уразгильдеева Е. Р.'!J47 | L43: ='Уразгильдеева Е. Р.'!M47 -> 0 | M43: ='ПК 4'!K47 -> 0 | N43: ='ПК 4'!J47 | O43: ='ПК 4'!M47 -> 0
A44: Кол-во чеков | D44: ='Ялта, Ленина, 18'!K48 -> 0 | E44: ='Ялта, Ленина, 18'!J48 -> 2.1666667 | F44: ='Ялта, Ленина, 18'!M48 -> 0 | G44: ='Рогалевич И. Е.'!K48 -> 6691 | H44: ='Рогалевич И. Е.'!J48 -> 2 | I44: ='Рогалевич И. Е.'!M48 -> 0 | J44: ='Уразгильдеева Е. Р.'!K48 -> 0 | K44: ='Уразгильдеева Е. Р.'!J48 | L44: ='Уразгильдеева Е. Р.'!M48 -> 0 | M44: ='ПК 4'!K48 -> 0 | N44: ='ПК 4'!J48 | O44: ='ПК 4'!M48 -> 0
A45: Кол-во смен план/отработано | D45: ='Ялта, Ленина, 18'!K49 -> 0 | E45: ='Ялта, Ленина, 18'!J49 -> 1.7 | G45: ='Рогалевич И. Е.'!K49 -> 0 | H45: ='Рогалевич И. Е.'!J49 -> 2.3333333 | J45: ='Уразгильдеева Е. Р.'!K49 -> 0 | K45: ='Уразгильдеева Е. Р.'!J49 | M45: ='ПК 4'!K49 -> 0 | N45: ='ПК 4'!J49 -> 0
A46: Средние продажи в смену | D46: ='Ялта, Ленина, 18'!K50 -> 0 | E46: ='Ялта, Ленина, 18'!J50 -> 2.2857143 | F46: ='Ялта, Ленина, 18'!M50 -> 0 | G46: ='Рогалевич И. Е.'!K50 -> 0 | H46: ='Рогалевич И. Е.'!J50 -> 2 | I46: ='Рогалевич И. Е.'!M50 -> 0 | J46: ='Уразгильдеева Е. Р.'!K50 -> 59359 | K46: ='Уразгильдеева Е. Р.'!J50 -> 1.55 | L46: ='Уразгильдеева Е. Р.'!M50 -> 0 | M46: ='ПК 4'!K50 -> 0 | N46: ='ПК 4'!J50 -> 0 | O46: ='ПК 4'!M50 -> 0
A47: Трафик | D47: ='Ялта, Ленина, 18'!K52 -> 0 | E47: ='Ялта, Ленина, 18'!J52 -> 2.3333333 | F47: ='Ялта, Ленина, 18'!M52 -> 0 | G47: ='Рогалевич И. Е.'!K52 -> 0 | H47: ='Рогалевич И. Е.'!J52 | I47: ='Рогалевич И. Е.'!M52 -> 0 | J47: ='Уразгильдеева Е. Р.'!K52 -> 0 | K47: ='Уразгильдеева Е. Р.'!J52 -> 0 | L47: ='Уразгильдеева Е. Р.'!M52 -> 0 | M47: ='ПК 4'!K52 -> 0 | N47: ='ПК 4'!J52 -> 0 | O47: ='ПК 4'!M52 -> 0
A48: UNOde50 | D48: ='Ялта, Ленина, 18'!S54 -> 185267 | E48: ='Ялта, Ленина, 18'!T53 -> 21 | F48: ='Ялта, Ленина, 18'!T54 -> 31 | G48: ='Рогалевич И. Е.'!S54 -> 1740554 | H48: ='Рогалевич И. Е.'!T53 | I48: ='Рогалевич И. Е.'!T54 -> 311 | J48: ='Уразгильдеева Е. Р.'!S54 -> 0 | K48: ='Уразгильдеева Е. Р.'!T53 -> 0 | L48: ='Уразгильдеева Е. Р.'!T54 -> 0 | M48: ='ПК 4'!S54 -> 0 | N48: ='ПК 4'!T53 -> 0 | O48: ='ПК 4'!T54 -> 0
A49: IS | D49: ='Ялта, Ленина, 18'!S48 -> 57195 | E49: ='Ялта, Ленина, 18'!T47 -> 8 | F49: ='Ялта, Ленина, 18'!T48 -> 13 | G49: ='Рогалевич И. Е.'!S48 -> 123474 | H49: ='Рогалевич И. Е.'!T47 -> 12 | I49: ='Рогалевич И. Е.'!T48 -> 24 | J49: ='Уразгильдеева Е. Р.'!S48 | K49: ='Уразгильдеева Е. Р.'!T47 | L49: ='Уразгильдеева Е. Р.'!T48 | M49: ='ПК 4'!S48 -> #REF! | N49: ='ПК 4'!T47 | O49: ='ПК 4'!T48 -> #REF!
A50: Отклонение от плана | D50: ='Ялта, Ленина, 18'!J51 -> 2 | G50: ='Рогалевич И. Е.'!N43 -> 0.15 | J50: ='Уразгильдеева Е. Р.'!N43 -> 0.057142857 | M50: ='ПК 4'!N43

Sheet План на день
A1: Выручка | D1: 185833
A2: Кол-во изделий | D2: =D1/D4 -> 30.972167
A3: Средний чек | D3: =D4*D5 -> 10200
A4: Средняя стоимость изделия | D4: ='Ялта, Ленина, 18'!I11 -> 6000
A5: Длина чека | D5: ='Ялта, Ленина, 18'!I12 -> 1.7
A6: Кол-во чеков | D6: =IF(D5<>0,D2/D5,"") -> 18.218922
A7: Конверсия | D7: ='Ялта, Ленина, 18'!I20 -> 0.25
A8: IS | D8: =('Ялта, Ленина, 18'!S12-'Ялта, Ленина, 18'!T12)/('Ялта, Ленина, 18'!I14-'Ялта, Ленина, 18'!J14) -> #DIV/0!
A9: UNOde50 | D9: =('Ялта, Ленина, 18'!S18-'Ялта, Ленина, 18'!T18)/('Ялта, Ленина, 18'!I14-'Ялта, Ленина, 18'!J14) -> #DIV/0!

Sheet Рогалевич И. Е.
B1: =TODAY()-1 -> 45879
B2: (отчетная дата) | J2: ЕЖЕДНЕВНЫЙ ОТЧЕТ О ПРОДАЖАХ
B3: Осталось до выполнения плана!!! | J3: =График!B29 -> Рогалевич Ирина
C4: =I8-D54 -> -142714.7 | E4: =IF(I8<>0,C4/I8,0) -> -0.089317306
F6: Целевые показатели
F7: Показатель | I7: План | J7: Факт | K7: % выполнения | L7: Прогноз выполнения | M7: % выполнения по прогнозу | N7: Отклонение | O7: Факт аналогичного месяца прошлого года | P7: Отклонение LFL
F8: Выручка | I8: ='Ялта, Ленина, 18'!I8/График!AJ31*График!AJ29 -> 1597839.3 | J8: =D54 -> 1740554 | K8: =IF(AND(I8<>"",I8<>0,J8<>""),J8/I8,"") -> 1.0893173 | L8: =IF(SUMIF($D$25:$D$53,">=0",$P$25:$P$53)<>0,I8*D54/SUMIF($D$25:$D$53,">=0",$P$25:$P$53),0) -> 1740554 | M8: =IF(AND(I8<>"",I8<>0,L8<>"",L8<>0),L8/I8,"") -> 1.0893173 | N8: =IF(AND(J8<>0,J8<>"",I8<>0,I8<>""),L8-I8,"") -> 142714.7 | P8: =IF(AND(O8<>"",O8<>0,L8<>"",L8<>0),-O8+L8,"") | Q8: =IF(AND(P8<>"",P8<>0,O8<>0,O8<>""),P8/O8,"")
F9: Кол-во изделий | I9: =I8/I11 -> 266.30655 | J9: =E54 -> 299 | K9: =IF(AND(I9<>"",I9<>0,J9<>""),J9/I9,"") -> 1.1227662 | L9: =IF(SUMIF($E$25:$E$51,">=0",$Q$25:$Q$51)<>0,I9*E54/SUMIF($E$25:$E$51,">=0",$Q$25:$Q$51),0) -> 299 | M9: =IF(AND(I9<>"",I9<>0,L9<>"",L9<>0),L9/I9,"") -> 1.1227662 | N9: =IF(AND(J9<>0,J9<>"",I9<>0,I9<>""),L9-I9,"") -> 32.69345 | O9: =O8/O11 -> #DIV/0! | P9: =IF(AND(O9<>"",O9<>0,L9<>"",L9<>0),-O9+L9,"") -> #DIV/0! | Q9: =IF(AND(P9<>"",P9<>0,O9<>0,O9<>""),P9/O9,"") -> #DIV/0!
F10: Средний чек | I10: =I11*I12 -> 10200 | J10: =H54 -> 11016.165 | K10: =IF(AND(I10<>"",I10<>0,J10<>""),J10/I10,"") -> 1.0800161 | L10: =J10 -> 11016.165 | M10: =IF(AND(I10<>"",I10<>0,L10<>"",L10<>0),L10/I10,"") -> 1.0800161 | N10: =IF(AND(J10<>0,J10<>"",I10<>0,I10<>""),L10-I10,"") -> 816.16456 | O10: =O11*O12 -> 0 | P10: =IF(AND(O10<>"",O10<>0,L10<>"",L10<>0),-O10+L10,"") | Q10: =IF(AND(P10<>"",P10<>0,O10<>0,O10<>""),P10/O10,"") | S10: IS
F11: Средняя стоимость изделия | I11: ='Ялта, Ленина, 18'!I11 -> 6000 | J11: =F54 -> 5821.2508 | K11: =IF(AND(I11<>"",I11<>0,J11<>""),J11/I11,"") -> 0.97020847 | L11: =IF(L9>0,L8/L9,"") -> 5821.2508 | M11: =IF(AND(I11<>"",I11<>0,L11<>"",L11<>0),L11/I11,"") -> 0.97020847 | N11: =IF(AND(J11<>0,J11<>"",I11<>0,I11<>""),L11-I11,"") -> -178.74916 | P11: =IF(AND(O11<>"",O11<>0,L11<>"",L11<>0),-O11+L11,"") | Q11: =IF(AND(P11<>"",P11<>0,O11<>0,O11<>""),P11/O11,"")
F12: Длина чека | I12: ='Ялта, Ленина, 18'!I12 -> 1.7 | J12: =J54 -> 1.8924051 | K12: =IF(AND(I12<>"",I12<>0,J12<>""),J12/I12,"") -> 1.1131794 | L12: =J12 -> 1.8924051 | M12: =IF(AND(I12<>"",I12<>0,L12<>"",L12<>0),L12/I12,"") -> 1.1131794 | N12: =IF(AND(J12<>0,J12<>"",I12<>0,I12<>""),L12-I12,"") -> 0.19240506 | P12: =IF(AND(O12<>"",O12<>0,L12<>"",L12<>0),-O12+L12,"") | Q12: =IF(AND(P12<>"",P12<>0,O12<>0,O12<>""),P12/O12,"") | S12: ='Ялта, Ленина, 18'!S12*График!AJ29/График!AJ31 -> 336799.46 | T12: =L54 -> 196446
F13: Кол-во чеков | I13: =IF(I12<>0,I9/I12,"") -> 156.65091 | J13: =G54 -> 158 | K13: =IF(AND(I13<>"",I13<>0,J13<>""),J13/I13,"") -> 1.0086121 | L13: =IF(SUMIF($G$25:$G$51,">=0",$R$25:$R$51)<>0,I13*G54/SUMIF($G$25:$G$51,">=0",$R$25:$R$51),"") -> 158 | M13: =IF(AND(I13<>"",I13<>0,L13<>"",L13<>0),L13/I13,"") -> 1.0086121 | N13: =IF(AND(J13<>0,J13<>"",I13<>0,I13<>""),L13-I13,"") -> 1.3490885 | P13: =IF(AND(O13<>"",O13<>0,L13<>"",L13<>0),-O13+L13,"") | Q13: =IF(AND(P13<>"",P13<>0,O13<>0,O13<>""),P13/O13,"") | S13: =T12/S12 -> 0.58327291 | T13: =S13/J14*I14 -> 0.58327291
F14: Кол-во смен план/отработано | I14: =График!AI29 -> 26 | J14: 26 | K14: =IF(AND(I14<>"",I14<>0,J14<>""),J14/I14,"") -> 1 | L14: =I14 -> 26 | M14: =IF(AND(I14<>"",I14<>0,L14<>"",L14<>0),L14/I14,"") -> 1 | N14: =IF(AND(J14<>0,J14<>"",I14<>0,I14<>""),L14-I14,"") -> 0 | P14: =IF(AND(O14<>"",O14<>0,L14<>"",L14<>0),-O14+L14,"") | Q14: =IF(AND(P14<>"",P14<>0,O14<>0,O14<>""),P14/O14,"")
F15: Средние продажи в смену | I15: ='Ялта, Ленина, 18'!I15 -> 131612.9 | J15: =J8/J14 -> 66944.385 | K15: =IF(AND(I15<>"",I15<>0,J15<>""),J15/I15,"") -> 0.50864606 | L15: =J15 -> 66944.385 | M15: =IF(AND(I15<>"",I15<>0,L15<>"",L15<>0),L15/I15,"") -> 0.50864606 | N15: =IF(AND(J15<>0,J15<>"",I15<>0,I15<>""),L15-I15,"") -> -64668.519 | P15: =IF(AND(O15<>"",O15<>0,L15<>"",L15<>0),-O15+L15,"") | Q15: =IF(AND(P15<>"",P15<>0,O15<>0,O15<>""),P15/O15,"")
F16: Отставание/Перевыполнение | J16: =J8-I15*J14 -> -1681381.5 | K16: =IF(AND(I16<>"",I16<>0,J16<>""),J16/I16,"") | L16: =J16 -> -1681381.5 | M16: =IF(AND(I16<>"",I16<>0,L16<>"",L16<>0),L16/I16,"") | N16: =IF(AND(J16<>0,J16<>"",I16<>0,I16<>""),L16-I16,"") | P16: =IF(AND(O16<>"",O16<>0,L16<>"",L16<>0),-O16+L16,"") | Q16: =IF(AND(P16<>"",P16<>0,O16<>0,O16<>""),P16/O16,"") | S16: UNOde50
F17: Трафик | I17: ='Ялта, Ленина, 18'!I17/График!AJ31*График!AJ29 -> 626.60365 | J17: =I54 -> 835 | K17: =IF(AND(I17<>"",I17<>0,J17<>""),J17/I17,"") -> 1.3325808 | L17: =J17/J14*I14 -> 835 | M17: =IF(AND(I17<>"",I17<>0,L17<>"",L17<>0),L17/I17,"") -> 1.3325808 | N17: =IF(AND(J17<>0,J17<>"",I17<>0,I17<>""),L17-I17,"") -> 208.39635 | P17: =IF(AND(O17<>"",O17<>0,L17<>"",L17<>0),-O17+L17,"") | Q17: =IF(AND(P17<>"",P17<>0,O17<>0,O17<>""),P17/O17,"")
K18: =IF(AND(I18<>"",I18<>0,J18<>""),J18/I18,"") | L18: =J18 -> 0 | M18: =IF(AND(I18<>"",I18<>0,L18<>"",L18<>0),L18/I18,"") | N18: =IF(AND(J18<>0,J18<>"",I18<>0,I18<>""),L18-I18,"") | O18: 0 | P18: =IF(AND(O18<>"",O18<>0,L18<>"",L18<>0),-O18+L18,"") | Q18: =IF(AND(P18<>"",P18<>0,O18<>0,O18<>""),P18/O18,"") | S18: ='Ялта, Ленина, 18'!S18*График!AJ29/График!AJ31 -> 305469.28 | T18: =K54 -> 442387
J19: =M54 -> 0 | K19: =IF(AND(I19<>"",I19<>0,J19<>""),J19/I19,"") | L19: =J19 -> 0 | M19: =IF(AND(I19<>"",I19<>0,L19<>"",L19<>0),L19/I19,"") | N19: =IF(AND(J19<>0,J19<>"",I19<>0,I19<>""),L19-I19,"") | O19: 0 | P19: =IF(AND(O19<>"",O19<>0,L19<>"",L19<>0),-O19+L19,"") | Q19: =IF(AND(P19<>"",P19<>0,O19<>0,O19<>""),P19/O19,"") | S19: =T18/S18 -> 1.4482209 | T19: =S19/J14*I14 -> 1.4482209
F20: Конверсия план/факт | I20: ='Ялта, Ленина, 18'!I20 -> 0.25 | J20: =N54 -> 0.18922156 | K20: =J20/I20 -> 0.75688623 | L20: =IF(AND(K8<>0,I14<>0,I54<>0),(I54*N54+(I54/K8-I54)*I20)/(I54/K8),0) -> 0.18379299 | M20: =IF(AND(I20<>"",I20<>0,L20<>"",L20<>0),L20/I20,"") -> 0.73517196 | N20: =IF(AND(J20<>0,J20<>"",I20<>0,I20<>""),L20-I20,"") -> -0.06620701 | P20: =IF(AND(O20<>"",O20<>0,L20<>"",L20<>0),-O20+L20,"") | Q20: =IF(AND(P20<>"",P20<>0,O20<>0,O20<>""),P20/O20,"")
B22: Факт продаж за месяц | O22: % выполнения дневного плана | P22: Раcпределение плана по дням
B23: Дата | C23: День недели | D23: Выручка (руб) | E23: Кол-во единиц (шт.) | F23: Средняя стоимость изделия (руб.) | G23: Количество чеков (шт.) | H23: Средняя сумма чека (руб.) | I23: Трафик | J23: Длина чека (шт.) | K23: UNOde50 | L23: IS | M23: Запасной | N23: Конверсия (%) | P23: выручка, план | Q23: кол-во ед, план | R23: Кол-во чеков, план | S23: выручка, скорректир.план | T23: кол-во ед, скорр. план | U23: кол-во чеков, скорр. план | V23: Коэфф. Дня Недели | W23: Специфика месяца
B24: 1 | C24: 2 | D24: 3 | E24: 4 | F24: 5 | G24: 6 | H24: 7 | I24: 8 | J24: 9 | K24: 10 | L24: 11 | M24: 12 | N24: 13 | P24: 1 | Q24: 2 | R24: 3 | S24: 4 | T24: 5 | U24: 6 | V24: 10 | W24: 11
A25: 1 | B25: 45840 | C25: ср | D25: =40209+12397+32744 -> 85350 | E25: 12 | F25: =IF(AND(E25<>"",E25<>0),D25/E25,"") -> 7112.5 | G25: 8 | H25: =IF(AND(G25<>"",G25<>0),D25/G25,"") -> 10668.75 | I25: 20 | J25: =IF(AND(G25<>"",G25<>0),E25/G25,"") -> 1.5 | K25: 12397 | L25: 40209 | N25: =IF(AND(I25<>"",I25<>0),G25/I25,"") -> 0.4 | O25: =D25/P25 -> 1.388813 | P25: =$I$8*V25*W25/SUMPRODUCT($W$25:$W$55,$V$25:$V$55) -> 61455.358 | Q25: =$I$9*V25*W25/SUMPRODUCT($W$25:$W$55,$V$25:$V$55) -> 10.24256 | R25: =IF($I$12="","",Q25/$I$12) -> 6.0250351 | S25: =IF(D25<>"",D25,P25) -> 85350 | T25: =IF(E25<>"",E25,Q25) -> 12 | U25: =IF(G25<>"",G25,R25) -> 8 | V25: 1 | W25: 1
A26: 2 | B26: 45841 | C26: чт | D26: =11403+24648 -> 36051 | E26: 11 | F26: =IF(AND(E26<>"",E26<>0),D26/E26,"") -> 3277.3636 | G26: 6 | H26: =IF(AND(G26<>"",G26<>0),D26/G26,"") -> 6008.5 | I26: 20 | J26: =IF(AND(G26<>"",G26<>0),E26/G26,"") -> 1.8333333 | L26: 11403 | N26: =IF(AND(I26<>"",I26<>0),G26/I26,"") -> 0.3 | O26: =D26/P26 -> 0.58662095 | P26: =$I$8*V26*W26/SUMPRODUCT($W$25:$W$55,$V$25:$V$55) -> 61455.358 | Q26: =$I$9*V26*W26/SUMPRODUCT($W$25:$W$55,$V$25:$V$55) -> 10.24256 | R26: =IF($I$12="","",Q26/$I$12) -> 6.0250351 | S26: =IF(W26<>"",IF(D26<>"",D26,($I$8-SUM($S$25:S25))*V26*W26/SUMPRODUCT($W26:$W$55,$V26:$V$55)),"") -> 36051 | T26: =IF(W26<>"",IF(E26<>"",E26,($I$9-SUM($T$25:T25))*V26*W26/SUMPRODUCT($W26:$W$55,$V26:$V$55)),"") -> 11 | U26: =IF(W26<>"",IF($I$12<>"",IF(G26<>"",G26,($I$9/$I$12-SUM($U$25:U25))*V26*W26/SUMPRODUCT($W26:$W$55,$V26:$V$55)),""),"") -> 6 | V26: 1 | W26: 1
A27: 3 | B27: 45842 | C27: пт | D27: =10503+48680 -> 59183 | E27: 9 | F27: =IF(AND(E27<>"",E27<>0),D27/E27,"") -> 6575.8889 | G27: 4 | H27: =IF(AND(G27<>"",G27<>0),D27/G27,"") -> 14795.75 | I27: 15 | J27: =IF(AND(G27<>"",G27<>0),E27/G27,"") -> 2.25 | L27: 10503 | N27: =IF(AND(I27<>"",I27<>0),G27/I27,"") -> 0.26666667 | O27: =D27/P27 -> 0.96302426 | P27: =$I$8*V27*W27/SUMPRODUCT($W$25:$W$55,$V$25:$V$55) -> 61455.358 | Q27: =$I$9*V27*W27/SUMPRODUCT($W$25:$W$55,$V$25:$V$55) -> 10.24256 | R27: =IF($I$12="","",Q27/$I$12) -> 6.0250351 | S27: =IF(W27<>"",IF(D27<>"",D27,($I$8-SUM($S$25:S26))*V27*W27/SUMPRODUCT($W27:$W$55,$V27:$V$55)),"") -> 59183 | T27: =IF(W27<>"",IF(E27<>"",E27,($I$9-SUM($T$25:T26))*V27*W27/SUMPRODUCT($W27:$W$55,$V27:$V$55)),"") -> 9 | U27: =IF(W27<>"",IF($I$12<>"",IF(G27<>"",G27,($I$9/$I$12-SUM($U$25:U26))*V27*W27/SUMPRODUCT($W27:$W$55,$V27:$V$55)),""),"") -> 4 | V27: 1 | W27: 1
A28: 4 | B28: 45843 | C28: сб | D28: =20972+6203+31245 -> 58420 | E28: 10 | F28: =IF(AND(E28<>"",E28<>0),D28/E28,"") -> 5842 | G28: 6 | H28: =IF(AND(G28<>"",G28<>0),D28/G28,"") -> 9736.6667 | I28: 20 | J28: =IF(AND(G28<>"",G28<>0),E28/G28,"") -> 1.6666667 | K28: 20972 | L28: 6203 | N28: =IF(AND(I28<>"",I28<>0),G28/I28,"") -> 0.3 | O28: =D28/P28 -> 0.95060874 | P28: =$I$8*V28*W28/SUMPRODUCT($W$25:$W$55,$V$25:$V$55) -> 61455.358 | Q28: =$I$9*V28*W28/SUMPRODUCT($W$25:$W$55,$V$25:$V$55) -> 10.24256 | R28: =IF($I$12="","",Q28/$I$12) -> 6.0250351 | S28: =IF(W28<>"",IF(D28<>"",D28,($I$8-SUM($S$25:S27))*V28*W28/SUMPRODUCT($W28:$W$55,$V28:$V$55)),"") -> 58420 | T28: =IF(W28<>"",IF(E28<>"",E28,($I$9-SUM($T$25:T27))*V28*W28/SUMPRODUCT($W28:$W$55,$V28:$V$55)),"") -> 10 | U28: =IF(W28<>"",IF($I$12<>"",IF(G28<>"",G28,($I$9/$I$12-SUM($U$25:U27))*V28*W28/SUMPRODUCT($W28:$W$55,$V28:$V$55)),""),"") -> 6 | V28: 1 | W28: 1
A29: 5 | B29: 45844 | C29: вс | D29: =22992+25706+62588 -> 111286 | E29: 18 | F29: =IF(AND(E29<>"",E29<>0),D29/E29,"") -> 6182.5556 | G29: 9 | H29: =IF(AND(G29<>"",G29<>0),D29/G29,"") -> 12365.111 | I29: 35 | J29: =IF(AND(G29<>"",G29<>0),E29/G29,"") -> 2 | K29: 22992 | L29: 25706 | N29: =IF(AND(I29<>"",I29<>0),G29/I29,"") -> 0.25714286 | O29: =D29/P29 -> 1.8108429 | P29: =$I$8*V29*W29/SUMPRODUCT($W$25:$W$55,$V$25:$V$55) -> 61455.358 | Q29: =$I$9*V29*W29/SUMPRODUCT($W$25:$W$55,$V$25:$V$55) -> 10.24256 | R29: =IF($I$12="","",Q29/$I$12) -> 6.0250351 | S29: =IF(W29<>"",IF(D29<>"",D29,($I$8-SUM($S$25:S28))*V29*W29/SUMPRODUCT($W29:$W$55,$V29:$V$55)),"") -> 111286 | T29: =IF(W29<>"",IF(E29<>"",E29,($I$9-SUM($T$25:T28))*V29*W29/SUMPRODUCT($W29:$W$55,$V29:$V$55)),"") -> 18 | U29: =IF(W29<>"",IF($I$12<>"",IF(G29<>"",G29,($I$9/$I$12-SUM($U$25:U28))*V29*W29/SUMPRODUCT($W29:$W$55,$V29:$V$55)),""),"") -> 9 | V29: 1 | W29: 1
A30: 6 | B30: 45845 | C30: пн | D30: =38735+10874 -> 49609 | E30: 4 | F30: =IF(AND(E30<>"",E30<>0),D30/E30,"") -> 12402.25 | G30: 4 | H30: =IF(AND(G30<>"",G30<>0),D30/G30,"") -> 12402.25 | I30: 25 | J30: =IF(AND(G30<>"",G30<>0),E30/G30,"") -> 1 | K30: 38735 | N30: =IF(AND(I30<>"",I30<>0),G30/I30,"") -> 0.16 | O30: =D30/P30 -> 0.80723637 | P30: =$I$8*V30*W30/SUMPRODUCT($W$25:$W$55,$V$25:$V$55) -> 61455.358 | Q30: =$I$9*V30*W30/SUMPRODUCT($W$25:$W$55,$V$25:$V$55) -> 10.24256 | R30: =IF($I$12="","",Q30/$I$12) -> 6.0250351 | S30: =IF(W30<>"",IF(D30<>"",D30,($I$8-SUM($S$25:S29))*V30*W30/SUMPRODUCT($W30:$W$55,$V30:$V$55)),"") -> 49609 | T30: =IF(W30<>"",IF(E30<>"",E30,($I$9-SUM($T$25:T29))*V30*W30/SUMPRODUCT($W30:$W$55,$V30:$V$55)),"") -> 4 | U30: =IF(W30<>"",IF($I$12<>"",IF(G30<>"",G30,($I$9/$I$12-SUM($U$25:U29))*V30*W30/SUMPRODUCT($W30:$W$55,$V30:$V$55)),""),"") -> 4 | V30: 1 | W30: 1
A31: 7 | B31: 45847 | C31: ср | D31: =10592+22463 -> 33055 | E31: 6 | F31: =IF(AND(E31<>"",E31<>0),D31/E31,"") -> 5509.1667 | G31: 5 | H31: =IF(AND(G31<>"",G31<>0),D31/G31,"") -> 6611 | I31: 25 | J31: =IF(AND(G31<>"",G31<>0),E31/G31,"") -> 1.2 | K31: 10592 | N31: =IF(AND(I31<>"",I31<>0),G31/I31,"") -> 0.2 | O31: =D31/P31 -> 0.53787011 | P31: =$I$8*V31*W31/SUMPRODUCT($W$25:$W$55,$V$25:$V$55) -> 61455.358 | Q31: =$I$9*V31*W31/SUMPRODUCT($W$25:$W$55,$V$25:$V$55) -> 10.24256 | R31: =IF($I$12="","",Q31/$I$12) -> 6.0250351 | S31: =IF(W31<>"",IF(D31<>"",D31,($I$8-SUM($S$25:S30))*V31*W31/SUMPRODUCT($W31:$W$55,$V31:$V$55)),"") -> 33055 | T31: =IF(W31<>"",IF(E31<>"",E31,($I$9-SUM($T$25:T30))*V31*W31/SUMPRODUCT($W31:$W$55,$V31:$V$55)),"") -> 6 | U31: =IF(W31<>"",IF($I$12<>"",IF(G31<>"",G31,($I$9/$I$12-SUM($U$25:U30))*V31*W31/SUMPRODUCT($W31:$W$55,$V31:$V$55)),""),"") -> 5 | V31: 1 | W31: 1
A32: 8 | B32: 45848 | C32: чт | D32: =75897+10491+24903 -> 111291 | E32: 16 | F32: =IF(AND(E32<>"",E32<>0),D32/E32,"") -> 6955.6875 | G32: 7 | H32: =IF(AND(G32<>"",G32<>0),D32/G32,"") -> 15898.714 | I32: 35 | J32: =IF(AND(G32<>"",G32<>0),E32/G32,"") -> 2.2857143 | K32: 10491 | L32: 24903 | N32: =IF(AND(I32<>"",I32<>0),G32/I32,"") -> 0.2 | O32: =D32/P32 -> 1.8109243 | P32: =$I$8*V32*W32/SUMPRODUCT($W$25:$W$55,$V$25:$V$55) -> 61455.358 | Q32: =$I$9*V32*W32/SUMPRODUCT($W$25:$W$55,$V$25:$V$55) -> 10.24256 | R32: =IF($I$12="","",Q32/$I$12) -> 6.0250351 | S32: =IF(W32<>"",IF(D32<>"",D32,($I$8-SUM($S$25:S31))*V32*W32/SUMPRODUCT($W32:$W$55,$V32:$V$55)),"") -> 111291 | T32: =IF(W32<>"",IF(E32<>"",E32,($I$9-SUM($T$25:T31))*V32*W32/SUMPRODUCT($W32:$W$55,$V32:$V$55)),"") -> 16 | U32: =IF(W32<>"",IF($I$12<>"",IF(G32<>"",G32,($I$9/$I$12-SUM($U$25:U31))*V32*W32/SUMPRODUCT($W32:$W$55,$V32:$V$55)),""),"") -> 7 | V32: 1 | W32: 1
A33: 9 | B33: 45849 | C33: пт | D33: =24990+14959 -> 39949 | E33: 5 | F33: =IF(AND(E33<>"",E33<>0),D33/E33,"") -> 7989.8 | G33: 4 | H33: =IF(AND(G33<>"",G33<>0),D33/G33,"") -> 9987.25 | I33: 30 | J33: =IF(AND(G33<>"",G33<>0),E33/G33,"") -> 1.25 | K33: 24990 | N33: =IF(AND(I33<>"",I33<>0),G33/I33,"") -> 0.13333333 | O33: =D33/P33 -> 0.6500491 | P33: =$I$8*V33*W33/SUMPRODUCT($W$25:$W$55,$V$25:$V$55) -> 61455.358 | Q33: =$I$9*V33*W33/SUMPRODUCT($W$25:$W$55,$V$25:$V$55) -> 10.24256 | R33: =IF($I$12="","",Q33/$I$12) -> 6.0250351 | S33: =IF(W33<>"",IF(D33<>"",D33,($I$8-SUM($S$25:S32))*V33*W33/SUMPRODUCT($W33:$W$55,$V33:$V$55)),"") -> 39949 | T33: =IF(W33<>"",IF(E33<>"",E33,($I$9-SUM($T$25:T32))*V33*W33/SUMPRODUCT($W33:$W$55,$V33:$V$55)),"") -> 5 | U33: =IF(W33<>"",IF($I$12<>"",IF(G33<>"",G33,($I$9/$I$12-SUM($U$25:U32))*V33*W33/SUMPRODUCT($W33:$W$55,$V33:$V$55)),""),"") -> 4 | V33: 1 | W33: 1
A34: 10 | B34: 45850 | C34: сб | D34: =57567+72793 -> 130360 | E34: 17 | F34: =IF(AND(E34<>"",E34<>0),D34/E34,"") -> 7668.2353 | G34: 5 | H34: =IF(AND(G34<>"",G34<>0),D34/G34,"") -> 26072 | I34: 30 | J34: =IF(AND(G34<>"",G34<>0),E34/G34,"") -> 3.4 | K34: 57567 | N34: =IF(AND(I34<>"",I34<>0),G34/I34,"") -> 0.16666667 | O34: =D34/P34 -> 2.1212146 | P34: =$I$8*V34*W34/SUMPRODUCT($W$25:$W$55,$V$25:$V$55) -> 61455.358 | Q34: =$I$9*V34*W34/SUMPRODUCT($W$25:$W$55,$V$25:$V$55) -> 10.24256 | R34: =IF($I$12="","",Q34/$I$12) -> 6.0250351 | S34: =IF(W34<>"",IF(D34<>"",D34,($I$8-SUM($S$25:S33))*V34*W34/SUMPRODUCT($W34:$W$55,$V34:$V$55)),"") -> 130360 | T34: =IF(W34<>"",IF(E34<>"",E34,($I$9-SUM($T$25:T33))*V34*W34/SUMPRODUCT($W34:$W$55,$V34:$V$55)),"") -> 17 | U34: =IF(W34<>"",IF($I$12<>"",IF(G34<>"",G34,($I$9/$I$12-SUM($U$25:U33))*V34*W34/SUMPRODUCT($W34:$W$55,$V34:$V$55)),""),"") -> 5 | V34: 1 | W34: 1
A35: 11 | B35: 45851 | C35: вс | D35: 27565 | E35: 5 | F35: =IF(AND(E35<>"",E35<>0),D35/E35,"") -> 5513 | G35: 5 | H35: =IF(AND(G35<>"",G35<>0),D35/G35,"") -> 5513 | I35: 35 | J35: =IF(AND(G35<>"",G35<>0),E35/G35,"") -> 1 | N35: =IF(AND(I35<>"",I35<>0),G35/I35,"") -> 0.14285714 | O35: =D35/P35 -> 0.44853697 | P35: =$I$8*V35*W35/SUMPRODUCT($W$25:$W$55,$V$25:$V$55) -> 61455.358 | Q35: =$I$9*V35*W35/SUMPRODUCT($W$25:$W$55,$V$25:$V$55) -> 10.24256 | R35: =IF($I$12="","",Q35/$I$12) -> 6.0250351 | S35: =IF(W35<>"",IF(D35<>"",D35,($I$8-SUM($S$25:S34))*V35*W35/SUMPRODUCT($W35:$W$55,$V35:$V$55)),"") -> 27565 | T35: =IF(W35<>"",IF(E34<>"",E34,($I$9-SUM($T$25:T34))*V35*W35/SUMPRODUCT($W35:$W$55,$V35:$V$55)),"") -> 17 | U35: =IF(W35<>"",IF($I$12<>"",IF(G35<>"",G35,($I$9/$I$12-SUM($U$25:U34))*V35*W35/SUMPRODUCT($W35:$W$55,$V35:$V$55)),""),"") -> 5 | V35: 1 | W35: 1
A36: 12 | B36: 45852 | C36: пн | D36: =14185+8902+71171 -> 94258 | E36: 17 | F36: 5544 | G36: 12 | H36: =IF(AND(G36<>"",G36<>0),D36/G36,"") -> 7854.8333 | I36: 45 | J36: =IF(AND(G36<>"",G36<>0),E36/G36,"") -> 1.4166667 | K36: 14185 | L36: 8902 | N36: =IF(AND(I36<>"",I36<>0),G36/I36,"") -> 0.26666667 | O36: =D36/P36 -> 1.5337638 | P36: =$I$8*V36*W36/SUMPRODUCT($W$25:$W$55,$V$25:$V$55) -> 61455.358 | Q36: =$I$9*V36*W36/SUMPRODUCT($W$25:$W$55,$V$25:$V$55) -> 10.24256 | R36: =IF($I$12="","",Q36/$I$12) -> 6.0250351 | S36: =IF(W36<>"",IF(D36<>"",D36,($I$8-SUM($S$25:S35))*V36*W36/SUMPRODUCT($W36:$W$55,$V36:$V$55)),"") -> 94258 | T36: =IF(W36<>"",IF(E36<>"",E36,($I$9-SUM($T$25:T35))*V36*W36/SUMPRODUCT($W36:$W$55,$V36:$V$55)),"") -> 17 | U36: =IF(W36<>"",IF($I$12<>"",IF(G36<>"",G36,($I$9/$I$12-SUM($U$25:U35))*V36*W36/SUMPRODUCT($W36:$W$55,$V36:$V$55)),""),"") -> 12 | V36: 1 | W36: 1
A37: 13 | B37: 45853 | C37: вт | D37: =109909+15666 -> 125575 | E37: 11 | F37: =IF(AND(E37<>"",E37<>0),D37/E37,"") -> 11415.909 | G37: 4 | H37: =IF(AND(G37<>"",G37<>0),D37/G37,"") -> 31393.75 | I37: 35 | J37: =IF(AND(G37<>"",G37<>0),E37/G37,"") -> 2.75 | K37: 109909 | N37: =IF(AND(I37<>"",I37<>0),G37/I37,"") -> 0.11428571 | O37: =D37/P37 -> 2.0433532 | P37: =$I$8*V37*W37/SUMPRODUCT($W$25:$W$55,$V$25:$V$55) -> 61455.358 | Q37: =$I$9*V37*W37/SUMPRODUCT($W$25:$W$55,$V$25:$V$55) -> 10.24256 | R37: =IF($I$12="","",Q37/$I$12) -> 6.0250351 | S37: =IF(W37<>"",IF(D37<>"",D37,($I$8-SUM($S$25:S36))*V37*W37/SUMPRODUCT($W37:$W$55,$V37:$V$55)),"") -> 125575 | T37: =IF(W37<>"",IF(E37<>"",E37,($I$9-SUM($T$25:T36))*V37*W37/SUMPRODUCT($W37:$W$55,$V37:$V$55)),"") -> 11 | U37: =IF(W37<>"",IF($I$12<>"",IF(G37<>"",G37,($I$9/$I$12-SUM($U$25:U36))*V37*W37/SUMPRODUCT($W37:$W$55,$V37:$V$55)),""),"") -> 4 | V37: 1 | W37: 1
A38: 14 | B38: 45855 | C38: чт | D38: =8202+27484+32345 -> 68031 | E38: 10 | F38: =IF(AND(E38<>"",E38<>0),D38/E38,"") -> 6803.1 | G38: 7 | H38: =IF(AND(G38<>"",G38<>0),D38/G38,"") -> 9718.7143 | I38: 35 | J38: =IF(AND(G38<>"",G38<>0),E38/G38,"") -> 1.4285714 | K38: 27484 | L38: 8202 | N38: =IF(AND(I38<>"",I38<>0),G38/I38,"") -> 0.2 | O38: =D38/P38 -> 1.1069987 | P38: =$I$8*V38*W38/SUMPRODUCT($W$25:$W$55,$V$25:$V$55) -> 61455.358 | Q38: =$I$9*V38*W38/SUMPRODUCT($W$25:$W$55,$V$25:$V$55) -> 10.24256 | R38: =IF($I$12="","",Q38/$I$12) -> 6.0250351 | S38: =IF(W38<>"",IF(D38<>"",D38,($I$8-SUM($S$25:S37))*V38*W38/SUMPRODUCT($W38:$W$55,$V38:$V$55)),"") -> 68031 | T38: =IF(W38<>"",IF(E38<>"",E38,($I$9-SUM($T$25:T37))*V38*W38/SUMPRODUCT($W38:$W$55,$V38:$V$55)),"") -> 10 | U38: =IF(W38<>"",IF($I$12<>"",IF(G38<>"",G38,($I$9/$I$12-SUM($U$25:U37))*V38*W38/SUMPRODUCT($W38:$W$55,$V38:$V$55)),""),"") -> 7 | V38: 1 | W38: 1
A39: 13 | B39: 45856 | C39: пт | D39: =691+48602 -> 49293 | E39: 12 | F39: =IF(AND(E39<>"",E39<>0),D39/E39,"") -> 4107.75 | G39: 6 | H39: =IF(AND(G39<>"",G39<>0),D39/G39,"") -> 8215.5 | I39: 40 | J39: =IF(AND(G39<>"",G39<>0),E39/G39,"") -> 2 | L39: 691 | N39: =IF(AND(I39<>"",I39<>0),G39/I39,"") -> 0.15 | O39: =D39/P39 -> 0.80209443 | P39: =$I$8*V39*W39/SUMPRODUCT($W$25:$W$55,$V$25:$V$55) -> 61455.358 | Q39: =$I$9*V39*W39/SUMPRODUCT($W$25:$W$55,$V$25:$V$55) -> 10.24256 | R39: =IF($I$12="","",Q39/$I$12) -> 6.0250351 | S39: =IF(W39<>"",IF(D39<>"",D39,($I$8-SUM($S$25:S38))*V39*W39/SUMPRODUCT($W39:$W$55,$V39:$V$55)),"") -> 49293 | T39: =IF(W39<>"",IF(E39<>"",E39,($I$9-SUM($T$25:T38))*V39*W39/SUMPRODUCT($W39:$W$55,$V39:$V$55)),"") -> 12 | U39: =IF(W39<>"",IF($I$12<>"",IF(G39<>"",G39,($I$9/$I$12-SUM($U$25:U38))*V39*W39/SUMPRODUCT($W39:$W$55,$V39:$V$55)),""),"") -> 6 | V39: 1 | W39: 1
A40: 13 | B40: 45857 | C40: сб | D40: =18483+9108 -> 27591 | E40: 6 | F40: =IF(AND(E40<>"",E40<>0),D40/E40,"") -> 4598.5 | G40: 5 | H40: =IF(AND(G40<>"",G40<>0),D40/G40,"") -> 5518.2 | I40: 30 | J40: =IF(AND(G40<>"",G40<>0),E40/G40,"") -> 1.2 | K40: 18483 | N40: =IF(AND(I40<>"",I40<>0),G40/I40,"") -> 0.16666667 | O40: =D40/P40 -> 0.44896004 | P40: =$I$8*V40*W40/SUMPRODUCT($W$25:$W$55,$V$25:$V$55) -> 61455.358 | Q40: =$I$9*V40*W40/SUMPRODUCT($W$25:$W$55,$V$25:$V$55) -> 10.24256 | R40: =IF($I$12="","",Q40/$I$12) -> 6.0250351 | S40: =IF(W40<>"",IF(D40<>"",D40,($I$8-SUM($S$25:S39))*V40*W40/SUMPRODUCT($W40:$W$55,$V40:$V$55)),"") -> 27591 | T40: =IF(W40<>"",IF(E40<>"",E40,($I$9-SUM($T$25:T39))*V40*W40/SUMPRODUCT($W40:$W$55,$V40:$V$55)),"") -> 6 | U40: =IF(W40<>"",IF($I$12<>"",IF(G40<>"",G40,($I$9/$I$12-SUM($U$25:U39))*V40*W40/SUMPRODUCT($W40:$W$55,$V40:$V$55)),""),"") -> 5 | V40: 1 | W40: 1
A41: 17 | B41: 45858 | C41: вс | D41: 48809 | E41: 12 | F41: =IF(AND(E41<>"",E41<>0),D41/E41,"") -> 4067.4167 | G41: 5 | H41: =IF(AND(G41<>"",G41<>0),D41/G41,"") -> 9761.8 | I41: 25 | J41: =IF(AND(G41<>"",G41<>0),E41/G41,"") -> 2.4 | N41: =IF(AND(I41<>"",I41<>0),G41/I41,"") -> 0.2 | O41: =D41/P41 -> 0.79421879 | P41: =$I$8*V41*W41/SUMPRODUCT($W$25:$W$55,$V$25:$V$55) -> 61455.358 | Q41: =$I$9*V41*W41/SUMPRODUCT($W$25:$W$55,$V$25:$V$55) -> 10.24256 | R41: =IF($I$12="","",Q41/$I$12) -> 6.0250351 | S41: =IF(W41<>"",IF(D41<>"",D41,($I$8-SUM($S$25:S40))*V41*W41/SUMPRODUCT($W41:$W$55,$V41:$V$55)),"") -> 48809 | T41: =IF(W41<>"",IF(E41<>"",E41,($I$9-SUM($T$25:T40))*V41*W41/SUMPRODUCT($W41:$W$55,$V41:$V$55)),"") -> 12 | U41: =IF(W41<>"",IF($I$12<>"",IF(G41<>"",G41,($I$9/$I$12-SUM($U$25:U40))*V41*W41/SUMPRODUCT($W41:$W$55,$V41:$V$55)),""),"") -> 5 | V41: 1 | W41: 1
A42: 18 | B42: 45859 | C42: пн | D42: =54657+81821 -> 136478 | E42: 23 | F42: =IF(AND(E42<>"",E42<>0),D42/E42,"") -> 5933.8261 | G42: 11 | H42: =IF(AND(G42<>"",G42<>0),D42/G42,"") -> 12407.091 | I42: 40 | J42: =IF(AND(G42<>"",G42<>0),E42/G42,"") -> 2.0909091 | K42: 54657 | N42: =IF(AND(I42<>"",I42<>0),G42/I42,"") -> 0.275 | O42: =D42/P42 -> 2.2207665 | P42: =$I$8*V42*W42/SUMPRODUCT($W$25:$W$55,$V$25:$V$55) -> 61455.358 | Q42: =$I$9*V42*W42/SUMPRODUCT($W$25:$W$55,$V$25:$V$55) -> 10.24256 | R42: =IF($I$12="","",Q42/$I$12) -> 6.0250351 | S42: =IF(W42<>"",IF(D42<>"",D42,($I$8-SUM($S$25:S41))*V42*W42/SUMPRODUCT($W42:$W$55,$V42:$V$55)),"") -> 136478 | T42: =IF(W42<>"",IF(E42<>"",E42,($I$9-SUM($T$25:T41))*V42*W42/SUMPRODUCT($W42:$W$55,$V42:$V$55)),"") -> 23 | U42: =IF(W42<>"",IF($I$12<>"",IF(G42<>"",G42,($I$9/$I$12-SUM($U$25:U41))*V42*W42/SUMPRODUCT($W42:$W$55,$V42:$V$55)),""),"") -> 11 | V42: 1 | W42: 1
...

Sheet Уразгильдеева Е. Р.
B1: =TODAY()-1 -> 45879
B2: (отчетная дата) | J2: ЕЖЕДНЕВНЫЙ ОТЧЕТ О ПРОДАЖАХ
B3: Осталось до выполнения плана!!! | J3: =График!B28 -> Уразгильдеева Екатерина
C4: =I8-D50 -> 606373.52 | E4: =IF(I8<>0, C4/I8, 0) -> 0.43073903
F6: Целевые показатели
F7: Показатель | I7: План | J7: Факт | K7: % выполнения | L7: Прогноз выполнения | M7: % выполнения по прогнозу | N7: Отклонение | O7: Факт аналогичного месяца прошлого года | P7: Отклонение LFL
F8: Выручка | I8: ='Ялта, Ленина, 18'!I8/График!AJ31*График!AJ28 -> 1407751.5 | J8: =D50 -> 801378 | K8: =J8/I8 -> 0.56926097 | L8: =IF(SUMIF($D$25:$D$49,">=0",$P$25:$P$49)<>0,I8*D50/SUMIF($D$25:$D$49,">=0",$P$25:$P$49),0) -> 801378 | M8: =IF(AND(I8<>"",I8<>0,L8<>"",L8<>0),L8/I8,"") -> 0.56926097 | N8: =IF(AND(J8<>0, J8<>"", I8<>0, I8<>""), L8-I8, "") -> -606373.52 | P8: =IF(AND(O8<>"", O8<>0, L8<>"", L8<>0), -O8+L8, "") | Q8: =IF(AND(P8<>"", P8<>0, O8<>0, O8<>""), P8/O8, "")
F9: Кол-во изделий | I9: =I8/I11 -> 234.62525 | J9: =E50 -> 155 | K9: =IF(AND(I9<>"", I9<>0, J9<>""), J9/I9, "") -> 0.66062795 | L9: =J9 -> 155 | M9: =IF(AND(I9<>"",I9<>0,L9<>"",L9<>0),L9/I9,"") -> 0.66062795 | N9: =IF(AND(J9<>0, J9<>"", I9<>0, I9<>""), L9-I9, "") -> -79.625253 | O9: =O8/O11 -> #DIV/0! | P9: =IF(AND(O9<>"", O9<>0, L9<>"", L9<>0), -O9+L9, "") -> #DIV/0! | Q9: =IF(AND(P9<>"", P9<>0, O9<>0, O9<>""), P9/O9, "") -> #DIV/0!
F10: Средний чек | I10: =I11*I12 -> 10200 | J10: =H50 -> 8013.78 | K10: =IF(AND(I10<>"", I10<>0, J10<>""), J10/I10, "") -> 0.78566471 | L10: =J10 -> 8013.78 | M10: =IF(AND(I10<>"",I10<>0,L10<>"",L10<>0),L10/I10,"") -> 0.78566471 | N10: =IF(AND(J10<>0, J10<>"", I10<>0, I10<>""), L10-I10, "") -> -2186.22 | O10: =O11*O12 -> 0 | P10: =IF(AND(O10<>"", O10<>0, L10<>"", L10<>0), -O10+L10, "") | Q10: =IF(AND(P10<>"", P10<>0, O10<>0, O10<>""), P10/O10, "") | S10: IS
F11: Средняя стоимость изделия | I11: ='Ялта, Ленина, 18'!I11 -> 6000 | J11: =F50 -> 5170.1806 | K11: =IF(AND(I11<>"", I11<>0, J11<>""), J11/I11, "") -> 0.86169677 | L11: =J11 -> 5170.1806 | M11: =IF(AND(I11<>"",I11<>0,L11<>"",L11<>0),L11/I11,"") -> 0.86169677 | N11: =IF(AND(J11<>0, J11<>"", I11<>0, I11<>""), L11-I11, "") -> -829.81935 | P11: =IF(AND(O11<>"", O11<>0, L11<>"", L11<>0), -O11+L11, "") | Q11: =IF(AND(P11<>"", P11<>0, O11<>0, O11<>""), P11/O11, "")
