Workbook
Name маг: NA()

Sheet Ялта, Ленина, 18
B1: =TODAY()-1 -> 45909
B2: (отчетная дата)
C3: Осталось до выполнения плана!!! | I3: =График!B3 -> ул. Набережная Ленина, 18
C4: =I8-D56 -> 818706 | E4: =IF(I8<>0, C4/I8, 0) -> 0.17418684
D5: =C4/(I14-J14) -> #DIV/0!
F6: Целевые показатели
F7: Показатель | I7: План | J7: Факт | K7: % выполнения | L7: Прогноз выполнения | M7: % выполнения по прогнозу | N7: Отклонение | O7: Факт аналогичного месяца прошлого года | P7: Отклонение LFL
F8: Выручка | I8: =I11*I12*I13 -> 4700160 | J8: =D56 -> 3881454 | K8: =IF(AND(I8<>"",I8<>0,J8<>""),J8/I8,"") -> 0.82581316 | L8: =IF(SUMIF($D$25:$D$55,">=0",$P$25:$P$55)<>0,I8*D56/SUMIF($D$25:$D$55,">=0",$P$25:$P$55),0) -> 3881454 | M8: =IF(AND(I8<>"", I8<>0, L8<>"", L8<>0), L8/I8, "") -> 0.82581316 | N8: =IF(AND(J8<>0, J8<>"", I8<>0, I8<>""), L8-I8, "") -> -818706 | P8: =IF(AND(O8<>"", O8<>0, L8<>"", L8<>0), -O8+L8, "") | Q8: =IF(AND(P8<>"", P8<>0, O8<>0, O8<>""), P8/O8, "")
F9: Кол-во изделий | I9: =I8/I11 -> 783.36 | J9: =E56 -> 672 | K9: =IF(AND(I9<>"", I9<>0, J9<>""), J9/I9, "") -> 0.85784314 | L9: =IF(SUMIF($E$25:$E$55, ">=0", $Q$25:$Q$55)<>0, I9*E56/SUMIF($E$25:$E$55, ">=0", $Q$25:$Q$55), 0) -> 672 | M9: =IF(AND(I9<>"", I9<>0, L9<>"", L9<>0), L9/I9, "") -> 0.85784314 | N9: =IF(AND(J9<>0, J9<>"", I9<>0, I9<>""), L9-I9, "") -> -111.36 | O9: =O8/O11 -> #DIV/0! | P9: =IF(AND(O9<>"", O9<>0, L9<>"", L9<>0), -O9+L9, "") -> #DIV/0! | Q9: =IF(AND(P9<>"", P9<>0, O9<>0, O9<>""), P9/O9, "") -> #DIV/0!
F10: Средний чек | I10: =I11*I12 -> 10200 | J10: =H56 -> 10323.016 | K10: =IF(AND(I10<>"", I10<>0, J10<>""), J10/I10, "") -> 1.0120604 | L10: =J10 -> 10323.016 | M10: =IF(AND(I10<>"", I10<>0, L10<>"", L10<>0), L10/I10, "") -> 1.0120604 | N10: =IF(AND(J10<>0, J10<>"", I10<>0, I10<>""), L10-I10, "") -> 123.01596 | O10: =O11*O12 -> 0 | P10: =IF(AND(O10<>"", O10<>0, L10<>"", L10<>0), -O10+L10, "") | Q10: =IF(AND(P10<>"", P10<>0, O10<>0, O10<>""), P10/O10, "") | S10: =L23 -> IS | V10: =M23 -> Agafi
F11: Средняя стоимость изделия | I11: 6000 | J11: =F56 -> 5775.9732 | K11: =IF(AND(I11<>"", I11<>0, J11<>""), J11/I11, "") -> 0.9626622 | L11: =IF(L9>0, L8/L9, "") -> 5775.9732 | M11: =IF(AND(I11<>"", I11<>0, L11<>"", L11<>0), L11/I11, "") -> 0.9626622 | N11: =IF(AND(J11<>0, J11<>"", I11<>0, I11<>""), L11-I11, "") -> -224.02679 | P11: =IF(AND(O11<>"", O11<>0, L11<>"", L11<>0), -O11+L11, "") | Q11: =IF(AND(P11<>"", P11<>0, O11<>0, O11<>""), P11/O11, "")
F12: Длина чека | I12: 1.7 | J12: =J56 -> 1.787234 | K12: =IF(AND(I12<>"", I12<>0, J12<>""), J12/I12, "") -> 1.0513141 | L12: =J12 -> 1.787234 | M12: =IF(AND(I12<>"", I12<>0, L12<>"", L12<>0), L12/I12, "") -> 1.0513141 | N12: =IF(AND(J12<>0, J12<>"", I12<>0, I12<>""), L12-I12, "") -> 0.087234043 | P12: =IF(AND(O12<>"", O12<>0, L12<>"", L12<>0), -O12+L12, "") | Q12: =IF(AND(P12<>"", P12<>0, O12<>0, O12<>""), P12/O12, "") | S12: 760000 | T12: =L56 -> 420152 | V12: 460000 | W12: =M56 -> 296296.31
F13: Кол-во чеков | I13: =I17*I20 -> 460.8 | J13: =G56 -> 376 | K13: =IF(AND(I13<>"", I13<>0, J13<>""), J13/I13, "") -> 0.81597222 | L13: =IF(SUMIF($G$25:$G$55, ">=0", $R$25:$R$55)<>0, I13*G56/SUMIF($G$25:$G$55, ">=0", $R$25:$R$55), "") -> 376 | M13: =IF(AND(I13<>"", I13<>0, L13<>"", L13<>0), L13/I13, "") -> 0.81597222 | N13: =IF(AND(J13<>0, J13<>"", I13<>0, I13<>""), L13-I13, "") -> -84.8 | P13: =IF(AND(O13<>"", O13<>0, L13<>"", L13<>0), -O13+L13, "") | Q13: =IF(AND(P13<>"", P13<>0, O13<>0, O13<>""), P13/O13, "") | S13: =T12/S12 -> 0.55283158 | T13: =S13/J14*I14 -> 0.55283158 | V13: =W12/V12 -> 0.64412241 | W13: =V13/J14*I14 -> 0.64412241
F14: Кол-во смен | I14: 31 | J14: 31 | K14: =IF(AND(I14<>"", I14<>0, J14<>""), J14/I14, "") -> 1 | L14: =I14 -> 31 | M14: =IF(AND(I14<>"", I14<>0, L14<>"", L14<>0), L14/I14, "") -> 1 | N14: =IF(AND(J14<>0, J14<>"", I14<>0, I14<>""), L14-I14, "") -> 0 | P14: =IF(AND(O14<>"", O14<>0, L14<>"", L14<>0), -O14+L14, "") | Q14: =IF(AND(P14<>"", P14<>0, O14<>0, O14<>""), P14/O14, "")
F15: Средние продажи в смену | I15: =I8/I14 -> 151618.06 | J15: =J8/J14 -> 125208.19 | K15: =IF(AND(I15<>"", I15<>0, J15<>""), J15/I15, "") -> 0.82581316 | L15: =J15 -> 125208.19 | M15: =IF(AND(I15<>"", I15<>0, L15<>"", L15<>0), L15/I15, "") -> 0.82581316 | N15: =IF(AND(J15<>0, J15<>"", I15<>0, I15<>""), L15-I15, "") -> -26409.871 | P15: =IF(AND(O15<>"", O15<>0, L15<>"", L15<>0), -O15+L15, "") | Q15: =IF(AND(P15<>"", P15<>0, O15<>0, O15<>""), P15/O15, "")
F16: Отставание/Перевыполнение | J16: =J8-I15*J14 -> -818706 | K16: =IF(AND(I16<>"", I16<>0, J16<>""), J16/I16, "") | L16: =J16 -> -818706 | M16: =IF(AND(I16<>"", I16<>0, L16<>"", L16<>0), L16/I16, "") | N16: =IF(AND(J16<>0, J16<>"", I16<>0, I16<>""), L16-I16, "") | P16: =IF(AND(O16<>"", O16<>0, L16<>"", L16<>0), -O16+L16, "") | Q16: =IF(AND(P16<>"", P16<>0, O16<>0, O16<>""), P16/O16, "") | S16: =K23 -> UNOde50
F17: Трафик | I17: 2560 | J17: =I56 -> 2645 | K17: =IF(AND(I17<>"", I17<>0, J17<>""), J17/I17, "") -> 1.0332031 | L17: =J17/J14*I14 -> 2645 | M17: =IF(AND(I17<>"", I17<>0, L17<>"", L17<>0), L17/I17, "") -> 1.0332031 | N17: =IF(AND(J17<>0, J17<>"", I17<>0, I17<>""), L17-I17, "") -> 85 | P17: =IF(AND(O17<>"", O17<>0, L17<>"", L17<>0), -O17+L17, "") | Q17: =IF(AND(P17<>"", P17<>0, O17<>0, O17<>""), P17/O17, "")
K18: =IF(AND(I18<>"", I18<>0, J18<>""), J18/I18, "") | L18: =J18 -> 0 | M18: =IF(AND(I18<>"", I18<>0, L18<>"", L18<>0), L18/I18, "") | N18: =IF(AND(J18<>0, J18<>"", I18<>0, I18<>""), L18-I18, "") | O18: 0 | P18: =IF(AND(O18<>"", O18<>0, L18<>"", L18<>0), -O18+L18, "") | Q18: =IF(AND(P18<>"", P18<>0, O18<>0, O18<>""), P18/O18, "") | S18: 880000 | T18: =K56 -> 639010.35
K19: =IF(AND(I19<>"", I19<>0, J19<>""), J19/I19, "") | L19: =J19 -> 0 | M19: =IF(AND(I19<>"", I19<>0, L19<>"", L19<>0), L19/I19, "") | N19: =IF(AND(J19<>0, J19<>"", I19<>0, I19<>""), L19-I19, "") | O19: 0 | P19: =IF(AND(O19<>"", O19<>0, L19<>"", L19<>0), -O19+L19, "") | Q19: =IF(AND(P19<>"", P19<>0, O19<>0, O19<>""), P19/O19, "") | S19: =T18/S18 -> 0.72614812 | T19: =S19/J14*I14 -> 0.72614812
F20: Конверсия план/факт | I20: 0.18 | J20: =N56 -> 0.14215501 | K20: =J20/I20 -> 0.78975005 | L20: =IF(AND(K8<>0, I14<>0, I56<>0), (I56*N56+(I56/K8-I56)*I20)/(I56/K8), 0) -> 0.14874711 | M20: =IF(AND(I20<>"", I20<>0, L20<>"", L20<>0), L20/I20, "") -> 0.82637283 | N20: =IF(AND(J20<>0, J20<>"", I20<>0, I20<>""), L20-I20, "") -> -0.031252891 | P20: =IF(AND(O20<>"", O20<>0, L20<>"", L20<>0), -O20+L20, "") | Q20: =IF(AND(P20<>"", P20<>0, O20<>0, O20<>""), P20/O20, "")
A22: Факт продаж за месяц | O22: % выполнения дневного плана | P22: Раcпределение плана по дням
A23: Сотрудник | B23: Дата | C23: День недели | D23: Выручка (руб) | E23: Кол-во единиц (шт.) | F23: Средняя стоимость изделия (руб.) | G23: Количество чеков (шт.) | H23: Средняя сумма чека (руб.) | I23: Трафик | J23: Длина чека (шт.) | K23: UNOde50 | L23: IS | M23: Agafi | N23: Конверсия (%) | P23: выручка, план | Q23: кол-во ед, план | R23: Кол-во чеков, план | S23: выручка, скорректир.план | T23: кол-во ед, скорр. план | U23: кол-во чеков, скорр. план | V23: Коэфф. Дня Недели | W23: Специфика месяца
B24: 1 | C24: 2 | D24: 3 | E24: 4 | F24: 5 | G24: 6 | H24: 7 | I24: 8 | J24: 9 | K24: 10 | L24: 11 | M24: 12 | N24: 13 | P24: 1 | Q24: 2 | R24: 3 | S24: 4 | T24: 5 | U24: 6 | V24: 10 | W24: 11
A25: Уразгильдеева,Яковенко | B25: 45870 | C25: пт | D25: =14392+15952+3413.7+35091 -> 68848.7 | E25: 15 | F25: =IF(AND(E25<>"",E25<>0),D25/E25,"") -> 4589.9133 | G25: 9 | H25: =IF(AND(G25<>"",G25<>0),D25/G25,"") -> 7649.8556 | I25: 40 | J25: =IF(AND(G25<>"",G25<>0),E25/G25,"") -> 1.6666667 | K25: 14392 | M25: 4772.06 | N25: =IF(AND(I25<>"",I25<>0),G25/I25,"") -> 0.225 | O25: =D25/P25 -> 0.45057013 | P25: =$I$8*V25*W25/SUMPRODUCT($W$25:$W$55,$V$25:$V$55) -> 152803.52 | Q25: =$I$9*V25*W25/SUMPRODUCT($W$25:$W$55,$V$25:$V$55) -> 25.467253 | R25: =IF($I$12="","",Q25/$I$12) -> 14.980737 | S25: =IF(D25<>"",D25,P25) -> 68848.7 | T25: =IF(E25<>"",E25,Q25) -> 15 | U25: =IF(G25<>"",G25,R25) -> 9 | V25: 0.9414554 | W25: 0.9414554
A26: Рогалевич,Уразгильдеева | B26: 45871 | C26: сб | D26: =16900+48674+11383 -> 76957 | E26: 13 | F26: =IF(AND(E26<>"",E26<>0),D26/E26,"") -> 5919.7692 | G26: 9 | H26: =IF(AND(G26<>"",G26<>0),D26/G26,"") -> 8550.7778 | I26: 60 | J26: =IF(AND(G26<>"",G26<>0),E26/G26,"") -> 1.4444444 | K26: 11383 | L26: 16900 | M26: 0 | N26: =IF(AND(I26<>"",I26<>0),G26/I26,"") -> 0.15 | O26: =D26/P26 -> 0.61335516 | P26: =$I$8*V26*W26/SUMPRODUCT($W$25:$W$55,$V$25:$V$55) -> 125468.91 | Q26: =$I$9*V26*W26/SUMPRODUCT($W$25:$W$55,$V$25:$V$55) -> 20.911484 | R26: =IF($I$12="","",Q26/$I$12) -> 12.300873 | S26: =IF(W26<>"",IF(D26<>"",D26,($I$8-SUM($S$25:S25))*V26*W26/SUMPRODUCT($W26:$W$55,$V26:$V$55)),"") -> 76957 | T26: =IF(W26<>"",IF(E26<>"",E26,($I$9-SUM($T$25:T25))*V26*W26/SUMPRODUCT($W26:$W$55,$V26:$V$55)),"") -> 13 | U26: =IF(W26<>"",IF($I$12<>"",IF(G26<>"",G26,($I$9/$I$12-SUM($U$25:U25))*V26*W26/SUMPRODUCT($W26:$W$55,$V26:$V$55)),""),"") -> 9 | V26: 0.85310234 | W26: 0.85310234
A27: Рогалевич,Яковенко | B27: 45872 | C27: вс | D27: =222210.6+4623 -> 226833.6 | E27: 46 | F27: =IF(AND(E27<>"",E27<>0),D27/E27,"") -> 4931.1652 | G27: 20 | H27: =IF(AND(G27<>"",G27<>0),D27/G27,"") -> 11341.68 | I27: 110 | J27: =IF(AND(G27<>"",G27<>0),E27/G27,"") -> 2.3 | L27: 4623 | M27: 44443.25 | N27: =IF(AND(I27<>"",I27<>0),G27/I27,"") -> 0.18181818 | O27: =D27/P27 -> 1.807887 | P27: =$I$8*V27*W27/SUMPRODUCT($W$25:$W$55,$V$25:$V$55) -> 125468.91 | Q27: =$I$9*V27*W27/SUMPRODUCT($W$25:$W$55,$V$25:$V$55) -> 20.911484 | R27: =IF($I$12="","",Q27/$I$12) -> 12.300873 | S27: =IF(W27<>"",IF(D27<>"",D27,($I$8-SUM($S$25:S26))*V27*W27/SUMPRODUCT($W27:$W$55,$V27:$V$55)),"") -> 226833.6 | T27: =IF(W27<>"",IF(E27<>"",E27,($I$9-SUM($T$25:T26))*V27*W27/SUMPRODUCT($W27:$W$55,$V27:$V$55)),"") -> 46 | U27: =IF(W27<>"",IF($I$12<>"",IF(G27<>"",G27,($I$9/$I$12-SUM($U$25:U26))*V27*W27/SUMPRODUCT($W27:$W$55,$V27:$V$55)),""),"") -> 20 | V27: 0.85310234 | W27: 0.85310234
A28: Рогалевич,Яковенко | B28: 45873 | C28: пн | D28: 45513 | E28: 11 | F28: =IF(AND(E28<>"",E28<>0),D28/E28,"") -> 4137.5455 | G28: 9 | H28: =IF(AND(G28<>"",G28<>0),D28/G28,"") -> 5057 | I28: 60 | J28: =IF(AND(G28<>"",G28<>0),E28/G28,"") -> 1.2222222 | N28: =IF(AND(I28<>"",I28<>0),G28/I28,"") -> 0.15 | O28: =D28/P28 -> 0.36274326 | P28: =$I$8*V28*W28/SUMPRODUCT($W$25:$W$55,$V$25:$V$55) -> 125468.91 | Q28: =$I$9*V28*W28/SUMPRODUCT($W$25:$W$55,$V$25:$V$55) -> 20.911484 | R28: =IF($I$12="","",Q28/$I$12) -> 12.300873 | S28: =IF(W28<>"",IF(D28<>"",D28,($I$8-SUM($S$25:S27))*V28*W28/SUMPRODUCT($W28:$W$55,$V28:$V$55)),"") -> 45513 | T28: =IF(W28<>"",IF(E28<>"",E28,($I$9-SUM($T$25:T27))*V28*W28/SUMPRODUCT($W28:$W$55,$V28:$V$55)),"") -> 11 | U28: =IF(W28<>"",IF($I$12<>"",IF(G28<>"",G28,($I$9/$I$12-SUM($U$25:U27))*V28*W28/SUMPRODUCT($W28:$W$55,$V28:$V$55)),""),"") -> 9 | V28: 0.85310234 | W28: 0.85310234
A29: Яковенко,Уразгильдеева | B29: 45874 | C29: вт | D29: 82687.7 | E29: 18 | F29: =IF(AND(E29<>"",E29<>0),D29/E29,"") -> 4593.7611 | G29: 11 | H29: =IF(AND(G29<>"",G29<>0),D29/G29,"") -> 7517.0636 | I29: 50 | J29: =IF(AND(G29<>"",G29<>0),E29/G29,"") -> 1.6363636 | L29: 16203 | N29: =IF(AND(I29<>"",I29<>0),G29/I29,"") -> 0.22 | O29: =D29/P29 -> 0.66384886 | P29: =$I$8*V29*W29/SUMPRODUCT($W$25:$W$55,$V$25:$V$55) -> 124558.02 | Q29: =$I$9*V29*W29/SUMPRODUCT($W$25:$W$55,$V$25:$V$55) -> 20.75967 | R29: =IF($I$12="","",Q29/$I$12) -> 12.211571 | S29: =IF(W29<>"",IF(D29<>"",D29,($I$8-SUM($S$25:S28))*V29*W29/SUMPRODUCT($W29:$W$55,$V29:$V$55)),"") -> 82687.7 | T29: =IF(W29<>"",IF(E29<>"",E29,($I$9-SUM($T$25:T28))*V29*W29/SUMPRODUCT($W29:$W$55,$V29:$V$55)),"") -> 18 | U29: =IF(W29<>"",IF($I$12<>"",IF(G29<>"",G29,($I$9/$I$12-SUM($U$25:U28))*V29*W29/SUMPRODUCT($W29:$W$55,$V29:$V$55)),""),"") -> 11 | V29: 0.85 | W29: 0.85
A30: Рогалевич,Уразгильдеева | B30: 45875 | C30: ср | D30: =24903+46510+57982 -> 129395 | E30: 13 | F30: =IF(AND(E30<>"",E30<>0),D30/E30,"") -> 9953.4615 | G30: 11 | H30: =IF(AND(G30<>"",G30<>0),D30/G30,"") -> 11763.182 | I30: 50 | J30: =IF(AND(G30<>"",G30<>0),E30/G30,"") -> 1.1818182 | K30: 57982 | L30: 24903 | N30: =IF(AND(I30<>"",I30<>0),G30/I30,"") -> 0.22 | O30: =D30/P30 -> 0.75055695 | P30: =$I$8*V30*W30/SUMPRODUCT($W$25:$W$55,$V$25:$V$55) -> 172398.64 | Q30: =$I$9*V30*W30/SUMPRODUCT($W$25:$W$55,$V$25:$V$55) -> 28.733107 | R30: =IF($I$12="","",Q30/$I$12) -> 16.901828 | S30: =IF(W30<>"",IF(D30<>"",D30,($I$8-SUM($S$25:S29))*V30*W30/SUMPRODUCT($W30:$W$55,$V30:$V$55)),"") -> 129395 | T30: =IF(W30<>"",IF(E30<>"",E30,($I$9-SUM($T$25:T29))*V30*W30/SUMPRODUCT($W30:$W$55,$V30:$V$55)),"") -> 13 | U30: =IF(W30<>"",IF($I$12<>"",IF(G30<>"",G30,($I$9/$I$12-SUM($U$25:U29))*V30*W30/SUMPRODUCT($W30:$W$55,$V30:$V$55)),""),"") -> 11 | V30: 1 | W30: 1
A31: Рогалевич,Яковенко | B31: 45876 | C31: чт | D31: =16403+77557+50326+38820 -> 183106 | E31: 27 | F31: =IF(AND(E31<>"",E31<>0),D31/E31,"") -> 6781.7037 | G31: 19 | H31: =IF(AND(G31<>"",G31<>0),D31/G31,"") -> 9637.1579 | I31: 110 | J31: =IF(AND(G31<>"",G31<>0),E31/G31,"") -> 1.4210526 | K31: 77557 | L31: 16403 | M31: 12890 | N31: =IF(AND(I31<>"",I31<>0),G31/I31,"") -> 0.17272727 | O31: =D31/P31 -> 1.4593735 | P31: =$I$8*V31*W31/SUMPRODUCT($W$25:$W$55,$V$25:$V$55) -> 125468.91 | Q31: =$I$9*V31*W31/SUMPRODUCT($W$25:$W$55,$V$25:$V$55) -> 20.911484 | R31: =IF($I$12="","",Q31/$I$12) -> 12.300873 | S31: =IF(W31<>"",IF(D31<>"",D31,($I$8-SUM($S$25:S30))*V31*W31/SUMPRODUCT($W31:$W$55,$V31:$V$55)),"") -> 183106 | T31: =IF(W31<>"",IF(E31<>"",E31,($I$9-SUM($T$25:T30))*V31*W31/SUMPRODUCT($W31:$W$55,$V31:$V$55)),"") -> 27 | U31: =IF(W31<>"",IF($I$12<>"",IF(G31<>"",G31,($I$9/$I$12-SUM($U$25:U30))*V31*W31/SUMPRODUCT($W31:$W$55,$V31:$V$55)),""),"") -> 19 | V31: 0.85310234 | W31: 0.85310234
A32: Рогалевич,Яковенко | B32: 45877 | C32: пт | D32: =110637+25206+7492 -> 143335 | E32: 22 | F32: =IF(AND(E32<>"",E32<>0),D32/E32,"") -> 6515.2273 | G32: 11 | H32: =IF(AND(G32<>"",G32<>0),D32/G32,"") -> 13030.455 | I32: 80 | J32: =IF(AND(G32<>"",G32<>0),E32/G32,"") -> 2 | K32: 7492 | L32: 25206 | M32: 34570 | N32: =IF(AND(I32<>"",I32<>0),G32/I32,"") -> 0.1375 | O32: =D32/P32 -> 1.1423946 | P32: =$I$8*V32*W32/SUMPRODUCT($W$25:$W$55,$V$25:$V$55) -> 125468.91 | Q32: =$I$9*V32*W32/SUMPRODUCT($W$25:$W$55,$V$25:$V$55) -> 20.911484 | R32: =IF($I$12="","",Q32/$I$12) -> 12.300873 | S32: =IF(W32<>"",IF(D32<>"",D32,($I$8-SUM($S$25:S31))*V32*W32/SUMPRODUCT($W32:$W$55,$V32:$V$55)),"") -> 143335 | T32: =IF(W32<>"",IF(E32<>"",E32,($I$9-SUM($T$25:T31))*V32*W32/SUMPRODUCT($W32:$W$55,$V32:$V$55)),"") -> 22 | U32: =IF(W32<>"",IF($I$12<>"",IF(G32<>"",G32,($I$9/$I$12-SUM($U$25:U31))*V32*W32/SUMPRODUCT($W32:$W$55,$V32:$V$55)),""),"") -> 11 | V32: 0.85310234 | W32: 0.85310234
A33: Рогалевич,Яковенко,Уразгильдеева | B33: 45878 | C33: сб | D33: =46707+128331 -> 175038 | E33: 22 | F33: =IF(AND(E33<>"",E33<>0),D33/E33,"") -> 7956.2727 | G33: 16 | H33: =IF(AND(G33<>"",G33<>0),D33/G33,"") -> 10939.875 | I33: 110 | J33: =IF(AND(G33<>"",G33<>0),E33/G33,"") -> 1.375 | L33: 46707 | M33: 49280 | N33: =IF(AND(I33<>"",I33<>0),G33/I33,"") -> 0.14545455 | O33: =D33/P33 -> 1.3950708 | P33: =$I$8*V33*W33/SUMPRODUCT($W$25:$W$55,$V$25:$V$55) -> 125468.91 | Q33: =$I$9*V33*W33/SUMPRODUCT($W$25:$W$55,$V$25:$V$55) -> 20.911484 | R33: =IF($I$12="","",Q33/$I$12) -> 12.300873 | S33: =IF(W33<>"",IF(D33<>"",D33,($I$8-SUM($S$25:S32))*V33*W33/SUMPRODUCT($W33:$W$55,$V33:$V$55)),"") -> 175038 | T33: =IF(W33<>"",IF(E33<>"",E33,($I$9-SUM($T$25:T32))*V33*W33/SUMPRODUCT($W33:$W$55,$V33:$V$55)),"") -> 22 | U33: =IF(W33<>"",IF($I$12<>"",IF(G33<>"",G33,($I$9/$I$12-SUM($U$25:U32))*V33*W33/SUMPRODUCT($W33:$W$55,$V33:$V$55)),""),"") -> 16 | V33: 0.85310234 | W33: 0.85310234
A34: Рогалевич,Уразгильдеева | B34: 45879 | C34: вс | D34: =6991+50928+33665+20158 -> 111742 | E34: 17 | F34: =IF(AND(E34<>"",E34<>0),D34/E34,"") -> 6573.0588 | G34: 10 | H34: =IF(AND(G34<>"",G34<>0),D34/G34,"") -> 11174.2 | I34: 60 | J34: =IF(AND(G34<>"",G34<>0),E34/G34,"") -> 1.7 | K34: 6991 | L34: 50928 | N34: =IF(AND(I34<>"",I34<>0),G34/I34,"") -> 0.16666667 | O34: =D34/P34 -> 0.89059516 | P34: =$I$8*V34*W34/SUMPRODUCT($W$25:$W$55,$V$25:$V$55) -> 125468.91 | Q34: =$I$9*V34*W34/SUMPRODUCT($W$25:$W$55,$V$25:$V$55) -> 20.911484 | R34: =IF($I$12="","",Q34/$I$12) -> 12.300873 | S34: =IF(W34<>"",IF(D34<>"",D34,($I$8-SUM($S$25:S33))*V34*W34/SUMPRODUCT($W34:$W$55,$V34:$V$55)),"") -> 111742 | T34: =IF(W34<>"",IF(E34<>"",E34,($I$9-SUM($T$25:T33))*V34*W34/SUMPRODUCT($W34:$W$55,$V34:$V$55)),"") -> 17 | U34: =IF(W34<>"",IF($I$12<>"",IF(G34<>"",G34,($I$9/$I$12-SUM($U$25:U33))*V34*W34/SUMPRODUCT($W34:$W$55,$V34:$V$55)),""),"") -> 10 | V34: 0.85310234 | W34: 0.85310234
A35: Рогалевич,Яковенко | B35: 45880 | C35: пн | D35: =6992+35332+6000+38721 -> 87045 | E35: 20 | F35: =IF(AND(E35<>"",E35<>0),D35/E35,"") -> 4352.25 | G35: 10 | H35: =IF(AND(G35<>"",G35<>0),D35/G35,"") -> 8704.5 | I35: 60 | J35: =IF(AND(G35<>"",G35<>0),E35/G35,"") -> 2 | K35: 6992 | N35: =IF(AND(I35<>"",I35<>0),G35/I35,"") -> 0.16666667 | O35: =D35/P35 -> 0.50490536 | P35: =$I$8*V35*W35/SUMPRODUCT($W$25:$W$55,$V$25:$V$55) -> 172398.64 | Q35: =$I$9*V35*W35/SUMPRODUCT($W$25:$W$55,$V$25:$V$55) -> 28.733107 | R35: =IF($I$12="","",Q35/$I$12) -> 16.901828 | S35: =IF(W35<>"",IF(D35<>"",D35,($I$8-SUM($S$25:S34))*V35*W35/SUMPRODUCT($W35:$W$55,$V35:$V$55)),"") -> 87045 | T35: =IF(W35<>"",IF(E35<>"",E35,($I$9-SUM($T$25:T34))*V35*W35/SUMPRODUCT($W35:$W$55,$V35:$V$55)),"") -> 20 | U35: =IF(W35<>"",IF($I$12<>"",IF(G35<>"",G35,($I$9/$I$12-SUM($U$25:U34))*V35*W35/SUMPRODUCT($W35:$W$55,$V35:$V$55)),""),"") -> 10 | V35: 1 | W35: 1
A36: Рогалевич,Яковенко | B36: 45881 | C36: вт | D36: =20806+14280+66878+79259 -> 181223 | E36: 38 | F36: =IF(AND(E36<>"",E36<>0),D36/E36,"") -> 4769.0263 | G36: 23 | H36: =IF(AND(G36<>"",G36<>0),D36/G36,"") -> 7879.2609 | I36: 110 | J36: =IF(AND(G36<>"",G36<>0),E36/G36,"") -> 1.6521739 | L36: 20806 | M36: 14280 | N36: =IF(AND(I36<>"",I36<>0),G36/I36,"") -> 0.20909091 | O36: =D36/P36 -> 1.0511858 | P36: =$I$8*V36*W36/SUMPRODUCT($W$25:$W$55,$V$25:$V$55) -> 172398.64 | Q36: =$I$9*V36*W36/SUMPRODUCT($W$25:$W$55,$V$25:$V$55) -> 28.733107 | R36: =IF($I$12="","",Q36/$I$12) -> 16.901828 | S36: =IF(W36<>"",IF(D36<>"",D36,($I$8-SUM($S$25:S35))*V36*W36/SUMPRODUCT($W36:$W$55,$V36:$V$55)),"") -> 181223 | T36: =IF(W36<>"",IF(E36<>"",E36,($I$9-SUM($T$25:T35))*V36*W36/SUMPRODUCT($W36:$W$55,$V36:$V$55)),"") -> 38 | U36: =IF(W36<>"",IF($I$12<>"",IF(G36<>"",G36,($I$9/$I$12-SUM($U$25:U35))*V36*W36/SUMPRODUCT($W36:$W$55,$V36:$V$55)),""),"") -> 23 | V36: 1 | W36: 1
A37: Рогалевич,Уразгильдеева,Яковенко | B37: 45882 | C37: ср | D37: 268700 | E37: 40 | F37: =IF(AND(E37<>"",E37<>0),D37/E37,"") -> 6717.5 | G37: 18 | H37: =IF(AND(G37<>"",G37<>0),D37/G37,"") -> 14927.778 | I37: 110 | J37: =IF(AND(G37<>"",G37<>0),E37/G37,"") -> 2.2222222 | K37: 109143 | L37: 16106 | M37: 7390 | N37: =IF(AND(I37<>"",I37<>0),G37/I37,"") -> 0.16363636 | O37: =D37/P37 -> 1.5585969 | P37: =$I$8*V37*W37/SUMPRODUCT($W$25:$W$55,$V$25:$V$55) -> 172398.64 | Q37: =$I$9*V37*W37/SUMPRODUCT($W$25:$W$55,$V$25:$V$55) -> 28.733107 | R37: =IF($I$12="","",Q37/$I$12) -> 16.901828 | S37: =IF(W37<>"",IF(D37<>"",D37,($I$8-SUM($S$25:S36))*V37*W37/SUMPRODUCT($W37:$W$55,$V37:$V$55)),"") -> 268700 | T37: =IF(W37<>"",IF(E37<>"",E37,($I$9-SUM($T$25:T36))*V37*W37/SUMPRODUCT($W37:$W$55,$V37:$V$55)),"") -> 40 | U37: =IF(W37<>"",IF($I$12<>"",IF(G37<>"",G37,($I$9/$I$12-SUM($U$25:U36))*V37*W37/SUMPRODUCT($W37:$W$55,$V37:$V$55)),""),"") -> 18 | V37: 1 | W37: 1
A38: Уразгильдеева,Яковенко | B38: 45883 | C38: чт | D38: 127931 | E38: 21 | F38: =IF(AND(E38<>"",E38<>0),D38/E38,"") -> 6091.9524 | G38: 9 | H38: =IF(AND(G38<>"",G38<>0),D38/G38,"") -> 14214.556 | I38: 100 | J38: =IF(AND(G38<>"",G38<>0),E38/G38,"") -> 2.3333333 | K38: 36570.35 | L38: 0 | M38: 19970 | N38: =IF(AND(I38<>"",I38<>0),G38/I38,"") -> 0.09 | O38: =D38/P38 -> 0.742065 | P38: =$I$8*V38*W38/SUMPRODUCT($W$25:$W$55,$V$25:$V$55) -> 172398.64 | Q38: =$I$9*V38*W38/SUMPRODUCT($W$25:$W$55,$V$25:$V$55) -> 28.733107 | R38: =IF($I$12="","",Q38/$I$12) -> 16.901828 | S38: =IF(W38<>"",IF(D38<>"",D38,($I$8-SUM($S$25:S37))*V38*W38/SUMPRODUCT($W38:$W$55,$V38:$V$55)),"") -> 127931 | T38: =IF(W38<>"",IF(E38<>"",E38,($I$9-SUM($T$25:T37))*V38*W38/SUMPRODUCT($W38:$W$55,$V38:$V$55)),"") -> 21 | U38: =IF(W38<>"",IF($I$12<>"",IF(G38<>"",G38,($I$9/$I$12-SUM($U$25:U37))*V38*W38/SUMPRODUCT($W38:$W$55,$V38:$V$55)),""),"") -> 9 | V38: 1 | W38: 1
A39: Рогалевич,Яковенко | B39: 45853 | C39: пт | D39: =19598+47387+39885 -> 106870 | E39: 20 | F39: =IF(AND(E39<>"",E39<>0),D39/E39,"") -> 5343.5 | G39: 12 | H39: =IF(AND(G39<>"",G39<>0),D39/G39,"") -> 8905.8333 | I39: 100 | J39: =IF(AND(G39<>"",G39<>0),E39/G39,"") -> 1.6666667 | K39: 19598 | N39: =IF(AND(I39<>"",I39<>0),G39/I39,"") -> 0.12 | O39: =D39/P39 -> 0.61990047 | P39: =$I$8*V39*W39/SUMPRODUCT($W$25:$W$55,$V$25:$V$55) -> 172398.64 | Q39: =$I$9*V39*W39/SUMPRODUCT($W$25:$W$55,$V$25:$V$55) -> 28.733107 | R39: =IF($I$12="","",Q39/$I$12) -> 16.901828 | S39: =IF(W39<>"",IF(D39<>"",D39,($I$8-SUM($S$25:S38))*V39*W39/SUMPRODUCT($W39:$W$55,$V39:$V$55)),"") -> 106870 | T39: =IF(W39<>"",IF(E39<>"",E39,($I$9-SUM($T$25:T38))*V39*W39/SUMPRODUCT($W39:$W$55,$V39:$V$55)),"") -> 20 | U39: =IF(W39<>"",IF($I$12<>"",IF(G39<>"",G39,($I$9/$I$12-SUM($U$25:U38))*V39*W39/SUMPRODUCT($W39:$W$55,$V39:$V$55)),""),"") -> 12 | V39: 1 | W39: 1
A40: Рогалевич,Яковенко,Уразгильдеева | B40: 45854 | C40: сб | D40: =5501+49605+66972+74558+9283 -> 205919 | E40: 42 | F40: =IF(AND(E40<>"",E40<>0),D40/E40,"") -> 4902.8333 | G40: 23 | H40: =IF(AND(G40<>"",G40<>0),D40/G40,"") -> 8953 | I40: 100 | J40: =IF(AND(G40<>"",G40<>0),E40/G40,"") -> 1.826087 | L40: 5501 | N40: =IF(AND(I40<>"",I40<>0),G40/I40,"") -> 0.23 | O40: =D40/P40 -> 1.1944351 | P40: =$I$8*V40*W40/SUMPRODUCT($W$25:$W$55,$V$25:$V$55) -> 172398.64 | Q40: =$I$9*V40*W40/SUMPRODUCT($W$25:$W$55,$V$25:$V$55) -> 28.733107 | R40: =IF($I$12="","",Q40/$I$12) -> 16.901828 | S40: =IF(W40<>"",IF(D40<>"",D40,($I$8-SUM($S$25:S39))*V40*W40/SUMPRODUCT($W40:$W$55,$V40:$V$55)),"") -> 205919 | T40: =IF(W40<>"",IF(E40<>"",E40,($I$9-SUM($T$25:T39))*V40*W40/SUMPRODUCT($W40:$W$55,$V40:$V$55)),"") -> 42 | U40: =IF(W40<>"",IF($I$12<>"",IF(G40<>"",G40,($I$9/$I$12-SUM($U$25:U39))*V40*W40/SUMPRODUCT($W40:$W$55,$V40:$V$55)),""),"") -> 23 | V40: 1 | W40: 1
A41: Рогалевич,Уразгильдеева | B41: 45855 | C41: вс | D41: 67955 | E41: 16 | F41: =IF(AND(E41<>"",E41<>0),D41/E41,"") -> 4247.1875 | G41: 9 | H41: =IF(AND(G41<>"",G41<>0),D41/G41,"") -> 7550.5556 | I41: 70 | J41: =IF(AND(G41<>"",G41<>0),E41/G41,"") -> 1.7777778 | N41: =IF(AND(I41<>"",I41<>0),G41/I41,"") -> 0.12857143 | O41: =D41/P41 -> 0.39417363 | P41: =$I$8*V41*W41/SUMPRODUCT($W$25:$W$55,$V$25:$V$55) -> 172398.64 | Q41: =$I$9*V41*W41/SUMPRODUCT($W$25:$W$55,$V$25:$V$55) -> 28.733107 | R41: =IF($I$12="","",Q41/$I$12) -> 16.901828 | S41: =IF(W41<>"",IF(D41<>"",D41,($I$8-SUM($S$25:S40))*V41*W41/SUMPRODUCT($W41:$W$55,$V41:$V$55)),"") -> 67955 | T41: =IF(W41<>"",IF(E41<>"",E41,($I$9-SUM($T$25:T40))*V41*W41/SUMPRODUCT($W41:$W$55,$V41:$V$55)),"") -> 16 | U41: =IF(W41<>"",IF($I$12<>"",IF(G41<>"",G41,($I$9/$I$12-SUM($U$25:U40))*V41*W41/SUMPRODUCT($W41:$W$55,$V41:$V$55)),""),"") -> 9 | V41: 1 | W41: 1
...

Sheet Конкурс
A1: Сотрудник | B1: Длина чека | C1: КВП
D2: 11 | E2: 12 | F2: 13 | G2: 14 | H2: 15 | I2: 16 | J2: 17 | K2: 18 | L2: 19 | M2: 20 | N2: 21 | O2: 22 | P2: 23 | Q2: 24 | R2: 25 | S2: 26 | T2: 27 | U2: 28 | V2: 29 | W2: 30 | X2: 31 | Y2: Итого
A3: =График!B29 -> Рогалевич Ирина | B3: ='Рогалевич И. Е. '!J12 -> 1.8355263 | C3: ='Рогалевич И. Е. '!K8 -> 0.93589757 | D3: 2 | E3: 1 | F3: 1 | G3: 0 | H3: 1 | I3: 1 | J3: 0 | K3: 0 | L3: 2 | M3: 0 | N3: 0 | O3: 1 | P3: 1 | Q3: 0 | R3: 1 | S3: 0 | T3: 1 | U3: 0 | V3: 0 | W3: 1 | X3: 2 | Y3: =SUM(D3:X3) -> 15
A4: =График!B28 -> Уразгильдеева Екатерина | B4: ='Уразгильдеева Е. Р. '!J12 -> 1.5824176 | C4: ='Уразгильдеева Е. Р. '!K8 -> 0.65490658 | D4: 0 | E4: 0 | F4: 1 | G4: 0 | H4: 0 | I4: 1 | J4: 2 | K4: 0 | L4: 0 | M4: 0 | N4: 1 | O4: 0 | P4: 0 | Q4: 0 | R4: 0 | S4: 0 | T4: 0 | U4: 0 | V4: 0 | W4: 0 | X4: 0 | Y4: =SUM(D4:X4) -> 5
A5: =График!B27 -> Яковенко Алина | B5: ='Яковенко А. К. '!J12 -> 1.858209 | C5: ='Яковенко А. К. '!K8 -> 0.8645136 | D5: 1 | E5: 1 | F5: 0 | G5: 1 | H5: 0 | I5: 0 | J5: 0 | K5: 0 | L5: 0 | M5: 0 | N5: 1 | O5: 1 | P5: 0 | Q5: 0 | R5: 0 | S5: 0 | T5: 1 | U5: 0 | V5: 0 | W5: 0 | X5: 0 | Y5: =SUM(D5:X5) -> 6

Sheet Св. по пок.
A1: 1-20.08
A2: Показатель | D2: ='Ялта, Ленина, 18'!I3 -> ул. Набережная Ленина, 18 | G2: =График!B29 -> Рогалевич Ирина | J2: =График!B28 -> Уразгильдеева Екатерина | M2: =График!B27 -> Яковенко Алина
D3: Факт | F3: Прогноз | G3: Факт | I3: Прогноз | J3: Факт | L3: Прогноз | M3: Факт | O3: Прогноз
A4: Выручка | D4: ='Ялта, Ленина, 18'!K8 -> 0.82581316 | E4: ='Ялта, Ленина, 18'!J8 -> 3881454 | F4: ='Ялта, Ленина, 18'!M8 -> 0.82581316 | G4: ='Рогалевич И. Е. '!K8 -> 0.93589757 | H4: ='Рогалевич И. Е. '!J8 -> 1621279.7 | I4: ='Рогалевич И. Е. '!M8 -> 0.93589757 | J4: ='Уразгильдеева Е. Р. '!K8 -> 0.65490658 | K4: ='Уразгильдеева Е. Р. '!J8 -> 954702.3 | L4: ='Уразгильдеева Е. Р. '!M8 -> 0.65490658 | M4: ='Яковенко А. К. '!K8 -> 0.8645136 | N4: ='Яковенко А. К. '!J8 -> 1305472 | O4: ='Яковенко А. К. '!M8 -> 0.8645136
A5: Кол-во изделий | D5: ='Ялта, Ленина, 18'!K9 -> 0.85784314 | E5: ='Ялта, Ленина, 18'!J9 -> 672 | F5: ='Ялта, Ленина, 18'!M9 -> 0.85784314 | G5: ='Рогалевич И. Е. '!K9 -> 0.96633081 | H5: ='Рогалевич И. Е. '!J9 -> 279 | I5: ='Рогалевич И. Е. '!M9 -> 0.96633081 | J5: ='Уразгильдеева Е. Р. '!K9 -> 0.59268663 | K5: ='Уразгильдеева Е. Р. '!J9 -> 144 | L5: ='Уразгильдеева Е. Р. '!M9 -> 0.59268663 | M5: ='Яковенко А. К. '!K9 -> 0.98936118 | N5: ='Яковенко А. К. '!J9 -> 249 | O5: ='Яковенко А. К. '!M9 -> 0.98936118
A6: Средний чек | D6: ='Ялта, Ленина, 18'!K10 -> 1.0120604 | E6: ='Ялта, Ленина, 18'!J10 -> 10323.016 | F6: ='Ялта, Ленина, 18'!M10 -> 1.0120604 | G6: ='Рогалевич И. Е. '!K10 -> 1.045717 | H6: ='Рогалевич И. Е. '!J10 -> 10666.314 | I6: ='Рогалевич И. Е. '!M10 -> 1.045717 | J6: ='Уразгильдеева Е. Р. '!K10 -> 1.0285524 | K6: ='Уразгильдеева Е. Р. '!J10 -> 10491.234 | L6: ='Уразгильдеева Е. Р. '!M10 -> 1.0285524 | M6: ='Яковенко А. К. '!K10 -> 0.95513023 | N6: ='Яковенко А. К. '!J10 -> 9742.3284 | O6: ='Яковенко А. К. '!M10 -> 0.95513023
A7: Средняя стоимость изделия | D7: ='Ялта, Ленина, 18'!K11 -> 0.9626622 | E7: ='Ялта, Ленина, 18'!J11 -> 5775.9732 | F7: ='Ялта, Ленина, 18'!M11 -> 0.9626622 | G7: ='Рогалевич И. Е. '!K11 -> 0.96850639 | H7: ='Рогалевич И. Е. '!J11 -> 5811.0384 | I7: ='Рогалевич И. Е. '!M11 -> 0.96850639 | J7: ='Уразгильдеева Е. Р. '!K11 -> 1.1049795 | K7: ='Уразгильдеева Е. Р. '!J11 -> 6629.8771 | L7: ='Уразгильдеева Е. Р. '!M11 -> 1.1049795 | M7: ='Яковенко А. К. '!K11 -> 0.87380991 | N7: ='Яковенко А. К. '!J11 -> 5242.8594 | O7: ='Яковенко А. К. '!M11 -> 0.87380991
A8: Длина чека | D8: ='Ялта, Ленина, 18'!K12 -> 1.0513141 | E8: ='Ялта, Ленина, 18'!J12 -> 1.787234 | F8: ='Ялта, Ленина, 18'!M12 -> 1.0513141 | G8: ='Рогалевич И. Е. '!K12 -> 1.0797214 | H8: ='Рогалевич И. Е. '!J12 -> 1.8355263 | I8: ='Рогалевич И. Е. '!M12 -> 1.0797214 | J8: ='Уразгильдеева Е. Р. '!K12 -> 0.93083387 | K8: ='Уразгильдеева Е. Р. '!J12 -> 1.5824176 | L8: ='Уразгильдеева Е. Р. '!M12 -> 0.93083387 | M8: ='Яковенко А. К. '!K12 -> 1.0930641 | N8: ='Яковенко А. К. '!J12 -> 1.858209 | O8: ='Яковенко А. К. '!M12 -> 1.0930641
A9: Кол-во чеков | D9: ='Ялта, Ленина, 18'!K13 -> 0.81597222 | E9: ='Ялта, Ленина, 18'!J13 -> 376 | F9: ='Ялта, Ленина, 18'!M13 -> 0.81597222 | G9: ='Рогалевич И. Е. '!K13 -> 0.89498166 | H9: ='Рогалевич И. Е. '!J13 -> 152 | I9: ='Рогалевич И. Е. '!M13 -> 0.89498166 | J9: ='Уразгильдеева Е. Р. '!K13 -> 0.63672654 | K9: ='Уразгильдеева Е. Р. '!J13 -> 91 | L9: ='Уразгильдеева Е. Р. '!M13 -> 0.63672654 | M9: ='Яковенко А. К. '!K13 -> 0.90512641 | N9: ='Яковенко А. К. '!J13 -> 134 | O9: ='Яковенко А. К. '!M13 -> 0.90512641
A10: Кол-во смен план/отработано | D10: ='Ялта, Ленина, 18'!K14 -> 1 | E10: ='Ялта, Ленина, 18'!J14 -> 31 | G10: ='Рогалевич И. Е. '!K14 -> 1 | H10: ='Рогалевич И. Е. '!J14 -> 26 | J10: ='Уразгильдеева Е. Р. '!K14 -> 1 | K10: ='Уразгильдеева Е. Р. '!J14 -> 18 | M10: ='Яковенко А. К. '!K14 -> 1 | N10: ='Яковенко А. К. '!J14 -> 21
A11: Средние продажи в смену | D11: ='Ялта, Ленина, 18'!K15 -> 0.82581316 | E11: ='Ялта, Ленина, 18'!J15 -> 125208.19 | F11: ='Ялта, Ленина, 18'!M15 -> 0.82581316 | G11: ='Рогалевич И. Е. '!K15 -> 0.41127627 | H11: ='Рогалевич И. Е. '!J15 -> 62356.912 | I11: ='Рогалевич И. Е. '!M15 -> 0.41127627 | J11: ='Уразгильдеева Е. Р. '!K15 -> 0.3498199 | K11: ='Уразгильдеева Е. Р. '!J15 -> 53039.017 | L11: ='Уразгильдеева Е. Р. '!M15 -> 0.3498199 | M11: ='Яковенко А. К. '!K15 -> 0.41001271 | N11: ='Яковенко А. К. '!J15 -> 62165.333 | O11: ='Яковенко А. К. '!M15 -> 0.41001271
A12: Трафик | D12: ='Ялта, Ленина, 18'!K17 -> 1.0332031 | E12: ='Ялта, Ленина, 18'!J17 -> 2645 | F12: ='Ялта, Ленина, 18'!M17 -> 1.0332031 | G12: ='Рогалевич И. Е. '!K17 -> 1.0736247 | H12: ='Рогалевич И. Е. '!J17 -> 1013 | I12: ='Рогалевич И. Е. '!M17 -> 1.0736247 | J12: ='Уразгильдеева Е. Р. '!K17 -> 0.92444297 | K12: ='Уразгильдеева Е. Р. '!J17 -> 734 | L12: ='Уразгильдеева Е. Р. '!M17 -> 0.92444297 | M12: ='Яковенко А. К. '!K17 -> 1.0918256 | N12: ='Яковенко А. К. '!J17 -> 898 | O12: ='Яковенко А. К. '!M17 -> 1.0918256
A13: UNOde50 | D13: ='Ялта, Ленина, 18'!S19 -> 0.72614812 | E13: ='Ялта, Ленина, 18'!T18 -> 639010.35 | F13: ='Ялта, Ленина, 18'!T19 -> 0.72614812 | G13: ='Рогалевич И. Е. '!S19 -> 0.98418521 | H13: ='Рогалевич И. Е. '!T18 -> 319210 | I13: ='Рогалевич И. Е. '!T19 -> 0.98418521 | J13: ='Уразгильдеева Е. Р. '!S19 -> 0.82748513 | K13: ='Уразгильдеева Е. Р. '!T18 -> 225849.35 | L13: ='Уразгильдеева Е. Р. '!T19 -> 0.82748513 | M13: ='Яковенко А. К. '!S19 -> 0.33230406 | N13: ='Яковенко А. К. '!T18 -> 93951 | O13: ='Яковенко А. К. '!T19 -> 0.33230406
A14: IS | D14: ='Ялта, Ленина, 18'!S13 -> 0.55283158 | E14: ='Ялта, Ленина, 18'!T12 -> 420152 | F14: ='Ялта, Ленина, 18'!T13 -> 0.55283158 | G14: ='Рогалевич И. Е. '!S13 -> 0.54286642 | H14: ='Рогалевич И. Е. '!T12 -> 152063 | I14: ='Рогалевич И. Е. '!T13 -> 0.54286642 | J14: ='Уразгильдеева Е. Р. '!S13 -> 0.65226299 | K14: ='Уразгильдеева Е. Р. '!T12 -> 153749 | L14: ='Уразгильдеева Е. Р. '!T13 -> 0.65226299 | M14: ='Яковенко А. К. '!S13 -> 0.46827558 | N14: ='Яковенко А. К. '!T12 -> 114340 | O14: ='Яковенко А. К. '!T13 -> 0.46827558
A15: ='Ялта, Ленина, 18'!M23 -> Agafi | D15: ='Ялта, Ленина, 18'!V13 -> 0.64412241 | E15: ='Ялта, Ленина, 18'!W12 -> 296296.31 | F15: ='Ялта, Ленина, 18'!W13 -> 0.64412241 | G15: ='Рогалевич И. Е. '!V13 -> 0.50266299 | H15: ='Рогалевич И. Е. '!W12 -> 85222 | I15: ='Рогалевич И. Е. '!W13 -> 0.50266299 | J15: ='Уразгильдеева Е. Р. '!V13 -> 0.38439655 | K15: ='Уразгильдеева Е. Р. '!W12 -> 54842 | L15: ='Уразгильдеева Е. Р. '!W13 -> 0.38439655 | M15: ='Яковенко А. К. '!V13 -> 1.0571337 | N15: ='Яковенко А. К. '!W12 -> 156232.31 | O15: ='Яковенко А. К. '!W13 -> 1.0571337
A16: Отклонение от плана | D16: ='Ялта, Ленина, 18'!J16 -> -818706 | G16: ='Рогалевич И. Е. '!N8 -> -111046.31 | J16: ='Уразгильдеева Е. Р. '!N8 -> -503066.38 | M16: ='Яковенко А. К. '!N8 -> -204593.31

Sheet План на день
A1: Выручка | D1: 172399
A2: Кол-во изделий | D2: =D1/D4 -> 28.733167
A3: Средний чек | D3: =D4*D5 -> 10200
A4: Средняя стоимость изделия | D4: ='Ялта, Ленина, 18'!I11 -> 6000
A5: Длина чека | D5: ='Ялта, Ленина, 18'!I12 -> 1.7
A6: Кол-во чеков | D6: =IF(D5<>0,D2/D5,"") -> 16.901863
A7: Конверсия | D7: ='Ялта, Ленина, 18'!I20 -> 0.18
A8: IS | D8: =('Ялта, Ленина, 18'!S12-'Ялта, Ленина, 18'!T12)/('Ялта, Ленина, 18'!I14-'Ялта, Ленина, 18'!J14) -> #DIV/0!
A9: UNOde50 | D9: =('Ялта, Ленина, 18'!S18-'Ялта, Ленина, 18'!T18)/('Ялта, Ленина, 18'!I14-'Ялта, Ленина, 18'!J14) -> #DIV/0!
A10: ='Ялта, Ленина, 18'!M23 -> Agafi | D10: =('Ялта, Ленина, 18'!V12-'Ялта, Ленина, 18'!W12)/('Ялта, Ленина, 18'!I14-'Ялта, Ленина, 18'!J14) -> #DIV/0!

Sheet Рогалевич И. Е. 
B1: =TODAY()-1 -> 45909
B2: (отчетная дата) | J2: ЕЖЕДНЕВНЫЙ ОТЧЕТ О ПРОДАЖАХ
B3: Осталось до выполнения плана!!! | J3: =График!B29 -> Рогалевич Ирина
C4: =I8-D54 -> 111046.31 | E4: =IF(I8<>0,C4/I8,0) -> 0.064102431
F6: Целевые показатели
F7: Показатель | I7: План | J7: Факт | K7: % выполнения | L7: Прогноз выполнения | M7: % выполнения по прогнозу | N7: Отклонение | O7: Факт аналогичного месяца прошлого года | P7: Отклонение LFL
F8: Выручка | I8: ='Ялта, Ленина, 18'!I8/График!AJ31*График!AJ29 -> 1732326 | J8: =D54 -> 1621279.7 | K8: =IF(AND(I8<>"",I8<>0,J8<>""),J8/I8,"") -> 0.93589757 | L8: =IF(SUMIF($D$25:$D$53,">=0",$P$25:$P$53)<>0,I8*D54/SUMIF($D$25:$D$53,">=0",$P$25:$P$53),0) -> 1621279.7 | M8: =IF(AND(I8<>"",I8<>0,L8<>"",L8<>0),L8/I8,"") -> 0.93589757 | N8: =IF(AND(J8<>0,J8<>"",I8<>0,I8<>""),L8-I8,"") -> -111046.31 | P8: =IF(AND(O8<>"",O8<>0,L8<>"",L8<>0),-O8+L8,"") | Q8: =IF(AND(P8<>"",P8<>0,O8<>0,O8<>""),P8/O8,"")
F9: Кол-во изделий | I9: =I8/I11 -> 288.721 | J9: =E54 -> 279 | K9: =IF(AND(I9<>"",I9<>0,J9<>""),J9/I9,"") -> 0.96633081 | L9: =IF(SUMIF($E$25:$E$51,">=0",$Q$25:$Q$51)<>0,I9*E54/SUMIF($E$25:$E$51,">=0",$Q$25:$Q$51),0) -> 279 | M9: =IF(AND(I9<>"",I9<>0,L9<>"",L9<>0),L9/I9,"") -> 0.96633081 | N9: =IF(AND(J9<>0,J9<>"",I9<>0,I9<>""),L9-I9,"") -> -9.7210014 | O9: =O8/O11 -> #DIV/0! | P9: =IF(AND(O9<>"",O9<>0,L9<>"",L9<>0),-O9+L9,"") -> #DIV/0! | Q9: =IF(AND(P9<>"",P9<>0,O9<>0,O9<>""),P9/O9,"") -> #DIV/0!
F10: Средний чек | I10: =I11*I12 -> 10200 | J10: =H54 -> 10666.314 | K10: =IF(AND(I10<>"",I10<>0,J10<>""),J10/I10,"") -> 1.045717 | L10: =J10 -> 10666.314 | M10: =IF(AND(I10<>"",I10<>0,L10<>"",L10<>0),L10/I10,"") -> 1.045717 | N10: =IF(AND(J10<>0,J10<>"",I10<>0,I10<>""),L10-I10,"") -> 466.31382 | O10: =O11*O12 -> 0 | P10: =IF(AND(O10<>"",O10<>0,L10<>"",L10<>0),-O10+L10,"") | Q10: =IF(AND(P10<>"",P10<>0,O10<>0,O10<>""),P10/O10,"") | S10: IS | V10: =M23 -> Agafi
F11: Средняя стоимость изделия | I11: ='Ялта, Ленина, 18'!I11 -> 6000 | J11: =F54 -> 5811.0384 | K11: =IF(AND(I11<>"",I11<>0,J11<>""),J11/I11,"") -> 0.96850639 | L11: =IF(L9>0,L8/L9,"") -> 5811.0384 | M11: =IF(AND(I11<>"",I11<>0,L11<>"",L11<>0),L11/I11,"") -> 0.96850639 | N11: =IF(AND(J11<>0,J11<>"",I11<>0,I11<>""),L11-I11,"") -> -188.96165 | P11: =IF(AND(O11<>"",O11<>0,L11<>"",L11<>0),-O11+L11,"") | Q11: =IF(AND(P11<>"",P11<>0,O11<>0,O11<>""),P11/O11,"")
F12: Длина чека | I12: ='Ялта, Ленина, 18'!I12 -> 1.7 | J12: =J54 -> 1.8355263 | K12: =IF(AND(I12<>"",I12<>0,J12<>""),J12/I12,"") -> 1.0797214 | L12: =J12 -> 1.8355263 | M12: =IF(AND(I12<>"",I12<>0,L12<>"",L12<>0),L12/I12,"") -> 1.0797214 | N12: =IF(AND(J12<>0,J12<>"",I12<>0,I12<>""),L12-I12,"") -> 0.13552632 | P12: =IF(AND(O12<>"",O12<>0,L12<>"",L12<>0),-O12+L12,"") | Q12: =IF(AND(P12<>"",P12<>0,O12<>0,O12<>""),P12/O12,"") | S12: ='Ялта, Ленина, 18'!S12*График!AJ29/График!AJ31 -> 280111.27 | T12: =L54 -> 152063 | V12: ='Ялта, Ленина, 18'!V12/График!AJ31*График!AJ29 -> 169541.03 | W12: =M54 -> 85222
F13: Кол-во чеков | I13: =IF(I12<>0,I9/I12,"") -> 169.83588 | J13: =G54 -> 152 | K13: =IF(AND(I13<>"",I13<>0,J13<>""),J13/I13,"") -> 0.89498166 | L13: =IF(SUMIF($G$25:$G$51,">=0",$R$25:$R$51)<>0,I13*G54/SUMIF($G$25:$G$51,">=0",$R$25:$R$51),"") -> 152 | M13: =IF(AND(I13<>"",I13<>0,L13<>"",L13<>0),L13/I13,"") -> 0.89498166 | N13: =IF(AND(J13<>0,J13<>"",I13<>0,I13<>""),L13-I13,"") -> -17.835883 | P13: =IF(AND(O13<>"",O13<>0,L13<>"",L13<>0),-O13+L13,"") | Q13: =IF(AND(P13<>"",P13<>0,O13<>0,O13<>""),P13/O13,"") | S13: =T12/S12 -> 0.54286642 | T13: =S13/J14*I14 -> 0.54286642 | V13: =W12/V12 -> 0.50266299 | W13: =V13/J14*I14 -> 0.50266299
F14: Кол-во смен план/отработано | I14: =График!AI29 -> 26 | J14: 26 | K14: =IF(AND(I14<>"",I14<>0,J14<>""),J14/I14,"") -> 1 | L14: =I14 -> 26 | M14: =IF(AND(I14<>"",I14<>0,L14<>"",L14<>0),L14/I14,"") -> 1 | N14: =IF(AND(J14<>0,J14<>"",I14<>0,I14<>""),L14-I14,"") -> 0 | P14: =IF(AND(O14<>"",O14<>0,L14<>"",L14<>0),-O14+L14,"") | Q14: =IF(AND(P14<>"",P14<>0,O14<>0,O14<>""),P14/O14,"")
F15: Средние продажи в смену | I15: ='Ялта, Ленина, 18'!I15 -> 151618.06 | J15: =J8/J14 -> 62356.912 | K15: =IF(AND(I15<>"",I15<>0,J15<>""),J15/I15,"") -> 0.41127627 | L15: =J15 -> 62356.912 | M15: =IF(AND(I15<>"",I15<>0,L15<>"",L15<>0),L15/I15,"") -> 0.41127627 | N15: =IF(AND(J15<>0,J15<>"",I15<>0,I15<>""),L15-I15,"") -> -89261.153 | P15: =IF(AND(O15<>"",O15<>0,L15<>"",L15<>0),-O15+L15,"") | Q15: =IF(AND(P15<>"",P15<>0,O15<>0,O15<>""),P15/O15,"")
F16: Отставание/Перевыполнение | J16: =J8-I15*J14 -> -2320790 | K16: =IF(AND(I16<>"",I16<>0,J16<>""),J16/I16,"") | L16: =J16 -> -2320790 | M16: =IF(AND(I16<>"",I16<>0,L16<>"",L16<>0),L16/I16,"") | N16: =IF(AND(J16<>0,J16<>"",I16<>0,I16<>""),L16-I16,"") | P16: =IF(AND(O16<>"",O16<>0,L16<>"",L16<>0),-O16+L16,"") | Q16: =IF(AND(P16<>"",P16<>0,O16<>0,O16<>""),P16/O16,"") | S16: UNOde50
F17: Трафик | I17: ='Ялта, Ленина, 18'!I17/График!AJ31*График!AJ29 -> 943.53268 | J17: =I54 -> 1013 | K17: =IF(AND(I17<>"",I17<>0,J17<>""),J17/I17,"") -> 1.0736247 | L17: =J17/J14*I14 -> 1013 | M17: =IF(AND(I17<>"",I17<>0,L17<>"",L17<>0),L17/I17,"") -> 1.0736247 | N17: =IF(AND(J17<>0,J17<>"",I17<>0,I17<>""),L17-I17,"") -> 69.467316 | P17: =IF(AND(O17<>"",O17<>0,L17<>"",L17<>0),-O17+L17,"") | Q17: =IF(AND(P17<>"",P17<>0,O17<>0,O17<>""),P17/O17,"")
K18: =IF(AND(I18<>"",I18<>0,J18<>""),J18/I18,"") | L18: =J18 -> 0 | M18: =IF(AND(I18<>"",I18<>0,L18<>"",L18<>0),L18/I18,"") | N18: =IF(AND(J18<>0,J18<>"",I18<>0,I18<>""),L18-I18,"") | O18: 0 | P18: =IF(AND(O18<>"",O18<>0,L18<>"",L18<>0),-O18+L18,"") | Q18: =IF(AND(P18<>"",P18<>0,O18<>0,O18<>""),P18/O18,"") | S18: ='Ялта, Ленина, 18'!S18*График!AJ29/График!AJ31 -> 324339.36 | T18: =K54 -> 319210
J19: =M54 -> 85222 | K19: =IF(AND(I19<>"",I19<>0,J19<>""),J19/I19,"") | L19: =J19 -> 85222 | M19: =IF(AND(I19<>"",I19<>0,L19<>"",L19<>0),L19/I19,"") | N19: =IF(AND(J19<>0,J19<>"",I19<>0,I19<>""),L19-I19,"") | O19: 0 | P19: =IF(AND(O19<>"",O19<>0,L19<>"",L19<>0),-O19+L19,"") | Q19: =IF(AND(P19<>"",P19<>0,O19<>0,O19<>""),P19/O19,"") | S19: =T18/S18 -> 0.98418521 | T19: =S19/J14*I14 -> 0.98418521
F20: Конверсия план/факт | I20: ='Ялта, Ленина, 18'!I20 -> 0.18 | J20: =N54 -> 0.15004936 | K20: =J20/I20 -> 0.83360755 | L20: =IF(AND(K8<>0,I14<>0,I54<>0),(I54*N54+(I54/K8-I54)*I20)/(I54/K8),0) -> 0.15196927 | M20: =IF(AND(I20<>"",I20<>0,L20<>"",L20<>0),L20/I20,"") -> 0.84427371 | N20: =IF(AND(J20<>0,J20<>"",I20<>0,I20<>""),L20-I20,"") -> -0.028030733 | P20: =IF(AND(O20<>"",O20<>0,L20<>"",L20<>0),-O20+L20,"") | Q20: =IF(AND(P20<>"",P20<>0,O20<>0,O20<>""),P20/O20,"")
B22: Факт продаж за месяц | O22: % выполнения дневного плана | P22: Раcпределение плана по дням
B23: Дата | C23: День недели | D23: Выручка (руб) | E23: Кол-во единиц (шт.) | F23: Средняя стоимость изделия (руб.) | G23: Количество чеков (шт.) | H23: Средняя сумма чека (руб.) | I23: Трафик | J23: Длина чека (шт.) | K23: UNOde50 | L23: IS | M23: Agafi | N23: Конверсия (%) | P23: выручка, план | Q23: кол-во ед, план | R23: Кол-во чеков, план | S23: выручка, скорректир.план | T23: кол-во ед, скорр. план | U23: кол-во чеков, скорр. план | V23: Коэфф. Дня Недели | W23: Специфика месяца
B24: 1 | C24: 2 | D24: 3 | E24: 4 | F24: 5 | G24: 6 | H24: 7 | I24: 8 | J24: 9 | K24: 10 | L24: 11 | M24: 12 | N24: 13 | P24: 1 | Q24: 2 | R24: 3 | S24: 4 | T24: 5 | U24: 6 | V24: 10 | W24: 11
A25: 1 | B25: 45871 | C25: сб | D25: 32095 | E25: 8 | F25: =IF(AND(E25<>"",E25<>0),D25/E25,"") -> 4011.875 | G25: 4 | H25: =IF(AND(G25<>"",G25<>0),D25/G25,"") -> 8023.75 | I25: 30 | J25: =IF(AND(G25<>"",G25<>0),E25/G25,"") -> 2 | N25: =IF(AND(I25<>"",I25<>0),G25/I25,"") -> 0.13333333 | O25: =D25/P25 -> 0.48170494 | P25: =$I$8*V25*W25/SUMPRODUCT($W$25:$W$53,$V$25:$V$53) -> 66627.923 | Q25: =$I$9*V25*W25/SUMPRODUCT($W$25:$W$53,$V$25:$V$53) -> 11.104654 | R25: =IF($I$12="","",Q25/$I$12) -> 6.5321494 | S25: =IF(D25<>"",D25,P25) -> 32095 | T25: =IF(E25<>"",E25,Q25) -> 8 | U25: =IF(G25<>"",G25,R25) -> 4 | V25: 1 | W25: 1
A26: 2 | B26: 45872 | C26: вс | D26: =122924+4623 -> 127547 | E26: 25 | F26: =IF(AND(E26<>"",E26<>0),D26/E26,"") -> 5101.88 | G26: 10 | H26: =IF(AND(G26<>"",G26<>0),D26/G26,"") -> 12754.7 | I26: 55 | J26: =IF(AND(G26<>"",G26<>0),E26/G26,"") -> 2.5 | L26: 4623 | M26: 27270 | N26: =IF(AND(I26<>"",I26<>0),G26/I26,"") -> 0.18181818 | O26: =D26/P26 -> 1.9143175 | P26: =$I$8*V26*W26/SUMPRODUCT($W$25:$W$53,$V$25:$V$53) -> 66627.923 | Q26: =$I$9*V26*W26/SUMPRODUCT($W$25:$W$53,$V$25:$V$53) -> 11.104654 | R26: =IF($I$12="","",Q26/$I$12) -> 6.5321494 | S26: =IF(W26<>"",IF(D26<>"",D26,($I$8-SUM($S$25:S25))*V26*W26/SUMPRODUCT($W26:$W$55,$V26:$V$55)),"") -> 127547 | T26: =IF(W26<>"",IF(E26<>"",E26,($I$9-SUM($T$25:T25))*V26*W26/SUMPRODUCT($W26:$W$55,$V26:$V$55)),"") -> 25 | U26: =IF(W26<>"",IF($I$12<>"",IF(G26<>"",G26,($I$9/$I$12-SUM($U$25:U25))*V26*W26/SUMPRODUCT($W26:$W$55,$V26:$V$55)),""),"") -> 10 | V26: 1 | W26: 1
A27: 3 | B27: 45873 | C27: пн | D27: 22961 | E27: 5 | F27: =IF(AND(E27<>"",E27<>0),D27/E27,"") -> 4592.2 | G27: 4 | H27: =IF(AND(G27<>"",G27<>0),D27/G27,"") -> 5740.25 | I27: 30 | J27: =IF(AND(G27<>"",G27<>0),E27/G27,"") -> 1.25 | N27: =IF(AND(I27<>"",I27<>0),G27/I27,"") -> 0.13333333 | O27: =D27/P27 -> 0.34461527 | P27: =$I$8*V27*W27/SUMPRODUCT($W$25:$W$53,$V$25:$V$53) -> 66627.923 | Q27: =$I$9*V27*W27/SUMPRODUCT($W$25:$W$53,$V$25:$V$53) -> 11.104654 | R27: =IF($I$12="","",Q27/$I$12) -> 6.5321494 | S27: =IF(W27<>"",IF(D27<>"",D27,($I$8-SUM($S$25:S26))*V27*W27/SUMPRODUCT($W27:$W$55,$V27:$V$55)),"") -> 22961 | T27: =IF(W27<>"",IF(E27<>"",E27,($I$9-SUM($T$25:T26))*V27*W27/SUMPRODUCT($W27:$W$55,$V27:$V$55)),"") -> 5 | U27: =IF(W27<>"",IF($I$12<>"",IF(G27<>"",G27,($I$9/$I$12-SUM($U$25:U26))*V27*W27/SUMPRODUCT($W27:$W$55,$V27:$V$55)),""),"") -> 4 | V27: 1 | W27: 1
A28: 4 | B28: 45875 | C28: ср | D28: =57982+27939 -> 85921 | E28: 8 | F28: =IF(AND(E28<>"",E28<>0),D28/E28,"") -> 10740.125 | G28: 6 | H28: =IF(AND(G28<>"",G28<>0),D28/G28,"") -> 14320.167 | I28: 25 | J28: =IF(AND(G28<>"",G28<>0),E28/G28,"") -> 1.3333333 | K28: 57982 | N28: =IF(AND(I28<>"",I28<>0),G28/I28,"") -> 0.24 | O28: =D28/P28 -> 1.2895644 | P28: =$I$8*V28*W28/SUMPRODUCT($W$25:$W$53,$V$25:$V$53) -> 66627.923 | Q28: =$I$9*V28*W28/SUMPRODUCT($W$25:$W$53,$V$25:$V$53) -> 11.104654 | R28: =IF($I$12="","",Q28/$I$12) -> 6.5321494 | S28: =IF(W28<>"",IF(D28<>"",D28,($I$8-SUM($S$25:S27))*V28*W28/SUMPRODUCT($W28:$W$55,$V28:$V$55)),"") -> 85921 | T28: =IF(W28<>"",IF(E28<>"",E28,($I$9-SUM($T$25:T27))*V28*W28/SUMPRODUCT($W28:$W$55,$V28:$V$55)),"") -> 8 | U28: =IF(W28<>"",IF($I$12<>"",IF(G28<>"",G28,($I$9/$I$12-SUM($U$25:U27))*V28*W28/SUMPRODUCT($W28:$W$55,$V28:$V$55)),""),"") -> 6 | V28: 1 | W28: 1
A29: 5 | B29: 45876 | C29: чт | D29: =77557+16403+38820 -> 132780 | E29: 17 | F29: =IF(AND(E29<>"",E29<>0),D29/E29,"") -> 7810.5882 | G29: 13 | H29: =IF(AND(G29<>"",G29<>0),D29/G29,"") -> 10213.846 | I29: 55 | J29: =IF(AND(G29<>"",G29<>0),E29/G29,"") -> 1.3076923 | K29: 77557 | L29: 16403 | N29: =IF(AND(I29<>"",I29<>0),G29/I29,"") -> 0.23636364 | O29: =D29/P29 -> 1.9928581 | P29: =$I$8*V29*W29/SUMPRODUCT($W$25:$W$53,$V$25:$V$53) -> 66627.923 | Q29: =$I$9*V29*W29/SUMPRODUCT($W$25:$W$53,$V$25:$V$53) -> 11.104654 | R29: =IF($I$12="","",Q29/$I$12) -> 6.5321494 | S29: =IF(W29<>"",IF(D29<>"",D29,($I$8-SUM($S$25:S28))*V29*W29/SUMPRODUCT($W29:$W$55,$V29:$V$55)),"") -> 132780 | T29: =IF(W29<>"",IF(E29<>"",E29,($I$9-SUM($T$25:T28))*V29*W29/SUMPRODUCT($W29:$W$55,$V29:$V$55)),"") -> 17 | U29: =IF(W29<>"",IF($I$12<>"",IF(G29<>"",G29,($I$9/$I$12-SUM($U$25:U28))*V29*W29/SUMPRODUCT($W29:$W$55,$V29:$V$55)),""),"") -> 13 | V29: 1 | W29: 1
A30: 6 | B30: 45877 | C30: пт | D30: =7492+38149 -> 45641 | E30: 7 | F30: =IF(AND(E30<>"",E30<>0),D30/E30,"") -> 6520.1429 | G30: 4 | H30: =IF(AND(G30<>"",G30<>0),D30/G30,"") -> 11410.25 | I30: 40 | J30: =IF(AND(G30<>"",G30<>0),E30/G30,"") -> 1.75 | K30: 7492 | M30: 13290 | N30: =IF(AND(I30<>"",I30<>0),G30/I30,"") -> 0.1 | O30: =D30/P30 -> 0.68501309 | P30: =$I$8*V30*W30/SUMPRODUCT($W$25:$W$53,$V$25:$V$53) -> 66627.923 | Q30: =$I$9*V30*W30/SUMPRODUCT($W$25:$W$53,$V$25:$V$53) -> 11.104654 | R30: =IF($I$12="","",Q30/$I$12) -> 6.5321494 | S30: =IF(W30<>"",IF(D30<>"",D30,($I$8-SUM($S$25:S29))*V30*W30/SUMPRODUCT($W30:$W$55,$V30:$V$55)),"") -> 45641 | T30: =IF(W30<>"",IF(E30<>"",E30,($I$9-SUM($T$25:T29))*V30*W30/SUMPRODUCT($W30:$W$55,$V30:$V$55)),"") -> 7 | U30: =IF(W30<>"",IF($I$12<>"",IF(G30<>"",G30,($I$9/$I$12-SUM($U$25:U29))*V30*W30/SUMPRODUCT($W30:$W$55,$V30:$V$55)),""),"") -> 4 | V30: 1 | W30: 1
A31: 7 | B31: 45878 | C31: сб | D31: 28859 | E31: 6 | F31: =IF(AND(E31<>"",E31<>0),D31/E31,"") -> 4809.8333 | G31: 4 | H31: =IF(AND(G31<>"",G31<>0),D31/G31,"") -> 7214.75 | I31: 30 | J31: =IF(AND(G31<>"",G31<>0),E31/G31,"") -> 1.5 | N31: =IF(AND(I31<>"",I31<>0),G31/I31,"") -> 0.13333333 | O31: =D31/P31 -> 0.43313672 | P31: =$I$8*V31*W31/SUMPRODUCT($W$25:$W$53,$V$25:$V$53) -> 66627.923 | Q31: =$I$9*V31*W31/SUMPRODUCT($W$25:$W$53,$V$25:$V$53) -> 11.104654 | R31: =IF($I$12="","",Q31/$I$12) -> 6.5321494 | S31: =IF(W31<>"",IF(D31<>"",D31,($I$8-SUM($S$25:S30))*V31*W31/SUMPRODUCT($W31:$W$55,$V31:$V$55)),"") -> 28859 | T31: =IF(W31<>"",IF(E31<>"",E31,($I$9-SUM($T$25:T30))*V31*W31/SUMPRODUCT($W31:$W$55,$V31:$V$55)),"") -> 6 | U31: =IF(W31<>"",IF($I$12<>"",IF(G31<>"",G31,($I$9/$I$12-SUM($U$25:U30))*V31*W31/SUMPRODUCT($W31:$W$55,$V31:$V$55)),""),"") -> 4 | V31: 1 | W31: 1
A32: 8 | B32: 45879 | C32: вс | D32: 33665 | E32: 8 | F32: =IF(AND(E32<>"",E32<>0),D32/E32,"") -> 4208.125 | G32: 4 | H32: =IF(AND(G32<>"",G32<>0),D32/G32,"") -> 8416.25 | I32: 30 | J32: =IF(AND(G32<>"",G32<>0),E32/G32,"") -> 2 | N32: =IF(AND(I32<>"",I32<>0),G32/I32,"") -> 0.13333333 | O32: =D32/P32 -> 0.50526864 | P32: =$I$8*V32*W32/SUMPRODUCT($W$25:$W$53,$V$25:$V$53) -> 66627.923 | Q32: =$I$9*V32*W32/SUMPRODUCT($W$25:$W$53,$V$25:$V$53) -> 11.104654 | R32: =IF($I$12="","",Q32/$I$12) -> 6.5321494 | S32: =IF(W32<>"",IF(D32<>"",D32,($I$8-SUM($S$25:S31))*V32*W32/SUMPRODUCT($W32:$W$55,$V32:$V$55)),"") -> 33665 | T32: =IF(W32<>"",IF(E32<>"",E32,($I$9-SUM($T$25:T31))*V32*W32/SUMPRODUCT($W32:$W$55,$V32:$V$55)),"") -> 8 | U32: =IF(W32<>"",IF($I$12<>"",IF(G32<>"",G32,($I$9/$I$12-SUM($U$25:U31))*V32*W32/SUMPRODUCT($W32:$W$55,$V32:$V$55)),""),"") -> 4 | V32: 1 | W32: 1
A33: 9 | B33: 45880 | C33: пн | D33: =38721+6992 -> 45713 | E33: 11 | F33: =IF(AND(E33<>"",E33<>0),D33/E33,"") -> 4155.7273 | G33: 5 | H33: =IF(AND(G33<>"",G33<>0),D33/G33,"") -> 9142.6 | I33: 30 | J33: =IF(AND(G33<>"",G33<>0),E33/G33,"") -> 2.2 | K33: 6992 | N33: =IF(AND(I33<>"",I33<>0),G33/I33,"") -> 0.16666667 | O33: =D33/P33 -> 0.68609372 | P33: =$I$8*V33*W33/SUMPRODUCT($W$25:$W$53,$V$25:$V$53) -> 66627.923 | Q33: =$I$9*V33*W33/SUMPRODUCT($W$25:$W$53,$V$25:$V$53) -> 11.104654 | R33: =IF($I$12="","",Q33/$I$12) -> 6.5321494 | S33: =IF(W33<>"",IF(D33<>"",D33,($I$8-SUM($S$25:S32))*V33*W33/SUMPRODUCT($W33:$W$55,$V33:$V$55)),"") -> 45713 | T33: =IF(W33<>"",IF(E33<>"",E33,($I$9-SUM($T$25:T32))*V33*W33/SUMPRODUCT($W33:$W$55,$V33:$V$55)),"") -> 11 | U33: =IF(W33<>"",IF($I$12<>"",IF(G33<>"",G33,($I$9/$I$12-SUM($U$25:U32))*V33*W33/SUMPRODUCT($W33:$W$55,$V33:$V$55)),""),"") -> 5 | V33: 1 | W33: 1
A34: 10 | B34: 45881 | C34: вт | D34: =79259+14803 -> 94062 | E34: 19 | F34: =IF(AND(E34<>"",E34<>0),D34/E34,"") -> 4950.6316 | G34: 11 | H34: =IF(AND(G34<>"",G34<>0),D34/G34,"") -> 8551.0909 | I34: 55 | J34: =IF(AND(G34<>"",G34<>0),E34/G34,"") -> 1.7272727 | L34: 14803 | N34: =IF(AND(I34<>"",I34<>0),G34/I34,"") -> 0.2 | O34: =D34/P34 -> 1.4117504 | P34: =$I$8*V34*W34/SUMPRODUCT($W$25:$W$53,$V$25:$V$53) -> 66627.923 | Q34: =$I$9*V34*W34/SUMPRODUCT($W$25:$W$53,$V$25:$V$53) -> 11.104654 | R34: =IF($I$12="","",Q34/$I$12) -> 6.5321494 | S34: =IF(W34<>"",IF(D34<>"",D34,($I$8-SUM($S$25:S33))*V34*W34/SUMPRODUCT($W34:$W$55,$V34:$V$55)),"") -> 94062 | T34: =IF(W34<>"",IF(E34<>"",E34,($I$9-SUM($T$25:T33))*V34*W34/SUMPRODUCT($W34:$W$55,$V34:$V$55)),"") -> 19 | U34: =IF(W34<>"",IF($I$12<>"",IF(G34<>"",G34,($I$9/$I$12-SUM($U$25:U33))*V34*W34/SUMPRODUCT($W34:$W$55,$V34:$V$55)),""),"") -> 11 | V34: 1 | W34: 1
A35: 11 | B35: 45882 | C35: ср | D35: 99166 | E35: 18 | F35: =IF(AND(E35<>"",E35<>0),D35/E35,"") -> 5509.2222 | G35: 7 | H35: =IF(AND(G35<>"",G35<>0),D35/G35,"") -> 14166.571 | I35: 40 | J35: =IF(AND(G35<>"",G35<>0),E35/G35,"") -> 2.5714286 | K35: 21180 | L35: 9903 | N35: =IF(AND(I35<>"",I35<>0),G35/I35,"") -> 0.175 | O35: =D35/P35 -> 1.488355 | P35: =$I$8*V35*W35/SUMPRODUCT($W$25:$W$53,$V$25:$V$53) -> 66627.923 | Q35: =$I$9*V35*W35/SUMPRODUCT($W$25:$W$53,$V$25:$V$53) -> 11.104654 | R35: =IF($I$12="","",Q35/$I$12) -> 6.5321494 | S35: =IF(W35<>"",IF(D35<>"",D35,($I$8-SUM($S$25:S34))*V35*W35/SUMPRODUCT($W35:$W$55,$V35:$V$55)),"") -> 99166 | T35: =IF(W35<>"",IF(E34<>"",E34,($I$9-SUM($T$25:T34))*V35*W35/SUMPRODUCT($W35:$W$55,$V35:$V$55)),"") -> 19 | U35: =IF(W35<>"",IF($I$12<>"",IF(G35<>"",G35,($I$9/$I$12-SUM($U$25:U34))*V35*W35/SUMPRODUCT($W35:$W$55,$V35:$V$55)),""),"") -> 7 | V35: 1 | W35: 1
A36: 12 | B36: 45884 | C36: пт | D36: =39885+19598 -> 59483 | E36: 8 | F36: 7435 | G36: 5 | H36: =IF(AND(G36<>"",G36<>0),D36/G36,"") -> 11896.6 | I36: 50 | J36: =IF(AND(G36<>"",G36<>0),E36/G36,"") -> 1.6 | K36: 19598 | N36: =IF(AND(I36<>"",I36<>0),G36/I36,"") -> 0.1 | O36: =D36/P36 -> 0.89276383 | P36: =$I$8*V36*W36/SUMPRODUCT($W$25:$W$53,$V$25:$V$53) -> 66627.923 | Q36: =$I$9*V36*W36/SUMPRODUCT($W$25:$W$53,$V$25:$V$53) -> 11.104654 | R36: =IF($I$12="","",Q36/$I$12) -> 6.5321494 | S36: =IF(W36<>"",IF(D36<>"",D36,($I$8-SUM($S$25:S35))*V36*W36/SUMPRODUCT($W36:$W$55,$V36:$V$55)),"") -> 59483 | T36: =IF(W36<>"",IF(E36<>"",E36,($I$9-SUM($T$25:T35))*V36*W36/SUMPRODUCT($W36:$W$55,$V36:$V$55)),"") -> 8 | U36: =IF(W36<>"",IF($I$12<>"",IF(G36<>"",G36,($I$9/$I$12-SUM($U$25:U35))*V36*W36/SUMPRODUCT($W36:$W$55,$V36:$V$55)),""),"") -> 5 | V36: 1 | W36: 1
A37: 13 | B37: 45885 | C37: сб | D37: 74558 | E37: 15 | F37: =IF(AND(E37<>"",E37<>0),D37/E37,"") -> 4970.5333 | G37: 6 | H37: =IF(AND(G37<>"",G37<>0),D37/G37,"") -> 12426.333 | I37: 30 | J37: =IF(AND(G37<>"",G37<>0),E37/G37,"") -> 2.5 | N37: =IF(AND(I37<>"",I37<>0),G37/I37,"") -> 0.2 | O37: =D37/P37 -> 1.1190203 | P37: =$I$8*V37*W37/SUMPRODUCT($W$25:$W$53,$V$25:$V$53) -> 66627.923 | Q37: =$I$9*V37*W37/SUMPRODUCT($W$25:$W$53,$V$25:$V$53) -> 11.104654 | R37: =IF($I$12="","",Q37/$I$12) -> 6.5321494 | S37: =IF(W37<>"",IF(D37<>"",D37,($I$8-SUM($S$25:S36))*V37*W37/SUMPRODUCT($W37:$W$55,$V37:$V$55)),"") -> 74558 | T37: =IF(W37<>"",IF(E37<>"",E37,($I$9-SUM($T$25:T36))*V37*W37/SUMPRODUCT($W37:$W$55,$V37:$V$55)),"") -> 15 | U37: =IF(W37<>"",IF($I$12<>"",IF(G37<>"",G37,($I$9/$I$12-SUM($U$25:U36))*V37*W37/SUMPRODUCT($W37:$W$55,$V37:$V$55)),""),"") -> 6 | V37: 1 | W37: 1
A38: 14 | B38: 45886 | C38: вс | D38: 21063 | E38: 5 | F38: =IF(AND(E38<>"",E38<>0),D38/E38,"") -> 4212.6 | G38: 4 | H38: =IF(AND(G38<>"",G38<>0),D38/G38,"") -> 5265.75 | I38: 35 | J38: =IF(AND(G38<>"",G38<>0),E38/G38,"") -> 1.25 | N38: =IF(AND(I38<>"",I38<>0),G38/I38,"") -> 0.11428571 | O38: =D38/P38 -> 0.31612872 | P38: =$I$8*V38*W38/SUMPRODUCT($W$25:$W$53,$V$25:$V$53) -> 66627.923 | Q38: =$I$9*V38*W38/SUMPRODUCT($W$25:$W$53,$V$25:$V$53) -> 11.104654 | R38: =IF($I$12="","",Q38/$I$12) -> 6.5321494 | S38: =IF(W38<>"",IF(D38<>"",D38,($I$8-SUM($S$25:S37))*V38*W38/SUMPRODUCT($W38:$W$55,$V38:$V$55)),"") -> 21063 | T38: =IF(W38<>"",IF(E38<>"",E38,($I$9-SUM($T$25:T37))*V38*W38/SUMPRODUCT($W38:$W$55,$V38:$V$55)),"") -> 5 | U38: =IF(W38<>"",IF($I$12<>"",IF(G38<>"",G38,($I$9/$I$12-SUM($U$25:U37))*V38*W38/SUMPRODUCT($W38:$W$55,$V38:$V$55)),""),"") -> 4 | V38: 1 | W38: 1
A39: 15 | B39: 45887 | C39: пн | D39: =21304+39632 -> 60936 | E39: 10 | F39: =IF(AND(E39<>"",E39<>0),D39/E39,"") -> 6093.6 | G39: 6 | H39: =IF(AND(G39<>"",G39<>0),D39/G39,"") -> 10156 | I39: 40 | J39: =IF(AND(G39<>"",G39<>0),E39/G39,"") -> 1.6666667 | L39: 21304 | N39: =IF(AND(I39<>"",I39<>0),G39/I39,"") -> 0.15 | O39: =D39/P39 -> 0.9145715 | P39: =$I$8*V39*W39/SUMPRODUCT($W$25:$W$53,$V$25:$V$53) -> 66627.923 | Q39: =$I$9*V39*W39/SUMPRODUCT($W$25:$W$53,$V$25:$V$53) -> 11.104654 | R39: =IF($I$12="","",Q39/$I$12) -> 6.5321494 | S39: =IF(W39<>"",IF(D39<>"",D39,($I$8-SUM($S$25:S38))*V39*W39/SUMPRODUCT($W39:$W$55,$V39:$V$55)),"") -> 60936 | T39: =IF(W39<>"",IF(E39<>"",E39,($I$9-SUM($T$25:T38))*V39*W39/SUMPRODUCT($W39:$W$55,$V39:$V$55)),"") -> 10 | U39: =IF(W39<>"",IF($I$12<>"",IF(G39<>"",G39,($I$9/$I$12-SUM($U$25:U38))*V39*W39/SUMPRODUCT($W39:$W$55,$V39:$V$55)),""),"") -> 6 | V39: 1 | W39: 1
A40: 16 | B40: 45888 | C40: вт | D40: =41975+2203+69525 -> 113703 | E40: 18 | F40: =IF(AND(E40<>"",E40<>0),D40/E40,"") -> 6316.8333 | G40: 11 | H40: =IF(AND(G40<>"",G40<>0),D40/G40,"") -> 10336.636 | I40: 75 | J40: =IF(AND(G40<>"",G40<>0),E40/G40,"") -> 1.6363636 | K40: 41975 | L40: 2203 | N40: =IF(AND(I40<>"",I40<>0),G40/I40,"") -> 0.14666667 | O40: =D40/P40 -> 1.7065368 | P40: =$I$8*V40*W40/SUMPRODUCT($W$25:$W$53,$V$25:$V$53) -> 66627.923 | Q40: =$I$9*V40*W40/SUMPRODUCT($W$25:$W$53,$V$25:$V$53) -> 11.104654 | R40: =IF($I$12="","",Q40/$I$12) -> 6.5321494 | S40: =IF(W40<>"",IF(D40<>"",D40,($I$8-SUM($S$25:S39))*V40*W40/SUMPRODUCT($W40:$W$55,$V40:$V$55)),"") -> 113703 | T40: =IF(W40<>"",IF(E40<>"",E40,($I$9-SUM($T$25:T39))*V40*W40/SUMPRODUCT($W40:$W$55,$V40:$V$55)),"") -> 18 | U40: =IF(W40<>"",IF($I$12<>"",IF(G40<>"",G40,($I$9/$I$12-SUM($U$25:U39))*V40*W40/SUMPRODUCT($W40:$W$55,$V40:$V$55)),""),"") -> 11 | V40: 1 | W40: 1
A41: 17 | B41: 45889 | C41: ср | D41: =9990+15103+26550 -> 51643 | E41: 9 | F41: =IF(AND(E41<>"",E41<>0),D41/E41,"") -> 5738.1111 | G41: 6 | H41: =IF(AND(G41<>"",G41<>0),D41/G41,"") -> 8607.1667 | I41: 49 | J41: =IF(AND(G41<>"",G41<>0),E41/G41,"") -> 1.5 | K41: 9990 | L41: 15103 | N41: =IF(AND(I41<>"",I41<>0),G41/I41,"") -> 0.12244898 | O41: =D41/P41 -> 0.77509545 | P41: =$I$8*V41*W41/SUMPRODUCT($W$25:$W$53,$V$25:$V$53) -> 66627.923 | Q41: =$I$9*V41*W41/SUMPRODUCT($W$25:$W$53,$V$25:$V$53) -> 11.104654 | R41: =IF($I$12="","",Q41/$I$12) -> 6.5321494 | S41: =IF(W41<>"",IF(D41<>"",D41,($I$8-SUM($S$25:S40))*V41*W41/SUMPRODUCT($W41:$W$55,$V41:$V$55)),"") -> 51643 | T41: =IF(W41<>"",IF(E41<>"",E41,($I$9-SUM($T$25:T40))*V41*W41/SUMPRODUCT($W41:$W$55,$V41:$V$55)),"") -> 9 | U41: =IF(W41<>"",IF($I$12<>"",IF(G41<>"",G41,($I$9/$I$12-SUM($U$25:U40))*V41*W41/SUMPRODUCT($W41:$W$55,$V41:$V$55)),""),"") -> 6 | V41: 1 | W41: 1
A42: 18 | B42: 45891 | C42: пт | D42: =14990+87860 -> 102850 | E42: 17 | F42: =IF(AND(E42<>"",E42<>0),D42/E42,"") -> 6050 | G42: 3 | H42: =IF(AND(G42<>"",G42<>0),D42/G42,"") -> 34283.333 | I42: 32 | J42: =IF(AND(G42<>"",G42<>0),E42/G42,"") -> 5.6666667 | K42: 14990 | N42: =IF(AND(I42<>"",I42<>0),G42/I42,"") -> 0.09375 | O42: =D42/P42 -> 1.5436471 | P42: =$I$8*V42*W42/SUMPRODUCT($W$25:$W$53,$V$25:$V$53) -> 66627.923 | Q42: =$I$9*V42*W42/SUMPRODUCT($W$25:$W$53,$V$25:$V$53) -> 11.104654 | R42: =IF($I$12="","",Q42/$I$12) -> 6.5321494 | S42: =IF(W42<>"",IF(D42<>"",D42,($I$8-SUM($S$25:S41))*V42*W42/SUMPRODUCT($W42:$W$55,$V42:$V$55)),"") -> 102850 | T42: =IF(W42<>"",IF(E42<>"",E42,($I$9-SUM($T$25:T41))*V42*W42/SUMPRODUCT($W42:$W$55,$V42:$V$55)),"") -> 17 | U42: =IF(W42<>"",IF($I$12<>"",IF(G42<>"",G42,($I$9/$I$12-SUM($U$25:U41))*V42*W42/SUMPRODUCT($W42:$W$55,$V42:$V$55)),""),"") -> 3 | V42: 1 | W42: 1
...

Sheet Уразгильдеева Е. Р. 
B1: =TODAY()-1 -> 45909
B2: (отчетная дата) | J2: ЕЖЕДНЕВНЫЙ ОТЧЕТ О ПРОДАЖАХ
B3: Осталось до выполнения плана!!! | J3: =График!B28 -> Уразгильдеева Екатерина
C4: =I8-D50 -> 503066.38 | E4: =IF(I8<>0, C4/I8, 0) -> 0.34509342
F6: Целевые показатели
F7: Показатель | I7: План | J7: Факт | K7: % выполнения | L7: Прогноз выполнения | M7: % выполнения по прогнозу | N7: Отклонение | O7: Факт аналогичного месяца прошлого года | P7: Отклонение LFL
F8: Выручка | I8: ='Ялта, Ленина, 18'!I8/График!AJ31*График!AJ28 -> 1457768.7 | J8: =D50 -> 954702.3 | K8: =IF(AND(I8<>"",I8<>0,J8<>""),J8/I8,"") -> 0.65490658 | L8: =IF(SUMIF($D$25:$D$49,">=0",$P$25:$P$49)<>0,I8*D50/SUMIF($D$25:$D$49,">=0",$P$25:$P$49),0) -> 954702.3 | M8: =IF(AND(I8<>"",I8<>0,L8<>"",L8<>0),L8/I8,"") -> 0.65490658 | N8: =IF(AND(J8<>0, J8<>"", I8<>0, I8<>""), L8-I8, "") -> -503066.38 | P8: =IF(AND(O8<>"", O8<>0, L8<>"", L8<>0), -O8+L8, "") | Q8: =IF(AND(P8<>"", P8<>0, O8<>0, O8<>""), P8/O8, "")
F9: Кол-во изделий | I9: =I8/I11 -> 242.96145 | J9: =E50 -> 144 | K9: =IF(AND(I9<>"", I9<>0, J9<>""), J9/I9, "") -> 0.59268663 | L9: =J9 -> 144 | M9: =IF(AND(I9<>"",I9<>0,L9<>"",L9<>0),L9/I9,"") -> 0.59268663 | N9: =IF(AND(J9<>0, J9<>"", I9<>0, I9<>""), L9-I9, "") -> -98.961446 | O9: =O8/O11 -> #DIV/0! | P9: =IF(AND(O9<>"", O9<>0, L9<>"", L9<>0), -O9+L9, "") -> #DIV/0! | Q9: =IF(AND(P9<>"", P9<>0, O9<>0, O9<>""), P9/O9, "") -> #DIV/0!
F10: Средний чек | I10: =I11*I12 -> 10200 | J10: =H50 -> 10491.234 | K10: =IF(AND(I10<>"", I10<>0, J10<>""), J10/I10, "") -> 1.0285524 | L10: =J10 -> 10491.234 | M10: =IF(AND(I10<>"",I10<>0,L10<>"",L10<>0),L10/I10,"") -> 1.0285524 | N10: =IF(AND(J10<>0, J10<>"", I10<>0, I10<>""), L10-I10, "") -> 291.23407 | O10: =O11*O12 -> 0 | P10: =IF(AND(O10<>"", O10<>0, L10<>"", L10<>0), -O10+L10, "") | Q10: =IF(AND(P10<>"", P10<>0, O10<>0, O10<>""), P10/O10, "") | S10: IS | V10: =M23 -> Agafi
F11: Средняя стоимость изделия | I11: ='Ялта, Ленина, 18'!I11 -> 6000 | J11: =F50 -> 6629.8771 | K11: =IF(AND(I11<>"", I11<>0, J11<>""), J11/I11, "") -> 1.1049795 | L11: =J11 -> 6629.8771 | M11: =IF(AND(I11<>"",I11<>0,L11<>"",L11<>0),L11/I11,"") -> 1.1049795 | N11: =IF(AND(J11<>0, J11<>"", I11<>0, I11<>""), L11-I11, "") -> 629.87708 | P11: =IF(AND(O11<>"", O11<>0, L11<>"", L11<>0), -O11+L11, "") | Q11: =IF(AND(P11<>"", P11<>0, O11<>0, O11<>""), P11/O11, "")
F12: Длина чека | I12: ='Ялта, Ленина, 18'!I12 -> 1.7 | J12: =J50 -> 1.5824176 | K12: =IF(AND(I12<>"", I12<>0, J12<>""), J12/I12, "") -> 0.93083387 | L12: =J12 -> 1.5824176 | M12: =IF(AND(I12<>"",I12<>0,L12<>"",L12<>0),L12/I12,"") -> 0.93083387 | N12: =IF(AND(J12<>0, J12<>"", I12<>0, I12<>""), L12-I12, "") -> -0.11758242 | P12: =IF(AND(O12<>"", O12<>0, L12<>"", L12<>0), -O12+L12, "") | Q12: =IF(AND(P12<>"", P12<>0, O12<>0, O12<>""), P12/O12, "") | S12: ='Ялта, Ленина, 18'!S12*График!AJ28/График!AJ31 -> 235716.27 | T12: =L50 -> 153749 | U12: =S12-T12 -> 81967.273 | V12: ='Ялта, Ленина, 18'!V12/График!AJ31*График!AJ28 -> 142670.38 | W12: =M50 -> 54842 | X12: =V12-W12 -> 87828.376
F13: Кол-во чеков | I13: =IF(I12<>0, I9/I12, "") -> 142.9185 | J13: =G50 -> 91 | K13: =IF(AND(I13<>"", I13<>0, J13<>""), J13/I13, "") -> 0.63672654 | L13: =J13 -> 91 | M13: =IF(AND(I13<>"",I13<>0,L13<>"",L13<>0),L13/I13,"") -> 0.63672654 | N13: =IF(AND(J13<>0, J13<>"", I13<>0, I13<>""), L13-I13, "") -> -51.918498 | P13: =IF(AND(O13<>"", O13<>0, L13<>"", L13<>0), -O13+L13, "") | Q13: =IF(AND(P13<>"", P13<>0, O13<>0, O13<>""), P13/O13, "") | S13: =T12/S12 -> 0.65226299 | T13: =S13/J14*I14 -> 0.65226299 | V13: =W12/V12 -> 0.38439655 | W13: =V13/J14*I14 -> 0.38439655
F14: Кол-во смен план/отработано | I14: =График!AI28 -> 18 | J14: 18 | K14: =IF(AND(I14<>"", I14<>0, J14<>""), J14/I14, "") -> 1 | L14: =I14 -> 18 | M14: =IF(AND(I14<>"",I14<>0,L14<>"",L14<>0),L14/I14,"") -> 1 | N14: =IF(AND(J14<>0, J14<>"", I14<>0, I14<>""), L14-I14, "") -> 0 | P14: =IF(AND(O14<>"", O14<>0, L14<>"", L14<>0), -O14+L14, "") | Q14: =IF(AND(P14<>"", P14<>0, O14<>0, O14<>""), P14/O14, "")
F15: Средние продажи в смену | I15: ='Ялта, Ленина, 18'!I15 -> 151618.06 | J15: =J8/J14 -> 53039.017 | K15: =IF(AND(I15<>"", I15<>0, J15<>""), J15/I15, "") -> 0.3498199 | L15: =J15 -> 53039.017 | M15: =IF(AND(I15<>"",I15<>0,L15<>"",L15<>0),L15/I15,"") -> 0.3498199 | N15: =IF(AND(J15<>0, J15<>"", I15<>0, I15<>""), L15-I15, "") -> -98579.048 | P15: =IF(AND(O15<>"", O15<>0, L15<>"", L15<>0), -O15+L15, "") | Q15: =IF(AND(P15<>"", P15<>0, O15<>0, O15<>""), P15/O15, "")
