Workbook
Name маг: NA()

Sheet Ялта, Ленина, 18
B1: =TODAY()-1 -> 45696
B2: (отчетная дата)
C3: Осталось до выполнения плана!!! | I3: =График!B3 -> ул. Набережная Ленина, 18
C4: =I8-D56 -> 229032.36 | E4: =IF(I8<>0, C4/I8, 0) -> 0.1272402
F6: Целевые показатели
F7: Показатель | I7: План | J7: Факт | K7: % выполнения | L7: Прогноз выполнения | M7: % выполнения по прогнозу | N7: Отклонение | O7: Факт аналогичного месяца прошлого года | P7: Отклонение LFL
F8: Выручка | I8: 1800000 | J8: =D56 -> 1570967.6 | K8: =IF(AND(I8<>"", I8<>0, J8<>""), J8/I8, "") -> 0.8727598 | L8: =IF(SUMIF($D$25:$D$55,">=0",$P$25:$P$55)<>0,I8*D56/SUMIF($D$25:$D$55,">=0",$P$25:$P$55),0) -> 1570967.6 | M8: =IF(AND(I8<>"", I8<>0, L8<>"", L8<>0), L8/I8, "") -> 0.8727598 | N8: =IF(AND(J8<>0, J8<>"", I8<>0, I8<>""), L8-I8, "") -> -229032.36 | P8: =IF(AND(O8<>"", O8<>0, L8<>"", L8<>0), -O8+L8, "") | Q8: =IF(AND(P8<>"", P8<>0, O8<>0, O8<>""), P8/O8, "")
F9: Кол-во изделий | I9: =I8/I11 -> 487.80488 | J9: =E56 -> 409 | K9: =IF(AND(I9<>"", I9<>0, J9<>""), J9/I9, "") -> 0.83845 | L9: =IF(SUMIF($E$25:$E$55, ">=0", $Q$25:$Q$55)<>0, I9*E56/SUMIF($E$25:$E$55, ">=0", $Q$25:$Q$55), 0) -> 409 | M9: =IF(AND(I9<>"", I9<>0, L9<>"", L9<>0), L9/I9, "") -> 0.83845 | N9: =IF(AND(J9<>0, J9<>"", I9<>0, I9<>""), L9-I9, "") -> -78.804878 | O9: =O8/O11 -> #DIV/0! | P9: =IF(AND(O9<>"", O9<>0, L9<>"", L9<>0), -O9+L9, "") -> #DIV/0! | Q9: =IF(AND(P9<>"", P9<>0, O9<>0, O9<>""), P9/O9, "") -> #DIV/0!
F10: Средний чек | I10: =I11*I12 -> 5904 | J10: =H56 -> 7777.0675 | K10: =IF(AND(I10<>"", I10<>0, J10<>""), J10/I10, "") -> 1.317254 | L10: =J10 -> 7777.0675 | M10: =IF(AND(I10<>"", I10<>0, L10<>"", L10<>0), L10/I10, "") -> 1.317254 | N10: =IF(AND(J10<>0, J10<>"", I10<>0, I10<>""), L10-I10, "") -> 1873.0675 | O10: =O11*O12 -> 0 | P10: =IF(AND(O10<>"", O10<>0, L10<>"", L10<>0), -O10+L10, "") | Q10: =IF(AND(P10<>"", P10<>0, O10<>0, O10<>""), P10/O10, "")
F11: Средняя стоимость изделия | I11: 3690 | J11: =F56 -> 3840.9967 | K11: =IF(AND(I11<>"", I11<>0, J11<>""), J11/I11, "") -> 1.0409205 | L11: =IF(L9>0, L8/L9, "") -> 3840.9967 | M11: =IF(AND(I11<>"", I11<>0, L11<>"", L11<>0), L11/I11, "") -> 1.0409205 | N11: =IF(AND(J11<>0, J11<>"", I11<>0, I11<>""), L11-I11, "") -> 150.99667 | P11: =IF(AND(O11<>"", O11<>0, L11<>"", L11<>0), -O11+L11, "") | Q11: =IF(AND(P11<>"", P11<>0, O11<>0, O11<>""), P11/O11, "")
F12: Длина чека | I12: 1.6 | J12: =J56 -> 2.0247525 | K12: =IF(AND(I12<>"", I12<>0, J12<>""), J12/I12, "") -> 1.2654703 | L12: =J12 -> 2.0247525 | M12: =IF(AND(I12<>"", I12<>0, L12<>"", L12<>0), L12/I12, "") -> 1.2654703 | N12: =IF(AND(J12<>0, J12<>"", I12<>0, I12<>""), L12-I12, "") -> 0.42475248 | P12: =IF(AND(O12<>"", O12<>0, L12<>"", L12<>0), -O12+L12, "") | Q12: =IF(AND(P12<>"", P12<>0, O12<>0, O12<>""), P12/O12, "")
F13: Кол-во чеков | I13: =I17*I20 -> 0 | J13: =G56 -> 202 | K13: =IF(AND(I13<>"", I13<>0, J13<>""), J13/I13, "") | L13: =IF(SUMIF($G$25:$G$55, ">=0", $R$25:$R$55)<>0, I13*G56/SUMIF($G$25:$G$55, ">=0", $R$25:$R$55), "") -> 0 | M13: =IF(AND(I13<>"", I13<>0, L13<>"", L13<>0), L13/I13, "") | N13: =IF(AND(J13<>0, J13<>"", I13<>0, I13<>""), L13-I13, "") | P13: =IF(AND(O13<>"", O13<>0, L13<>"", L13<>0), -O13+L13, "") | Q13: =IF(AND(P13<>"", P13<>0, O13<>0, O13<>""), P13/O13, "")
F14: Кол-во смен | I14: 30 | J14: 30 | K14: =IF(AND(I14<>"", I14<>0, J14<>""), J14/I14, "") -> 1 | L14: =IF(SUMIF($D$25:$D$55,">=0",$P$25:$P$55),I56*I8/SUMIF($D$25:$D$55,">=0",$P$25:$P$55),"") -> 0 | M14: =IF(AND(I14<>"", I14<>0, L14<>"", L14<>0), L14/I14, "") | N14: =IF(AND(J14<>0, J14<>"", I14<>0, I14<>""), L14-I14, "") -> -30 | P14: =IF(AND(O14<>"", O14<>0, L14<>"", L14<>0), -O14+L14, "") | Q14: =IF(AND(P14<>"", P14<>0, O14<>0, O14<>""), P14/O14, "")
F15: Средние продажи в смену | I15: =I8/I14 -> 60000 | J15: =J8/J14 -> 52365.588 | K15: =IF(AND(I15<>"", I15<>0, J15<>""), J15/I15, "") -> 0.8727598 | L15: =J15 -> 52365.588 | M15: =IF(AND(I15<>"", I15<>0, L15<>"", L15<>0), L15/I15, "") -> 0.8727598 | N15: =IF(AND(J15<>0, J15<>"", I15<>0, I15<>""), L15-I15, "") -> -7634.412 | P15: =IF(AND(O15<>"", O15<>0, L15<>"", L15<>0), -O15+L15, "") | Q15: =IF(AND(P15<>"", P15<>0, O15<>0, O15<>""), P15/O15, "")
F16: Отставание/Перевыполнение | J16: =J8-I15*J14 -> -229032.36 | K16: =IF(AND(I16<>"", I16<>0, J16<>""), J16/I16, "") | L16: =J16 -> -229032.36 | M16: =IF(AND(I16<>"", I16<>0, L16<>"", L16<>0), L16/I16, "") | N16: =IF(AND(J16<>0, J16<>"", I16<>0, I16<>""), L16-I16, "") | P16: =IF(AND(O16<>"", O16<>0, L16<>"", L16<>0), -O16+L16, "") | Q16: =IF(AND(P16<>"", P16<>0, O16<>0, O16<>""), P16/O16, "") | S16: Подарочные сертификаты
F17: Трафик | J17: =I56 -> 0 | K17: =IF(AND(I17<>"", I17<>0, J17<>""), J17/I17, "") | L17: =J17 -> 0 | M17: =IF(AND(I17<>"", I17<>0, L17<>"", L17<>0), L17/I17, "") | N17: =IF(AND(J17<>0, J17<>"", I17<>0, I17<>""), L17-I17, "") | P17: =IF(AND(O17<>"", O17<>0, L17<>"", L17<>0), -O17+L17, "") | Q17: =IF(AND(P17<>"", P17<>0, O17<>0, O17<>""), P17/O17, "")
K18: =IF(AND(I18<>"", I18<>0, J18<>""), J18/I18, "") | L18: =J18 -> 0 | M18: =IF(AND(I18<>"", I18<>0, L18<>"", L18<>0), L18/I18, "") | N18: =IF(AND(J18<>0, J18<>"", I18<>0, I18<>""), L18-I18, "") | O18: 0 | P18: =IF(AND(O18<>"", O18<>0, L18<>"", L18<>0), -O18+L18, "") | Q18: =IF(AND(P18<>"", P18<>0, O18<>0, O18<>""), P18/O18, "")
J19: =M56 -> 0 | K19: =IF(AND(I19<>"", I19<>0, J19<>""), J19/I19, "") | L19: =J19 -> 0 | M19: =IF(AND(I19<>"", I19<>0, L19<>"", L19<>0), L19/I19, "") | N19: =IF(AND(J19<>0, J19<>"", I19<>0, I19<>""), L19-I19, "") | O19: 0 | P19: =IF(AND(O19<>"", O19<>0, L19<>"", L19<>0), -O19+L19, "") | Q19: =IF(AND(P19<>"", P19<>0, O19<>0, O19<>""), P19/O19, "") | S19: =S18/I16 -> #DIV/0!
F20: Конверсия план/факт | I20: 0.257 | J20: =N56 | K20: =J20/I20 -> #VALUE! | L20: =IF(AND(K8<>0, I14<>0, I56<>0), (I56*N56+(I56/K8-I56)*I20)/(I56/K8), 0) -> 0 | M20: =IF(AND(I20<>"", I20<>0, L20<>"", L20<>0), L20/I20, "") | N20: =IF(AND(J20<>0, J20<>"", I20<>0, I20<>""), L20-I20, "") | P20: =IF(AND(O20<>"", O20<>0, L20<>"", L20<>0), -O20+L20, "") | Q20: =IF(AND(P20<>"", P20<>0, O20<>0, O20<>""), P20/O20, "")
A22: Факт продаж за месяц | O22: % выполнения дневного плана | P22: Раcпределение плана по дням
A23: Сотрудник | B23: Дата | C23: День недели | D23: Выручка (руб) | E23: Кол-во единиц (шт.) | F23: Средняя стоимость изделия (руб.) | G23: Количество чеков (шт.) | H23: Средняя сумма чека (руб.) | I23: Трафик | J23: Длина чека (шт.) | K23: Запасной | L23: Запасной | M23: Запасной | N23: Конверсия (%) | P23: выручка, план | Q23: кол-во ед, план | R23: Кол-во чеков, план | S23: выручка, скорректир.план | T23: кол-во ед, скорр. план | U23: кол-во чеков, скорр. план | V23: Коэфф. Дня Недели | W23: Специфика месяца
B24: 1 | C24: 2 | D24: 3 | E24: 4 | F24: 5 | G24: 6 | H24: 7 | I24: 8 | J24: 9 | K24: 10 | L24: 11 | M24: 12 | N24: 13 | P24: 1 | Q24: 2 | R24: 3 | S24: 4 | T24: 5 | U24: 6 | V24: 10 | W24: 11
B25: 45658 | C25: ср | F25: =IF(AND(E25<>"",E25<>0),D25/E25,"") | H25: =IF(AND(G25<>"",G25<>0),D25/G25,"") | J25: =IF(AND(G25<>"",G25<>0),E25/G25,"") | N25: =IF(AND(I25<>"",I25<>0),G25/I25,"") | O25: =D25/P25 -> #DIV/0! | P25: =$I$8*V25*W25/SUMPRODUCT($W$25:$W$55,$V$25:$V$55) -> 0 | Q25: =$I$9*V25*W25/SUMPRODUCT($W$25:$W$55,$V$25:$V$55) -> 0 | R25: =IF($I$12="","",Q25/$I$12) -> 0 | S25: =IF(D25<>"",D25,P25) -> 0 | T25: =IF(E25<>"",E25,Q25) -> 0 | U25: =IF(G25<>"",G25,R25) -> 0
A26: Кекош, Орешникова | B26: 45659 | C26: чт | D26: 140171.7 | E26: 36 | F26: =IF(AND(E26<>"",E26<>0),D26/E26,"") -> 3893.6583 | G26: 19 | H26: =IF(AND(G26<>"",G26<>0),D26/G26,"") -> 7377.4579 | J26: =IF(AND(G26<>"",G26<>0),E26/G26,"") -> 1.8947368 | N26: =IF(AND(I26<>"",I26<>0),G26/I26,"") | O26: =D26/P26 -> 1.4271339 | P26: =$I$8*V26*W26/SUMPRODUCT($W$25:$W$55,$V$25:$V$55) -> 98219.022 | Q26: =$I$9*V26*W26/SUMPRODUCT($W$25:$W$55,$V$25:$V$55) -> 26.617621 | R26: =IF($I$12="","",Q26/$I$12) -> 16.636013 | S26: =IF(W26<>"",IF(D26<>"",D26,($I$8-SUM($S$25:S25))*V26*W26/SUMPRODUCT($W26:$W$55,$V26:$V$55)),"") -> 140171.7 | T26: =IF(W26<>"",IF(E26<>"",E26,($I$9-SUM($T$25:T25))*V26*W26/SUMPRODUCT($W26:$W$55,$V26:$V$55)),"") -> 36 | U26: =IF(W26<>"",IF($I$12<>"",IF(G26<>"",G26,($I$9/$I$12-SUM($U$25:U25))*V26*W26/SUMPRODUCT($W26:$W$55,$V26:$V$55)),""),"") -> 19 | V26: 1.2 | W26: 1.2
A27: Кекош, Орешникова | B27: 45660 | C27: пт | D27: 91852 | E27: 25 | F27: =IF(AND(E27<>"",E27<>0),D27/E27,"") -> 3674.08 | G27: 13 | H27: =IF(AND(G27<>"",G27<>0),D27/G27,"") -> 7065.5385 | J27: =IF(AND(G27<>"",G27<>0),E27/G27,"") -> 1.9230769 | N27: =IF(AND(I27<>"",I27<>0),G27/I27,"") | O27: =D27/P27 -> 0.93517526 | P27: =$I$8*V27*W27/SUMPRODUCT($W$25:$W$55,$V$25:$V$55) -> 98219.022 | Q27: =$I$9*V27*W27/SUMPRODUCT($W$25:$W$55,$V$25:$V$55) -> 26.617621 | R27: =IF($I$12="","",Q27/$I$12) -> 16.636013 | S27: =IF(W27<>"",IF(D27<>"",D27,($I$8-SUM($S$25:S26))*V27*W27/SUMPRODUCT($W27:$W$55,$V27:$V$55)),"") -> 91852 | T27: =IF(W27<>"",IF(E27<>"",E27,($I$9-SUM($T$25:T26))*V27*W27/SUMPRODUCT($W27:$W$55,$V27:$V$55)),"") -> 25 | U27: =IF(W27<>"",IF($I$12<>"",IF(G27<>"",G27,($I$9/$I$12-SUM($U$25:U26))*V27*W27/SUMPRODUCT($W27:$W$55,$V27:$V$55)),""),"") -> 13 | V27: 1.2 | W27: 1.2
A28: Кекош, Орешникова | B28: 45661 | C28: сб | D28: 141443 | E28: 34 | F28: =IF(AND(E28<>"",E28<>0),D28/E28,"") -> 4160.0882 | G28: 18 | H28: =IF(AND(G28<>"",G28<>0),D28/G28,"") -> 7857.9444 | J28: =IF(AND(G28<>"",G28<>0),E28/G28,"") -> 1.8888889 | N28: =IF(AND(I28<>"",I28<>0),G28/I28,"") | O28: =D28/P28 -> 1.4400775 | P28: =$I$8*V28*W28/SUMPRODUCT($W$25:$W$55,$V$25:$V$55) -> 98219.022 | Q28: =$I$9*V28*W28/SUMPRODUCT($W$25:$W$55,$V$25:$V$55) -> 26.617621 | R28: =IF($I$12="","",Q28/$I$12) -> 16.636013 | S28: =IF(W28<>"",IF(D28<>"",D28,($I$8-SUM($S$25:S27))*V28*W28/SUMPRODUCT($W28:$W$55,$V28:$V$55)),"") -> 141443 | T28: =IF(W28<>"",IF(E28<>"",E28,($I$9-SUM($T$25:T27))*V28*W28/SUMPRODUCT($W28:$W$55,$V28:$V$55)),"") -> 34 | U28: =IF(W28<>"",IF($I$12<>"",IF(G28<>"",G28,($I$9/$I$12-SUM($U$25:U27))*V28*W28/SUMPRODUCT($W28:$W$55,$V28:$V$55)),""),"") -> 18 | V28: 1.2 | W28: 1.2
A29: Кекош, Орешникова | B29: 45662 | C29: вс | D29: 165681 | E29: 39 | F29: =IF(AND(E29<>"",E29<>0),D29/E29,"") -> 4248.2308 | G29: 11 | H29: =IF(AND(G29<>"",G29<>0),D29/G29,"") -> 15061.909 | J29: =IF(AND(G29<>"",G29<>0),E29/G29,"") -> 3.5454545 | N29: =IF(AND(I29<>"",I29<>0),G29/I29,"") | O29: =D29/P29 -> 1.6868525 | P29: =$I$8*V29*W29/SUMPRODUCT($W$25:$W$55,$V$25:$V$55) -> 98219.022 | Q29: =$I$9*V29*W29/SUMPRODUCT($W$25:$W$55,$V$25:$V$55) -> 26.617621 | R29: =IF($I$12="","",Q29/$I$12) -> 16.636013 | S29: =IF(W29<>"",IF(D29<>"",D29,($I$8-SUM($S$25:S28))*V29*W29/SUMPRODUCT($W29:$W$55,$V29:$V$55)),"") -> 165681 | T29: =IF(W29<>"",IF(E29<>"",E29,($I$9-SUM($T$25:T28))*V29*W29/SUMPRODUCT($W29:$W$55,$V29:$V$55)),"") -> 39 | U29: =IF(W29<>"",IF($I$12<>"",IF(G29<>"",G29,($I$9/$I$12-SUM($U$25:U28))*V29*W29/SUMPRODUCT($W29:$W$55,$V29:$V$55)),""),"") -> 11 | V29: 1.2 | W29: 1.2
A30: Рогалевич, Орешникова | B30: 45663 | C30: пн | D30: 37861 | E30: 12 | F30: =IF(AND(E30<>"",E30<>0),D30/E30,"") -> 3155.0833 | G30: 9 | H30: =IF(AND(G30<>"",G30<>0),D30/G30,"") -> 4206.7778 | J30: =IF(AND(G30<>"",G30<>0),E30/G30,"") -> 1.3333333 | N30: =IF(AND(I30<>"",I30<>0),G30/I30,"") | O30: =D30/P30 -> 0.38547523 | P30: =$I$8*V30*W30/SUMPRODUCT($W$25:$W$55,$V$25:$V$55) -> 98219.022 | Q30: =$I$9*V30*W30/SUMPRODUCT($W$25:$W$55,$V$25:$V$55) -> 26.617621 | R30: =IF($I$12="","",Q30/$I$12) -> 16.636013 | S30: =IF(W30<>"",IF(D30<>"",D30,($I$8-SUM($S$25:S29))*V30*W30/SUMPRODUCT($W30:$W$55,$V30:$V$55)),"") -> 37861 | T30: =IF(W30<>"",IF(E30<>"",E30,($I$9-SUM($T$25:T29))*V30*W30/SUMPRODUCT($W30:$W$55,$V30:$V$55)),"") -> 12 | U30: =IF(W30<>"",IF($I$12<>"",IF(G30<>"",G30,($I$9/$I$12-SUM($U$25:U29))*V30*W30/SUMPRODUCT($W30:$W$55,$V30:$V$55)),""),"") -> 9 | V30: 1.2 | W30: 1.2
A31: Рогалевич | B31: 45664 | C31: вт | D31: 65247 | E31: 16 | F31: =IF(AND(E31<>"",E31<>0),D31/E31,"") -> 4077.9375 | G31: 10 | H31: =IF(AND(G31<>"",G31<>0),D31/G31,"") -> 6524.7 | J31: =IF(AND(G31<>"",G31<>0),E31/G31,"") -> 1.6 | N31: =IF(AND(I31<>"",I31<>0),G31/I31,"") | O31: =D31/P31 -> 0.66430105 | P31: =$I$8*V31*W31/SUMPRODUCT($W$25:$W$55,$V$25:$V$55) -> 98219.022 | Q31: =$I$9*V31*W31/SUMPRODUCT($W$25:$W$55,$V$25:$V$55) -> 26.617621 | R31: =IF($I$12="","",Q31/$I$12) -> 16.636013 | S31: =IF(W31<>"",IF(D31<>"",D31,($I$8-SUM($S$25:S30))*V31*W31/SUMPRODUCT($W31:$W$55,$V31:$V$55)),"") -> 65247 | T31: =IF(W31<>"",IF(E31<>"",E31,($I$9-SUM($T$25:T30))*V31*W31/SUMPRODUCT($W31:$W$55,$V31:$V$55)),"") -> 16 | U31: =IF(W31<>"",IF($I$12<>"",IF(G31<>"",G31,($I$9/$I$12-SUM($U$25:U30))*V31*W31/SUMPRODUCT($W31:$W$55,$V31:$V$55)),""),"") -> 10 | V31: 1.2 | W31: 1.2
A32: Кекош, Рогалевич | B32: 45665 | C32: ср | D32: 101885 | E32: 29 | F32: =IF(AND(E32<>"",E32<>0),D32/E32,"") -> 3513.2759 | G32: 14 | H32: =IF(AND(G32<>"",G32<>0),D32/G32,"") -> 7277.5 | J32: =IF(AND(G32<>"",G32<>0),E32/G32,"") -> 2.0714286 | N32: =IF(AND(I32<>"",I32<>0),G32/I32,"") | O32: =D32/P32 -> 1.0373245 | P32: =$I$8*V32*W32/SUMPRODUCT($W$25:$W$55,$V$25:$V$55) -> 98219.022 | Q32: =$I$9*V32*W32/SUMPRODUCT($W$25:$W$55,$V$25:$V$55) -> 26.617621 | R32: =IF($I$12="","",Q32/$I$12) -> 16.636013 | S32: =IF(W32<>"",IF(D32<>"",D32,($I$8-SUM($S$25:S31))*V32*W32/SUMPRODUCT($W32:$W$55,$V32:$V$55)),"") -> 101885 | T32: =IF(W32<>"",IF(E32<>"",E32,($I$9-SUM($T$25:T31))*V32*W32/SUMPRODUCT($W32:$W$55,$V32:$V$55)),"") -> 29 | U32: =IF(W32<>"",IF($I$12<>"",IF(G32<>"",G32,($I$9/$I$12-SUM($U$25:U31))*V32*W32/SUMPRODUCT($W32:$W$55,$V32:$V$55)),""),"") -> 14 | V32: 1.2 | W32: 1.2
A33: Рогалевич | B33: 45666 | C33: чт | D33: 93262 | E33: 27 | F33: =IF(AND(E33<>"",E33<>0),D33/E33,"") -> 3454.1481 | G33: 5 | H33: =IF(AND(G33<>"",G33<>0),D33/G33,"") -> 18652.4 | J33: =IF(AND(G33<>"",G33<>0),E33/G33,"") -> 5.4 | N33: =IF(AND(I33<>"",I33<>0),G33/I33,"") | O33: =D33/P33 -> 1.3673245 | P33: =$I$8*V33*W33/SUMPRODUCT($W$25:$W$55,$V$25:$V$55) -> 68207.654 | Q33: =$I$9*V33*W33/SUMPRODUCT($W$25:$W$55,$V$25:$V$55) -> 18.484459 | R33: =IF($I$12="","",Q33/$I$12) -> 11.552787 | S33: =IF(W33<>"",IF(D33<>"",D33,($I$8-SUM($S$25:S32))*V33*W33/SUMPRODUCT($W33:$W$55,$V33:$V$55)),"") -> 93262 | T33: =IF(W33<>"",IF(E33<>"",E33,($I$9-SUM($T$25:T32))*V33*W33/SUMPRODUCT($W33:$W$55,$V33:$V$55)),"") -> 27 | U33: =IF(W33<>"",IF($I$12<>"",IF(G33<>"",G33,($I$9/$I$12-SUM($U$25:U32))*V33*W33/SUMPRODUCT($W33:$W$55,$V33:$V$55)),""),"") -> 5 | V33: 1 | W33: 1
A34: Кекош, Рогалевич | B34: 45667 | C34: пт | D34: 78019 | E34: 22 | F34: =IF(AND(E34<>"",E34<>0),D34/E34,"") -> 3546.3182 | G34: 15 | H34: =IF(AND(G34<>"",G34<>0),D34/G34,"") -> 5201.2667 | J34: =IF(AND(G34<>"",G34<>0),E34/G34,"") -> 1.4666667 | N34: =IF(AND(I34<>"",I34<>0),G34/I34,"") | O34: =D34/P34 -> 1.1438452 | P34: =$I$8*V34*W34/SUMPRODUCT($W$25:$W$55,$V$25:$V$55) -> 68207.654 | Q34: =$I$9*V34*W34/SUMPRODUCT($W$25:$W$55,$V$25:$V$55) -> 18.484459 | R34: =IF($I$12="","",Q34/$I$12) -> 11.552787 | S34: =IF(W34<>"",IF(D34<>"",D34,($I$8-SUM($S$25:S33))*V34*W34/SUMPRODUCT($W34:$W$55,$V34:$V$55)),"") -> 78019 | T34: =IF(W34<>"",IF(E34<>"",E34,($I$9-SUM($T$25:T33))*V34*W34/SUMPRODUCT($W34:$W$55,$V34:$V$55)),"") -> 22 | U34: =IF(W34<>"",IF($I$12<>"",IF(G34<>"",G34,($I$9/$I$12-SUM($U$25:U33))*V34*W34/SUMPRODUCT($W34:$W$55,$V34:$V$55)),""),"") -> 15 | V34: 1 | W34: 1
A35: Кекош, Рогалевич | B35: 45668 | C35: сб | D35: 29453 | E35: 7 | F35: =IF(AND(E35<>"",E35<>0),D35/E35,"") -> 4207.5714 | G35: 3 | H35: =IF(AND(G35<>"",G35<>0),D35/G35,"") -> 9817.6667 | J35: =IF(AND(G35<>"",G35<>0),E35/G35,"") -> 2.3333333 | N35: =IF(AND(I35<>"",I35<>0),G35/I35,"") | O35: =D35/P35 -> 0.43181371 | P35: =$I$8*V35*W35/SUMPRODUCT($W$25:$W$55,$V$25:$V$55) -> 68207.654 | Q35: =$I$9*V35*W35/SUMPRODUCT($W$25:$W$55,$V$25:$V$55) -> 18.484459 | R35: =IF($I$12="","",Q35/$I$12) -> 11.552787 | S35: =IF(W35<>"",IF(D35<>"",D35,($I$8-SUM($S$25:S34))*V35*W35/SUMPRODUCT($W35:$W$55,$V35:$V$55)),"") -> 29453 | T35: =IF(W35<>"",IF(E35<>"",E35,($I$9-SUM($T$25:T34))*V35*W35/SUMPRODUCT($W35:$W$55,$V35:$V$55)),"") -> 7 | U35: =IF(W35<>"",IF($I$12<>"",IF(G35<>"",G35,($I$9/$I$12-SUM($U$25:U34))*V35*W35/SUMPRODUCT($W35:$W$55,$V35:$V$55)),""),"") -> 3 | V35: 1 | W35: 1
A36: Кекош | B36: 45669 | C36: вс | D36: 7884 | E36: 2 | F36: =IF(AND(E36<>"",E36<>0),D36/E36,"") -> 3942 | G36: 2 | H36: =IF(AND(G36<>"",G36<>0),D36/G36,"") -> 3942 | J36: =IF(AND(G36<>"",G36<>0),E36/G36,"") -> 1 | N36: =IF(AND(I36<>"",I36<>0),G36/I36,"") | O36: =D36/P36 -> 0.14270148 | P36: =$I$8*V36*W36/SUMPRODUCT($W$25:$W$55,$V$25:$V$55) -> 55248.2 | Q36: =$I$9*V36*W36/SUMPRODUCT($W$25:$W$55,$V$25:$V$55) -> 14.972412 | R36: =IF($I$12="","",Q36/$I$12) -> 9.3577575 | S36: =IF(W36<>"",IF(D36<>"",D36,($I$8-SUM($S$25:S35))*V36*W36/SUMPRODUCT($W36:$W$55,$V36:$V$55)),"") -> 7884 | T36: =IF(W36<>"",IF(E35<>"",E35,($I$9-SUM($T$25:T35))*V36*W36/SUMPRODUCT($W36:$W$55,$V36:$V$55)),"") -> 7 | U36: =IF(W36<>"",IF($I$12<>"",IF(G36<>"",G36,($I$9/$I$12-SUM($U$25:U35))*V36*W36/SUMPRODUCT($W36:$W$55,$V36:$V$55)),""),"") -> 2 | V36: 0.9 | W36: 0.9
A37: Рогалевич | B37: 45670 | C37: пн | D37: 18667 | E37: 4 | F37: =IF(AND(E37<>"",E37<>0),D37/E37,"") -> 4666.75 | G37: 3 | H37: =IF(AND(G37<>"",G37<>0),D37/G37,"") -> 6222.3333 | J37: =IF(AND(G37<>"",G37<>0),E37/G37,"") -> 1.3333333 | N37: =IF(AND(I37<>"",I37<>0),G37/I37,"") | O37: =D37/P37 -> 0.42762338 | P37: =$I$8*V37*W37/SUMPRODUCT($W$25:$W$55,$V$25:$V$55) -> 43652.899 | Q37: =$I$9*V37*W37/SUMPRODUCT($W$25:$W$55,$V$25:$V$55) -> 11.830054 | R37: =IF($I$12="","",Q37/$I$12) -> 7.3937837 | S37: =IF(W37<>"",IF(D37<>"",D37,($I$8-SUM($S$25:S36))*V37*W37/SUMPRODUCT($W37:$W$55,$V37:$V$55)),"") -> 18667 | T37: =IF(W37<>"",IF(E37<>"",E37,($I$9-SUM($T$25:T36))*V37*W37/SUMPRODUCT($W37:$W$55,$V37:$V$55)),"") -> 4 | U37: =IF(W37<>"",IF($I$12<>"",IF(G37<>"",G37,($I$9/$I$12-SUM($U$25:U36))*V37*W37/SUMPRODUCT($W37:$W$55,$V37:$V$55)),""),"") -> 3 | V37: 0.8 | W37: 0.8
A38: Кекош, Рогалевич | B38: 45671 | C38: вт | D38: 4382 | E38: 1 | F38: =IF(AND(E38<>"",E38<>0),D38/E38,"") -> 4382 | G38: 1 | H38: =IF(AND(G38<>"",G38<>0),D38/G38,"") -> 4382 | J38: =IF(AND(G38<>"",G38<>0),E38/G38,"") -> 1 | N38: =IF(AND(I38<>"",I38<>0),G38/I38,"") | O38: =D38/P38 -> 0.1003828 | P38: =$I$8*V38*W38/SUMPRODUCT($W$25:$W$55,$V$25:$V$55) -> 43652.899 | Q38: =$I$9*V38*W38/SUMPRODUCT($W$25:$W$55,$V$25:$V$55) -> 11.830054 | R38: =IF($I$12="","",Q38/$I$12) -> 7.3937837 | S38: =IF(W38<>"",IF(D38<>"",D38,($I$8-SUM($S$25:S37))*V38*W38/SUMPRODUCT($W38:$W$55,$V38:$V$55)),"") -> 4382 | T38: =IF(W38<>"",IF(E38<>"",E38,($I$9-SUM($T$25:T37))*V38*W38/SUMPRODUCT($W38:$W$55,$V38:$V$55)),"") -> 1 | U38: =IF(W38<>"",IF($I$12<>"",IF(G38<>"",G38,($I$9/$I$12-SUM($U$25:U37))*V38*W38/SUMPRODUCT($W38:$W$55,$V38:$V$55)),""),"") -> 1 | V38: 0.8 | W38: 0.8
A39: Кекош, Рогалевич | B39: 45672 | C39: ср | D39: 45624 | E39: 9 | F39: =IF(AND(E39<>"",E39<>0),D39/E39,"") -> 5069.3333 | G39: 5 | H39: =IF(AND(G39<>"",G39<>0),D39/G39,"") -> 9124.8 | J39: =IF(AND(G39<>"",G39<>0),E39/G39,"") -> 1.8 | N39: =IF(AND(I39<>"",I39<>0),G39/I39,"") | O39: =D39/P39 -> 1.045154 | P39: =$I$8*V39*W39/SUMPRODUCT($W$25:$W$55,$V$25:$V$55) -> 43652.899 | Q39: =$I$9*V39*W39/SUMPRODUCT($W$25:$W$55,$V$25:$V$55) -> 11.830054 | R39: =IF($I$12="","",Q39/$I$12) -> 7.3937837 | S39: =IF(W39<>"",IF(D39<>"",D39,($I$8-SUM($S$25:S38))*V39*W39/SUMPRODUCT($W39:$W$55,$V39:$V$55)),"") -> 45624 | T39: =IF(W39<>"",IF(E39<>"",E39,($I$9-SUM($T$25:T38))*V39*W39/SUMPRODUCT($W39:$W$55,$V39:$V$55)),"") -> 9 | U39: =IF(W39<>"",IF($I$12<>"",IF(G39<>"",G39,($I$9/$I$12-SUM($U$25:U38))*V39*W39/SUMPRODUCT($W39:$W$55,$V39:$V$55)),""),"") -> 5 | V39: 0.8 | W39: 0.8
A40: Кекош, Рогалевич | B40: 45673 | C40: чт | D40: 28397 | E40: 8 | F40: =IF(AND(E40<>"",E40<>0),D40/E40,"") -> 3549.625 | G40: 7 | H40: =IF(AND(G40<>"",G40<>0),D40/G40,"") -> 4056.7143 | J40: =IF(AND(G40<>"",G40<>0),E40/G40,"") -> 1.1428571 | N40: =IF(AND(I40<>"",I40<>0),G40/I40,"") | O40: =D40/P40 -> 0.65051808 | P40: =$I$8*V40*W40/SUMPRODUCT($W$25:$W$55,$V$25:$V$55) -> 43652.899 | Q40: =$I$9*V40*W40/SUMPRODUCT($W$25:$W$55,$V$25:$V$55) -> 11.830054 | R40: =IF($I$12="","",Q40/$I$12) -> 7.3937837 | S40: =IF(W40<>"",IF(D40<>"",D40,($I$8-SUM($S$25:S39))*V40*W40/SUMPRODUCT($W40:$W$55,$V40:$V$55)),"") -> 28397 | T40: =IF(W40<>"",IF(E40<>"",E40,($I$9-SUM($T$25:T39))*V40*W40/SUMPRODUCT($W40:$W$55,$V40:$V$55)),"") -> 8 | U40: =IF(W40<>"",IF($I$12<>"",IF(G40<>"",G40,($I$9/$I$12-SUM($U$25:U39))*V40*W40/SUMPRODUCT($W40:$W$55,$V40:$V$55)),""),"") -> 7 | V40: 0.8 | W40: 0.8
A41: Кекош, Рогалевич | B41: 45674 | C41: пт | D41: 27760 | E41: 6 | F41: =IF(AND(E41<>"",E41<>0),D41/E41,"") -> 4626.6667 | G41: 3 | H41: =IF(AND(G41<>"",G41<>0),D41/G41,"") -> 9253.3333 | J41: =IF(AND(G41<>"",G41<>0),E41/G41,"") -> 2 | N41: =IF(AND(I41<>"",I41<>0),G41/I41,"") | O41: =D41/P41 -> 0.50245981 | P41: =$I$8*V41*W41/SUMPRODUCT($W$25:$W$55,$V$25:$V$55) -> 55248.2 | Q41: =$I$9*V41*W41/SUMPRODUCT($W$25:$W$55,$V$25:$V$55) -> 14.972412 | R41: =IF($I$12="","",Q41/$I$12) -> 9.3577575 | S41: =IF(W41<>"",IF(D41<>"",D41,($I$8-SUM($S$25:S40))*V41*W41/SUMPRODUCT($W41:$W$55,$V41:$V$55)),"") -> 27760 | T41: =IF(W41<>"",IF(E41<>"",E41,($I$9-SUM($T$25:T40))*V41*W41/SUMPRODUCT($W41:$W$55,$V41:$V$55)),"") -> 6 | U41: =IF(W41<>"",IF($I$12<>"",IF(G41<>"",G41,($I$9/$I$12-SUM($U$25:U40))*V41*W41/SUMPRODUCT($W41:$W$55,$V41:$V$55)),""),"") -> 3 | V41: 0.9 | W41: 0.9
A42: Рогалевич | B42: 45675 | C42: сб | D42: 39780 | E42: 12 | F42: =IF(AND(E42<>"",E42<>0),D42/E42,"") -> 3315 | G42: 7 | H42: =IF(AND(G42<>"",G42<>0),D42/G42,"") -> 5682.8571 | J42: =IF(AND(G42<>"",G42<>0),E42/G42,"") -> 1.7142857 | N42: =IF(AND(I42<>"",I42<>0),G42/I42,"") | O42: =D42/P42 -> 0.72002346 | P42: =$I$8*V42*W42/SUMPRODUCT($W$25:$W$55,$V$25:$V$55) -> 55248.2 | Q42: =$I$9*V42*W42/SUMPRODUCT($W$25:$W$55,$V$25:$V$55) -> 14.972412 | R42: =IF($I$12="","",Q42/$I$12) -> 9.3577575 | S42: =IF(W42<>"",IF(D42<>"",D42,($I$8-SUM($S$25:S41))*V42*W42/SUMPRODUCT($W42:$W$55,$V42:$V$55)),"") -> 39780 | T42: =IF(W42<>"",IF(E42<>"",E42,($I$9-SUM($T$25:T41))*V42*W42/SUMPRODUCT($W42:$W$55,$V42:$V$55)),"") -> 12 | U42: =IF(W42<>"",IF($I$12<>"",IF(G42<>"",G42,($I$9/$I$12-SUM($U$25:U41))*V42*W42/SUMPRODUCT($W42:$W$55,$V42:$V$55)),""),"") -> 7 | V42: 0.9 | W42: 0.9
...

Sheet Св. по пок.
A1: Сводная по показателям
A2: Показатель | D2: ='Ялта, Ленина, 18'!I3 -> ул. Набережная Ленина, 18 | G2: =График!B26 -> Орешникова Елена | J2: =График!B30 -> Кекош Анна
D3: Факт | F3: Прогноз | G3: Факт | I3: Прогноз | J3: Факт | L3: Прогноз
A4: Выручка | D4: ='Ялта, Ленина, 18'!K8 -> 0.8727598 | E4: ='Ялта, Ленина, 18'!J8 -> 1570967.6 | F4: ='Ялта, Ленина, 18'!M8 -> 0.8727598 | G4: ='Рогалевич И. Е.'!K8 -> 0.90672296 | H4: ='Рогалевич И. Е.'!J8 -> 833967.94 | I4: ='Рогалевич И. Е.'!M8 -> 0.88896059 | J4: ='Кекош А. И.'!K8 -> 0.97359796 | K4: ='Кекош А. И.'!J8 -> 517697.6 | L4: ='Кекош А. И.'!M8 -> 1.3610517
A5: Кол-во изделий | D5: ='Ялта, Ленина, 18'!K9 -> 0.83845 | E5: ='Ялта, Ленина, 18'!J9 -> 409 | F5: ='Ялта, Ленина, 18'!M9 -> 0.83845 | G5: ='Рогалевич И. Е.'!K9 -> 0.82244238 | H5: ='Рогалевич И. Е.'!J9 -> 205 | I5: ='Рогалевич И. Е.'!M9 -> 0.86965916 | J5: ='Кекош А. И.'!K9 -> 0.80498514 | K5: ='Кекош А. И.'!J9 -> 116 | L5: ='Кекош А. И.'!M9 -> 0.80498514
A6: Средний чек | D6: ='Ялта, Ленина, 18'!K10 -> 1.317254 | E6: ='Ялта, Ленина, 18'!J10 -> 7777.0675 | F6: ='Ялта, Ленина, 18'!M10 -> 1.317254 | G6: ='Рогалевич И. Е.'!K10 -> 1.3985617 | H6: ='Рогалевич И. Е.'!J10 -> 8257.1083 | I6: ='Рогалевич И. Е.'!M10 -> 1.3985617 | J6: ='Кекош А. И.'!K10 -> 1.4614318 | K6: ='Кекош А. И.'!J10 -> 8628.2933 | L6: ='Кекош А. И.'!M10 -> 1.4614318
A7: Средняя стоимость изделия | D7: ='Ялта, Ленина, 18'!K11 -> 1.0409205 | E7: ='Ялта, Ленина, 18'!J11 -> 3840.9967 | F7: ='Ялта, Ленина, 18'!M11 -> 1.0409205 | G7: ='Рогалевич И. Е.'!K11 -> 1.102476 | H7: ='Рогалевич И. Е.'!J11 -> 4068.1363 | I7: ='Рогалевич И. Е.'!M11 -> 1.0221942 | J7: ='Кекош А. И.'!K11 -> 1.2094608 | K7: ='Кекош А. И.'!J11 -> 4462.9103 | L7: ='Кекош А. И.'!M11 -> 1.2094608
A8: Длина чека | D8: ='Ялта, Ленина, 18'!K12 -> 1.2654703 | E8: ='Ялта, Ленина, 18'!J12 -> 2.0247525 | F8: ='Ялта, Ленина, 18'!M12 -> 1.2654703 | G8: ='Рогалевич И. Е.'!K12 -> 1.2685644 | H8: ='Рогалевич И. Е.'!J12 -> 2.029703 | I8: ='Рогалевич И. Е.'!M12 -> 1.2685644 | J8: ='Кекош А. И.'!K12 -> 1.2083333 | K8: ='Кекош А. И.'!J12 -> 1.9333333 | L8: ='Кекош А. И.'!M12 -> 1.2083333
A9: Кол-во чеков | D9: ='Ялта, Ленина, 18'!K13 | E9: ='Ялта, Ленина, 18'!J13 -> 202 | F9: ='Ялта, Ленина, 18'!M13 | G9: ='Рогалевич И. Е.'!K13 -> 0.64832531 | H9: ='Рогалевич И. Е.'!J13 -> 101 | I9: ='Рогалевич И. Е.'!M13 -> 0.6861281 | J9: ='Кекош А. И.'!K13 -> 0.66619459 | K9: ='Кекош А. И.'!J13 -> 60 | L9: ='Кекош А. И.'!M13 -> 0.66619459
A10: Кол-во смен план/отработано | D10: ='Ялта, Ленина, 18'!K14 -> 1 | E10: ='Ялта, Ленина, 18'!J14 -> 30 | F10: ='Ялта, Ленина, 18'!M14 | G10: ='Рогалевич И. Е.'!K14 -> 1 | H10: ='Рогалевич И. Е.'!J14 -> 24 | I10: ='Рогалевич И. Е.'!M14 | J10: ='Кекош А. И.'!K14 -> 1 | K10: ='Кекош А. И.'!J14 -> 15 | L10: ='Кекош А. И.'!M14 -> 1
A11: Средние продажи в смену | D11: ='Ялта, Ленина, 18'!K15 -> 0.8727598 | E11: ='Ялта, Ленина, 18'!J15 -> 52365.588 | F11: ='Ялта, Ленина, 18'!M15 -> 0.8727598 | G11: ='Рогалевич И. Е.'!K15 -> 0.5791444 | H11: ='Рогалевич И. Е.'!J15 -> 34748.664 | I11: ='Рогалевич И. Е.'!M15 -> 0.5791444 | J11: ='Кекош А. И.'!K15 -> 0.57521956 | K11: ='Кекош А. И.'!J15 -> 34513.173 | L11: ='Кекош А. И.'!M15 -> 0.57521956
A12: Отставание/Перевыполнение | D12: ='Ялта, Ленина, 18'!J16 -> -229032.36 | G12: ='Рогалевич И. Е.'!J16 -> -606032.06 | J12: ='Кекош А. И.'!J16 -> -382302.4

Sheet План на день
A1: Выручка | D1: 75468
A2: Кол-во изделий | D2: =D1/D4 -> 20.452033
A3: Средний чек | D3: =D4*D5 -> 5904
A4: Средняя стоимость изделия | D4: ='Ялта, Ленина, 18'!I11 -> 3690
A5: Длина чека | D5: ='Ялта, Ленина, 18'!I12 -> 1.6
A6: Кол-во чеков | D6: =IF(D5<>0,D2/D5,"") -> 12.78252
A7: Конверсия | D7: ='Ялта, Ленина, 18'!I20 -> 0.257

Sheet Кекош А. И.
B1: =TODAY()-1 -> 45696
B2: (отчетная дата) | J2: ЕЖЕДНЕВНЫЙ ОТЧЕТ О ПРОДАЖАХ
B3: Осталось до выполнения плана!!! | J3: =График!B30 -> Кекош Анна
C4: =I8-D50 -> 14038.927 | E4: =IF(I8<>0, C4/I8, 0) -> 0.026402036
F6: Целевые показатели
F7: Показатель | I7: План | J7: Факт | K7: % выполнения | L7: Прогноз выполнения | M7: % выполнения по прогнозу | N7: Отклонение | O7: Факт аналогичного месяца прошлого года | P7: Отклонение LFL
F8: Выручка | I8: ='Ялта, Ленина, 18'!I8/График!AJ31*График!AJ30 -> 531736.53 | J8: =D50 -> 517697.6 | K8: =J8/I8 -> 0.97359796 | L8: =IF(SUMIF($D$25:$D$49,">=0",$P$25:$P$49)<>0,I8*D50/SUMIF($D$25:$D$49,">=0",$P$25:$P$49),0) -> 723720.91 | M8: =IF(AND(I8<>"",I8<>0,L8<>"",L8<>0),L8/I8,"") -> 1.3610517 | N8: =IF(AND(J8<>0, J8<>"", I8<>0, I8<>""), L8-I8, "") -> 191984.38 | P8: =IF(AND(O8<>"", O8<>0, L8<>"", L8<>0), -O8+L8, "") | Q8: =IF(AND(P8<>"", P8<>0, O8<>0, O8<>""), P8/O8, "")
F9: Кол-во изделий | I9: =I8/I11 -> 144.10204 | J9: =E50 -> 116 | K9: =IF(AND(I9<>"", I9<>0, J9<>""), J9/I9, "") -> 0.80498514 | L9: =J9 -> 116 | M9: =IF(AND(I9<>"",I9<>0,L9<>"",L9<>0),L9/I9,"") -> 0.80498514 | N9: =IF(AND(J9<>0, J9<>"", I9<>0, I9<>""), L9-I9, "") -> -28.10204 | O9: =O8/O11 -> #DIV/0! | P9: =IF(AND(O9<>"", O9<>0, L9<>"", L9<>0), -O9+L9, "") -> #DIV/0! | Q9: =IF(AND(P9<>"", P9<>0, O9<>0, O9<>""), P9/O9, "") -> #DIV/0!
F10: Средний чек | I10: =I11*I12 -> 5904 | J10: =H50 -> 8628.2933 | K10: =IF(AND(I10<>"", I10<>0, J10<>""), J10/I10, "") -> 1.4614318 | L10: =J10 -> 8628.2933 | M10: =IF(AND(I10<>"",I10<>0,L10<>"",L10<>0),L10/I10,"") -> 1.4614318 | N10: =IF(AND(J10<>0, J10<>"", I10<>0, I10<>""), L10-I10, "") -> 2724.2933 | O10: =O11*O12 -> 0 | P10: =IF(AND(O10<>"", O10<>0, L10<>"", L10<>0), -O10+L10, "") | Q10: =IF(AND(P10<>"", P10<>0, O10<>0, O10<>""), P10/O10, "")
F11: Средняя стоимость изделия | I11: ='Ялта, Ленина, 18'!I11 -> 3690 | J11: =F50 -> 4462.9103 | K11: =IF(AND(I11<>"", I11<>0, J11<>""), J11/I11, "") -> 1.2094608 | L11: =J11 -> 4462.9103 | M11: =IF(AND(I11<>"",I11<>0,L11<>"",L11<>0),L11/I11,"") -> 1.2094608 | N11: =IF(AND(J11<>0, J11<>"", I11<>0, I11<>""), L11-I11, "") -> 772.91034 | P11: =IF(AND(O11<>"", O11<>0, L11<>"", L11<>0), -O11+L11, "") | Q11: =IF(AND(P11<>"", P11<>0, O11<>0, O11<>""), P11/O11, "")
F12: Длина чека | I12: ='Ялта, Ленина, 18'!I12 -> 1.6 | J12: =J50 -> 1.9333333 | K12: =IF(AND(I12<>"", I12<>0, J12<>""), J12/I12, "") -> 1.2083333 | L12: =J12 -> 1.9333333 | M12: =IF(AND(I12<>"",I12<>0,L12<>"",L12<>0),L12/I12,"") -> 1.2083333 | N12: =IF(AND(J12<>0, J12<>"", I12<>0, I12<>""), L12-I12, "") -> 0.33333333 | P12: =IF(AND(O12<>"", O12<>0, L12<>"", L12<>0), -O12+L12, "") | Q12: =IF(AND(P12<>"", P12<>0, O12<>0, O12<>""), P12/O12, "")
F13: Кол-во чеков | I13: =IF(I12<>0, I9/I12, "") -> 90.063775 | J13: =G50 -> 60 | K13: =IF(AND(I13<>"", I13<>0, J13<>""), J13/I13, "") -> 0.66619459 | L13: =J13 -> 60 | M13: =IF(AND(I13<>"",I13<>0,L13<>"",L13<>0),L13/I13,"") -> 0.66619459 | N13: =IF(AND(J13<>0, J13<>"", I13<>0, I13<>""), L13-I13, "") -> -30.063775 | P13: =IF(AND(O13<>"", O13<>0, L13<>"", L13<>0), -O13+L13, "") | Q13: =IF(AND(P13<>"", P13<>0, O13<>0, O13<>""), P13/O13, "")
F14: Кол-во смен план/отработано | I14: =График!AI30 -> 15 | J14: 15 | K14: =IF(AND(I14<>"", I14<>0, J14<>""), J14/I14, "") -> 1 | L14: =J14 -> 15 | M14: =IF(AND(I14<>"",I14<>0,L14<>"",L14<>0),L14/I14,"") -> 1 | N14: =IF(AND(J14<>0, J14<>"", I14<>0, I14<>""), L14-I14, "") -> 0 | P14: =IF(AND(O14<>"", O14<>0, L14<>"", L14<>0), -O14+L14, "") | Q14: =IF(AND(P14<>"", P14<>0, O14<>0, O14<>""), P14/O14, "")
F15: Средние продажи в смену | I15: ='Ялта, Ленина, 18'!I15 -> 60000 | J15: =J8/J14 -> 34513.173 | K15: =IF(AND(I15<>"", I15<>0, J15<>""), J15/I15, "") -> 0.57521956 | L15: =J15 -> 34513.173 | M15: =IF(AND(I15<>"",I15<>0,L15<>"",L15<>0),L15/I15,"") -> 0.57521956 | N15: =IF(AND(J15<>0, J15<>"", I15<>0, I15<>""), L15-I15, "") -> -25486.827 | P15: =IF(AND(O15<>"", O15<>0, L15<>"", L15<>0), -O15+L15, "") | Q15: =IF(AND(P15<>"", P15<>0, O15<>0, O15<>""), P15/O15, "")
F16: Отставание/Перевыполнение | J16: =J8-I15*J14 -> -382302.4 | K16: =IF(AND(I16<>"", I16<>0, J16<>""), J16/I16, "") | L16: =J16 -> -382302.4 | M16: =IF(AND(I16<>"",I16<>0,L16<>"",L16<>0),L16/I16,"") | N16: =IF(AND(J16<>0, J16<>"", I16<>0, I16<>""), L16-I16, "") | P16: =IF(AND(O16<>"", O16<>0, L16<>"", L16<>0), -O16+L16, "") | Q16: =IF(AND(P16<>"", P16<>0, O16<>0, O16<>""), P16/O16, "") | S16: Подарочные сертификаты
F17: Трафик | I17: ='Ялта, Ленина, 18'!I17/График!AJ31*График!AJ30 -> 0 | J17: =I50 -> 0 | K17: =IF(AND(I17<>"", I17<>0, J17<>""), J17/I17, "") | L17: =J17 -> 0 | M17: =IF(AND(I17<>"",I17<>0,L17<>"",L17<>0),L17/I17,"") | N17: =IF(AND(J17<>0, J17<>"", I17<>0, I17<>""), L17-I17, "") | P17: =IF(AND(O17<>"", O17<>0, L17<>"", L17<>0), -O17+L17, "") | Q17: =IF(AND(P17<>"", P17<>0, O17<>0, O17<>""), P17/O17, "")
K18: =IF(AND(I18<>"", I18<>0, J18<>""), J18/I18, "") | L18: =J18 -> 0 | M18: =IF(AND(I18<>"",I18<>0,L18<>"",L18<>0),L18/I18,"") | N18: =IF(AND(J18<>0, J18<>"", I18<>0, I18<>""), L18-I18, "") | O18: 0 | P18: =IF(AND(O18<>"", O18<>0, L18<>"", L18<>0), -O18+L18, "") | Q18: =IF(AND(P18<>"", P18<>0, O18<>0, O18<>""), P18/O18, "") | S18: 3000
J19: =M50 -> 0 | K19: =IF(AND(I19<>"", I19<>0, J19<>""), J19/I19, "") | L19: =J19 -> 0 | M19: =IF(AND(I19<>"",I19<>0,L19<>"",L19<>0),L19/I19,"") | N19: =IF(AND(J19<>0, J19<>"", I19<>0, I19<>""), L19-I19, "") | O19: 0 | P19: =IF(AND(O19<>"", O19<>0, L19<>"", L19<>0), -O19+L19, "") | Q19: =IF(AND(P19<>"", P19<>0, O19<>0, O19<>""), P19/O19, "") | S19: =S18/I16 -> #DIV/0!
F20: Конверсия план/факт | I20: ='Ялта, Ленина, 18'!I20 -> 0.257 | J20: =N50 | K20: =J20/I20 -> #VALUE! | L20: =IF(AND(K8<>0,I14<>0,I50<>0),(I50*N50+(I50/K8-I50)*I20)/(I50/K8),0) -> 0 | M20: =IF(AND(I20<>"",I20<>0,L20<>"",L20<>0),L20/I20,"") | N20: =IF(AND(J20<>0, J20<>"", I20<>0, I20<>""), L20-I20, "") | P20: =IF(AND(O20<>"", O20<>0, L20<>"", L20<>0), -O20+L20, "") | Q20: =IF(AND(P20<>"", P20<>0, O20<>0, O20<>""), P20/O20, "")
B22: Факт продаж за месяц | O22: % выполнения дневного плана | P22: Раcпределение плана по дням
B23: Дата | C23: День недели | D23: Выручка (руб) | E23: Кол-во единиц (шт.) | F23: Средняя стоимость изделия (руб.) | G23: Количество чеков (шт.) | H23: Средняя сумма чека (руб.) | I23: Трафик | J23: Длина чека (шт.) | K23: Запасной | L23: Запасной | M23: Запасной | N23: Конверсия (%) | P23: выручка, план | Q23: кол-во ед, план | R23: Кол-во чеков, план | S23: выручка, скорректир.план | T23: кол-во ед, скорр. план | U23: кол-во чеков, скорр. план | V23: Коэфф. Дня Недели | W23: Специфика месяца
B24: 1 | C24: 2 | D24: 3 | E24: в | F24: 5 | G24: 6 | H24: 7 | I24: 8 | J24: 9 | K24: 10 | L24: 11 | M24: 12 | N24: 13 | P24: 1 | Q24: 2 | R24: 3 | S24: 4 | T24: 5 | U24: 6 | V24: 10 | W24: 11
A25: 1 | B25: 45659 | C25: чт | E25: 18 | F25: =IF(AND(E25<>"",E25<>0),D25/E25,"") -> 0 | G25: 8 | H25: =IF(AND(G25<>"",G25<>0),D25/G25,"") -> 0 | J25: =IF(AND(G25<>"",G25<>0),E25/G25,"") -> 2.25 | N25: =IF(AND(I25<>"",I25<>0),G25/I25,"") | O25: =D25/P25 -> 0 | P25: =$I$8*V25*W25/SUMPRODUCT($W$25:$W$60,$V$25:$V$60) -> 23507.362 | Q25: =$I$9*V25*W25/SUMPRODUCT($W$25:$W$60,$V$25:$V$60) -> 6.3705588 | R25: =IF($I$12="","",Q25/$I$12) -> 3.9815992 | S25: =IF(W25<>"",IF(D25<>"",D25,($I$8-SUM($S24:S$25))*V25*W25/SUMPRODUCT($W25:$W$60,$V25:$V$60)),"") -> 70085.85 | T25: =IF(W25<>"",IF(E25<>"",E25,($I$9-SUM($T24:T$25))*V25*W25/SUMPRODUCT($W25:$W$60,$V25:$V$60)),"") -> 18 | U25: =IF(W25<>"",IF($I$12<>"",IF(G25<>"",G25,($I$9/$I$12-SUM($U24:U$25))*V25*W25/SUMPRODUCT($W25:$W$60,$V25:$V$60)),""),"") -> 8 | V25: 1 | W25: 1
A26: 2 | B26: 45660 | C26: пт | E26: 12 | F26: =IF(AND(E26<>"",E26<>0),D26/E26,"") -> 0 | G26: 6 | H26: =IF(AND(G26<>"",G26<>0),D26/G26,"") -> 0 | J26: =IF(AND(G26<>"",G26<>0),E26/G26,"") -> 2 | N26: =IF(AND(I26<>"",I26<>0),G26/I26,"") | O26: =D26/P26 -> 0 | P26: =$I$8*V26*W26/SUMPRODUCT($W$25:$W$60,$V$25:$V$60) -> 23507.362 | Q26: =$I$9*V26*W26/SUMPRODUCT($W$25:$W$60,$V$25:$V$60) -> 6.3705588 | R26: =IF($I$12="","",Q26/$I$12) -> 3.9815992 | S26: =IF(W26<>"",IF(D26<>"",D26,($I$8-SUM($S$25:S25))*V26*W26/SUMPRODUCT($W26:$W$60,$V26:$V$60)),"") -> 45926 | T26: =IF(W26<>"",IF(E26<>"",E26,($I$9-SUM($T$25:T25))*V26*W26/SUMPRODUCT($W26:$W$60,$V26:$V$60)),"") -> 12 | U26: =IF(W26<>"",IF($I$12<>"",IF(G26<>"",G26,($I$9/$I$12-SUM($U$25:U25))*V26*W26/SUMPRODUCT($W26:$W$60,$V26:$V$60)),""),"") -> 6 | V26: 1 | W26: 1
A27: 3 | B27: 45661 | C27: сб | E27: 17 | F27: =IF(AND(E27<>"",E27<>0),D27/E27,"") -> 0 | G27: 9 | H27: =IF(AND(G27<>"",G27<>0),D27/G27,"") -> 0 | J27: =IF(AND(G27<>"",G27<>0),E27/G27,"") -> 1.8888889 | N27: =IF(AND(I27<>"",I27<>0),G27/I27,"") | O27: =D27/P27 -> 0 | P27: =$I$8*V27*W27/SUMPRODUCT($W$25:$W$60,$V$25:$V$60) -> 23507.362 | Q27: =$I$9*V27*W27/SUMPRODUCT($W$25:$W$60,$V$25:$V$60) -> 6.3705588 | R27: =IF($I$12="","",Q27/$I$12) -> 3.9815992 | S27: =IF(W27<>"",IF(D27<>"",D27,($I$8-SUM($S$25:S26))*V27*W27/SUMPRODUCT($W27:$W$60,$V27:$V$60)),"") -> 70721.5 | T27: =IF(W27<>"",IF(E27<>"",E27,($I$9-SUM($T$25:T26))*V27*W27/SUMPRODUCT($W27:$W$60,$V27:$V$60)),"") -> 17 | U27: =IF(W27<>"",IF($I$12<>"",IF(G27<>"",G27,($I$9/$I$12-SUM($U$25:U26))*V27*W27/SUMPRODUCT($W27:$W$60,$V27:$V$60)),""),"") -> 9 | V27: 1 | W27: 1
A28: 4 | B28: 45662 | C28: вс | D28: 327758.6 | E28: 19 | F28: =IF(AND(E28<>"",E28<>0),D28/E28,"") -> 17250.453 | G28: 5 | H28: =IF(AND(G28<>"",G28<>0),D28/G28,"") -> 65551.72 | J28: =IF(AND(G28<>"",G28<>0),E28/G28,"") -> 3.8 | N28: =IF(AND(I28<>"",I28<>0),G28/I28,"") | O28: =D28/P28 -> 13.942807 | P28: =$I$8*V28*W28/SUMPRODUCT($W$25:$W$60,$V$25:$V$60) -> 23507.362 | Q28: =$I$9*V28*W28/SUMPRODUCT($W$25:$W$60,$V$25:$V$60) -> 6.3705588 | R28: =IF($I$12="","",Q28/$I$12) -> 3.9815992 | S28: =IF(W28<>"",IF(D28<>"",D28,($I$8-SUM($S$25:S27))*V28*W28/SUMPRODUCT($W28:$W$60,$V28:$V$60)),"") -> 327758.6 | T28: =IF(W28<>"",IF(E28<>"",E28,($I$9-SUM($T$25:T27))*V28*W28/SUMPRODUCT($W28:$W$60,$V28:$V$60)),"") -> 19 | U28: =IF(W28<>"",IF($I$12<>"",IF(G28<>"",G28,($I$9/$I$12-SUM($U$25:U27))*V28*W28/SUMPRODUCT($W28:$W$60,$V28:$V$60)),""),"") -> 5 | V28: 1 | W28: 1
A29: 5 | B29: 45665 | C29: ср | D29: 29826 | E29: 9 | F29: 3513 | G29: 6 | H29: 7278 | J29: 2.07 | O29: 0.8 | P29: 127742 | Q29: 35 | R29: 22 | S29: 101885 | T29: 29 | U29: 14 | V29: 1.2 | W29: 1.2
A30: 6 | B30: 45667 | C30: сб | D30: 38280 | E30: 12 | F30: =IF(AND(E30<>"",E30<>0),D30/E30,"") -> 3190 | G30: 8 | H30: =IF(AND(G30<>"",G30<>0),D30/G30,"") -> 4785 | P30: =$I$8*V30*W30/SUMPRODUCT($W$25:$W$60,$V$25:$V$60) -> 23507.362 | V30: 1 | W30: 1
A31: 7 | B31: 45668 | C31: сб | D31: 24761 | E31: 6 | F31: 4208 | G31: 2 | H31: 9818 | J31: 2.33 | O31: 0.35 | P31: 83841 | Q31: 23 | R31: 14 | S31: 29453 | T31: 7 | U31: 3 | V31: 1 | W31: 1
A32: 8 | B32: 45669 | C32: вс | D32: 7884 | E32: 2 | F32: =IF(AND(E32<>"",E32<>0),D32/E32,"") -> 3942 | G32: 2 | H32: =IF(AND(G32<>"",G32<>0),D32/G32,"") -> 3942 | J32: =IF(AND(G32<>"",G32<>0),E32/G32,"") -> 1 | N32: =IF(AND(I32<>"",I32<>0),G32/I32,"") | O32: =D32/P32 -> 0.41405468 | P32: =$I$8*V32*W32/SUMPRODUCT($W$25:$W$55,$V$25:$V$55) -> 19040.963 | Q32: =$I$9*V32*W32/SUMPRODUCT($W$25:$W$55,$V$25:$V$55) -> 5.1601526 | R32: =IF($I$12="","",Q32/$I$12) -> 3.2250954 | S32: =IF(W32<>"",IF(D32<>"",D32,($I$8-SUM($S$25:S31))*V32*W32/SUMPRODUCT($W32:$W$55,$V32:$V$55)),"") -> 7884 | T32: =IF(W32<>"",IF(E31<>"",E31,($I$9-SUM($T$25:T31))*V32*W32/SUMPRODUCT($W32:$W$55,$V32:$V$55)),"") -> 6 | U32: =IF(W32<>"",IF($I$12<>"",IF(G32<>"",G32,($I$9/$I$12-SUM($U$25:U31))*V32*W32/SUMPRODUCT($W32:$W$55,$V32:$V$55)),""),"") -> 2 | V32: 0.9 | W32: 0.9
A33: 9 | B33: 45671 | C33: вт | D33: 4382 | E33: 1 | F33: =IF(AND(E33<>"",E33<>0),D33/E33,"") -> 4382 | G33: 1 | H33: =IF(AND(G33<>"",G33<>0),D33/G33,"") -> 4382 | J33: =IF(AND(G33<>"",G33<>0),E33/G33,"") -> 1 | N33: =IF(AND(I33<>"",I33<>0),G33/I33,"") | O33: =D33/P33 -> 0.29126514 | P33: =$I$8*V33*W33/SUMPRODUCT($W$25:$W$55,$V$25:$V$55) -> 15044.712 | Q33: =$I$9*V33*W33/SUMPRODUCT($W$25:$W$55,$V$25:$V$55) -> 4.0771576 | R33: =IF($I$12="","",Q33/$I$12) -> 2.5482235 | S33: =IF(W33<>"",IF(D33<>"",D33,($I$8-SUM($S$25:S32))*V33*W33/SUMPRODUCT($W33:$W$55,$V33:$V$55)),"") -> 4382 | T33: =IF(W33<>"",IF(E33<>"",E33,($I$9-SUM($T$25:T32))*V33*W33/SUMPRODUCT($W33:$W$55,$V33:$V$55)),"") -> 1 | U33: =IF(W33<>"",IF($I$12<>"",IF(G33<>"",G33,($I$9/$I$12-SUM($U$25:U32))*V33*W33/SUMPRODUCT($W33:$W$55,$V33:$V$55)),""),"") -> 1 | V33: 0.8 | W33: 0.8
A34: 10 | B34: 45672 | C34: ср | D34: =5992+5092 -> 11084 | E34: 2 | F34: =IF(AND(E34<>"",E34<>0),D34/E34,"") -> 5542 | G34: 2 | H34: =IF(AND(G34<>"",G34<>0),D34/G34,"") -> 5542 | J34: =IF(AND(G34<>"",G34<>0),E34/G34,"") -> 1 | N34: =IF(AND(I34<>"",I34<>0),G34/I34,"") | O34: =D34/P34 -> 0.47151186 | P34: =$I$8*V34*W34/SUMPRODUCT($W$25:$W$60,$V$25:$V$60) -> 23507.362 | Q34: =$I$9*V34*W34/SUMPRODUCT($W$25:$W$60,$V$25:$V$60) -> 6.3705588 | R34: =IF($I$12="","",Q34/$I$12) -> 3.9815992 | S34: =IF(W34<>"",IF(D34<>"",D34,($I$8-SUM($S$25:S33))*V34*W34/SUMPRODUCT($W34:$W$60,$V34:$V$60)),"") -> 11084 | T34: =IF(W34<>"",IF(E34<>"",E34,($I$9-SUM($T$25:T33))*V34*W34/SUMPRODUCT($W34:$W$60,$V34:$V$60)),"") -> 2 | U34: =IF(W34<>"",IF($I$12<>"",IF(G34<>"",G34,($I$9/$I$12-SUM($U$25:U33))*V34*W34/SUMPRODUCT($W34:$W$60,$V34:$V$60)),""),"") -> 2 | V34: 1 | W34: 1
A35: 11 | B35: 45673 | C35: чт | D35: 16522 | E35: 5 | F35: =IF(AND(E35<>"",E35<>0),D35/E35,"") -> 3304.4 | G35: 5 | H35: =IF(AND(G35<>"",G35<>0),D35/G35,"") -> 3304.4 | J35: =IF(AND(G35<>"",G35<>0),E35/G35,"") -> 1 | N35: =IF(AND(I35<>"",I35<>0),G35/I35,"") | O35: =D35/P35 -> 1.0981932 | P35: =$I$8*V35*W35/SUMPRODUCT($W$25:$W$55,$V$25:$V$55) -> 15044.712 | Q35: =$I$9*V35*W35/SUMPRODUCT($W$25:$W$55,$V$25:$V$55) -> 4.0771576 | R35: =IF($I$12="","",Q35/$I$12) -> 2.5482235 | S35: =IF(W35<>"",IF(D35<>"",D35,($I$8-SUM($S$25:S34))*V35*W35/SUMPRODUCT($W35:$W$55,$V35:$V$55)),"") -> 16522 | T35: =IF(W35<>"",IF(E35<>"",E35,($I$9-SUM($T$25:T34))*V35*W35/SUMPRODUCT($W35:$W$55,$V35:$V$55)),"") -> 5 | U35: =IF(W35<>"",IF($I$12<>"",IF(G35<>"",G35,($I$9/$I$12-SUM($U$25:U34))*V35*W35/SUMPRODUCT($W35:$W$55,$V35:$V$55)),""),"") -> 5 | V35: 0.8 | W35: 0.8
A36: 12 | B36: 45674 | C36: пт | D36: 19377 | E36: 4 | F36: =IF(AND(E36<>"",E36<>0),D36/E36,"") -> 4844.25 | G36: 2 | H36: =IF(AND(G36<>"",G36<>0),D36/G36,"") -> 9688.5 | J36: =IF(AND(G36<>"",G36<>0),E36/G36,"") -> 2 | N36: =IF(AND(I36<>"",I36<>0),G36/I36,"") | O36: =D36/P36 -> 1.0176481 | P36: =$I$8*V36*W36/SUMPRODUCT($W$25:$W$55,$V$25:$V$55) -> 19040.963 | Q36: =$I$9*V36*W36/SUMPRODUCT($W$25:$W$55,$V$25:$V$55) -> 5.1601526 | R36: =IF($I$12="","",Q36/$I$12) -> 3.2250954 | S36: =IF(W36<>"",IF(D36<>"",D36,($I$8-SUM($S$25:S35))*V36*W36/SUMPRODUCT($W36:$W$55,$V36:$V$55)),"") -> 19377 | T36: =IF(W36<>"",IF(E36<>"",E36,($I$9-SUM($T$25:T35))*V36*W36/SUMPRODUCT($W36:$W$55,$V36:$V$55)),"") -> 4 | U36: =IF(W36<>"",IF($I$12<>"",IF(G36<>"",G36,($I$9/$I$12-SUM($U$25:U35))*V36*W36/SUMPRODUCT($W36:$W$55,$V36:$V$55)),""),"") -> 2 | V36: 0.9 | W36: 0.9
A37: 13 | B37: 45677 | C37: пн | D37: 26748 | E37: 6 | F37: =IF(AND(E37<>"",E37<>0),D37/E37,"") -> 4458 | G37: 2 | H37: =IF(AND(G37<>"",G37<>0),D37/G37,"") -> 13374 | J37: =IF(AND(G37<>"",G37<>0),E37/G37,"") -> 3 | N37: =IF(AND(I37<>"",I37<>0),G37/I37,"") | O37: =D37/P37 -> 1.7779005 | P37: =$I$8*V37*W37/SUMPRODUCT($W$25:$W$55,$V$25:$V$55) -> 15044.712 | Q37: =$I$9*V37*W37/SUMPRODUCT($W$25:$W$55,$V$25:$V$55) -> 4.0771576 | R37: =IF($I$12="","",Q37/$I$12) -> 2.5482235 | S37: =IF(W37<>"",IF(D37<>"",D37,($I$8-SUM($S$25:S36))*V37*W37/SUMPRODUCT($W37:$W$55,$V37:$V$55)),"") -> 26748 | T37: =IF(W37<>"",IF(E37<>"",E37,($I$9-SUM($T$25:T36))*V37*W37/SUMPRODUCT($W37:$W$55,$V37:$V$55)),"") -> 6 | U37: =IF(W37<>"",IF($I$12<>"",IF(G37<>"",G37,($I$9/$I$12-SUM($U$25:U36))*V37*W37/SUMPRODUCT($W37:$W$55,$V37:$V$55)),""),"") -> 2 | V37: 0.8 | W37: 0.8
A38: 14 | B38: 45678 | C38: вт | D38: 11075 | E38: 3 | F38: =IF(AND(E38<>"",E38<>0),D38/E38,"") -> 3691.6667 | G38: 2 | H38: =IF(AND(G38<>"",G38<>0),D38/G38,"") -> 5537.5 | J38: =IF(AND(G38<>"",G38<>0),E38/G38,"") -> 1.5 | N38: =IF(AND(I38<>"",I38<>0),G38/I38,"") | O38: =D38/P38 -> 0.73613907 | P38: =$I$8*V38*W38/SUMPRODUCT($W$25:$W$55,$V$25:$V$55) -> 15044.712 | Q38: =$I$9*V38*W38/SUMPRODUCT($W$25:$W$55,$V$25:$V$55) -> 4.0771576 | R38: =IF($I$12="","",Q38/$I$12) -> 2.5482235 | S38: =IF(W38<>"",IF(D38<>"",D38,($I$8-SUM($S$25:S37))*V38*W38/SUMPRODUCT($W38:$W$55,$V38:$V$55)),"") -> 11075 | T38: =IF(W38<>"",IF(E38<>"",E38,($I$9-SUM($T$25:T37))*V38*W38/SUMPRODUCT($W38:$W$55,$V38:$V$55)),"") -> 3 | U38: =IF(W38<>"",IF($I$12<>"",IF(G38<>"",G38,($I$9/$I$12-SUM($U$25:U37))*V38*W38/SUMPRODUCT($W38:$W$55,$V38:$V$55)),""),"") -> 2 | V38: 0.8 | W38: 0.8
A39: 15 | F39: =IF(AND(E39<>"",E39<>0),D39/E39,"") | H39: =IF(AND(G39<>"",G39<>0),D39/G39,"") | J39: =IF(AND(G39<>"",G39<>0),E39/G39,"") | N39: =IF(AND(I39<>"",I39<>0),G39/I39,"") | O39: =D39/P39 -> 0 | P39: =$I$8*V39*W39/SUMPRODUCT($W$25:$W$60,$V$25:$V$60) -> 23507.362 | Q39: =$I$9*V39*W39/SUMPRODUCT($W$25:$W$60,$V$25:$V$60) -> 6.3705588 | R39: =IF($I$12="","",Q39/$I$12) -> 3.9815992 | S39: =IF(W39<>"",IF(D39<>"",D39,($I$8-SUM($S$25:S38))*V39*W39/SUMPRODUCT($W39:$W$60,$V39:$V$60)),"") -> 5801.615 | T39: =IF(W39<>"",IF(E39<>"",E39,($I$9-SUM($T$25:T38))*V39*W39/SUMPRODUCT($W39:$W$60,$V39:$V$60)),"") -> 1.510204 | U39: =IF(W39<>"",IF($I$12<>"",IF(G39<>"",G39,($I$9/$I$12-SUM($U$25:U38))*V39*W39/SUMPRODUCT($W39:$W$60,$V39:$V$60)),""),"") -> 2.9063775 | V39: 1 | W39: 1
A40: 16 | F40: =IF(AND(E40<>"",E40<>0),D40/E40,"") | H40: =IF(AND(G40<>"",G40<>0),D40/G40,"") | J40: =IF(AND(G40<>"",G40<>0),E40/G40,"") | N40: =IF(AND(I40<>"",I40<>0),G40/I40,"") | O40: =D40/P40 -> 0 | P40: =$I$8*V40*W40/SUMPRODUCT($W$25:$W$60,$V$25:$V$60) -> 23507.362 | Q40: =$I$9*V40*W40/SUMPRODUCT($W$25:$W$60,$V$25:$V$60) -> 6.3705588 | R40: =IF($I$12="","",Q40/$I$12) -> 3.9815992 | S40: =IF(W40<>"",IF(D40<>"",D40,($I$8-SUM($S$25:S39))*V40*W40/SUMPRODUCT($W40:$W$60,$V40:$V$60)),"") -> 5801.615 | T40: =IF(W40<>"",IF(E40<>"",E40,($I$9-SUM($T$25:T39))*V40*W40/SUMPRODUCT($W40:$W$60,$V40:$V$60)),"") -> 1.510204 | U40: =IF(W40<>"",IF($I$12<>"",IF(G40<>"",G40,($I$9/$I$12-SUM($U$25:U39))*V40*W40/SUMPRODUCT($W40:$W$60,$V40:$V$60)),""),"") -> 2.9063775 | V40: 1 | W40: 1
A41: 17 | F41: =IF(AND(E41<>"",E41<>0),D41/E41,"") | H41: =IF(AND(G41<>"",G41<>0),D41/G41,"") | J41: =IF(AND(G41<>"",G41<>0),E41/G41,"") | N41: =IF(AND(I41<>"",I41<>0),G41/I41,"") | O41: =D41/P41 -> 0 | P41: =$I$8*V41*W41/SUMPRODUCT($W$25:$W$60,$V$25:$V$60) -> 23507.362 | Q41: =$I$9*V41*W41/SUMPRODUCT($W$25:$W$60,$V$25:$V$60) -> 6.3705588 | R41: =IF($I$12="","",Q41/$I$12) -> 3.9815992 | S41: =IF(W41<>"",IF(D41<>"",D41,($I$8-SUM($S$25:S40))*V41*W41/SUMPRODUCT($W41:$W$60,$V41:$V$60)),"") -> 5801.615 | T41: =IF(W41<>"",IF(E41<>"",E41,($I$9-SUM($T$25:T40))*V41*W41/SUMPRODUCT($W41:$W$60,$V41:$V$60)),"") -> 1.510204 | U41: =IF(W41<>"",IF($I$12<>"",IF(G41<>"",G41,($I$9/$I$12-SUM($U$25:U40))*V41*W41/SUMPRODUCT($W41:$W$60,$V41:$V$60)),""),"") -> 2.9063775 | V41: 1 | W41: 1
A42: 18 | F42: =IF(AND(E42<>"",E42<>0),D42/E42,"") | H42: =IF(AND(G42<>"",G42<>0),D42/G42,"") | J42: =IF(AND(G42<>"",G42<>0),E42/G42,"") | N42: =IF(AND(I42<>"",I42<>0),G42/I42,"") | O42: =D42/P42 -> 0 | P42: =$I$8*V42*W42/SUMPRODUCT($W$25:$W$60,$V$25:$V$60) -> 23507.362 | Q42: =$I$9*V42*W42/SUMPRODUCT($W$25:$W$60,$V$25:$V$60) -> 6.3705588 | R42: =IF($I$12="","",Q42/$I$12) -> 3.9815992 | S42: =IF(W42<>"",IF(D42<>"",D42,($I$8-SUM($S$25:S41))*V42*W42/SUMPRODUCT($W42:$W$60,$V42:$V$60)),"") -> 5801.615 | T42: =IF(W42<>"",IF(E42<>"",E42,($I$9-SUM($T$25:T41))*V42*W42/SUMPRODUCT($W42:$W$60,$V42:$V$60)),"") -> 1.510204 | U42: =IF(W42<>"",IF($I$12<>"",IF(G42<>"",G42,($I$9/$I$12-SUM($U$25:U41))*V42*W42/SUMPRODUCT($W42:$W$60,$V42:$V$60)),""),"") -> 2.9063775 | V42: 1 | W42: 1
...

Sheet Рогалевич И. Е.
B1: =TODAY()-1 -> 45696
B2: (отчетная дата) | J2: ЕЖЕДНЕВНЫЙ ОТЧЕТ О ПРОДАЖАХ
B3: Осталось до выполнения плана!!! | J3: =График!B29 -> Рогалевич Ирина
C4: =I8-D50 -> 85792.539 | E4: =IF(I8<>0,C4/I8,0) -> 0.093277044
F6: Целевые показатели
F7: Показатель | I7: План | J7: Факт | K7: % выполнения | L7: Прогноз выполнения | M7: % выполнения по прогнозу | N7: Отклонение | O7: Факт аналогичного месяца прошлого года | P7: Отклонение LFL
F8: Выручка | I8: ='Ялта, Ленина, 18'!I8/График!AJ31*График!AJ29 -> 919760.48 | J8: =D50 -> 833967.94 | K8: =IF(AND(I8<>"",I8<>0,J8<>""),J8/I8,"") -> 0.90672296 | L8: =IF(SUMIF($D$25:$D$49,">=0",$P$25:$P$49)<>0,I8*D50/SUMIF($D$25:$D$49,">=0",$P$25:$P$49),0) -> 817630.81 | M8: =IF(AND(I8<>"",I8<>0,L8<>"",L8<>0),L8/I8,"") -> 0.88896059 | N8: =IF(AND(J8<>0,J8<>"",I8<>0,I8<>""),L8-I8,"") -> -102129.67 | P8: =IF(AND(O8<>"",O8<>0,L8<>"",L8<>0),-O8+L8,"") | Q8: =IF(AND(P8<>"",P8<>0,O8<>0,O8<>""),P8/O8,"")
F9: Кол-во изделий | I9: =I8/I11 -> 249.25758 | J9: =E50 -> 205 | K9: =IF(AND(I9<>"",I9<>0,J9<>""),J9/I9,"") -> 0.82244238 | L9: =IF(SUMIF($E$25:$E$48,">=0",$Q$25:$Q$48)<>0,I9*E50/SUMIF($E$25:$E$48,">=0",$Q$25:$Q$48),0) -> 216.76914 | M9: =IF(AND(I9<>"",I9<>0,L9<>"",L9<>0),L9/I9,"") -> 0.86965916 | N9: =IF(AND(J9<>0,J9<>"",I9<>0,I9<>""),L9-I9,"") -> -32.488443 | O9: =O8/O11 -> #DIV/0! | P9: =IF(AND(O9<>"",O9<>0,L9<>"",L9<>0),-O9+L9,"") -> #DIV/0! | Q9: =IF(AND(P9<>"",P9<>0,O9<>0,O9<>""),P9/O9,"") -> #DIV/0!
F10: Средний чек | I10: =I11*I12 -> 5904 | J10: =H50 -> 8257.1083 | K10: =IF(AND(I10<>"",I10<>0,J10<>""),J10/I10,"") -> 1.3985617 | L10: =J10 -> 8257.1083 | M10: =IF(AND(I10<>"",I10<>0,L10<>"",L10<>0),L10/I10,"") -> 1.3985617 | N10: =IF(AND(J10<>0,J10<>"",I10<>0,I10<>""),L10-I10,"") -> 2353.1083 | O10: =O11*O12 -> 0 | P10: =IF(AND(O10<>"",O10<>0,L10<>"",L10<>0),-O10+L10,"") | Q10: =IF(AND(P10<>"",P10<>0,O10<>0,O10<>""),P10/O10,"")
F11: Средняя стоимость изделия | I11: ='Ялта, Ленина, 18'!I11 -> 3690 | J11: =F50 -> 4068.1363 | K11: =IF(AND(I11<>"",I11<>0,J11<>""),J11/I11,"") -> 1.102476 | L11: =IF(L9>0,L8/L9,"") -> 3771.8967 | M11: =IF(AND(I11<>"",I11<>0,L11<>"",L11<>0),L11/I11,"") -> 1.0221942 | N11: =IF(AND(J11<>0,J11<>"",I11<>0,I11<>""),L11-I11,"") -> 81.89675 | P11: =IF(AND(O11<>"",O11<>0,L11<>"",L11<>0),-O11+L11,"") | Q11: =IF(AND(P11<>"",P11<>0,O11<>0,O11<>""),P11/O11,"")
F12: Длина чека | I12: ='Ялта, Ленина, 18'!I12 -> 1.6 | J12: =J50 -> 2.029703 | K12: =IF(AND(I12<>"",I12<>0,J12<>""),J12/I12,"") -> 1.2685644 | L12: =J12 -> 2.029703 | M12: =IF(AND(I12<>"",I12<>0,L12<>"",L12<>0),L12/I12,"") -> 1.2685644 | N12: =IF(AND(J12<>0,J12<>"",I12<>0,I12<>""),L12-I12,"") -> 0.42970297 | P12: =IF(AND(O12<>"",O12<>0,L12<>"",L12<>0),-O12+L12,"") | Q12: =IF(AND(P12<>"",P12<>0,O12<>0,O12<>""),P12/O12,"")
F13: Кол-во чеков | I13: =IF(I12<>0,I9/I12,"") -> 155.78599 | J13: =G50 -> 101 | K13: =IF(AND(I13<>"",I13<>0,J13<>""),J13/I13,"") -> 0.64832531 | L13: =IF(SUMIF($G$25:$G$48,">=0",$R$25:$R$48)<>0,I13*G50/SUMIF($G$25:$G$48,">=0",$R$25:$R$48),"") -> 106.88914 | M13: =IF(AND(I13<>"",I13<>0,L13<>"",L13<>0),L13/I13,"") -> 0.6861281 | N13: =IF(AND(J13<>0,J13<>"",I13<>0,I13<>""),L13-I13,"") -> -48.896845 | P13: =IF(AND(O13<>"",O13<>0,L13<>"",L13<>0),-O13+L13,"") | Q13: =IF(AND(P13<>"",P13<>0,O13<>0,O13<>""),P13/O13,"")
F14: Кол-во смен план/отработано | I14: =График!AI29 -> 24 | J14: 24 | K14: =IF(AND(I14<>"",I14<>0,J14<>""),J14/I14,"") -> 1 | L14: =IF(SUMIF($D$25:$D$48,">=0",$P$25:$P$48),I50*I8/SUMIF($D$25:$D$48,">=0",$P$25:$P$48),"") -> 0 | M14: =IF(AND(I14<>"",I14<>0,L14<>"",L14<>0),L14/I14,"") | N14: =IF(AND(J14<>0,J14<>"",I14<>0,I14<>""),L14-I14,"") -> -24 | P14: =IF(AND(O14<>"",O14<>0,L14<>"",L14<>0),-O14+L14,"") | Q14: =IF(AND(P14<>"",P14<>0,O14<>0,O14<>""),P14/O14,"")
F15: Средние продажи в смену | I15: ='Ялта, Ленина, 18'!I15 -> 60000 | J15: =J8/J14 -> 34748.664 | K15: =IF(AND(I15<>"",I15<>0,J15<>""),J15/I15,"") -> 0.5791444 | L15: =J15 -> 34748.664 | M15: =IF(AND(I15<>"",I15<>0,L15<>"",L15<>0),L15/I15,"") -> 0.5791444 | N15: =IF(AND(J15<>0,J15<>"",I15<>0,I15<>""),L15-I15,"") -> -25251.336 | P15: =IF(AND(O15<>"",O15<>0,L15<>"",L15<>0),-O15+L15,"") | Q15: =IF(AND(P15<>"",P15<>0,O15<>0,O15<>""),P15/O15,"")
F16: Отставание/Перевыполнение | J16: =J8-I15*J14 -> -606032.06 | K16: =IF(AND(I16<>"",I16<>0,J16<>""),J16/I16,"") | L16: =J16 -> -606032.06 | M16: =IF(AND(I16<>"",I16<>0,L16<>"",L16<>0),L16/I16,"") | N16: =IF(AND(J16<>0,J16<>"",I16<>0,I16<>""),L16-I16,"") | P16: =IF(AND(O16<>"",O16<>0,L16<>"",L16<>0),-O16+L16,"") | Q16: =IF(AND(P16<>"",P16<>0,O16<>0,O16<>""),P16/O16,"") | S16: Подарочные сертификаты
F17: Трафик | I17: ='Ялта, Ленина, 18'!I17/График!AJ31*График!AJ26 -> 0 | J17: =I50 -> 0 | K17: =IF(AND(I17<>"",I17<>0,J17<>""),J17/I17,"") | L17: =J17 -> 0 | M17: =IF(AND(I17<>"",I17<>0,L17<>"",L17<>0),L17/I17,"") | N17: =IF(AND(J17<>0,J17<>"",I17<>0,I17<>""),L17-I17,"") | P17: =IF(AND(O17<>"",O17<>0,L17<>"",L17<>0),-O17+L17,"") | Q17: =IF(AND(P17<>"",P17<>0,O17<>0,O17<>""),P17/O17,"")
K18: =IF(AND(I18<>"",I18<>0,J18<>""),J18/I18,"") | L18: =J18 -> 0 | M18: =IF(AND(I18<>"",I18<>0,L18<>"",L18<>0),L18/I18,"") | N18: =IF(AND(J18<>0,J18<>"",I18<>0,I18<>""),L18-I18,"") | O18: 0 | P18: =IF(AND(O18<>"",O18<>0,L18<>"",L18<>0),-O18+L18,"") | Q18: =IF(AND(P18<>"",P18<>0,O18<>0,O18<>""),P18/O18,"")
J19: =M50 -> 0 | K19: =IF(AND(I19<>"",I19<>0,J19<>""),J19/I19,"") | L19: =J19 -> 0 | M19: =IF(AND(I19<>"",I19<>0,L19<>"",L19<>0),L19/I19,"") | N19: =IF(AND(J19<>0,J19<>"",I19<>0,I19<>""),L19-I19,"") | O19: 0 | P19: =IF(AND(O19<>"",O19<>0,L19<>"",L19<>0),-O19+L19,"") | Q19: =IF(AND(P19<>"",P19<>0,O19<>0,O19<>""),P19/O19,"") | S19: =S18/I16 -> #DIV/0!
F20: Конверсия план/факт | I20: ='Ялта, Ленина, 18'!I20 -> 0.257 | J20: =N50 | K20: =J20/I20 -> #VALUE! | L20: =IF(AND(K8<>0,I14<>0,I50<>0),(I50*N50+(I50/K8-I50)*I20)/(I50/K8),0) -> 0 | M20: =IF(AND(I20<>"",I20<>0,L20<>"",L20<>0),L20/I20,"") | N20: =IF(AND(J20<>0,J20<>"",I20<>0,I20<>""),L20-I20,"") | P20: =IF(AND(O20<>"",O20<>0,L20<>"",L20<>0),-O20+L20,"") | Q20: =IF(AND(P20<>"",P20<>0,O20<>0,O20<>""),P20/O20,"")
B22: Факт продаж за месяц | O22: % выполнения дневного плана | P22: Раcпределение плана по дням
B23: Дата | C23: День недели | D23: Выручка (руб) | E23: Кол-во единиц (шт.) | F23: Средняя стоимость изделия (руб.) | G23: Количество чеков (шт.) | H23: Средняя сумма чека (руб.) | I23: Трафик | J23: Длина чека (шт.) | K23: Запасной | L23: Запасной | M23: Запасной | N23: Конверсия (%) | P23: выручка, план | Q23: кол-во ед, план | R23: Кол-во чеков, план | S23: выручка, скорректир.план | T23: кол-во ед, скорр. план | U23: кол-во чеков, скорр. план | V23: Коэфф. Дня Недели | W23: Специфика месяца
B24: 1 | C24: 2 | D24: 3 | E24: 4 | F24: 5 | G24: 6 | H24: 7 | I24: 8 | J24: 9 | K24: 10 | L24: 11 | M24: 12 | N24: 13 | P24: 1 | Q24: 2 | R24: 3 | S24: 4 | T24: 5 | U24: 6 | V24: 10 | W24: 11
A25: 1 | B25: 45663 | C25: пн | D25: 37861 | E25: 12 | F25: =IF(AND(E25<>"",E25<>0),D25/E25,"") -> 3155.0833 | G25: 9 | H25: =IF(AND(G25<>"",G25<>0),D25/G25,"") -> 4206.7778 | J25: =IF(AND(G25<>"",G25<>0),E25/G25,"") -> 1.3333333 | N25: =IF(AND(I25<>"",I25<>0),G25/I25,"") | O25: =D25/P25 -> 0.55857231 | P25: =$I$8*V25*W25/SUMPRODUCT($W$25:$W$57,$V$25:$V$57) -> 67781.734 | Q25: =$I$9*V25*W25/SUMPRODUCT($W$25:$W$57,$V$25:$V$57) -> 18.369034 | R25: =IF($I$12="","",Q25/$I$12) -> 11.480646 | S25: =IF(W25<>"",IF(D25<>"",D25,($I$8-SUM($S24:S$25))*V25*W25/SUMPRODUCT($W25:$W$57,$V25:$V$57)),"") -> 37861 | T25: =IF(W25<>"",IF(E25<>"",E25,($I$9-SUM($T24:T$25))*V25*W25/SUMPRODUCT($W25:$W$57,$V25:$V$57)),"") -> 12 | U25: =IF(W25<>"",IF($I$12<>"",IF(G25<>"",G25,($I$9/$I$12-SUM($U24:U$25))*V25*W25/SUMPRODUCT($W25:$W$57,$V25:$V$57)),""),"") -> 9 | V25: 1.2 | W25: 1.2
A26: 2 | B26: 45664 | C26: вт | D26: 65247 | E26: 16 | F26: =IF(AND(E26<>"",E26<>0),D26/E26,"") -> 4077.9375 | G26: 10 | H26: =IF(AND(G26<>"",G26<>0),D26/G26,"") -> 6524.7 | J26: =IF(AND(G26<>"",G26<>0),E26/G26,"") -> 1.6 | N26: =IF(AND(I26<>"",I26<>0),G26/I26,"") | O26: =D26/P26 -> 0.96260446 | P26: =$I$8*V26*W26/SUMPRODUCT($W$25:$W$57,$V$25:$V$57) -> 67781.734 | Q26: =$I$9*V26*W26/SUMPRODUCT($W$25:$W$57,$V$25:$V$57) -> 18.369034 | R26: =IF($I$12="","",Q26/$I$12) -> 11.480646 | S26: =IF(W26<>"",IF(D26<>"",D26,($I$8-SUM($S$25:S25))*V26*W26/SUMPRODUCT($W26:$W$57,$V26:$V$57)),"") -> 65247 | T26: =IF(W26<>"",IF(E26<>"",E26,($I$9-SUM($T$25:T25))*V26*W26/SUMPRODUCT($W26:$W$57,$V26:$V$57)),"") -> 16 | U26: =IF(W26<>"",IF($I$12<>"",IF(G26<>"",G26,($I$9/$I$12-SUM($U$25:U25))*V26*W26/SUMPRODUCT($W26:$W$57,$V26:$V$57)),""),"") -> 10 | V26: 1.2 | W26: 1.2
A27: 3 | B27: 45665 | C27: ср | D27: 64146 | F27: =IF(AND(E27<>"",E27<>0),D27/E27,"") | H27: =IF(AND(G27<>"",G27<>0),D27/G27,"") | J27: =IF(AND(G27<>"",G27<>0),E27/G27,"") | N27: =IF(AND(I27<>"",I27<>0),G27/I27,"") | O27: =D27/P27 -> 0.94636115 | P27: =$I$8*V27*W27/SUMPRODUCT($W$25:$W$57,$V$25:$V$57) -> 67781.734 | Q27: =$I$9*V27*W27/SUMPRODUCT($W$25:$W$57,$V$25:$V$57) -> 18.369034 | R27: =IF($I$12="","",Q27/$I$12) -> 11.480646 | S27: =IF(W27<>"",IF(D27<>"",D27,($I$8-SUM($S$25:S26))*V27*W27/SUMPRODUCT($W27:$W$57,$V27:$V$57)),"") -> 64146 | T27: =IF(W27<>"",IF(E27<>"",E27,($I$9-SUM($T$25:T26))*V27*W27/SUMPRODUCT($W27:$W$57,$V27:$V$57)),"") -> 19.124305 | U27: =IF(W27<>"",IF($I$12<>"",IF(G27<>"",G27,($I$9/$I$12-SUM($U$25:U26))*V27*W27/SUMPRODUCT($W27:$W$57,$V27:$V$57)),""),"") -> 11.823039 | V27: 1.2 | W27: 1.2
A28: 4 | B28: 45666 | C28: чт | D28: 93262 | E28: 27 | F28: =IF(AND(E28<>"",E28<>0),D28/E28,"") -> 3454.1481 | G28: 5 | H28: =IF(AND(G28<>"",G28<>0),D28/G28,"") -> 18652.4 | J28: =IF(AND(G28<>"",G28<>0),E28/G28,"") -> 5.4 | N28: =IF(AND(I28<>"",I28<>0),G28/I28,"") | O28: =D28/P28 -> 1.9813196 | P28: =$I$8*V28*W28/SUMPRODUCT($W$25:$W$57,$V$25:$V$57) -> 47070.649 | Q28: =$I$9*V28*W28/SUMPRODUCT($W$25:$W$57,$V$25:$V$57) -> 12.756273 | R28: =IF($I$12="","",Q28/$I$12) -> 7.9726709 | S28: =IF(W28<>"",IF(D28<>"",D28,($I$8-SUM($S$25:S27))*V28*W28/SUMPRODUCT($W28:$W$57,$V28:$V$57)),"") -> 93262 | T28: =IF(W28<>"",IF(E28<>"",E28,($I$9-SUM($T$25:T27))*V28*W28/SUMPRODUCT($W28:$W$57,$V28:$V$57)),"") -> 27 | U28: =IF(W28<>"",IF($I$12<>"",IF(G28<>"",G28,($I$9/$I$12-SUM($U$25:U27))*V28*W28/SUMPRODUCT($W28:$W$57,$V28:$V$57)),""),"") -> 5 | V28: 1 | W28: 1
A29: 5 | B29: 45667 | C29: пт | D29: 39739 | E29: 10 | F29: =IF(AND(E29<>"",E29<>0),D29/E29,"") -> 3973.9 | G29: 7 | H29: =IF(AND(G29<>"",G29<>0),D29/G29,"") -> 5677 | J29: =IF(AND(G29<>"",G29<>0),E29/G29,"") -> 1.4285714 | N29: =IF(AND(I29<>"",I29<>0),G29/I29,"") | O29: =D29/P29 -> 0.8442416 | P29: =$I$8*V29*W29/SUMPRODUCT($W$25:$W$57,$V$25:$V$57) -> 47070.649 | Q29: =$I$9*V29*W29/SUMPRODUCT($W$25:$W$57,$V$25:$V$57) -> 12.756273 | R29: =IF($I$12="","",Q29/$I$12) -> 7.9726709 | S29: =IF(W29<>"",IF(D29<>"",D29,($I$8-SUM($S$25:S28))*V29*W29/SUMPRODUCT($W29:$W$57,$V29:$V$57)),"") -> 39739 | T29: =IF(W29<>"",IF(E29<>"",E29,($I$9-SUM($T$25:T28))*V29*W29/SUMPRODUCT($W29:$W$57,$V29:$V$57)),"") -> 10 | U29: =IF(W29<>"",IF($I$12<>"",IF(G29<>"",G29,($I$9/$I$12-SUM($U$25:U28))*V29*W29/SUMPRODUCT($W29:$W$57,$V29:$V$57)),""),"") -> 7 | V29: 1 | W29: 1
A30: 6 | B30: 45668 | C30: сб | D30: 4692 | E30: 1 | F30: =IF(AND(E30<>"",E30<>0),D30/E30,"") -> 4692 | G30: 1 | H30: =IF(AND(G30<>"",G30<>0),D30/G30,"") -> 4692 | J30: =IF(AND(G30<>"",G30<>0),E30/G30,"") -> 1 | N30: =IF(AND(I30<>"",I30<>0),G30/I30,"") | O30: =D30/P30 -> 0.099679952 | P30: =$I$8*V30*W30/SUMPRODUCT($W$25:$W$57,$V$25:$V$57) -> 47070.649 | Q30: =$I$9*V30*W30/SUMPRODUCT($W$25:$W$57,$V$25:$V$57) -> 12.756273 | R30: =IF($I$12="","",Q30/$I$12) -> 7.9726709 | S30: =IF(W30<>"",IF(D30<>"",D30,($I$8-SUM($S$25:S29))*V30*W30/SUMPRODUCT($W30:$W$57,$V30:$V$57)),"") -> 4692 | T30: =IF(W30<>"",IF(E30<>"",E30,($I$9-SUM($T$25:T29))*V30*W30/SUMPRODUCT($W30:$W$57,$V30:$V$57)),"") -> 1 | U30: =IF(W30<>"",IF($I$12<>"",IF(G30<>"",G30,($I$9/$I$12-SUM($U$25:U29))*V30*W30/SUMPRODUCT($W30:$W$57,$V30:$V$57)),""),"") -> 1 | V30: 1 | W30: 1
A31: 7 | B31: 45670 | C31: пн | D31: 18667 | E31: 4 | F31: =IF(AND(E31<>"",E31<>0),D31/E31,"") -> 4666.75 | G31: 3 | H31: =IF(AND(G31<>"",G31<>0),D31/G31,"") -> 6222.3333 | J31: =IF(AND(G31<>"",G31<>0),E31/G31,"") -> 1.3333333 | N31: =IF(AND(I31<>"",I31<>0),G31/I31,"") | O31: =D31/P31 -> 0.61964702 | P31: =$I$8*V31*W31/SUMPRODUCT($W$25:$W$57,$V$25:$V$57) -> 30125.215 | Q31: =$I$9*V31*W31/SUMPRODUCT($W$25:$W$57,$V$25:$V$57) -> 8.164015 | R31: =IF($I$12="","",Q31/$I$12) -> 5.1025094 | S31: =IF(W31<>"",IF(D31<>"",D31,($I$8-SUM($S$25:S30))*V31*W31/SUMPRODUCT($W31:$W$57,$V31:$V$57)),"") -> 18667 | T31: =IF(W31<>"",IF(E31<>"",E31,($I$9-SUM($T$25:T30))*V31*W31/SUMPRODUCT($W31:$W$57,$V31:$V$57)),"") -> 4 | U31: =IF(W31<>"",IF($I$12<>"",IF(G31<>"",G31,($I$9/$I$12-SUM($U$25:U30))*V31*W31/SUMPRODUCT($W31:$W$57,$V31:$V$57)),""),"") -> 3 | V31: 0.8 | W31: 0.8
A32: 8 | B32: 45671 | C32: вт | D32: 0 | E32: 0 | F32: =IF(AND(E32<>"",E32<>0),D32/E32,"") | G32: 0 | H32: =IF(AND(G32<>"",G32<>0),D32/G32,"") | J32: =IF(AND(G32<>"",G32<>0),E32/G32,"") | N32: =IF(AND(I32<>"",I32<>0),G32/I32,"") | O32: =D32/P32 -> 0 | P32: =$I$8*V32*W32/SUMPRODUCT($W$25:$W$57,$V$25:$V$57) -> 47070.649 | Q32: =$I$9*V32*W32/SUMPRODUCT($W$25:$W$57,$V$25:$V$57) -> 12.756273 | R32: =IF($I$12="","",Q32/$I$12) -> 7.9726709 | S32: =IF(W32<>"",IF(D32<>"",D32,($I$8-SUM($S$25:S31))*V32*W32/SUMPRODUCT($W32:$W$57,$V32:$V$57)),"") -> 0 | T32: =IF(W32<>"",IF(E32<>"",E32,($I$9-SUM($T$25:T31))*V32*W32/SUMPRODUCT($W32:$W$57,$V32:$V$57)),"") -> 0 | U32: =IF(W32<>"",IF($I$12<>"",IF(G32<>"",G32,($I$9/$I$12-SUM($U$25:U31))*V32*W32/SUMPRODUCT($W32:$W$57,$V32:$V$57)),""),"") -> 0 | V32: 1 | W32: 1
