Workbook
Name маг: NA()

Sheet Ялта, Ленина, 18
B1: =TODAY()-1 -> 45969
B2: (отчетная дата)
C3: Осталось до выполнения плана!!! | I3: =График!B3 -> ул. Набережная Ленина, 18
C4: =I8-D56 -> 974460.8 | E4: =IF(I8<>0, C4/I8, 0) -> 0.40168016
D5: =C4/(I14-J14) -> #DIV/0!
F6: Целевые показатели
F7: Показатель | I7: План | J7: Факт | K7: % выполнения | L7: Прогноз выполнения | M7: % выполнения по прогнозу | N7: Отклонение | O7: Факт аналогичного месяца прошлого года | P7: Отклонение LFL
F8: Выручка | I8: =I11*I12*I13 -> 2425962 | J8: =D56 -> 1451501.2 | K8: =IF(AND(I8<>"",I8<>0,J8<>""),J8/I8,"") -> 0.59831984 | L8: =IF(SUMIF($D$25:$D$55,">=0",$P$25:$P$55)<>0,I8*D56/SUMIF($D$25:$D$55,">=0",$P$25:$P$55),0) -> 1451501.2 | M8: =IF(AND(I8<>"", I8<>0, L8<>"", L8<>0), L8/I8, "") -> 0.59831984 | N8: =IF(AND(J8<>0, J8<>"", I8<>0, I8<>""), L8-I8, "") -> -974460.8 | P8: =IF(AND(O8<>"", O8<>0, L8<>"", L8<>0), -O8+L8, "") | Q8: =IF(AND(P8<>"", P8<>0, O8<>0, O8<>""), P8/O8, "")
F9: Кол-во изделий | I9: =I8/I11 -> 411.18 | J9: =E56 -> 243 | K9: =IF(AND(I9<>"", I9<>0, J9<>""), J9/I9, "") -> 0.59098205 | L9: =IF(SUMIF($E$25:$E$55, ">=0", $Q$25:$Q$55)<>0, I9*E56/SUMIF($E$25:$E$55, ">=0", $Q$25:$Q$55), 0) -> 253.53162 | M9: =IF(AND(I9<>"", I9<>0, L9<>"", L9<>0), L9/I9, "") -> 0.61659521 | N9: =IF(AND(J9<>0, J9<>"", I9<>0, I9<>""), L9-I9, "") -> -157.64838 | O9: =O8/O11 -> #DIV/0! | P9: =IF(AND(O9<>"", O9<>0, L9<>"", L9<>0), -O9+L9, "") -> #DIV/0! | Q9: =IF(AND(P9<>"", P9<>0, O9<>0, O9<>""), P9/O9, "") -> #DIV/0!
F10: Средний чек | I10: =I11*I12 -> 10502 | J10: =H56 -> 10294.335 | K10: =IF(AND(I10<>"", I10<>0, J10<>""), J10/I10, "") -> 0.98022612 | L10: =J10 -> 10294.335 | M10: =IF(AND(I10<>"", I10<>0, L10<>"", L10<>0), L10/I10, "") -> 0.98022612 | N10: =IF(AND(J10<>0, J10<>"", I10<>0, I10<>""), L10-I10, "") -> -207.66525 | O10: =O11*O12 -> 0 | P10: =IF(AND(O10<>"", O10<>0, L10<>"", L10<>0), -O10+L10, "") | Q10: =IF(AND(P10<>"", P10<>0, O10<>0, O10<>""), P10/O10, "") | S10: =L23 -> IS | V10: =M23 -> Agafi
F11: Средняя стоимость изделия | I11: 5900 | J11: =F56 -> 5973.256 | K11: =IF(AND(I11<>"", I11<>0, J11<>""), J11/I11, "") -> 1.0124163 | L11: =IF(L9>0, L8/L9, "") -> 5725.1289 | M11: =IF(AND(I11<>"", I11<>0, L11<>"", L11<>0), L11/I11, "") -> 0.97036083 | N11: =IF(AND(J11<>0, J11<>"", I11<>0, I11<>""), L11-I11, "") -> -174.87109 | P11: =IF(AND(O11<>"", O11<>0, L11<>"", L11<>0), -O11+L11, "") | Q11: =IF(AND(P11<>"", P11<>0, O11<>0, O11<>""), P11/O11, "")
F12: Длина чека | I12: 1.78 | J12: =J56 -> 1.7234043 | K12: =IF(AND(I12<>"", I12<>0, J12<>""), J12/I12, "") -> 0.96820464 | L12: =J12 -> 1.7234043 | M12: =IF(AND(I12<>"", I12<>0, L12<>"", L12<>0), L12/I12, "") -> 0.96820464 | N12: =IF(AND(J12<>0, J12<>"", I12<>0, I12<>""), L12-I12, "") -> -0.056595745 | P12: =IF(AND(O12<>"", O12<>0, L12<>"", L12<>0), -O12+L12, "") | Q12: =IF(AND(P12<>"", P12<>0, O12<>0, O12<>""), P12/O12, "") | S12: 510000 | T12: =L56 -> 63621 | V12: 480000 | W12: =M56 -> 91314
F13: Кол-во чеков | I13: =I17*I20 -> 231 | J13: =G56 -> 141 | K13: =IF(AND(I13<>"", I13<>0, J13<>""), J13/I13, "") -> 0.61038961 | L13: =IF(SUMIF($G$25:$G$55, ">=0", $R$25:$R$55)<>0, I13*G56/SUMIF($G$25:$G$55, ">=0", $R$25:$R$55), "") -> 141 | M13: =IF(AND(I13<>"", I13<>0, L13<>"", L13<>0), L13/I13, "") -> 0.61038961 | N13: =IF(AND(J13<>0, J13<>"", I13<>0, I13<>""), L13-I13, "") -> -90 | P13: =IF(AND(O13<>"", O13<>0, L13<>"", L13<>0), -O13+L13, "") | Q13: =IF(AND(P13<>"", P13<>0, O13<>0, O13<>""), P13/O13, "") | S13: =T12/S12 -> 0.12474706 | T13: =S13/J14*I14 -> 0.12474706 | V13: =W12/V12 -> 0.1902375 | W13: =V13/J14*I14 -> 0.1902375
F14: Кол-во смен | I14: 31 | J14: 31 | K14: =IF(AND(I14<>"", I14<>0, J14<>""), J14/I14, "") -> 1 | L14: =I14 -> 31 | M14: =IF(AND(I14<>"", I14<>0, L14<>"", L14<>0), L14/I14, "") -> 1 | N14: =IF(AND(J14<>0, J14<>"", I14<>0, I14<>""), L14-I14, "") -> 0 | P14: =IF(AND(O14<>"", O14<>0, L14<>"", L14<>0), -O14+L14, "") | Q14: =IF(AND(P14<>"", P14<>0, O14<>0, O14<>""), P14/O14, "")
F15: Средние продажи в смену | I15: =I8/I14 -> 78256.839 | J15: =J8/J14 -> 46822.619 | K15: =IF(AND(I15<>"", I15<>0, J15<>""), J15/I15, "") -> 0.59831984 | L15: =J15 -> 46822.619 | M15: =IF(AND(I15<>"", I15<>0, L15<>"", L15<>0), L15/I15, "") -> 0.59831984 | N15: =IF(AND(J15<>0, J15<>"", I15<>0, I15<>""), L15-I15, "") -> -31434.219 | P15: =IF(AND(O15<>"", O15<>0, L15<>"", L15<>0), -O15+L15, "") | Q15: =IF(AND(P15<>"", P15<>0, O15<>0, O15<>""), P15/O15, "")
F16: Отставание/Перевыполнение | J16: =J8-I15*J14 -> -974460.8 | K16: =IF(AND(I16<>"", I16<>0, J16<>""), J16/I16, "") | L16: =J16 -> -974460.8 | M16: =IF(AND(I16<>"", I16<>0, L16<>"", L16<>0), L16/I16, "") | N16: =IF(AND(J16<>0, J16<>"", I16<>0, I16<>""), L16-I16, "") | P16: =IF(AND(O16<>"", O16<>0, L16<>"", L16<>0), -O16+L16, "") | Q16: =IF(AND(P16<>"", P16<>0, O16<>0, O16<>""), P16/O16, "") | S16: =K23 -> UNOde50
F17: Трафик | I17: 2100 | J17: =I56 -> 1794.35 | K17: =IF(AND(I17<>"", I17<>0, J17<>""), J17/I17, "") -> 0.85445238 | L17: =J17/J14*I14 -> 1794.35 | M17: =IF(AND(I17<>"", I17<>0, L17<>"", L17<>0), L17/I17, "") -> 0.85445238 | N17: =IF(AND(J17<>0, J17<>"", I17<>0, I17<>""), L17-I17, "") -> -305.65 | P17: =IF(AND(O17<>"", O17<>0, L17<>"", L17<>0), -O17+L17, "") | Q17: =IF(AND(P17<>"", P17<>0, O17<>0, O17<>""), P17/O17, "")
K18: =IF(AND(I18<>"", I18<>0, J18<>""), J18/I18, "") | L18: =J18 -> 0 | M18: =IF(AND(I18<>"", I18<>0, L18<>"", L18<>0), L18/I18, "") | N18: =IF(AND(J18<>0, J18<>"", I18<>0, I18<>""), L18-I18, "") | O18: 0 | P18: =IF(AND(O18<>"", O18<>0, L18<>"", L18<>0), -O18+L18, "") | Q18: =IF(AND(P18<>"", P18<>0, O18<>0, O18<>""), P18/O18, "") | S18: 1020000 | T18: =K56 -> 228147.2
K19: =IF(AND(I19<>"", I19<>0, J19<>""), J19/I19, "") | L19: =J19 -> 0 | M19: =IF(AND(I19<>"", I19<>0, L19<>"", L19<>0), L19/I19, "") | N19: =IF(AND(J19<>0, J19<>"", I19<>0, I19<>""), L19-I19, "") | O19: 0 | P19: =IF(AND(O19<>"", O19<>0, L19<>"", L19<>0), -O19+L19, "") | Q19: =IF(AND(P19<>"", P19<>0, O19<>0, O19<>""), P19/O19, "") | S19: =T18/S18 -> 0.22367373 | T19: =S19/J14*I14 -> 0.22367373
F20: Конверсия план/факт | I20: 0.11 | J20: =N56 -> 0.078579987 | K20: =J20/I20 -> 0.71436352 | L20: =IF(AND(K8<>0, I14<>0, I56<>0), (I56*N56+(I56/K8-I56)*I20)/(I56/K8), 0) -> 0.091200783 | M20: =IF(AND(I20<>"", I20<>0, L20<>"", L20<>0), L20/I20, "") -> 0.82909803 | N20: =IF(AND(J20<>0, J20<>"", I20<>0, I20<>""), L20-I20, "") -> -0.018799217 | P20: =IF(AND(O20<>"", O20<>0, L20<>"", L20<>0), -O20+L20, "") | Q20: =IF(AND(P20<>"", P20<>0, O20<>0, O20<>""), P20/O20, "")
A22: Факт продаж за месяц | O22: % выполнения дневного плана | P22: Раcпределение плана по дням
A23: Сотрудник | B23: Дата | C23: День недели | D23: Выручка (руб) | E23: Кол-во единиц (шт.) | F23: Средняя стоимость изделия (руб.) | G23: Количество чеков (шт.) | H23: Средняя сумма чека (руб.) | I23: Трафик | J23: Длина чека (шт.) | K23: UNOde50 | L23: IS | M23: Agafi | N23: Конверсия (%) | P23: выручка, план | Q23: кол-во ед, план | R23: Кол-во чеков, план | S23: выручка, скорректир.план | T23: кол-во ед, скорр. план | U23: кол-во чеков, скорр. план | V23: Коэфф. Дня Недели | W23: Специфика месяца
B24: 1 | C24: 2 | D24: 3 | E24: 4 | F24: 5 | G24: 6 | H24: 7 | I24: 8 | J24: 9 | K24: 10 | L24: 11 | M24: 12 | N24: 13 | P24: 1 | Q24: 2 | R24: 3 | S24: 4 | T24: 5 | U24: 6 | V24: 10 | W24: 11
A25: Уразгильдеева | B25: 45931 | C25: ср | D25: =35078+8792+30606 -> 74476 | E25: 10 | F25: =IF(AND(E25<>"",E25<>0),D25/E25,"") -> 7447.6 | G25: 6 | H25: =IF(AND(G25<>"",G25<>0),D25/G25,"") -> 12412.667 | I25: 52 | J25: =IF(AND(G25<>"",G25<>0),E25/G25,"") -> 1.6666667 | L25: 30606 | M25: 8792 | N25: =IF(AND(I25<>"",I25<>0),G25/I25,"") -> 0.11538462 | O25: =D25/P25 -> 0.83381527 | P25: =$I$8*V25*W25/SUMPRODUCT($W$25:$W$55,$V$25:$V$55) -> 89319.545 | Q25: =$I$9*V25*W25/SUMPRODUCT($W$25:$W$55,$V$25:$V$55) -> 15.138906 | R25: =IF($I$12="","",Q25/$I$12) -> 8.5050033 | S25: =IF(D25<>"",D25,P25) -> 74476 | T25: =IF(E25<>"",E25,Q25) -> 10 | U25: =IF(G25<>"",G25,R25) -> 6 | V25: 0.9414554 | W25: 0.9414554
A26: Рогалевич,Уразгильдеева | B26: 45932 | C26: чт | D26: 90821 | E26: 18 | F26: =IF(AND(E26<>"",E26<>0),D26/E26,"") -> 5045.6111 | G26: 10 | H26: =IF(AND(G26<>"",G26<>0),D26/G26,"") -> 9082.1 | I26: 82 | J26: =IF(AND(G26<>"",G26<>0),E26/G26,"") -> 1.8 | K26: 14992 | L26: 6203 | N26: =IF(AND(I26<>"",I26<>0),G26/I26,"") -> 0.12195122 | O26: =D26/P26 -> 1.2383318 | P26: =$I$8*V26*W26/SUMPRODUCT($W$25:$W$55,$V$25:$V$55) -> 73341.411 | Q26: =$I$9*V26*W26/SUMPRODUCT($W$25:$W$55,$V$25:$V$55) -> 12.430748 | R26: =IF($I$12="","",Q26/$I$12) -> 6.9835661 | S26: =IF(W26<>"",IF(D26<>"",D26,($I$8-SUM($S$25:S25))*V26*W26/SUMPRODUCT($W26:$W$55,$V26:$V$55)),"") -> 90821 | T26: =IF(W26<>"",IF(E26<>"",E26,($I$9-SUM($T$25:T25))*V26*W26/SUMPRODUCT($W26:$W$55,$V26:$V$55)),"") -> 18 | U26: =IF(W26<>"",IF(E26<>"",E26,($I$9-SUM($T$25:T25))*V26*W26/SUMPRODUCT($W26:$W$55,$V26:$V$55)),"") -> 18 | V26: 0.85310234 | W26: 0.85310234
A27: Рогалевич,Уразгильдеева | B27: 45933 | C27: пт | D27: =31311+14377+8190+6990 -> 60868 | E27: 11 | F27: =IF(AND(E27<>"",E27<>0),D27/E27,"") -> 5533.4545 | G27: 7 | H27: =IF(AND(G27<>"",G27<>0),D27/G27,"") -> 8695.4286 | I27: 84 | J27: =IF(AND(G27<>"",G27<>0),E27/G27,"") -> 1.5714286 | K27: 8190 | M27: 6990 | N27: =IF(AND(I27<>"",I27<>0),G27/I27,"") -> 0.083333333 | O27: =D27/P27 -> 0.82992677 | P27: =$I$8*V27*W27/SUMPRODUCT($W$25:$W$55,$V$25:$V$55) -> 73341.411 | Q27: =$I$9*V27*W27/SUMPRODUCT($W$25:$W$55,$V$25:$V$55) -> 12.430748 | R27: =IF($I$12="","",Q27/$I$12) -> 6.9835661 | S27: =IF(W27<>"",IF(D27<>"",D27,($I$8-SUM($S$25:S26))*V27*W27/SUMPRODUCT($W27:$W$55,$V27:$V$55)),"") -> 60868 | T27: =IF(W27<>"",IF(E27<>"",E27,($I$9-SUM($T$25:T26))*V27*W27/SUMPRODUCT($W27:$W$55,$V27:$V$55)),"") -> 11 | U27: =IF(W27<>"",IF(E27<>"",E27,($I$9-SUM($T$25:T26))*V27*W27/SUMPRODUCT($W27:$W$55,$V27:$V$55)),"") -> 11 | V27: 0.85310234 | W27: 0.85310234
A28: Рогалевич | B28: 45934 | C28: сб | D28: 76483 | E28: 11 | F28: =IF(AND(E28<>"",E28<>0),D28/E28,"") -> 6953 | G28: 4 | H28: =IF(AND(G28<>"",G28<>0),D28/G28,"") -> 19120.75 | I28: 81 | J28: =IF(AND(G28<>"",G28<>0),E28/G28,"") -> 2.75 | M28: 19675 | N28: =IF(AND(I28<>"",I28<>0),G28/I28,"") -> 0.049382716 | O28: =D28/P28 -> 1.0428351 | P28: =$I$8*V28*W28/SUMPRODUCT($W$25:$W$55,$V$25:$V$55) -> 73341.411 | Q28: =$I$9*V28*W28/SUMPRODUCT($W$25:$W$55,$V$25:$V$55) -> 12.430748 | R28: =IF($I$12="","",Q28/$I$12) -> 6.9835661 | S28: =IF(W28<>"",IF(D28<>"",D28,($I$8-SUM($S$25:S27))*V28*W28/SUMPRODUCT($W28:$W$55,$V28:$V$55)),"") -> 76483 | T28: =IF(W28<>"",IF(E28<>"",E28,($I$9-SUM($T$25:T27))*V28*W28/SUMPRODUCT($W28:$W$55,$V28:$V$55)),"") -> 11 | U28: =IF(W28<>"",IF(E28<>"",E28,($I$9-SUM($T$25:T27))*V28*W28/SUMPRODUCT($W28:$W$55,$V28:$V$55)),"") -> 11 | V28: 0.85310234 | W28: 0.85310234
A29: Рогалевич,Уразгильдеева | B29: 45935 | C29: вс | D29: 85724 | E29: 18 | F29: =IF(AND(E29<>"",E29<>0),D29/E29,"") -> 4762.4444 | G29: 13 | H29: =IF(AND(G29<>"",G29<>0),D29/G29,"") -> 6594.1538 | I29: 138 | J29: =IF(AND(G29<>"",G29<>0),E29/G29,"") -> 1.3846154 | L29: 12106 | N29: =IF(AND(I29<>"",I29<>0),G29/I29,"") -> 0.094202899 | O29: =D29/P29 -> 1.1773825 | P29: =$I$8*V29*W29/SUMPRODUCT($W$25:$W$55,$V$25:$V$55) -> 72808.964 | Q29: =$I$9*V29*W29/SUMPRODUCT($W$25:$W$55,$V$25:$V$55) -> 12.340502 | R29: =IF($I$12="","",Q29/$I$12) -> 6.9328665 | S29: =IF(W29<>"",IF(D29<>"",D29,($I$8-SUM($S$25:S28))*V29*W29/SUMPRODUCT($W29:$W$55,$V29:$V$55)),"") -> 85724 | T29: =IF(W29<>"",IF(E29<>"",E29,($I$9-SUM($T$25:T28))*V29*W29/SUMPRODUCT($W29:$W$55,$V29:$V$55)),"") -> 18 | U29: =IF(W29<>"",IF(E29<>"",E29,($I$9-SUM($T$25:T28))*V29*W29/SUMPRODUCT($W29:$W$55,$V29:$V$55)),"") -> 18 | V29: 0.85 | W29: 0.85
A30: Рогалевич,Уразгильдеева | B30: 45936 | C30: пн | D30: =10490+5803+58949 -> 75242 | E30: 12 | F30: =IF(AND(E30<>"",E30<>0),D30/E30,"") -> 6270.1667 | G30: 8 | H30: =IF(AND(G30<>"",G30<>0),D30/G30,"") -> 9405.25 | I30: 56 | J30: =IF(AND(G30<>"",G30<>0),E30/G30,"") -> 1.5 | K30: 10490 | L30: 5803 | N30: =IF(AND(I30<>"",I30<>0),G30/I30,"") -> 0.14285714 | O30: =D30/P30 -> 0.74664358 | P30: =$I$8*V30*W30/SUMPRODUCT($W$25:$W$55,$V$25:$V$55) -> 100773.65 | Q30: =$I$9*V30*W30/SUMPRODUCT($W$25:$W$55,$V$25:$V$55) -> 17.08028 | R30: =IF($I$12="","",Q30/$I$12) -> 9.5956629 | S30: =IF(W30<>"",IF(D30<>"",D30,($I$8-SUM($S$25:S29))*V30*W30/SUMPRODUCT($W30:$W$55,$V30:$V$55)),"") -> 75242 | T30: =IF(W30<>"",IF(E30<>"",E30,($I$9-SUM($T$25:T29))*V30*W30/SUMPRODUCT($W30:$W$55,$V30:$V$55)),"") -> 12 | U30: =IF(W30<>"",IF(E30<>"",E30,($I$9-SUM($T$25:T29))*V30*W30/SUMPRODUCT($W30:$W$55,$V30:$V$55)),"") -> 12 | V30: 1 | W30: 1
A31: Рогалевич | B31: 45937 | C31: вт | D31: 0 | F31: =IF(AND(E31<>"",E31<>0),D31/E31,"") | G31: 0 | H31: =IF(AND(G31<>"",G31<>0),D31/G31,"") | I31: 52 | J31: =IF(AND(G31<>"",G31<>0),E31/G31,"") | N31: =IF(AND(I31<>"",I31<>0),G31/I31,"") -> 0 | O31: =D31/P31 -> 0 | P31: =$I$8*V31*W31/SUMPRODUCT($W$25:$W$55,$V$25:$V$55) -> 100773.65 | Q31: =$I$9*V31*W31/SUMPRODUCT($W$25:$W$55,$V$25:$V$55) -> 17.08028 | R31: =IF($I$12="","",Q31/$I$12) -> 9.5956629 | S31: =IF(W31<>"",IF(D31<>"",D31,($I$8-SUM($S$25:S30))*V31*W31/SUMPRODUCT($W31:$W$55,$V31:$V$55)),"") -> 0 | T31: =IF(W31<>"",IF(E31<>"",E31,($I$9-SUM($T$25:T30))*V31*W31/SUMPRODUCT($W31:$W$55,$V31:$V$55)),"") -> 17.176329 | U31: =IF(W31<>"",IF(E31<>"",E31,($I$9-SUM($T$25:T30))*V31*W31/SUMPRODUCT($W31:$W$55,$V31:$V$55)),"") -> 17.176329 | V31: 1 | W31: 1
A32: Рогалевич,Уразгильдеева | B32: 45938 | C32: ср | D32: 40351 | E32: 6 | F32: =IF(AND(E32<>"",E32<>0),D32/E32,"") -> 6725.1667 | G32: 5 | H32: =IF(AND(G32<>"",G32<>0),D32/G32,"") -> 8070.2 | I32: 76 | J32: =IF(AND(G32<>"",G32<>0),E32/G32,"") -> 1.2 | N32: =IF(AND(I32<>"",I32<>0),G32/I32,"") -> 0.065789474 | O32: =D32/P32 -> 0.55018031 | P32: =$I$8*V32*W32/SUMPRODUCT($W$25:$W$55,$V$25:$V$55) -> 73341.411 | Q32: =$I$9*V32*W32/SUMPRODUCT($W$25:$W$55,$V$25:$V$55) -> 12.430748 | R32: =IF($I$12="","",Q32/$I$12) -> 6.9835661 | S32: =IF(W32<>"",IF(D32<>"",D32,($I$8-SUM($S$25:S31))*V32*W32/SUMPRODUCT($W32:$W$55,$V32:$V$55)),"") -> 40351 | T32: =IF(W32<>"",IF(E32<>"",E32,($I$9-SUM($T$25:T31))*V32*W32/SUMPRODUCT($W32:$W$55,$V32:$V$55)),"") -> 6 | U32: =IF(W32<>"",IF(E32<>"",E32,($I$9-SUM($T$25:T31))*V32*W32/SUMPRODUCT($W32:$W$55,$V32:$V$55)),"") -> 6 | V32: 0.85310234 | W32: 0.85310234
A33: Уразгильдеева | B33: 45939 | C33: чт | D33: 22026 | E33: 3 | F33: =IF(AND(E33<>"",E33<>0),D33/E33,"") -> 7342 | G33: 3 | H33: =IF(AND(G33<>"",G33<>0),D33/G33,"") -> 7342 | I33: 42 | J33: =IF(AND(G33<>"",G33<>0),E33/G33,"") -> 1 | K33: 13492 | N33: =IF(AND(I33<>"",I33<>0),G33/I33,"") -> 0.071428571 | O33: =D33/P33 -> 0.30032147 | P33: =$I$8*V33*W33/SUMPRODUCT($W$25:$W$55,$V$25:$V$55) -> 73341.411 | Q33: =$I$9*V33*W33/SUMPRODUCT($W$25:$W$55,$V$25:$V$55) -> 12.430748 | R33: =IF($I$12="","",Q33/$I$12) -> 6.9835661 | S33: =IF(W33<>"",IF(D33<>"",D33,($I$8-SUM($S$25:S32))*V33*W33/SUMPRODUCT($W33:$W$55,$V33:$V$55)),"") -> 22026 | T33: =IF(W33<>"",IF(E33<>"",E33,($I$9-SUM($T$25:T32))*V33*W33/SUMPRODUCT($W33:$W$55,$V33:$V$55)),"") -> 3 | U33: =IF(W33<>"",IF(E33<>"",E33,($I$9-SUM($T$25:T32))*V33*W33/SUMPRODUCT($W33:$W$55,$V33:$V$55)),"") -> 3 | V33: 0.85310234 | W33: 0.85310234
A34: Уразгильдеева | B34: 45940 | C34: пт | D34: 21466 | E34: 4 | F34: =IF(AND(E34<>"",E34<>0),D34/E34,"") -> 5366.5 | G34: 2 | H34: =IF(AND(G34<>"",G34<>0),D34/G34,"") -> 10733 | I34: 28 | J34: =IF(AND(G34<>"",G34<>0),E34/G34,"") -> 2 | N34: =IF(AND(I34<>"",I34<>0),G34/I34,"") -> 0.071428571 | O34: =D34/P34 -> 0.29268594 | P34: =$I$8*V34*W34/SUMPRODUCT($W$25:$W$55,$V$25:$V$55) -> 73341.411 | Q34: =$I$9*V34*W34/SUMPRODUCT($W$25:$W$55,$V$25:$V$55) -> 12.430748 | R34: =IF($I$12="","",Q34/$I$12) -> 6.9835661 | S34: =IF(W34<>"",IF(D34<>"",D34,($I$8-SUM($S$25:S33))*V34*W34/SUMPRODUCT($W34:$W$55,$V34:$V$55)),"") -> 21466 | T34: =IF(W34<>"",IF(E34<>"",E34,($I$9-SUM($T$25:T33))*V34*W34/SUMPRODUCT($W34:$W$55,$V34:$V$55)),"") -> 4 | U34: =IF(W34<>"",IF(E34<>"",E34,($I$9-SUM($T$25:T33))*V34*W34/SUMPRODUCT($W34:$W$55,$V34:$V$55)),"") -> 4 | V34: 0.85310234 | W34: 0.85310234
A35: Рогалевич | B35: 45941 | C35: сб | D35: 82347 | E35: 17 | F35: =IF(AND(E35<>"",E35<>0),D35/E35,"") -> 4843.9412 | G35: 10 | H35: =IF(AND(G35<>"",G35<>0),D35/G35,"") -> 8234.7 | I35: 72 | J35: =IF(AND(G35<>"",G35<>0),E35/G35,"") -> 1.7 | N35: =IF(AND(I35<>"",I35<>0),G35/I35,"") -> 0.13888889 | O35: =D35/P35 -> 1.12279 | P35: =$I$8*V35*W35/SUMPRODUCT($W$25:$W$55,$V$25:$V$55) -> 73341.411 | Q35: =$I$9*V35*W35/SUMPRODUCT($W$25:$W$55,$V$25:$V$55) -> 12.430748 | R35: =IF($I$12="","",Q35/$I$12) -> 6.9835661 | S35: =IF(W35<>"",IF(D35<>"",D35,($I$8-SUM($S$25:S34))*V35*W35/SUMPRODUCT($W35:$W$55,$V35:$V$55)),"") -> 82347 | T35: =IF(W35<>"",IF(E35<>"",E35,($I$9-SUM($T$25:T34))*V35*W35/SUMPRODUCT($W35:$W$55,$V35:$V$55)),"") -> 17 | U35: =IF(W35<>"",IF(E35<>"",E35,($I$9-SUM($T$25:T34))*V35*W35/SUMPRODUCT($W35:$W$55,$V35:$V$55)),"") -> 17 | V35: 0.85310234 | W35: 0.85310234
A36: Рогалевич | B36: 45942 | C36: вс | D36: 87721 | E36: 12 | F36: =IF(AND(E36<>"",E36<>0),D36/E36,"") -> 7310.0833 | G36: 5 | H36: =IF(AND(G36<>"",G36<>0),D36/G36,"") -> 17544.2 | I36: 86 | J36: =IF(AND(G36<>"",G36<>0),E36/G36,"") -> 2.4 | K36: 12816 | M36: 22783 | N36: =IF(AND(I36<>"",I36<>0),G36/I36,"") -> 0.058139535 | O36: =D36/P36 -> 1.1960637 | P36: =$I$8*V36*W36/SUMPRODUCT($W$25:$W$55,$V$25:$V$55) -> 73341.411 | Q36: =$I$9*V36*W36/SUMPRODUCT($W$25:$W$55,$V$25:$V$55) -> 12.430748 | R36: =IF($I$12="","",Q36/$I$12) -> 6.9835661 | S36: =IF(W36<>"",IF(D36<>"",D36,($I$8-SUM($S$25:S35))*V36*W36/SUMPRODUCT($W36:$W$55,$V36:$V$55)),"") -> 87721 | T36: =IF(W36<>"",IF(E36<>"",E36,($I$9-SUM($T$25:T35))*V36*W36/SUMPRODUCT($W36:$W$55,$V36:$V$55)),"") -> 12 | U36: =IF(W36<>"",IF(E36<>"",E36,($I$9-SUM($T$25:T35))*V36*W36/SUMPRODUCT($W36:$W$55,$V36:$V$55)),"") -> 12 | V36: 0.85310234 | W36: 0.85310234
A37: Рогалевич,Уразгильдеева | B37: 45943 | C37: пн | D37: 11773 | E37: 2 | F37: 5886 | G37: 2 | H37: =IF(AND(G37<>"",G37<>0),D37/G37,"") -> 5886.5 | I37: =49*0.85 -> 41.65 | J37: =IF(AND(G37<>"",G37<>0),E37/G37,"") -> 1 | N37: =IF(AND(I37<>"",I37<>0),G37/I37,"") -> 0.048019208 | O37: =D37/P37 -> 0.16052323 | P37: =$I$8*V37*W37/SUMPRODUCT($W$25:$W$55,$V$25:$V$55) -> 73341.411 | Q37: =$I$9*V37*W37/SUMPRODUCT($W$25:$W$55,$V$25:$V$55) -> 12.430748 | R37: =IF($I$12="","",Q37/$I$12) -> 6.9835661 | S37: =IF(W37<>"",IF(D37<>"",D37,($I$8-SUM($S$25:S36))*V37*W37/SUMPRODUCT($W37:$W$55,$V37:$V$55)),"") -> 11773 | T37: =IF(W37<>"",IF(E37<>"",E37,($I$9-SUM($T$25:T36))*V37*W37/SUMPRODUCT($W37:$W$55,$V37:$V$55)),"") -> 2 | U37: =IF(W37<>"",IF(E37<>"",E37,($I$9-SUM($T$25:T36))*V37*W37/SUMPRODUCT($W37:$W$55,$V37:$V$55)),"") -> 2 | V37: 0.85310234 | W37: 0.85310234
A38: Рогалевич,Уразгильдеева | B38: 45944 | C38: вт | D38: 9763 | E38: 2 | F38: =IF(AND(E38<>"",E38<>0),D38/E38,"") -> 4881.5 | G38: 2 | H38: =IF(AND(G38<>"",G38<>0),D38/G38,"") -> 4881.5 | I38: =59*0.85 -> 50.15 | J38: =IF(AND(G38<>"",G38<>0),E38/G38,"") -> 1 | N38: =IF(AND(I38<>"",I38<>0),G38/I38,"") -> 0.039880359 | O38: =D38/P38 -> 0.13311716 | P38: =$I$8*V38*W38/SUMPRODUCT($W$25:$W$55,$V$25:$V$55) -> 73341.411 | Q38: =$I$9*V38*W38/SUMPRODUCT($W$25:$W$55,$V$25:$V$55) -> 12.430748 | R38: =IF($I$12="","",Q38/$I$12) -> 6.9835661 | S38: =IF(W38<>"",IF(D38<>"",D38,($I$8-SUM($S$25:S37))*V38*W38/SUMPRODUCT($W38:$W$55,$V38:$V$55)),"") -> 9763 | T38: =IF(W38<>"",IF(E38<>"",E38,($I$9-SUM($T$25:T37))*V38*W38/SUMPRODUCT($W38:$W$55,$V38:$V$55)),"") -> 2 | U38: =IF(W38<>"",IF(E38<>"",E38,($I$9-SUM($T$25:T37))*V38*W38/SUMPRODUCT($W38:$W$55,$V38:$V$55)),"") -> 2 | V38: 0.85310234 | W38: 0.85310234
A39: Рогалевич | B39: 45945 | C39: ср | D39: 30491 | E39: 7 | F39: =IF(AND(E39<>"",E39<>0),D39/E39,"") -> 4355.8571 | G39: 2 | H39: =IF(AND(G39<>"",G39<>0),D39/G39,"") -> 15245.5 | I39: =41*0.85 -> 34.85 | J39: =IF(AND(G39<>"",G39<>0),E39/G39,"") -> 3.5 | N39: =IF(AND(I39<>"",I39<>0),G39/I39,"") -> 0.057388809 | O39: =D39/P39 -> 0.41574057 | P39: =$I$8*V39*W39/SUMPRODUCT($W$25:$W$55,$V$25:$V$55) -> 73341.411 | Q39: =$I$9*V39*W39/SUMPRODUCT($W$25:$W$55,$V$25:$V$55) -> 12.430748 | R39: =IF($I$12="","",Q39/$I$12) -> 6.9835661 | S39: =IF(W39<>"",IF(D39<>"",D39,($I$8-SUM($S$25:S38))*V39*W39/SUMPRODUCT($W39:$W$55,$V39:$V$55)),"") -> 30491 | T39: =IF(W39<>"",IF(E39<>"",E39,($I$9-SUM($T$25:T38))*V39*W39/SUMPRODUCT($W39:$W$55,$V39:$V$55)),"") -> 7 | U39: =IF(W39<>"",IF(E39<>"",E39,($I$9-SUM($T$25:T38))*V39*W39/SUMPRODUCT($W39:$W$55,$V39:$V$55)),"") -> 7 | V39: 0.85310234 | W39: 0.85310234
A40: Рогалевич | B40: 45946 | C40: чт | D40: 22984.2 | E40: 4 | F40: =IF(AND(E40<>"",E40<>0),D40/E40,"") -> 5746.05 | G40: 4 | H40: =IF(AND(G40<>"",G40<>0),D40/G40,"") -> 5746.05 | I40: =31*0.85 -> 26.35 | J40: =IF(AND(G40<>"",G40<>0),E40/G40,"") -> 1 | K40: 8811.2 | N40: =IF(AND(I40<>"",I40<>0),G40/I40,"") -> 0.15180266 | O40: =D40/P40 -> 0.31338639 | P40: =$I$8*V40*W40/SUMPRODUCT($W$25:$W$55,$V$25:$V$55) -> 73341.411 | Q40: =$I$9*V40*W40/SUMPRODUCT($W$25:$W$55,$V$25:$V$55) -> 12.430748 | R40: =IF($I$12="","",Q40/$I$12) -> 6.9835661 | S40: =IF(W40<>"",IF(D40<>"",D40,($I$8-SUM($S$25:S39))*V40*W40/SUMPRODUCT($W40:$W$55,$V40:$V$55)),"") -> 22984.2 | T40: =IF(W40<>"",IF(E40<>"",E40,($I$9-SUM($T$25:T39))*V40*W40/SUMPRODUCT($W40:$W$55,$V40:$V$55)),"") -> 4 | U40: =IF(W40<>"",IF(E40<>"",E40,($I$9-SUM($T$25:T39))*V40*W40/SUMPRODUCT($W40:$W$55,$V40:$V$55)),"") -> 4 | V40: 0.85310234 | W40: 0.85310234
A41: Рогалевич,Уразгильдеева | B41: 45947 | C41: пт | D41: 68088 | E41: 13 | F41: =IF(AND(E41<>"",E41<>0),D41/E41,"") -> 5237.5385 | G41: 9 | H41: =IF(AND(G41<>"",G41<>0),D41/G41,"") -> 7565.3333 | I41: =79*0.85 -> 67.15 | J41: =IF(AND(G41<>"",G41<>0),E41/G41,"") -> 1.4444444 | M41: 7590 | N41: =IF(AND(I41<>"",I41<>0),G41/I41,"") -> 0.13402829 | O41: =D41/P41 -> 0.83413926 | P41: =$I$8*V41*W41/SUMPRODUCT($W$25:$W$55,$V$25:$V$55) -> 81626.658 | Q41: =$I$9*V41*W41/SUMPRODUCT($W$25:$W$55,$V$25:$V$55) -> 13.835027 | R41: =IF($I$12="","",Q41/$I$12) -> 7.772487 | S41: =IF(W41<>"",IF(D41<>"",D41,($I$8-SUM($S$25:S40))*V41*W41/SUMPRODUCT($W41:$W$55,$V41:$V$55)),"") -> 68088 | T41: =IF(W41<>"",IF(E41<>"",E41,($I$9-SUM($T$25:T40))*V41*W41/SUMPRODUCT($W41:$W$55,$V41:$V$55)),"") -> 13 | U41: =IF(W41<>"",IF(E41<>"",E41,($I$9-SUM($T$25:T40))*V41*W41/SUMPRODUCT($W41:$W$55,$V41:$V$55)),"") -> 13 | V41: 0.9 | W41: 0.9
...

Sheet Конкурс
A1: Сотрудник | B1: Длина чека | C1: КВП
D2: 9 | E2: 10 | F2: 11 | G2: 12 | H2: 13 | I2: 14 | J2: 15 | K2: 16 | L2: 17 | M2: 18 | N2: 19 | O2: 20 | P2: 21 | Q2: 22 | R2: 23 | S2: 24 | T2: 25 | U2: 26 | V2: 27 | W2: 28 | X2: 29 | Y2: 30 | Z2: Итого
A3: =График!B29 -> Рогалевич Ирина | B3: ='Рогалевич И. Е. '!J12 -> 1.8024691 | C3: ='Рогалевич И. Е. '!K8 -> 0.63847531 | Z3: =SUM(D3:Y3) -> 0
A4: =График!B28 -> Уразгильдеева Екатерина | B4: ='Уразгильдеева Е. Р. '!J12 -> 1.6166667 | C4: ='Уразгильдеева Е. Р. '!K8 -> 0.54797264 | Z4: =SUM(D4:Y4) -> 0
A5: =График!B27 -> Арапова Анна-Мария | B5: ='[1]Яковенко А. К'!J12 -> #REF! | C5: ='[1]Яковенко А. К'!K8 -> #REF! | Z5: =SUM(D5:Y5) -> 0

Sheet Св. по пок.
A1: 1-20.08
A2: Показатель | D2: ='Ялта, Ленина, 18'!I3 -> ул. Набережная Ленина, 18 | G2: =График!B29 -> Рогалевич Ирина | J2: =График!B28 -> Уразгильдеева Екатерина | M2: =График!B27 -> Арапова Анна-Мария
D3: Факт | F3: Прогноз | G3: Факт | I3: Прогноз | J3: Факт | L3: Прогноз | M3: Факт | O3: Прогноз
A4: Выручка | D4: ='Ялта, Ленина, 18'!K8 -> 0.59831984 | E4: ='Ялта, Ленина, 18'!J8 -> 1451501.2 | F4: ='Ялта, Ленина, 18'!M8 -> 0.59831984 | G4: ='Рогалевич И. Е. '!K8 -> 0.63847531 | H4: ='Рогалевич И. Е. '!J8 -> 861672.2 | I4: ='Рогалевич И. Е. '!M8 -> 0.69168158 | J4: ='Уразгильдеева Е. Р. '!K8 -> 0.54797264 | K4: ='Уразгильдеева Е. Р. '!J8 -> 589829 | L4: ='Уразгильдеева Е. Р. '!M8 -> 0.5768133 | M4: ='[1]Яковенко А. К'!K8 -> #REF! | N4: ='[1]Яковенко А. К'!J8 -> #REF! | O4: ='[1]Яковенко А. К'!M8 -> #REF!
A5: Кол-во изделий | D5: ='Ялта, Ленина, 18'!K9 -> 0.59098205 | E5: ='Ялта, Ленина, 18'!J9 -> 243 | F5: ='Ялта, Ленина, 18'!M9 -> 0.61659521 | G5: ='Рогалевич И. Е. '!K9 -> 0.63827361 | H5: ='Рогалевич И. Е. '!J9 -> 146 | I5: ='Рогалевич И. Е. '!M9 -> 0.69146308 | J5: ='Уразгильдеева Е. Р. '!K9 -> 0.53168756 | K5: ='Уразгильдеева Е. Р. '!J9 -> 97 | L5: ='Уразгильдеева Е. Р. '!M9 -> 0.55967111 | M5: ='[1]Яковенко А. К'!K9 -> #REF! | N5: ='[1]Яковенко А. К'!J9 -> #REF! | O5: ='[1]Яковенко А. К'!M9 -> #REF!
A6: Средний чек | D6: ='Ялта, Ленина, 18'!K10 -> 0.98022612 | E6: ='Ялта, Ленина, 18'!J10 -> 10294.335 | F6: ='Ялта, Ленина, 18'!M10 -> 0.98022612 | G6: ='Рогалевич И. Е. '!K10 -> 1.0129431 | H6: ='Рогалевич И. Е. '!J10 -> 10637.928 | I6: ='Рогалевич И. Е. '!M10 -> 1.0129431 | J6: ='Уразгильдеева Е. Р. '!K10 -> 0.93605821 | K6: ='Уразгильдеева Е. Р. '!J10 -> 9830.4833 | L6: ='Уразгильдеева Е. Р. '!M10 -> 0.93605821 | M6: ='[1]Яковенко А. К'!K10 -> #REF! | N6: ='[1]Яковенко А. К'!J10 -> #REF! | O6: ='[1]Яковенко А. К'!M10 -> #REF!
A7: Средняя стоимость изделия | D7: ='Ялта, Ленина, 18'!K11 -> 1.0124163 | E7: ='Ялта, Ленина, 18'!J11 -> 5973.256 | F7: ='Ялта, Ленина, 18'!M11 -> 0.97036083 | G7: ='Рогалевич И. Е. '!K11 -> 1.000316 | H7: ='Рогалевич И. Е. '!J11 -> 5901.8644 | I7: ='Рогалевич И. Е. '!M11 -> 1.000316 | J7: ='Уразгильдеева Е. Р. '!K11 -> 1.030629 | K7: ='Уразгильдеева Е. Р. '!J11 -> 6080.7113 | L7: ='Уразгильдеева Е. Р. '!M11 -> 1.030629 | M7: ='[1]Яковенко А. К'!K11 -> #REF! | N7: ='[1]Яковенко А. К'!J11 -> #REF! | O7: ='[1]Яковенко А. К'!M11 -> #REF!
A8: Длина чека | D8: ='Ялта, Ленина, 18'!K12 -> 0.96820464 | E8: ='Ялта, Ленина, 18'!J12 -> 1.7234043 | F8: ='Ялта, Ленина, 18'!M12 -> 0.96820464 | G8: ='Рогалевич И. Е. '!K12 -> 1.0126231 | H8: ='Рогалевич И. Е. '!J12 -> 1.8024691 | I8: ='Рогалевич И. Е. '!M12 -> 1.0126231 | J8: ='Уразгильдеева Е. Р. '!K12 -> 0.9082397 | K8: ='Уразгильдеева Е. Р. '!J12 -> 1.6166667 | L8: ='Уразгильдеева Е. Р. '!M12 -> 0.9082397 | M8: ='[1]Яковенко А. К'!K12 -> #REF! | N8: ='[1]Яковенко А. К'!J12 -> #REF! | O8: ='[1]Яковенко А. К'!M12 -> #REF!
A9: Кол-во чеков | D9: ='Ялта, Ленина, 18'!K13 -> 0.61038961 | E9: ='Ялта, Ленина, 18'!J13 -> 141 | F9: ='Ялта, Ленина, 18'!M13 -> 0.61038961 | G9: ='Рогалевич И. Е. '!K13 -> 0.63031705 | H9: ='Рогалевич И. Е. '!J13 -> 81 | I9: ='Рогалевич И. Е. '!M13 -> 0.68284347 | J9: ='Уразгильдеева Е. Р. '!K13 -> 0.58540444 | K9: ='Уразгильдеева Е. Р. '!J13 -> 60 | L9: ='Уразгильдеева Е. Р. '!M13 -> 0.6162152 | M9: ='[1]Яковенко А. К'!K13 -> #REF! | N9: ='[1]Яковенко А. К'!J13 -> #REF! | O9: ='[1]Яковенко А. К'!M13 -> #REF!
A10: Кол-во смен план/отработано | D10: ='Ялта, Ленина, 18'!K14 -> 1 | E10: ='Ялта, Ленина, 18'!J14 -> 31 | G10: ='Рогалевич И. Е. '!K14 -> 1 | H10: ='Рогалевич И. Е. '!J14 -> 26 | J10: ='Уразгильдеева Е. Р. '!K14 -> 1 | K10: ='Уразгильдеева Е. Р. '!J14 -> 20 | M10: ='[1]Яковенко А. К'!K14 -> #REF! | N10: ='[1]Яковенко А. К'!J14 -> #REF!
A11: Средние продажи в смену | D11: ='Ялта, Ленина, 18'!K15 -> 0.59831984 | E11: ='Ялта, Ленина, 18'!J15 -> 46822.619 | F11: ='Ялта, Ленина, 18'!M15 -> 0.59831984 | G11: ='Рогалевич И. Е. '!K15 -> 0.42349319 | H11: ='Рогалевич И. Е. '!J15 -> 33141.238 | I11: ='Рогалевич И. Е. '!M15 -> 0.42349319 | J11: ='Уразгильдеева Е. Р. '!K15 -> 0.3768546 | K11: ='Уразгильдеева Е. Р. '!J15 -> 29491.45 | L11: ='Уразгильдеева Е. Р. '!M15 -> 0.3768546 | M11: ='[1]Яковенко А. К'!K15 -> #REF! | N11: ='[1]Яковенко А. К'!J15 -> #REF! | O11: ='[1]Яковенко А. К'!M15 -> #REF!
A12: Трафик | D12: ='Ялта, Ленина, 18'!K17 -> 0.85445238 | E12: ='Ялта, Ленина, 18'!J17 -> 1794.35 | F12: ='Ялта, Ленина, 18'!M17 -> 0.85445238 | G12: ='Рогалевич И. Е. '!K17 -> 0.65739734 | H12: ='Рогалевич И. Е. '!J17 -> 768 | I12: ='Рогалевич И. Е. '!M17 -> 0.65739734 | J12: ='Уразгильдеева Е. Р. '!K17 -> 0.54413343 | K12: ='Уразгильдеева Е. Р. '!J17 -> 507 | L12: ='Уразгильдеева Е. Р. '!M17 -> 0.54413343 | M12: ='[1]Яковенко А. К'!K17 -> #REF! | N12: ='[1]Яковенко А. К'!J17 -> #REF! | O12: ='[1]Яковенко А. К'!M17 -> #REF!
A13: UNOde50 | D13: ='Ялта, Ленина, 18'!S19 -> 0.22367373 | E13: ='Ялта, Ленина, 18'!T18 -> 228147.2 | F13: ='Ялта, Ленина, 18'!T19 -> 0.22367373 | G13: ='Рогалевич И. Е. '!S19 -> 0.24972348 | H13: ='Рогалевич И. Е. '!T18 -> 141701.2 | I13: ='Рогалевич И. Е. '!T19 -> 0.24972348 | J13: ='Уразгильдеева Е. Р. '!S19 -> 0.19101236 | K13: ='Уразгильдеева Е. Р. '!T18 -> 86446 | L13: ='Уразгильдеева Е. Р. '!T19 -> 0.19101236 | M13: ='[1]Яковенко А. К'!S19 -> #REF! | N13: ='[1]Яковенко А. К'!T18 -> #REF! | O13: ='[1]Яковенко А. К'!T19 -> #REF!
A14: IS | D14: ='Ялта, Ленина, 18'!S13 -> 0.12474706 | E14: ='Ялта, Ленина, 18'!T12 -> 63621 | F14: ='Ялта, Ленина, 18'!T13 -> 0.12474706 | G14: ='Рогалевич И. Е. '!S13 -> 0.094502882 | H14: ='Рогалевич И. Е. '!T12 -> 26812 | I14: ='Рогалевич И. Е. '!T13 -> 0.094502882 | J14: ='Уразгильдеева Е. Р. '!S13 -> 0.16266742 | K14: ='Уразгильдеева Е. Р. '!T12 -> 36809 | L14: ='Уразгильдеева Е. Р. '!T13 -> 0.16266742 | M14: ='[1]Яковенко А. К'!S13 -> #REF! | N14: ='[1]Яковенко А. К'!T12 -> #REF! | O14: ='[1]Яковенко А. К'!T13 -> #REF!
A15: ='Ялта, Ленина, 18'!M23 -> Agafi | D15: ='Ялта, Ленина, 18'!V13 -> 0.1902375 | E15: ='Ялта, Ленина, 18'!W12 -> 91314 | F15: ='Ялта, Ленина, 18'!W13 -> 0.1902375 | G15: ='Рогалевич И. Е. '!V13 -> 0.27650385 | H15: ='Рогалевич И. Е. '!W12 -> 73834 | I15: ='Рогалевич И. Е. '!W13 -> 0.27650385 | J15: ='Уразгильдеева Е. Р. '!V13 -> 0.082076142 | K15: ='Уразгильдеева Е. Р. '!W12 -> 17480 | L15: ='Уразгильдеева Е. Р. '!W13 -> 0.082076142 | M15: ='[1]Яковенко А. К'!V13 -> #REF! | N15: ='[1]Яковенко А. К'!W12 -> #REF! | O15: ='[1]Яковенко А. К'!W13 -> #REF!
A16: Отклонение от плана | D16: ='Ялта, Ленина, 18'!J16 -> -974460.8 | G16: ='Рогалевич И. Е. '!N8 -> -416099.74 | J16: ='Уразгильдеева Е. Р. '!N8 -> -455511.41 | M16: ='[1]Яковенко А. К'!N8 -> #REF!

Sheet План на день
A1: Выручка | D1: 146121
A2: Кол-во изделий | D2: =D1/D4 -> 24.766271
A3: Средний чек | D3: =D4*D5 -> 10502
A4: Средняя стоимость изделия | D4: ='Ялта, Ленина, 18'!I11 -> 5900
A5: Длина чека | D5: ='Ялта, Ленина, 18'!I12 -> 1.78
A6: Кол-во чеков | D6: =IF(D5<>0,D2/D5,"") -> 13.913635
A7: Конверсия | D7: ='Ялта, Ленина, 18'!I20 -> 0.11
A8: IS | D8: =('Ялта, Ленина, 18'!S12-'Ялта, Ленина, 18'!T12)/('Ялта, Ленина, 18'!I14-'Ялта, Ленина, 18'!J14) -> #DIV/0!
A9: UNOde50 | D9: =('Ялта, Ленина, 18'!S18-'Ялта, Ленина, 18'!T18)/('Ялта, Ленина, 18'!I14-'Ялта, Ленина, 18'!J14) -> #DIV/0!
A10: ='Ялта, Ленина, 18'!M23 -> Agafi | D10: =('Ялта, Ленина, 18'!V12-'Ялта, Ленина, 18'!W12)/('Ялта, Ленина, 18'!I14-'Ялта, Ленина, 18'!J14) -> #DIV/0!

Sheet Рогалевич И. Е. 
B1: =TODAY()-1 -> 45969
B2: (отчетная дата) | J2: ЕЖЕДНЕВНЫЙ ОТЧЕТ О ПРОДАЖАХ
B3: Осталось до выполнения плана!!! | J3: =График!B29 -> Рогалевич Ирина
C4: =I8-D57 -> 487905.76 | E4: =IF(I8<>0,C4/I8,0) -> 0.36152469
F6: Целевые показатели
F7: Показатель | I7: План | J7: Факт | K7: % выполнения | L7: Прогноз выполнения | M7: % выполнения по прогнозу | N7: Отклонение | O7: Факт аналогичного месяца прошлого года | P7: Отклонение LFL
F8: Выручка | I8: ='Ялта, Ленина, 18'!I8/График!AJ31*График!AJ29 -> 1349578 | J8: =D57 -> 861672.2 | K8: =IF(AND(I8<>"",I8<>0,J8<>""),J8/I8,"") -> 0.63847531 | L8: =IF(SUMIF($D$25:$D$56,">=0",$P$25:$P$56)<>0,I8*D57/SUMIF($D$25:$D$56,">=0",$P$25:$P$56),0) -> 933478.22 | M8: =IF(AND(I8<>"",I8<>0,L8<>"",L8<>0),L8/I8,"") -> 0.69168158 | N8: =IF(AND(J8<>0,J8<>"",I8<>0,I8<>""),L8-I8,"") -> -416099.74 | P8: =IF(AND(O8<>"",O8<>0,L8<>"",L8<>0),-O8+L8,"") | Q8: =IF(AND(P8<>"",P8<>0,O8<>0,O8<>""),P8/O8,"")
F9: Кол-во изделий | I9: =I8/I11 -> 228.74203 | J9: =E57 -> 146 | K9: =IF(AND(I9<>"",I9<>0,J9<>""),J9/I9,"") -> 0.63827361 | L9: =IF(SUMIF($E$25:$E$54,">=0",$Q$25:$Q$54)<>0,I9*E57/SUMIF($E$25:$E$54,">=0",$Q$25:$Q$54),0) -> 158.16667 | M9: =IF(AND(I9<>"",I9<>0,L9<>"",L9<>0),L9/I9,"") -> 0.69146308 | N9: =IF(AND(J9<>0,J9<>"",I9<>0,I9<>""),L9-I9,"") -> -70.57536 | O9: =O8/O11 -> #DIV/0! | P9: =IF(AND(O9<>"",O9<>0,L9<>"",L9<>0),-O9+L9,"") -> #DIV/0! | Q9: =IF(AND(P9<>"",P9<>0,O9<>0,O9<>""),P9/O9,"") -> #DIV/0!
F10: Средний чек | I10: =I11*I12 -> 10502 | J10: =H57 -> 10637.928 | K10: =IF(AND(I10<>"",I10<>0,J10<>""),J10/I10,"") -> 1.0129431 | L10: =J10 -> 10637.928 | M10: =IF(AND(I10<>"",I10<>0,L10<>"",L10<>0),L10/I10,"") -> 1.0129431 | N10: =IF(AND(J10<>0,J10<>"",I10<>0,I10<>""),L10-I10,"") -> 135.9284 | O10: =O11*O12 -> 0 | P10: =IF(AND(O10<>"",O10<>0,L10<>"",L10<>0),-O10+L10,"") | Q10: =IF(AND(P10<>"",P10<>0,O10<>0,O10<>""),P10/O10,"") | S10: IS | V10: =M23 -> Agafi
F11: Средняя стоимость изделия | I11: ='Ялта, Ленина, 18'!I11 -> 5900 | J11: =F57 -> 5901.8644 | K11: =IF(AND(I11<>"",I11<>0,J11<>""),J11/I11,"") -> 1.000316 | L11: =IF(L9>0,L8/L9,"") -> 5901.8644 | M11: =IF(AND(I11<>"",I11<>0,L11<>"",L11<>0),L11/I11,"") -> 1.000316 | N11: =IF(AND(J11<>0,J11<>"",I11<>0,I11<>""),L11-I11,"") -> 1.8643836 | P11: =IF(AND(O11<>"",O11<>0,L11<>"",L11<>0),-O11+L11,"") | Q11: =IF(AND(P11<>"",P11<>0,O11<>0,O11<>""),P11/O11,"")
F12: Длина чека | I12: ='Ялта, Ленина, 18'!I12 -> 1.78 | J12: =J57 -> 1.8024691 | K12: =IF(AND(I12<>"",I12<>0,J12<>""),J12/I12,"") -> 1.0126231 | L12: =J12 -> 1.8024691 | M12: =IF(AND(I12<>"",I12<>0,L12<>"",L12<>0),L12/I12,"") -> 1.0126231 | N12: =IF(AND(J12<>0,J12<>"",I12<>0,I12<>""),L12-I12,"") -> 0.022469136 | P12: =IF(AND(O12<>"",O12<>0,L12<>"",L12<>0),-O12+L12,"") | Q12: =IF(AND(P12<>"",P12<>0,O12<>0,O12<>""),P12/O12,"") | S12: ='Ялта, Ленина, 18'!S12*График!AJ29/График!AJ31 -> 283716.22 | T12: =L57 -> 26812 | V12: ='Ялта, Ленина, 18'!V12/График!AJ31*График!AJ29 -> 267027.03 | W12: =M57 -> 73834
F13: Кол-во чеков | I13: =IF(I12<>0,I9/I12,"") -> 128.50676 | J13: =G57 -> 81 | K13: =IF(AND(I13<>"",I13<>0,J13<>""),J13/I13,"") -> 0.63031705 | L13: =IF(SUMIF($G$25:$G$54,">=0",$R$25:$R$54)<>0,I13*G57/SUMIF($G$25:$G$54,">=0",$R$25:$R$54),"") -> 87.75 | M13: =IF(AND(I13<>"",I13<>0,L13<>"",L13<>0),L13/I13,"") -> 0.68284347 | N13: =IF(AND(J13<>0,J13<>"",I13<>0,I13<>""),L13-I13,"") -> -40.756757 | P13: =IF(AND(O13<>"",O13<>0,L13<>"",L13<>0),-O13+L13,"") | Q13: =IF(AND(P13<>"",P13<>0,O13<>0,O13<>""),P13/O13,"") | S13: =T12/S12 -> 0.094502882 | T13: =S13/J14*I14 -> 0.094502882 | V13: =W12/V12 -> 0.27650385 | W13: =V13/J14*I14 -> 0.27650385
F14: Кол-во смен план/отработано | I14: =График!AI29 -> 26 | J14: 26 | K14: =IF(AND(I14<>"",I14<>0,J14<>""),J14/I14,"") -> 1 | L14: =I14 -> 26 | M14: =IF(AND(I14<>"",I14<>0,L14<>"",L14<>0),L14/I14,"") -> 1 | N14: =IF(AND(J14<>0,J14<>"",I14<>0,I14<>""),L14-I14,"") -> 0 | P14: =IF(AND(O14<>"",O14<>0,L14<>"",L14<>0),-O14+L14,"") | Q14: =IF(AND(P14<>"",P14<>0,O14<>0,O14<>""),P14/O14,"")
F15: Средние продажи в смену | I15: ='Ялта, Ленина, 18'!I15 -> 78256.839 | J15: =J8/J14 -> 33141.238 | K15: =IF(AND(I15<>"",I15<>0,J15<>""),J15/I15,"") -> 0.42349319 | L15: =J15 -> 33141.238 | M15: =IF(AND(I15<>"",I15<>0,L15<>"",L15<>0),L15/I15,"") -> 0.42349319 | N15: =IF(AND(J15<>0,J15<>"",I15<>0,I15<>""),L15-I15,"") -> -45115.6 | P15: =IF(AND(O15<>"",O15<>0,L15<>"",L15<>0),-O15+L15,"") | Q15: =IF(AND(P15<>"",P15<>0,O15<>0,O15<>""),P15/O15,"")
F16: Отставание/Перевыполнение | J16: =J8-I15*J14 -> -1173005.6 | K16: =IF(AND(I16<>"",I16<>0,J16<>""),J16/I16,"") | L16: =J16 -> -1173005.6 | M16: =IF(AND(I16<>"",I16<>0,L16<>"",L16<>0),L16/I16,"") | N16: =IF(AND(J16<>0,J16<>"",I16<>0,I16<>""),L16-I16,"") | P16: =IF(AND(O16<>"",O16<>0,L16<>"",L16<>0),-O16+L16,"") | Q16: =IF(AND(P16<>"",P16<>0,O16<>0,O16<>""),P16/O16,"") | S16: UNOde50
F17: Трафик | I17: ='Ялта, Ленина, 18'!I17/График!AJ31*График!AJ29 -> 1168.2432 | J17: =I57 -> 768 | K17: =IF(AND(I17<>"",I17<>0,J17<>""),J17/I17,"") -> 0.65739734 | L17: =J17/J14*I14 -> 768 | M17: =IF(AND(I17<>"",I17<>0,L17<>"",L17<>0),L17/I17,"") -> 0.65739734 | N17: =IF(AND(J17<>0,J17<>"",I17<>0,I17<>""),L17-I17,"") -> -400.24324 | P17: =IF(AND(O17<>"",O17<>0,L17<>"",L17<>0),-O17+L17,"") | Q17: =IF(AND(P17<>"",P17<>0,O17<>0,O17<>""),P17/O17,"")
K18: =IF(AND(I18<>"",I18<>0,J18<>""),J18/I18,"") | L18: =J18 -> 0 | M18: =IF(AND(I18<>"",I18<>0,L18<>"",L18<>0),L18/I18,"") | N18: =IF(AND(J18<>0,J18<>"",I18<>0,I18<>""),L18-I18,"") | O18: 0 | P18: =IF(AND(O18<>"",O18<>0,L18<>"",L18<>0),-O18+L18,"") | Q18: =IF(AND(P18<>"",P18<>0,O18<>0,O18<>""),P18/O18,"") | S18: ='Ялта, Ленина, 18'!S18*График!AJ29/График!AJ31 -> 567432.43 | T18: =K57 -> 141701.2
K19: =IF(AND(I19<>"",I19<>0,J19<>""),J19/I19,"") | L19: =J19 -> 0 | M19: =IF(AND(I19<>"",I19<>0,L19<>"",L19<>0),L19/I19,"") | N19: =IF(AND(J19<>0,J19<>"",I19<>0,I19<>""),L19-I19,"") | O19: 0 | P19: =IF(AND(O19<>"",O19<>0,L19<>"",L19<>0),-O19+L19,"") | Q19: =IF(AND(P19<>"",P19<>0,O19<>0,O19<>""),P19/O19,"") | S19: =T18/S18 -> 0.24972348 | T19: =S19/J14*I14 -> 0.24972348
F20: Конверсия план/факт | I20: ='Ялта, Ленина, 18'!I20 -> 0.11 | J20: =N57 -> 0.10546875 | K20: =J20/I20 -> 0.95880682 | L20: =IF(AND(K8<>0,I14<>0,I57<>0),(I57*N57+(I57/K8-I57)*I20)/(I57/K8),0) -> 0.10710691 | M20: =IF(AND(I20<>"",I20<>0,L20<>"",L20<>0),L20/I20,"") -> 0.97369917 | N20: =IF(AND(J20<>0,J20<>"",I20<>0,I20<>""),L20-I20,"") -> -0.0028930912 | P20: =IF(AND(O20<>"",O20<>0,L20<>"",L20<>0),-O20+L20,"") | Q20: =IF(AND(P20<>"",P20<>0,O20<>0,O20<>""),P20/O20,"")
B22: Факт продаж за месяц | O22: % выполнения дневного плана | P22: Раcпределение плана по дням
B23: Дата | C23: День недели | D23: Выручка (руб) | E23: Кол-во единиц (шт.) | F23: Средняя стоимость изделия (руб.) | G23: Количество чеков (шт.) | H23: Средняя сумма чека (руб.) | I23: Трафик | J23: Длина чека (шт.) | K23: UNOde50 | L23: IS | M23: Agafi | N23: Конверсия (%) | P23: выручка, план | Q23: кол-во ед, план | R23: Кол-во чеков, план | S23: выручка, скорректир.план | T23: кол-во ед, скорр. план | U23: кол-во чеков, скорр. план | V23: Коэфф. Дня Недели | W23: Специфика месяца
B24: 1 | C24: 2 | D24: 3 | E24: 4 | F24: 5 | G24: 6 | H24: 7 | I24: 8 | J24: 9 | K24: 10 | L24: 11 | M24: 12 | N24: 13 | P24: 1 | Q24: 2 | R24: 3 | S24: 4 | T24: 5 | U24: 6 | V24: 10 | W24: 11
A25: 1 | B25: 45932 | C25: чт | D25: 46368 | E25: 11 | F25: =IF(AND(E25<>"",E25<>0),D25/E25,"") -> 4215.2727 | G25: 4 | H25: =IF(AND(G25<>"",G25<>0),D25/G25,"") -> 11592 | I25: 25 | J25: =IF(AND(G25<>"",G25<>0),E25/G25,"") -> 2.75 | N25: =IF(AND(I25<>"",I25<>0),G25/I25,"") -> 0.16 | O25: =D25/P25 -> 0.8932926 | P25: =$I$8*V25*W25/SUMPRODUCT($W$25:$W$56,$V$25:$V$56) -> 51906.845 | Q25: =$I$9*V25*W25/SUMPRODUCT($W$25:$W$56,$V$25:$V$56) -> 8.7977703 | R25: =IF($I$12="","",Q25/$I$12) -> 4.9425676 | S25: =IF(D25<>"",D25,P25) -> 46368 | T25: =IF(E25<>"",E25,Q25) -> 11 | U25: =IF(G25<>"",G25,R25) -> 4 | V25: 1 | W25: 1
A26: 2 | B26: 45933 | C26: пт | D26: =8190+6990+14377 -> 29557 | E26: 5 | F26: =IF(AND(E26<>"",E26<>0),D26/E26,"") -> 5911.4 | G26: 2 | H26: =IF(AND(G26<>"",G26<>0),D26/G26,"") -> 14778.5 | I26: 30 | J26: =IF(AND(G26<>"",G26<>0),E26/G26,"") -> 2.5 | K26: 8190 | M26: 6990 | N26: =IF(AND(I26<>"",I26<>0),G26/I26,"") -> 0.066666667 | O26: =D26/P26 -> 0.56942394 | P26: =$I$8*V26*W26/SUMPRODUCT($W$25:$W$56,$V$25:$V$56) -> 51906.845 | Q26: =$I$9*V26*W26/SUMPRODUCT($W$25:$W$58,$V$25:$V$58) -> 8.7977703 | R26: =IF($I$12="","",Q26/$I$12) -> 4.9425676 | S26: =IF(W26<>"",IF(D26<>"",D26,($I$8-SUM($S$25:S25))*V26*W26/SUMPRODUCT($W26:$W$56,$V26:$V$56)),"") -> 29557 | T26: =IF(W26<>"",IF(E26<>"",E26,($I$9-SUM($T$25:T25))*V26*W26/SUMPRODUCT($W26:$W$58,$V26:$V$58)),"") -> 5 | U26: =IF(W26<>"",IF($I$12<>"",IF(G26<>"",G26,($I$9/$I$12-SUM($U$25:U25))*V26*W26/SUMPRODUCT($W26:$W$58,$V26:$V$58)),""),"") -> 2 | V26: 1 | W26: 1
A27: 3 | B27: 45934 | C27: сб | D27: 76483 | E27: 11 | F27: =IF(AND(E27<>"",E27<>0),D27/E27,"") -> 6953 | G27: 4 | H27: =IF(AND(G27<>"",G27<>0),D27/G27,"") -> 19120.75 | I27: 50 | J27: =IF(AND(G27<>"",G27<>0),E27/G27,"") -> 2.75 | M27: 19675 | N27: =IF(AND(I27<>"",I27<>0),G27/I27,"") -> 0.08 | O27: =D27/P27 -> 1.4734666 | P27: =$I$8*V27*W27/SUMPRODUCT($W$25:$W$56,$V$25:$V$56) -> 51906.845 | Q27: =$I$9*V27*W27/SUMPRODUCT($W$25:$W$58,$V$25:$V$58) -> 8.7977703 | R27: =IF($I$12="","",Q27/$I$12) -> 4.9425676 | S27: =IF(W27<>"",IF(D27<>"",D27,($I$8-SUM($S$25:S26))*V27*W27/SUMPRODUCT($W27:$W$58,$V27:$V$58)),"") -> 76483 | T27: =IF(W27<>"",IF(E27<>"",E27,($I$9-SUM($T$25:T26))*V27*W27/SUMPRODUCT($W27:$W$58,$V27:$V$58)),"") -> 11 | U27: =IF(W27<>"",IF($I$12<>"",IF(G27<>"",G27,($I$9/$I$12-SUM($U$25:U26))*V27*W27/SUMPRODUCT($W27:$W$58,$V27:$V$58)),""),"") -> 4 | V27: 1 | W27: 1
A28: 4 | B28: 45935 | C28: вс | D28: =12106+16910 -> 29016 | E28: 7 | F28: =IF(AND(E28<>"",E28<>0),D28/E28,"") -> 4145.1429 | G28: 5 | H28: =IF(AND(G28<>"",G28<>0),D28/G28,"") -> 5803.2 | I28: 35 | J28: =IF(AND(G28<>"",G28<>0),E28/G28,"") -> 1.4 | L28: 12106 | N28: =IF(AND(I28<>"",I28<>0),G28/I28,"") -> 0.14285714 | O28: =D28/P28 -> 0.55900142 | P28: =$I$8*V28*W28/SUMPRODUCT($W$25:$W$56,$V$25:$V$56) -> 51906.845 | Q28: =$I$9*V28*W28/SUMPRODUCT($W$25:$W$58,$V$25:$V$58) -> 8.7977703 | R28: =IF($I$12="","",Q28/$I$12) -> 4.9425676 | S28: =IF(W28<>"",IF(D28<>"",D28,($I$8-SUM($S$25:S27))*V28*W28/SUMPRODUCT($W28:$W$58,$V28:$V$58)),"") -> 29016 | T28: =IF(W28<>"",IF(E28<>"",E28,($I$9-SUM($T$25:T27))*V28*W28/SUMPRODUCT($W28:$W$58,$V28:$V$58)),"") -> 7 | U28: =IF(W28<>"",IF($I$12<>"",IF(G28<>"",G28,($I$9/$I$12-SUM($U$25:U27))*V28*W28/SUMPRODUCT($W28:$W$58,$V28:$V$58)),""),"") -> 5 | V28: 1 | W28: 1
A29: 5 | B29: 45936 | C29: пн | D29: =5803+36600 -> 42403 | E29: 7 | F29: =IF(AND(E29<>"",E29<>0),D29/E29,"") -> 6057.5714 | G29: 4 | H29: =IF(AND(G29<>"",G29<>0),D29/G29,"") -> 10600.75 | I29: 25 | J29: =IF(AND(G29<>"",G29<>0),E29/G29,"") -> 1.75 | L29: 5803 | N29: =IF(AND(I29<>"",I29<>0),G29/I29,"") -> 0.16 | O29: =D29/P29 -> 0.81690575 | P29: =$I$8*V29*W29/SUMPRODUCT($W$25:$W$56,$V$25:$V$56) -> 51906.845 | Q29: =$I$9*V29*W29/SUMPRODUCT($W$25:$W$58,$V$25:$V$58) -> 8.7977703 | R29: =IF($I$12="","",Q29/$I$12) -> 4.9425676 | S29: =IF(W29<>"",IF(D29<>"",D29,($I$8-SUM($S$25:S28))*V29*W29/SUMPRODUCT($W29:$W$58,$V29:$V$58)),"") -> 42403 | T29: =IF(W29<>"",IF(E29<>"",E29,($I$9-SUM($T$25:T28))*V29*W29/SUMPRODUCT($W29:$W$58,$V29:$V$58)),"") -> 7 | U29: =IF(W29<>"",IF($I$12<>"",IF(G29<>"",G29,($I$9/$I$12-SUM($U$25:U28))*V29*W29/SUMPRODUCT($W29:$W$58,$V29:$V$58)),""),"") -> 4 | V29: 1 | W29: 1
A30: 6 | B30: 45937 | C30: вт | F30: =IF(AND(E30<>"",E30<>0),D30/E30,"") | H30: =IF(AND(G30<>"",G30<>0),D30/G30,"") | I30: 52 | J30: =IF(AND(G30<>"",G30<>0),E30/G30,"") | N30: =IF(AND(I30<>"",I30<>0),G30/I30,"") -> 0 | O30: =D30/P30 -> 0 | P30: =$I$8*V30*W30/SUMPRODUCT($W$25:$W$56,$V$25:$V$56) -> 51906.845 | Q30: =$I$9*V30*W30/SUMPRODUCT($W$25:$W$58,$V$25:$V$58) -> 8.7977703 | R30: =IF($I$12="","",Q30/$I$12) -> 4.9425676 | S30: =IF(W30<>"",IF(D30<>"",D30,($I$8-SUM($S$25:S29))*V30*W30/SUMPRODUCT($W30:$W$58,$V30:$V$58)),"") -> 53607.189 | T30: =IF(W30<>"",IF(E30<>"",E30,($I$9-SUM($T$25:T29))*V30*W30/SUMPRODUCT($W30:$W$58,$V30:$V$58)),"") -> 8.9400965 | U30: =IF(W30<>"",IF($I$12<>"",IF(G30<>"",G30,($I$9/$I$12-SUM($U$25:U29))*V30*W30/SUMPRODUCT($W30:$W$58,$V30:$V$58)),""),"") -> 5.2146075 | V30: 1 | W30: 1
A31: 7 | B31: 45938 | C31: ср | D31: 9084 | E31: 2 | F31: =IF(AND(E31<>"",E31<>0),D31/E31,"") -> 4542 | G31: 2 | H31: =IF(AND(G31<>"",G31<>0),D31/G31,"") -> 4542 | I31: 20 | J31: =IF(AND(G31<>"",G31<>0),E31/G31,"") -> 1 | N31: =IF(AND(I31<>"",I31<>0),G31/I31,"") -> 0.1 | O31: =D31/P31 -> 0.17500582 | P31: =$I$8*V31*W31/SUMPRODUCT($W$25:$W$56,$V$25:$V$56) -> 51906.845 | Q31: =$I$9*V31*W31/SUMPRODUCT($W$25:$W$58,$V$25:$V$58) -> 8.7977703 | R31: =IF($I$12="","",Q31/$I$12) -> 4.9425676 | S31: =IF(W31<>"",IF(D31<>"",D31,($I$8-SUM($S$25:S30))*V31*W31/SUMPRODUCT($W31:$W$58,$V31:$V$58)),"") -> 9084 | T31: =IF(W31<>"",IF(E31<>"",E31,($I$9-SUM($T$25:T30))*V31*W31/SUMPRODUCT($W31:$W$58,$V31:$V$58)),"") -> 2 | U31: =IF(W31<>"",IF($I$12<>"",IF(G31<>"",G31,($I$9/$I$12-SUM($U$25:U30))*V31*W31/SUMPRODUCT($W31:$W$58,$V31:$V$58)),""),"") -> 2 | V31: 1 | W31: 1
A32: 8 | B32: 45941 | C32: сб | D32: 82347 | E32: 17 | F32: =IF(AND(E32<>"",E32<>0),D32/E32,"") -> 4843.9412 | G32: 10 | H32: =IF(AND(G32<>"",G32<>0),D32/G32,"") -> 8234.7 | I32: 72 | J32: =IF(AND(G32<>"",G32<>0),E32/G32,"") -> 1.7 | N32: =IF(AND(I32<>"",I32<>0),G32/I32,"") -> 0.13888889 | O32: =D32/P32 -> 1.5864382 | P32: =$I$8*V32*W32/SUMPRODUCT($W$25:$W$56,$V$25:$V$56) -> 51906.845 | Q32: =$I$9*V32*W32/SUMPRODUCT($W$25:$W$58,$V$25:$V$58) -> 8.7977703 | R32: =IF($I$12="","",Q32/$I$12) -> 4.9425676 | S32: =IF(W32<>"",IF(D32<>"",D32,($I$8-SUM($S$25:S31))*V32*W32/SUMPRODUCT($W32:$W$58,$V32:$V$58)),"") -> 82347 | T32: =IF(W32<>"",IF(E32<>"",E32,($I$9-SUM($T$25:T31))*V32*W32/SUMPRODUCT($W32:$W$58,$V32:$V$58)),"") -> 17 | U32: =IF(W32<>"",IF($I$12<>"",IF(G32<>"",G32,($I$9/$I$12-SUM($U$25:U31))*V32*W32/SUMPRODUCT($W32:$W$58,$V32:$V$58)),""),"") -> 10 | V32: 1 | W32: 1
A33: 9 | B33: 45942 | C33: вс | D33: 87721 | E33: 12 | F33: =IF(AND(E33<>"",E33<>0),D33/E33,"") -> 7310.0833 | G33: 5 | H33: =IF(AND(G33<>"",G33<>0),D33/G33,"") -> 17544.2 | I33: 60 | J33: =IF(AND(G33<>"",G33<>0),E33/G33,"") -> 2.4 | K33: 12816 | M33: 22783 | N33: =IF(AND(I33<>"",I33<>0),G33/I33,"") -> 0.083333333 | O33: =D33/P33 -> 1.6899698 | P33: =$I$8*V33*W33/SUMPRODUCT($W$25:$W$56,$V$25:$V$56) -> 51906.845 | Q33: =$I$9*V33*W33/SUMPRODUCT($W$25:$W$58,$V$25:$V$58) -> 8.7977703 | R33: =IF($I$12="","",Q33/$I$12) -> 4.9425676 | S33: =IF(W33<>"",IF(D33<>"",D33,($I$8-SUM($S$25:S32))*V33*W33/SUMPRODUCT($W33:$W$58,$V33:$V$58)),"") -> 87721 | T33: =IF(W33<>"",IF(E33<>"",E33,($I$9-SUM($T$25:T32))*V33*W33/SUMPRODUCT($W33:$W$58,$V33:$V$58)),"") -> 12 | U33: =IF(W33<>"",IF($I$12<>"",IF(G33<>"",G33,($I$9/$I$12-SUM($U$25:U32))*V33*W33/SUMPRODUCT($W33:$W$58,$V33:$V$58)),""),"") -> 5 | V33: 1 | W33: 1
A34: 10 | B34: 45943 | C34: пн | D34: 11773 | E34: 2 | F34: =IF(AND(E34<>"",E34<>0),D34/E34,"") -> 5886.5 | G34: 2 | H34: =IF(AND(G34<>"",G34<>0),D34/G34,"") -> 5886.5 | I34: 15 | J34: =IF(AND(G34<>"",G34<>0),E34/G34,"") -> 1 | N34: =IF(AND(I34<>"",I34<>0),G34/I34,"") -> 0.13333333 | O34: =D34/P34 -> 0.22681017 | P34: =$I$8*V34*W34/SUMPRODUCT($W$25:$W$56,$V$25:$V$56) -> 51906.845 | Q34: =$I$9*V34*W34/SUMPRODUCT($W$25:$W$58,$V$25:$V$58) -> 8.7977703 | R34: =IF($I$12="","",Q34/$I$12) -> 4.9425676 | S34: =IF(W34<>"",IF(D34<>"",D34,($I$8-SUM($S$25:S33))*V34*W34/SUMPRODUCT($W34:$W$58,$V34:$V$58)),"") -> 11773 | T34: =IF(W34<>"",IF(E34<>"",E34,($I$9-SUM($T$25:T33))*V34*W34/SUMPRODUCT($W34:$W$58,$V34:$V$58)),"") -> 2 | U34: =IF(W34<>"",IF($I$12<>"",IF(G34<>"",G34,($I$9/$I$12-SUM($U$25:U33))*V34*W34/SUMPRODUCT($W34:$W$58,$V34:$V$58)),""),"") -> 2 | V34: 1 | W34: 1
A35: 11 | B35: 45944 | C35: вт | D35: 5492 | E35: 1 | F35: =IF(AND(E35<>"",E35<>0),D35/E35,"") -> 5492 | G35: 1 | H35: =IF(AND(G35<>"",G35<>0),D35/G35,"") -> 5492 | I35: 15 | J35: =IF(AND(G35<>"",G35<>0),E35/G35,"") -> 1 | N35: =IF(AND(I35<>"",I35<>0),G35/I35,"") -> 0.066666667 | O35: =D35/P35 -> 0.10580493 | P35: =$I$8*V35*W35/SUMPRODUCT($W$25:$W$56,$V$25:$V$56) -> 51906.845 | Q35: =$I$9*V35*W35/SUMPRODUCT($W$25:$W$58,$V$25:$V$58) -> 8.7977703 | R35: =IF($I$12="","",Q35/$I$12) -> 4.9425676 | S35: =IF(W35<>"",IF(D35<>"",D35,($I$8-SUM($S$25:S34))*V35*W35/SUMPRODUCT($W35:$W$58,$V35:$V$58)),"") -> 5492 | T35: =IF(W35<>"",IF(E34<>"",E34,($I$9-SUM($T$25:T34))*V35*W35/SUMPRODUCT($W35:$W$58,$V35:$V$58)),"") -> 2 | U35: =IF(W35<>"",IF($I$12<>"",IF(G35<>"",G35,($I$9/$I$12-SUM($U$25:U34))*V35*W35/SUMPRODUCT($W35:$W$58,$V35:$V$58)),""),"") -> 1 | V35: 1 | W35: 1
A36: 11 | B36: 45945 | C36: ср | D36: 30491 | E36: 7 | F36: =IF(AND(E36<>"",E36<>0),D36/E36,"") -> 4355.8571 | G36: 2 | H36: =IF(AND(G36<>"",G36<>0),D36/G36,"") -> 15245.5 | I36: 25 | J36: =IF(AND(G36<>"",G36<>0),E36/G36,"") -> 3.5 | N36: =IF(AND(I36<>"",I36<>0),G36/I36,"") -> 0.08 | O36: =D36/P36 -> 0.58741771 | P36: =$I$8*V36*W36/SUMPRODUCT($W$25:$W$56,$V$25:$V$56) -> 51906.845 | Q36: =$I$9*V36*W36/SUMPRODUCT($W$25:$W$58,$V$25:$V$58) -> 8.7977703 | R36: =IF($I$12="","",Q36/$I$12) -> 4.9425676 | S36: =IF(W36<>"",IF(D36<>"",D36,($I$8-SUM($S$25:S35))*V36*W36/SUMPRODUCT($W36:$W$58,$V36:$V$58)),"") -> 30491 | T36: =IF(W36<>"",IF(E35<>"",E35,($I$9-SUM($T$25:T35))*V36*W36/SUMPRODUCT($W36:$W$58,$V36:$V$58)),"") -> 1 | U36: =IF(W36<>"",IF($I$12<>"",IF(G36<>"",G36,($I$9/$I$12-SUM($U$25:U35))*V36*W36/SUMPRODUCT($W36:$W$58,$V36:$V$58)),""),"") -> 2 | V36: 1 | W36: 1
A37: 13 | B37: 45946 | C37: чт | D37: 22984.2 | E37: 4 | F37: =IF(AND(E37<>"",E37<>0),D37/E37,"") -> 5746.05 | G37: 4 | H37: =IF(AND(G37<>"",G37<>0),D37/G37,"") -> 5746.05 | I37: 20 | J37: =IF(AND(G37<>"",G37<>0),E37/G37,"") -> 1 | K37: 8811.2 | N37: =IF(AND(I37<>"",I37<>0),G37/I37,"") -> 0.2 | O37: =D37/P37 -> 0.4427971 | P37: =$I$8*V37*W37/SUMPRODUCT($W$25:$W$56,$V$25:$V$56) -> 51906.845 | Q37: =$I$9*V37*W37/SUMPRODUCT($W$25:$W$58,$V$25:$V$58) -> 8.7977703 | R37: =IF($I$12="","",Q37/$I$12) -> 4.9425676 | S37: =IF(W37<>"",IF(D37<>"",D37,($I$8-SUM($S$25:S36))*V37*W37/SUMPRODUCT($W37:$W$58,$V37:$V$58)),"") -> 22984.2 | T37: =IF(W37<>"",IF(E37<>"",E37,($I$9-SUM($T$25:T36))*V37*W37/SUMPRODUCT($W37:$W$58,$V37:$V$58)),"") -> 4 | U37: =IF(W37<>"",IF($I$12<>"",IF(G37<>"",G37,($I$9/$I$12-SUM($U$25:U36))*V37*W37/SUMPRODUCT($W37:$W$58,$V37:$V$58)),""),"") -> 4 | V37: 1 | W37: 1
A38: 14 | B38: 45947 | C38: пт | D38: 29263 | E38: 6 | F38: =IF(AND(E38<>"",E38<>0),D38/E38,"") -> 4877.1667 | G38: 4 | H38: =IF(AND(G38<>"",G38<>0),D38/G38,"") -> 7315.75 | I38: 20 | J38: =IF(AND(G38<>"",G38<>0),E38/G38,"") -> 1.5 | M38: 7590 | N38: =IF(AND(I38<>"",I38<>0),G38/I38,"") -> 0.2 | O38: =D38/P38 -> 0.56375995 | P38: =$I$8*V38*W38/SUMPRODUCT($W$25:$W$56,$V$25:$V$56) -> 51906.845 | Q38: =$I$9*V38*W38/SUMPRODUCT($W$25:$W$58,$V$25:$V$58) -> 8.7977703 | R38: =IF($I$12="","",Q38/$I$12) -> 4.9425676 | S38: =IF(W38<>"",IF(D38<>"",D38,($I$8-SUM($S$25:S37))*V38*W38/SUMPRODUCT($W38:$W$58,$V38:$V$58)),"") -> 29263 | T38: =IF(W38<>"",IF(E38<>"",E38,($I$9-SUM($T$25:T37))*V38*W38/SUMPRODUCT($W38:$W$58,$V38:$V$58)),"") -> 6 | U38: =IF(W38<>"",IF($I$12<>"",IF(G38<>"",G38,($I$9/$I$12-SUM($U$25:U37))*V38*W38/SUMPRODUCT($W38:$W$58,$V38:$V$58)),""),"") -> 4 | V38: 1 | W38: 1
A39: 15 | B39: 45948 | C39: сб | D39: 20912 | E39: 3 | F39: =IF(AND(E39<>"",E39<>0),D39/E39,"") -> 6970.6667 | G39: 3 | H39: =IF(AND(G39<>"",G39<>0),D39/G39,"") -> 6970.6667 | I39: 25 | J39: =IF(AND(G39<>"",G39<>0),E39/G39,"") -> 1 | N39: =IF(AND(I39<>"",I39<>0),G39/I39,"") -> 0.12 | O39: =D39/P39 -> 0.40287558 | P39: =$I$8*V39*W39/SUMPRODUCT($W$25:$W$56,$V$25:$V$56) -> 51906.845 | Q39: =$I$9*V39*W39/SUMPRODUCT($W$25:$W$58,$V$25:$V$58) -> 8.7977703 | R39: =IF($I$12="","",Q39/$I$12) -> 4.9425676 | S39: =IF(W39<>"",IF(D39<>"",D39,($I$8-SUM($S$25:S38))*V39*W39/SUMPRODUCT($W39:$W$58,$V39:$V$58)),"") -> 20912 | T39: =IF(W39<>"",IF(E39<>"",E39,($I$9-SUM($T$25:T38))*V39*W39/SUMPRODUCT($W39:$W$58,$V39:$V$58)),"") -> 3 | U39: =IF(W39<>"",IF($I$12<>"",IF(G39<>"",G39,($I$9/$I$12-SUM($U$25:U38))*V39*W39/SUMPRODUCT($W39:$W$58,$V39:$V$58)),""),"") -> 3 | V39: 1 | W39: 1
A40: 16 | B40: 45949 | C40: вс | D40: 12472 | E40: 3 | F40: =IF(AND(E40<>"",E40<>0),D40/E40,"") -> 4157.3333 | G40: 2 | H40: =IF(AND(G40<>"",G40<>0),D40/G40,"") -> 6236 | I40: 20 | J40: =IF(AND(G40<>"",G40<>0),E40/G40,"") -> 1.5 | N40: =IF(AND(I40<>"",I40<>0),G40/I40,"") -> 0.1 | O40: =D40/P40 -> 0.2402766 | P40: =$I$8*V40*W40/SUMPRODUCT($W$25:$W$56,$V$25:$V$56) -> 51906.845 | Q40: =$I$9*V40*W40/SUMPRODUCT($W$25:$W$58,$V$25:$V$58) -> 8.7977703 | R40: =IF($I$12="","",Q40/$I$12) -> 4.9425676 | S40: =IF(W40<>"",IF(D40<>"",D40,($I$8-SUM($S$25:S39))*V40*W40/SUMPRODUCT($W40:$W$58,$V40:$V$58)),"") -> 12472 | T40: =IF(W40<>"",IF(E40<>"",E40,($I$9-SUM($T$25:T39))*V40*W40/SUMPRODUCT($W40:$W$58,$V40:$V$58)),"") -> 3 | U40: =IF(W40<>"",IF($I$12<>"",IF(G40<>"",G40,($I$9/$I$12-SUM($U$25:U39))*V40*W40/SUMPRODUCT($W40:$W$58,$V40:$V$58)),""),"") -> 2 | V40: 1 | W40: 1
A41: 17 | B41: 45950 | C41: пн | D41: 33331 | E41: 6 | F41: =IF(AND(E41<>"",E41<>0),D41/E41,"") -> 5555.1667 | G41: 4 | H41: =IF(AND(G41<>"",G41<>0),D41/G41,"") -> 8332.75 | I41: 30 | J41: =IF(AND(G41<>"",G41<>0),E41/G41,"") -> 1.5 | N41: =IF(AND(I41<>"",I41<>0),G41/I41,"") -> 0.13333333 | O41: =D41/P41 -> 0.64213112 | P41: =$I$8*V41*W41/SUMPRODUCT($W$25:$W$56,$V$25:$V$56) -> 51906.845 | Q41: =$I$9*V41*W41/SUMPRODUCT($W$25:$W$58,$V$25:$V$58) -> 8.7977703 | R41: =IF($I$12="","",Q41/$I$12) -> 4.9425676 | S41: =IF(W41<>"",IF(D41<>"",D41,($I$8-SUM($S$25:S40))*V41*W41/SUMPRODUCT($W41:$W$58,$V41:$V$58)),"") -> 33331 | T41: =IF(W41<>"",IF(E41<>"",E41,($I$9-SUM($T$25:T40))*V41*W41/SUMPRODUCT($W41:$W$58,$V41:$V$58)),"") -> 6 | U41: =IF(W41<>"",IF($I$12<>"",IF(G41<>"",G41,($I$9/$I$12-SUM($U$25:U40))*V41*W41/SUMPRODUCT($W41:$W$58,$V41:$V$58)),""),"") -> 4 | V41: 1 | W41: 1
A42: 18 | B42: 45951 | C42: вт | D42: 28366 | E42: 5 | F42: =IF(AND(E42<>"",E42<>0),D42/E42,"") -> 5673.2 | G42: 3 | H42: =IF(AND(G42<>"",G42<>0),D42/G42,"") -> 9455.3333 | I42: 35 | J42: =IF(AND(G42<>"",G42<>0),E42/G42,"") -> 1.6666667 | M42: 8004 | N42: =IF(AND(I42<>"",I42<>0),G42/I42,"") -> 0.085714286 | O42: =D42/P42 -> 0.54647899 | P42: =$I$8*V42*W42/SUMPRODUCT($W$25:$W$56,$V$25:$V$56) -> 51906.845 | Q42: =$I$9*V42*W42/SUMPRODUCT($W$25:$W$58,$V$25:$V$58) -> 8.7977703 | R42: =IF($I$12="","",Q42/$I$12) -> 4.9425676 | S42: =IF(W42<>"",IF(D42<>"",D42,($I$8-SUM($S$25:S41))*V42*W42/SUMPRODUCT($W42:$W$58,$V42:$V$58)),"") -> 28366 | T42: =IF(W42<>"",IF(E42<>"",E42,($I$9-SUM($T$25:T41))*V42*W42/SUMPRODUCT($W42:$W$58,$V42:$V$58)),"") -> 5 | U42: =IF(W42<>"",IF($I$12<>"",IF(G42<>"",G42,($I$9/$I$12-SUM($U$25:U41))*V42*W42/SUMPRODUCT($W42:$W$58,$V42:$V$58)),""),"") -> 3 | V42: 1 | W42: 1
...

Sheet Уразгильдеева Е. Р. 
B1: =TODAY()-1 -> 45969
B2: (отчетная дата) | J2: ЕЖЕДНЕВНЫЙ ОТЧЕТ О ПРОДАЖАХ
B3: Осталось до выполнения плана!!! | J3: =График!B28 -> Уразгильдеева Екатерина
C4: =I8-D50 -> 1076384 | E4: =IF(I8<>0, C4/I8, 0) -> 1
F6: Целевые показатели
F7: Показатель | I7: План | J7: Факт | K7: % выполнения | L7: Прогноз выполнения | M7: % выполнения по прогнозу | N7: Отклонение | O7: Факт аналогичного месяца прошлого года | P7: Отклонение LFL
F8: Выручка | I8: ='Ялта, Ленина, 18'!I8/График!AJ31*График!AJ28 -> 1076384 | J8: =D57 -> 589829 | K8: =IF(AND(I8<>"",I8<>0,J8<>""),J8/I8,"") -> 0.54797264 | L8: =IF(SUMIF($D$25:$D$56,">=0",$P$25:$P$56)<>0,I8*D57/SUMIF($D$25:$D$56,">=0",$P$25:$P$56),0) -> 620872.63 | M8: =IF(AND(I8<>"",I8<>0,L8<>"",L8<>0),L8/I8,"") -> 0.5768133 | N8: =IF(AND(J8<>0,J8<>"",I8<>0,I8<>""),L8-I8,"") -> -455511.41 | P8: =IF(AND(O8<>"", O8<>0, L8<>"", L8<>0), -O8+L8, "") | Q8: =IF(AND(P8<>"", P8<>0, O8<>0, O8<>""), P8/O8, "")
F9: Кол-во изделий | I9: =I8/I11 -> 182.43797 | J9: =E57 -> 97 | K9: =IF(AND(I9<>"", I9<>0, J9<>""), J9/I9, "") -> 0.53168756 | L9: =IF(SUMIF($E$25:$E$54,">=0",$Q$25:$Q$54)<>0,I9*E57/SUMIF($E$25:$E$54,">=0",$Q$25:$Q$54),0) -> 102.10526 | M9: =IF(AND(I9<>"",I9<>0,L9<>"",L9<>0),L9/I9,"") -> 0.55967111 | N9: =IF(AND(J9<>0,J9<>"",I9<>0,I9<>""),L9-I9,"") -> -80.33271 | O9: =O8/O11 -> #DIV/0! | P9: =IF(AND(O9<>"", O9<>0, L9<>"", L9<>0), -O9+L9, "") -> #DIV/0! | Q9: =IF(AND(P9<>"", P9<>0, O9<>0, O9<>""), P9/O9, "") -> #DIV/0!
F10: Средний чек | I10: =I11*I12 -> 10502 | J10: =H57 -> 9830.4833 | K10: =IF(AND(I10<>"", I10<>0, J10<>""), J10/I10, "") -> 0.93605821 | L10: =J10 -> 9830.4833 | M10: =IF(AND(I10<>"",I10<>0,L10<>"",L10<>0),L10/I10,"") -> 0.93605821 | N10: =IF(AND(J10<>0,J10<>"",I10<>0,I10<>""),L10-I10,"") -> -671.51667 | O10: =O11*O12 -> 0 | P10: =IF(AND(O10<>"", O10<>0, L10<>"", L10<>0), -O10+L10, "") | Q10: =IF(AND(P10<>"", P10<>0, O10<>0, O10<>""), P10/O10, "") | S10: IS | V10: =M23 -> Agafi
F11: Средняя стоимость изделия | I11: ='Ялта, Ленина, 18'!I11 -> 5900 | J11: =F57 -> 6080.7113 | K11: =IF(AND(I11<>"", I11<>0, J11<>""), J11/I11, "") -> 1.030629 | L11: =IF(L9>0,L8/L9,"") -> 6080.7113 | M11: =IF(AND(I11<>"",I11<>0,L11<>"",L11<>0),L11/I11,"") -> 1.030629 | N11: =IF(AND(J11<>0,J11<>"",I11<>0,I11<>""),L11-I11,"") -> 180.71134 | P11: =IF(AND(O11<>"", O11<>0, L11<>"", L11<>0), -O11+L11, "") | Q11: =IF(AND(P11<>"", P11<>0, O11<>0, O11<>""), P11/O11, "")
F12: Длина чека | I12: ='Ялта, Ленина, 18'!I12 -> 1.78 | J12: =J57 -> 1.6166667 | K12: =IF(AND(I12<>"", I12<>0, J12<>""), J12/I12, "") -> 0.9082397 | L12: =J12 -> 1.6166667 | M12: =IF(AND(I12<>"",I12<>0,L12<>"",L12<>0),L12/I12,"") -> 0.9082397 | N12: =IF(AND(J12<>0,J12<>"",I12<>0,I12<>""),L12-I12,"") -> -0.16333333 | P12: =IF(AND(O12<>"", O12<>0, L12<>"", L12<>0), -O12+L12, "") | Q12: =IF(AND(P12<>"", P12<>0, O12<>0, O12<>""), P12/O12, "") | S12: ='Ялта, Ленина, 18'!S12*График!AJ28/График!AJ31 -> 226283.78 | T12: =L57 -> 36809 | U12: =S12-T12 -> 189474.78 | V12: ='Ялта, Ленина, 18'!V12/График!AJ31*График!AJ28 -> 212972.97 | W12: =M57 -> 17480 | X12: =V12-W12 -> 195492.97
F13: Кол-во чеков | I13: =IF(I12<>0, I9/I12, "") -> 102.49324 | J13: =G57 -> 60 | K13: =IF(AND(I13<>"", I13<>0, J13<>""), J13/I13, "") -> 0.58540444 | L13: =IF(SUMIF($G$25:$G$54,">=0",$R$25:$R$54)<>0,I13*G57/SUMIF($G$25:$G$54,">=0",$R$25:$R$54),"") -> 63.157895 | M13: =IF(AND(I13<>"",I13<>0,L13<>"",L13<>0),L13/I13,"") -> 0.6162152 | N13: =IF(AND(J13<>0,J13<>"",I13<>0,I13<>""),L13-I13,"") -> -39.335349 | P13: =IF(AND(O13<>"", O13<>0, L13<>"", L13<>0), -O13+L13, "") | Q13: =IF(AND(P13<>"", P13<>0, O13<>0, O13<>""), P13/O13, "") | S13: =T12/S12 -> 0.16266742 | T13: =S13/J14*I14 -> 0.16266742 | V13: =W12/V12 -> 0.082076142 | W13: =V13/J14*I14 -> 0.082076142
F14: Кол-во смен план/отработано | I14: =График!AI28 -> 20 | J14: 20 | K14: =IF(AND(I14<>"", I14<>0, J14<>""), J14/I14, "") -> 1 | L14: =I14 -> 20 | M14: =IF(AND(I14<>"",I14<>0,L14<>"",L14<>0),L14/I14,"") -> 1 | N14: =IF(AND(J14<>0,J14<>"",I14<>0,I14<>""),L14-I14,"") -> 0 | P14: =IF(AND(O14<>"", O14<>0, L14<>"", L14<>0), -O14+L14, "") | Q14: =IF(AND(P14<>"", P14<>0, O14<>0, O14<>""), P14/O14, "")
F15: Средние продажи в смену | I15: ='Ялта, Ленина, 18'!I15 -> 78256.839 | J15: =J8/J14 -> 29491.45 | K15: =IF(AND(I15<>"", I15<>0, J15<>""), J15/I15, "") -> 0.3768546 | L15: =J15 -> 29491.45 | M15: =IF(AND(I15<>"",I15<>0,L15<>"",L15<>0),L15/I15,"") -> 0.3768546 | N15: =IF(AND(J15<>0,J15<>"",I15<>0,I15<>""),L15-I15,"") -> -48765.389 | P15: =IF(AND(O15<>"", O15<>0, L15<>"", L15<>0), -O15+L15, "") | Q15: =IF(AND(P15<>"", P15<>0, O15<>0, O15<>""), P15/O15, "")
F16: Отставание/Перевыполнение | J16: =J8-I15*J14 -> -975307.77 | K16: =IF(AND(I16<>"", I16<>0, J16<>""), J16/I16, "") | L16: =J16 -> -975307.77 | M16: =IF(AND(I16<>"",I16<>0,L16<>"",L16<>0),L16/I16,"") | N16: =IF(AND(J16<>0,J16<>"",I16<>0,I16<>""),L16-I16,"") | P16: =IF(AND(O16<>"", O16<>0, L16<>"", L16<>0), -O16+L16, "") | Q16: =IF(AND(P16<>"", P16<>0, O16<>0, O16<>""), P16/O16, "") | S16: UNOde50
F17: Трафик | I17: ='Ялта, Ленина, 18'!I17/График!AJ31*График!AJ28 -> 931.75676 | J17: =I57 -> 507 | K17: =IF(AND(I17<>"", I17<>0, J17<>""), J17/I17, "") -> 0.54413343 | L17: =J17/J14*I14 -> 507 | M17: =IF(AND(I17<>"",I17<>0,L17<>"",L17<>0),L17/I17,"") -> 0.54413343 | N17: =IF(AND(J17<>0,J17<>"",I17<>0,I17<>""),L17-I17,"") -> -424.75676 | P17: =IF(AND(O17<>"", O17<>0, L17<>"", L17<>0), -O17+L17, "") | Q17: =IF(AND(P17<>"", P17<>0, O17<>0, O17<>""), P17/O17, "")
K18: =IF(AND(I18<>"", I18<>0, J18<>""), J18/I18, "") | L18: =J18 -> 0 | M18: =IF(AND(I18<>"",I18<>0,L18<>"",L18<>0),L18/I18,"") | N18: =IF(AND(J18<>0,J18<>"",I18<>0,I18<>""),L18-I18,"") | O18: 0 | P18: =IF(AND(O18<>"", O18<>0, L18<>"", L18<>0), -O18+L18, "") | Q18: =IF(AND(P18<>"", P18<>0, O18<>0, O18<>""), P18/O18, "") | S18: ='Ялта, Ленина, 18'!S18*График!AJ28/График!AJ31 -> 452567.57 | T18: =K57 -> 86446
K19: =IF(AND(I19<>"", I19<>0, J19<>""), J19/I19, "") | L19: =J19 -> 0 | M19: =IF(AND(I19<>"",I19<>0,L19<>"",L19<>0),L19/I19,"") | N19: =IF(AND(J19<>0,J19<>"",I19<>0,I19<>""),L19-I19,"") | O19: 0 | P19: =IF(AND(O19<>"", O19<>0, L19<>"", L19<>0), -O19+L19, "") | Q19: =IF(AND(P19<>"", P19<>0, O19<>0, O19<>""), P19/O19, "") | S19: =T18/S18 -> 0.19101236 | T19: =S19/J14*I14 -> 0.19101236
