Workbook
Name маг: NA()

Sheet Центрум
A1: =TODAY()-1 -> 46151
A2: (01.03.2026-31.03.2026) | I2: ЕЖЕДНЕВНЫЙ ОТЧЕТ О ПРОДАЖАХ
C3: Осталось до выполнения плана!!! | I3: ТРК Центрум
C4: =I8-D56 -> 622617 | E4: =IF(I8<>0,C4/I8,0) -> 0.33174393
F6: Целевые показатели
F7: Показатель | I7: План | J7: Факт | K7: % выполнения | L7: Прогноз выполнения | M7: % выполнения по прогнозу | N7: Отклонение | O7: Факт аналогичного месяца прошлого года | P7: Отклонение LFL
F8: Выручка | I8: =I13*I10 -> 1876800 | J8: =D56 -> 1254183 | K8: =IF(AND(I8<>"",I8<>0,J8<>""),J8/I8,"") -> 0.66825607 | L8: =IF(SUMIF($D$25:$D$55,">=0",$V$25:$V$55)<>0,I8*D56/SUMIF($D$25:$D$55,">=0",$V$25:$V$55),0) -> 1254183 | M8: =L8/I8 -> 0.66825607 | N8: =IF(AND(J8<>0,J8<>"",I8<>0,I8<>""),L8-I8,"") -> -622617 | P8: =IF(AND(O8<>"",O8<>0,L8<>"",L8<>0),-O8+L8,"") | Q8: =IF(AND(O8<>"",O8<>0,N8<>0,N8<>""),O8/N8,"")
F9: Кол-во изделий | I9: =I8/I11 -> 272 | J9: =E56 -> 159 | K9: =IF(AND(I9<>"",I9<>0,J9<>""),J9/I9,"") -> 0.58455882 | L9: =IF(SUMIF($E$25:$E$55,">=0",$W$25:$W$55)<>0,I9*E56/SUMIF($E$25:$E$55,">=0",$W$25:$W$55),0) -> 159 | M9: =IF(AND(I9<>"",I9<>0,L9<>"",L9<>0),L9/I9,"") -> 0.58455882 | N9: =IF(AND(J9<>0,J9<>"",I9<>0,I9<>""),L9-I9,"") -> -113 | P9: =IF(AND(O9<>"",O9<>0,L9<>"",L9<>0),-O9+L9,"") | Q9: =IF(AND(O9<>"",O9<>0,N9<>0,N9<>""),O9/N9,"")
F10: Средний чек | I10: =I11*I12 -> 11730 | J10: =H56 -> 15677.288 | K10: =IF(AND(I10<>"",I10<>0,J10<>""),J10/I10,"") -> 1.3365121 | L10: =J10 -> 15677.288 | M10: =IF(AND(I10<>"",I10<>0,L10<>"",L10<>0),L10/I10,"") -> 1.3365121 | N10: =IF(AND(J10<>0,J10<>"",I10<>0,I10<>""),L10-I10,"") -> 3947.2875 | P10: =IF(AND(O10<>"",O10<>0,L10<>"",L10<>0),-O10+L10,"") | Q10: =IF(AND(O10<>"",O10<>0,N10<>0,N10<>""),O10/N10,"")
F11: Средняя стоимость изделия | I11: 6900 | J11: =F56 -> 7887.9434 | K11: =IF(AND(I11<>"",I11<>0,J11<>""),J11/I11,"") -> 1.1431802 | L11: =IF(L9>0,L8/L9,"") -> 7887.9434 | M11: =IF(AND(I11<>"",I11<>0,L11<>"",L11<>0),L11/I11,"") -> 1.1431802 | N11: =IF(AND(J11<>0,J11<>"",I11<>0,I11<>""),L11-I11,"") -> 987.9434 | P11: =IF(AND(O11<>"",O11<>0,L11<>"",L11<>0),-O11+L11,"") | Q11: =IF(AND(O11<>"",O11<>0,N11<>0,N11<>""),O11/N11,"")
F12: Длина чека | I12: 1.7 | J12: =J56 -> 1.9875 | K12: =IF(AND(I12<>"",I12<>0,J12<>""),J12/I12,"") -> 1.1691176 | L12: =J12 -> 1.9875 | M12: =IF(AND(I12<>"",I12<>0,L12<>"",L12<>0),L12/I12,"") -> 1.1691176 | N12: =IF(AND(J12<>0,J12<>"",I12<>0,I12<>""),L12-I12,"") -> 0.2875 | P12: =IF(AND(O12<>"",O12<>0,L12<>"",L12<>0),-O12+L12,"") | Q12: =IF(AND(O12<>"",O12<>0,N12<>0,N12<>""),O12/N12,"")
F13: Кол-во чеков | I13: =I17*I20 -> 160 | J13: =G56 -> 80 | K13: =IF(AND(I13<>"",I13<>0,J13<>""),J13/I13,"") -> 0.5 | L13: =IF(SUMIF($G$25:$G$55,">=0",$X$25:$X$55)<>0,I13*G56/SUMIF($G$25:$G$55,">=0",$X$25:$X$55),"") -> 80 | M13: =IF(AND(I13<>"",I13<>0,L13<>"",L13<>0),L13/I13,"") -> 0.5 | N13: =IF(AND(J13<>0,J13<>"",I13<>0,I13<>""),L13-I13,"") -> -80 | P13: =IF(AND(O13<>"",O13<>0,L13<>"",L13<>0),-O13+L13,"") | Q13: =IF(AND(O13<>"",O13<>0,N13<>0,N13<>""),O13/N13,"")
F14: Кол-во смен | I14: 30 | J14: 30 | K14: =IF(AND(I14<>"",I14<>0,J14<>""),J14/I14,"") -> 1 | L14: =IF(SUMIF($D$25:$D$55,">=0",$V$25:$V$55),I56*I8/SUMIF($D$25:$D$55,">=0",$V$25:$V$55),"") -> 1041.25 | N14: =IF(AND(J14<>0,J14<>"",I14<>0,I14<>""),L14-I14,"") -> 1011.25 | P14: =IF(AND(O14<>"",O14<>0,L14<>"",L14<>0),-O14+L14,"") | Q14: =IF(AND(O14<>"",O14<>0,N14<>0,N14<>""),O14/N14,"")
F15: Средние продажи в смену | I15: =I8/I14 -> 62560 | J15: =J8/J14 -> 41806.1 | K15: =IF(AND(I15<>"",I15<>0,J15<>""),J15/I15,"") -> 0.66825607 | L15: =J15 -> 41806.1 | M15: =IF(AND(I15<>"",I15<>0,L15<>"",L15<>0),L15/I15,"") -> 0.66825607 | N15: =IF(AND(J15<>0,J15<>"",I15<>0,I15<>""),L15-I15,"") -> -20753.9 | P15: =IF(AND(O15<>"",O15<>0,L15<>"",L15<>0),-O15+L15,"") | Q15: =IF(AND(O15<>"",O15<>0,N15<>0,N15<>""),O15/N15,"")
F16: Отставание/Перевыполнение | J16: =J8-I15*J14 -> -622617 | K16: =IF(AND(I16<>"",I16<>0,J16<>""),J16/I16,"") | L16: =J16 -> -622617 | M16: =IF(AND(I16<>"",I16<>0,L16<>"",L16<>0),L16/I16,"") | N16: =IF(AND(J16<>0,J16<>"",I16<>0,I16<>""),L16-I16,"") | P16: =IF(AND(O16<>"",O16<>0,L16<>"",L16<>0),-O16+L16,"") | Q16: =IF(AND(O16<>"",O16<>0,N16<>0,N16<>""),O16/N16,"") | S16: Подарочные сертификаты
F17: Трафик | I17: 1600 | J17: =I56 -> 1041.25 | K17: =IF(AND(I17<>"",I17<>0,J17<>""),J17/I17,"") -> 0.65078125 | L17: =J17/J14*I14 -> 1041.25 | M17: =IF(AND(I17<>"",I17<>0,L17<>"",L17<>0),L17/I17,"") -> 0.65078125 | N17: =IF(AND(J17<>0,J17<>"",I17<>0,I17<>""),L17-I17,"") -> -558.75 | P17: =IF(AND(O17<>"",O17<>0,L17<>"",L17<>0),-O17+L17,"") | Q17: =IF(AND(O17<>"",O17<>0,N17<>0,N17<>""),O17/N17,"")
F18: Выручка на вошедшего | I18: =I8/I17 -> 1173 | J18: =J8/J17 -> 1204.4975 | K18: =IF(AND(I18<>"",I18<>0,J18<>""),J18/I18,"") -> 1.0268521 | L18: =J18 -> 1204.4975 | M18: =IF(AND(I18<>"",I18<>0,L18<>"",L18<>0),L18/I18,"") -> 1.0268521 | N18: =IF(AND(J18<>0,J18<>"",I18<>0,I18<>""),L18-I18,"") -> 31.497479 | P18: =IF(AND(O18<>"",O18<>0,L18<>"",L18<>0),-O18+L18,"") | Q18: =IF(AND(O18<>"",O18<>0,N18<>0,N18<>""),O18/N18,"")
K19: =IF(AND(I19<>"",I19<>0,J19<>""),J19/I19,"") | L19: =J19 -> 0 | M19: =IF(AND(I19<>"",I19<>0,L19<>"",L19<>0),L19/I19,"") | N19: =IF(AND(J19<>0,J19<>"",I19<>0,I19<>""),L19-I19,"") | O19: 0 | P19: =IF(AND(O19<>"",O19<>0,L19<>"",L19<>0),-O19+L19,"") | Q19: =IF(AND(O19<>"",O19<>0,N19<>0,N19<>""),O19/N19,"") | S19: =S18/I16 -> #DIV/0!
F20: Конверсия | I20: 0.1 | J20: =T56 -> 0.076830732 | K20: =J20/I20 -> 0.76830732 | L20: =J20/I20 -> 0.76830732 | M20: =J20/I20 -> 0.76830732 | N20: =IF(AND(J20<>0,J20<>"",I20<>0,I20<>""),L20-I20,"") -> 0.66830732 | P20: =IF(AND(O20<>"",O20<>0,L20<>"",L20<>0),-O20+L20,"") | Q20: =IF(AND(O20<>"",O20<>0,N20<>0,N20<>""),O20/N20,"")
A22: Факт продаж за месяц | U22: % выполнения дневного плана | V22: Раcпределение плана по дням
A23: Сотрудник | B23: Дата | C23: День недели | D23: Выручка (руб) | E23: Кол-во единиц (шт.) | F23: Средняя стоимость изделия (руб.) | G23: Количество чеков (шт.) | H23: Средняя сумма чека (руб.) | I23: Трафик | J23: Длина чека (шт.) | K23: UNOde50 | L23: IS | M23: Agafi | N23: Kalliope | O23: Raganella | P23: CC/MP | Q23: Eva Rites | R23: Antura | S23: SALE | T23: Конверсия (%) | V23: выручка, план | W23: кол-во ед, план | X23: Кол-во чеков, план | Y23: выручка, скорректир.план | Z23: кол-во ед, скорр. план | AA23: кол-во чеков, скорр. план | AB23: Коэфф. Дня Недели | AC23: Специфика месяца
B24: 1 | C24: 2 | D24: 3 | E24: 4 | F24: 5 | H24: 7 | J24: 9 | K24: 10 | L24: 11 | M24: 12 | N24: 13 | O24: 14 | P24: 15 | Q24: 16 | R24: 17 | T24: 13 | V24: 1 | W24: 2 | X24: 3 | Y24: 4 | Z24: 5 | AA24: 6 | AB24: 10 | AC24: 11
A25: Маркова | B25: 46113 | C25: ср | D25: 27636 | E25: 6 | F25: =IF(AND(E25<>"",E25<>0),D25/E25,"") -> 4606 | G25: 4 | H25: =IF(AND(G25<>"",G25<>0),D25/G25,"") -> 6909 | I25: 35 | J25: =IF(AND(G25<>"",G25<>0),E25/G25,"") -> 1.5 | T25: =IF(AND(I25<>"",I25<>0),G25/I25,"") -> 0.11428571 | U25: =D25/V25 -> 0.32151463 | V25: =$I$8*AB25*AC25/SUMPRODUCT($AC$25:$AC$55,$AB$25:$AB$55) -> 85955.654 | W25: =$I$9*AB25*AC25/SUMPRODUCT($AC$25:$AC$55,$AB$25:$AB$55) -> 12.457341 | X25: =IF($I$12="","",W25/$I$12) -> 7.3278478 | Y25: =IF(D25<>"",D25,V25) -> 27636 | Z25: =IF(E25<>"",E25,W25) -> 6 | AA25: =IF(G25<>"",G25,X25) -> 4 | AB25: 1 | AC25: 0.75349421
A26: Бешлиева | B26: 46114 | C26: чт | D26: 29523 | E26: 3 | F26: =IF(AND(E26<>"",E26<>0),D26/E26,"") -> 9841 | G26: 2 | H26: =IF(AND(G26<>"",G26<>0),D26/G26,"") -> 14761.5 | I26: 40 | J26: =IF(AND(G26<>"",G26<>0),E26/G26,"") -> 1.5 | P26: 12391 | T26: =IF(AND(I26<>"",I26<>0),G26/I26,"") -> 0.05 | U26: =D26/V26 -> 0.19321479 | V26: =$I$8*AB26*AC26/SUMPRODUCT($AC$25:$AC$55,$AB$25:$AB$55) -> 152798.86 | W26: =$I$9*AB26*AC26/SUMPRODUCT($AC$25:$AC$55,$AB$25:$AB$55) -> 22.144763 | X26: =IF($I$12="","",W26/$I$12) -> 13.026331 | Y26: =IF(AB26<>"",IF(D26<>"",D26,($I$8-SUM($Y$25:Y25))*AA26*AB26/SUMPRODUCT($AB26:$AB$55,$AA26:$AA$55)),"") -> 29523 | Z26: =IF(AC26<>"",IF(E26<>"",E26,($I$9-SUM($Z$25:Z25))*AB26*AC26/SUMPRODUCT($AC26:$AC$55,$AB26:$AB$55)),"") -> 3 | AA26: =IF(AC26<>"",IF($I$12<>"",IF(G26<>"",G26,($I$9/$I$12-SUM($AA$25:AA25))*AB26*AC26/SUMPRODUCT($AC26:$AC$55,$AB26:$AB$55)),""),"") -> 2 | AB26: 1 | AC26: 1.3394472
A27: Бешлиева | B27: 46115 | C27: пт | D27: 14876 | E27: 3 | F27: =IF(AND(E27<>"",E27<>0),D27/E27,"") -> 4958.6667 | G27: 2 | H27: =IF(AND(G27<>"",G27<>0),D27/G27,"") -> 7438 | I27: 44 | J27: =IF(AND(G27<>"",G27<>0),E27/G27,"") -> 1.5 | T27: =IF(AND(I27<>"",I27<>0),G27/I27,"") -> 0.045454545 | U27: =D27/V27 -> 0.080452006 | V27: =$I$8*AB27*AC27/SUMPRODUCT($AC$25:$AC$55,$AB$25:$AB$55) -> 184905.27 | W27: =$I$9*AB27*AC27/SUMPRODUCT($AC$25:$AC$55,$AB$25:$AB$55) -> 26.797865 | X27: =IF($I$12="","",W27/$I$12) -> 15.76345 | Y27: =IF(AB27<>"",IF(D27<>"",D27,($I$8-SUM($Y$25:Y26))*AA27*AB27/SUMPRODUCT($AB27:$AB$55,$AA27:$AA$55)),"") -> 14876 | Z27: =IF(AC27<>"",IF(E27<>"",E27,($I$9-SUM($Z$25:Z26))*AB27*AC27/SUMPRODUCT($AC27:$AC$55,$AB27:$AB$55)),"") -> 3 | AA27: =IF(AC27<>"",IF($I$12<>"",IF(G27<>"",G27,($I$9/$I$12-SUM($AA$25:AA26))*AB27*AC27/SUMPRODUCT($AC27:$AC$55,$AB27:$AB$55)),""),"") -> 2 | AB27: 1 | AC27: 1.6208945
A28: Маркова | B28: 46116 | C28: сб | D28: 30939 | E28: 5 | F28: =IF(AND(E28<>"",E28<>0),D28/E28,"") -> 6187.8 | G28: 4 | H28: =IF(AND(G28<>"",G28<>0),D28/G28,"") -> 7734.75 | I28: 51 | J28: =IF(AND(G28<>"",G28<>0),E28/G28,"") -> 1.25 | S28: 4263 | T28: =IF(AND(I28<>"",I28<>0),G28/I28,"") -> 0.078431373 | U28: =D28/V28 -> 0.28181778 | V28: =$I$8*AB28*AC28/SUMPRODUCT($AC$25:$AC$55,$AB$25:$AB$55) -> 109783.71 | W28: =$I$9*AB28*AC28/SUMPRODUCT($AC$25:$AC$55,$AB$25:$AB$55) -> 15.910682 | X28: =IF($I$12="","",W28/$I$12) -> 9.3592248 | Y28: =IF(AB28<>"",IF(D28<>"",D28,($I$8-SUM($Y$25:Y27))*AA28*AB28/SUMPRODUCT($AB28:$AB$55,$AA28:$AA$55)),"") -> 30939 | Z28: =IF(AC28<>"",IF(E28<>"",E28,($I$9-SUM($Z$25:Z27))*AB28*AC28/SUMPRODUCT($AC28:$AC$55,$AB28:$AB$55)),"") -> 5 | AA28: =IF(AC28<>"",IF($I$12<>"",IF(G28<>"",G28,($I$9/$I$12-SUM($AA$25:AA27))*AB28*AC28/SUMPRODUCT($AC28:$AC$55,$AB28:$AB$55)),""),"") -> 4 | AB28: 1 | AC28: 0.96237284
A29: Маркова | B29: 46117 | C29: вс | D29: 18674 | E29: 3 | F29: =IF(AND(E29<>"",E29<>0),D29/E29,"") -> 6224.6667 | G29: 3 | H29: =IF(AND(G29<>"",G29<>0),D29/G29,"") -> 6224.6667 | I29: 34 | J29: =IF(AND(G29<>"",G29<>0),E29/G29,"") -> 1 | T29: =IF(AND(I29<>"",I29<>0),G29/I29,"") -> 0.088235294 | U29: =D29/V29 -> 0.25177848 | V29: =$I$8*AB29*AC29/SUMPRODUCT($AC$25:$AC$55,$AB$25:$AB$55) -> 74168.373 | W29: =$I$9*AB29*AC29/SUMPRODUCT($AC$25:$AC$55,$AB$25:$AB$55) -> 10.74904 | X29: =IF($I$12="","",W29/$I$12) -> 6.3229644 | Y29: =IF(AB29<>"",IF(D29<>"",D29,($I$8-SUM($Y$25:Y28))*AA29*AB29/SUMPRODUCT($AB29:$AB$55,$AA29:$AA$55)),"") -> 18674 | Z29: =IF(AC29<>"",IF(E29<>"",E29,($I$9-SUM($Z$25:Z28))*AB29*AC29/SUMPRODUCT($AC29:$AC$55,$AB29:$AB$55)),"") -> 3 | AA29: =IF(AC29<>"",IF($I$12<>"",IF(G29<>"",G29,($I$9/$I$12-SUM($AA$25:AA28))*AB29*AC29/SUMPRODUCT($AC29:$AC$55,$AB29:$AB$55)),""),"") -> 3 | AB29: 1 | AC29: 0.65016595
A30: Маркова,Рогалевич | B30: 46118 | C30: пн | D30: 8055 | E30: 2 | F30: =IF(AND(E30<>"",E30<>0),D30/E30,"") -> 4027.5 | G30: 1 | H30: =IF(AND(G30<>"",G30<>0),D30/G30,"") -> 8055 | I30: 31 | J30: =IF(AND(G30<>"",G30<>0),E30/G30,"") -> 2 | S30: 8051.17 | T30: =IF(AND(I30<>"",I30<>0),G30/I30,"") -> 0.032258065 | U30: =D30/V30 -> 0.097903561 | V30: =$I$8*AB30*AC30/SUMPRODUCT($AC$25:$AC$55,$AB$25:$AB$55) -> 82274.842 | W30: =$I$9*AB30*AC30/SUMPRODUCT($AC$25:$AC$55,$AB$25:$AB$55) -> 11.92389 | X30: =IF($I$12="","",W30/$I$12) -> 7.014053 | Y30: =IF(AB30<>"",IF(D30<>"",D30,($I$8-SUM($Y$25:Y29))*AA30*AB30/SUMPRODUCT($AB30:$AB$55,$AA30:$AA$55)),"") -> 8055 | Z30: =IF(AC30<>"",IF(E30<>"",E30,($I$9-SUM($Z$25:Z29))*AB30*AC30/SUMPRODUCT($AC30:$AC$55,$AB30:$AB$55)),"") -> 2 | AA30: =IF(AC30<>"",IF($I$12<>"",IF(G30<>"",G30,($I$9/$I$12-SUM($AA$25:AA29))*AB30*AC30/SUMPRODUCT($AC30:$AC$55,$AB30:$AB$55)),""),"") -> 1 | AB30: 1 | AC30: 0.72122791
A31: Бешлиева,Рогалевич | B31: 46119 | C31: вт | D31: 16967 | E31: 3 | F31: =IF(AND(E31<>"",E31<>0),D31/E31,"") -> 5655.6667 | G31: 2 | H31: =IF(AND(G31<>"",G31<>0),D31/G31,"") -> 8483.5 | I31: 34 | J31: =IF(AND(G31<>"",G31<>0),E31/G31,"") -> 1.5 | T31: =IF(AND(I31<>"",I31<>0),G31/I31,"") -> 0.058823529 | U31: =D31/V31 -> 0.20622343 | V31: =$I$8*AB31*AC31/SUMPRODUCT($AC$25:$AC$55,$AB$25:$AB$55) -> 82274.842 | W31: =$I$9*AB31*AC31/SUMPRODUCT($AC$25:$AC$55,$AB$25:$AB$55) -> 11.92389 | X31: =IF($I$12="","",W31/$I$12) -> 7.014053 | Y31: =IF(AB31<>"",IF(D31<>"",D31,($I$8-SUM($Y$25:Y30))*AA31*AB31/SUMPRODUCT($AB31:$AB$55,$AA31:$AA$55)),"") -> 16967 | Z31: =IF(AC31<>"",IF(E31<>"",E31,($I$9-SUM($Z$25:Z30))*AB31*AC31/SUMPRODUCT($AC31:$AC$55,$AB31:$AB$55)),"") -> 3 | AA31: =IF(AC31<>"",IF($I$12<>"",IF(G31<>"",G31,($I$9/$I$12-SUM($AA$25:AA30))*AB31*AC31/SUMPRODUCT($AC31:$AC$55,$AB31:$AB$55)),""),"") -> 2 | AB31: 1 | AC31: 0.72122791
A32: Бешлиева,Рогалевич | B32: 46120 | C32: ср | D32: 90013 | E32: 9 | F32: =IF(AND(E32<>"",E32<>0),D32/E32,"") -> 10001.444 | G32: 6 | H32: =IF(AND(G32<>"",G32<>0),D32/G32,"") -> 15002.167 | I32: 42 | J32: =IF(AND(G32<>"",G32<>0),E32/G32,"") -> 1.5 | K32: 51415 | M32: 7093 | R32: 6440 | T32: =IF(AND(I32<>"",I32<>0),G32/I32,"") -> 0.14285714 | U32: =D32/V32 -> 1.4790559 | V32: =$I$8*AB32*AC32/SUMPRODUCT($AC$25:$AC$55,$AB$25:$AB$55) -> 60858.416 | W32: =$I$9*AB32*AC32/SUMPRODUCT($AC$25:$AC$55,$AB$25:$AB$55) -> 8.8200603 | X32: =IF($I$12="","",W32/$I$12) -> 5.1882707 | Y32: =IF(AB32<>"",IF(D32<>"",D32,($I$8-SUM($Y$25:Y31))*AA32*AB32/SUMPRODUCT($AB32:$AB$55,$AA32:$AA$55)),"") -> 90013 | Z32: =IF(AC32<>"",IF(E32<>"",E32,($I$9-SUM($Z$25:Z31))*AB32*AC32/SUMPRODUCT($AC32:$AC$55,$AB32:$AB$55)),"") -> 9 | AA32: =IF(AC32<>"",IF($I$12<>"",IF(G32<>"",G32,($I$9/$I$12-SUM($AA$25:AA31))*AB32*AC32/SUMPRODUCT($AC32:$AC$55,$AB32:$AB$55)),""),"") -> 6 | AB32: 1 | AC32: 0.53348979
A33: Маркова,Рогалевич | B33: 46121 | C33: чт | D33: 37609 | E33: 5 | F33: =IF(AND(E33<>"",E33<>0),D33/E33,"") -> 7521.8 | G33: 3 | H33: =IF(AND(G33<>"",G33<>0),D33/G33,"") -> 12536.333 | I33: 46 | J33: =IF(AND(G33<>"",G33<>0),E33/G33,"") -> 1.6666667 | S33: 4123 | T33: =IF(AND(I33<>"",I33<>0),G33/I33,"") -> 0.065217391 | U33: =D33/V33 -> 0.82420883 | V33: =$I$8*AB33*AC33/SUMPRODUCT($AC$25:$AC$55,$AB$25:$AB$55) -> 45630.426 | W33: =$I$9*AB33*AC33/SUMPRODUCT($AC$25:$AC$55,$AB$25:$AB$55) -> 6.6131052 | X33: =IF($I$12="","",W33/$I$12) -> 3.8900619 | Y33: =IF(AB33<>"",IF(D33<>"",D33,($I$8-SUM($Y$25:Y32))*AA33*AB33/SUMPRODUCT($AB33:$AB$55,$AA33:$AA$55)),"") -> 37609 | Z33: =IF(AC33<>"",IF(E33<>"",E33,($I$9-SUM($Z$25:Z32))*AB33*AC33/SUMPRODUCT($AC33:$AC$55,$AB33:$AB$55)),"") -> 5 | AA33: =IF(AC33<>"",IF($I$12<>"",IF(G33<>"",G33,($I$9/$I$12-SUM($AA$25:AA32))*AB33*AC33/SUMPRODUCT($AC33:$AC$55,$AB33:$AB$55)),""),"") -> 3 | AB33: 1 | AC33: 0.4
A34: Бешлиева,Рогалевич | B34: 46122 | C34: пт | D34: 23175 | E34: 4 | F34: =IF(AND(E34<>"",E34<>0),D34/E34,"") -> 5793.75 | G34: 2 | H34: =IF(AND(G34<>"",G34<>0),D34/G34,"") -> 11587.5 | I34: 51 | J34: =IF(AND(G34<>"",G34<>0),E34/G34,"") -> 2 | T34: =IF(AND(I34<>"",I34<>0),G34/I34,"") -> 0.039215686 | U34: =D34/V34 -> 0.5078848 | V34: =$I$8*AB34*AC34/SUMPRODUCT($AC$25:$AC$55,$AB$25:$AB$55) -> 45630.426 | W34: =$I$9*AB34*AC34/SUMPRODUCT($AC$25:$AC$55,$AB$25:$AB$55) -> 6.6131052 | X34: =IF($I$12="","",W34/$I$12) -> 3.8900619 | Y34: =IF(AB34<>"",IF(D34<>"",D34,($I$8-SUM($Y$25:Y33))*AA34*AB34/SUMPRODUCT($AB34:$AB$55,$AA34:$AA$55)),"") -> 23175 | Z34: =IF(AC34<>"",IF(E34<>"",E34,($I$9-SUM($Z$25:Z33))*AB34*AC34/SUMPRODUCT($AC34:$AC$55,$AB34:$AB$55)),"") -> 4 | AA34: =IF(AC34<>"",IF($I$12<>"",IF(G34<>"",G34,($I$9/$I$12-SUM($AA$25:AA33))*AB34*AC34/SUMPRODUCT($AC34:$AC$55,$AB34:$AB$55)),""),"") -> 2 | AB34: 1 | AC34: 0.4
A35: Бешлиева | B35: 46123 | C35: сб | D35: 77762 | E35: 10 | F35: =IF(AND(E35<>"",E35<>0),D35/E35,"") -> 7776.2 | G35: 6 | H35: =IF(AND(G35<>"",G35<>0),D35/G35,"") -> 12960.333 | I35: 36 | J35: =IF(AND(G35<>"",G35<>0),E35/G35,"") -> 1.6666667 | R35: 25513 | T35: =IF(AND(I35<>"",I35<>0),G35/I35,"") -> 0.16666667 | U35: =D35/V35 -> 1.7041699 | V35: =$I$8*AB35*AC35/SUMPRODUCT($AC$25:$AC$55,$AB$25:$AB$55) -> 45630.426 | W35: =$I$9*AB35*AC35/SUMPRODUCT($AC$25:$AC$55,$AB$25:$AB$55) -> 6.6131052 | X35: =IF($I$12="","",W35/$I$12) -> 3.8900619 | Y35: =IF(AB35<>"",IF(D35<>"",D35,($I$8-SUM($Y$25:Y34))*AA35*AB35/SUMPRODUCT($AB35:$AB$55,$AA35:$AA$55)),"") -> 77762 | Z35: =IF(AC35<>"",IF(E35<>"",E35,($I$9-SUM($Z$25:Z34))*AB35*AC35/SUMPRODUCT($AC35:$AC$55,$AB35:$AB$55)),"") -> 10 | AA35: =IF(AC35<>"",IF($I$12<>"",IF(G35<>"",G35,($I$9/$I$12-SUM($AA$25:AA34))*AB35*AC35/SUMPRODUCT($AC35:$AC$55,$AB35:$AB$55)),""),"") -> 6 | AB35: 1 | AC35: 0.4
A36: Маркова | B36: 46124 | C36: вс | D36: 28377 | E36: 3 | F36: =IF(AND(E36<>"",E36<>0),D36/E36,"") -> 9459 | G36: 2 | H36: =IF(AND(G36<>"",G36<>0),D36/G36,"") -> 14188.5 | I36: 46 | J36: =IF(AND(G36<>"",G36<>0),E36/G36,"") -> 1.5 | M36: 14992 | T36: =IF(AND(I36<>"",I36<>0),G36/I36,"") -> 0.043478261 | U36: =D36/V36 -> 0.62188768 | V36: =$I$8*AB36*AC36/SUMPRODUCT($AC$25:$AC$55,$AB$25:$AB$55) -> 45630.426 | W36: =$I$9*AB36*AC36/SUMPRODUCT($AC$25:$AC$55,$AB$25:$AB$55) -> 6.6131052 | X36: =IF($I$12="","",W36/$I$12) -> 3.8900619 | Y36: =IF(AB36<>"",IF(D36<>"",D36,($I$8-SUM($Y$25:Y35))*AA36*AB36/SUMPRODUCT($AB36:$AB$55,$AA36:$AA$55)),"") -> 28377 | Z36: =IF(AC36<>"",IF(E35<>"",E35,($I$9-SUM($Z$25:Z35))*AB36*AC36/SUMPRODUCT($AC36:$AC$55,$AB36:$AB$55)),"") -> 10 | AA36: =IF(AC36<>"",IF($I$12<>"",IF(G36<>"",G36,($I$9/$I$12-SUM($AA$25:AA35))*AB36*AC36/SUMPRODUCT($AC36:$AC$55,$AB36:$AB$55)),""),"") -> 2 | AB36: 1 | AC36: 0.4
A37: Бешлиева | B37: 46125 | C37: пн | D37: 44417 | E37: 6 | F37: =IF(AND(E37<>"",E37<>0),D37/E37,"") -> 7402.8333 | G37: 5 | H37: =IF(AND(G37<>"",G37<>0),D37/G37,"") -> 8883.4 | I37: 42 | J37: =IF(AND(G37<>"",G37<>0),E37/G37,"") -> 1.2 | K37: 10993 | O37: 7658 | T37: =IF(AND(I37<>"",I37<>0),G37/I37,"") -> 0.11904762 | U37: =D37/V37 -> 0.97340752 | V37: =$I$8*AB37*AC37/SUMPRODUCT($AC$25:$AC$55,$AB$25:$AB$55) -> 45630.426 | W37: =$I$9*AB37*AC37/SUMPRODUCT($AC$25:$AC$55,$AB$25:$AB$55) -> 6.6131052 | X37: =IF($I$12="","",W37/$I$12) -> 3.8900619 | Y37: =IF(AB37<>"",IF(D37<>"",D37,($I$8-SUM($Y$25:Y36))*AA37*AB37/SUMPRODUCT($AB37:$AB$55,$AA37:$AA$55)),"") -> 44417 | Z37: =IF(AC37<>"",IF(E37<>"",E37,($I$9-SUM($Z$25:Z36))*AB37*AC37/SUMPRODUCT($AC37:$AC$55,$AB37:$AB$55)),"") -> 6 | AA37: =IF(AC37<>"",IF($I$12<>"",IF(G37<>"",G37,($I$9/$I$12-SUM($AA$25:AA36))*AB37*AC37/SUMPRODUCT($AC37:$AC$55,$AB37:$AB$55)),""),"") -> 5 | AB37: 1 | AC37: 0.4
A38: Маркова | B38: 46126 | C38: вт | D38: 4692 | E38: 1 | F38: =IF(AND(E38<>"",E38<>0),D38/E38,"") -> 4692 | G38: 1 | H38: =IF(AND(G38<>"",G38<>0),D38/G38,"") -> 4692 | I38: 34 | J38: =IF(AND(G38<>"",G38<>0),E38/G38,"") -> 1 | T38: =IF(AND(I38<>"",I38<>0),G38/I38,"") -> 0.029411765 | U38: =D38/V38 -> 0.10221277 | V38: =$I$8*AB38*AC38/SUMPRODUCT($AC$25:$AC$55,$AB$25:$AB$55) -> 45904.247 | W38: =$I$9*AB38*AC38/SUMPRODUCT($AC$25:$AC$55,$AB$25:$AB$55) -> 6.6527894 | X38: =IF($I$12="","",W38/$I$12) -> 3.9134055 | Y38: =IF(AB38<>"",IF(D38<>"",D38,($I$8-SUM($Y$25:Y37))*AA38*AB38/SUMPRODUCT($AB38:$AB$55,$AA38:$AA$55)),"") -> 4692 | Z38: =IF(AC38<>"",IF(E38<>"",E38,($I$9-SUM($Z$25:Z37))*AB38*AC38/SUMPRODUCT($AC38:$AC$55,$AB38:$AB$55)),"") -> 1 | AA38: =IF(AC38<>"",IF($I$12<>"",IF(G38<>"",G38,($I$9/$I$12-SUM($AA$25:AA37))*AB38*AC38/SUMPRODUCT($AC38:$AC$55,$AB38:$AB$55)),""),"") -> 1 | AB38: 1 | AC38: 0.40240033
A39: Бешлиева | B39: 46127 | C39: ср | D39: 4196 | E39: 1 | F39: =IF(AND(E39<>"",E39<>0),D39/E39,"") -> 4196 | G39: 1 | H39: =IF(AND(G39<>"",G39<>0),D39/G39,"") -> 4196 | I39: 36 | J39: =IF(AND(G39<>"",G39<>0),E39/G39,"") -> 1 | S39: 4193 | T39: =IF(AND(I39<>"",I39<>0),G39/I39,"") -> 0.027777778 | U39: =D39/V39 -> 0.045541057 | V39: =$I$8*AB39*AC39/SUMPRODUCT($AC$25:$AC$55,$AB$25:$AB$55) -> 92136.641 | W39: =$I$9*AB39*AC39/SUMPRODUCT($AC$25:$AC$55,$AB$25:$AB$55) -> 13.353136 | X39: =IF($I$12="","",W39/$I$12) -> 7.8547861 | Y39: =IF(AB39<>"",IF(D39<>"",D39,($I$8-SUM($Y$25:Y38))*AA39*AB39/SUMPRODUCT($AB39:$AB$55,$AA39:$AA$55)),"") -> 4196 | Z39: =IF(AC39<>"",IF(E39<>"",E39,($I$9-SUM($Z$25:Z38))*AB39*AC39/SUMPRODUCT($AC39:$AC$55,$AB39:$AB$55)),"") -> 1 | AA39: =IF(AC39<>"",IF($I$12<>"",IF(G39<>"",G39,($I$9/$I$12-SUM($AA$25:AA38))*AB39*AC39/SUMPRODUCT($AC39:$AC$55,$AB39:$AB$55)),""),"") -> 1 | AB39: 1 | AC39: 0.80767724
A40: Маркова | B40: 46128 | C40: чт | D40: 11286 | E40: 2 | F40: =IF(AND(E40<>"",E40<>0),D40/E40,"") -> 5643 | G40: 2 | H40: =IF(AND(G40<>"",G40<>0),D40/G40,"") -> 5643 | I40: 18 | J40: =IF(AND(G40<>"",G40<>0),E40/G40,"") -> 1 | T40: =IF(AND(I40<>"",I40<>0),G40/I40,"") -> 0.11111111 | U40: =D40/V40 -> 0.12249198 | V40: =$I$8*AB40*AC40/SUMPRODUCT($AC$25:$AC$55,$AB$25:$AB$55) -> 92136.641 | W40: =$I$9*AB40*AC40/SUMPRODUCT($AC$25:$AC$55,$AB$25:$AB$55) -> 13.353136 | X40: =IF($I$12="","",W40/$I$12) -> 7.8547861 | Y40: =IF(AB40<>"",IF(D40<>"",D40,($I$8-SUM($Y$25:Y39))*AA40*AB40/SUMPRODUCT($AB40:$AB$55,$AA40:$AA$55)),"") -> 11286 | Z40: =IF(AC40<>"",IF(E40<>"",E40,($I$9-SUM($Z$25:Z39))*AB40*AC40/SUMPRODUCT($AC40:$AC$55,$AB40:$AB$55)),"") -> 2 | AA40: =IF(AC40<>"",IF($I$12<>"",IF(G40<>"",G40,($I$9/$I$12-SUM($AA$25:AA39))*AB40*AC40/SUMPRODUCT($AC40:$AC$55,$AB40:$AB$55)),""),"") -> 2 | AB40: 1 | AC40: 0.80767724
A41: Маркова | B41: 46129 | C41: пт | D41: 0 | E41: 0 | F41: 0 | G41: 0 | H41: 0 | I41: 20 | J41: =IF(AND(G41<>"",G41<>0),E41/G41,"") | T41: =IF(AND(I41<>"",I41<>0),G41/I41,"") -> 0 | U41: =D41/V41 -> 0 | V41: =$I$8*AB41*AC41/SUMPRODUCT($AC$25:$AC$55,$AB$25:$AB$55) -> 77491.522 | W41: =$I$9*AB41*AC41/SUMPRODUCT($AC$25:$AC$55,$AB$25:$AB$55) -> 11.230655 | X41: =IF($I$12="","",W41/$I$12) -> 6.6062678 | Y41: =IF(AB41<>"",IF(D41<>"",D41,($I$8-SUM($Y$25:Y40))*AA41*AB41/SUMPRODUCT($AB41:$AB$55,$AA41:$AA$55)),"") -> 0 | Z41: =IF(AC41<>"",IF(E41<>"",E41,($I$9-SUM($Z$25:Z40))*AB41*AC41/SUMPRODUCT($AC41:$AC$55,$AB41:$AB$55)),"") -> 0 | AA41: =IF(AC41<>"",IF($I$12<>"",IF(G41<>"",G41,($I$9/$I$12-SUM($AA$25:AA40))*AB41*AC41/SUMPRODUCT($AC41:$AC$55,$AB41:$AB$55)),""),"") -> 0 | AB41: 1 | AC41: 0.67929694
A42: Бешлиева | B42: 46130 | C42: сб | D42: 38263 | E42: 7 | F42: =IF(AND(E42<>"",E42<>0),D42/E42,"") -> 5466.1429 | G42: 4 | H42: =IF(AND(G42<>"",G42<>0),D42/G42,"") -> 9565.75 | I42: 35 | J42: =IF(AND(G42<>"",G42<>0),E42/G42,"") -> 1.75 | T42: =IF(AND(I42<>"",I42<>0),G42/I42,"") -> 0.11428571 | U42: =D42/V42 -> 0.91576768 | V42: =$I$8*AB42*AC42/SUMPRODUCT($AC$25:$AC$55,$AB$25:$AB$55) -> 41782.431 | W42: =$I$9*AB42*AC42/SUMPRODUCT($AC$25:$AC$55,$AB$25:$AB$55) -> 6.0554248 | X42: =IF($I$12="","",W42/$I$12) -> 3.5620146 | Y42: =IF(AB42<>"",IF(D42<>"",D42,($I$8-SUM($Y$25:Y41))*AA42*AB42/SUMPRODUCT($AB42:$AB$55,$AA42:$AA$55)),"") -> 38263 | Z42: =IF(AC42<>"",IF(E42<>"",E42,($I$9-SUM($Z$25:Z41))*AB42*AC42/SUMPRODUCT($AC42:$AC$55,$AB42:$AB$55)),"") -> 7 | AA42: =IF(AC42<>"",IF($I$12<>"",IF(G42<>"",G42,($I$9/$I$12-SUM($AA$25:AA41))*AB42*AC42/SUMPRODUCT($AC42:$AC$55,$AB42:$AB$55)),""),"") -> 4 | AB42: 1 | AC42: 0.36626817
...

Sheet Справочник магазинов
A1: МЕГА Белая Дача
A2: Гагаринский
A3: Марфино

Sheet Сводная
A2: Показатель | D2: =Центрум!I3 -> ТРК Центрум | G2: =[1]График!B28 -> Рогалевич Ирина | J2: =График!B27 -> Маркова Диана | M2: =График!B26 -> Бешлиева Аджере
D3: Факт | F3: Прогноз | G3: Факт | I3: Прогноз | J3: Факт | L3: Прогноз | M3: Факт | O3: Прогноз
A4: Выручка | D4: =Центрум!K8 -> 0.66825607 | E4: =Центрум!J8 -> 1254183 | F4: =Центрум!M8 -> 0.66825607 | G4: =Рогалевич!N8 -> #DIV/0! | H4: =Рогалевич!M8 -> #DIV/0! | I4: =Рогалевич!P8 -> #DIV/0! | J4: =Маркова!N8 -> 0.34306653 | K4: =Маркова!M8 -> 191420 | L4: =Маркова!P8 -> 0.34306653 | M4: =Бешлиева!N8 -> 0.59231937 | N4: =Бешлиева!M8 -> 540810 | O4: =Бешлиева!P8 -> 0.59231937
A5: Кол-во изделий | D5: =Центрум!K9 -> 0.58455882 | E5: =Центрум!J9 -> 159 | F5: =Центрум!M9 -> 0.58455882 | G5: =Рогалевич!N9 -> #DIV/0! | H5: =Рогалевич!M9 -> #DIV/0! | I5: =Рогалевич!P9 -> #DIV/0! | J5: =Маркова!N9 -> 0.38335561 | K5: =Маркова!M9 -> 31 | L5: =Маркова!P9 -> 0.38335561 | M5: =Бешлиева!N9 -> 0.60457516 | N5: =Бешлиева!M9 -> 80 | O5: =Бешлиева!P9 -> 0.60457516
A6: Средний чек | D6: =Центрум!K10 -> 1.3365121 | E6: =Центрум!J10 -> 15677.288 | F6: =Центрум!M10 -> 1.3365121 | G6: =Рогалевич!N10 -> 53514.125 | H6: =Рогалевич!M10 -> 5.562159 | I6: =Рогалевич!P10 | J6: =Маркова!N10 -> 0.74176548 | K6: =Маркова!M10 -> 8700.9091 | L6: =Маркова!P10 -> 0.74176548 | M6: =Бешлиева!N10 -> 0.92209719 | N6: =Бешлиева!M10 -> 10816.2 | O6: =Бешлиева!P10 -> 0.92209719
A7: Средняя стоимость изделия | D7: =Центрум!K11 -> 1.1431802 | E7: =Центрум!J11 -> 7887.9434 | F7: =Центрум!M11 -> 1.1431802 | G7: =Рогалевич!N11 -> #DIV/0! | H7: =Рогалевич!M11 -> #DIV/0! | I7: =Рогалевич!P11 -> #DIV/0! | J7: =Маркова!N11 -> 0.89490416 | K7: =Маркова!M11 -> 6174.8387 | L7: =Маркова!P11 -> 0.89490416 | M7: =Бешлиева!N11 -> 0.97972826 | N7: =Бешлиева!M11 -> 6760.125 | O7: =Бешлиева!P11 -> 0.97972826
A8: Длина чека | D8: =Центрум!K12 -> 1.1691176 | E8: =Центрум!J12 -> 1.9875 | F8: =Центрум!M12 -> 1.1691176 | G8: =Рогалевич!N12 -> 4.3 | H8: =Рогалевич!M12 -> 3.5294118 | I8: =Рогалевич!P12 | J8: =Маркова!N12 -> 0.82887701 | K8: =Маркова!M12 -> 1.4090909 | L8: =Маркова!P12 -> 0.82887701 | M8: =Бешлиева!N12 -> 0.94117647 | N8: =Бешлиева!M12 -> 1.6 | O8: =Бешлиева!P12 -> 0.94117647
A9: Кол-во чеков | D9: =Центрум!K13 -> 0.5 | E9: =Центрум!J13 -> 80 | F9: =Центрум!M13 -> 0.5 | G9: =Рогалевич!N13 -> #DIV/0! | H9: =Рогалевич!M13 -> #DIV/0! | I9: =Рогалевич!P13 -> #DIV/0! | J9: =Маркова!N13 -> 0.4625 | K9: =Маркова!M13 -> 22 | L9: =Маркова!P13 -> 0.4625 | M9: =Бешлиева!N13 -> 0.64236111 | N9: =Бешлиева!M13 -> 50 | O9: =Бешлиева!P13 -> 0.64236111
A10: Кол-во смен план/отработано | D10: =Центрум!K14 -> 1 | E10: =Центрум!J14 -> 30 | G10: =Рогалевич!N14 -> #DIV/0! | H10: =Рогалевич!M14 -> #DIV/0! | I10: =Рогалевич!P14 -> #DIV/0! | J10: =Маркова!N14 -> 1 | K10: =Маркова!M14 -> 11 | M10: =Бешлиева!N14 -> 1 | N10: =Бешлиева!M14 -> 18 | O10: =Бешлиева!P14 -> 0
A11: Средние продажи в смену | D11: =Центрум!K15 -> 0.66825607 | E11: =Центрум!J15 -> 41806.1 | F11: =Центрум!M15 -> 0.66825607 | G11: =Рогалевич!N15 -> -10364.7 | H11: =Рогалевич!M15 -> 0.83432385 | I11: =Рогалевич!P15 | J11: =Маркова!N15 -> 0.55632411 | K11: =Маркова!M15 -> 17401.818 | L11: =Маркова!P15 -> 0.55632411 | M11: =Бешлиева!N15 -> 0.9605179 | N11: =Бешлиева!M15 -> 30045 | O11: =Бешлиева!P15 -> 0.9605179
A12: Трафик | D12: =Центрум!K17 -> 0.65078125 | E12: =Центрум!J17 -> 1041.25 | F12: =Центрум!M17 -> 0.65078125 | G12: =Рогалевич!N17 | H12: =Рогалевич!M17 | I12: =Рогалевич!P17 | J12: =Маркова!N17 -> 0.42381818 | K12: =Маркова!M17 -> 201.6 | L12: =Маркова!P17 -> 0.42381818 | M12: =Бешлиева!N17 -> 0.54472222 | N12: =Бешлиева!M17 -> 424 | O12: =Бешлиева!P17 -> 0.54472222
A13: ='[1]Ялта, Ленина, 18'!F18 -> Выручка на вошедшего | D13: =Центрум!K18 -> 1.0268521 | E13: =Центрум!J18 -> 1204.4975 | F13: ='[1]Ялта, Ленина, 18'!M18 -> 0.75390061 | G13: =Рогалевич!N18 -> #DIV/0! | H13: =Рогалевич!M18 -> #DIV/0! | I13: =Рогалевич!P18 | J13: =Маркова!N18 -> 0.8094663 | K13: =Маркова!M18 -> 949.50397 | L13: =Маркова!P18 -> 0.8094663 | M13: =Бешлиева!N18 -> 1.0873788 | N13: =Бешлиева!M18 -> 1275.4953 | O13: =Бешлиева!P18 -> 1.0873788
A14: ='[1]Ялта, Ленина, 18'!F20 -> Конверсия план/факт | D14: =Центрум!K20 -> 0.76830732 | E14: =Центрум!J20 -> 0.076830732 | G14: =Рогалевич!N20 -> -0.0061249965 | H14: =Рогалевич!M20 -> 0.93875003 | J14: =Маркова!N20 -> 1.0912698 | K14: =Маркова!M20 -> 0.10912698 | L14: =Маркова!T13 | M14: =Бешлиева!N20 -> 1.1792453 | N14: =Бешлиева!M20 -> 0.11792453
A15: Доп. KPI | D15: =Центрум!L56+Центрум!S56 -> 53655.17 | G15: =[1]Рогалевич!R57 -> 0 | J15: =[1]Уразгильдеева!R57 -> 0 | M15: =Бешлиева!L48+Бешлиева!S48 -> 37218

Sheet План на день
A1: Выручка | D1: =86000 -> 86000
A2: Кол-во изделий | D2: =D1/D4 -> 12.463768
A3: Средний чек | D3: =D4*D5 -> 11730
A4: Средняя стоимость изделия | D4: =Центрум!I11 -> 6900
A5: Длина чека | D5: =Центрум!I12 -> 1.7
A6: Кол-во чеков | D6: =IF(D5<>0,D2/D5,"") -> 7.3316283
A7: Конверсия | D7: =Центрум!I20 -> 0.1

Sheet Рогалевич
C1: =TODAY()-1 -> 46151
C2: (отчетная дата) | J2: ЕЖЕДНЕВНЫЙ ОТЧЕТ О ПРОДАЖАХ
C3: Осталось до выполнения плана!!! | J3: =График!B28 -> Рогалевич Ирина
C4: =I8-D48 -> -116158.41 | E4: =IF(I8<>0,C4/I8,0) -> -0.28624927
F6: Целевые показатели
F7: Показатель | I7: План | J7: Факт | K7: % выполнения | L7: Прогноз выполнения | M7: % выполнения по прогнозу | N7: Отклонение | O7: Факт аналогичного месяца прошлого года | P7: Отклонение LFL
F8: Выручка | I8: =Центрум!I8/График!AJ29*График!AJ28 -> 405794.59 | J8: =D48 -> 521953 | K8: =IF(AND(I8<>"",I8<>0,J8<>""),J8/I8,"") -> 1.2862493 | L8: =IF(SUMIF($D$25:$D$47,">=0",$V$25:$V$47)<>0,I8*D48/SUMIF($D$25:$D$47,">=0",$V$25:$V$47),0) -> #DIV/0! | M8: =L8/I8 -> #DIV/0! | N8: =IF(AND(J8<>0,J8<>"",I8<>0,I8<>""),L8-I8,"") -> #DIV/0! | P8: =IF(AND(O8<>"",O8<>0,L8<>"",L8<>0),-O8+L8,"") -> #DIV/0! | Q8: =IF(AND(P8<>"",P8<>0,O8<>0,O8<>""),P8/O8,"") -> #DIV/0!
F9: Кол-во изделий | I9: =I8/I11 -> 58.810811 | J9: =E48 -> 48 | K9: =IF(AND(I9<>"",I9<>0,J9<>""),J9/I9,"") -> 0.81617647 | L9: =IF(SUMIF($E$25:$E$47,">=0",$W$25:$W$47)<>0,I9*E48/SUMIF($E$25:$E$47,">=0",$W$25:$W$47),0) -> #DIV/0! | M9: =IF(AND(I9<>"",I9<>0,L9<>"",L9<>0),L9/I9,"") -> #DIV/0! | N9: =IF(AND(J9<>0,J9<>"",I9<>0,I9<>""),L9-I9,"") -> #DIV/0! | P9: =IF(AND(O9<>"",O9<>0,L9<>"",L9<>0),-O9+L9,"") -> #DIV/0! | Q9: =IF(AND(P9<>"",P9<>0,O9<>0,O9<>""),P9/O9,"") -> #DIV/0!
F10: Средний чек | I10: =I11*I12 -> 11730 | J10: =H48 -> 65244.125 | K10: =IF(AND(I10<>"",I10<>0,J10<>""),J10/I10,"") -> 5.562159 | L10: =J10 -> 65244.125 | M10: =IF(AND(I10<>"",I10<>0,L10<>"",L10<>0),L10/I10,"") -> 5.562159 | N10: =IF(AND(J10<>0,J10<>"",I10<>0,I10<>""),L10-I10,"") -> 53514.125 | O10: =O11*O12 -> 0 | P10: =IF(AND(O10<>"",O10<>0,L10<>"",L10<>0),-O10+L10,"") | Q10: =IF(AND(P10<>"",P10<>0,O10<>0,O10<>""),P10/O10,"")
F11: Средняя стоимость изделия | I11: =Центрум!I11 -> 6900 | J11: =F48 -> 10874.021 | K11: =IF(AND(I11<>"",I11<>0,J11<>""),J11/I11,"") -> 1.575945 | L11: =IF(L9>0,L8/L9,"") -> #DIV/0! | M11: =IF(AND(I11<>"",I11<>0,L11<>"",L11<>0),L11/I11,"") -> #DIV/0! | N11: =IF(AND(J11<>0,J11<>"",I11<>0,I11<>""),L11-I11,"") -> #DIV/0! | P11: =IF(AND(O11<>"",O11<>0,L11<>"",L11<>0),-O11+L11,"") -> #DIV/0! | Q11: =IF(AND(P11<>"",P11<>0,O11<>0,O11<>""),P11/O11,"") -> #DIV/0!
F12: Длина чека | I12: =Центрум!I12 -> 1.7 | J12: =J48 -> 6 | K12: =IF(AND(I12<>"",I12<>0,J12<>""),J12/I12,"") -> 3.5294118 | L12: =J12 -> 6 | M12: =IF(AND(I12<>"",I12<>0,L12<>"",L12<>0),L12/I12,"") -> 3.5294118 | N12: =IF(AND(J12<>0,J12<>"",I12<>0,I12<>""),L12-I12,"") -> 4.3 | P12: =IF(AND(O12<>"",O12<>0,L12<>"",L12<>0),-O12+L12,"") | Q12: =IF(AND(P12<>"",P12<>0,O12<>0,O12<>""),P12/O12,"")
F13: Кол-во чеков | I13: =IF(I12<>0,I9/I12,"") -> 34.594595 | J13: =G48 -> 8 | K13: =IF(AND(I13<>"",I13<>0,J13<>""),J13/I13,"") -> 0.23125 | L13: =IF(SUMIF($G$25:$G$47,">=0",$X$25:$X$47)<>0,I13*G48/SUMIF($G$25:$G$47,">=0",$X$25:$X$47),"") -> #DIV/0! | M13: =IF(AND(I13<>"",I13<>0,L13<>"",L13<>0),L13/I13,"") -> #DIV/0! | N13: =IF(AND(J13<>0,J13<>"",I13<>0,I13<>""),L13-I13,"") -> #DIV/0! | P13: =IF(AND(O13<>"",O13<>0,L13<>"",L13<>0),-O13+L13,"") -> #DIV/0! | Q13: =IF(AND(P13<>"",P13<>0,O13<>0,O13<>""),P13/O13,"") -> #DIV/0!
F14: Кол-во смен | I14: =График!AI28 -> 10 | J14: 10 | K14: =IF(AND(I14<>"",I14<>0,J14<>""),J14/I14,"") -> 1 | L14: =IF(SUMIF($D$25:$D$47,">=0",$V$25:$V$47),I48*I8/SUMIF($D$25:$D$47,">=0",$V$25:$V$47),"") -> #DIV/0! | M14: =IF(AND(I14<>"",I14<>0,L14<>"",L14<>0),L14/I14,"") -> #DIV/0! | N14: =IF(AND(J14<>0,J14<>"",I14<>0,I14<>""),L14-I14,"") -> #DIV/0! | P14: =IF(AND(O14<>"",O14<>0,L14<>"",L14<>0),-O14+L14,"") -> #DIV/0! | Q14: =IF(AND(P14<>"",P14<>0,O14<>0,O14<>""),P14/O14,"") -> #DIV/0!
F15: Средние продажи в смену | I15: =Центрум!I15 -> 62560 | J15: =J8/J14 -> 52195.3 | K15: =IF(AND(I15<>"",I15<>0,J15<>""),J15/I15,"") -> 0.83432385 | L15: =J15 -> 52195.3 | M15: =IF(AND(I15<>"",I15<>0,L15<>"",L15<>0),L15/I15,"") -> 0.83432385 | N15: =IF(AND(J15<>0,J15<>"",I15<>0,I15<>""),L15-I15,"") -> -10364.7 | P15: =IF(AND(O15<>"",O15<>0,L15<>"",L15<>0),-O15+L15,"") | Q15: =IF(AND(P15<>"",P15<>0,O15<>0,O15<>""),P15/O15,"")
F16: Отставание/Перевыполнение | J16: =J8-I15*J14 -> -103647 | K16: =IF(AND(I16<>"",I16<>0,J16<>""),J16/I16,"") | L16: =J16 -> -103647 | M16: =IF(AND(I16<>"",I16<>0,L16<>"",L16<>0),L16/I16,"") | N16: =IF(AND(J16<>0,J16<>"",I16<>0,I16<>""),L16-I16,"") | P16: =IF(AND(O16<>"",O16<>0,L16<>"",L16<>0),-O16+L16,"") | Q16: =IF(AND(P16<>"",P16<>0,O16<>0,O16<>""),P16/O16,"") | S16: Подарочные сертификаты
F17: Трафик | I17: =Центрум!I17/График!AJ29*График!AJ25 -> 0 | J17: =I48 -> 84 | K17: =IF(AND(I17<>"",I17<>0,J17<>""),J17/I17,"") | L17: =J17/J14*I14 -> 84 | M17: =IF(AND(I17<>"",I17<>0,L17<>"",L17<>0),L17/I17,"") | N17: =IF(AND(J17<>0,J17<>"",I17<>0,I17<>""),L17-I17,"") | P17: =IF(AND(O17<>"",O17<>0,L17<>"",L17<>0),-O17+L17,"") | Q17: =IF(AND(P17<>"",P17<>0,O17<>0,O17<>""),P17/O17,"")
F18: Выручка на вошедшего | I18: =I8/I17 -> #DIV/0! | J18: =J8/J17 -> 6213.7262 | K18: =IF(AND(I18<>"",I18<>0,J18<>""),J18/I18,"") -> #DIV/0! | L18: =J18 -> 6213.7262 | M18: =IF(AND(I18<>"",I18<>0,L18<>"",L18<>0),L18/I18,"") -> #DIV/0! | N18: =IF(AND(J18<>0,J18<>"",I18<>0,I18<>""),L18-I18,"") -> #DIV/0! | O18: 0 | P18: =IF(AND(O18<>"",O18<>0,L18<>"",L18<>0),-O18+L18,"") | Q18: =IF(AND(P18<>"",P18<>0,O18<>0,O18<>""),P18/O18,"")
J19: =Q48 -> 0 | K19: =IF(AND(I19<>"",I19<>0,J19<>""),J19/I19,"") | L19: =J19 -> 0 | M19: =IF(AND(I19<>"",I19<>0,L19<>"",L19<>0),L19/I19,"") | N19: =IF(AND(J19<>0,J19<>"",I19<>0,I19<>""),L19-I19,"") | O19: 0 | P19: =IF(AND(O19<>"",O19<>0,L19<>"",L19<>0),-O19+L19,"") | Q19: =IF(AND(P19<>"",P19<>0,O19<>0,O19<>""),P19/O19,"") | S19: =S18/I16 -> #DIV/0!
F20: Конверсия | I20: =Центрум!I20 -> 0.1 | J20: =T48 -> 0.095238095 | K20: =J20/I20 -> 0.95238095 | L20: =IF(AND(K8<>0,I14<>0,I48<>0),(I48*T48+(I48/K8-I48)*I20)/(I48/K8),0) -> 0.093875003 | M20: =IF(AND(I20<>"",I20<>0,L20<>"",L20<>0),L20/I20,"") -> 0.93875003 | N20: =IF(AND(J20<>0,J20<>"",I20<>0,I20<>""),L20-I20,"") -> -0.0061249965 | P20: =IF(AND(O20<>"",O20<>0,L20<>"",L20<>0),-O20+L20,"") | Q20: =IF(AND(P20<>"",P20<>0,O20<>0,O20<>""),P20/O20,"")
A22: Факт продаж за месяц | V22: Раcпределение плана по дням
B23: Дата | C23: День недели | D23: Выручка (руб) | E23: Кол-во единиц (шт.) | F23: Средняя стоимость изделия (руб.) | G23: Количество чеков (шт.) | H23: Средняя сумма чека (руб.) | I23: Трафик | J23: Длина чека (шт.) | K23: UNOde50 | L23: IS | M23: Agafi | N23: Kalliope | O23: Raganella | P23: CC/MP | Q23: Eva Rites | R23: Antura | S23: SALE | T23: Конверсия (%) | U23: % выполнения дневного плана | V23: выручка, план | W23: кол-во ед, план | X23: Кол-во чеков, план | Y23: выручка, скорректир.план | Z23: кол-во ед, скорр. план | AA23: кол-во чеков, скорр. план | AB23: Коэфф. Дня Недели | AC23: Специфика месяца
B24: 1 | C24: 2 | D24: 3 | E24: в | F24: 5 | G24: 6 | H24: 7 | I24: 8 | J24: 9 | K24: 10 | L24: 11 | M24: 12 | N24: 13 | O24: 14 | P24: 15 | Q24: 16 | R24: 17 | S24: 18 | T24: 19 | V24: 1 | W24: 2 | X24: 3 | Y24: 4 | Z24: 5 | AA24: 6 | AB24: 10 | AC24: 11
A25: 1 | B25: 46118 | C25: пн | D25: 0 | E25: 0 | F25: 0 | G25: 0 | H25: 0 | J25: =IF(AND(G25<>"",G25<>0),E25/G25,"") | T25: =IF(AND(I25<>"",I25<>0),G25/I25,"") | U25: =D25/V25 -> #DIV/0! | V25: =$I$8*AB25*AC25/SUMPRODUCT($AC$25:$AC$55,$AB$25:$AB$55) -> #DIV/0! | W25: =$I$9*AB25*AC25/SUMPRODUCT($AC$25:$AC$55,$AB$25:$AB$55) -> #DIV/0! | X25: =IF($I$12="","",W25/$I$12) -> #DIV/0! | Y25: =IF(AC25<>"",IF(D25<>"",D25,($I$8-SUM($Y24:Y$25))*AB25*AC25/SUMPRODUCT($AC25:$AC$55,$AB25:$AB$55)),"") | Z25: =IF(AC25<>"",IF(E25<>"",E25,($I$9-SUM($Z24:Z$25))*AB25*AC25/SUMPRODUCT($AC25:$AC$55,$AB25:$AB$55)),"") | AA25: =IF(AC25<>"",IF($I$12<>"",IF(G25<>"",G25,($I$9/$I$12-SUM($AA24:AA$25))*AB25*AC25/SUMPRODUCT($AC25:$AC$55,$AB25:$AB$55)),""),"")
A26: 2 | B26: 46119 | C26: вт | D26: 0 | E26: 0 | F26: 0 | G26: 0 | H26: 0 | I26: 8 | J26: =IF(AND(G26<>"",G26<>0),E26/G26,"") | T26: =IF(AND(I26<>"",I26<>0),G26/I26,"") -> 0 | U26: =D26/V26 -> #DIV/0! | V26: =$I$8*AB26*AC26/SUMPRODUCT($AC$25:$AC$55,$AB$25:$AB$55) -> #DIV/0! | W26: =$I$9*AB26*AC26/SUMPRODUCT($AC$25:$AC$55,$AB$25:$AB$55) -> #DIV/0! | X26: =IF($I$12="","",W26/$I$12) -> #DIV/0! | Y26: =IF(AC26<>"",IF(D26<>"",D26,($I$8-SUM($Y$25:Y25))*AB26*AC26/SUMPRODUCT($AC26:$AC$55,$AB26:$AB$55)),"") | Z26: =IF(AC26<>"",IF(E26<>"",E26,($I$9-SUM($Z$25:Z25))*AB26*AC26/SUMPRODUCT($AC26:$AC$55,$AB26:$AB$55)),"") | AA26: =IF(AC26<>"",IF($I$12<>"",IF(G26<>"",G26,($I$9/$I$12-SUM($AA$25:AA25))*AB26*AC26/SUMPRODUCT($AC26:$AC$55,$AB26:$AB$55)),""),"")
A27: 3 | B27: 46120 | C27: ср | D27: 21072 | E27: 3 | F27: =IF(AND(E27<>"",E27<>0),D27/E27,"") -> 7024 | G27: 2 | H27: =IF(AND(G27<>"",G27<>0),D27/G27,"") -> 10536 | I27: 20 | J27: =IF(AND(G27<>"",G27<>0),E27/G27,"") -> 1.5 | T27: =IF(AND(I27<>"",I27<>0),G27/I27,"") -> 0.1 | U27: =D27/V27 -> #DIV/0! | V27: =$I$8*AB27*AC27/SUMPRODUCT($AC$25:$AC$55,$AB$25:$AB$55) -> #DIV/0! | W27: =$I$9*AB27*AC27/SUMPRODUCT($AC$25:$AC$55,$AB$25:$AB$55) -> #DIV/0! | X27: =IF($I$12="","",W27/$I$12) -> #DIV/0! | Y27: =IF(AC27<>"",IF(D27<>"",D27,($I$8-SUM($Y$25:Y26))*AB27*AC27/SUMPRODUCT($AC27:$AC$55,$AB27:$AB$55)),"") | Z27: =IF(AC27<>"",IF(E27<>"",E27,($I$9-SUM($Z$25:Z26))*AB27*AC27/SUMPRODUCT($AC27:$AC$55,$AB27:$AB$55)),"") | AA27: =IF(AC27<>"",IF($I$12<>"",IF(G27<>"",G27,($I$9/$I$12-SUM($AA$25:AA26))*AB27*AC27/SUMPRODUCT($AC27:$AC$55,$AB27:$AB$55)),""),"")
A28: 4 | B28: 46121 | C28: чт | D28: 12200 | E28: 2 | F28: =IF(AND(E28<>"",E28<>0),D28/E28,"") -> 6100 | G28: 1 | H28: =IF(AND(G28<>"",G28<>0),D28/G28,"") -> 12200 | I28: 15 | J28: =IF(AND(G28<>"",G28<>0),E28/G28,"") -> 2 | T28: =IF(AND(I28<>"",I28<>0),G28/I28,"") -> 0.066666667 | U28: =D28/V28 -> #DIV/0! | V28: =$I$8*AB28*AC28/SUMPRODUCT($AC$25:$AC$55,$AB$25:$AB$55) -> #DIV/0! | W28: =$I$9*AB28*AC28/SUMPRODUCT($AC$25:$AC$55,$AB$25:$AB$55) -> #DIV/0! | X28: =IF($I$12="","",W28/$I$12) -> #DIV/0! | Y28: =IF(AC28<>"",IF(D28<>"",D28,($I$8-SUM($Y$25:Y27))*AB28*AC28/SUMPRODUCT($AC28:$AC$55,$AB28:$AB$55)),"") | Z28: =IF(AC28<>"",IF(E27<>"",E27,($I$9-SUM($Z$25:Z27))*AB28*AC28/SUMPRODUCT($AC28:$AC$55,$AB28:$AB$55)),"") | AA28: =IF(AC28<>"",IF($I$12<>"",IF(G28<>"",G28,($I$9/$I$12-SUM($AA$25:AA27))*AB28*AC28/SUMPRODUCT($AC28:$AC$55,$AB28:$AB$55)),""),"")
A29: 5 | B29: 46122 | C29: пт | D29: 0 | E29: 0 | F29: 0 | G29: 0 | H29: =IF(AND(G29<>"",G29<>0),D29/G29,"") | I29: 15 | J29: =IF(AND(G29<>"",G29<>0),E29/G29,"") | T29: =IF(AND(I29<>"",I29<>0),G29/I29,"") -> 0 | U29: =D29/V29 -> #DIV/0! | V29: =$I$8*AB29*AC29/SUMPRODUCT($AC$25:$AC$55,$AB$25:$AB$55) -> #DIV/0! | W29: =$I$9*AB29*AC29/SUMPRODUCT($AC$25:$AC$55,$AB$25:$AB$55) -> #DIV/0! | X29: =IF($I$12="","",W29/$I$12) -> #DIV/0! | Y29: =IF(AC29<>"",IF(D29<>"",D29,($I$8-SUM($Y$25:Y28))*AB29*AC29/SUMPRODUCT($AC29:$AC$55,$AB29:$AB$55)),"") | Z29: =IF(AC29<>"",IF(E29<>"",E29,($I$9-SUM($Z$25:Z28))*AB29*AC29/SUMPRODUCT($AC29:$AC$55,$AB29:$AB$55)),"") | AA29: =IF(AC29<>"",IF($I$12<>"",IF(G29<>"",G29,($I$9/$I$12-SUM($AA$25:AA28))*AB29*AC29/SUMPRODUCT($AC29:$AC$55,$AB29:$AB$55)),""),"")
A30: 6 | B30: 46132 | C30: пн | D30: 0 | E30: 0 | F30: 0 | G30: 0 | H30: 0 | I30: 10 | J30: =IF(AND(G30<>"",G30<>0),E30/G30,"") | T30: =IF(AND(I30<>"",I30<>0),G30/I30,"") -> 0 | U30: =D30/V30 -> #DIV/0! | V30: =$I$8*AB30*AC30/SUMPRODUCT($AC$25:$AC$55,$AB$25:$AB$55) -> #DIV/0! | W30: =$I$9*AB30*AC30/SUMPRODUCT($AC$25:$AC$55,$AB$25:$AB$55) -> #DIV/0! | X30: =IF($I$12="","",W30/$I$12) -> #DIV/0! | Y30: =IF(AC30<>"",IF(D30<>"",D30,($I$8-SUM($Y$25:Y29))*AB30*AC30/SUMPRODUCT($AC30:$AC$55,$AB30:$AB$55)),"") | Z30: =IF(AC30<>"",IF(E30<>"",E30,($I$9-SUM($Z$25:Z29))*AB30*AC30/SUMPRODUCT($AC30:$AC$55,$AB30:$AB$55)),"") | AA30: =IF(AC30<>"",IF($I$12<>"",IF(G30<>"",G30,($I$9/$I$12-SUM($AA$25:AA29))*AB30*AC30/SUMPRODUCT($AC30:$AC$55,$AB30:$AB$55)),""),"")
A31: 7 | B31: 46133 | C31: вт | D31: 0 | E31: 0 | F31: 0 | G31: 0 | H31: 0 | I31: 7 | J31: =IF(AND(G31<>"",G31<>0),E31/G31,"") | T31: =IF(AND(I31<>"",I31<>0),G31/I31,"") -> 0 | U31: =D31/V31 -> #DIV/0! | V31: =$I$8*AB31*AC31/SUMPRODUCT($AC$25:$AC$55,$AB$25:$AB$55) -> #DIV/0! | W31: =$I$9*AB31*AC31/SUMPRODUCT($AC$25:$AC$55,$AB$25:$AB$55) -> #DIV/0! | X31: =IF($I$12="","",W31/$I$12) -> #DIV/0! | Y31: =IF(AC31<>"",IF(D31<>"",D31,($I$8-SUM($Y$25:Y30))*AB31*AC31/SUMPRODUCT($AC31:$AC$55,$AB31:$AB$55)),"") | Z31: =IF(AC31<>"",IF(E31<>"",E31,($I$9-SUM($Z$25:Z30))*AB31*AC31/SUMPRODUCT($AC31:$AC$55,$AB31:$AB$55)),"") | AA31: =IF(AC31<>"",IF($I$12<>"",IF(G31<>"",G31,($I$9/$I$12-SUM($AA$25:AA30))*AB31*AC31/SUMPRODUCT($AC31:$AC$55,$AB31:$AB$55)),""),"")
A32: 8 | B32: 46134 | C32: ср | D32: 34650 | E32: 6 | F32: =IF(AND(E32<>"",E32<>0),D32/E32,"") -> 5775 | G32: 2 | H32: =IF(AND(G32<>"",G32<>0),D32/G32,"") -> 17325 | I32: 13 | J32: =IF(AND(G32<>"",G32<>0),E32/G32,"") -> 3 | T32: =IF(AND(I32<>"",I32<>0),G32/I32,"") -> 0.15384615 | U32: =D32/V32 -> #DIV/0! | V32: =$I$8*AB32*AC32/SUMPRODUCT($AC$25:$AC$55,$AB$25:$AB$55) -> #DIV/0! | W32: =$I$9*AB32*AC32/SUMPRODUCT($AC$25:$AC$55,$AB$25:$AB$55) -> #DIV/0! | X32: =IF($I$12="","",W32/$I$12) -> #DIV/0! | Y32: =IF(AC32<>"",IF(D32<>"",D32,($I$8-SUM($Y$25:Y31))*AB32*AC32/SUMPRODUCT($AC32:$AC$55,$AB32:$AB$55)),"") | Z32: =IF(AC32<>"",IF(E32<>"",E32,($I$9-SUM($Z$25:Z31))*AB32*AC32/SUMPRODUCT($AC32:$AC$55,$AB32:$AB$55)),"") | AA32: =IF(AC32<>"",IF($I$12<>"",IF(G32<>"",G32,($I$9/$I$12-SUM($AA$25:AA31))*AB32*AC32/SUMPRODUCT($AC32:$AC$55,$AB32:$AB$55)),""),"")
A33: 9 | B33: 46135 | C33: чт | D33: 0 | E33: 0 | F33: 0 | G33: 0 | H33: 0 | I33: 0 | J33: =IF(AND(G33<>"",G33<>0),E33/G33,"") | T33: =IF(AND(I33<>"",I33<>0),G33/I33,"") | U33: =D33/V33 -> #DIV/0! | V33: =$I$8*AB33*AC33/SUMPRODUCT($AC$25:$AC$55,$AB$25:$AB$55) -> #DIV/0! | W33: =$I$9*AB33*AC33/SUMPRODUCT($AC$25:$AC$55,$AB$25:$AB$55) -> #DIV/0! | X33: =IF($I$12="","",W33/$I$12) -> #DIV/0! | Y33: =IF(AC33<>"",IF(D33<>"",D33,($I$8-SUM($Y$25:Y32))*AB33*AC33/SUMPRODUCT($AC33:$AC$55,$AB33:$AB$55)),"") | Z33: =IF(AC33<>"",IF(E33<>"",E33,($I$9-SUM($Z$25:Z32))*AB33*AC33/SUMPRODUCT($AC33:$AC$55,$AB33:$AB$55)),"") | AA33: =IF(AC33<>"",IF($I$12<>"",IF(G33<>"",G33,($I$9/$I$12-SUM($AA$25:AA32))*AB33*AC33/SUMPRODUCT($AC33:$AC$55,$AB33:$AB$55)),""),"")
A34: 10 | B34: 46142 | C34: чт | D34: 454031 | E34: 37 | F34: =IF(AND(E34<>"",E34<>0),D34/E34,"") -> 12271.108 | G34: 3 | H34: =IF(AND(G34<>"",G34<>0),D34/G34,"") -> 151343.67 | I34: 17 | J34: =IF(AND(G34<>"",G34<>0),E34/G34,"") -> 12.333333 | N34: 227591 | O34: 190704 | P34: 26543 | T34: =IF(AND(I34<>"",I34<>0),G34/I34,"") -> 0.17647059 | U34: =D34/V34 -> #DIV/0! | V34: =$I$8*AB34*AC34/SUMPRODUCT($AC$25:$AC$55,$AB$25:$AB$55) -> #DIV/0! | W34: =$I$9*AB34*AC34/SUMPRODUCT($AC$25:$AC$55,$AB$25:$AB$55) -> #DIV/0! | X34: =IF($I$12="","",W34/$I$12) -> #DIV/0! | Y34: =IF(AC34<>"",IF(D34<>"",D34,($I$8-SUM($Y$25:Y33))*AB34*AC34/SUMPRODUCT($AC34:$AC$55,$AB34:$AB$55)),"") | Z34: =IF(AC34<>"",IF(E34<>"",E34,($I$9-SUM($Z$25:Z33))*AB34*AC34/SUMPRODUCT($AC34:$AC$55,$AB34:$AB$55)),"") | AA34: =IF(AC34<>"",IF($I$12<>"",IF(G34<>"",G34,($I$9/$I$12-SUM($AA$25:AA33))*AB34*AC34/SUMPRODUCT($AC34:$AC$55,$AB34:$AB$55)),""),"")
A35: 11 | F35: =IF(AND(E35<>"",E35<>0),D35/E35,"") | H35: =IF(AND(G35<>"",G35<>0),D35/G35,"") | J35: =IF(AND(G35<>"",G35<>0),E35/G35,"") | T35: =IF(AND(I35<>"",I35<>0),G35/I35,"") | U35: =D35/V35 -> #DIV/0! | V35: =$I$8*AB35*AC35/SUMPRODUCT($AC$25:$AC$55,$AB$25:$AB$55) -> #DIV/0! | W35: =$I$9*AB35*AC35/SUMPRODUCT($AC$25:$AC$55,$AB$25:$AB$55) -> #DIV/0! | X35: =IF($I$12="","",W35/$I$12) -> #DIV/0! | Y35: =IF(AC35<>"",IF(D35<>"",D35,($I$8-SUM($Y$25:Y34))*AB35*AC35/SUMPRODUCT($AC35:$AC$55,$AB35:$AB$55)),"") | Z35: =IF(AC34<>"",IF(E34<>"",E34,($I$9-SUM($Z$25:Z33))*AB34*AC34/SUMPRODUCT($AC34:$AC$55,$AB34:$AB$55)),"") | AA35: =IF(AC34<>"",IF($I$12<>"",IF(G34<>"",G34,($I$9/$I$12-SUM($AA$25:AA33))*AB34*AC34/SUMPRODUCT($AC34:$AC$55,$AB34:$AB$55)),""),"")
A36: 12 | F36: =IF(AND(E36<>"",E36<>0),D36/E36,"") | H36: =IF(AND(G36<>"",G36<>0),D36/G36,"") | J36: =IF(AND(G36<>"",G36<>0),E36/G36,"") | T36: =IF(AND(I36<>"",I36<>0),G36/I36,"") | U36: =D36/V36 -> #DIV/0! | V36: =$I$8*AB36*AC36/SUMPRODUCT($AC$25:$AC$55,$AB$25:$AB$55) -> #DIV/0! | W36: =$I$9*AB36*AC36/SUMPRODUCT($AC$25:$AC$55,$AB$25:$AB$55) -> #DIV/0! | X36: =IF($I$12="","",W36/$I$12) -> #DIV/0! | Y36: =IF(AC36<>"",IF(D36<>"",D36,($I$8-SUM($Y$25:Y35))*AB36*AC36/SUMPRODUCT($AC36:$AC$55,$AB36:$AB$55)),"") | Z36: =IF(AC36<>"",IF(E36<>"",E36,($I$9-SUM($Z$25:Z35))*AB36*AC36/SUMPRODUCT($AC36:$AC$55,$AB36:$AB$55)),"") | AA36: =IF(AC36<>"",IF($I$12<>"",IF(G36<>"",G36,($I$9/$I$12-SUM($AA$25:AA35))*AB36*AC36/SUMPRODUCT($AC36:$AC$55,$AB36:$AB$55)),""),"")
A37: 13 | F37: =IF(AND(E37<>"",E37<>0),D37/E37,"") | H37: =IF(AND(G37<>"",G37<>0),D37/G37,"") | J37: =IF(AND(G37<>"",G37<>0),E37/G37,"") | T37: =IF(AND(I37<>"",I37<>0),G37/I37,"") | U37: =D37/V37 -> #DIV/0! | V37: =$I$8*AB37*AC37/SUMPRODUCT($AC$25:$AC$55,$AB$25:$AB$55) -> #DIV/0! | W37: =$I$9*AB37*AC37/SUMPRODUCT($AC$25:$AC$55,$AB$25:$AB$55) -> #DIV/0! | X37: =IF($I$12="","",W37/$I$12) -> #DIV/0! | Y37: =IF(AC37<>"",IF(D37<>"",D37,($I$8-SUM($Y$25:Y36))*AB37*AC37/SUMPRODUCT($AC37:$AC$55,$AB37:$AB$55)),"") | Z37: =IF(AC37<>"",IF(E37<>"",E37,($I$9-SUM($Z$25:Z36))*AB37*AC37/SUMPRODUCT($AC37:$AC$55,$AB37:$AB$55)),"") | AA37: =IF(AC37<>"",IF($I$12<>"",IF(G37<>"",G37,($I$9/$I$12-SUM($AA$25:AA36))*AB37*AC37/SUMPRODUCT($AC37:$AC$55,$AB37:$AB$55)),""),"")
A38: 14 | F38: =IF(AND(E38<>"",E38<>0),D38/E38,"") | H38: =IF(AND(G38<>"",G38<>0),D38/G38,"") | J38: =IF(AND(G38<>"",G38<>0),E38/G38,"") | T38: =IF(AND(I38<>"",I38<>0),G38/I38,"") | U38: =D38/V38 -> #DIV/0! | V38: =$I$8*AB38*AC38/SUMPRODUCT($AC$25:$AC$46,$AB$25:$AB$46) -> #DIV/0! | W38: =$I$9*AB38*AC38/SUMPRODUCT($AC$25:$AC$46,$AB$25:$AB$46) -> #DIV/0! | X38: =IF($I$12="","",W38/$I$12) -> #DIV/0! | Y38: =IF(AC38<>"",IF(D38<>"",D38,($I$8-SUM($Y$25:Y37))*AB38*AC38/SUMPRODUCT($AC38:$AC$55,$AB38:$AB$55)),"") | Z38: =IF(AC38<>"",IF(E38<>"",E38,($I$9-SUM($Z$25:Z37))*AB38*AC38/SUMPRODUCT($AC38:$AC$55,$AB38:$AB$55)),"") | AA38: =IF(AC38<>"",IF($I$12<>"",IF(G38<>"",G38,($I$9/$I$12-SUM($AA$25:AA37))*AB38*AC38/SUMPRODUCT($AC38:$AC$55,$AB38:$AB$55)),""),"")
F39: =IF(AND(E39<>"",E39<>0),D39/E39,"") | H39: =IF(AND(G39<>"",G39<>0),D39/G39,"") | J39: =IF(AND(G39<>"",G39<>0),E39/G39,"") | T39: =IF(AND(I39<>"",I39<>0),G39/I39,"") | U39: =D39/V39 -> #DIV/0! | V39: =$I$8*AB39*AC39/SUMPRODUCT($AC$25:$AC$46,$AB$25:$AB$46) -> #DIV/0! | W39: =$I$9*AB39*AC39/SUMPRODUCT($AC$25:$AC$46,$AB$25:$AB$46) -> #DIV/0! | X39: =IF($I$12="","",W39/$I$12) -> #DIV/0! | Y39: =IF(AC39<>"",IF(D39<>"",D39,($I$8-SUM($Y$25:Y38))*AB39*AC39/SUMPRODUCT($AC39:$AC$47,$AB39:$AB$47)),"") | Z39: =IF(AC39<>"",IF(E39<>"",E39,($I$9-SUM($Z$25:Z38))*AB39*AC39/SUMPRODUCT($AC39:$AC$55,$AB39:$AB$55)),"") | AA39: =IF(AC39<>"",IF($I$12<>"",IF(G39<>"",G39,($I$9/$I$12-SUM($AA$25:AA38))*AB39*AC39/SUMPRODUCT($AC39:$AC$55,$AB39:$AB$55)),""),"")
F40: =IF(AND(E40<>"",E40<>0),D40/E40,"") | H40: =IF(AND(G40<>"",G40<>0),D40/G40,"") | J40: =IF(AND(G40<>"",G40<>0),E40/G40,"") | T40: =IF(AND(I40<>"",I40<>0),G40/I40,"") | U40: =D40/V40 -> #DIV/0! | V40: =$I$8*AB40*AC40/SUMPRODUCT($AC$25:$AC$46,$AB$25:$AB$46) -> #DIV/0! | W40: =$I$9*AB40*AC40/SUMPRODUCT($AC$25:$AC$46,$AB$25:$AB$46) -> #DIV/0! | X40: =IF($I$12="","",W40/$I$12) -> #DIV/0! | Y40: =IF(AC40<>"",IF(D40<>"",D40,($I$8-SUM($Y$25:Y39))*AB40*AC40/SUMPRODUCT($AC40:$AC$46,$AB40:$AB$46)),"") | Z40: =IF(AC40<>"",IF(E40<>"",E40,($I$9-SUM($Z$25:Z39))*AB40*AC40/SUMPRODUCT($AC40:$AC$46,$AB40:$AB$46)),"") | AA40: =IF(AC40<>"",IF($I$12<>"",IF(G40<>"",G40,($I$9/$I$12-SUM($AA$25:AA39))*AB40*AC40/SUMPRODUCT($AC40:$AC$55,$AB40:$AB$55)),""),"")
F41: =IF(AND(E41<>"",E41<>0),D41/E41,"") | H41: =IF(AND(G41<>"",G41<>0),D41/G41,"") | J41: =IF(AND(G41<>"",G41<>0),E41/G41,"") | T41: =IF(AND(I41<>"",I41<>0),G41/I41,"") | U41: =D41/V41 -> #DIV/0! | V41: =$I$8*AB41*AC41/SUMPRODUCT($AC$25:$AC$46,$AB$25:$AB$46) -> #DIV/0! | W41: =$I$9*AB41*AC41/SUMPRODUCT($AC$25:$AC$46,$AB$25:$AB$46) -> #DIV/0! | X41: =IF($I$12="","",W41/$I$12) -> #DIV/0! | Y41: =IF(AC41<>"",IF(D41<>"",D41,($I$8-SUM($Y$25:Y40))*AB41*AC41/SUMPRODUCT($AC41:$AC$46,$AB41:$AB$46)),"") | Z41: =IF(AC41<>"",IF(E41<>"",E41,($I$9-SUM($Z$25:Z40))*AB41*AC41/SUMPRODUCT($AC41:$AC$46,$AB41:$AB$46)),"") | AA41: =IF(AC41<>"",IF($I$12<>"",IF(G41<>"",G41,($I$9/$I$12-SUM($AA$25:AA40))*AB41*AC41/SUMPRODUCT($AC41:$AC$55,$AB41:$AB$55)),""),"")
F42: =IF(AND(E42<>"",E42<>0),D42/E42,"") | H42: =IF(AND(G42<>"",G42<>0),D42/G42,"") | J42: =IF(AND(G42<>"",G42<>0),E42/G42,"") | T42: =IF(AND(I42<>"",I42<>0),G42/I42,"") | U42: =D42/V42 -> #DIV/0! | V42: =$I$8*AB42*AC42/SUMPRODUCT($AC$25:$AC$46,$AB$25:$AB$46) -> #DIV/0! | W42: =$I$9*AB42*AC42/SUMPRODUCT($AC$25:$AC$46,$AB$25:$AB$46) -> #DIV/0! | X42: =IF($I$12="","",W42/$I$12) -> #DIV/0! | Y42: =IF(AC42<>"",IF(D42<>"",D42,($I$8-SUM($Y$25:Y41))*AB42*AC42/SUMPRODUCT($AC42:$AC$46,$AB42:$AB$46)),"") | Z42: =IF(AC42<>"",IF(E42<>"",E42,($I$9-SUM($Z$25:Z41))*AB42*AC42/SUMPRODUCT($AC42:$AC$46,$AB42:$AB$46)),"") | AA42: =IF(AC42<>"",IF($I$12<>"",IF(G42<>"",G42,($I$9/$I$12-SUM($AA$25:AA41))*AB42*AC42/SUMPRODUCT($AC42:$AC$46,$AB42:$AB$46)),""),"")
...

Sheet Маркова
C1: =TODAY()-1 -> 46151
C2: (отчетная дата) | M2: ЕЖЕДНЕВНЫЙ ОТЧЕТ О ПРОДАЖАХ
C3: Осталось до выполнения плана!!! | M3: =График!B27 -> Маркова Диана
C4: =L8-D48 -> 366547.57 | E4: =IF(L8<>0,C4/L8,0) -> 0.65693347
I6: Целевые показатели
I7: Показатель | L7: План | M7: Факт | N7: % выполнения | O7: Прогноз выполнения | P7: % выполнения по прогнозу | Q7: Отклонение | R7: Факт аналогичного месяца прошлого года | S7: Отклонение LFL
I8: Выручка | L8: =Центрум!I8/График!AJ29*График!AJ27 -> 557967.57 | M8: =D48 -> 191420 | N8: =IF(AND(L8<>"",L8<>0,M8<>""),M8/L8,"") -> 0.34306653 | O8: =IF(SUMIF($D$25:$D$47,">=0",$V$25:$V$47)<>0,L8*D48/SUMIF($D$25:$D$47,">=0",$V$25:$V$47),0) -> 191420 | P8: =O8/L8 -> 0.34306653 | Q8: =IF(AND(M8<>0,M8<>"",L8<>0,L8<>""),O8-L8,"") -> -366547.57 | S8: =IF(AND(R8<>"",R8<>0,O8<>"",O8<>0),-R8+O8,"") | T8: =IF(AND(S8<>"",S8<>0,R8<>0,R8<>""),S8/R8,"")
I9: Кол-во изделий | L9: =L8/L11 -> 80.864865 | M9: =E48 -> 31 | N9: =IF(AND(L9<>"",L9<>0,M9<>""),M9/L9,"") -> 0.38335561 | O9: =IF(SUMIF($E$25:$E$47,">=0",$W$25:$W$47)<>0,L9*E48/SUMIF($E$25:$E$47,">=0",$W$25:$W$47),0) -> 31 | P9: =IF(AND(L9<>"",L9<>0,O9<>"",O9<>0),O9/L9,"") -> 0.38335561 | Q9: =IF(AND(M9<>0,M9<>"",L9<>0,L9<>""),O9-L9,"") -> -49.864865 | R9: =R8/R11 -> #DIV/0! | S9: =IF(AND(R9<>"",R9<>0,O9<>"",O9<>0),-R9+O9,"") -> #DIV/0! | T9: =IF(AND(S9<>"",S9<>0,R9<>0,R9<>""),S9/R9,"") -> #DIV/0!
I10: Средний чек | L10: =L11*L12 -> 11730 | M10: =H48 -> 8700.9091 | N10: =IF(AND(L10<>"",L10<>0,M10<>""),M10/L10,"") -> 0.74176548 | O10: =M10 -> 8700.9091 | P10: =IF(AND(L10<>"",L10<>0,O10<>"",O10<>0),O10/L10,"") -> 0.74176548 | Q10: =IF(AND(M10<>0,M10<>"",L10<>0,L10<>""),O10-L10,"") -> -3029.0909 | R10: =R11*R12 -> 0 | S10: =IF(AND(R10<>"",R10<>0,O10<>"",O10<>0),-R10+O10,"") | T10: =IF(AND(S10<>"",S10<>0,R10<>0,R10<>""),S10/R10,"")
I11: Средняя стоимость изделия | L11: =Центрум!I11 -> 6900 | M11: =F48 -> 6174.8387 | N11: =IF(AND(L11<>"",L11<>0,M11<>""),M11/L11,"") -> 0.89490416 | O11: =M11 -> 6174.8387 | P11: =IF(AND(L11<>"",L11<>0,O11<>"",O11<>0),O11/L11,"") -> 0.89490416 | Q11: =IF(AND(M11<>0,M11<>"",L11<>0,L11<>""),O11-L11,"") -> -725.16129 | S11: =IF(AND(R11<>"",R11<>0,O11<>"",O11<>0),-R11+O11,"") | T11: =IF(AND(S11<>"",S11<>0,R11<>0,R11<>""),S11/R11,"")
I12: Длина чека | L12: =Центрум!I12 -> 1.7 | M12: =J48 -> 1.4090909 | N12: =IF(AND(L12<>"",L12<>0,M12<>""),M12/L12,"") -> 0.82887701 | O12: =M12 -> 1.4090909 | P12: =IF(AND(L12<>"",L12<>0,O12<>"",O12<>0),O12/L12,"") -> 0.82887701 | Q12: =IF(AND(M12<>0,M12<>"",L12<>0,L12<>""),O12-L12,"") -> -0.29090909 | S12: =IF(AND(R12<>"",R12<>0,O12<>"",O12<>0),-R12+O12,"") | T12: =IF(AND(S12<>"",S12<>0,R12<>0,R12<>""),S12/R12,"")
I13: Кол-во чеков | L13: =IF(L12<>0,L9/L12,"") -> 47.567568 | M13: =G48 -> 22 | N13: =IF(AND(L13<>"",L13<>0,M13<>""),M13/L13,"") -> 0.4625 | O13: =IF(SUMIF($G$25:$G$47,">=0",$X$25:$X$47)<>0,L13*G48/SUMIF($G$25:$G$47,">=0",$X$25:$X$47),"") -> 22 | P13: =IF(AND(L13<>"",L13<>0,O13<>"",O13<>0),O13/L13,"") -> 0.4625 | Q13: =IF(AND(M13<>0,M13<>"",L13<>0,L13<>""),O13-L13,"") -> -25.567568 | S13: =IF(AND(R13<>"",R13<>0,O13<>"",O13<>0),-R13+O13,"") | T13: =IF(AND(S13<>"",S13<>0,R13<>0,R13<>""),S13/R13,"")
I14: Кол-во смен план/отработано | L14: =График!AI27 -> 11 | M14: 11 | N14: =IF(AND(L14<>"",L14<>0,M14<>""),M14/L14,"") -> 1 | O14: =IF(SUMIF($D$25:$D$47,">=0",$V$25:$V$47),I48*L8/SUMIF($D$25:$D$47,">=0",$V$25:$V$47),"") -> 201.6 | Q14: =IF(AND(M14<>0,M14<>"",L14<>0,L14<>""),O14-L14,"") -> 190.6 | S14: =IF(AND(R14<>"",R14<>0,O14<>"",O14<>0),-R14+O14,"") | T14: =IF(AND(S14<>"",S14<>0,R14<>0,R14<>""),S14/R14,"")
I15: Средние продажи в смену | L15: =Центрум!I15/2 -> 31280 | M15: =M8/M14 -> 17401.818 | N15: =IF(AND(L15<>"",L15<>0,M15<>""),M15/L15,"") -> 0.55632411 | O15: =M15 -> 17401.818 | P15: =IF(AND(L15<>"",L15<>0,O15<>"",O15<>0),O15/L15,"") -> 0.55632411 | Q15: =IF(AND(M15<>0,M15<>"",L15<>0,L15<>""),O15-L15,"") -> -13878.182 | S15: =IF(AND(R15<>"",R15<>0,O15<>"",O15<>0),-R15+O15,"") | T15: =IF(AND(S15<>"",S15<>0,R15<>0,R15<>""),S15/R15,"")
I16: Отставание/Перевыполнение | M16: =M8-L15*M14 -> -152660 | N16: =IF(AND(L16<>"",L16<>0,M16<>""),M16/L16,"") | O16: =M16 -> -152660 | P16: =IF(AND(L16<>"",L16<>0,O16<>"",O16<>0),O16/L16,"") | Q16: =IF(AND(M16<>0,M16<>"",L16<>0,L16<>""),O16-L16,"") | S16: =IF(AND(R16<>"",R16<>0,O16<>"",O16<>0),-R16+O16,"") | T16: =IF(AND(S16<>"",S16<>0,R16<>0,R16<>""),S16/R16,"") | V16: Подарочные сертификаты
I17: Трафик | L17: =Центрум!I17/График!AJ29*График!AJ27 -> 475.67568 | M17: =I48 -> 201.6 | N17: =IF(AND(L17<>"",L17<>0,M17<>""),M17/L17,"") -> 0.42381818 | O17: =M17/M14*L14 -> 201.6 | P17: =IF(AND(L17<>"",L17<>0,O17<>"",O17<>0),O17/L17,"") -> 0.42381818 | Q17: =IF(AND(M17<>0,M17<>"",L17<>0,L17<>""),O17-L17,"") -> -274.07568 | S17: =IF(AND(R17<>"",R17<>0,O17<>"",O17<>0),-R17+O17,"") | T17: =IF(AND(S17<>"",S17<>0,R17<>0,R17<>""),S17/R17,"")
I18: Выручка на вошедшего | L18: =L8/L17 -> 1173 | M18: =M8/M17 -> 949.50397 | N18: =IF(AND(L18<>"",L18<>0,M18<>""),M18/L18,"") -> 0.8094663 | O18: =M18 -> 949.50397 | P18: =IF(AND(L18<>"",L18<>0,O18<>"",O18<>0),O18/L18,"") -> 0.8094663 | Q18: =IF(AND(M18<>0,M18<>"",L18<>0,L18<>""),O18-L18,"") -> -223.49603 | R18: 0 | S18: =IF(AND(R18<>"",R18<>0,O18<>"",O18<>0),-R18+O18,"") | T18: =IF(AND(S18<>"",S18<>0,R18<>0,R18<>""),S18/R18,"")
N19: =IF(AND(L19<>"",L19<>0,M19<>""),M19/L19,"") | O19: =M19 -> 0 | P19: =IF(AND(L19<>"",L19<>0,O19<>"",O19<>0),O19/L19,"") | Q19: =IF(AND(M19<>0,M19<>"",L19<>0,L19<>""),O19-L19,"") | R19: 0 | S19: =IF(AND(R19<>"",R19<>0,O19<>"",O19<>0),-R19+O19,"") | T19: =IF(AND(S19<>"",S19<>0,R19<>0,R19<>""),S19/R19,"") | V19: =V18/L16 -> #DIV/0!
I20: Конверсия план/факт | L20: =Центрум!I20 -> 0.1 | M20: =T48 -> 0.10912698 | N20: =M20/L20 -> 1.0912698 | O20: =IF(AND(N8<>0,L14<>0,I48<>0),(I48*T48+(I48/N8-I48)*L20)/(I48/N8),0) -> 0.10313116 | P20: =IF(AND(L20<>"",L20<>0,O20<>"",O20<>0),O20/L20,"") -> 1.0313116 | Q20: =IF(AND(M20<>0,M20<>"",L20<>0,L20<>""),O20-L20,"") -> 0.0031311628 | S20: =IF(AND(R20<>"",R20<>0,O20<>"",O20<>0),-R20+O20,"") | T20: =IF(AND(S20<>"",S20<>0,R20<>0,R20<>""),S20/R20,"")
A22: Факт продаж за месяц | V22: Раcпределение плана по дням
B23: Дата | C23: День недели | D23: Выручка (руб) | E23: Кол-во единиц (шт.) | F23: Средняя стоимость изделия (руб.) | G23: Количество чеков (шт.) | H23: Средняя сумма чека (руб.) | I23: Трафик | J23: Длина чека (шт.) | K23: UNOde50 | L23: IS | M23: Agafi | N23: Kalliope | O23: Raganella | P23: CC/MP | Q23: Eva Rites | R23: Antura | S23: SALE | T23: Конверсия (%) | U23: % выполнения дневного плана | V23: выручка, план | W23: кол-во ед, план | X23: Кол-во чеков, план | Y23: выручка, скорректир.план | Z23: кол-во ед, скорр. план | AA23: кол-во чеков, скорр. план | AB23: Коэфф. Дня Недели | AC23: Специфика месяца
B24: 1 | C24: 2 | D24: 3 | E24: в | F24: 5 | G24: 6 | H24: 7 | I24: 8 | J24: 9 | K24: 10 | L24: 11 | M24: 12 | N24: 13 | O24: 14 | P24: 15 | Q24: 16 | R24: 17 | T24: 18 | V24: 1 | W24: 2 | X24: 3 | Y24: 4 | Z24: 5 | AA24: 6 | AB24: 10 | AC24: 11
A25: 1 | B25: 46113 | C25: ср | D25: 27636 | E25: 6 | F25: =IF(AND(E25<>"",E25<>0),D25/E25,"") -> 4606 | G25: 4 | H25: =IF(AND(G25<>"",G25<>0),D25/G25,"") -> 6909 | I25: 35 | J25: =IF(AND(G25<>"",G25<>0),E25/G25,"") -> 1.5 | T25: =IF(AND(I25<>"",I25<>0),G25/I25,"") -> 0.11428571 | U25: =D25/V25 -> 0.49529761 | V25: =$L$8*AB25*AC25/SUMPRODUCT($AC$25:$AC$55,$AB$25:$AB$55) -> 55796.757 | W25: =$L$9*AB25*AC25/SUMPRODUCT($AC$25:$AC$55,$AB$25:$AB$55) -> 8.0864865 | X25: =IF($L$12="","",W25/$L$12) -> 4.7567568 | Y25: =IF(AC25<>"",IF(D25<>"",D25,($L$8-SUM($Y24:Y$25))*AB25*AC25/SUMPRODUCT($AC25:$AC$55,$AB25:$AB$55)),"") -> 27636 | Z25: =IF(AC25<>"",IF(E25<>"",E25,($L$9-SUM($Z24:Z$25))*AB25*AC25/SUMPRODUCT($AC25:$AC$55,$AB25:$AB$55)),"") -> 6 | AA25: =IF(AC25<>"",IF($L$12<>"",IF(G25<>"",G25,($L$9/$L$12-SUM($AA24:AA$25))*AB25*AC25/SUMPRODUCT($AC25:$AC$55,$AB25:$AB$55)),""),"") -> 4 | AB25: 1 | AC25: 1
A26: 2 | B26: 46116 | C26: сб | D26: 30939 | E26: 5 | F26: =IF(AND(E26<>"",E26<>0),D26/E26,"") -> 6187.8 | G26: 4 | H26: =IF(AND(G26<>"",G26<>0),D26/G26,"") -> 7734.75 | I26: 30 | J26: =IF(AND(G26<>"",G26<>0),E26/G26,"") -> 1.25 | S26: 4263 | T26: =IF(AND(I26<>"",I26<>0),G26/I26,"") -> 0.13333333 | U26: =D26/V26 -> 0.55449459 | V26: =$L$8*AB26*AC26/SUMPRODUCT($AC$25:$AC$55,$AB$25:$AB$55) -> 55796.757 | W26: =$L$9*AB26*AC26/SUMPRODUCT($AC$25:$AC$55,$AB$25:$AB$55) -> 8.0864865 | X26: =IF($L$12="","",W26/$L$12) -> 4.7567568 | Y26: =IF(AC26<>"",IF(D26<>"",D26,($L$8-SUM($Y$25:Y25))*AB26*AC26/SUMPRODUCT($AC26:$AC$55,$AB26:$AB$55)),"") -> 30939 | Z26: =IF(AC26<>"",IF(E26<>"",E26,($L$9-SUM($Z$25:Z25))*AB26*AC26/SUMPRODUCT($AC26:$AC$55,$AB26:$AB$55)),"") -> 5 | AA26: =IF(AC26<>"",IF($L$12<>"",IF(G26<>"",G26,($L$9/$L$12-SUM($AA$25:AA25))*AB26*AC26/SUMPRODUCT($AC26:$AC$55,$AB26:$AB$55)),""),"") -> 4 | AB26: 1 | AC26: 1
A27: 3 | B27: 46117 | C27: вс | D27: 18674 | E27: 3 | F27: =IF(AND(E27<>"",E27<>0),D27/E27,"") -> 6224.6667 | G27: 3 | H27: =IF(AND(G27<>"",G27<>0),D27/G27,"") -> 6224.6667 | I27: 22 | J27: =IF(AND(G27<>"",G27<>0),E27/G27,"") -> 1 | T27: =IF(AND(I27<>"",I27<>0),G27/I27,"") -> 0.13636364 | U27: =D27/V27 -> 0.33467895 | V27: =$L$8*AB27*AC27/SUMPRODUCT($AC$25:$AC$55,$AB$25:$AB$55) -> 55796.757 | W27: =$L$9*AB27*AC27/SUMPRODUCT($AC$25:$AC$55,$AB$25:$AB$55) -> 8.0864865 | X27: =IF($L$12="","",W27/$L$12) -> 4.7567568 | Y27: =IF(AC27<>"",IF(D27<>"",D27,($L$8-SUM($Y$25:Y26))*AB27*AC27/SUMPRODUCT($AC27:$AC$55,$AB27:$AB$55)),"") -> 18674 | Z27: =IF(AC27<>"",IF(E27<>"",E27,($L$9-SUM($Z$25:Z26))*AB27*AC27/SUMPRODUCT($AC27:$AC$55,$AB27:$AB$55)),"") -> 3 | AA27: =IF(AC27<>"",IF($L$12<>"",IF(G27<>"",G27,($L$9/$L$12-SUM($AA$25:AA26))*AB27*AC27/SUMPRODUCT($AC27:$AC$55,$AB27:$AB$55)),""),"") -> 3 | AB27: 1 | AC27: 1
A28: 4 | B28: 46118 | C28: пн | D28: 8055 | E28: 2 | F28: =IF(AND(E28<>"",E28<>0),D28/E28,"") -> 4027.5 | G28: 1 | H28: =IF(AND(G28<>"",G28<>0),D28/G28,"") -> 8055 | I28: 8 | J28: =IF(AND(G28<>"",G28<>0),E28/G28,"") -> 2 | S28: 8051.17 | T28: =IF(AND(I28<>"",I28<>0),G28/I28,"") -> 0.125 | U28: =D28/V28 -> 0.14436323 | V28: =$L$8*AB28*AC28/SUMPRODUCT($AC$25:$AC$55,$AB$25:$AB$55) -> 55796.757 | W28: =$L$9*AB28*AC28/SUMPRODUCT($AC$25:$AC$55,$AB$25:$AB$55) -> 8.0864865 | X28: =IF($L$12="","",W28/$L$12) -> 4.7567568 | Y28: =IF(AC28<>"",IF(D28<>"",D28,($L$8-SUM($Y$25:Y27))*AB28*AC28/SUMPRODUCT($AC28:$AC$55,$AB28:$AB$55)),"") -> 8055 | Z28: =IF(AC28<>"",IF(E28<>"",E28,($L$9-SUM($Z$25:Z27))*AB28*AC28/SUMPRODUCT($AC28:$AC$55,$AB28:$AB$55)),"") -> 2 | AA28: =IF(AC28<>"",IF($L$12<>"",IF(G28<>"",G28,($L$9/$L$12-SUM($AA$25:AA27))*AB28*AC28/SUMPRODUCT($AC28:$AC$55,$AB28:$AB$55)),""),"") -> 1 | AB28: 1 | AC28: 1
