Workbook
Name маг: NA()

Sheet Центрум
B1: =TODAY()-1 -> 46170
B2: (отчетная дата) | J2: ЕЖЕДНЕВНЫЙ ОТЧЕТ О ПРОДАЖАХ
C3: Осталось до выполнения плана!!! | I3: ТРК Центрум
C4: =I8-D56 -> 496100.02 | E4: =IF(I8<>0,C4/I8,0) -> 0.25857128
F6: Целевые показатели
F7: Показатель | I7: План | J7: Факт | K7: % выполнения | L7: Прогноз выполнения | M7: % выполнения по прогнозу | N7: Отклонение | O7: Факт аналогичного месяца прошлого года | P7: Отклонение LFL
F8: Выручка | I8: =I13*I10 -> 1918620 | J8: =D56 -> 1422520 | K8: =IF(AND(I8<>"",I8<>0,J8<>""),J8/I8,"") -> 0.74142872 | L8: =IF(SUMIF($D$25:$D$55,">=0",$U$25:$U$55)<>0,I8*D56/SUMIF($D$25:$D$55,">=0",$U$25:$U$55),0) -> 1422520 | M8: =L8/I8 -> 0.74142872 | N8: =IF(AND(J8<>0,J8<>"",I8<>0,I8<>""),L8-I8,"") -> -496100.02 | P8: =IF(AND(O8<>"",O8<>0,L8<>"",L8<>0),-O8+L8,"") | Q8: =IF(AND(O8<>"",O8<>0,N8<>0,N8<>""),O8/N8,"")
F9: Кол-во изделий | I9: =I8/I11 -> 290.7 | J9: =E56 -> 202 | K9: =IF(AND(I9<>"",I9<>0,J9<>""),J9/I9,"") -> 0.69487444 | L9: =IF(SUMIF($E$25:$E$55,">=0",$V$25:$V$55)<>0,I9*E56/SUMIF($E$25:$E$55,">=0",$V$25:$V$55),0) -> 202 | M9: =IF(AND(I9<>"",I9<>0,L9<>"",L9<>0),L9/I9,"") -> 0.69487444 | N9: =IF(AND(J9<>0,J9<>"",I9<>0,I9<>""),L9-I9,"") -> -88.7 | P9: =IF(AND(O9<>"",O9<>0,L9<>"",L9<>0),-O9+L9,"") | Q9: =IF(AND(O9<>"",O9<>0,N9<>0,N9<>""),O9/N9,"")
F10: Средний чек | I10: =I11*I12 -> 11220 | J10: =H56 -> 12932 | K10: =IF(AND(I10<>"",I10<>0,J10<>""),J10/I10,"") -> 1.1525847 | L10: =J10 -> 12932 | M10: =IF(AND(I10<>"",I10<>0,L10<>"",L10<>0),L10/I10,"") -> 1.1525847 | N10: =IF(AND(J10<>0,J10<>"",I10<>0,I10<>""),L10-I10,"") -> 1711.9998 | P10: =IF(AND(O10<>"",O10<>0,L10<>"",L10<>0),-O10+L10,"") | Q10: =IF(AND(O10<>"",O10<>0,N10<>0,N10<>""),O10/N10,"")
F11: Средняя стоимость изделия | I11: 6600 | J11: =F56 -> 7042.1781 | K11: =IF(AND(I11<>"",I11<>0,J11<>""),J11/I11,"") -> 1.0669967 | L11: =IF(L9>0,L8/L9,"") -> 7042.1781 | M11: =IF(AND(I11<>"",I11<>0,L11<>"",L11<>0),L11/I11,"") -> 1.0669967 | N11: =IF(AND(J11<>0,J11<>"",I11<>0,I11<>""),L11-I11,"") -> 442.17812 | P11: =IF(AND(O11<>"",O11<>0,L11<>"",L11<>0),-O11+L11,"") | Q11: =IF(AND(O11<>"",O11<>0,N11<>0,N11<>""),O11/N11,"")
F12: Длина чека | I12: 1.7 | J12: =J56 -> 1.8363636 | K12: =IF(AND(I12<>"",I12<>0,J12<>""),J12/I12,"") -> 1.0802139 | L12: =J12 -> 1.8363636 | M12: =IF(AND(I12<>"",I12<>0,L12<>"",L12<>0),L12/I12,"") -> 1.0802139 | N12: =IF(AND(J12<>0,J12<>"",I12<>0,I12<>""),L12-I12,"") -> 0.13636364 | P12: =IF(AND(O12<>"",O12<>0,L12<>"",L12<>0),-O12+L12,"") | Q12: =IF(AND(O12<>"",O12<>0,N12<>0,N12<>""),O12/N12,"")
F13: Кол-во чеков | I13: =I17*I20 -> 171 | J13: =G56 -> 110 | K13: =IF(AND(I13<>"",I13<>0,J13<>""),J13/I13,"") -> 0.64327485 | L13: =IF(SUMIF($G$25:$G$55,">=0",$W$25:$W$55)<>0,I13*G56/SUMIF($G$25:$G$55,">=0",$W$25:$W$55),"") -> 110 | M13: =IF(AND(I13<>"",I13<>0,L13<>"",L13<>0),L13/I13,"") -> 0.64327485 | N13: =IF(AND(J13<>0,J13<>"",I13<>0,I13<>""),L13-I13,"") -> -61 | P13: =IF(AND(O13<>"",O13<>0,L13<>"",L13<>0),-O13+L13,"") | Q13: =IF(AND(O13<>"",O13<>0,N13<>0,N13<>""),O13/N13,"")
F14: Кол-во смен | I14: 31 | J14: 31 | K14: =IF(AND(I14<>"",I14<>0,J14<>""),J14/I14,"") -> 1 | L14: =IF(SUMIF($D$25:$D$55,">=0",$U$25:$U$55),I56*I8/SUMIF($D$25:$D$55,">=0",$U$25:$U$55),"") -> 1421.6 | N14: =IF(AND(J14<>0,J14<>"",I14<>0,I14<>""),L14-I14,"") -> 1390.6 | P14: =IF(AND(O14<>"",O14<>0,L14<>"",L14<>0),-O14+L14,"") | Q14: =IF(AND(O14<>"",O14<>0,N14<>0,N14<>""),O14/N14,"")
F15: Средние продажи в смену | I15: =I8/I14 -> 61890.968 | J15: =J8/J14 -> 45887.741 | K15: =IF(AND(I15<>"",I15<>0,J15<>""),J15/I15,"") -> 0.74142872 | L15: =J15 -> 45887.741 | M15: =IF(AND(I15<>"",I15<>0,L15<>"",L15<>0),L15/I15,"") -> 0.74142872 | N15: =IF(AND(J15<>0,J15<>"",I15<>0,I15<>""),L15-I15,"") -> -16003.226 | P15: =IF(AND(O15<>"",O15<>0,L15<>"",L15<>0),-O15+L15,"") | Q15: =IF(AND(O15<>"",O15<>0,N15<>0,N15<>""),O15/N15,"")
F16: Отставание/Перевыполнение | J16: =J8-I15*J14 -> -496100.02 | K16: =IF(AND(I16<>"",I16<>0,J16<>""),J16/I16,"") | L16: =J16 -> -496100.02 | M16: =IF(AND(I16<>"",I16<>0,L16<>"",L16<>0),L16/I16,"") | N16: =IF(AND(J16<>0,J16<>"",I16<>0,I16<>""),L16-I16,"") | P16: =IF(AND(O16<>"",O16<>0,L16<>"",L16<>0),-O16+L16,"") | Q16: =IF(AND(O16<>"",O16<>0,N16<>0,N16<>""),O16/N16,"") | W16: Подарочные сертификаты
F17: Трафик | I17: 1900 | J17: =I56 -> 1421.6 | K17: =IF(AND(I17<>"",I17<>0,J17<>""),J17/I17,"") -> 0.74821053 | L17: =J17/J14*I14 -> 1421.6 | M17: =IF(AND(I17<>"",I17<>0,L17<>"",L17<>0),L17/I17,"") -> 0.74821053 | N17: =IF(AND(J17<>0,J17<>"",I17<>0,I17<>""),L17-I17,"") -> -478.4 | P17: =IF(AND(O17<>"",O17<>0,L17<>"",L17<>0),-O17+L17,"") | Q17: =IF(AND(O17<>"",O17<>0,N17<>0,N17<>""),O17/N17,"")
K18: =IF(AND(I18<>"",I18<>0,J18<>""),J18/I18,"") | L18: =J18 -> 0 | M18: =IF(AND(I18<>"",I18<>0,L18<>"",L18<>0),L18/I18,"") | N18: =IF(AND(J18<>0,J18<>"",I18<>0,I18<>""),L18-I18,"") | P18: =IF(AND(O18<>"",O18<>0,L18<>"",L18<>0),-O18+L18,"") | Q18: =IF(AND(O18<>"",O18<>0,N18<>0,N18<>""),O18/N18,"")
K19: =IF(AND(I19<>"",I19<>0,J19<>""),J19/I19,"") | L19: =J19 -> 0 | M19: =IF(AND(I19<>"",I19<>0,L19<>"",L19<>0),L19/I19,"") | N19: =IF(AND(J19<>0,J19<>"",I19<>0,I19<>""),L19-I19,"") | O19: 0 | P19: =IF(AND(O19<>"",O19<>0,L19<>"",L19<>0),-O19+L19,"") | Q19: =IF(AND(O19<>"",O19<>0,N19<>0,N19<>""),O19/N19,"") | W19: =W18/I16 -> #DIV/0!
F20: Конверсия | I20: 0.09 | J20: =S56 -> 0.077377603 | K20: =J20/I20 -> 0.85975114 | L20: =J20/I20 -> 0.85975114 | M20: =J20/I20 -> 0.85975114 | N20: =IF(AND(J20<>0,J20<>"",I20<>0,I20<>""),L20-I20,"") -> 0.76975114 | P20: =IF(AND(O20<>"",O20<>0,L20<>"",L20<>0),-O20+L20,"") | Q20: =IF(AND(O20<>"",O20<>0,N20<>0,N20<>""),O20/N20,"")
A22: Факт продаж за месяц | U22: Раcпределение плана по дням
A23: Сотрудник | B23: Дата | C23: День недели | D23: Выручка (руб) | E23: Кол-во единиц (шт.) | F23: Средняя стоимость изделия (руб.) | G23: Количество чеков (шт.) | H23: Средняя сумма чека (руб.) | I23: Трафик | J23: Длина чека (шт.) | K23: UNOde50 | L23: IS | M23: Agafi | N23: Kalliope | O23: Raganella | P23: CC/MP | Q23: Eva Rites | R23: Antura | S23: Конверсия (%) | T23: % выполнения дневного плана | U23: выручка, план | V23: кол-во ед, план | W23: Кол-во чеков, план | X23: выручка, скорректир.план | Y23: кол-во ед, скорр. план | Z23: кол-во чеков, скорр. план | AA23: Коэфф. Дня Недели | AB23: Специфика месяца
B24: 1 | C24: 2 | D24: 3 | E24: 4 | F24: 5 | G24: 6 | H24: 7 | I24: 8 | J24: 9 | K24: 10 | L24: 11 | M24: 12 | N24: 13 | O24: 14 | P24: 15 | Q24: 16 | R24: 17 | S24: 13 | U24: 1 | V24: 2 | W24: 3 | X24: 4 | Y24: 5 | Z24: 6 | AA24: 10 | AB24: 11
B25: 46023 | C25: чт | D25: 0 | E25: 0 | F25: =IF(AND(E25<>"",E25<>0),D25/E25,"") | G25: 0 | H25: =IF(AND(G25<>"",G25<>0),D25/G25,"") | I25: 0 | J25: =IF(AND(G25<>"",G25<>0),E25/G25,"") | S25: =IF(AND(I25<>"",I25<>0),G25/I25,"") | T25: =D25/U25 -> 0 | U25: =$I$8*AA25*AB25/SUMPRODUCT($AB$25:$AB$55,$AA$25:$AA$55) -> 64505.635 | V25: =$I$9*AA25*AB25/SUMPRODUCT($AB$25:$AB$55,$AA$25:$AA$55) -> 9.7735811 | W25: =IF($I$12="","",V25/$I$12) -> 5.7491654 | X25: =IF(D25<>"",D25,U25) -> 0 | Y25: =IF(E25<>"",E25,V25) -> 0 | Z25: =IF(G25<>"",G25,W25) -> 0 | AA25: 0.9414554 | AB25: 0.9414554
A26: Свидовская, Корж, Козлова | B26: 46024 | C26: пт | D26: 52276 | E26: 7 | F26: =IF(AND(E26<>"",E26<>0),D26/E26,"") -> 7468 | G26: 3 | H26: =IF(AND(G26<>"",G26<>0),D26/G26,"") -> 17425.333 | I26: 77 | J26: =IF(AND(G26<>"",G26<>0),E26/G26,"") -> 2.3333333 | Q26: 15180 | S26: =IF(AND(I26<>"",I26<>0),G26/I26,"") -> 0.038961039 | T26: =D26/U26 -> 0.98696541 | U26: =$I$8*AA26*AB26/SUMPRODUCT($AB$25:$AB$55,$AA$25:$AA$55) -> 52966.395 | V26: =$I$9*AA26*AB26/SUMPRODUCT($AB$25:$AB$55,$AA$25:$AA$55) -> 8.0252114 | W26: =IF($I$12="","",V26/$I$12) -> 4.7207126 | X26: =IF(AB26<>"",IF(D26<>"",D26,($I$8-SUM($X$25:X25))*AA26*AB26/SUMPRODUCT($AB26:$AB$55,$AA26:$AA$55)),"") -> 52276 | Y26: =IF(AB26<>"",IF(E26<>"",E26,($I$9-SUM($Y$25:Y25))*AA26*AB26/SUMPRODUCT($AB26:$AB$55,$AA26:$AA$55)),"") -> 7 | Z26: =IF(AB26<>"",IF($I$12<>"",IF(G26<>"",G26,($I$9/$I$12-SUM($Z$25:Z25))*AA26*AB26/SUMPRODUCT($AB26:$AB$55,$AA26:$AA$55)),""),"") -> 3 | AA26: 0.85310234 | AB26: 0.85310234
A27: Свидовская, Корж, Козлова | B27: 46025 | C27: сб | D27: 21059 | E27: 4 | F27: =IF(AND(E27<>"",E27<>0),D27/E27,"") -> 5264.75 | G27: 3 | H27: =IF(AND(G27<>"",G27<>0),D27/G27,"") -> 7019.6667 | I27: 76 | J27: =IF(AND(G27<>"",G27<>0),E27/G27,"") -> 1.3333333 | Q27: 8693 | S27: =IF(AND(I27<>"",I27<>0),G27/I27,"") -> 0.039473684 | T27: =D27/U27 -> 0.39759172 | U27: =$I$8*AA27*AB27/SUMPRODUCT($AB$25:$AB$55,$AA$25:$AA$55) -> 52966.395 | V27: =$I$9*AA27*AB27/SUMPRODUCT($AB$25:$AB$55,$AA$25:$AA$55) -> 8.0252114 | W27: =IF($I$12="","",V27/$I$12) -> 4.7207126 | X27: =IF(AB27<>"",IF(D27<>"",D27,($I$8-SUM($X$25:X26))*AA27*AB27/SUMPRODUCT($AB27:$AB$55,$AA27:$AA$55)),"") -> 21059 | Y27: =IF(AB27<>"",IF(E27<>"",E27,($I$9-SUM($Y$25:Y26))*AA27*AB27/SUMPRODUCT($AB27:$AB$55,$AA27:$AA$55)),"") -> 4 | Z27: =IF(AB27<>"",IF($I$12<>"",IF(G27<>"",G27,($I$9/$I$12-SUM($Z$25:Z26))*AA27*AB27/SUMPRODUCT($AB27:$AB$55,$AA27:$AA$55)),""),"") -> 3 | AA27: 0.85310234 | AB27: 0.85310234
A28: Свидовская, Корж, Козлова | B28: 46026 | C28: вс | D28: 73715 | E28: 10 | F28: =IF(AND(E28<>"",E28<>0),D28/E28,"") -> 7371.5 | G28: 2 | H28: =IF(AND(G28<>"",G28<>0),D28/G28,"") -> 36857.5 | I28: 90 | J28: =IF(AND(G28<>"",G28<>0),E28/G28,"") -> 5 | S28: =IF(AND(I28<>"",I28<>0),G28/I28,"") -> 0.022222222 | T28: =D28/U28 -> 1.3917315 | U28: =$I$8*AA28*AB28/SUMPRODUCT($AB$25:$AB$55,$AA$25:$AA$55) -> 52966.395 | V28: =$I$9*AA28*AB28/SUMPRODUCT($AB$25:$AB$55,$AA$25:$AA$55) -> 8.0252114 | W28: =IF($I$12="","",V28/$I$12) -> 4.7207126 | X28: =IF(AB28<>"",IF(D28<>"",D28,($I$8-SUM($X$25:X27))*AA28*AB28/SUMPRODUCT($AB28:$AB$55,$AA28:$AA$55)),"") -> 73715 | Y28: =IF(AB28<>"",IF(E28<>"",E28,($I$9-SUM($Y$25:Y27))*AA28*AB28/SUMPRODUCT($AB28:$AB$55,$AA28:$AA$55)),"") -> 10 | Z28: =IF(AB28<>"",IF($I$12<>"",IF(G28<>"",G28,($I$9/$I$12-SUM($Z$25:Z27))*AA28*AB28/SUMPRODUCT($AB28:$AB$55,$AA28:$AA$55)),""),"") -> 2 | AA28: 0.85310234 | AB28: 0.85310234
A29: Козлова, Корж | B29: 46027 | C29: пн | D29: 28155 | E29: 4 | F29: =IF(AND(E29<>"",E29<>0),D29/E29,"") -> 7038.75 | G29: 4 | H29: =IF(AND(G29<>"",G29<>0),D29/G29,"") -> 7038.75 | I29: 100 | J29: =IF(AND(G29<>"",G29<>0),E29/G29,"") -> 1 | M29: 7093 | S29: =IF(AND(I29<>"",I29<>0),G29/I29,"") -> 0.04 | T29: =D29/U29 -> 0.53545075 | U29: =$I$8*AA29*AB29/SUMPRODUCT($AB$25:$AB$55,$AA$25:$AA$55) -> 52581.867 | V29: =$I$9*AA29*AB29/SUMPRODUCT($AB$25:$AB$55,$AA$25:$AA$55) -> 7.9669496 | W29: =IF($I$12="","",V29/$I$12) -> 4.6864409 | X29: =IF(AB29<>"",IF(D29<>"",D29,($I$8-SUM($X$25:X28))*AA29*AB29/SUMPRODUCT($AB29:$AB$55,$AA29:$AA$55)),"") -> 28155 | Y29: =IF(AB29<>"",IF(E29<>"",E29,($I$9-SUM($Y$25:Y28))*AA29*AB29/SUMPRODUCT($AB29:$AB$55,$AA29:$AA$55)),"") -> 4 | Z29: =IF(AB29<>"",IF($I$12<>"",IF(G29<>"",G29,($I$9/$I$12-SUM($Z$25:Z28))*AA29*AB29/SUMPRODUCT($AB29:$AB$55,$AA29:$AA$55)),""),"") -> 4 | AA29: 0.85 | AB29: 0.85
A30: Козлова, Стекольщикова | B30: 46028 | C30: вт | D30: 113842.98 | E30: ='Козлова В. Э.'!E29+'Стекольщикова А. А.'!E25 -> 19 | F30: =IF(AND(E30<>"",E30<>0),D30/E30,"") -> 5991.7358 | G30: 7 | H30: =IF(AND(G30<>"",G30<>0),D30/G30,"") -> 16263.283 | I30: 73 | J30: =IF(AND(G30<>"",G30<>0),E30/G30,"") -> 2.7142857 | M30: 14590 | Q30: 9390 | S30: =IF(AND(I30<>"",I30<>0),G30/I30,"") -> 0.095890411 | T30: =D30/U30 -> 1.564257 | U30: =$I$8*AA30*AB30/SUMPRODUCT($AB$25:$AB$55,$AA$25:$AA$55) -> 72777.671 | V30: =$I$9*AA30*AB30/SUMPRODUCT($AB$25:$AB$55,$AA$25:$AA$55) -> 11.02692 | W30: =IF($I$12="","",V30/$I$12) -> 6.4864234 | X30: =IF(AB30<>"",IF(D30<>"",D30,($I$8-SUM($X$25:X29))*AA30*AB30/SUMPRODUCT($AB30:$AB$55,$AA30:$AA$55)),"") -> 113842.98 | Y30: =IF(AB30<>"",IF(E30<>"",E30,($I$9-SUM($Y$25:Y29))*AA30*AB30/SUMPRODUCT($AB30:$AB$55,$AA30:$AA$55)),"") -> 19 | Z30: =IF(AB30<>"",IF($I$12<>"",IF(G30<>"",G30,($I$9/$I$12-SUM($Z$25:Z29))*AA30*AB30/SUMPRODUCT($AB30:$AB$55,$AA30:$AA$55)),""),"") -> 7 | AA30: 1 | AB30: 1
A31: Стекольщикова, Корж, Свидовская | B31: 46029 | C31: ср | D31: 12278 | E31: 3 | F31: =IF(AND(E31<>"",E31<>0),D31/E31,"") -> 4092.6667 | G31: 3 | H31: =IF(AND(G31<>"",G31<>0),D31/G31,"") -> 4092.6667 | I31: 51 | J31: =IF(AND(G31<>"",G31<>0),E31/G31,"") -> 1 | S31: =IF(AND(I31<>"",I31<>0),G31/I31,"") -> 0.058823529 | T31: =D31/U31 -> 0.16870559 | U31: =$I$8*AA31*AB31/SUMPRODUCT($AB$25:$AB$55,$AA$25:$AA$55) -> 72777.671 | V31: =$I$9*AA31*AB31/SUMPRODUCT($AB$25:$AB$55,$AA$25:$AA$55) -> 11.02692 | W31: =IF($I$12="","",V31/$I$12) -> 6.4864234 | X31: =IF(AB31<>"",IF(D31<>"",D31,($I$8-SUM($X$25:X30))*AA31*AB31/SUMPRODUCT($AB31:$AB$55,$AA31:$AA$55)),"") -> 12278 | Y31: =IF(AB31<>"",IF(E31<>"",E31,($I$9-SUM($Y$25:Y30))*AA31*AB31/SUMPRODUCT($AB31:$AB$55,$AA31:$AA$55)),"") -> 3 | Z31: =IF(AB31<>"",IF($I$12<>"",IF(G31<>"",G31,($I$9/$I$12-SUM($Z$25:Z30))*AA31*AB31/SUMPRODUCT($AB31:$AB$55,$AA31:$AA$55)),""),"") -> 3 | AA31: 1 | AB31: 1
A32: Стекольщикова, Корж, Свидовская | B32: 46030 | C32: чт | D32: 16971 | E32: 4 | F32: =IF(AND(E32<>"",E32<>0),D32/E32,"") -> 4242.75 | G32: 3 | H32: =IF(AND(G32<>"",G32<>0),D32/G32,"") -> 5657 | I32: 65 | J32: =IF(AND(G32<>"",G32<>0),E32/G32,"") -> 1.3333333 | S32: =IF(AND(I32<>"",I32<>0),G32/I32,"") -> 0.046153846 | T32: =D32/U32 -> 0.3204107 | U32: =$I$8*AA32*AB32/SUMPRODUCT($AB$25:$AB$55,$AA$25:$AA$55) -> 52966.395 | V32: =$I$9*AA32*AB32/SUMPRODUCT($AB$25:$AB$55,$AA$25:$AA$55) -> 8.0252114 | W32: =IF($I$12="","",V32/$I$12) -> 4.7207126 | X32: =IF(AB32<>"",IF(D32<>"",D32,($I$8-SUM($X$25:X31))*AA32*AB32/SUMPRODUCT($AB32:$AB$55,$AA32:$AA$55)),"") -> 16971 | Y32: =IF(AB32<>"",IF(E32<>"",E32,($I$9-SUM($Y$25:Y31))*AA32*AB32/SUMPRODUCT($AB32:$AB$55,$AA32:$AA$55)),"") -> 4 | Z32: =IF(AB32<>"",IF($I$12<>"",IF(G32<>"",G32,($I$9/$I$12-SUM($Z$25:Z31))*AA32*AB32/SUMPRODUCT($AB32:$AB$55,$AA32:$AA$55)),""),"") -> 3 | AA32: 0.85310234 | AB32: 0.85310234
A33: Стекольщикова, Свидовская, Козлова | B33: 46031 | C33: пт | D33: 46753 | E33: 8 | F33: =IF(AND(E33<>"",E33<>0),D33/E33,"") -> 5844.125 | G33: 6 | H33: =IF(AND(G33<>"",G33<>0),D33/G33,"") -> 7792.1667 | I33: 77 | J33: =IF(AND(G33<>"",G33<>0),E33/G33,"") -> 1.3333333 | S33: =IF(AND(I33<>"",I33<>0),G33/I33,"") -> 0.077922078 | T33: =D33/U33 -> 0.88269175 | U33: =$I$8*AA33*AB33/SUMPRODUCT($AB$25:$AB$55,$AA$25:$AA$55) -> 52966.395 | V33: =$I$9*AA33*AB33/SUMPRODUCT($AB$25:$AB$55,$AA$25:$AA$55) -> 8.0252114 | W33: =IF($I$12="","",V33/$I$12) -> 4.7207126 | X33: =IF(AB33<>"",IF(D33<>"",D33,($I$8-SUM($X$25:X32))*AA33*AB33/SUMPRODUCT($AB33:$AB$55,$AA33:$AA$55)),"") -> 46753 | Y33: =IF(AB33<>"",IF(E33<>"",E33,($I$9-SUM($Y$25:Y32))*AA33*AB33/SUMPRODUCT($AB33:$AB$55,$AA33:$AA$55)),"") -> 8 | Z33: =IF(AB33<>"",IF($I$12<>"",IF(G33<>"",G33,($I$9/$I$12-SUM($Z$25:Z32))*AA33*AB33/SUMPRODUCT($AB33:$AB$55,$AA33:$AA$55)),""),"") -> 6 | AA33: 0.85310234 | AB33: 0.85310234
A34: Стекольщикова, Козлова | B34: 46032 | C34: сб | D34: =32079+7503 -> 39582 | E34: 6 | F34: =IF(AND(E34<>"",E34<>0),D34/E34,"") -> 6597 | G34: 5 | H34: =IF(AND(G34<>"",G34<>0),D34/G34,"") -> 7916.4 | I34: 64 | J34: =IF(AND(G34<>"",G34<>0),E34/G34,"") -> 1.2 | L34: 7503 | M34: 8393 | S34: =IF(AND(I34<>"",I34<>0),G34/I34,"") -> 0.078125 | T34: =D34/U34 -> 1.3945528 | U34: =$I$8*AA34*AB34/SUMPRODUCT($AB$25:$AB$55,$AA$25:$AA$55) -> 28383.292 | V34: =$I$9*AA34*AB34/SUMPRODUCT($AB$25:$AB$55,$AA$25:$AA$55) -> 4.3004987 | W34: =IF($I$12="","",V34/$I$12) -> 2.5297051 | X34: =IF(AB34<>"",IF(D34<>"",D34,($I$8-SUM($X$25:X33))*AA34*AB34/SUMPRODUCT($AB34:$AB$55,$AA34:$AA$55)),"") -> 39582 | Y34: =IF(AB34<>"",IF(E34<>"",E34,($I$9-SUM($Y$25:Y33))*AA34*AB34/SUMPRODUCT($AB34:$AB$55,$AA34:$AA$55)),"") -> 6 | Z34: =IF(AB34<>"",IF($I$12<>"",IF(G34<>"",G34,($I$9/$I$12-SUM($Z$25:Z33))*AA34*AB34/SUMPRODUCT($AB34:$AB$55,$AA34:$AA$55)),""),"") -> 5 | AA34: 0.65 | AB34: 0.6
A35: Козлова, Корж, Свидовская | B35: 46033 | C35: вс | D35: =11984+220 -> 12204 | E35: 2 | F35: =IF(AND(E35<>"",E35<>0),D35/E35,"") -> 6102 | G35: 2 | H35: =IF(AND(G35<>"",G35<>0),D35/G35,"") -> 6102 | I35: 44 | J35: =IF(AND(G35<>"",G35<>0),E35/G35,"") -> 1 | L35: 220 | S35: =IF(AND(I35<>"",I35<>0),G35/I35,"") -> 0.045454545 | T35: =D35/U35 -> 0.31940723 | U35: =$I$8*AA35*AB35/SUMPRODUCT($AB$25:$AB$55,$AA$25:$AA$55) -> 38208.277 | V35: =$I$9*AA35*AB35/SUMPRODUCT($AB$25:$AB$55,$AA$25:$AA$55) -> 5.7891329 | W35: =IF($I$12="","",V35/$I$12) -> 3.4053723 | X35: =IF(AB35<>"",IF(D35<>"",D35,($I$8-SUM($X$25:X34))*AA35*AB35/SUMPRODUCT($AB35:$AB$55,$AA35:$AA$55)),"") -> 12204 | Y35: =IF(AB35<>"",IF(E35<>"",E35,($I$9-SUM($Y$25:Y34))*AA35*AB35/SUMPRODUCT($AB35:$AB$55,$AA35:$AA$55)),"") -> 2 | Z35: =IF(AB35<>"",IF($I$12<>"",IF(G35<>"",G35,($I$9/$I$12-SUM($Z$25:Z34))*AA35*AB35/SUMPRODUCT($AB35:$AB$55,$AA35:$AA$55)),""),"") -> 2 | AA35: 0.75 | AB35: 0.7
A36: Свидовская, Корж | B36: 46034 | C36: пн | D36: 10158 | E36: 2 | F36: =IF(AND(E36<>"",E36<>0),D36/E36,"") -> 5079 | G36: 2 | H36: =IF(AND(G36<>"",G36<>0),D36/G36,"") -> 5079 | I36: 52 | J36: =IF(AND(G36<>"",G36<>0),E36/G36,"") -> 1 | S36: =IF(AND(I36<>"",I36<>0),G36/I36,"") -> 0.038461538 | T36: =D36/U36 -> 0.13957578 | U36: =$I$8*AA36*AB36/SUMPRODUCT($AB$25:$AB$55,$AA$25:$AA$55) -> 72777.671 | V36: =$I$9*AA36*AB36/SUMPRODUCT($AB$25:$AB$55,$AA$25:$AA$55) -> 11.02692 | W36: =IF($I$12="","",V36/$I$12) -> 6.4864234 | X36: =IF(AB36<>"",IF(D36<>"",D36,($I$8-SUM($X$25:X35))*AA36*AB36/SUMPRODUCT($AB36:$AB$55,$AA36:$AA$55)),"") -> 10158 | Y36: =IF(AB36<>"",IF(E35<>"",E35,($I$9-SUM($Y$25:Y35))*AA36*AB36/SUMPRODUCT($AB36:$AB$55,$AA36:$AA$55)),"") -> 2 | Z36: =IF(AB36<>"",IF($I$12<>"",IF(G36<>"",G36,($I$9/$I$12-SUM($Z$25:Z35))*AA36*AB36/SUMPRODUCT($AB36:$AB$55,$AA36:$AA$55)),""),"") -> 2 | AA36: 1 | AB36: 1
A37: Корж | B37: 46035 | C37: вт | D37: 5393 | E37: 1 | F37: =IF(AND(E37<>"",E37<>0),D37/E37,"") -> 5393 | G37: 1 | H37: =IF(AND(G37<>"",G37<>0),D37/G37,"") -> 5393 | I37: 38 | J37: =IF(AND(G37<>"",G37<>0),E37/G37,"") -> 1 | S37: =IF(AND(I37<>"",I37<>0),G37/I37,"") -> 0.026315789 | T37: =D37/U37 -> 0.074102399 | U37: =$I$8*AA37*AB37/SUMPRODUCT($AB$25:$AB$55,$AA$25:$AA$55) -> 72777.671 | V37: =$I$9*AA37*AB37/SUMPRODUCT($AB$25:$AB$55,$AA$25:$AA$55) -> 11.02692 | W37: =IF($I$12="","",V37/$I$12) -> 6.4864234 | X37: =IF(AB37<>"",IF(D37<>"",D37,($I$8-SUM($X$25:X36))*AA37*AB37/SUMPRODUCT($AB37:$AB$55,$AA37:$AA$55)),"") -> 5393 | Y37: =IF(AB37<>"",IF(E37<>"",E37,($I$9-SUM($Y$25:Y36))*AA37*AB37/SUMPRODUCT($AB37:$AB$55,$AA37:$AA$55)),"") -> 1 | Z37: =IF(AB37<>"",IF($I$12<>"",IF(G37<>"",G37,($I$9/$I$12-SUM($Z$25:Z36))*AA37*AB37/SUMPRODUCT($AB37:$AB$55,$AA37:$AA$55)),""),"") -> 1 | AA37: 1 | AB37: 1
A38: Козлова,Рогалевич | B38: 46036 | C38: ср | D38: =6443+44640 -> 51083 | E38: 9 | F38: =IF(AND(E38<>"",E38<>0),D38/E38,"") -> 5675.8889 | G38: 6 | H38: =IF(AND(G38<>"",G38<>0),D38/G38,"") -> 8513.8333 | I38: 61 | J38: =IF(AND(G38<>"",G38<>0),E38/G38,"") -> 1.5 | K38: 7220 | L38: 6443 | M38: 11393 | S38: =IF(AND(I38<>"",I38<>0),G38/I38,"") -> 0.098360656 | T38: =D38/U38 -> 0.70190485 | U38: =$I$8*AA38*AB38/SUMPRODUCT($AB$25:$AB$55,$AA$25:$AA$55) -> 72777.671 | V38: =$I$9*AA38*AB38/SUMPRODUCT($AB$25:$AB$55,$AA$25:$AA$55) -> 11.02692 | W38: =IF($I$12="","",V38/$I$12) -> 6.4864234 | X38: =IF(AB38<>"",IF(D38<>"",D38,($I$8-SUM($X$25:X37))*AA38*AB38/SUMPRODUCT($AB38:$AB$55,$AA38:$AA$55)),"") -> 51083 | Y38: =IF(AB38<>"",IF(E38<>"",E38,($I$9-SUM($Y$25:Y37))*AA38*AB38/SUMPRODUCT($AB38:$AB$55,$AA38:$AA$55)),"") -> 9 | Z38: =IF(AB38<>"",IF($I$12<>"",IF(G38<>"",G38,($I$9/$I$12-SUM($Z$25:Z37))*AA38*AB38/SUMPRODUCT($AB38:$AB$55,$AA38:$AA$55)),""),"") -> 6 | AA38: 1 | AB38: 1
A39: Свидовская, Козлова,Рогалевич | B39: 46037 | C39: чт | D39: =17806+63046 -> 80852 | E39: 8 | F39: =IF(AND(E39<>"",E39<>0),D39/E39,"") -> 10106.5 | G39: 4 | H39: =IF(AND(G39<>"",G39<>0),D39/G39,"") -> 20213 | I39: 51 | J39: =IF(AND(G39<>"",G39<>0),E39/G39,"") -> 2 | L39: 17806 | R39: 38380 | S39: =IF(AND(I39<>"",I39<>0),G39/I39,"") -> 0.078431373 | T39: =D39/U39 -> 1.1109451 | U39: =$I$8*AA39*AB39/SUMPRODUCT($AB$25:$AB$55,$AA$25:$AA$55) -> 72777.671 | V39: =$I$9*AA39*AB39/SUMPRODUCT($AB$25:$AB$55,$AA$25:$AA$55) -> 11.02692 | W39: =IF($I$12="","",V39/$I$12) -> 6.4864234 | X39: =IF(AB39<>"",IF(D39<>"",D39,($I$8-SUM($X$25:X38))*AA39*AB39/SUMPRODUCT($AB39:$AB$55,$AA39:$AA$55)),"") -> 80852 | Y39: =IF(AB39<>"",IF(E39<>"",E39,($I$9-SUM($Y$25:Y38))*AA39*AB39/SUMPRODUCT($AB39:$AB$55,$AA39:$AA$55)),"") -> 8 | Z39: =IF(AB39<>"",IF($I$12<>"",IF(G39<>"",G39,($I$9/$I$12-SUM($Z$25:Z38))*AA39*AB39/SUMPRODUCT($AB39:$AB$55,$AA39:$AA$55)),""),"") -> 4 | AA39: 1 | AB39: 1
A40: Корж, Свидовская, Рогалевич, Сейтджелилова | B40: 46038 | C40: пт | D40: =26501+62037+11502 -> 100040 | E40: 8 | F40: =IF(AND(E40<>"",E40<>0),D40/E40,"") -> 12505 | G40: 3 | H40: =IF(AND(G40<>"",G40<>0),D40/G40,"") -> 33346.667 | I40: 46 | J40: =IF(AND(G40<>"",G40<>0),E40/G40,"") -> 2.6666667 | L40: 26501 | N40: 62037 | S40: =IF(AND(I40<>"",I40<>0),G40/I40,"") -> 0.065217391 | T40: =D40/U40 -> 1.3745974 | U40: =$I$8*AA40*AB40/SUMPRODUCT($AB$25:$AB$55,$AA$25:$AA$55) -> 72777.671 | V40: =$I$9*AA40*AB40/SUMPRODUCT($AB$25:$AB$55,$AA$25:$AA$55) -> 11.02692 | W40: =IF($I$12="","",V40/$I$12) -> 6.4864234 | X40: =IF(AB40<>"",IF(D40<>"",D40,($I$8-SUM($X$25:X39))*AA40*AB40/SUMPRODUCT($AB40:$AB$55,$AA40:$AA$55)),"") -> 100040 | Y40: =IF(AB40<>"",IF(E40<>"",E40,($I$9-SUM($Y$25:Y39))*AA40*AB40/SUMPRODUCT($AB40:$AB$55,$AA40:$AA$55)),"") -> 8 | Z40: =IF(AB40<>"",IF($I$12<>"",IF(G40<>"",G40,($I$9/$I$12-SUM($Z$25:Z39))*AA40*AB40/SUMPRODUCT($AB40:$AB$55,$AA40:$AA$55)),""),"") -> 3 | AA40: 1 | AB40: 1
A41: Корж, Рогалевич, Сейтджелилова | B41: 46039 | C41: сб | D41: 58965 | E41: 7 | F41: =IF(AND(E41<>"",E41<>0),D41/E41,"") -> 8423.5714 | G41: 4 | H41: =IF(AND(G41<>"",G41<>0),D41/G41,"") -> 14741.25 | I41: 56 | J41: =IF(AND(G41<>"",G41<>0),E41/G41,"") -> 1.75 | R41: 23229 | S41: =IF(AND(I41<>"",I41<>0),G41/I41,"") -> 0.071428571 | T41: =D41/U41 -> 0.8102073 | U41: =$I$8*AA41*AB41/SUMPRODUCT($AB$25:$AB$55,$AA$25:$AA$55) -> 72777.671 | V41: =$I$9*AA41*AB41/SUMPRODUCT($AB$25:$AB$55,$AA$25:$AA$55) -> 11.02692 | W41: =IF($I$12="","",V41/$I$12) -> 6.4864234 | X41: =IF(AB41<>"",IF(D41<>"",D41,($I$8-SUM($X$25:X40))*AA41*AB41/SUMPRODUCT($AB41:$AB$55,$AA41:$AA$55)),"") -> 58965 | Y41: =IF(AB41<>"",IF(E41<>"",E41,($I$9-SUM($Y$25:Y40))*AA41*AB41/SUMPRODUCT($AB41:$AB$55,$AA41:$AA$55)),"") -> 7 | Z41: =IF(AB41<>"",IF($I$12<>"",IF(G41<>"",G41,($I$9/$I$12-SUM($Z$25:Z40))*AA41*AB41/SUMPRODUCT($AB41:$AB$55,$AA41:$AA$55)),""),"") -> 4 | AA41: 1 | AB41: 1
A42: Корж, Рогалевич, Сейтджелилова, Козлова | B42: 46040 | C42: вс | D42: 21509 | E42: 5 | F42: =IF(AND(E42<>"",E42<>0),D42/E42,"") -> 4301.8 | G42: 3 | H42: =IF(AND(G42<>"",G42<>0),D42/G42,"") -> 7169.6667 | I42: 96 | J42: =IF(AND(G42<>"",G42<>0),E42/G42,"") -> 1.6666667 | R42: 19276 | S42: =IF(AND(I42<>"",I42<>0),G42/I42,"") -> 0.03125 | T42: =D42/U42 -> 0.29554395 | U42: =$I$8*AA42*AB42/SUMPRODUCT($AB$25:$AB$55,$AA$25:$AA$55) -> 72777.671 | V42: =$I$9*AA42*AB42/SUMPRODUCT($AB$25:$AB$55,$AA$25:$AA$55) -> 11.02692 | W42: =IF($I$12="","",V42/$I$12) -> 6.4864234 | X42: =IF(AB42<>"",IF(D42<>"",D42,($I$8-SUM($X$25:X41))*AA42*AB42/SUMPRODUCT($AB42:$AB$55,$AA42:$AA$55)),"") -> 21509 | Y42: =IF(AB42<>"",IF(E42<>"",E42,($I$9-SUM($Y$25:Y41))*AA42*AB42/SUMPRODUCT($AB42:$AB$55,$AA42:$AA$55)),"") -> 5 | Z42: =IF(AB42<>"",IF($I$12<>"",IF(G42<>"",G42,($I$9/$I$12-SUM($Z$25:Z41))*AA42*AB42/SUMPRODUCT($AB42:$AB$55,$AA42:$AA$55)),""),"") -> 3 | AA42: 1 | AB42: 1
...

Sheet Конкурс
A1: Личный ежедневный КВП, %
A3: Сотруник | B3: 45282 | C3: 45283 | D3: 45284 | E3: 45285 | F3: 45286 | G3: 45287 | H3: 45288 | I3: 45289 | J3: 45290 | K3: 45291 | L3: Итого:
A4: Доп сотрудник | B4: ='Доп сотрудник'!T35 -> #DIV/0! | D4: 0.27 | E4: 0.57 | F4: 0.73 | G4: 0.88 | H4: 0.98
A5: Стекольщикова Алла | C5: 0.25 | D5: 0.79 | E5: 0.33 | F5: 0.13 | G5: 0.75 | H5: 0.67 | I5: 0.74 | J5: 1.72 | K5: 0.33
A6: Свидовская София | B6: ='Свидовская С. А.'!T39 -> 1.2450573 | E6: 0.25 | F6: 0.25 | H6: 0.38 | I6: 1.11 | J6: 1.17 | K6: 0.34
A7: Корж Анастасия | C7: 0.33 | D7: 0.57 | E7: 0.08 | F7: 0.45 | G7: 0.4 | H7: 0.24 | I7: 0.25 | J7: 0.28 | K7: 0.23
A8: Козлова Валерия | B8: ='Козлова В. Э.'!T39 -> 1.2945013 | C8: 0.52 | D8: 0.31 | G8: 0.29 | I8: 0.49 | J8: 0.23 | K8: 0.1
A10: Личный КВП, баллы
A12: Сотруник | B12: 45282 | C12: 45283 | D12: 45284 | E12: 45285 | F12: 45286 | G12: 45287 | H12: 45288 | I12: 45289 | J12: 45290 | K12: 45291 | L12: Итого:
A13: Доп сотрудник | B13: 0 | D13: 0 | E13: 1 | F13: 1 | G13: 1 | H13: 1 | L13: =SUM(B13:K13) -> 4
A14: Стекольщикова Алла | C14: 0 | D14: 1 | E14: 0 | F14: 0 | G14: 0 | H14: 0 | I14: 0 | J14: 2 | K14: 0 | L14: =SUM(B14:K14) -> 3
A15: Свидовская София | B15: 1 | E15: 0 | F15: 0 | H15: 0 | I15: 2 | J15: 1 | K15: 1 | L15: =SUM(B15:K15) -> 5
A16: Корж Анастасия | C16: 0 | D16: 0 | E16: 0 | F16: 0 | G16: 0 | H16: 0 | I16: 0 | J16: 0 | K16: 0 | L16: =SUM(B16:K16) -> 0
A17: Козлова Валерия | B17: 0 | C17: 1 | D17: 0 | G17: 0 | I17: 0 | J17: 0 | K17: 0 | L17: =SUM(B17:K17) -> 1

Sheet Сводная
A1: Сводная по показателям
A2: Показатель | D2: =Центрум!I3 -> ТРК Центрум | G2: =График!B27 -> Свидовская София | J2: =График!B25 -> Корж Анастасия | M2: =График!B26 -> Козлова Валерия | P2: =График!B28 -> Сейтджелилова Алина
D3: Факт | F3: Прогноз | G3: Факт | I3: Прогноз | J3: Факт | L3: Прогноз | M3: Факт | O3: Прогноз | P3: Факт | R3: Прогноз
A4: Выручка | D4: =Центрум!K8 -> 0.74142872 | E4: =Центрум!J8 -> 1422520 | F4: =Центрум!M8 -> 0.74142872 | G4: ='Свидовская С. А.'!K8 -> 0.75489417 | H4: ='Свидовская С. А.'!J8 -> 268023 | I4: ='Свидовская С. А.'!M8 -> 0.80775624 | J4: ='Корж А. А.'!K8 -> 0.7998031 | K4: ='Корж А. А.'!J8 -> 505135 | L4: ='Корж А. А.'!M8 -> 0.82474864 | M4: ='Козлова В. Э.'!K8 -> 0.42070029 | N4: ='Козлова В. Э.'!J8 -> 262830.98 | O4: ='Козлова В. Э.'!M8 -> 0.4995816 | P4: ='Стекольщикова А. А.'!K8 -> 0.28779604 | Q4: ='Стекольщикова А. А.'!J8 -> 88426 | R4: ='Стекольщикова А. А.'!M8 -> 1.5238114
A5: Кол-во изделий | D5: ='Центрум'!K9 -> 0.69487444 | E5: ='Центрум'!J9 -> 202 | F5: ='Центрум'!M9 -> 0.69487444 | G5: ='Свидовская С. А.'!K9 -> 0.76215236 | H5: ='Свидовская С. А.'!J9 -> 41 | I5: ='Свидовская С. А.'!M9 -> 0.78645933 | J5: ='Корж А. А.'!K9 -> 0.67925511 | K5: ='Корж А. А.'!J9 -> 65 | L5: ='Корж А. А.'!M9 -> 0.72528367 | M5: ='Козлова В. Э.'!K9 -> 0.47539292 | N5: ='Козлова В. Э.'!J9 -> 45 | O5: ='Козлова В. Э.'!M9 -> 0.56452909 | P5: ='Стекольщикова А. А.'!K9 -> 0.30073004 | Q5: ='Стекольщикова А. А.'!J9 -> 14 | R5: ='Стекольщикова А. А.'!M9 -> 1.3145261
A6: Средний чек | D6: =Центрум!K10 -> 1.1525847 | E6: =Центрум!J10 -> 12932 | F6: =Центрум!M10 -> 1.1525847 | G6: ='Свидовская С. А.'!K10 -> 0.77057961 | H6: ='Свидовская С. А.'!J10 -> 8645.9032 | I6: ='Свидовская С. А.'!M10 -> 0.77057961 | J6: ='Корж А. А.'!K10 -> 1.6674424 | K6: ='Корж А. А.'!J10 -> 18708.704 | L6: ='Корж А. А.'!M10 -> 1.6674424 | M6: ='Козлова В. Э.'!K10 -> 0.90097004 | N6: ='Козлова В. Э.'!J10 -> 10108.884 | O6: ='Козлова В. Э.'!M10 -> 0.90097004 | P6: ='Стекольщикова А. А.'!K10 -> 0.87567835 | Q6: ='Стекольщикова А. А.'!J10 -> 9825.1111 | R6: ='Стекольщикова А. А.'!M10 -> 0.87567835
A7: Средняя стоимость изделия | D7: ='Центрум'!K11 -> 1.0669967 | E7: ='Центрум'!J11 -> 7042.1781 | F7: ='Центрум'!M11 -> 1.0669967 | G7: ='Свидовская С. А.'!K11 -> 0.99047672 | H7: ='Свидовская С. А.'!J11 -> 6537.1463 | I7: ='Свидовская С. А.'!M11 -> 0.99047672 | J7: ='Корж А. А.'!K11 -> 1.1774709 | K7: ='Корж А. А.'!J11 -> 7771.3077 | L7: ='Корж А. А.'!M11 -> 1.1774709 | M7: ='Козлова В. Э.'!K11 -> 0.88495279 | N7: ='Козлова В. Э.'!J11 -> 5840.6884 | O7: ='Козлова В. Э.'!M11 -> 0.88495279 | P7: ='Стекольщикова А. А.'!K11 -> 0.95699134 | Q7: ='Стекольщикова А. А.'!J11 -> 6316.1429 | R7: ='Стекольщикова А. А.'!M11 -> 0.95699134
A8: Длина чека | D8: ='Центрум'!K12 -> 1.0802139 | E8: ='Центрум'!J12 -> 1.8363636 | F8: ='Центрум'!M12 -> 1.0802139 | G8: ='Свидовская С. А.'!K12 -> 0.77798861 | H8: ='Свидовская С. А.'!J12 -> 1.3225806 | I8: ='Свидовская С. А.'!M12 -> 0.77798861 | J8: ='Корж А. А.'!K12 -> 1.416122 | K8: ='Корж А. А.'!J12 -> 2.4074074 | L8: ='Корж А. А.'!M12 -> 1.416122 | M8: ='Козлова В. Э.'!K12 -> 1.0180995 | N8: ='Козлова В. Э.'!J12 -> 1.7307692 | O8: ='Козлова В. Э.'!M12 -> 1.0180995 | P8: ='Стекольщикова А. А.'!K12 -> 0.91503268 | Q8: ='Стекольщикова А. А.'!J12 -> 1.5555556 | R8: ='Стекольщикова А. А.'!M12 -> 0.91503268
A9: Кол-во чеков | D9: ='Центрум'!K13 -> 0.64327485 | E9: ='Центрум'!J13 -> 110 | F9: ='Центрум'!M13 -> 0.64327485 | G9: ='Свидовская С. А.'!K13 -> 0.97964462 | H9: ='Свидовская С. А.'!J13 -> 31 | I9: ='Свидовская С. А.'!M13 -> 1.0226579 | J9: ='Корж А. А.'!K13 -> 0.47965861 | K9: ='Корж А. А.'!J13 -> 27 | L9: ='Корж А. А.'!M13 -> 0.51561385 | M9: ='Козлова В. Э.'!K13 -> 0.46694149 | N9: ='Козлова В. Э.'!J13 -> 26 | O9: ='Козлова В. Э.'!M13 -> 0.55449302 | P9: ='Стекольщикова А. А.'!K13 -> 0.32865497 | Q9: ='Стекольщикова А. А.'!J13 -> 9 | R9: ='Стекольщикова А. А.'!M13 -> 1.5223538
A10: Кол-во смен план/отработано | D10: ='Центрум'!K14 -> 1 | E10: ='Центрум'!J14 -> 31 | G10: ='Свидовская С. А.'!K14 -> 1.8 | H10: ='Свидовская С. А.'!J14 -> 18 | J10: ='Корж А. А.'!K14 -> 1.0555556 | K10: ='Корж А. А.'!J14 -> 19 | M10: ='Козлова В. Э.'!K14 -> 1 | N10: ='Козлова В. Э.'!J14 -> 19 | P10: ='Стекольщикова А. А.'!K14 -> 0.5 | Q10: ='Стекольщикова А. А.'!J14 -> 5
A11: Средние продажи в смену | D11: ='Центрум'!K15 -> 0.74142872 | E11: ='Центрум'!J15 -> 45887.741 | F11: ='Центрум'!M15 -> 0.74142872 | G11: ='Свидовская С. А.'!K15 -> 0.48117414 | H11: ='Свидовская С. А.'!J15 -> 14890.167 | I11: ='Свидовская С. А.'!M15 -> 0.48117414 | J11: ='Корж А. А.'!K15 -> 0.85912545 | K11: ='Корж А. А.'!J15 -> 26586.053 | L11: ='Корж А. А.'!M15 -> 0.85912545 | M11: ='Козлова В. Э.'!K15 -> 0.44701868 | N11: ='Козлова В. Э.'!J15 -> 13833.209 | O11: ='Козлова В. Э.'!M15 -> 0.44701868 | P11: ='Стекольщикова А. А.'!K15 -> 0.28574767 | Q11: ='Стекольщикова А. А.'!J15 -> 17685.2 | R11: ='Стекольщикова А. А.'!M15 -> 0.28574767
A12: Отставание/Перевыполнение | D12: =Центрум!J16 -> -496100.02 | G12: ='Свидовская С. А.'!N8 -> -68255.594 | J12: ='Корж А. А.'!N8 -> -110684.23 | M12: ='Козлова В. Э.'!N8 -> -312634.58 | P12: ='Стекольщикова А. А.'!N8 -> 160942.26

Sheet Справочник магазинов
A1: МЕГА Белая Дача
A2: Гагаринский
A3: Марфино

Sheet План на день
A1: Выручка | D1: =86000 -> 86000
A2: Кол-во изделий | D2: =D1/D4 -> 13.030303
A3: Средний чек | D3: =D4*D5 -> 11220
A4: Средняя стоимость изделия | D4: =Центрум!I11 -> 6600
A5: Длина чека | D5: ='Центрум'!I12 -> 1.7
A6: Кол-во чеков | D6: =IF(D5<>0,D2/D5,"") -> 7.6648841
A7: Конверсия | D7: =Центрум!I20 -> 0.09

Sheet Сейтджелилова А.Э.
B1: =TODAY()-1 -> 46170
B2: (отчетная дата) | J2: ЕЖЕДНЕВНЫЙ ОТЧЕТ О ПРОДАЖАХ
B3: Осталось до выполнения плана!!! | J3: =График!B23 -> 0
C4: =I8-D49 -> -165233 | E4: =IF(I8<>0,C4/I8,0) -> 0
F6: Целевые показатели
F7: Показатель | I7: План | J7: Факт | K7: % выполнения | L7: Прогноз выполнения | M7: % выполнения по прогнозу | N7: Отклонение | O7: Факт аналогичного месяца прошлого года | P7: Отклонение LFL
F8: Выручка | I8: =Центрум!I8/График!AJ29*График!AJ23 -> 0 | J8: =D49 -> 165233 | K8: =IF(AND(I8<>"",I8<>0,J8<>""),J8/I8,"") | L8: =IF(SUMIF($D$25:$D$47,">=0",$U$25:$U$47)<>0,I8*D49/SUMIF($D$25:$D$47,">=0",$U$25:$U$47),0) -> 0 | M8: =L8/I8 -> #DIV/0! | N8: =IF(AND(J8<>0,J8<>"",I8<>0,I8<>""),L8-I8,"") | P8: =IF(AND(O8<>"",O8<>0,L8<>"",L8<>0),-O8+L8,"") | Q8: =IF(AND(P8<>"",P8<>0,O8<>0,O8<>""),P8/O8,"")
F9: Кол-во изделий | I9: =I8/I11 -> 0 | J9: =E49 -> 19 | K9: =IF(AND(I9<>"",I9<>0,J9<>""),J9/I9,"") | L9: =IF(SUMIF($E$25:$E$47,">=0",$V$25:$V$47)<>0,I9*E49/SUMIF($E$25:$E$47,">=0",$V$25:$V$47),0) -> 0 | M9: =IF(AND(I9<>"",I9<>0,L9<>"",L9<>0),L9/I9,"") | N9: =IF(AND(J9<>0,J9<>"",I9<>0,I9<>""),L9-I9,"") | O9: =O8/O11 -> #DIV/0! | P9: =IF(AND(O9<>"",O9<>0,L9<>"",L9<>0),-O9+L9,"") -> #DIV/0! | Q9: =IF(AND(P9<>"",P9<>0,O9<>0,O9<>""),P9/O9,"") -> #DIV/0!
F10: Средний чек | I10: =I11*I12 -> 11220 | J10: =H49 -> 23604.714 | K10: =IF(AND(I10<>"",I10<>0,J10<>""),J10/I10,"") -> 2.103807 | L10: =J10 -> 23604.714 | M10: =IF(AND(I10<>"",I10<>0,L10<>"",L10<>0),L10/I10,"") -> 2.103807 | N10: =IF(AND(J10<>0,J10<>"",I10<>0,I10<>""),L10-I10,"") -> 12384.714 | O10: =O11*O12 -> 0 | P10: =IF(AND(O10<>"",O10<>0,L10<>"",L10<>0),-O10+L10,"") | Q10: =IF(AND(P10<>"",P10<>0,O10<>0,O10<>""),P10/O10,"")
F11: Средняя стоимость изделия | I11: =Центрум!I11 -> 6600 | J11: =F49 -> 8696.4737 | K11: =IF(AND(I11<>"",I11<>0,J11<>""),J11/I11,"") -> 1.3176475 | L11: =J11 -> 8696.4737 | M11: =IF(AND(I11<>"",I11<>0,L11<>"",L11<>0),L11/I11,"") -> 1.3176475 | N11: =IF(AND(J11<>0,J11<>"",I11<>0,I11<>""),L11-I11,"") -> 2096.4737 | P11: =IF(AND(O11<>"",O11<>0,L11<>"",L11<>0),-O11+L11,"") | Q11: =IF(AND(P11<>"",P11<>0,O11<>0,O11<>""),P11/O11,"")
F12: Длина чека | I12: ='Центрум'!I12 -> 1.7 | J12: =J49 -> 2.7142857 | K12: =IF(AND(I12<>"",I12<>0,J12<>""),J12/I12,"") -> 1.5966387 | L12: =J12 -> 2.7142857 | M12: =IF(AND(I12<>"",I12<>0,L12<>"",L12<>0),L12/I12,"") -> 1.5966387 | N12: =IF(AND(J12<>0,J12<>"",I12<>0,I12<>""),L12-I12,"") -> 1.0142857 | P12: =IF(AND(O12<>"",O12<>0,L12<>"",L12<>0),-O12+L12,"") | Q12: =IF(AND(P12<>"",P12<>0,O12<>0,O12<>""),P12/O12,"")
F13: Кол-во чеков | I13: =IF(I12<>0,I9/I12,"") -> 0 | J13: =G49 -> 7 | K13: =IF(AND(I13<>"",I13<>0,J13<>""),J13/I13,"") | L13: =IF(SUMIF($G$25:$G$47,">=0",$W$25:$W$47)<>0,I13*G49/SUMIF($G$25:$G$47,">=0",$W$25:$W$47),"") | M13: =IF(AND(I13<>"",I13<>0,L13<>"",L13<>0),L13/I13,"") | N13: =IF(AND(J13<>0,J13<>"",I13<>0,I13<>""),L13-I13,"") | P13: =IF(AND(O13<>"",O13<>0,L13<>"",L13<>0),-O13+L13,"") | Q13: =IF(AND(P13<>"",P13<>0,O13<>0,O13<>""),P13/O13,"")
F14: Кол-во смен план/отработано | I14: =График!AI23 -> 0 | J14: 13 | K14: =IF(AND(I14<>"",I14<>0,J14<>""),J14/I14,"") | L14: =IF(SUMIF($D$25:$D$47,">=0",$U$25:$U$47),I49*I8/SUMIF($D$25:$D$47,">=0",$U$25:$U$47),"") | N14: =IF(AND(J14<>0,J14<>"",I14<>0,I14<>""),L14-I14,"") | P14: =IF(AND(O14<>"",O14<>0,L14<>"",L14<>0),-O14+L14,"") | Q14: =IF(AND(P14<>"",P14<>0,O14<>0,O14<>""),P14/O14,"")
F15: Средние продажи в смену | I15: =Центрум!I15/2 -> 30945.484 | J15: =J8/J14 -> 12710.231 | K15: =IF(AND(I15<>"",I15<>0,J15<>""),J15/I15,"") -> 0.41072975 | L15: =J15 -> 12710.231 | M15: =IF(AND(I15<>"",I15<>0,L15<>"",L15<>0),L15/I15,"") -> 0.41072975 | N15: =IF(AND(J15<>0,J15<>"",I15<>0,I15<>""),L15-I15,"") -> -18235.253 | P15: =IF(AND(O15<>"",O15<>0,L15<>"",L15<>0),-O15+L15,"") | Q15: =IF(AND(P15<>"",P15<>0,O15<>0,O15<>""),P15/O15,"")
F16: Отставание/Перевыполнение | J16: =J8-I15*J14 -> -237058.29 | K16: =IF(AND(I16<>"",I16<>0,J16<>""),J16/I16,"") | L16: =J16 -> -237058.29 | M16: =IF(AND(I16<>"",I16<>0,L16<>"",L16<>0),L16/I16,"") | N16: =IF(AND(J16<>0,J16<>"",I16<>0,I16<>""),L16-I16,"") | P16: =IF(AND(O16<>"",O16<>0,L16<>"",L16<>0),-O16+L16,"") | Q16: =IF(AND(P16<>"",P16<>0,O16<>0,O16<>""),P16/O16,"") | T16: Подарочные сертификаты
F17: Трафик | I17: =Центрум!I17/График!AJ29*График!AJ23 -> 0 | J17: =I49 -> 139.2 | K17: =IF(AND(I17<>"",I17<>0,J17<>""),J17/I17,"") | L17: =J17/J14*I14 -> 0 | M17: =IF(AND(I17<>"",I17<>0,L17<>"",L17<>0),L17/I17,"") | N17: =IF(AND(J17<>0,J17<>"",I17<>0,I17<>""),L17-I17,"") | P17: =IF(AND(O17<>"",O17<>0,L17<>"",L17<>0),-O17+L17,"") | Q17: =IF(AND(P17<>"",P17<>0,O17<>0,O17<>""),P17/O17,"")
K18: =IF(AND(I18<>"",I18<>0,J18<>""),J18/I18,"") | L18: =J18 -> 0 | M18: =IF(AND(I18<>"",I18<>0,L18<>"",L18<>0),L18/I18,"") | N18: =IF(AND(J18<>0,J18<>"",I18<>0,I18<>""),L18-I18,"") | O18: 0 | P18: =IF(AND(O18<>"",O18<>0,L18<>"",L18<>0),-O18+L18,"") | Q18: =IF(AND(P18<>"",P18<>0,O18<>0,O18<>""),P18/O18,"")
J19: =P49 -> 0 | K19: =IF(AND(I19<>"",I19<>0,J19<>""),J19/I19,"") | L19: =J19 -> 0 | M19: =IF(AND(I19<>"",I19<>0,L19<>"",L19<>0),L19/I19,"") | N19: =IF(AND(J19<>0,J19<>"",I19<>0,I19<>""),L19-I19,"") | O19: 0 | P19: =IF(AND(O19<>"",O19<>0,L19<>"",L19<>0),-O19+L19,"") | Q19: =IF(AND(P19<>"",P19<>0,O19<>0,O19<>""),P19/O19,"") | T19: =T18/I16 -> #DIV/0!
F20: Конверсия план/факт | I20: =Центрум!I20 -> 0.09 | J20: =S49 -> 0.050287356 | K20: =J20/I20 -> 0.5587484 | L20: =IF(AND(K8<>0,I14<>0,I49<>0),(I49*S49+(I49/K8-I49)*I20)/(I49/K8),0) -> 0 | M20: =IF(AND(I20<>"",I20<>0,L20<>"",L20<>0),L20/I20,"") | N20: =IF(AND(J20<>0,J20<>"",I20<>0,I20<>""),L20-I20,"") -> -0.09 | P20: =IF(AND(O20<>"",O20<>0,L20<>"",L20<>0),-O20+L20,"") | Q20: =IF(AND(P20<>"",P20<>0,O20<>0,O20<>""),P20/O20,"")
B22: Факт продаж за месяц | T22: % выполнения дневного плана | U22: Раcпределение плана по дням
B23: Дата | C23: День недели | D23: Выручка (руб) | E23: Кол-во единиц (шт.) | F23: Средняя стоимость изделия (руб.) | G23: Количество чеков (шт.) | H23: Средняя сумма чека (руб.) | I23: Трафик | J23: Длина чека (шт.) | K23: UNOde50 | L23: IS | M23: Agafi | N23: Kalliope | O23: Raganella | P23: CC/MP | Q23: Eva Rites | R23: Antura | S23: Конверсия (%) | U23: выручка, план | V23: кол-во ед, план | W23: Кол-во чеков, план | X23: выручка, скорректир.план | Y23: кол-во ед, скорр. план | Z23: кол-во чеков, скорр. план | AA23: Коэфф. Дня Недели | AB23: Специфика месяца
B24: 1 | C24: 2 | D24: 3 | E24: в | F24: 5 | G24: 6 | H24: 7 | I24: 8 | J24: 9 | K24: 10 | L24: 11 | M24: 12 | N24: 13 | O24: 14 | P24: 15 | Q24: 16 | R24: 17 | S24: 18 | U24: 1 | V24: 2 | W24: 3 | X24: 4 | Y24: 5 | Z24: 6 | AA24: 10 | AB24: 11
A25: 1 | B25: 46038 | C25: пт | D25: 0 | E25: 0 | F25: =IF(AND(E25<>"",E25<>0),D25/E25,"") | G25: 0 | H25: =IF(AND(G25<>"",G25<>0),D25/G25,"") | I25: 12 | J25: =IF(AND(G25<>"",G25<>0),E25/G25,"") | S25: =IF(AND(I25<>"",I25<>0),G25/I25,"") -> 0 | T25: =D25/U25 -> #DIV/0! | U25: =$I$8*AA25*AB25/SUMPRODUCT($AB$25:$AB$56,$AA$25:$AA$56) -> 0 | V25: =$I$9*AA25*AB25/SUMPRODUCT($AB$25:$AB$56,$AA$25:$AA$56) -> 0 | W25: =IF($I$12="","",V25/$I$12) -> 0 | X25: =IF(AB25<>"",IF(D25<>"",D25,($I$8-SUM($X24:X$25))*AA25*AB25/SUMPRODUCT($AB25:$AB$56,$AA25:$AA$56)),"") -> 0 | Y25: =IF(AB25<>"",IF(E25<>"",E25,($I$9-SUM($Y24:Y$25))*AA25*AB25/SUMPRODUCT($AB25:$AB$56,$AA25:$AA$56)),"") -> 0 | Z25: =IF(AB25<>"",IF($I$12<>"",IF(G25<>"",G25,($I$9/$I$12-SUM($Z24:Z$25))*AA25*AB25/SUMPRODUCT($AB25:$AB$56,$AA25:$AA$56)),""),"") -> 0 | AA25: 1 | AB25: 1
A26: 2 | B26: 46039 | C26: сб | D26: 15970 | E26: 2 | F26: =IF(AND(E26<>"",E26<>0),D26/E26,"") -> 7985 | G26: 1 | H26: =IF(AND(G26<>"",G26<>0),D26/G26,"") -> 15970 | I26: 19 | J26: =IF(AND(G26<>"",G26<>0),E26/G26,"") -> 2 | S26: =IF(AND(I26<>"",I26<>0),G26/I26,"") -> 0.052631579 | T26: =D26/U26 -> #DIV/0! | U26: =$I$8*AA26*AB26/SUMPRODUCT($AB$25:$AB$56,$AA$25:$AA$56) -> 0 | V26: =$I$9*AA26*AB26/SUMPRODUCT($AB$25:$AB$56,$AA$25:$AA$56) -> 0 | W26: =IF($I$12="","",V26/$I$12) -> 0 | X26: =IF(AB26<>"",IF(D26<>"",D26,($I$8-SUM($X25:X$25))*AA26*AB26/SUMPRODUCT($AB26:$AB$56,$AA26:$AA$56)),"") -> 15970 | Y26: =IF(AB26<>"",IF(E26<>"",E26,($I$9-SUM($Y25:Y$25))*AA26*AB26/SUMPRODUCT($AB26:$AB$56,$AA26:$AA$56)),"") -> 2 | Z26: =IF(AB26<>"",IF($I$12<>"",IF(G26<>"",G26,($I$9/$I$12-SUM($Z25:Z$25))*AA26*AB26/SUMPRODUCT($AB26:$AB$56,$AA26:$AA$56)),""),"") -> 1 | AA26: 1 | AB26: 1
A27: 3 | B27: 46040 | C27: вс | D27: 0 | E27: 0 | F27: =IF(AND(E27<>"",E27<>0),D27/E27,"") | G27: 0 | H27: =IF(AND(G27<>"",G27<>0),D27/G27,"") | I27: 24 | J27: =IF(AND(G27<>"",G27<>0),E27/G27,"") | S27: =IF(AND(I27<>"",I27<>0),G27/I27,"") -> 0 | T27: =D27/U27 -> #DIV/0! | U27: =$I$8*AA27*AB27/SUMPRODUCT($AB$25:$AB$56,$AA$25:$AA$56) -> 0 | V27: =$I$9*AA27*AB27/SUMPRODUCT($AB$25:$AB$56,$AA$25:$AA$56) -> 0 | W27: =IF($I$12="","",V27/$I$12) -> 0 | X27: =IF(AB27<>"",IF(D27<>"",D27,($I$8-SUM($X$25:X26))*AA27*AB27/SUMPRODUCT($AB27:$AB$56,$AA27:$AA$56)),"") -> 0 | Y27: =IF(AB27<>"",IF(E27<>"",E27,($I$9-SUM($Y$25:Y26))*AA27*AB27/SUMPRODUCT($AB27:$AB$56,$AA27:$AA$56)),"") -> 0 | Z27: =IF(AB27<>"",IF($I$12<>"",IF(G27<>"",G27,($I$9/$I$12-SUM($Z$25:Z26))*AA27*AB27/SUMPRODUCT($AB27:$AB$56,$AA27:$AA$56)),""),"") -> 0 | AA27: 1 | AB27: 1
A28: 4 | B28: 46042 | C28: вт | D28: 0 | E28: 0 | F28: =IF(AND(E28<>"",E28<>0),D28/E28,"") | G28: 0 | H28: =IF(AND(G28<>"",G28<>0),D28/G28,"") | I28: 16 | J28: =IF(AND(G28<>"",G28<>0),E28/G28,"") | S28: =IF(AND(I28<>"",I28<>0),G28/I28,"") -> 0 | T28: =D28/U28 -> #DIV/0! | U28: =$I$8*AA28*AB28/SUMPRODUCT($AB$25:$AB$56,$AA$25:$AA$56) -> 0 | V28: =$I$9*AA28*AB28/SUMPRODUCT($AB$25:$AB$56,$AA$25:$AA$56) -> 0 | W28: =IF($I$12="","",V28/$I$12) -> 0 | X28: =IF(AB28<>"",IF(D28<>"",D28,($I$8-SUM($X$25:X27))*AA28*AB28/SUMPRODUCT($AB28:$AB$56,$AA28:$AA$56)),"") -> 0 | Y28: =IF(AB28<>"",IF(E28<>"",E28,($I$9-SUM($Y$25:Y27))*AA28*AB28/SUMPRODUCT($AB28:$AB$56,$AA28:$AA$56)),"") -> 0 | Z28: =IF(AB28<>"",IF($I$12<>"",IF(G28<>"",G28,($I$9/$I$12-SUM($Z$25:Z27))*AA28*AB28/SUMPRODUCT($AB28:$AB$56,$AA28:$AA$56)),""),"") -> 0 | AA28: 1 | AB28: 1
A29: 5 | B29: 46043 | C29: ср | D29: 68258 | E29: 5 | F29: =IF(AND(E29<>"",E29<>0),D29/E29,"") -> 13651.6 | G29: 1 | H29: =IF(AND(G29<>"",G29<>0),D29/G29,"") -> 68258 | I29: 12 | J29: =IF(AND(G29<>"",G29<>0),E29/G29,"") -> 5 | M29: 31570 | O29: 36688 | S29: =IF(AND(I29<>"",I29<>0),G29/I29,"") -> 0.083333333 | T29: =D29/U29 -> #DIV/0! | U29: =$I$8*AA29*AB29/SUMPRODUCT($AB$25:$AB$56,$AA$25:$AA$56) -> 0 | V29: =$I$9*AA29*AB29/SUMPRODUCT($AB$25:$AB$56,$AA$25:$AA$56) -> 0 | W29: =IF($I$12="","",V29/$I$12) -> 0 | X29: =IF(AB29<>"",IF(D29<>"",D29,($I$8-SUM($X$25:X28))*AA29*AB29/SUMPRODUCT($AB29:$AB$56,$AA29:$AA$56)),"") -> 68258 | Y29: =IF(AB29<>"",IF(E29<>"",E29,($I$9-SUM($Y$25:Y28))*AA29*AB29/SUMPRODUCT($AB29:$AB$56,$AA29:$AA$56)),"") -> 5 | Z29: =IF(AB29<>"",IF($I$12<>"",IF(G29<>"",G29,($I$9/$I$12-SUM($Z$25:Z28))*AA29*AB29/SUMPRODUCT($AB29:$AB$56,$AA29:$AA$56)),""),"") -> 1 | AA29: 1 | AB29: 1
A30: 6 | B30: 46044 | C30: чт | D30: 0 | E30: 0 | F30: =IF(AND(E30<>"",E30<>0),D30/E30,"") | G30: 0 | H30: =IF(AND(G30<>"",G30<>0),D30/G30,"") | I30: 18 | J30: =IF(AND(G30<>"",G30<>0),E30/G30,"") | S30: =IF(AND(I30<>"",I30<>0),G30/I30,"") -> 0 | T30: =D30/U30 -> #DIV/0! | U30: =$I$8*AA30*AB30/SUMPRODUCT($AB$25:$AB$56,$AA$25:$AA$56) -> 0 | V30: =$I$9*AA30*AB30/SUMPRODUCT($AB$25:$AB$56,$AA$25:$AA$56) -> 0 | W30: =IF($I$12="","",V30/$I$12) -> 0 | X30: =IF(AB30<>"",IF(D30<>"",D30,($I$8-SUM($X$25:X29))*AA30*AB30/SUMPRODUCT($AB30:$AB$56,$AA30:$AA$56)),"") -> 0 | Y30: =IF(AB30<>"",IF(E30<>"",E30,($I$9-SUM($Y$25:Y29))*AA30*AB30/SUMPRODUCT($AB30:$AB$56,$AA30:$AA$56)),"") -> 0 | Z30: =IF(AB30<>"",IF($I$12<>"",IF(G30<>"",G30,($I$9/$I$12-SUM($Z$25:Z29))*AA30*AB30/SUMPRODUCT($AB30:$AB$56,$AA30:$AA$56)),""),"") -> 0 | AA30: 1 | AB30: 1
A31: 7 | B31: 46045 | C31: пт | D31: =19277+3951 -> 23228 | E31: 4 | F31: =IF(AND(E31<>"",E31<>0),D31/E31,"") -> 5807 | G31: 2 | H31: =IF(AND(G31<>"",G31<>0),D31/G31,"") -> 11614 | I31: 19 | J31: =IF(AND(G31<>"",G31<>0),E31/G31,"") -> 2 | S31: =IF(AND(I31<>"",I31<>0),G31/I31,"") -> 0.10526316 | T31: =D31/U31 -> #DIV/0! | U31: =$I$8*AA31*AB31/SUMPRODUCT($AB$25:$AB$56,$AA$25:$AA$56) -> 0 | V31: =$I$9*AA31*AB31/SUMPRODUCT($AB$25:$AB$56,$AA$25:$AA$56) -> 0 | W31: =IF($I$12="","",V31/$I$12) -> 0 | X31: =IF(AB31<>"",IF(D31<>"",D31,($I$8-SUM($X$25:X30))*AA31*AB31/SUMPRODUCT($AB31:$AB$56,$AA31:$AA$56)),"") -> 23228 | Y31: =IF(AB31<>"",IF(E31<>"",E31,($I$9-SUM($Y$25:Y30))*AA31*AB31/SUMPRODUCT($AB31:$AB$56,$AA31:$AA$56)),"") -> 4 | Z31: =IF(AB31<>"",IF($I$12<>"",IF(G31<>"",G31,($I$9/$I$12-SUM($Z$25:Z30))*AA31*AB31/SUMPRODUCT($AB31:$AB$56,$AA31:$AA$56)),""),"") -> 2 | AA31: 1 | AB31: 1
A32: 8 | B32: 46046 | C32: сб | D32: 16272 | E32: 3 | F32: =IF(AND(E32<>"",E32<>0),D32/E32,"") -> 5424 | G32: 1 | H32: =IF(AND(G32<>"",G32<>0),D32/G32,"") -> 16272 | I32: 27 | J32: =IF(AND(G32<>"",G32<>0),E32/G32,"") -> 3 | S32: =IF(AND(I32<>"",I32<>0),G32/I32,"") -> 0.037037037 | T32: =D32/U32 -> #DIV/0! | U32: =$I$8*AA32*AB32/SUMPRODUCT($AB$25:$AB$56,$AA$25:$AA$56) -> 0 | V32: =$I$9*AA32*AB32/SUMPRODUCT($AB$25:$AB$56,$AA$25:$AA$56) -> 0 | W32: =IF($I$12="","",V32/$I$12) -> 0 | X32: =IF(AB32<>"",IF(D32<>"",D32,($I$8-SUM($X$25:X31))*AA32*AB32/SUMPRODUCT($AB32:$AB$56,$AA32:$AA$56)),"") -> 16272 | Y32: =IF(AB32<>"",IF(E32<>"",E32,($I$9-SUM($Y$25:Y31))*AA32*AB32/SUMPRODUCT($AB32:$AB$56,$AA32:$AA$56)),"") -> 3 | Z32: =IF(AB32<>"",IF($I$12<>"",IF(G32<>"",G32,($I$9/$I$12-SUM($Z$25:Z31))*AA32*AB32/SUMPRODUCT($AB32:$AB$56,$AA32:$AA$56)),""),"") -> 1 | AA32: 1 | AB32: 1
A33: 9 | B33: 46049 | C33: вт | D33: 28856 | E33: 2 | F33: =IF(AND(E33<>"",E33<>0),D33/E33,"") -> 14428 | G33: 1 | H33: =IF(AND(G33<>"",G33<>0),D33/G33,"") -> 28856 | J33: =IF(AND(G33<>"",G33<>0),E33/G33,"") -> 2 | S33: =IF(AND(I33<>"",I33<>0),G33/I33,"") | T33: =D33/U33 -> #DIV/0! | U33: =$I$8*AA33*AB33/SUMPRODUCT($AB$25:$AB$56,$AA$25:$AA$56) -> 0 | V33: =$I$9*AA33*AB33/SUMPRODUCT($AB$25:$AB$56,$AA$25:$AA$56) -> 0 | W33: =IF($I$12="","",V33/$I$12) -> 0 | X33: =IF(AB33<>"",IF(D33<>"",D33,($I$8-SUM($X$25:X32))*AA33*AB33/SUMPRODUCT($AB33:$AB$56,$AA33:$AA$56)),"") -> 28856 | Y33: =IF(AB33<>"",IF(E33<>"",E33,($I$9-SUM($Y$25:Y32))*AA33*AB33/SUMPRODUCT($AB33:$AB$56,$AA33:$AA$56)),"") -> 2 | Z33: =IF(AB33<>"",IF($I$12<>"",IF(G33<>"",G33,($I$9/$I$12-SUM($Z$25:Z32))*AA33*AB33/SUMPRODUCT($AB33:$AB$56,$AA33:$AA$56)),""),"") -> 1 | AA33: 1 | AB33: 1
A34: 10 | B34: 46050 | C34: ср | D34: =22501-28856 -> -6355 | E34: 3 | F34: =IF(AND(E34<>"",E34<>0),D34/E34,"") -> -2118.3333 | G34: 1 | H34: =IF(AND(G34<>"",G34<>0),D34/G34,"") -> -6355 | I34: 27 | J34: =IF(AND(G34<>"",G34<>0),E34/G34,"") -> 3 | S34: =IF(AND(I34<>"",I34<>0),G34/I34,"") -> 0.037037037 | T34: =D34/U34 -> #DIV/0! | U34: =$I$8*AA34*AB34/SUMPRODUCT($AB$25:$AB$56,$AA$25:$AA$56) -> 0 | V34: =$I$9*AA34*AB34/SUMPRODUCT($AB$25:$AB$56,$AA$25:$AA$56) -> 0 | W34: =IF($I$12="","",V34/$I$12) -> 0 | X34: =IF(AB34<>"",IF(D34<>"",D34,($I$8-SUM($X$25:X33))*AA34*AB34/SUMPRODUCT($AB34:$AB$56,$AA34:$AA$56)),"") -> -6355 | Y34: =IF(AB34<>"",IF(E34<>"",E34,($I$9-SUM($Y$25:Y33))*AA34*AB34/SUMPRODUCT($AB34:$AB$56,$AA34:$AA$56)),"") -> 3 | Z34: =IF(AB34<>"",IF($I$12<>"",IF(G34<>"",G34,($I$9/$I$12-SUM($Z$25:Z33))*AA34*AB34/SUMPRODUCT($AB34:$AB$56,$AA34:$AA$56)),""),"") -> 1 | AA34: 1 | AB34: 1
A35: 11 | B35: 29.янв. | C35: чт | F35: =IF(AND(E35<>"",E35<>0),D35/E35,"") | H35: =IF(AND(G35<>"",G35<>0),D35/G35,"") | J35: =IF(AND(G35<>"",G35<>0),E35/G35,"") | S35: =IF(AND(I35<>"",I35<>0),G35/I35,"") | T35: =D35/U35 -> #DIV/0! | U35: =$I$8*AA35*AB35/SUMPRODUCT($AB$25:$AB$56,$AA$25:$AA$56) -> 0 | V35: =$I$9*AA35*AB35/SUMPRODUCT($AB$25:$AB$56,$AA$25:$AA$56) -> 0 | W35: =IF($I$12="","",V35/$I$12) -> 0 | X35: =IF(AB35<>"",IF(D35<>"",D35,($I$8-SUM($X$25:X34))*AA35*AB35/SUMPRODUCT($AB35:$AB$56,$AA35:$AA$56)),"") -> -73114.5 | Y35: =IF(AB35<>"",IF(E35<>"",E35,($I$9-SUM($Y$25:Y34))*AA35*AB35/SUMPRODUCT($AB35:$AB$56,$AA35:$AA$56)),"") -> -9.5 | Z35: =IF(AB35<>"",IF($I$12<>"",IF(G35<>"",G35,($I$9/$I$12-SUM($Z$25:Z34))*AA35*AB35/SUMPRODUCT($AB35:$AB$56,$AA35:$AA$56)),""),"") -> -3.5 | AA35: 1 | AB35: 1
A36: 12 | B36: 46052 | C36: пт | F36: =IF(AND(E36<>"",E36<>0),D36/E36,"") | H36: =IF(AND(G36<>"",G36<>0),D36/G36,"") | J36: =IF(AND(G36<>"",G36<>0),E36/G36,"") | S36: =IF(AND(I36<>"",I36<>0),G36/I36,"") | T36: =D36/U36 -> #DIV/0! | U36: =$I$8*AA36*AB36/SUMPRODUCT($AB$25:$AB$56,$AA$25:$AA$56) -> 0 | V36: =$I$9*AA36*AB36/SUMPRODUCT($AB$25:$AB$56,$AA$25:$AA$56) -> 0 | W36: =IF($I$12="","",V36/$I$12) -> 0 | X36: =IF(AB36<>"",IF(D36<>"",D36,($I$8-SUM($X$25:X35))*AA36*AB36/SUMPRODUCT($AB36:$AB$56,$AA36:$AA$56)),"") -> -73114.5 | Y36: =IF(AB36<>"",IF(E36<>"",E36,($I$9-SUM($Y$25:Y35))*AA36*AB36/SUMPRODUCT($AB36:$AB$56,$AA36:$AA$56)),"") -> -9.5 | Z36: =IF(AB36<>"",IF($I$12<>"",IF(G36<>"",G36,($I$9/$I$12-SUM($Z$25:Z35))*AA36*AB36/SUMPRODUCT($AB36:$AB$56,$AA36:$AA$56)),""),"") -> -3.5 | AA36: 1 | AB36: 1
A37: 13 | B37: 46053 | C37: сб | D37: 19004 | F37: =IF(AND(E37<>"",E37<>0),D37/E37,"") | H37: =IF(AND(G37<>"",G37<>0),D37/G37,"") | J37: =IF(AND(G37<>"",G37<>0),E37/G37,"") | L37: 220 | M37: 10892 | S37: =IF(AND(I37<>"",I37<>0),G37/I37,"") | T37: =D37/U37 -> #DIV/0! | U37: =$I$8*AA37*AB37/SUMPRODUCT($AB$25:$AB$56,$AA$25:$AA$56) -> 0 | V37: =$I$9*AA37*AB37/SUMPRODUCT($AB$25:$AB$56,$AA$25:$AA$56) -> 0 | W37: =IF($I$12="","",V37/$I$12) -> 0 | X37: =IF(AB37<>"",IF(D37<>"",D37,($I$8-SUM($X$25:X36))*AA37*AB37/SUMPRODUCT($AB37:$AB$56,$AA37:$AA$56)),"") | Y37: =IF(AB37<>"",IF(E37<>"",E37,($I$9-SUM($Y$25:Y36))*AA37*AB37/SUMPRODUCT($AB37:$AB$56,$AA37:$AA$56)),"") | Z37: =IF(AB37<>"",IF($I$12<>"",IF(G37<>"",G37,($I$9/$I$12-SUM($Z$25:Z36))*AA37*AB37/SUMPRODUCT($AB37:$AB$56,$AA37:$AA$56)),""),"")
F38: =IF(AND(E38<>"",E38<>0),D38/E38,"") | H38: =IF(AND(G38<>"",G38<>0),D38/G38,"") | J38: =IF(AND(G38<>"",G38<>0),E38/G38,"") | S38: =IF(AND(I38<>"",I38<>0),G38/I38,"") | T38: =D38/U38 -> #DIV/0! | U38: =$I$8*AA38*AB38/SUMPRODUCT($AB$25:$AB$46,$AA$25:$AA$46) -> 0 | V38: =$I$9*AA38*AB38/SUMPRODUCT($AB$25:$AB$46,$AA$25:$AA$46) -> 0 | W38: =IF($I$12="","",V38/$I$12) -> 0 | X38: =IF(AB38<>"",IF(D38<>"",D38,($I$8-SUM($X$25:X37))*AA38*AB38/SUMPRODUCT($AB38:$AB$56,$AA38:$AA$56)),"") | Y38: =IF(AB38<>"",IF(E38<>"",E38,($I$9-SUM($Y$25:Y37))*AA38*AB38/SUMPRODUCT($AB38:$AB$56,$AA38:$AA$56)),"") | Z38: =IF(AB38<>"",IF($I$12<>"",IF(G38<>"",G38,($I$9/$I$12-SUM($Z$25:Z37))*AA38*AB38/SUMPRODUCT($AB38:$AB$56,$AA38:$AA$56)),""),"")
F39: =IF(AND(E39<>"",E39<>0),D39/E39,"") | H39: =IF(AND(G39<>"",G39<>0),D39/G39,"") | J39: =IF(AND(G39<>"",G39<>0),E39/G39,"") | S39: =IF(AND(I39<>"",I39<>0),G39/I39,"") | T39: =D39/U39 -> #DIV/0! | U39: =$I$8*AA39*AB39/SUMPRODUCT($AB$25:$AB$46,$AA$25:$AA$46) -> 0 | V39: =$I$9*AA39*AB39/SUMPRODUCT($AB$25:$AB$46,$AA$25:$AA$46) -> 0 | W39: =IF($I$12="","",V39/$I$12) -> 0 | X39: =IF(AB39<>"",IF(D39<>"",D39,($I$8-SUM($X$25:X38))*AA39*AB39/SUMPRODUCT($AB39:$AB$56,$AA39:$AA$56)),"") | Y39: =IF(AB39<>"",IF(E39<>"",E39,($I$9-SUM($Y$25:Y38))*AA39*AB39/SUMPRODUCT($AB39:$AB$56,$AA39:$AA$56)),"") | Z39: =IF(AB39<>"",IF($I$12<>"",IF(G39<>"",G39,($I$9/$I$12-SUM($Z$25:Z38))*AA39*AB39/SUMPRODUCT($AB39:$AB$56,$AA39:$AA$56)),""),"")
F40: =IF(AND(E40<>"",E40<>0),D40/E40,"") | H40: =IF(AND(G40<>"",G40<>0),D40/G40,"") | J40: =IF(AND(G40<>"",G40<>0),E40/G40,"") | S40: =IF(AND(I40<>"",I40<>0),G40/I40,"") | T40: =D40/U40 -> #DIV/0! | U40: =$I$8*AA40*AB40/SUMPRODUCT($AB$25:$AB$46,$AA$25:$AA$46) -> 0 | V40: =$I$9*AA40*AB40/SUMPRODUCT($AB$25:$AB$46,$AA$25:$AA$46) -> 0 | W40: =IF($I$12="","",V40/$I$12) -> 0 | X40: =IF(AB40<>"",IF(D40<>"",D40,($I$8-SUM($X$25:X39))*AA40*AB40/SUMPRODUCT($AB40:$AB$56,$AA40:$AA$56)),"") | Y40: =IF(AB40<>"",IF(E40<>"",E40,($I$9-SUM($Y$25:Y39))*AA40*AB40/SUMPRODUCT($AB40:$AB$56,$AA40:$AA$56)),"") | Z40: =IF(AB40<>"",IF($I$12<>"",IF(G40<>"",G40,($I$9/$I$12-SUM($Z$25:Z39))*AA40*AB40/SUMPRODUCT($AB40:$AB$56,$AA40:$AA$56)),""),"")
F41: =IF(AND(E41<>"",E41<>0),D41/E41,"") | H41: =IF(AND(G41<>"",G41<>0),D41/G41,"") | J41: =IF(AND(G41<>"",G41<>0),E41/G41,"") | S41: =IF(AND(I41<>"",I41<>0),G41/I41,"") | T41: =D41/U41 -> #DIV/0! | U41: =$I$8*AA41*AB41/SUMPRODUCT($AB$25:$AB$46,$AA$25:$AA$46) -> 0 | V41: =$I$9*AA41*AB41/SUMPRODUCT($AB$25:$AB$46,$AA$25:$AA$46) -> 0 | W41: =IF($I$12="","",V41/$I$12) -> 0 | X41: =IF(AB41<>"",IF(D41<>"",D41,($I$8-SUM($X$25:X40))*AA41*AB41/SUMPRODUCT($AB41:$AB$56,$AA41:$AA$56)),"") | Y41: =IF(AB41<>"",IF(E41<>"",E41,($I$9-SUM($Y$25:Y40))*AA41*AB41/SUMPRODUCT($AB41:$AB$56,$AA41:$AA$56)),"") | Z41: =IF(AB41<>"",IF($I$12<>"",IF(G41<>"",G41,($I$9/$I$12-SUM($Z$25:Z40))*AA41*AB41/SUMPRODUCT($AB41:$AB$56,$AA41:$AA$56)),""),"")
F42: =IF(AND(E42<>"",E42<>0),D42/E42,"") | H42: =IF(AND(G42<>"",G42<>0),D42/G42,"") | J42: =IF(AND(G42<>"",G42<>0),E42/G42,"") | S42: =IF(AND(I42<>"",I42<>0),G42/I42,"") | T42: =D42/U42 -> #DIV/0! | U42: =$I$8*AA42*AB42/SUMPRODUCT($AB$25:$AB$46,$AA$25:$AA$46) -> 0 | V42: =$I$9*AA42*AB42/SUMPRODUCT($AB$25:$AB$46,$AA$25:$AA$46) -> 0 | W42: =IF($I$12="","",V42/$I$12) -> 0 | X42: =IF(AB42<>"",IF(D42<>"",D42,($I$8-SUM($X$25:X41))*AA42*AB42/SUMPRODUCT($AB42:$AB$56,$AA42:$AA$56)),"") | Y42: =IF(AB42<>"",IF(E42<>"",E42,($I$9-SUM($Y$25:Y41))*AA42*AB42/SUMPRODUCT($AB42:$AB$56,$AA42:$AA$56)),"") | Z42: =IF(AB42<>"",IF($I$12<>"",IF(G42<>"",G42,($I$9/$I$12-SUM($Z$25:Z41))*AA42*AB42/SUMPRODUCT($AB42:$AB$56,$AA42:$AA$56)),""),"")
...

Sheet Козлова В. Э.
B1: =TODAY()-1 -> 46170
B2: (отчетная дата) | J2: ЕЖЕДНЕВНЫЙ ОТЧЕТ О ПРОДАЖАХ
B3: Осталось до выполнения плана!!! | J3: =График!B26 -> Козлова Валерия
C4: =I8-D49 -> 361915.39 | E4: =IF(I8<>0,C4/I8,0) -> 0.57929971
F6: Целевые показатели
F7: Показатель | I7: План | J7: Факт | K7: % выполнения | L7: Прогноз выполнения | M7: % выполнения по прогнозу | N7: Отклонение | O7: Факт аналогичного месяца прошлого года | P7: Отклонение LFL
F8: Выручка | I8: =Центрум!I8/График!AJ29*График!AJ26 -> 624746.37 | J8: =D49 -> 262830.98 | K8: =IF(AND(I8<>"",I8<>0,J8<>""),J8/I8,"") -> 0.42070029 | L8: =IF(SUMIF($D$25:$D$47,">=0",$U$25:$U$47)<>0,I8*D49/SUMIF($D$25:$D$47,">=0",$U$25:$U$47),0) -> 312111.79 | M8: =L8/I8 -> 0.4995816 | N8: =IF(AND(J8<>0,J8<>"",I8<>0,I8<>""),L8-I8,"") -> -312634.58 | P8: =IF(AND(O8<>"",O8<>0,L8<>"",L8<>0),-O8+L8,"") | Q8: =IF(AND(P8<>"",P8<>0,O8<>0,O8<>""),P8/O8,"")
F9: Кол-во изделий | I9: =I8/I11 -> 94.658541 | J9: =E49 -> 45 | K9: =IF(AND(I9<>"",I9<>0,J9<>""),J9/I9,"") -> 0.47539292 | L9: =IF(SUMIF($E$25:$E$47,">=0",$V$25:$V$47)<>0,I9*E49/SUMIF($E$25:$E$47,">=0",$V$25:$V$47),0) -> 53.4375 | M9: =IF(AND(I9<>"",I9<>0,L9<>"",L9<>0),L9/I9,"") -> 0.56452909 | N9: =IF(AND(J9<>0,J9<>"",I9<>0,I9<>""),L9-I9,"") -> -41.221041 | O9: =O8/O11 -> #DIV/0! | P9: =IF(AND(O9<>"",O9<>0,L9<>"",L9<>0),-O9+L9,"") -> #DIV/0! | Q9: =IF(AND(P9<>"",P9<>0,O9<>0,O9<>""),P9/O9,"") -> #DIV/0!
F10: Средний чек | I10: =I11*I12 -> 11220 | J10: =H49 -> 10108.884 | K10: =IF(AND(I10<>"",I10<>0,J10<>""),J10/I10,"") -> 0.90097004 | L10: =J10 -> 10108.884 | M10: =IF(AND(I10<>"",I10<>0,L10<>"",L10<>0),L10/I10,"") -> 0.90097004 | N10: =IF(AND(J10<>0,J10<>"",I10<>0,I10<>""),L10-I10,"") -> -1111.1162 | O10: =O11*O12 -> 0 | P10: =IF(AND(O10<>"",O10<>0,L10<>"",L10<>0),-O10+L10,"") | Q10: =IF(AND(P10<>"",P10<>0,O10<>0,O10<>""),P10/O10,"")
F11: Средняя стоимость изделия | I11: =Центрум!I11 -> 6600 | J11: =F49 -> 5840.6884 | K11: =IF(AND(I11<>"",I11<>0,J11<>""),J11/I11,"") -> 0.88495279 | L11: =J11 -> 5840.6884 | M11: =IF(AND(I11<>"",I11<>0,L11<>"",L11<>0),L11/I11,"") -> 0.88495279 | N11: =IF(AND(J11<>0,J11<>"",I11<>0,I11<>""),L11-I11,"") -> -759.31156 | P11: =IF(AND(O11<>"",O11<>0,L11<>"",L11<>0),-O11+L11,"") | Q11: =IF(AND(P11<>"",P11<>0,O11<>0,O11<>""),P11/O11,"")
F12: Длина чека | I12: ='Центрум'!I12 -> 1.7 | J12: =J49 -> 1.7307692 | K12: =IF(AND(I12<>"",I12<>0,J12<>""),J12/I12,"") -> 1.0180995 | L12: =J12 -> 1.7307692 | M12: =IF(AND(I12<>"",I12<>0,L12<>"",L12<>0),L12/I12,"") -> 1.0180995 | N12: =IF(AND(J12<>0,J12<>"",I12<>0,I12<>""),L12-I12,"") -> 0.030769231 | P12: =IF(AND(O12<>"",O12<>0,L12<>"",L12<>0),-O12+L12,"") | Q12: =IF(AND(P12<>"",P12<>0,O12<>0,O12<>""),P12/O12,"")
F13: Кол-во чеков | I13: =IF(I12<>0,I9/I12,"") -> 55.681495 | J13: =G49 -> 26 | K13: =IF(AND(I13<>"",I13<>0,J13<>""),J13/I13,"") -> 0.46694149 | L13: =IF(SUMIF($G$25:$G$47,">=0",$W$25:$W$47)<>0,I13*G49/SUMIF($G$25:$G$47,">=0",$W$25:$W$47),"") -> 30.875 | M13: =IF(AND(I13<>"",I13<>0,L13<>"",L13<>0),L13/I13,"") -> 0.55449302 | N13: =IF(AND(J13<>0,J13<>"",I13<>0,I13<>""),L13-I13,"") -> -24.806495 | P13: =IF(AND(O13<>"",O13<>0,L13<>"",L13<>0),-O13+L13,"") | Q13: =IF(AND(P13<>"",P13<>0,O13<>0,O13<>""),P13/O13,"")
F14: Кол-во смен план/отработано | I14: =График!AI26 -> 19 | J14: 19 | K14: =IF(AND(I14<>"",I14<>0,J14<>""),J14/I14,"") -> 1 | L14: =IF(SUMIF($D$25:$D$47,">=0",$U$25:$U$47),I49*I8/SUMIF($D$25:$D$47,">=0",$U$25:$U$47),"") -> 404.7 | N14: =IF(AND(J14<>0,J14<>"",I14<>0,I14<>""),L14-I14,"") -> 385.7 | P14: =IF(AND(O14<>"",O14<>0,L14<>"",L14<>0),-O14+L14,"") | Q14: =IF(AND(P14<>"",P14<>0,O14<>0,O14<>""),P14/O14,"")
F15: Средние продажи в смену | I15: =Центрум!I15/2 -> 30945.484 | J15: =J8/J14 -> 13833.209 | K15: =IF(AND(I15<>"",I15<>0,J15<>""),J15/I15,"") -> 0.44701868 | L15: =J15 -> 13833.209 | M15: =IF(AND(I15<>"",I15<>0,L15<>"",L15<>0),L15/I15,"") -> 0.44701868 | N15: =IF(AND(J15<>0,J15<>"",I15<>0,I15<>""),L15-I15,"") -> -17112.274 | P15: =IF(AND(O15<>"",O15<>0,L15<>"",L15<>0),-O15+L15,"") | Q15: =IF(AND(P15<>"",P15<>0,O15<>0,O15<>""),P15/O15,"")
F16: Отставание/Перевыполнение | J16: =J8-I15*J14 -> -325133.21 | K16: =IF(AND(I16<>"",I16<>0,J16<>""),J16/I16,"") | L16: =J16 -> -325133.21 | M16: =IF(AND(I16<>"",I16<>0,L16<>"",L16<>0),L16/I16,"") | N16: =IF(AND(J16<>0,J16<>"",I16<>0,I16<>""),L16-I16,"") | P16: =IF(AND(O16<>"",O16<>0,L16<>"",L16<>0),-O16+L16,"") | Q16: =IF(AND(P16<>"",P16<>0,O16<>0,O16<>""),P16/O16,"") | T16: Подарочные сертификаты
F17: Трафик | I17: =Центрум!I17/График!AJ29*График!AJ26 -> 618.68327 | J17: =I49 -> 340.8 | K17: =IF(AND(I17<>"",I17<>0,J17<>""),J17/I17,"") -> 0.55084728 | L17: =J17/J14*I14 -> 340.8 | M17: =IF(AND(I17<>"",I17<>0,L17<>"",L17<>0),L17/I17,"") -> 0.55084728 | N17: =IF(AND(J17<>0,J17<>"",I17<>0,I17<>""),L17-I17,"") -> -277.88327 | P17: =IF(AND(O17<>"",O17<>0,L17<>"",L17<>0),-O17+L17,"") | Q17: =IF(AND(P17<>"",P17<>0,O17<>0,O17<>""),P17/O17,"")
K18: =IF(AND(I18<>"",I18<>0,J18<>""),J18/I18,"") | L18: =J18 -> 0 | M18: =IF(AND(I18<>"",I18<>0,L18<>"",L18<>0),L18/I18,"") | N18: =IF(AND(J18<>0,J18<>"",I18<>0,I18<>""),L18-I18,"") | O18: 0 | P18: =IF(AND(O18<>"",O18<>0,L18<>"",L18<>0),-O18+L18,"") | Q18: =IF(AND(P18<>"",P18<>0,O18<>0,O18<>""),P18/O18,"")
J19: =P49 -> 0 | K19: =IF(AND(I19<>"",I19<>0,J19<>""),J19/I19,"") | L19: =J19 -> 0 | M19: =IF(AND(I19<>"",I19<>0,L19<>"",L19<>0),L19/I19,"") | N19: =IF(AND(J19<>0,J19<>"",I19<>0,I19<>""),L19-I19,"") | O19: 0 | P19: =IF(AND(O19<>"",O19<>0,L19<>"",L19<>0),-O19+L19,"") | Q19: =IF(AND(P19<>"",P19<>0,O19<>0,O19<>""),P19/O19,"") | T19: =T18/I16 -> #DIV/0!
F20: Конверсия план/факт | I20: =Центрум!I20 -> 0.09 | J20: =S49 -> 0.07629108 | K20: =J20/I20 -> 0.84767866 | L20: =IF(AND(K8<>0,I14<>0,I49<>0),(I49*S49+(I49/K8-I49)*I20)/(I49/K8),0) -> 0.084232653 | M20: =IF(AND(I20<>"",I20<>0,L20<>"",L20<>0),L20/I20,"") -> 0.93591837 | N20: =IF(AND(J20<>0,J20<>"",I20<>0,I20<>""),L20-I20,"") -> -0.0057673467 | P20: =IF(AND(O20<>"",O20<>0,L20<>"",L20<>0),-O20+L20,"") | Q20: =IF(AND(P20<>"",P20<>0,O20<>0,O20<>""),P20/O20,"")
B22: Факт продаж за месяц | T22: % выполнения дневного плана | U22: Раcпределение плана по дням
B23: Дата | C23: День недели | D23: Выручка (руб) | E23: Кол-во единиц (шт.) | F23: Средняя стоимость изделия (руб.) | G23: Количество чеков (шт.) | H23: Средняя сумма чека (руб.) | I23: Трафик | J23: Длина чека (шт.) | K23: UNOde50 | L23: IS | M23: Agafi | N23: Kalliope | O23: Raganella | P23: CC/MP | Q23: Eva Rites | R23: Antura | S23: Конверсия (%) | U23: выручка, план | V23: кол-во ед, план | W23: Кол-во чеков, план | X23: выручка, скорректир.план | Y23: кол-во ед, скорр. план | Z23: кол-во чеков, скорр. план | AA23: Коэфф. Дня Недели | AB23: Специфика месяца
B24: 1 | C24: 2 | D24: 3 | E24: в | F24: 5 | G24: 6 | H24: 7 | I24: 8 | J24: 9 | K24: 10 | L24: 11 | M24: 12 | N24: 13 | O24: 14 | P24: 15 | Q24: 16 | R24: 17 | S24: 18 | U24: 1 | V24: 2 | W24: 3 | X24: 4 | Y24: 5 | Z24: 6 | AA24: 10 | AB24: 11
A25: 1 | B25: 46024 | C25: пт | D25: 0 | E25: 0 | F25: =IF(AND(E25<>"",E25<>0),D25/E25,"") | G25: 0 | H25: =IF(AND(G25<>"",G25<>0),D25/G25,"") | I25: 25 | J25: =IF(AND(G25<>"",G25<>0),E25/G25,"") | S25: =IF(AND(I25<>"",I25<>0),G25/I25,"") -> 0 | T25: =D25/U25 -> #REF! | U25: =$I$8*AA25*AB25/SUMPRODUCT($AA$25:$AA$55,$Z$25:$Z$55) -> #REF! | V25: =$I$9*AA25*AB25/SUMPRODUCT($AA$25:$AA$55,$Z$25:$Z$55) -> #REF! | W25: =IF($I$12="","",V25/$I$12) -> #REF! | X25: =IF(AB25<>"",IF(E25<>"",E25,($I$8-SUM($W24:X$25))*AA25*AB25/SUMPRODUCT($AA25:$AA$48,$Z25:$Z$48)),"") -> 0 | Y25: =IF(AB25<>"",IF(F25<>"",F25,($I$9-SUM($X24:Y$25))*AA25*AB25/SUMPRODUCT($AA25:$AA$55,$Z25:$Z$55)),"") -> #REF! | Z25: =IF(AB25<>"",IF($I$12<>"",IF(H25<>"",H25,($I$9/$I$12-SUM($Y24:Z$25))*AA25*AB25/SUMPRODUCT($AA25:$AA$55,$Z25:$Z$55)),""),"") -> #REF! | AA25: 1 | AB25: 1
