Workbook
Name маг: NA()

Sheet Центрум
B1: =TODAY()-1 -> 46031
B2: (отчетная дата) | J2: ЕЖЕДНЕВНЫЙ ОТЧЕТ О ПРОДАЖАХ
C3: Осталось до выполнения плана!!! | I3: ТРК Центрум
C4: =I8-D56 -> 3005284.9 | E4: =IF(I8<>0,C4/I8,0) -> 0.49327017
F6: Целевые показатели
F7: Показатель | I7: План | J7: Факт | K7: % выполнения | L7: Прогноз выполнения | M7: % выполнения по прогнозу | N7: Отклонение | O7: Факт аналогичного месяца прошлого года | P7: Отклонение LFL
F8: Выручка | I8: =I13*I10 -> 6092573.8 | J8: =D56 -> 3087288.9 | K8: =IF(AND(I8<>"",I8<>0,J8<>""),J8/I8,"") -> 0.50672983 | L8: =IF(SUMIF($D$25:$D$55,">=0",$T$25:$T$55)<>0,I8*D56/SUMIF($D$25:$D$55,">=0",$T$25:$T$55),0) -> 3087288.9 | M8: =L8/I8 -> 0.50672983 | N8: =IF(AND(J8<>0,J8<>"",I8<>0,I8<>""),L8-I8,"") -> -3005284.9 | O8: 343307.22 | P8: =IF(AND(O8<>"",O8<>0,L8<>"",L8<>0),-O8+L8,"") -> 2743981.7 | R8: =IF(AND(P8<>"",P8<>0,O8<>0,O8<>""),P8/O8,"") -> 7.9927875
F9: Кол-во изделий | I9: =I8/I11 -> 743.904 | J9: =E56 -> 398 | K9: =IF(AND(I9<>"",I9<>0,J9<>""),J9/I9,"") -> 0.53501527 | L9: =IF(SUMIF($E$25:$E$55,">=0",$U$25:$U$55)<>0,I9*E56/SUMIF($E$25:$E$55,">=0",$U$25:$U$55),0) -> 398 | M9: =IF(AND(I9<>"",I9<>0,L9<>"",L9<>0),L9/I9,"") -> 0.53501527 | N9: =IF(AND(J9<>0,J9<>"",I9<>0,I9<>""),L9-I9,"") -> -345.904 | O9: 104 | P9: =IF(AND(O9<>"",O9<>0,L9<>"",L9<>0),-O9+L9,"") -> 294 | R9: =IF(AND(P9<>"",P9<>0,O9<>0,O9<>""),P9/O9,"") -> 2.8269231
F10: Средний чек | I10: =I11*I12 -> 13759.2 | J10: =H56 -> 12251.146 | K10: =IF(AND(I10<>"",I10<>0,J10<>""),J10/I10,"") -> 0.89039671 | L10: =J10 -> 12251.146 | M10: =IF(AND(I10<>"",I10<>0,L10<>"",L10<>0),L10/I10,"") -> 0.89039671 | N10: =IF(AND(J10<>0,J10<>"",I10<>0,I10<>""),L10-I10,"") -> -1508.0536 | O10: 4702.8386 | P10: =IF(AND(O10<>"",O10<>0,L10<>"",L10<>0),-O10+L10,"") -> 7548.3078 | R10: =IF(AND(P10<>"",P10<>0,O10<>0,O10<>""),P10/O10,"") -> 1.6050535
F11: Средняя стоимость изделия | I11: 8190 | J11: =F56 -> 7757.0073 | K11: =IF(AND(I11<>"",I11<>0,J11<>""),J11/I11,"") -> 0.94713153 | L11: =IF(L9>0,L8/L9,"") -> 7757.0073 | M11: =IF(AND(I11<>"",I11<>0,L11<>"",L11<>0),L11/I11,"") -> 0.94713153 | N11: =IF(AND(J11<>0,J11<>"",I11<>0,I11<>""),L11-I11,"") -> -432.99274 | O11: 3301.031 | P11: =IF(AND(O11<>"",O11<>0,L11<>"",L11<>0),-O11+L11,"") -> 4455.9763 | R11: =IF(AND(P11<>"",P11<>0,O11<>0,O11<>""),P11/O11,"") -> 1.3498741
F12: Длина чека | I12: 1.68 | J12: =J56 -> 1.5793651 | K12: =IF(AND(I12<>"",I12<>0,J12<>""),J12/I12,"") -> 0.94009826 | L12: =J12 -> 1.5793651 | M12: =IF(AND(I12<>"",I12<>0,L12<>"",L12<>0),L12/I12,"") -> 0.94009826 | N12: =IF(AND(J12<>0,J12<>"",I12<>0,I12<>""),L12-I12,"") -> -0.10063492 | O12: 1.4246575 | P12: =IF(AND(O12<>"",O12<>0,L12<>"",L12<>0),-O12+L12,"") -> 0.15470755 | R12: =IF(AND(P12<>"",P12<>0,O12<>0,O12<>""),P12/O12,"") -> 0.1085928
F13: Кол-во чеков | I13: =I17*I20 -> 442.8 | J13: =G56 -> 252 | K13: =IF(AND(I13<>"",I13<>0,J13<>""),J13/I13,"") -> 0.56910569 | L13: =IF(SUMIF($G$25:$G$55,">=0",$V$25:$V$55)<>0,I13*G56/SUMIF($G$25:$G$55,">=0",$V$25:$V$55),"") -> 252 | M13: =IF(AND(I13<>"",I13<>0,L13<>"",L13<>0),L13/I13,"") -> 0.56910569 | N13: =IF(AND(J13<>0,J13<>"",I13<>0,I13<>""),L13-I13,"") -> -190.8 | O13: 73 | P13: =IF(AND(O13<>"",O13<>0,L13<>"",L13<>0),-O13+L13,"") -> 179 | R13: =IF(AND(P13<>"",P13<>0,O13<>0,O13<>""),P13/O13,"") -> 2.4520548
F14: Кол-во смен | I14: 31 | J14: 31 | K14: =IF(AND(I14<>"",I14<>0,J14<>""),J14/I14,"") -> 1 | L14: =IF(SUMIF($D$25:$D$55,">=0",$T$25:$T$55),I56*I8/SUMIF($D$25:$D$55,">=0",$T$25:$T$55),"") -> 2859.3 | N14: =IF(AND(J14<>0,J14<>"",I14<>0,I14<>""),L14-I14,"") -> 2828.3 | O14: 31 | P14: =IF(AND(O14<>"",O14<>0,L14<>"",L14<>0),-O14+L14,"") -> 2828.3 | R14: =IF(AND(P14<>"",P14<>0,O14<>0,O14<>""),P14/O14,"") -> 91.235484
F15: Средние продажи в смену | I15: =I8/I14 -> 196534.64 | J15: =J8/J14 -> 99589.964 | K15: =IF(AND(I15<>"",I15<>0,J15<>""),J15/I15,"") -> 0.50672983 | L15: =J15 -> 99589.964 | M15: =IF(AND(I15<>"",I15<>0,L15<>"",L15<>0),L15/I15,"") -> 0.50672983 | N15: =IF(AND(J15<>0,J15<>"",I15<>0,I15<>""),L15-I15,"") -> -96944.673 | O15: 11074.426 | P15: =IF(AND(O15<>"",O15<>0,L15<>"",L15<>0),-O15+L15,"") -> 88515.538 | R15: =IF(AND(P15<>"",P15<>0,O15<>0,O15<>""),P15/O15,"") -> 7.9927875
F16: Отставание/Перевыполнение | J16: =J8-I15*J14 -> -3005284.9 | K16: =IF(AND(I16<>"",I16<>0,J16<>""),J16/I16,"") | L16: =J16 -> -3005284.9 | M16: =IF(AND(I16<>"",I16<>0,L16<>"",L16<>0),L16/I16,"") | N16: =IF(AND(J16<>0,J16<>"",I16<>0,I16<>""),L16-I16,"") | O16: -182714.47 | P16: =IF(AND(O16<>"",O16<>0,L16<>"",L16<>0),-O16+L16,"") -> -2822570.4 | R16: =IF(AND(P16<>"",P16<>0,O16<>0,O16<>""),P16/O16,"") -> 15.447985 | V16: Подарочные сертификаты
F17: Трафик | I17: 3600 | J17: =I56 -> 2859.3 | K17: =IF(AND(I17<>"",I17<>0,J17<>""),J17/I17,"") -> 0.79425 | L17: =J17/J14*I14 -> 2859.3 | M17: =IF(AND(I17<>"",I17<>0,L17<>"",L17<>0),L17/I17,"") -> 0.79425 | N17: =IF(AND(J17<>0,J17<>"",I17<>0,I17<>""),L17-I17,"") -> -740.7 | O17: 381 | P17: =IF(AND(O17<>"",O17<>0,L17<>"",L17<>0),-O17+L17,"") -> 2478.3 | R17: =IF(AND(P17<>"",P17<>0,O17<>0,O17<>""),P17/O17,"") -> 6.5047244
K18: =IF(AND(I18<>"",I18<>0,J18<>""),J18/I18,"") | L18: =J18 -> 0 | M18: =IF(AND(I18<>"",I18<>0,L18<>"",L18<>0),L18/I18,"") | N18: =IF(AND(J18<>0,J18<>"",I18<>0,I18<>""),L18-I18,"") | P18: =IF(AND(O18<>"",O18<>0,L18<>"",L18<>0),-O18+L18,"") | R18: =IF(AND(P18<>"",P18<>0,O18<>0,O18<>""),P18/O18,"")
K19: =IF(AND(I19<>"",I19<>0,J19<>""),J19/I19,"") | L19: =J19 -> 0 | M19: =IF(AND(I19<>"",I19<>0,L19<>"",L19<>0),L19/I19,"") | N19: =IF(AND(J19<>0,J19<>"",I19<>0,I19<>""),L19-I19,"") | O19: 0 | P19: =IF(AND(O19<>"",O19<>0,L19<>"",L19<>0),-O19+L19,"") | R19: =IF(AND(P19<>"",P19<>0,O19<>0,O19<>""),P19/O19,"") | V19: =V18/I16 -> #DIV/0!
F20: Конверсия | I20: 0.123 | J20: =R56 -> 0.088133459 | K20: =J20/I20 -> 0.71653219 | L20: =J20/I20 -> 0.71653219 | M20: =J20/I20 -> 0.71653219 | N20: =IF(AND(J20<>0,J20<>"",I20<>0,I20<>""),L20-I20,"") -> 0.59353219 | O20: 0.19160105 | P20: =IF(AND(O20<>"",O20<>0,L20<>"",L20<>0),-O20+L20,"") -> 0.52493114 | R20: =IF(AND(P20<>"",P20<>0,O20<>0,O20<>""),P20/O20,"") -> 2.7397091
A22: Факт продаж за месяц | T22: Раcпределение плана по дням
A23: Сотрудник | B23: Дата | C23: День недели | D23: Выручка (руб) | E23: Кол-во единиц (шт.) | F23: Средняя стоимость изделия (руб.) | G23: Количество чеков (шт.) | H23: Средняя сумма чека (руб.) | I23: Трафик | J23: Длина чека (шт.) | K23: UNOde50 | L23: IS | M23: Agafi | N23: Kalliope | O23: Raganella | P23: CC/MP | Q23: Eva Rites | R23: Конверсия (%) | S23: % выполнения дневного плана | T23: выручка, план | U23: кол-во ед, план | V23: Кол-во чеков, план | W23: выручка, скорректир.план | X23: кол-во ед, скорр. план | Y23: кол-во чеков, скорр. план | Z23: Коэфф. Дня Недели | AA23: Специфика месяца
B24: 1 | C24: 2 | D24: 3 | E24: 4 | F24: 5 | G24: 6 | H24: 7 | I24: 8 | J24: 9 | K24: 10 | L24: 11 | M24: 12 | N24: 13 | O24: 14 | P24: 15 | Q24: 16 | R24: 13 | T24: 1 | U24: 2 | V24: 3 | W24: 4 | X24: 5 | Y24: 6 | Z24: 10 | AA24: 11
A25: Рогалевич, Козлова | B25: 45992 | C25: пн | D25: 13572 | E25: 2 | F25: =IF(AND(E25<>"",E25<>0),D25/E25,"") -> 6786 | G25: 1 | H25: =IF(AND(G25<>"",G25<>0),D25/G25,"") -> 13572 | I25: 64 | J25: =IF(AND(G25<>"",G25<>0),E25/G25,"") -> 2 | R25: =IF(AND(I25<>"",I25<>0),G25/I25,"") -> 0.015625 | S25: =D25/T25 -> 0.07091956 | T25: =$I$8*Z25*AA25/SUMPRODUCT($AA$25:$AA$55,$Z$25:$Z$55) -> 191371.75 | U25: =$I$9*Z25*AA25/SUMPRODUCT($AA$25:$AA$55,$Z$25:$Z$55) -> 23.366514 | V25: =IF($I$12="","",U25/$I$12) -> 13.908639 | W25: =IF(D25<>"",D25,T25) -> 13572 | X25: =IF(E25<>"",E25,U25) -> 2 | Y25: =IF(G25<>"",G25,V25) -> 1 | Z25: 0.9414554 | AA25: 0.9414554
A26: Рогалевич,Свидовская, Стекольщикова | B26: 45993 | C26: вт | D26: 88382 | E26: 10 | F26: =IF(AND(E26<>"",E26<>0),D26/E26,"") -> 8838.2 | G26: 6 | H26: =IF(AND(G26<>"",G26<>0),D26/G26,"") -> 14730.333 | I26: 103 | J26: =IF(AND(G26<>"",G26<>0),E26/G26,"") -> 1.6666667 | K26: 30744 | M26: =17684 -> 17684 | P26: 8593 | R26: =IF(AND(I26<>"",I26<>0),G26/I26,"") -> 0.058252427 | S26: =D26/T26 -> 0.56244912 | T26: =$I$8*Z26*AA26/SUMPRODUCT($AA$25:$AA$55,$Z$25:$Z$55) -> 157137.77 | U26: =$I$9*Z26*AA26/SUMPRODUCT($AA$25:$AA$55,$Z$25:$Z$55) -> 19.186541 | V26: =IF($I$12="","",U26/$I$12) -> 11.42056 | W26: =IF(AA26<>"",IF(D26<>"",D26,($I$8-SUM($W$25:W25))*Z26*AA26/SUMPRODUCT($AA26:$AA$55,$Z26:$Z$55)),"") -> 88382 | X26: =IF(AA26<>"",IF(E26<>"",E26,($I$9-SUM($X$25:X25))*Z26*AA26/SUMPRODUCT($AA26:$AA$55,$Z26:$Z$55)),"") -> 10 | Y26: =IF(AA26<>"",IF($I$12<>"",IF(G26<>"",G26,($I$9/$I$12-SUM($Y$25:Y25))*Z26*AA26/SUMPRODUCT($AA26:$AA$55,$Z26:$Z$55)),""),"") -> 6 | Z26: 0.85310234 | AA26: 0.85310234
A27: Рогалевич, Стекольщикова, Свидовская, Корж | B27: 45994 | C27: ср | D27: 74261 | E27: 7 | F27: =IF(AND(E27<>"",E27<>0),D27/E27,"") -> 10608.714 | G27: 4 | H27: =IF(AND(G27<>"",G27<>0),D27/G27,"") -> 18565.25 | I27: 90 | J27: =IF(AND(G27<>"",G27<>0),E27/G27,"") -> 1.75 | M27: 15190 | N27: =27149+5307 -> 32456 | O27: 15390 | R27: =IF(AND(I27<>"",I27<>0),G27/I27,"") -> 0.044444444 | S27: =D27/T27 -> 0.4725853 | T27: =$I$8*Z27*AA27/SUMPRODUCT($AA$25:$AA$55,$Z$25:$Z$55) -> 157137.77 | U27: =$I$9*Z27*AA27/SUMPRODUCT($AA$25:$AA$55,$Z$25:$Z$55) -> 19.186541 | V27: =IF($I$12="","",U27/$I$12) -> 11.42056 | W27: =IF(AA27<>"",IF(D27<>"",D27,($I$8-SUM($W$25:W26))*Z27*AA27/SUMPRODUCT($AA27:$AA$55,$Z27:$Z$55)),"") -> 74261 | X27: =IF(AA27<>"",IF(E27<>"",E27,($I$9-SUM($X$25:X26))*Z27*AA27/SUMPRODUCT($AA27:$AA$55,$Z27:$Z$55)),"") -> 7 | Y27: =IF(AA27<>"",IF($I$12<>"",IF(G27<>"",G27,($I$9/$I$12-SUM($Y$25:Y26))*Z27*AA27/SUMPRODUCT($AA27:$AA$55,$Z27:$Z$55)),""),"") -> 4 | Z27: 0.85310234 | AA27: 0.85310234
A28: Рогалевич, Стекольщикова,Корж, Козлова | B28: 45995 | C28: чт | D28: 165232 | E28: 18 | F28: =IF(AND(E28<>"",E28<>0),D28/E28,"") -> 9179.5556 | G28: 13 | H28: =IF(AND(G28<>"",G28<>0),D28/G28,"") -> 12710.154 | I28: 87 | J28: =IF(AND(G28<>"",G28<>0),E28/G28,"") -> 1.3846154 | K28: =32375+11493 -> 43868 | M28: =8699+10892+14992 -> 34583 | N28: 21370 | R28: =IF(AND(I28<>"",I28<>0),G28/I28,"") -> 0.14942529 | S28: =D28/T28 -> 1.0515104 | T28: =$I$8*Z28*AA28/SUMPRODUCT($AA$25:$AA$55,$Z$25:$Z$55) -> 157137.77 | U28: =$I$9*Z28*AA28/SUMPRODUCT($AA$25:$AA$55,$Z$25:$Z$55) -> 19.186541 | V28: =IF($I$12="","",U28/$I$12) -> 11.42056 | W28: =IF(AA28<>"",IF(D28<>"",D28,($I$8-SUM($W$25:W27))*Z28*AA28/SUMPRODUCT($AA28:$AA$55,$Z28:$Z$55)),"") -> 165232 | X28: =IF(AA28<>"",IF(E28<>"",E28,($I$9-SUM($X$25:X27))*Z28*AA28/SUMPRODUCT($AA28:$AA$55,$Z28:$Z$55)),"") -> 18 | Y28: =IF(AA28<>"",IF($I$12<>"",IF(G28<>"",G28,($I$9/$I$12-SUM($Y$25:Y27))*Z28*AA28/SUMPRODUCT($AA28:$AA$55,$Z28:$Z$55)),""),"") -> 13 | Z28: 0.85310234 | AA28: 0.85310234
A29: Рогалевич, Стекольщикова, Козлова | B29: 45996 | C29: пт | D29: 77191 | E29: 11 | F29: =IF(AND(E29<>"",E29<>0),D29/E29,"") -> 7017.3636 | G29: 9 | H29: =IF(AND(G29<>"",G29<>0),D29/G29,"") -> 8576.7778 | I29: 117 | J29: =IF(AND(G29<>"",G29<>0),E29/G29,"") -> 1.2222222 | M29: =15922+7493 -> 23415 | N29: 13290 | R29: =IF(AND(I29<>"",I29<>0),G29/I29,"") -> 0.076923077 | S29: =D29/T29 -> 0.49482371 | T29: =$I$8*Z29*AA29/SUMPRODUCT($AA$25:$AA$55,$Z$25:$Z$55) -> 155996.97 | U29: =$I$9*Z29*AA29/SUMPRODUCT($AA$25:$AA$55,$Z$25:$Z$55) -> 19.047249 | V29: =IF($I$12="","",U29/$I$12) -> 11.337648 | W29: =IF(AA29<>"",IF(D29<>"",D29,($I$8-SUM($W$25:W28))*Z29*AA29/SUMPRODUCT($AA29:$AA$55,$Z29:$Z$55)),"") -> 77191 | X29: =IF(AA29<>"",IF(E29<>"",E29,($I$9-SUM($X$25:X28))*Z29*AA29/SUMPRODUCT($AA29:$AA$55,$Z29:$Z$55)),"") -> 11 | Y29: =IF(AA29<>"",IF($I$12<>"",IF(G29<>"",G29,($I$9/$I$12-SUM($Y$25:Y28))*Z29*AA29/SUMPRODUCT($AA29:$AA$55,$Z29:$Z$55)),""),"") -> 9 | Z29: 0.85 | AA29: 0.85
A30: Рогалевич, Стекольщикова, Козлова, свидовская | B30: 45997 | C30: сб | D30: 165526 | E30: 20 | F30: =IF(AND(E30<>"",E30<>0),D30/E30,"") -> 8276.3 | G30: 12 | H30: =IF(AND(G30<>"",G30<>0),D30/G30,"") -> 13793.833 | I30: 144 | J30: =IF(AND(G30<>"",G30<>0),E30/G30,"") -> 1.6666667 | K30: 18990 | M30: 8082 | O30: =13390+8990 -> 22380 | P30: 19680 | R30: =IF(AND(I30<>"",I30<>0),G30/I30,"") -> 0.083333333 | S30: =D30/T30 -> 0.76663369 | T30: =$I$8*Z30*AA30/SUMPRODUCT($AA$25:$AA$55,$Z$25:$Z$55) -> 215912.76 | U30: =$I$9*Z30*AA30/SUMPRODUCT($AA$25:$AA$55,$Z$25:$Z$55) -> 26.362975 | V30: =IF($I$12="","",U30/$I$12) -> 15.692247 | W30: =IF(AA30<>"",IF(D30<>"",D30,($I$8-SUM($W$25:W29))*Z30*AA30/SUMPRODUCT($AA30:$AA$55,$Z30:$Z$55)),"") -> 165526 | X30: =IF(AA30<>"",IF(E30<>"",E30,($I$9-SUM($X$25:X29))*Z30*AA30/SUMPRODUCT($AA30:$AA$55,$Z30:$Z$55)),"") -> 20 | Y30: =IF(AA30<>"",IF($I$12<>"",IF(G30<>"",G30,($I$9/$I$12-SUM($Y$25:Y29))*Z30*AA30/SUMPRODUCT($AA30:$AA$55,$Z30:$Z$55)),""),"") -> 12 | Z30: 1 | AA30: 1
A31: Рогалевич, Корж, Свидовская | B31: 45998 | C31: вс | D31: 72565 | E31: 10 | F31: =IF(AND(E31<>"",E31<>0),D31/E31,"") -> 7256.5 | G31: 7 | H31: =IF(AND(G31<>"",G31<>0),D31/G31,"") -> 10366.429 | I31: 108 | J31: =IF(AND(G31<>"",G31<>0),E31/G31,"") -> 1.4285714 | N31: =17272+24082 -> 41354 | R31: =IF(AND(I31<>"",I31<>0),G31/I31,"") -> 0.064814815 | S31: =D31/T31 -> 0.33608481 | T31: =$I$8*Z31*AA31/SUMPRODUCT($AA$25:$AA$55,$Z$25:$Z$55) -> 215912.76 | U31: =$I$9*Z31*AA31/SUMPRODUCT($AA$25:$AA$55,$Z$25:$Z$55) -> 26.362975 | V31: =IF($I$12="","",U31/$I$12) -> 15.692247 | W31: =IF(AA31<>"",IF(D31<>"",D31,($I$8-SUM($W$25:W30))*Z31*AA31/SUMPRODUCT($AA31:$AA$55,$Z31:$Z$55)),"") -> 72565 | X31: =IF(AA31<>"",IF(E31<>"",E31,($I$9-SUM($X$25:X30))*Z31*AA31/SUMPRODUCT($AA31:$AA$55,$Z31:$Z$55)),"") -> 10 | Y31: =IF(AA31<>"",IF($I$12<>"",IF(G31<>"",G31,($I$9/$I$12-SUM($Y$25:Y30))*Z31*AA31/SUMPRODUCT($AA31:$AA$55,$Z31:$Z$55)),""),"") -> 7 | Z31: 1 | AA31: 1
A32: Свидовская, Корж | B32: 45999 | C32: пн | D32: 35971 | E32: 7 | F32: =IF(AND(E32<>"",E32<>0),D32/E32,"") -> 5138.7143 | G32: 5 | H32: =IF(AND(G32<>"",G32<>0),D32/G32,"") -> 7194.2 | I32: 80 | J32: =IF(AND(G32<>"",G32<>0),E32/G32,"") -> 1.4 | O32: 5993 | R32: =IF(AND(I32<>"",I32<>0),G32/I32,"") -> 0.0625 | S32: =D32/T32 -> 0.22891378 | T32: =$I$8*Z32*AA32/SUMPRODUCT($AA$25:$AA$55,$Z$25:$Z$55) -> 157137.77 | U32: =$I$9*Z32*AA32/SUMPRODUCT($AA$25:$AA$55,$Z$25:$Z$55) -> 19.186541 | V32: =IF($I$12="","",U32/$I$12) -> 11.42056 | W32: =IF(AA32<>"",IF(D32<>"",D32,($I$8-SUM($W$25:W31))*Z32*AA32/SUMPRODUCT($AA32:$AA$55,$Z32:$Z$55)),"") -> 35971 | X32: =IF(AA32<>"",IF(E32<>"",E32,($I$9-SUM($X$25:X31))*Z32*AA32/SUMPRODUCT($AA32:$AA$55,$Z32:$Z$55)),"") -> 7 | Y32: =IF(AA32<>"",IF($I$12<>"",IF(G32<>"",G32,($I$9/$I$12-SUM($Y$25:Y31))*Z32*AA32/SUMPRODUCT($AA32:$AA$55,$Z32:$Z$55)),""),"") -> 5 | Z32: 0.85310234 | AA32: 0.85310234
A33: Стекольщикова, Свидовская, Козлова | B33: 46000 | C33: вт | D33: 95353 | E33: 10 | F33: =IF(AND(E33<>"",E33<>0),D33/E33,"") -> 9535.3 | G33: 4 | H33: =IF(AND(G33<>"",G33<>0),D33/G33,"") -> 23838.25 | I33: 68 | J33: =IF(AND(G33<>"",G33<>0),E33/G33,"") -> 2.5 | K33: 13990 | M33: 9782 | N33: 33744 | O33: 33446 | R33: =IF(AND(I33<>"",I33<>0),G33/I33,"") -> 0.058823529 | S33: =D33/T33 -> 0.60681147 | T33: =$I$8*Z33*AA33/SUMPRODUCT($AA$25:$AA$55,$Z$25:$Z$55) -> 157137.77 | U33: =$I$9*Z33*AA33/SUMPRODUCT($AA$25:$AA$55,$Z$25:$Z$55) -> 19.186541 | V33: =IF($I$12="","",U33/$I$12) -> 11.42056 | W33: =IF(AA33<>"",IF(D33<>"",D33,($I$8-SUM($W$25:W32))*Z33*AA33/SUMPRODUCT($AA33:$AA$55,$Z33:$Z$55)),"") -> 95353 | X33: =IF(AA33<>"",IF(E33<>"",E33,($I$9-SUM($X$25:X32))*Z33*AA33/SUMPRODUCT($AA33:$AA$55,$Z33:$Z$55)),"") -> 10 | Y33: =IF(AA33<>"",IF($I$12<>"",IF(G33<>"",G33,($I$9/$I$12-SUM($Y$25:Y32))*Z33*AA33/SUMPRODUCT($AA33:$AA$55,$Z33:$Z$55)),""),"") -> 4 | Z33: 0.85310234 | AA33: 0.85310234
A34: Стекольщикова, Козлова, Корж | B34: 46001 | C34: ср | D34: 31725 | E34: 5 | F34: =IF(AND(E34<>"",E34<>0),D34/E34,"") -> 6345 | G34: 4 | H34: =IF(AND(G34<>"",G34<>0),D34/G34,"") -> 7931.25 | I34: 81 | J34: =IF(AND(G34<>"",G34<>0),E34/G34,"") -> 1.25 | P34: 15084 | R34: =IF(AND(I34<>"",I34<>0),G34/I34,"") -> 0.049382716 | S34: =D34/T34 -> 0.37675472 | T34: =$I$8*Z34*AA34/SUMPRODUCT($AA$25:$AA$55,$Z$25:$Z$55) -> 84205.978 | U34: =$I$9*Z34*AA34/SUMPRODUCT($AA$25:$AA$55,$Z$25:$Z$55) -> 10.28156 | V34: =IF($I$12="","",U34/$I$12) -> 6.1199763 | W34: =IF(AA34<>"",IF(D34<>"",D34,($I$8-SUM($W$25:W33))*Z34*AA34/SUMPRODUCT($AA34:$AA$55,$Z34:$Z$55)),"") -> 31725 | X34: =IF(AA34<>"",IF(E34<>"",E34,($I$9-SUM($X$25:X33))*Z34*AA34/SUMPRODUCT($AA34:$AA$55,$Z34:$Z$55)),"") -> 5 | Y34: =IF(AA34<>"",IF($I$12<>"",IF(G34<>"",G34,($I$9/$I$12-SUM($Y$25:Y33))*Z34*AA34/SUMPRODUCT($AA34:$AA$55,$Z34:$Z$55)),""),"") -> 4 | Z34: 0.65 | AA34: 0.6
A35: Стекольщикова, Козлова, Корж | B35: 46002 | C35: чт | D35: 17930 | E35: 3 | F35: =IF(AND(E35<>"",E35<>0),D35/E35,"") -> 5976.6667 | G35: 2 | H35: =IF(AND(G35<>"",G35<>0),D35/G35,"") -> 8965 | I35: 84 | J35: =IF(AND(G35<>"",G35<>0),E35/G35,"") -> 1.5 | M35: 14437 | R35: =IF(AND(I35<>"",I35<>0),G35/I35,"") -> 0.023809524 | S35: =D35/T35 -> 0.15817676 | T35: =$I$8*Z35*AA35/SUMPRODUCT($AA$25:$AA$55,$Z$25:$Z$55) -> 113354.2 | U35: =$I$9*Z35*AA35/SUMPRODUCT($AA$25:$AA$55,$Z$25:$Z$55) -> 13.840562 | V35: =IF($I$12="","",U35/$I$12) -> 8.2384297 | W35: =IF(AA35<>"",IF(D35<>"",D35,($I$8-SUM($W$25:W34))*Z35*AA35/SUMPRODUCT($AA35:$AA$55,$Z35:$Z$55)),"") -> 17930 | X35: =IF(AA35<>"",IF(E35<>"",E35,($I$9-SUM($X$25:X34))*Z35*AA35/SUMPRODUCT($AA35:$AA$55,$Z35:$Z$55)),"") -> 3 | Y35: =IF(AA35<>"",IF($I$12<>"",IF(G35<>"",G35,($I$9/$I$12-SUM($Y$25:Y34))*Z35*AA35/SUMPRODUCT($AA35:$AA$55,$Z35:$Z$55)),""),"") -> 2 | Z35: 0.75 | AA35: 0.7
A36: Стекольщикова, Свидовская, Козлова | B36: 46003 | C36: пт | D36: 31850 | E36: 5 | F36: =IF(AND(E36<>"",E36<>0),D36/E36,"") -> 6370 | G36: 5 | H36: =IF(AND(G36<>"",G36<>0),D36/G36,"") -> 6370 | I36: 92 | J36: =IF(AND(G36<>"",G36<>0),E36/G36,"") -> 1 | N36: 4390 | R36: =IF(AND(I36<>"",I36<>0),G36/I36,"") -> 0.054347826 | S36: =D36/T36 -> 0.20417063 | T36: =$I$8*Z36*AA36/SUMPRODUCT($AA$25:$AA$55,$Z$25:$Z$55) -> 155996.97 | U36: =$I$9*Z36*AA36/SUMPRODUCT($AA$25:$AA$55,$Z$25:$Z$55) -> 19.047249 | V36: =IF($I$12="","",U36/$I$12) -> 11.337648 | W36: =IF(AA36<>"",IF(D36<>"",D36,($I$8-SUM($W$25:W35))*Z36*AA36/SUMPRODUCT($AA36:$AA$55,$Z36:$Z$55)),"") -> 31850 | X36: =IF(AA36<>"",IF(E35<>"",E35,($I$9-SUM($X$25:X35))*Z36*AA36/SUMPRODUCT($AA36:$AA$55,$Z36:$Z$55)),"") -> 3 | Y36: =IF(AA36<>"",IF($I$12<>"",IF(G36<>"",G36,($I$9/$I$12-SUM($Y$25:Y35))*Z36*AA36/SUMPRODUCT($AA36:$AA$55,$Z36:$Z$55)),""),"") -> 5 | Z36: 0.85 | AA36: 0.85
A37: Стекольщикова, Свидовская, Корж | B37: 46004 | C37: сб | D37: 144713 | E37: 24 | F37: =IF(AND(E37<>"",E37<>0),D37/E37,"") -> 6029.7083 | G37: 12 | H37: =IF(AND(G37<>"",G37<>0),D37/G37,"") -> 12059.417 | I37: 136 | J37: =IF(AND(G37<>"",G37<>0),E37/G37,"") -> 2 | K37: =15493+13357 -> 28850 | L37: 6004.01 | N37: 7490 | O37: 11993 | P37: 6493 | R37: =IF(AND(I37<>"",I37<>0),G37/I37,"") -> 0.088235294 | S37: =D37/T37 -> 0.74264629 | T37: =$I$8*Z37*AA37/SUMPRODUCT($AA$25:$AA$55,$Z$25:$Z$55) -> 194861.27 | U37: =$I$9*Z37*AA37/SUMPRODUCT($AA$25:$AA$55,$Z$25:$Z$55) -> 23.792585 | V37: =IF($I$12="","",U37/$I$12) -> 14.162253 | W37: =IF(AA37<>"",IF(D37<>"",D37,($I$8-SUM($W$25:W36))*Z37*AA37/SUMPRODUCT($AA37:$AA$55,$Z37:$Z$55)),"") -> 144713 | X37: =IF(AA37<>"",IF(E37<>"",E37,($I$9-SUM($X$25:X36))*Z37*AA37/SUMPRODUCT($AA37:$AA$55,$Z37:$Z$55)),"") -> 24 | Y37: =IF(AA37<>"",IF($I$12<>"",IF(G37<>"",G37,($I$9/$I$12-SUM($Y$25:Y36))*Z37*AA37/SUMPRODUCT($AA37:$AA$55,$Z37:$Z$55)),""),"") -> 12 | Z37: 0.95 | AA37: 0.95
A38: Свидовская, Корж, Козлова | B38: 46005 | C38: вс | D38: 31461 | E38: 6 | F38: =IF(AND(E38<>"",E38<>0),D38/E38,"") -> 5243.5 | G38: 4 | H38: =IF(AND(G38<>"",G38<>0),D38/G38,"") -> 7865.25 | I38: 118 | J38: =IF(AND(G38<>"",G38<>0),E38/G38,"") -> 1.5 | N38: 8190 | R38: =IF(AND(I38<>"",I38<>0),G38/I38,"") -> 0.033898305 | S38: =D38/T38 -> 0.16145333 | T38: =$I$8*Z38*AA38/SUMPRODUCT($AA$25:$AA$55,$Z$25:$Z$55) -> 194861.27 | U38: =$I$9*Z38*AA38/SUMPRODUCT($AA$25:$AA$55,$Z$25:$Z$55) -> 23.792585 | V38: =IF($I$12="","",U38/$I$12) -> 14.162253 | W38: =IF(AA38<>"",IF(D38<>"",D38,($I$8-SUM($W$25:W37))*Z38*AA38/SUMPRODUCT($AA38:$AA$55,$Z38:$Z$55)),"") -> 31461 | X38: =IF(AA38<>"",IF(E38<>"",E38,($I$9-SUM($X$25:X37))*Z38*AA38/SUMPRODUCT($AA38:$AA$55,$Z38:$Z$55)),"") -> 6 | Y38: =IF(AA38<>"",IF($I$12<>"",IF(G38<>"",G38,($I$9/$I$12-SUM($Y$25:Y37))*Z38*AA38/SUMPRODUCT($AA38:$AA$55,$Z38:$Z$55)),""),"") -> 4 | Z38: 0.95 | AA38: 0.95
A39: Свидовская, Козлова | B39: 46006 | C39: пн | D39: 20868 | E39: 4 | F39: =IF(AND(E39<>"",E39<>0),D39/E39,"") -> 5217 | G39: 2 | H39: =IF(AND(G39<>"",G39<>0),D39/G39,"") -> 10434 | I39: 88 | J39: =IF(AND(G39<>"",G39<>0),E39/G39,"") -> 2 | R39: =IF(AND(I39<>"",I39<>0),G39/I39,"") -> 0.022727273 | S39: =D39/T39 -> 0.22875774 | T39: =$I$8*Z39*AA39/SUMPRODUCT($AA$25:$AA$55,$Z$25:$Z$55) -> 91223.143 | U39: =$I$9*Z39*AA39/SUMPRODUCT($AA$25:$AA$55,$Z$25:$Z$55) -> 11.138357 | V39: =IF($I$12="","",U39/$I$12) -> 6.6299743 | W39: =IF(AA39<>"",IF(D39<>"",D39,($I$8-SUM($W$25:W38))*Z39*AA39/SUMPRODUCT($AA39:$AA$55,$Z39:$Z$55)),"") -> 20868 | X39: =IF(AA39<>"",IF(E39<>"",E39,($I$9-SUM($X$25:X38))*Z39*AA39/SUMPRODUCT($AA39:$AA$55,$Z39:$Z$55)),"") -> 4 | Y39: =IF(AA39<>"",IF($I$12<>"",IF(G39<>"",G39,($I$9/$I$12-SUM($Y$25:Y38))*Z39*AA39/SUMPRODUCT($AA39:$AA$55,$Z39:$Z$55)),""),"") -> 2 | Z39: 0.65 | AA39: 0.65
A40: Стекольщикова, Козлова, Корж | B40: 46007 | C40: вт | D40: 58894 | E40: 8 | F40: =IF(AND(E40<>"",E40<>0),D40/E40,"") -> 7361.75 | G40: 6 | H40: =IF(AND(G40<>"",G40<>0),D40/G40,"") -> 9815.6667 | I40: 78 | J40: =IF(AND(G40<>"",G40<>0),E40/G40,"") -> 1.3333333 | M40: 22184 | R40: =IF(AND(I40<>"",I40<>0),G40/I40,"") -> 0.076923077 | S40: =D40/T40 -> 0.48492012 | T40: =$I$8*Z40*AA40/SUMPRODUCT($AA$25:$AA$55,$Z$25:$Z$55) -> 121450.93 | U40: =$I$9*Z40*AA40/SUMPRODUCT($AA$25:$AA$55,$Z$25:$Z$55) -> 14.829173 | V40: =IF($I$12="","",U40/$I$12) -> 8.8268889 | W40: =IF(AA40<>"",IF(D40<>"",D40,($I$8-SUM($W$25:W39))*Z40*AA40/SUMPRODUCT($AA40:$AA$55,$Z40:$Z$55)),"") -> 58894 | X40: =IF(AA40<>"",IF(E40<>"",E40,($I$9-SUM($X$25:X39))*Z40*AA40/SUMPRODUCT($AA40:$AA$55,$Z40:$Z$55)),"") -> 8 | Y40: =IF(AA40<>"",IF($I$12<>"",IF(G40<>"",G40,($I$9/$I$12-SUM($Y$25:Y39))*Z40*AA40/SUMPRODUCT($AA40:$AA$55,$Z40:$Z$55)),""),"") -> 6 | Z40: 0.75 | AA40: 0.75
A41: Стекольщикова, Козлова, Корж | B41: 46008 | C41: ср | D41: 84716 | E41: 9 | F41: =IF(AND(E41<>"",E41<>0),D41/E41,"") -> 9412.8889 | G41: 5 | H41: =IF(AND(G41<>"",G41<>0),D41/G41,"") -> 16943.2 | I41: 122 | J41: =IF(AND(G41<>"",G41<>0),E41/G41,"") -> 1.8 | O41: 41473 | R41: =IF(AND(I41<>"",I41<>0),G41/I41,"") -> 0.040983607 | S41: =D41/T41 -> 0.54306182 | T41: =$I$8*Z41*AA41/SUMPRODUCT($AA$25:$AA$55,$Z$25:$Z$55) -> 155996.97 | U41: =$I$9*Z41*AA41/SUMPRODUCT($AA$25:$AA$55,$Z$25:$Z$55) -> 19.047249 | V41: =IF($I$12="","",U41/$I$12) -> 11.337648 | W41: =IF(AA41<>"",IF(D41<>"",D41,($I$8-SUM($W$25:W40))*Z41*AA41/SUMPRODUCT($AA41:$AA$55,$Z41:$Z$55)),"") -> 84716 | X41: =IF(AA41<>"",IF(E41<>"",E41,($I$9-SUM($X$25:X40))*Z41*AA41/SUMPRODUCT($AA41:$AA$55,$Z41:$Z$55)),"") -> 9 | Y41: =IF(AA41<>"",IF($I$12<>"",IF(G41<>"",G41,($I$9/$I$12-SUM($Y$25:Y40))*Z41*AA41/SUMPRODUCT($AA41:$AA$55,$Z41:$Z$55)),""),"") -> 5 | Z41: 0.85 | AA41: 0.85
A42: Стекольщикова, Корж, Свидовская | B42: 46009 | C42: чт | D42: 70243.02 | E42: 11 | F42: =IF(AND(E42<>"",E42<>0),D42/E42,"") -> 6385.7291 | G42: 7 | H42: =IF(AND(G42<>"",G42<>0),D42/G42,"") -> 10034.717 | I42: 88 | J42: =IF(AND(G42<>"",G42<>0),E42/G42,"") -> 1.5714286 | O42: 15066 | R42: =IF(AND(I42<>"",I42<>0),G42/I42,"") -> 0.079545455 | S42: =D42/T42 -> 0.40164266 | T42: =$I$8*Z42*AA42/SUMPRODUCT($AA$25:$AA$55,$Z$25:$Z$55) -> 174889.34 | U42: =$I$9*Z42*AA42/SUMPRODUCT($AA$25:$AA$55,$Z$25:$Z$55) -> 21.35401 | V42: =IF($I$12="","",U42/$I$12) -> 12.71072 | W42: =IF(AA42<>"",IF(D42<>"",D42,($I$8-SUM($W$25:W41))*Z42*AA42/SUMPRODUCT($AA42:$AA$55,$Z42:$Z$55)),"") -> 70243.02 | X42: =IF(AA42<>"",IF(E42<>"",E42,($I$9-SUM($X$25:X41))*Z42*AA42/SUMPRODUCT($AA42:$AA$55,$Z42:$Z$55)),"") -> 11 | Y42: =IF(AA42<>"",IF($I$12<>"",IF(G42<>"",G42,($I$9/$I$12-SUM($Y$25:Y41))*Z42*AA42/SUMPRODUCT($AA42:$AA$55,$Z42:$Z$55)),""),"") -> 7 | Z42: 0.9 | AA42: 0.9
...

Sheet Конкурс
A1: Личный ежедневный КВП, %
A3: Сотруник | B3: 45282 | C3: 45283 | D3: 45284 | E3: 45285 | F3: 45286 | G3: 45287 | H3: 45288 | I3: 45289 | J3: 45290 | K3: 45291 | L3: Итого:
A4: Доп сотрудник | B4: ='Доп сотрудник'!S35 -> 0.65039442 | D4: 0.27 | E4: 0.57 | F4: 0.73 | G4: 0.88 | H4: 0.98
A5: Стекольщикова Алла | C5: 0.25 | D5: 0.79 | E5: 0.33 | F5: 0.13 | G5: 0.75 | H5: 0.67 | I5: 0.74 | J5: 1.72 | K5: 0.33
A6: Свидовская София | B6: ='Свидовская С. А.'!R39 -> 0.64951176 | E6: 0.25 | F6: 0.25 | H6: 0.38 | I6: 1.11 | J6: 1.17 | K6: 0.34
A7: Корж Анастасия | C7: 0.33 | D7: 0.57 | E7: 0.08 | F7: 0.45 | G7: 0.4 | H7: 0.24 | I7: 0.25 | J7: 0.28 | K7: 0.23
A8: Козлова Валерия | B8: ='Козлова В. Э.'!S39 -> 0.42155461 | C8: 0.52 | D8: 0.31 | G8: 0.29 | I8: 0.49 | J8: 0.23 | K8: 0.1
A10: Личный КВП, баллы
A12: Сотруник | B12: 45282 | C12: 45283 | D12: 45284 | E12: 45285 | F12: 45286 | G12: 45287 | H12: 45288 | I12: 45289 | J12: 45290 | K12: 45291 | L12: Итого:
A13: Доп сотрудник | B13: 0 | D13: 0 | E13: 1 | F13: 1 | G13: 1 | H13: 1 | L13: =SUM(B13:K13) -> 4
A14: Стекольщикова Алла | C14: 0 | D14: 1 | E14: 0 | F14: 0 | G14: 0 | H14: 0 | I14: 0 | J14: 2 | K14: 0 | L14: =SUM(B14:K14) -> 3
A15: Свидовская София | B15: 1 | E15: 0 | F15: 0 | H15: 0 | I15: 2 | J15: 1 | K15: 1 | L15: =SUM(B15:K15) -> 5
A16: Корж Анастасия | C16: 0 | D16: 0 | E16: 0 | F16: 0 | G16: 0 | H16: 0 | I16: 0 | J16: 0 | K16: 0 | L16: =SUM(B16:K16) -> 0
A17: Козлова Валерия | B17: 0 | C17: 1 | D17: 0 | G17: 0 | I17: 0 | J17: 0 | K17: 0 | L17: =SUM(B17:K17) -> 1

Sheet Сводная
A1: Сводная по показателям
A2: Показатель | D2: =Центрум!I3 -> ТРК Центрум | G2: =График!B27 -> Свидовская София | J2: =График!B25 -> Корж Анастасия | M2: =График!B26 -> Козлова Валерия | P2: =График!B28 -> Стекольщикова Алла
D3: Факт | F3: Прогноз | G3: Факт | I3: Прогноз | J3: Факт | L3: Прогноз | M3: Факт | O3: Прогноз | P3: Факт | R3: Прогноз
A4: Выручка | D4: =Центрум!K8 -> 0.50672983 | E4: =Центрум!J8 -> 3087288.9 | F4: =Центрум!M8 -> 0.50672983 | G4: ='Свидовская С. А.'!K8 -> 0.5356874 | H4: ='Свидовская С. А.'!J8 -> 657954.52 | I4: ='Свидовская С. А.'!M8 -> 0.5528889 | J4: ='Корж А. А.'!K8 -> 0.36611769 | K4: ='Корж А. А.'!J8 -> 460812.37 | L4: ='Корж А. А.'!M8 -> 0.37639353 | M4: ='Козлова В. Э.'!K8 -> 0.35464809 | N4: ='Козлова В. Э.'!J8 -> 439907 | O4: ='Козлова В. Э.'!M8 -> 0.36559716 | P4: ='Стекольщикова А. А.'!K8 -> 0.61807695 | Q4: ='Стекольщикова А. А.'!J8 -> 875652 | R4: ='Стекольщикова А. А.'!M8 -> 0.62541458
A5: Кол-во изделий | D5: =Центрум!K9 -> 0.53501527 | E5: =Центрум!J9 -> 398 | F5: =Центрум!M9 -> 0.53501527 | G5: ='Свидовская С. А.'!K9 -> 0.58678922 | H5: ='Свидовская С. А.'!J9 -> 88 | I5: ='Свидовская С. А.'!M9 -> 0.59630055 | J5: ='Корж А. А.'!K9 -> 0.42295468 | K5: ='Корж А. А.'!J9 -> 65 | L5: ='Корж А. А.'!M9 -> 0.42831094 | M5: ='Козлова В. Э.'!K9 -> 0.3829558 | N5: ='Козлова В. Э.'!J9 -> 58 | O5: ='Козлова В. Э.'!M9 -> 0.3887622 | P5: ='Стекольщикова А. А.'!K9 -> 0.57230837 | Q5: ='Стекольщикова А. А.'!J9 -> 99 | R5: ='Стекольщикова А. А.'!M9 -> 0.57150148
A6: Средний чек | D6: =Центрум!K10 -> 0.89039671 | E6: =Центрум!J10 -> 12251.146 | F6: =Центрум!M10 -> 0.89039671 | G6: ='Свидовская С. А.'!K10 -> 0.85391504 | H6: ='Свидовская С. А.'!J10 -> 11749.188 | I6: ='Свидовская С. А.'!M10 -> 0.85391504 | J6: ='Корж А. А.'!K10 -> 0.81685898 | K6: ='Корж А. А.'!J10 -> 11239.326 | L6: ='Корж А. А.'!M10 -> 0.81685898 | M6: ='Козлова В. Э.'!K10 -> 0.81979088 | N6: ='Козлова В. Э.'!J10 -> 11279.667 | O6: ='Козлова В. Э.'!M10 -> 0.81979088 | P6: ='Стекольщикова А. А.'!K10 -> 0.9359 | Q6: ='Стекольщикова А. А.'!J10 -> 12877.235 | R6: ='Стекольщикова А. А.'!M10 -> 0.9359
A7: Средняя стоимость изделия | D7: =Центрум!K11 -> 0.94713153 | E7: =Центрум!J11 -> 7757.0073 | F7: =Центрум!M11 -> 0.94713153 | G7: ='Свидовская С. А.'!K11 -> 0.91291281 | H7: ='Свидовская С. А.'!J11 -> 7476.7559 | I7: ='Свидовская С. А.'!M11 -> 0.91291281 | J7: ='Корж А. А.'!K11 -> 0.86561918 | K7: ='Корж А. А.'!J11 -> 7089.4211 | L7: ='Корж А. А.'!M11 -> 0.86561918 | M7: ='Козлова В. Э.'!K11 -> 0.92608101 | N7: ='Козлова В. Э.'!J11 -> 7584.6034 | O7: ='Козлова В. Э.'!M11 -> 0.92608101 | P7: ='Стекольщикова А. А.'!K11 -> 1.0799719 | Q7: ='Стекольщикова А. А.'!J11 -> 8844.9697 | R7: ='Стекольщикова А. А.'!M11 -> 1.0799719
A8: Длина чека | D8: =Центрум!K12 -> 0.94009826 | E8: =Центрум!J12 -> 1.5793651 | F8: =Центрум!M12 -> 0.94009826 | G8: ='Свидовская С. А.'!K12 -> 0.93537415 | H8: ='Свидовская С. А.'!J12 -> 1.5714286 | I8: ='Свидовская С. А.'!M12 -> 0.93537415 | J8: ='Корж А. А.'!K12 -> 0.94367015 | K8: ='Корж А. А.'!J12 -> 1.5853659 | L8: ='Корж А. А.'!M12 -> 0.94367015 | M8: ='Козлова В. Э.'!K12 -> 0.88522589 | N8: ='Козлова В. Э.'!J12 -> 1.4871795 | O8: ='Козлова В. Э.'!M12 -> 0.88522589 | P8: ='Стекольщикова А. А.'!K12 -> 0.86659664 | Q8: ='Стекольщикова А. А.'!J12 -> 1.4558824 | R8: ='Стекольщикова А. А.'!M12 -> 0.86659664
A9: Кол-во чеков | D9: =Центрум!K13 -> 0.56910569 | E9: =Центрум!J13 -> 252 | F9: =Центрум!M13 -> 0.56910569 | G9: ='Свидовская С. А.'!K13 -> 0.62733103 | H9: ='Свидовская С. А.'!J13 -> 56 | I9: ='Свидовская С. А.'!M13 -> 0.6402762 | J9: ='Корж А. А.'!K13 -> 0.44820183 | K9: ='Корж А. А.'!J13 -> 41 | L9: ='Корж А. А.'!M13 -> 0.45580001 | M9: ='Козлова В. Э.'!K13 -> 0.432608 | N9: ='Козлова В. Э.'!J13 -> 39 | O9: ='Козлова В. Э.'!M13 -> 0.44105928 | P9: ='Стекольщикова А. А.'!K13 -> 0.66040918 | Q9: ='Стекольщикова А. А.'!J13 -> 68 | R9: ='Стекольщикова А. А.'!M13 -> 0.66192359
A10: Кол-во смен план/отработано | D10: =Центрум!K14 -> 1 | E10: =Центрум!J14 -> 31 | G10: ='Свидовская С. А.'!K14 -> 1 | H10: ='Свидовская С. А.'!J14 -> 21 | J10: ='Корж А. А.'!K14 -> 1 | K10: ='Корж А. А.'!J14 -> 21 | M10: ='Козлова В. Э.'!K14 -> 1 | N10: ='Козлова В. Э.'!J14 -> 21 | P10: ='Стекольщикова А. А.'!K14 -> 1 | Q10: ='Стекольщикова А. А.'!J14 -> 25
A11: Средние продажи в смену | D11: =Центрум!K15 -> 0.50672983 | E11: =Центрум!J15 -> 99589.964 | F11: =Центрум!M15 -> 0.50672983 | G11: ='Свидовская С. А.'!K15 -> 0.15941804 | H11: ='Свидовская С. А.'!J15 -> 31331.168 | I11: ='Свидовская С. А.'!M15 -> 0.15941804 | J11: ='Корж А. А.'!K15 -> 0.1116518 | K11: ='Корж А. А.'!J15 -> 21943.446 | L11: ='Корж А. А.'!M15 -> 0.1116518 | M11: ='Козлова В. Э.'!K15 -> 0.10658657 | N11: ='Козлова В. Э.'!J15 -> 20947.952 | O11: ='Козлова В. Э.'!M15 -> 0.10658657 | P11: ='Стекольщикова А. А.'!K15 -> 0.17821836 | Q11: ='Стекольщикова А. А.'!J15 -> 35026.08 | R11: ='Стекольщикова А. А.'!M15 -> 0.17821836
A12: Отставание/Перевыполнение | D12: =Центрум!J16 -> -3005284.9 | G12: ='Свидовская С. А.'!N8 -> -549161.26 | J12: ='Корж А. А.'!N8 -> -784899.46 | M12: ='Козлова В. Э.'!N8 -> -786915.97 | P12: ='Стекольщикова А. А.'!N8 -> -530688.73

Sheet Справочник магазинов
A1: МЕГА Белая Дача
A2: Гагаринский
A3: Марфино

Sheet План на день
A1: Выручка | D1: =681244 -> 681244
A2: Кол-во изделий | D2: =D1/D4 -> 83.179976
A3: Средний чек | D3: =D4*D5 -> 13759.2
A4: Средняя стоимость изделия | D4: =Центрум!I11 -> 8190
A5: Длина чека | D5: =Центрум!I12 -> 1.68
A6: Кол-во чеков | D6: =IF(D5<>0,D2/D5,"") -> 49.51189
A7: Конверсия | D7: =Центрум!I20 -> 0.123

Sheet Козлова В. Э.
B1: =TODAY()-1 -> 46031
B2: (отчетная дата) | J2: ЕЖЕДНЕВНЫЙ ОТЧЕТ О ПРОДАЖАХ
B3: Осталось до выполнения плана!!! | J3: =График!B26 -> Козлова Валерия
C4: =I8-D49 -> 800497.24 | E4: =IF(I8<>0,C4/I8,0) -> 0.64535191
F6: Целевые показатели
F7: Показатель | I7: План | J7: Факт | K7: % выполнения | L7: Прогноз выполнения | M7: % выполнения по прогнозу | N7: Отклонение | O7: Факт аналогичного месяца прошлого года | P7: Отклонение LFL
F8: Выручка | I8: =Центрум!I8/График!AJ29*График!AJ26 -> 1240404.2 | J8: =D49 -> 439907 | K8: =IF(AND(I8<>"",I8<>0,J8<>""),J8/I8,"") -> 0.35464809 | L8: =IF(SUMIF($D$25:$D$47,">=0",$T$25:$T$47)<>0,I8*D49/SUMIF($D$25:$D$47,">=0",$T$25:$T$47),0) -> 453488.27 | M8: =L8/I8 -> 0.36559716 | N8: =IF(AND(J8<>0,J8<>"",I8<>0,I8<>""),L8-I8,"") -> -786915.97 | P8: =IF(AND(O8<>"",O8<>0,L8<>"",L8<>0),-O8+L8,"") | Q8: =IF(AND(P8<>"",P8<>0,O8<>0,O8<>""),P8/O8,"")
F9: Кол-во изделий | I9: =I8/I11 -> 151.45351 | J9: =E49 -> 58 | K9: =IF(AND(I9<>"",I9<>0,J9<>""),J9/I9,"") -> 0.3829558 | L9: =IF(SUMIF($E$25:$E$47,">=0",$U$25:$U$47)<>0,I9*E49/SUMIF($E$25:$E$47,">=0",$U$25:$U$47),0) -> 58.879399 | M9: =IF(AND(I9<>"",I9<>0,L9<>"",L9<>0),L9/I9,"") -> 0.3887622 | N9: =IF(AND(J9<>0,J9<>"",I9<>0,I9<>""),L9-I9,"") -> -92.57411 | O9: =O8/O11 -> #DIV/0! | P9: =IF(AND(O9<>"",O9<>0,L9<>"",L9<>0),-O9+L9,"") -> #DIV/0! | Q9: =IF(AND(P9<>"",P9<>0,O9<>0,O9<>""),P9/O9,"") -> #DIV/0!
F10: Средний чек | I10: =I11*I12 -> 13759.2 | J10: =H49 -> 11279.667 | K10: =IF(AND(I10<>"",I10<>0,J10<>""),J10/I10,"") -> 0.81979088 | L10: =J10 -> 11279.667 | M10: =IF(AND(I10<>"",I10<>0,L10<>"",L10<>0),L10/I10,"") -> 0.81979088 | N10: =IF(AND(J10<>0,J10<>"",I10<>0,I10<>""),L10-I10,"") -> -2479.5333 | O10: =O11*O12 -> 0 | P10: =IF(AND(O10<>"",O10<>0,L10<>"",L10<>0),-O10+L10,"") | Q10: =IF(AND(P10<>"",P10<>0,O10<>0,O10<>""),P10/O10,"")
F11: Средняя стоимость изделия | I11: =Центрум!I11 -> 8190 | J11: =F49 -> 7584.6034 | K11: =IF(AND(I11<>"",I11<>0,J11<>""),J11/I11,"") -> 0.92608101 | L11: =J11 -> 7584.6034 | M11: =IF(AND(I11<>"",I11<>0,L11<>"",L11<>0),L11/I11,"") -> 0.92608101 | N11: =IF(AND(J11<>0,J11<>"",I11<>0,I11<>""),L11-I11,"") -> -605.39655 | P11: =IF(AND(O11<>"",O11<>0,L11<>"",L11<>0),-O11+L11,"") | Q11: =IF(AND(P11<>"",P11<>0,O11<>0,O11<>""),P11/O11,"")
F12: Длина чека | I12: =Центрум!I12 -> 1.68 | J12: =J49 -> 1.4871795 | K12: =IF(AND(I12<>"",I12<>0,J12<>""),J12/I12,"") -> 0.88522589 | L12: =J12 -> 1.4871795 | M12: =IF(AND(I12<>"",I12<>0,L12<>"",L12<>0),L12/I12,"") -> 0.88522589 | N12: =IF(AND(J12<>0,J12<>"",I12<>0,I12<>""),L12-I12,"") -> -0.19282051 | P12: =IF(AND(O12<>"",O12<>0,L12<>"",L12<>0),-O12+L12,"") | Q12: =IF(AND(P12<>"",P12<>0,O12<>0,O12<>""),P12/O12,"")
F13: Кол-во чеков | I13: =IF(I12<>0,I9/I12,"") -> 90.150898 | J13: =G49 -> 39 | K13: =IF(AND(I13<>"",I13<>0,J13<>""),J13/I13,"") -> 0.432608 | L13: =IF(SUMIF($G$25:$G$47,">=0",$V$25:$V$47)<>0,I13*G49/SUMIF($G$25:$G$47,">=0",$V$25:$V$47),"") -> 39.76189 | M13: =IF(AND(I13<>"",I13<>0,L13<>"",L13<>0),L13/I13,"") -> 0.44105928 | N13: =IF(AND(J13<>0,J13<>"",I13<>0,I13<>""),L13-I13,"") -> -50.389008 | P13: =IF(AND(O13<>"",O13<>0,L13<>"",L13<>0),-O13+L13,"") | Q13: =IF(AND(P13<>"",P13<>0,O13<>0,O13<>""),P13/O13,"")
F14: Кол-во смен план/отработано | I14: =График!AI26 -> 21 | J14: 21 | K14: =IF(AND(I14<>"",I14<>0,J14<>""),J14/I14,"") -> 1 | L14: =IF(SUMIF($D$25:$D$47,">=0",$T$25:$T$47),I49*I8/SUMIF($D$25:$D$47,">=0",$T$25:$T$47),"") -> 598.93724 | N14: =IF(AND(J14<>0,J14<>"",I14<>0,I14<>""),L14-I14,"") -> 577.93724 | P14: =IF(AND(O14<>"",O14<>0,L14<>"",L14<>0),-O14+L14,"") | Q14: =IF(AND(P14<>"",P14<>0,O14<>0,O14<>""),P14/O14,"")
F15: Средние продажи в смену | I15: =Центрум!I15 -> 196534.64 | J15: =J8/J14 -> 20947.952 | K15: =IF(AND(I15<>"",I15<>0,J15<>""),J15/I15,"") -> 0.10658657 | L15: =J15 -> 20947.952 | M15: =IF(AND(I15<>"",I15<>0,L15<>"",L15<>0),L15/I15,"") -> 0.10658657 | N15: =IF(AND(J15<>0,J15<>"",I15<>0,I15<>""),L15-I15,"") -> -175586.69 | P15: =IF(AND(O15<>"",O15<>0,L15<>"",L15<>0),-O15+L15,"") | Q15: =IF(AND(P15<>"",P15<>0,O15<>0,O15<>""),P15/O15,"")
F16: Отставание/Перевыполнение | J16: =J8-I15*J14 -> -3687320.4 | K16: =IF(AND(I16<>"",I16<>0,J16<>""),J16/I16,"") | L16: =J16 -> -3687320.4 | M16: =IF(AND(I16<>"",I16<>0,L16<>"",L16<>0),L16/I16,"") | N16: =IF(AND(J16<>0,J16<>"",I16<>0,I16<>""),L16-I16,"") | P16: =IF(AND(O16<>"",O16<>0,L16<>"",L16<>0),-O16+L16,"") | Q16: =IF(AND(P16<>"",P16<>0,O16<>0,O16<>""),P16/O16,"") | S16: Подарочные сертификаты
F17: Трафик | I17: =Центрум!I17/График!AJ29*График!AJ26 -> 732.93413 | J17: =I49 -> 581 | K17: =IF(AND(I17<>"",I17<>0,J17<>""),J17/I17,"") -> 0.79270425 | L17: =J17/J14*I14 -> 581 | M17: =IF(AND(I17<>"",I17<>0,L17<>"",L17<>0),L17/I17,"") -> 0.79270425 | N17: =IF(AND(J17<>0,J17<>"",I17<>0,I17<>""),L17-I17,"") -> -151.93413 | P17: =IF(AND(O17<>"",O17<>0,L17<>"",L17<>0),-O17+L17,"") | Q17: =IF(AND(P17<>"",P17<>0,O17<>0,O17<>""),P17/O17,"")
K18: =IF(AND(I18<>"",I18<>0,J18<>""),J18/I18,"") | L18: =J18 -> 0 | M18: =IF(AND(I18<>"",I18<>0,L18<>"",L18<>0),L18/I18,"") | N18: =IF(AND(J18<>0,J18<>"",I18<>0,I18<>""),L18-I18,"") | O18: 0 | P18: =IF(AND(O18<>"",O18<>0,L18<>"",L18<>0),-O18+L18,"") | Q18: =IF(AND(P18<>"",P18<>0,O18<>0,O18<>""),P18/O18,"")
J19: =P49 -> 0 | K19: =IF(AND(I19<>"",I19<>0,J19<>""),J19/I19,"") | L19: =J19 -> 0 | M19: =IF(AND(I19<>"",I19<>0,L19<>"",L19<>0),L19/I19,"") | N19: =IF(AND(J19<>0,J19<>"",I19<>0,I19<>""),L19-I19,"") | O19: 0 | P19: =IF(AND(O19<>"",O19<>0,L19<>"",L19<>0),-O19+L19,"") | Q19: =IF(AND(P19<>"",P19<>0,O19<>0,O19<>""),P19/O19,"") | S19: =S18/I16 -> #DIV/0!
F20: Конверсия план/факт | I20: =Центрум!I20 -> 0.123 | J20: =R49 -> 0.067125645 | K20: =J20/I20 -> 0.54573695 | L20: =IF(AND(K8<>0,I14<>0,I49<>0),(I49*R49+(I49/K8-I49)*I20)/(I49/K8),0) -> 0.10318427 | M20: =IF(AND(I20<>"",I20<>0,L20<>"",L20<>0),L20/I20,"") -> 0.83889648 | N20: =IF(AND(J20<>0,J20<>"",I20<>0,I20<>""),L20-I20,"") -> -0.019815733 | P20: =IF(AND(O20<>"",O20<>0,L20<>"",L20<>0),-O20+L20,"") | Q20: =IF(AND(P20<>"",P20<>0,O20<>0,O20<>""),P20/O20,"")
B22: Факт продаж за месяц | S22: % выполнения дневного плана | T22: Раcпределение плана по дням
B23: Дата | C23: День недели | D23: Выручка (руб) | E23: Кол-во единиц (шт.) | F23: Средняя стоимость изделия (руб.) | G23: Количество чеков (шт.) | H23: Средняя сумма чека (руб.) | I23: Трафик | J23: Длина чека (шт.) | K23: UNOde50 | L23: IS | M23: Agafi | N23: Kalliope | O23: Raganella | P23: CC/MP | Q23: Eva Rites | R23: Конверсия (%) | T23: выручка, план | U23: кол-во ед, план | V23: Кол-во чеков, план | W23: выручка, скорректир.план | X23: кол-во ед, скорр. план | Y23: кол-во чеков, скорр. план | Z23: Коэфф. Дня Недели | AA23: Специфика месяца
B24: 1 | C24: 2 | D24: 3 | E24: в | F24: 5 | G24: 6 | H24: 7 | I24: 8 | J24: 9 | K24: 10 | L24: 11 | M24: 12 | N24: 13 | O24: 14 | P24: 15 | R24: 13 | T24: 1 | U24: 2 | V24: 3 | W24: 4 | X24: 5 | Y24: 6 | Z24: 10 | AA24: 11
A25: 1 | B25: 45992 | C25: пн | D25: 13572 | E25: 2 | F25: =IF(AND(E25<>"",E25<>0),D25/E25,"") -> 6786 | G25: 1 | H25: =IF(AND(G25<>"",G25<>0),D25/G25,"") -> 13572 | I25: 32 | J25: =IF(AND(G25<>"",G25<>0),E25/G25,"") -> 2 | R25: =IF(AND(I25<>"",I25<>0),G25/I25,"") -> 0.03125 | S25: =D25/T25 -> 0.23382946 | T25: =$I$8*Z25*AA25/SUMPRODUCT($AA$25:$AA$56,$Z$25:$Z$56) -> 58042.302 | U25: =$I$9*Z25*AA25/SUMPRODUCT($AA$25:$AA$56,$Z$25:$Z$56) -> 7.0869722 | V25: =IF($I$12="","",U25/$I$12) -> 4.2184358 | W25: =IF(AA25<>"",IF(D25<>"",D25,($I$8-SUM($W24:W$25))*Z25*AA25/SUMPRODUCT($AA25:$AA$56,$Z25:$Z$56)),"") -> 13572 | X25: =IF(AA25<>"",IF(E25<>"",E25,($I$9-SUM($X24:X$25))*Z25*AA25/SUMPRODUCT($AA25:$AA$56,$Z25:$Z$56)),"") -> 2 | Y25: =IF(AA25<>"",IF($I$12<>"",IF(G25<>"",G25,($I$9/$I$12-SUM($Y24:Y$25))*Z25*AA25/SUMPRODUCT($AA25:$AA$56,$Z25:$Z$56)),""),"") -> 1 | Z25: 1 | AA25: 1
A26: 2 | B26: 45995 | C26: чт | D26: 11892 | E26: 2 | F26: =IF(AND(E26<>"",E26<>0),D26/E26,"") -> 5946 | G26: 2 | H26: =IF(AND(G26<>"",G26<>0),D26/G26,"") -> 5946 | I26: 21 | J26: =IF(AND(G26<>"",G26<>0),E26/G26,"") -> 1 | M26: 8699 | R26: =IF(AND(I26<>"",I26<>0),G26/I26,"") -> 0.095238095 | S26: =D26/T26 -> 0.28151919 | T26: =$I$8*Z26*AA26/SUMPRODUCT($AA$25:$AA$56,$Z$25:$Z$56) -> 42242.235 | U26: =$I$9*Z26*AA26/SUMPRODUCT($AA$25:$AA$56,$Z$25:$Z$56) -> 5.1577821 | V26: =IF($I$12="","",U26/$I$12) -> 3.0701084 | W26: =IF(AA26<>"",IF(D26<>"",D26,($I$8-SUM($W$25:W25))*Z26*AA26/SUMPRODUCT($AA26:$AA$56,$Z26:$Z$56)),"") -> 11892 | X26: =IF(AA26<>"",IF(E26<>"",E26,($I$9-SUM($X$25:X25))*Z26*AA26/SUMPRODUCT($AA26:$AA$56,$Z26:$Z$56)),"") -> 2 | Y26: =IF(AA26<>"",IF($I$12<>"",IF(G26<>"",G26,($I$9/$I$12-SUM($Y$25:Y25))*Z26*AA26/SUMPRODUCT($AA26:$AA$56,$Z26:$Z$56)),""),"") -> 2 | Z26: 0.85310234 | AA26: 0.85310234
A27: 3 | B27: 45996 | C27: пт | D27: 27997 | E27: 3 | F27: =IF(AND(E27<>"",E27<>0),D27/E27,"") -> 9332.3333 | G27: 3 | H27: =IF(AND(G27<>"",G27<>0),D27/G27,"") -> 9332.3333 | I27: 39 | J27: =IF(AND(G27<>"",G27<>0),E27/G27,"") -> 1 | M27: 15922 | R27: =IF(AND(I27<>"",I27<>0),G27/I27,"") -> 0.076923077 | S27: =D27/T27 -> 1.9802659 | T27: 14138 | U27: 4 | V27: 2 | W27: 16611 | X27: 3 | Y27: 3 | Z27: 0.94 | AA27: 0.94
A28: 4 | B28: 45997 | C28: сб | D28: 16020 | E28: 3 | F28: =IF(AND(E28<>"",E28<>0),D28/E28,"") -> 5340 | G28: 2 | H28: =IF(AND(G28<>"",G28<>0),D28/G28,"") -> 8010 | I28: 36 | J28: =IF(AND(G28<>"",G28<>0),E28/G28,"") -> 1.5 | R28: =IF(AND(I28<>"",I28<>0),G28/I28,"") -> 0.055555556 | S28: =D28/T28 -> 0.24658554 | T28: =$I$8*Z28*AA28/SUMPRODUCT($AA$25:$AA$56,$Z$25:$Z$56) -> 64967.312 | U28: =$I$9*Z28*AA28/SUMPRODUCT($AA$25:$AA$56,$Z$25:$Z$56) -> 7.9325167 | V28: =IF($I$12="","",U28/$I$12) -> 4.7217361 | W28: =IF(AA28<>"",IF(D28<>"",D28,($I$8-SUM($W$25:W27))*Z28*AA28/SUMPRODUCT($AA28:$AA$56,$Z28:$Z$56)),"") -> 16020 | X28: =IF(AA28<>"",IF(E28<>"",E28,($I$9-SUM($X$25:X27))*Z28*AA28/SUMPRODUCT($AA28:$AA$56,$Z28:$Z$56)),"") -> 3 | Y28: =IF(AA28<>"",IF($I$12<>"",IF(G28<>"",G28,($I$9/$I$12-SUM($Y$25:Y27))*Z28*AA28/SUMPRODUCT($AA28:$AA$56,$Z28:$Z$56)),""),"") -> 2 | Z28: 1.0579743 | AA28: 1.0579743
A29: 5 | B29: 46000 | C29: вт | D29: 47734 | E29: 5 | F29: =IF(AND(E29<>"",E29<>0),D29/E29,"") -> 9546.8 | G29: 1 | H29: =IF(AND(G29<>"",G29<>0),D29/G29,"") -> 47734 | I29: 22 | J29: =IF(AND(G29<>"",G29<>0),E29/G29,"") -> 5 | K29: 13990 | M29: 9782 | N29: 33744 | R29: =IF(AND(I29<>"",I29<>0),G29/I29,"") -> 0.045454545 | S29: =D29/T29 -> 0.82240018 | T29: =$I$8*Z29*AA29/SUMPRODUCT($AA$25:$AA$56,$Z$25:$Z$56) -> 58042.302 | U29: =$I$9*Z29*AA29/SUMPRODUCT($AA$25:$AA$56,$Z$25:$Z$56) -> 7.0869722 | V29: =IF($I$12="","",U29/$I$12) -> 4.2184358 | W29: =IF(AA29<>"",IF(D29<>"",D29,($I$8-SUM($W$25:W28))*Z29*AA29/SUMPRODUCT($AA29:$AA$56,$Z29:$Z$56)),"") -> 47734 | X29: =IF(AA29<>"",IF(E29<>"",E29,($I$9-SUM($X$25:X28))*Z29*AA29/SUMPRODUCT($AA29:$AA$56,$Z29:$Z$56)),"") -> 5 | Y29: =IF(AA29<>"",IF($I$12<>"",IF(G29<>"",G29,($I$9/$I$12-SUM($Y$25:Y28))*Z29*AA29/SUMPRODUCT($AA29:$AA$56,$Z29:$Z$56)),""),"") -> 1 | Z29: 1 | AA29: 1
A30: 6 | B30: 46001 | C30: ср | D30: 0 | E30: 0 | F30: =IF(AND(E30<>"",E30<>0),D30/E30,"") | G30: 0 | H30: =IF(AND(G30<>"",G30<>0),D30/G30,"") | I30: 27 | J30: =IF(AND(G30<>"",G30<>0),E30/G30,"") | R30: =IF(AND(I30<>"",I30<>0),G30/I30,"") -> 0 | S30: =D30/T30 -> 0 | T30: =$I$8*Z30*AA30/SUMPRODUCT($AA$25:$AA$56,$Z$25:$Z$56) -> 58042.302 | U30: =$I$9*Z30*AA30/SUMPRODUCT($AA$25:$AA$56,$Z$25:$Z$56) -> 7.0869722 | V30: =IF($I$12="","",U30/$I$12) -> 4.2184358 | W30: =IF(AA30<>"",IF(D30<>"",D30,($I$8-SUM($W$25:W29))*Z30*AA30/SUMPRODUCT($AA30:$AA$56,$Z30:$Z$56)),"") -> 0 | X30: =IF(AA30<>"",IF(E30<>"",E30,($I$9-SUM($X$25:X29))*Z30*AA30/SUMPRODUCT($AA30:$AA$56,$Z30:$Z$56)),"") -> 0 | Y30: =IF(AA30<>"",IF($I$12<>"",IF(G30<>"",G30,($I$9/$I$12-SUM($Y$25:Y29))*Z30*AA30/SUMPRODUCT($AA30:$AA$56,$Z30:$Z$56)),""),"") -> 0 | Z30: 1 | AA30: 1
A31: 7 | B31: 46002 | C31: чт | D31: 17930 | E31: 3 | F31: =IF(AND(E31<>"",E31<>0),D31/E31,"") -> 5976.6667 | G31: 2 | H31: =IF(AND(G31<>"",G31<>0),D31/G31,"") -> 8965 | I31: 28 | J31: =IF(AND(G31<>"",G31<>0),E31/G31,"") -> 1.5 | M31: 14437 | R31: =IF(AND(I31<>"",I31<>0),G31/I31,"") -> 0.071428571 | S31: =D31/T31 -> 0.30891263 | T31: =$I$8*Z31*AA31/SUMPRODUCT($AA$25:$AA$56,$Z$25:$Z$56) -> 58042.302 | U31: =$I$9*Z31*AA31/SUMPRODUCT($AA$25:$AA$56,$Z$25:$Z$56) -> 7.0869722 | V31: =IF($I$12="","",U31/$I$12) -> 4.2184358 | W31: =IF(AA31<>"",IF(D31<>"",D31,($I$8-SUM($W$25:W30))*Z31*AA31/SUMPRODUCT($AA31:$AA$56,$Z31:$Z$56)),"") -> 17930 | X31: =IF(AA31<>"",IF(E31<>"",E31,($I$9-SUM($X$25:X30))*Z31*AA31/SUMPRODUCT($AA31:$AA$56,$Z31:$Z$56)),"") -> 3 | Y31: =IF(AA31<>"",IF($I$12<>"",IF(G31<>"",G31,($I$9/$I$12-SUM($Y$25:Y30))*Z31*AA31/SUMPRODUCT($AA31:$AA$56,$Z31:$Z$56)),""),"") -> 2 | Z31: 1 | AA31: 1
A32: 8 | B32: 46003 | C32: пт | D32: 0 | E32: 0 | F32: =IF(AND(E32<>"",E32<>0),D32/E32,"") | G32: 0 | H32: =IF(AND(G32<>"",G32<>0),D32/G32,"") | I32: 31 | J32: =IF(AND(G32<>"",G32<>0),E32/G32,"") | R32: =IF(AND(I32<>"",I32<>0),G32/I32,"") -> 0 | S32: =D32/T32 -> 0 | T32: =$I$8*Z32*AA32/SUMPRODUCT($AA$25:$AA$56,$Z$25:$Z$56) -> 58042.302 | U32: =$I$9*Z32*AA32/SUMPRODUCT($AA$25:$AA$56,$Z$25:$Z$56) -> 7.0869722 | V32: =IF($I$12="","",U32/$I$12) -> 4.2184358 | W32: =IF(AA32<>"",IF(D32<>"",D32,($I$8-SUM($W$25:W31))*Z32*AA32/SUMPRODUCT($AA32:$AA$56,$Z32:$Z$56)),"") -> 0 | X32: =IF(AA32<>"",IF(E32<>"",E32,($I$9-SUM($X$25:X31))*Z32*AA32/SUMPRODUCT($AA32:$AA$56,$Z32:$Z$56)),"") -> 0 | Y32: =IF(AA32<>"",IF($I$12<>"",IF(G32<>"",G32,($I$9/$I$12-SUM($Y$25:Y31))*Z32*AA32/SUMPRODUCT($AA32:$AA$56,$Z32:$Z$56)),""),"") -> 0 | Z32: 1 | AA32: 1
A33: 9 | B33: 46005 | C33: вс | D33: 10120 | E33: 2 | F33: =IF(AND(E33<>"",E33<>0),D33/E33,"") -> 5060 | G33: 1 | H33: =IF(AND(G33<>"",G33<>0),D33/G33,"") -> 10120 | I33: 40 | J33: =IF(AND(G33<>"",G33<>0),E33/G33,"") -> 2 | R33: =IF(AND(I33<>"",I33<>0),G33/I33,"") -> 0.025 | S33: =D33/T33 -> 0.17435559 | T33: =$I$8*Z33*AA33/SUMPRODUCT($AA$25:$AA$56,$Z$25:$Z$56) -> 58042.302 | U33: =$I$9*Z33*AA33/SUMPRODUCT($AA$25:$AA$56,$Z$25:$Z$56) -> 7.0869722 | V33: =IF($I$12="","",U33/$I$12) -> 4.2184358 | W33: =IF(AA33<>"",IF(D33<>"",D33,($I$8-SUM($W$25:W32))*Z33*AA33/SUMPRODUCT($AA33:$AA$56,$Z33:$Z$56)),"") -> 10120 | X33: =IF(AA33<>"",IF(E33<>"",E33,($I$9-SUM($X$25:X32))*Z33*AA33/SUMPRODUCT($AA33:$AA$56,$Z33:$Z$56)),"") -> 2 | Y33: =IF(AA33<>"",IF($I$12<>"",IF(G33<>"",G33,($I$9/$I$12-SUM($Y$25:Y32))*Z33*AA33/SUMPRODUCT($AA33:$AA$56,$Z33:$Z$56)),""),"") -> 1 | Z33: 1 | AA33: 1
A34: 10 | B34: 46006 | C34: пн | D34: 0 | E34: 0 | F34: =IF(AND(E34<>"",E34<>0),D34/E34,"") | G34: 0 | H34: =IF(AND(G34<>"",G34<>0),D34/G34,"") | I34: 44 | J34: =IF(AND(G34<>"",G34<>0),E34/G34,"") | R34: =IF(AND(I34<>"",I34<>0),G34/I34,"") -> 0 | S34: =D34/T34 -> 0 | T34: =$I$8*Z34*AA34/SUMPRODUCT($AA$25:$AA$56,$Z$25:$Z$56) -> 58042.302 | U34: =$I$9*Z34*AA34/SUMPRODUCT($AA$25:$AA$56,$Z$25:$Z$56) -> 7.0869722 | V34: =IF($I$12="","",U34/$I$12) -> 4.2184358 | W34: =IF(AA34<>"",IF(D34<>"",D34,($I$8-SUM($W$25:W33))*Z34*AA34/SUMPRODUCT($AA34:$AA$56,$Z34:$Z$56)),"") -> 0 | X34: =IF(AA34<>"",IF(E34<>"",E34,($I$9-SUM($X$25:X33))*Z34*AA34/SUMPRODUCT($AA34:$AA$56,$Z34:$Z$56)),"") -> 0 | Y34: =IF(AA34<>"",IF($I$12<>"",IF(G34<>"",G34,($I$9/$I$12-SUM($Y$25:Y33))*Z34*AA34/SUMPRODUCT($AA34:$AA$56,$Z34:$Z$56)),""),"") -> 0 | Z34: 1 | AA34: 1
A35: 11 | B35: 46007 | C35: вт | D35: 6982 | E35: 1 | F35: =IF(AND(E35<>"",E35<>0),D35/E35,"") -> 6982 | G35: 1 | H35: =IF(AND(G35<>"",G35<>0),D35/G35,"") -> 6982 | I35: 26 | J35: =IF(AND(G35<>"",G35<>0),E35/G35,"") -> 1 | R35: =IF(AND(I35<>"",I35<>0),G35/I35,"") -> 0.038461538 | S35: =D35/T35 -> 0.12029158 | T35: =$I$8*Z35*AA35/SUMPRODUCT($AA$25:$AA$56,$Z$25:$Z$56) -> 58042.302 | U35: =$I$9*Z35*AA35/SUMPRODUCT($AA$25:$AA$56,$Z$25:$Z$56) -> 7.0869722 | V35: =IF($I$12="","",U35/$I$12) -> 4.2184358 | W35: =IF(AA35<>"",IF(D35<>"",D35,($I$8-SUM($W$25:W34))*Z35*AA35/SUMPRODUCT($AA35:$AA$56,$Z35:$Z$56)),"") -> 6982 | X35: =IF(AA35<>"",IF(E35<>"",E35,($I$9-SUM($X$25:X34))*Z35*AA35/SUMPRODUCT($AA35:$AA$56,$Z35:$Z$56)),"") -> 1 | Y35: =IF(AA35<>"",IF($I$12<>"",IF(G35<>"",G35,($I$9/$I$12-SUM($Y$25:Y34))*Z35*AA35/SUMPRODUCT($AA35:$AA$56,$Z35:$Z$56)),""),"") -> 1 | Z35: 1 | AA35: 1
A36: 12 | B36: 46008 | C36: ср | D36: =41473+14185+7493 -> 63151 | E36: 6 | F36: =IF(AND(E36<>"",E36<>0),D36/E36,"") -> 10525.167 | G36: 3 | H36: =IF(AND(G36<>"",G36<>0),D36/G36,"") -> 21050.333 | I36: 40 | J36: =IF(AND(G36<>"",G36<>0),E36/G36,"") -> 2 | O36: 41473 | R36: =IF(AND(I36<>"",I36<>0),G36/I36,"") -> 0.075 | S36: =D36/T36 -> 1.0880168 | T36: =$I$8*Z36*AA36/SUMPRODUCT($AA$25:$AA$56,$Z$25:$Z$56) -> 58042.302 | U36: =$I$9*Z36*AA36/SUMPRODUCT($AA$25:$AA$56,$Z$25:$Z$56) -> 7.0869722 | V36: =IF($I$12="","",U36/$I$12) -> 4.2184358 | W36: =IF(AA36<>"",IF(D36<>"",D36,($I$8-SUM($W$25:W35))*Z36*AA36/SUMPRODUCT($AA36:$AA$56,$Z36:$Z$56)),"") -> 63151 | X36: =IF(AA36<>"",IF(E36<>"",E36,($I$9-SUM($X$25:X35))*Z36*AA36/SUMPRODUCT($AA36:$AA$56,$Z36:$Z$56)),"") -> 6 | Y36: =IF(AA36<>"",IF($I$12<>"",IF(G36<>"",G36,($I$9/$I$12-SUM($Y$25:Y35))*Z36*AA36/SUMPRODUCT($AA36:$AA$56,$Z36:$Z$56)),""),"") -> 3 | Z36: 1 | AA36: 1
A37: 13 | B37: 46010 | C37: пт | D37: 16056 | E37: 3 | F37: =IF(AND(E37<>"",E37<>0),D37/E37,"") -> 5352 | G37: 2 | H37: =IF(AND(G37<>"",G37<>0),D37/G37,"") -> 8028 | I37: 22 | J37: =IF(AND(G37<>"",G37<>0),E37/G37,"") -> 1.5 | N37: 14707 | R37: =IF(AND(I37<>"",I37<>0),G37/I37,"") -> 0.090909091 | S37: =D37/T37 -> 0.27662583 | T37: =$I$8*Z37*AA37/SUMPRODUCT($AA$25:$AA$56,$Z$25:$Z$56) -> 58042.302 | U37: =$I$9*Z37*AA37/SUMPRODUCT($AA$25:$AA$56,$Z$25:$Z$56) -> 7.0869722 | V37: =IF($I$12="","",U37/$I$12) -> 4.2184358 | W37: =IF(AA37<>"",IF(D37<>"",D37,($I$8-SUM($W$25:W36))*Z37*AA37/SUMPRODUCT($AA37:$AA$56,$Z37:$Z$56)),"") -> 16056 | X37: =IF(AA37<>"",IF(E37<>"",E37,($I$9-SUM($X$25:X36))*Z37*AA37/SUMPRODUCT($AA37:$AA$56,$Z37:$Z$56)),"") -> 3 | Y37: =IF(AA37<>"",IF($I$12<>"",IF(G37<>"",G37,($I$9/$I$12-SUM($Y$25:Y36))*Z37*AA37/SUMPRODUCT($AA37:$AA$56,$Z37:$Z$56)),""),"") -> 2 | Z37: 1 | AA37: 1
A38: 14 | B38: 46011 | C38: сб | D38: =6298+6589+12354+5894+24676+12482 -> 68293 | E38: =1+1+2+1+3+1 -> 9 | F38: =IF(AND(E38<>"",E38<>0),D38/E38,"") -> 7588.1111 | G38: 6 | H38: =IF(AND(G38<>"",G38<>0),D38/G38,"") -> 11382.167 | I38: 62 | J38: =IF(AND(G38<>"",G38<>0),E38/G38,"") -> 1.5 | R38: =IF(AND(I38<>"",I38<>0),G38/I38,"") -> 0.096774194 | S38: =D38/T38 -> 1.1766074 | T38: =$I$8*Z38*AA38/SUMPRODUCT($AA$25:$AA$46,$Z$25:$Z$46) -> 58042.302 | U38: =$I$9*Z38*AA38/SUMPRODUCT($AA$25:$AA$46,$Z$25:$Z$46) -> 7.0869722 | V38: =IF($I$12="","",U38/$I$12) -> 4.2184358 | W38: =IF(AA38<>"",IF(D38<>"",D38,($I$8-SUM($W$25:W37))*Z38*AA38/SUMPRODUCT($AA38:$AA$56,$Z38:$Z$56)),"") -> 68293 | X38: =IF(AA38<>"",IF(E38<>"",E38,($I$9-SUM($X$25:X37))*Z38*AA38/SUMPRODUCT($AA38:$AA$56,$Z38:$Z$56)),"") -> 9 | Y38: =IF(AA38<>"",IF($I$12<>"",IF(G38<>"",G38,($I$9/$I$12-SUM($Y$25:Y37))*Z38*AA38/SUMPRODUCT($AA38:$AA$56,$Z38:$Z$56)),""),"") -> 6 | Z38: 1 | AA38: 1
A39: 15 | B39: 46013 | C39: пн | D39: =10684+13784 -> 24468 | E39: =2 -> 2 | F39: =IF(AND(E39<>"",E39<>0),D39/E39,"") -> 12234 | G39: 1 | H39: =IF(AND(G39<>"",G39<>0),D39/G39,"") -> 24468 | I39: 40 | J39: =IF(AND(G39<>"",G39<>0),E39/G39,"") -> 2 | R39: =IF(AND(I39<>"",I39<>0),G39/I39,"") -> 0.025 | S39: =D39/T39 -> 0.42155461 | T39: =$I$8*Z39*AA39/SUMPRODUCT($AA$25:$AA$46,$Z$25:$Z$46) -> 58042.302 | U39: =$I$9*Z39*AA39/SUMPRODUCT($AA$25:$AA$46,$Z$25:$Z$46) -> 7.0869722 | V39: =IF($I$12="","",U39/$I$12) -> 4.2184358 | W39: =IF(AA39<>"",IF(D39<>"",D39,($I$8-SUM($W$25:W38))*Z39*AA39/SUMPRODUCT($AA39:$AA$56,$Z39:$Z$56)),"") -> 24468 | X39: =IF(AA39<>"",IF(E39<>"",E39,($I$9-SUM($X$25:X38))*Z39*AA39/SUMPRODUCT($AA39:$AA$56,$Z39:$Z$56)),"") -> 2 | Y39: =IF(AA39<>"",IF($I$12<>"",IF(G39<>"",G39,($I$9/$I$12-SUM($Y$25:Y38))*Z39*AA39/SUMPRODUCT($AA39:$AA$56,$Z39:$Z$56)),""),"") -> 1 | Z39: 1 | AA39: 1
A40: 16 | B40: 46014 | C40: вт | D40: =13784+4593+10974 -> 29351 | E40: 5 | F40: =IF(AND(E40<>"",E40<>0),D40/E40,"") -> 5870.2 | G40: 3 | H40: =IF(AND(G40<>"",G40<>0),D40/G40,"") -> 9783.6667 | I40: 23 | J40: =IF(AND(G40<>"",G40<>0),E40/G40,"") -> 1.6666667 | N40: 7490 | R40: =IF(AND(I40<>"",I40<>0),G40/I40,"") -> 0.13043478 | S40: =D40/T40 -> 0.50568291 | T40: =$I$8*Z40*AA40/SUMPRODUCT($AA$25:$AA$46,$Z$25:$Z$46) -> 58042.302 | U40: =$I$9*Z40*AA40/SUMPRODUCT($AA$25:$AA$46,$Z$25:$Z$46) -> 7.0869722 | V40: =IF($I$12="","",U40/$I$12) -> 4.2184358 | W40: =IF(AA40<>"",IF(D40<>"",D40,($I$8-SUM($W$25:W39))*Z40*AA40/SUMPRODUCT($AA40:$AA$56,$Z40:$Z$56)),"") -> 29351 | X40: =IF(AA40<>"",IF(E40<>"",E40,($I$9-SUM($X$25:X39))*Z40*AA40/SUMPRODUCT($AA40:$AA$56,$Z40:$Z$56)),"") -> 5 | Y40: =IF(AA40<>"",IF($I$12<>"",IF(G40<>"",G40,($I$9/$I$12-SUM($Y$25:Y39))*Z40*AA40/SUMPRODUCT($AA40:$AA$56,$Z40:$Z$56)),""),"") -> 3 | Z40: 1 | AA40: 1
A41: 17 | B41: 46015 | C41: ср | D41: =4693+13084 -> 17777 | E41: =1+2 -> 3 | F41: =IF(AND(E41<>"",E41<>0),D41/E41,"") -> 5925.6667 | G41: 2 | H41: =IF(AND(G41<>"",G41<>0),D41/G41,"") -> 8888.5 | I41: 20 | J41: =IF(AND(G41<>"",G41<>0),E41/G41,"") -> 1.5 | R41: =IF(AND(I41<>"",I41<>0),G41/I41,"") -> 0.1 | S41: =D41/T41 -> 0.30627662 | T41: =$I$8*Z41*AA41/SUMPRODUCT($AA$25:$AA$46,$Z$25:$Z$46) -> 58042.302 | U41: =$I$9*Z41*AA41/SUMPRODUCT($AA$25:$AA$46,$Z$25:$Z$46) -> 7.0869722 | V41: =IF($I$12="","",U41/$I$12) -> 4.2184358 | W41: =IF(AA41<>"",IF(D41<>"",D41,($I$8-SUM($W$25:W40))*Z41*AA41/SUMPRODUCT($AA41:$AA$56,$Z41:$Z$56)),"") -> 17777 | X41: =IF(AA41<>"",IF(E41<>"",E41,($I$9-SUM($X$25:X40))*Z41*AA41/SUMPRODUCT($AA41:$AA$56,$Z41:$Z$56)),"") -> 3 | Y41: =IF(AA41<>"",IF($I$12<>"",IF(G41<>"",G41,($I$9/$I$12-SUM($Y$25:Y40))*Z41*AA41/SUMPRODUCT($AA41:$AA$56,$Z41:$Z$56)),""),"") -> 2 | Z41: 1 | AA41: 1
A42: 18 | B42: 46018 | C42: сб | D42: =10482+6074 -> 16556 | E42: 2 | F42: =IF(AND(E42<>"",E42<>0),D42/E42,"") -> 8278 | G42: 2 | H42: =IF(AND(G42<>"",G42<>0),D42/G42,"") -> 8278 | I42: 28 | J42: =IF(AND(G42<>"",G42<>0),E42/G42,"") -> 1 | M42: 10482 | R42: =IF(AND(I42<>"",I42<>0),G42/I42,"") -> 0.071428571 | S42: =D42/T42 -> 0.28524024 | T42: =$I$8*Z42*AA42/SUMPRODUCT($AA$25:$AA$46,$Z$25:$Z$46) -> 58042.302 | U42: =$I$9*Z42*AA42/SUMPRODUCT($AA$25:$AA$46,$Z$25:$Z$46) -> 7.0869722 | V42: =IF($I$12="","",U42/$I$12) -> 4.2184358 | W42: =IF(AA42<>"",IF(D42<>"",D42,($I$8-SUM($W$25:W41))*Z42*AA42/SUMPRODUCT($AA42:$AA$56,$Z42:$Z$56)),"") -> 16556 | X42: =IF(AA42<>"",IF(E42<>"",E42,($I$9-SUM($X$25:X41))*Z42*AA42/SUMPRODUCT($AA42:$AA$56,$Z42:$Z$56)),"") -> 2 | Y42: =IF(AA42<>"",IF($I$12<>"",IF(G42<>"",G42,($I$9/$I$12-SUM($Y$25:Y41))*Z42*AA42/SUMPRODUCT($AA42:$AA$56,$Z42:$Z$56)),""),"") -> 2 | Z42: 1 | AA42: 1
...

Sheet Корж А. А.
B1: =TODAY()-1 -> 46031
B2: (отчетная дата) | J2: ЕЖЕДНЕВНЫЙ ОТЧЕТ О ПРОДАЖАХ
B3: Осталось до выполнения плана!!! | J3: =График!B25 -> Корж Анастасия
C4: =I8-D48 -> 797833.11 | E4: =IF(I8<>0,C4/I8,0) -> 0.63388231
F6: Целевые показатели
F7: Показатель | I7: План | J7: Факт | K7: % выполнения | L7: Прогноз выполнения | M7: % выполнения по прогнозу | N7: Отклонение | O7: Факт аналогичного месяца прошлого года | P7: Отклонение LFL
F8: Выручка | I8: =Центрум!I8/График!AJ29*График!AJ25 -> 1258645.5 | J8: =D48 -> 460812.37 | K8: =IF(AND(I8<>"",I8<>0,J8<>""),J8/I8,"") -> 0.36611769 | L8: =IF(SUMIF($D$25:$D$47,">=0",$S$25:$S$47)<>0,I8*D48/SUMIF($D$25:$D$47,">=0",$S$25:$S$47),0) -> 473746.01 | M8: =L8/I8 -> 0.37639353 | N8: =IF(AND(J8<>0,J8<>"",I8<>0,I8<>""),L8-I8,"") -> -784899.46 | P8: =IF(AND(O8<>"",O8<>0,L8<>"",L8<>0),-O8+L8,"") | Q8: =IF(AND(P8<>"",P8<>0,O8<>0,O8<>""),P8/O8,"")
F9: Кол-во изделий | I9: =I8/I11 -> 153.68077 | J9: =E48 -> 65 | K9: =IF(AND(I9<>"",I9<>0,J9<>""),J9/I9,"") -> 0.42295468 | L9: =IF(SUMIF($E$25:$E$47,">=0",$T$25:$T$47)<>0,I9*E48/SUMIF($E$25:$E$47,">=0",$T$25:$T$47),0) -> 65.823153 | M9: =IF(AND(I9<>"",I9<>0,L9<>"",L9<>0),L9/I9,"") -> 0.42831094 | N9: =IF(AND(J9<>0,J9<>"",I9<>0,I9<>""),L9-I9,"") -> -87.857613 | O9: =O8/O11 -> #DIV/0! | P9: =IF(AND(O9<>"",O9<>0,L9<>"",L9<>0),-O9+L9,"") -> #DIV/0! | Q9: =IF(AND(P9<>"",P9<>0,O9<>0,O9<>""),P9/O9,"") -> #DIV/0!
F10: Средний чек | I10: =I11*I12 -> 13759.2 | J10: =H48 -> 11239.326 | K10: =IF(AND(I10<>"",I10<>0,J10<>""),J10/I10,"") -> 0.81685898 | L10: =J10 -> 11239.326 | M10: =IF(AND(I10<>"",I10<>0,L10<>"",L10<>0),L10/I10,"") -> 0.81685898 | N10: =IF(AND(J10<>0,J10<>"",I10<>0,I10<>""),L10-I10,"") -> -2519.8739 | O10: =O11*O12 -> 0 | P10: =IF(AND(O10<>"",O10<>0,L10<>"",L10<>0),-O10+L10,"") | Q10: =IF(AND(P10<>"",P10<>0,O10<>0,O10<>""),P10/O10,"")
F11: Средняя стоимость изделия | I11: =Центрум!I11 -> 8190 | J11: =F48 -> 7089.4211 | K11: =IF(AND(I11<>"",I11<>0,J11<>""),J11/I11,"") -> 0.86561918 | L11: =J11 -> 7089.4211 | M11: =IF(AND(I11<>"",I11<>0,L11<>"",L11<>0),L11/I11,"") -> 0.86561918 | N11: =IF(AND(J11<>0,J11<>"",I11<>0,I11<>""),L11-I11,"") -> -1100.5789 | P11: =IF(AND(O11<>"",O11<>0,L11<>"",L11<>0),-O11+L11,"") | Q11: =IF(AND(P11<>"",P11<>0,O11<>0,O11<>""),P11/O11,"")
F12: Длина чека | I12: =Центрум!I12 -> 1.68 | J12: =J48 -> 1.5853659 | K12: =IF(AND(I12<>"",I12<>0,J12<>""),J12/I12,"") -> 0.94367015 | L12: =J12 -> 1.5853659 | M12: =IF(AND(I12<>"",I12<>0,L12<>"",L12<>0),L12/I12,"") -> 0.94367015 | N12: =IF(AND(J12<>0,J12<>"",I12<>0,I12<>""),L12-I12,"") -> -0.094634146 | P12: =IF(AND(O12<>"",O12<>0,L12<>"",L12<>0),-O12+L12,"") | Q12: =IF(AND(P12<>"",P12<>0,O12<>0,O12<>""),P12/O12,"")
F13: Кол-во чеков | I13: =IF(I12<>0,I9/I12,"") -> 91.476647 | J13: =G48 -> 41 | K13: =IF(AND(I13<>"",I13<>0,J13<>""),J13/I13,"") -> 0.44820183 | L13: =IF(SUMIF($G$25:$G$47,">=0",$U$25:$U$47)<>0,I13*G48/SUMIF($G$25:$G$47,">=0",$U$25:$U$47),"") -> 41.695057 | M13: =IF(AND(I13<>"",I13<>0,L13<>"",L13<>0),L13/I13,"") -> 0.45580001 | N13: =IF(AND(J13<>0,J13<>"",I13<>0,I13<>""),L13-I13,"") -> -49.78159 | P13: =IF(AND(O13<>"",O13<>0,L13<>"",L13<>0),-O13+L13,"") | Q13: =IF(AND(P13<>"",P13<>0,O13<>0,O13<>""),P13/O13,"")
F14: Кол-во смен план/отработано | I14: =График!AI25 -> 21 | J14: 21 | K14: =IF(AND(I14<>"",I14<>0,J14<>""),J14/I14,"") -> 1 | L14: =IF(SUMIF($D$25:$D$47,">=0",$S$25:$S$47),I48*I8/SUMIF($D$25:$D$47,">=0",$S$25:$S$47),"") -> 538.70713 | N14: =IF(AND(J14<>0,J14<>"",I14<>0,I14<>""),L14-I14,"") -> 517.70713 | P14: =IF(AND(O14<>"",O14<>0,L14<>"",L14<>0),-O14+L14,"") | Q14: =IF(AND(P14<>"",P14<>0,O14<>0,O14<>""),P14/O14,"")
F15: Средние продажи в смену | I15: =Центрум!I15 -> 196534.64 | J15: =J8/J14 -> 21943.446 | K15: =IF(AND(I15<>"",I15<>0,J15<>""),J15/I15,"") -> 0.1116518 | L15: =J15 -> 21943.446 | M15: =IF(AND(I15<>"",I15<>0,L15<>"",L15<>0),L15/I15,"") -> 0.1116518 | N15: =IF(AND(J15<>0,J15<>"",I15<>0,I15<>""),L15-I15,"") -> -174591.19 | P15: =IF(AND(O15<>"",O15<>0,L15<>"",L15<>0),-O15+L15,"") | Q15: =IF(AND(P15<>"",P15<>0,O15<>0,O15<>""),P15/O15,"")
F16: Отставание/Перевыполнение | J16: =J8-I15*J14 -> -3666415 | K16: =IF(AND(I16<>"",I16<>0,J16<>""),J16/I16,"") | L16: =J16 -> -3666415 | M16: =IF(AND(I16<>"",I16<>0,L16<>"",L16<>0),L16/I16,"") | N16: =IF(AND(J16<>0,J16<>"",I16<>0,I16<>""),L16-I16,"") | P16: =IF(AND(O16<>"",O16<>0,L16<>"",L16<>0),-O16+L16,"") | Q16: =IF(AND(P16<>"",P16<>0,O16<>0,O16<>""),P16/O16,"") | S16: Подарочные сертификаты
F17: Трафик | I17: =Центрум!I17/График!AJ29*График!AJ25 -> 743.71257 | J17: =I48 -> 524 | K17: =IF(AND(I17<>"",I17<>0,J17<>""),J17/I17,"") -> 0.70457327 | L17: =J17/J14*I14 -> 524 | M17: =IF(AND(I17<>"",I17<>0,L17<>"",L17<>0),L17/I17,"") -> 0.70457327 | N17: =IF(AND(J17<>0,J17<>"",I17<>0,I17<>""),L17-I17,"") -> -219.71257 | P17: =IF(AND(O17<>"",O17<>0,L17<>"",L17<>0),-O17+L17,"") | Q17: =IF(AND(P17<>"",P17<>0,O17<>0,O17<>""),P17/O17,"")
K18: =IF(AND(I18<>"",I18<>0,J18<>""),J18/I18,"") | L18: =J18 -> 0 | M18: =IF(AND(I18<>"",I18<>0,L18<>"",L18<>0),L18/I18,"") | N18: =IF(AND(J18<>0,J18<>"",I18<>0,I18<>""),L18-I18,"") | O18: 0 | P18: =IF(AND(O18<>"",O18<>0,L18<>"",L18<>0),-O18+L18,"") | Q18: =IF(AND(P18<>"",P18<>0,O18<>0,O18<>""),P18/O18,"")
J19: =P48 -> 0 | K19: =IF(AND(I19<>"",I19<>0,J19<>""),J19/I19,"") | L19: =J19 -> 0 | M19: =IF(AND(I19<>"",I19<>0,L19<>"",L19<>0),L19/I19,"") | N19: =IF(AND(J19<>0,J19<>"",I19<>0,I19<>""),L19-I19,"") | O19: 0 | P19: =IF(AND(O19<>"",O19<>0,L19<>"",L19<>0),-O19+L19,"") | Q19: =IF(AND(P19<>"",P19<>0,O19<>0,O19<>""),P19/O19,"") | S19: =S18/I16 -> #DIV/0!
F20: Конверсия план/факт | I20: =Центрум!I20 -> 0.123 | J20: =Q48 -> 0.078244275 | K20: =J20/I20 -> 0.63613232 | L20: =IF(AND(K8<>0,I14<>0,I48<>0),(I48*Q48+(I48/K8-I48)*I20)/(I48/K8),0) -> 0.10661414 | M20: =IF(AND(I20<>"",I20<>0,L20<>"",L20<>0),L20/I20,"") -> 0.86678161 | N20: =IF(AND(J20<>0,J20<>"",I20<>0,I20<>""),L20-I20,"") -> -0.016385863 | P20: =IF(AND(O20<>"",O20<>0,L20<>"",L20<>0),-O20+L20,"") | Q20: =IF(AND(P20<>"",P20<>0,O20<>0,O20<>""),P20/O20,"")
