Workbook
Name маг: NA()

Sheet Центрум
B1: =TODAY()-1 -> 46171
B2: (01.02.2026-28.02.2026) | J2: ЕЖЕДНЕВНЫЙ ОТЧЕТ О ПРОДАЖАХ
C3: Осталось до выполнения плана!!! | I3: ТРК Центрум
C4: =I8-D56 -> 1025637 | E4: =IF(I8<>0,C4/I8,0) -> 0.54841737
F6: Целевые показатели
F7: Показатель | I7: План | J7: Факт | K7: % выполнения | L7: Прогноз выполнения | M7: % выполнения по прогнозу | N7: Отклонение | O7: Факт аналогичного месяца прошлого года | P7: Отклонение LFL
F8: Выручка | I8: =I13*I10 -> 1870176 | J8: =D56 -> 844539 | K8: =IF(AND(I8<>"",I8<>0,J8<>""),J8/I8,"") -> 0.45158263 | L8: =IF(SUMIF($D$25:$D$55,">=0",$V$25:$V$55)<>0,I8*D56/SUMIF($D$25:$D$55,">=0",$V$25:$V$55),0) -> 844539 | M8: =L8/I8 -> 0.45158263 | N8: =IF(AND(J8<>0,J8<>"",I8<>0,I8<>""),L8-I8,"") -> -1025637 | P8: =IF(AND(O8<>"",O8<>0,L8<>"",L8<>0),-O8+L8,"") | Q8: =IF(AND(O8<>"",O8<>0,N8<>0,N8<>""),O8/N8,"")
F9: Кол-во изделий | I9: =I8/I11 -> 257.6 | J9: =E56 -> 106 | K9: =IF(AND(I9<>"",I9<>0,J9<>""),J9/I9,"") -> 0.41149068 | L9: =IF(SUMIF($E$25:$E$55,">=0",$W$25:$W$55)<>0,I9*E56/SUMIF($E$25:$E$55,">=0",$W$25:$W$55),0) -> 106 | M9: =IF(AND(I9<>"",I9<>0,L9<>"",L9<>0),L9/I9,"") -> 0.41149068 | N9: =IF(AND(J9<>0,J9<>"",I9<>0,I9<>""),L9-I9,"") -> -151.6 | P9: =IF(AND(O9<>"",O9<>0,L9<>"",L9<>0),-O9+L9,"") | Q9: =IF(AND(O9<>"",O9<>0,N9<>0,N9<>""),O9/N9,"")
F10: Средний чек | I10: =I11*I12 -> 13358.4 | J10: =H56 -> 12239.696 | K10: =IF(AND(I10<>"",I10<>0,J10<>""),J10/I10,"") -> 0.91625462 | L10: =J10 -> 12239.696 | M10: =IF(AND(I10<>"",I10<>0,L10<>"",L10<>0),L10/I10,"") -> 0.91625462 | N10: =IF(AND(J10<>0,J10<>"",I10<>0,I10<>""),L10-I10,"") -> -1118.7043 | P10: =IF(AND(O10<>"",O10<>0,L10<>"",L10<>0),-O10+L10,"") | Q10: =IF(AND(O10<>"",O10<>0,N10<>0,N10<>""),O10/N10,"")
F11: Средняя стоимость изделия | I11: 7260 | J11: =F56 -> 7967.3491 | K11: =IF(AND(I11<>"",I11<>0,J11<>""),J11/I11,"") -> 1.097431 | L11: =IF(L9>0,L8/L9,"") -> 7967.3491 | M11: =IF(AND(I11<>"",I11<>0,L11<>"",L11<>0),L11/I11,"") -> 1.097431 | N11: =IF(AND(J11<>0,J11<>"",I11<>0,I11<>""),L11-I11,"") -> 707.34906 | P11: =IF(AND(O11<>"",O11<>0,L11<>"",L11<>0),-O11+L11,"") | Q11: =IF(AND(O11<>"",O11<>0,N11<>0,N11<>""),O11/N11,"")
F12: Длина чека | I12: 1.84 | J12: =J56 -> 1.5362319 | K12: =IF(AND(I12<>"",I12<>0,J12<>""),J12/I12,"") -> 0.83490863 | L12: =J12 -> 1.5362319 | M12: =IF(AND(I12<>"",I12<>0,L12<>"",L12<>0),L12/I12,"") -> 0.83490863 | N12: =IF(AND(J12<>0,J12<>"",I12<>0,I12<>""),L12-I12,"") -> -0.30376812 | P12: =IF(AND(O12<>"",O12<>0,L12<>"",L12<>0),-O12+L12,"") | Q12: =IF(AND(O12<>"",O12<>0,N12<>0,N12<>""),O12/N12,"")
F13: Кол-во чеков | I13: =I17*I20 -> 140 | J13: =G56 -> 69 | K13: =IF(AND(I13<>"",I13<>0,J13<>""),J13/I13,"") -> 0.49285714 | L13: =IF(SUMIF($G$25:$G$55,">=0",$X$25:$X$55)<>0,I13*G56/SUMIF($G$25:$G$55,">=0",$X$25:$X$55),"") -> 69 | M13: =IF(AND(I13<>"",I13<>0,L13<>"",L13<>0),L13/I13,"") -> 0.49285714 | N13: =IF(AND(J13<>0,J13<>"",I13<>0,I13<>""),L13-I13,"") -> -71 | P13: =IF(AND(O13<>"",O13<>0,L13<>"",L13<>0),-O13+L13,"") | Q13: =IF(AND(O13<>"",O13<>0,N13<>0,N13<>""),O13/N13,"")
F14: Кол-во смен | I14: 28 | J14: 28 | K14: =IF(AND(I14<>"",I14<>0,J14<>""),J14/I14,"") -> 1 | L14: =IF(SUMIF($D$25:$D$55,">=0",$V$25:$V$55),I56*I8/SUMIF($D$25:$D$55,">=0",$V$25:$V$55),"") -> 1338 | N14: =IF(AND(J14<>0,J14<>"",I14<>0,I14<>""),L14-I14,"") -> 1310 | P14: =IF(AND(O14<>"",O14<>0,L14<>"",L14<>0),-O14+L14,"") | Q14: =IF(AND(O14<>"",O14<>0,N14<>0,N14<>""),O14/N14,"")
F15: Средние продажи в смену | I15: =I8/I14 -> 66792 | J15: =J8/J14 -> 30162.107 | K15: =IF(AND(I15<>"",I15<>0,J15<>""),J15/I15,"") -> 0.45158263 | L15: =J15 -> 30162.107 | M15: =IF(AND(I15<>"",I15<>0,L15<>"",L15<>0),L15/I15,"") -> 0.45158263 | N15: =IF(AND(J15<>0,J15<>"",I15<>0,I15<>""),L15-I15,"") -> -36629.893 | P15: =IF(AND(O15<>"",O15<>0,L15<>"",L15<>0),-O15+L15,"") | Q15: =IF(AND(O15<>"",O15<>0,N15<>0,N15<>""),O15/N15,"")
F16: Отставание/Перевыполнение | J16: =J8-I15*J14 -> -1025637 | K16: =IF(AND(I16<>"",I16<>0,J16<>""),J16/I16,"") | L16: =J16 -> -1025637 | M16: =IF(AND(I16<>"",I16<>0,L16<>"",L16<>0),L16/I16,"") | N16: =IF(AND(J16<>0,J16<>"",I16<>0,I16<>""),L16-I16,"") | P16: =IF(AND(O16<>"",O16<>0,L16<>"",L16<>0),-O16+L16,"") | Q16: =IF(AND(O16<>"",O16<>0,N16<>0,N16<>""),O16/N16,"") | W16: Подарочные сертификаты
F17: Трафик | I17: 1400 | J17: =I56 -> 1338 | K17: =IF(AND(I17<>"",I17<>0,J17<>""),J17/I17,"") -> 0.95571429 | L17: =J17/J14*I14 -> 1338 | M17: =IF(AND(I17<>"",I17<>0,L17<>"",L17<>0),L17/I17,"") -> 0.95571429 | N17: =IF(AND(J17<>0,J17<>"",I17<>0,I17<>""),L17-I17,"") -> -62 | P17: =IF(AND(O17<>"",O17<>0,L17<>"",L17<>0),-O17+L17,"") | Q17: =IF(AND(O17<>"",O17<>0,N17<>0,N17<>""),O17/N17,"")
K18: =IF(AND(I18<>"",I18<>0,J18<>""),J18/I18,"") | L18: =J18 -> 0 | M18: =IF(AND(I18<>"",I18<>0,L18<>"",L18<>0),L18/I18,"") | N18: =IF(AND(J18<>0,J18<>"",I18<>0,I18<>""),L18-I18,"") | P18: =IF(AND(O18<>"",O18<>0,L18<>"",L18<>0),-O18+L18,"") | Q18: =IF(AND(O18<>"",O18<>0,N18<>0,N18<>""),O18/N18,"")
K19: =IF(AND(I19<>"",I19<>0,J19<>""),J19/I19,"") | L19: =J19 -> 0 | M19: =IF(AND(I19<>"",I19<>0,L19<>"",L19<>0),L19/I19,"") | N19: =IF(AND(J19<>0,J19<>"",I19<>0,I19<>""),L19-I19,"") | O19: 0 | P19: =IF(AND(O19<>"",O19<>0,L19<>"",L19<>0),-O19+L19,"") | Q19: =IF(AND(O19<>"",O19<>0,N19<>0,N19<>""),O19/N19,"") | W19: =W18/I16 -> #DIV/0!
F20: Конверсия | I20: 0.1 | J20: =T56 -> 0.051569507 | K20: =J20/I20 -> 0.51569507 | L20: =J20/I20 -> 0.51569507 | M20: =J20/I20 -> 0.51569507 | N20: =IF(AND(J20<>0,J20<>"",I20<>0,I20<>""),L20-I20,"") -> 0.41569507 | P20: =IF(AND(O20<>"",O20<>0,L20<>"",L20<>0),-O20+L20,"") | Q20: =IF(AND(O20<>"",O20<>0,N20<>0,N20<>""),O20/N20,"")
A22: Факт продаж за месяц | U22: Раcпределение плана по дням
A23: Сотрудник | B23: Дата | C23: День недели | D23: Выручка (руб) | E23: Кол-во единиц (шт.) | F23: Средняя стоимость изделия (руб.) | G23: Количество чеков (шт.) | H23: Средняя сумма чека (руб.) | I23: Трафик | J23: Длина чека (шт.) | K23: UNOde50 | L23: IS | M23: Agafi | N23: Kalliope | O23: Raganella | P23: CC/MP | Q23: Eva Rites | R23: Antura | S23: SALE | T23: Конверсия (%) | U23: % выполнения дневного плана | V23: выручка, план | W23: кол-во ед, план | X23: Кол-во чеков, план | Y23: выручка, скорректир.план | Z23: кол-во ед, скорр. план | AA23: кол-во чеков, скорр. план | AB23: Коэфф. Дня Недели | AC23: Специфика месяца
B24: 1 | C24: 2 | D24: 3 | E24: 4 | F24: 5 | G24: 6 | H24: 7 | I24: 8 | J24: 9 | K24: 10 | L24: 11 | M24: 12 | N24: 13 | O24: 14 | P24: 15 | Q24: 16 | R24: 17 | T24: 13 | V24: 1 | W24: 2 | X24: 3 | Y24: 4 | Z24: 5 | AA24: 6 | AB24: 10 | AC24: 11
A25: Козлова, Сейтджеилова | B25: 46054 | C25: вс | D25: =42903-10892+7503 -> 39514 | E25: 8 | F25: =IF(AND(E25<>"",E25<>0),D25/E25,"") -> 4939.25 | G25: 6 | H25: =IF(AND(G25<>"",G25<>0),D25/G25,"") -> 6585.6667 | I25: 57 | J25: =IF(AND(G25<>"",G25<>0),E25/G25,"") -> 1.3333333 | L25: 7503 | M25: 8592 | T25: =IF(AND(I25<>"",I25<>0),G25/I25,"") -> 0.10526316 | U25: =D25/V25 -> 0.52837185 | V25: =$I$8*AB25*AC25/SUMPRODUCT($AC$25:$AC$55,$AB$25:$AB$55) -> 74784.453 | W25: =$I$9*AB25*AC25/SUMPRODUCT($AC$25:$AC$55,$AB$25:$AB$55) -> 10.300889 | X25: =IF($I$12="","",W25/$I$12) -> 5.5983092 | Y25: =IF(D25<>"",D25,V25) -> 39514 | Z25: =IF(E25<>"",E25,W25) -> 8 | AA25: =IF(G25<>"",G25,X25) -> 6 | AB25: 0.9414554 | AC25: 0.9414554
A26: Козлова, Сейтджеилова | B26: 46055 | C26: пн | D26: 6492 | E26: 1 | F26: =IF(AND(E26<>"",E26<>0),D26/E26,"") -> 6492 | G26: 1 | H26: =IF(AND(G26<>"",G26<>0),D26/G26,"") -> 6492 | I26: 34 | J26: =IF(AND(G26<>"",G26<>0),E26/G26,"") -> 1 | T26: =IF(AND(I26<>"",I26<>0),G26/I26,"") -> 0.029411765 | U26: =D26/V26 -> 0.10572177 | V26: =$I$8*AB26*AC26/SUMPRODUCT($AC$25:$AC$55,$AB$25:$AB$55) -> 61406.463 | W26: =$I$9*AB26*AC26/SUMPRODUCT($AC$25:$AC$55,$AB$25:$AB$55) -> 8.4581905 | X26: =IF($I$12="","",W26/$I$12) -> 4.5968427 | Y26: =IF(AC26<>"",IF(D26<>"",D26,($I$8-SUM($Y$25:Y25))*AB26*AC26/SUMPRODUCT($AC26:$AC$55,$AB26:$AB$55)),"") -> 6492 | Z26: =IF(AC26<>"",IF(E26<>"",E26,($I$9-SUM($Z$25:Z25))*AB26*AC26/SUMPRODUCT($AC26:$AC$55,$AB26:$AB$55)),"") -> 1 | AA26: =IF(AC26<>"",IF($I$12<>"",IF(G26<>"",G26,($I$9/$I$12-SUM($AA$25:AA25))*AB26*AC26/SUMPRODUCT($AC26:$AC$55,$AB26:$AB$55)),""),"") -> 1 | AB26: 0.85310234 | AC26: 0.85310234
A27: Корж, Сейтджелилова | B27: 46056 | C27: вт | D27: 30122 | E27: 5 | F27: =IF(AND(E27<>"",E27<>0),D27/E27,"") -> 6024.4 | G27: 2 | H27: =IF(AND(G27<>"",G27<>0),D27/G27,"") -> 15061 | I27: 37 | J27: =IF(AND(G27<>"",G27<>0),E27/G27,"") -> 2.5 | M27: 23903 | S27: 6219 | T27: =IF(AND(I27<>"",I27<>0),G27/I27,"") -> 0.054054054 | U27: =D27/V27 -> 0.49053468 | V27: =$I$8*AB27*AC27/SUMPRODUCT($AC$25:$AC$55,$AB$25:$AB$55) -> 61406.463 | W27: =$I$9*AB27*AC27/SUMPRODUCT($AC$25:$AC$55,$AB$25:$AB$55) -> 8.4581905 | X27: =IF($I$12="","",W27/$I$12) -> 4.5968427 | Y27: =IF(AC27<>"",IF(D27<>"",D27,($I$8-SUM($Y$25:Y26))*AB27*AC27/SUMPRODUCT($AC27:$AC$55,$AB27:$AB$55)),"") -> 30122 | Z27: =IF(AC27<>"",IF(E27<>"",E27,($I$9-SUM($Z$25:Z26))*AB27*AC27/SUMPRODUCT($AC27:$AC$55,$AB27:$AB$55)),"") -> 5 | AA27: =IF(AC27<>"",IF($I$12<>"",IF(G27<>"",G27,($I$9/$I$12-SUM($AA$25:AA26))*AB27*AC27/SUMPRODUCT($AC27:$AC$55,$AB27:$AB$55)),""),"") -> 2 | AB27: 0.85310234 | AC27: 0.85310234
A28: Корж, Козлова | B28: 46057 | C28: ср | D28: 61757 | E28: 6 | F28: =IF(AND(E28<>"",E28<>0),D28/E28,"") -> 10292.833 | G28: 4 | H28: =IF(AND(G28<>"",G28<>0),D28/G28,"") -> 15439.25 | I28: 37 | J28: =IF(AND(G28<>"",G28<>0),E28/G28,"") -> 1.5 | R28: =14445+35593 -> 50038 | T28: =IF(AND(I28<>"",I28<>0),G28/I28,"") -> 0.10810811 | U28: =D28/V28 -> 1.0057085 | V28: =$I$8*AB28*AC28/SUMPRODUCT($AC$25:$AC$55,$AB$25:$AB$55) -> 61406.463 | W28: =$I$9*AB28*AC28/SUMPRODUCT($AC$25:$AC$55,$AB$25:$AB$55) -> 8.4581905 | X28: =IF($I$12="","",W28/$I$12) -> 4.5968427 | Y28: =IF(AC28<>"",IF(D28<>"",D28,($I$8-SUM($Y$25:Y27))*AB28*AC28/SUMPRODUCT($AC28:$AC$55,$AB28:$AB$55)),"") -> 61757 | Z28: =IF(AC28<>"",IF(E28<>"",E28,($I$9-SUM($Z$25:Z27))*AB28*AC28/SUMPRODUCT($AC28:$AC$55,$AB28:$AB$55)),"") -> 6 | AA28: =IF(AC28<>"",IF($I$12<>"",IF(G28<>"",G28,($I$9/$I$12-SUM($AA$25:AA27))*AB28*AC28/SUMPRODUCT($AC28:$AC$55,$AB28:$AB$55)),""),"") -> 4 | AB28: 0.85310234 | AC28: 0.85310234
A29: Корж, Козлова | B29: 46058 | C29: чт | D29: 8335 | E29: 2 | F29: =IF(AND(E29<>"",E29<>0),D29/E29,"") -> 4167.5 | G29: 2 | H29: =IF(AND(G29<>"",G29<>0),D29/G29,"") -> 4167.5 | I29: 34 | J29: =IF(AND(G29<>"",G29<>0),E29/G29,"") -> 1 | T29: =IF(AND(I29<>"",I29<>0),G29/I29,"") -> 0.058823529 | U29: =D29/V29 -> 0.13672752 | V29: =$I$8*AB29*AC29/SUMPRODUCT($AC$25:$AC$55,$AB$25:$AB$55) -> 60960.662 | W29: =$I$9*AB29*AC29/SUMPRODUCT($AC$25:$AC$55,$AB$25:$AB$55) -> 8.3967853 | X29: =IF($I$12="","",W29/$I$12) -> 4.5634703 | Y29: =IF(AC29<>"",IF(D29<>"",D29,($I$8-SUM($Y$25:Y28))*AB29*AC29/SUMPRODUCT($AC29:$AC$55,$AB29:$AB$55)),"") -> 8335 | Z29: =IF(AC29<>"",IF(E29<>"",E29,($I$9-SUM($Z$25:Z28))*AB29*AC29/SUMPRODUCT($AC29:$AC$55,$AB29:$AB$55)),"") -> 2 | AA29: =IF(AC29<>"",IF($I$12<>"",IF(G29<>"",G29,($I$9/$I$12-SUM($AA$25:AA28))*AB29*AC29/SUMPRODUCT($AC29:$AC$55,$AB29:$AB$55)),""),"") -> 2 | AB29: 0.85 | AC29: 0.85
A30: Корж, Сейтджелилова | B30: 46059 | C30: пт | D30: 4529 | E30: 1 | F30: =IF(AND(E30<>"",E30<>0),D30/E30,"") -> 4529 | G30: 1 | H30: =IF(AND(G30<>"",G30<>0),D30/G30,"") -> 4529 | I30: 51 | J30: =IF(AND(G30<>"",G30<>0),E30/G30,"") -> 1 | T30: =IF(AND(I30<>"",I30<>0),G30/I30,"") -> 0.019607843 | U30: =D30/V30 -> 0.05367728 | V30: =$I$8*AB30*AC30/SUMPRODUCT($AC$25:$AC$55,$AB$25:$AB$55) -> 84374.618 | W30: =$I$9*AB30*AC30/SUMPRODUCT($AC$25:$AC$55,$AB$25:$AB$55) -> 11.621848 | X30: =IF($I$12="","",W30/$I$12) -> 6.3162219 | Y30: =IF(AC30<>"",IF(D30<>"",D30,($I$8-SUM($Y$25:Y29))*AB30*AC30/SUMPRODUCT($AC30:$AC$55,$AB30:$AB$55)),"") -> 4529 | Z30: =IF(AC30<>"",IF(E30<>"",E30,($I$9-SUM($Z$25:Z29))*AB30*AC30/SUMPRODUCT($AC30:$AC$55,$AB30:$AB$55)),"") -> 1 | AA30: =IF(AC30<>"",IF($I$12<>"",IF(G30<>"",G30,($I$9/$I$12-SUM($AA$25:AA29))*AB30*AC30/SUMPRODUCT($AC30:$AC$55,$AB30:$AB$55)),""),"") -> 1 | AB30: 1 | AC30: 1
A31: Сейтджелилова, Козлова | B31: 46060 | C31: сб | D31: 42752 | E31: 6 | F31: =IF(AND(E31<>"",E31<>0),D31/E31,"") -> 7125.3333 | G31: 3 | H31: =IF(AND(G31<>"",G31<>0),D31/G31,"") -> 14250.667 | I31: 56 | J31: =IF(AND(G31<>"",G31<>0),E31/G31,"") -> 2 | M31: 15984 | T31: =IF(AND(I31<>"",I31<>0),G31/I31,"") -> 0.053571429 | U31: =D31/V31 -> 0.41875427 | V31: =$I$8*AB31*AC31/SUMPRODUCT($AC$25:$AC$55,$AB$25:$AB$55) -> 102093.29 | W31: =$I$9*AB31*AC31/SUMPRODUCT($AC$25:$AC$55,$AB$25:$AB$55) -> 14.062436 | X31: =IF($I$12="","",W31/$I$12) -> 7.6426285 | Y31: =IF(AC31<>"",IF(D31<>"",D31,($I$8-SUM($Y$25:Y30))*AB31*AC31/SUMPRODUCT($AC31:$AC$55,$AB31:$AB$55)),"") -> 42752 | Z31: =IF(AC31<>"",IF(E31<>"",E31,($I$9-SUM($Z$25:Z30))*AB31*AC31/SUMPRODUCT($AC31:$AC$55,$AB31:$AB$55)),"") -> 6 | AA31: =IF(AC31<>"",IF($I$12<>"",IF(G31<>"",G31,($I$9/$I$12-SUM($AA$25:AA30))*AB31*AC31/SUMPRODUCT($AC31:$AC$55,$AB31:$AB$55)),""),"") -> 3 | AB31: 1.1 | AC31: 1.1
A32: Сейтджелилова, Козлова | B32: 46061 | C32: вс | D32: 31503 | E32: 5 | F32: =IF(AND(E32<>"",E32<>0),D32/E32,"") -> 6300.6 | G32: 3 | H32: =IF(AND(G32<>"",G32<>0),D32/G32,"") -> 10501 | I32: 60 | J32: =IF(AND(G32<>"",G32<>0),E32/G32,"") -> 1.6666667 | T32: =IF(AND(I32<>"",I32<>0),G32/I32,"") -> 0.05 | U32: =D32/V32 -> 0.42125066 | V32: =$I$8*AB32*AC32/SUMPRODUCT($AC$25:$AC$55,$AB$25:$AB$55) -> 74784.453 | W32: =$I$9*AB32*AC32/SUMPRODUCT($AC$25:$AC$55,$AB$25:$AB$55) -> 10.300889 | X32: =IF($I$12="","",W32/$I$12) -> 5.5983092 | Y32: =IF(AC32<>"",IF(D32<>"",D32,($I$8-SUM($Y$25:Y31))*AB32*AC32/SUMPRODUCT($AC32:$AC$55,$AB32:$AB$55)),"") -> 31503 | Z32: =IF(AC32<>"",IF(E32<>"",E32,($I$9-SUM($Z$25:Z31))*AB32*AC32/SUMPRODUCT($AC32:$AC$55,$AB32:$AB$55)),"") -> 5 | AA32: =IF(AC32<>"",IF($I$12<>"",IF(G32<>"",G32,($I$9/$I$12-SUM($AA$25:AA31))*AB32*AC32/SUMPRODUCT($AC32:$AC$55,$AB32:$AB$55)),""),"") -> 3 | AB32: 0.9414554 | AC32: 0.9414554
A33: Козлова, Корж | B33: 46062 | C33: пн | D33: 0 | E33: 0 | F33: =IF(AND(E33<>"",E33<>0),D33/E33,"") | G33: 0 | H33: =IF(AND(G33<>"",G33<>0),D33/G33,"") | I33: 39 | J33: =IF(AND(G33<>"",G33<>0),E33/G33,"") | T33: =IF(AND(I33<>"",I33<>0),G33/I33,"") -> 0 | U33: =D33/V33 -> 0 | V33: =$I$8*AB33*AC33/SUMPRODUCT($AC$25:$AC$55,$AB$25:$AB$55) -> 47460.723 | W33: =$I$9*AB33*AC33/SUMPRODUCT($AC$25:$AC$55,$AB$25:$AB$55) -> 6.5372896 | X33: =IF($I$12="","",W33/$I$12) -> 3.5528748 | Y33: =IF(AC33<>"",IF(D33<>"",D33,($I$8-SUM($Y$25:Y32))*AB33*AC33/SUMPRODUCT($AC33:$AC$55,$AB33:$AB$55)),"") -> 0 | Z33: =IF(AC33<>"",IF(E33<>"",E33,($I$9-SUM($Z$25:Z32))*AB33*AC33/SUMPRODUCT($AC33:$AC$55,$AB33:$AB$55)),"") -> 0 | AA33: =IF(AC33<>"",IF($I$12<>"",IF(G33<>"",G33,($I$9/$I$12-SUM($AA$25:AA32))*AB33*AC33/SUMPRODUCT($AC33:$AC$55,$AB33:$AB$55)),""),"") -> 0 | AB33: 0.75 | AC33: 0.75
A34: Свидовская, Сейтджелилова | B34: 46063 | C34: вт | D34: 44550 | E34: 6 | F34: =IF(AND(E34<>"",E34<>0),D34/E34,"") -> 7425 | G34: 4 | H34: =IF(AND(G34<>"",G34<>0),D34/G34,"") -> 11137.5 | I34: 51 | J34: =IF(AND(G34<>"",G34<>0),E34/G34,"") -> 1.5 | Q34: 9776.78 | T34: =IF(AND(I34<>"",I34<>0),G34/I34,"") -> 0.078431373 | U34: =D34/V34 -> 0.93867092 | V34: =$I$8*AB34*AC34/SUMPRODUCT($AC$25:$AC$55,$AB$25:$AB$55) -> 47460.723 | W34: =$I$9*AB34*AC34/SUMPRODUCT($AC$25:$AC$55,$AB$25:$AB$55) -> 6.5372896 | X34: =IF($I$12="","",W34/$I$12) -> 3.5528748 | Y34: =IF(AC34<>"",IF(D34<>"",D34,($I$8-SUM($Y$25:Y33))*AB34*AC34/SUMPRODUCT($AC34:$AC$55,$AB34:$AB$55)),"") -> 44550 | Z34: =IF(AC34<>"",IF(E34<>"",E34,($I$9-SUM($Z$25:Z33))*AB34*AC34/SUMPRODUCT($AC34:$AC$55,$AB34:$AB$55)),"") -> 6 | AA34: =IF(AC34<>"",IF($I$12<>"",IF(G34<>"",G34,($I$9/$I$12-SUM($AA$25:AA33))*AB34*AC34/SUMPRODUCT($AC34:$AC$55,$AB34:$AB$55)),""),"") -> 4 | AB34: 0.75 | AC34: 0.75
A35: Свидовская, Сейтджелилова | B35: 46064 | C35: ср | D35: =5692+4741 -> 10433 | E35: 2 | F35: =IF(AND(E35<>"",E35<>0),D35/E35,"") -> 5216.5 | G35: 2 | H35: =IF(AND(G35<>"",G35<>0),D35/G35,"") -> 5216.5 | I35: 54 | J35: =IF(AND(G35<>"",G35<>0),E35/G35,"") -> 1 | T35: =IF(AND(I35<>"",I35<>0),G35/I35,"") -> 0.037037037 | U35: =D35/V35 -> 0.19320458 | V35: =$I$8*AB35*AC35/SUMPRODUCT($AC$25:$AC$55,$AB$25:$AB$55) -> 53999.756 | W35: =$I$9*AB35*AC35/SUMPRODUCT($AC$25:$AC$55,$AB$25:$AB$55) -> 7.4379829 | X35: =IF($I$12="","",W35/$I$12) -> 4.042382 | Y35: =IF(AC35<>"",IF(D35<>"",D35,($I$8-SUM($Y$25:Y34))*AB35*AC35/SUMPRODUCT($AC35:$AC$55,$AB35:$AB$55)),"") -> 10433 | Z35: =IF(AC35<>"",IF(E35<>"",E35,($I$9-SUM($Z$25:Z34))*AB35*AC35/SUMPRODUCT($AC35:$AC$55,$AB35:$AB$55)),"") -> 2 | AA35: =IF(AC35<>"",IF($I$12<>"",IF(G35<>"",G35,($I$9/$I$12-SUM($AA$25:AA34))*AB35*AC35/SUMPRODUCT($AC35:$AC$55,$AB35:$AB$55)),""),"") -> 2 | AB35: 0.8 | AC35: 0.8
A36: Корж, Свидовская | B36: 46065 | C36: чт | D36: =181056+27344 -> 208400 | E36: 14 | F36: =IF(AND(E36<>"",E36<>0),D36/E36,"") -> 14885.714 | G36: 4 | H36: =IF(AND(G36<>"",G36<>0),D36/G36,"") -> 52100 | I36: 41 | J36: =IF(AND(G36<>"",G36<>0),E36/G36,"") -> 3.5 | K36: 62658 | L36: 15902 | M36: 23181 | R36: 79315 | S36: 1647 | T36: =IF(AND(I36<>"",I36<>0),G36/I36,"") -> 0.097560976 | U36: =D36/V36 -> 3.8592767 | V36: =$I$8*AB36*AC36/SUMPRODUCT($AC$25:$AC$55,$AB$25:$AB$55) -> 53999.756 | W36: =$I$9*AB36*AC36/SUMPRODUCT($AC$25:$AC$55,$AB$25:$AB$55) -> 7.4379829 | X36: =IF($I$12="","",W36/$I$12) -> 4.042382 | Y36: =IF(AC36<>"",IF(D36<>"",D36,($I$8-SUM($Y$25:Y35))*AB36*AC36/SUMPRODUCT($AC36:$AC$55,$AB36:$AB$55)),"") -> 208400 | Z36: =IF(AC36<>"",IF(E35<>"",E35,($I$9-SUM($Z$25:Z35))*AB36*AC36/SUMPRODUCT($AC36:$AC$55,$AB36:$AB$55)),"") -> 2 | AA36: =IF(AC36<>"",IF($I$12<>"",IF(G36<>"",G36,($I$9/$I$12-SUM($AA$25:AA35))*AB36*AC36/SUMPRODUCT($AC36:$AC$55,$AB36:$AB$55)),""),"") -> 4 | AB36: 0.8 | AC36: 0.8
A37: Корж, Свидовская | B37: 46066 | C37: пт | D37: =48975+10982 -> 59957 | E37: 9 | F37: =IF(AND(E37<>"",E37<>0),D37/E37,"") -> 6661.8889 | G37: 6 | H37: =IF(AND(G37<>"",G37<>0),D37/G37,"") -> 9992.8333 | I37: 71 | J37: =IF(AND(G37<>"",G37<>0),E37/G37,"") -> 1.5 | M37: 10982 | T37: =IF(AND(I37<>"",I37<>0),G37/I37,"") -> 0.084507042 | U37: =D37/V37 -> 0.7106047 | V37: =$I$8*AB37*AC37/SUMPRODUCT($AC$25:$AC$55,$AB$25:$AB$55) -> 84374.618 | W37: =$I$9*AB37*AC37/SUMPRODUCT($AC$25:$AC$55,$AB$25:$AB$55) -> 11.621848 | X37: =IF($I$12="","",W37/$I$12) -> 6.3162219 | Y37: =IF(AC37<>"",IF(D37<>"",D37,($I$8-SUM($Y$25:Y36))*AB37*AC37/SUMPRODUCT($AC37:$AC$55,$AB37:$AB$55)),"") -> 59957 | Z37: =IF(AC37<>"",IF(E37<>"",E37,($I$9-SUM($Z$25:Z36))*AB37*AC37/SUMPRODUCT($AC37:$AC$55,$AB37:$AB$55)),"") -> 9 | AA37: =IF(AC37<>"",IF($I$12<>"",IF(G37<>"",G37,($I$9/$I$12-SUM($AA$25:AA36))*AB37*AC37/SUMPRODUCT($AC37:$AC$55,$AB37:$AB$55)),""),"") -> 6 | AB37: 1 | AC37: 1
A38: Корж, Сейтджелилова | B38: 46067 | C38: сб | D38: 38589 | E38: 4 | F38: =IF(AND(E38<>"",E38<>0),D38/E38,"") -> 9647.25 | G38: 3 | H38: =IF(AND(G38<>"",G38<>0),D38/G38,"") -> 12863 | I38: 51 | J38: =IF(AND(G38<>"",G38<>0),E38/G38,"") -> 1.3333333 | T38: =IF(AND(I38<>"",I38<>0),G38/I38,"") -> 0.058823529 | U38: =D38/V38 -> 0.37797784 | V38: =$I$8*AB38*AC38/SUMPRODUCT($AC$25:$AC$55,$AB$25:$AB$55) -> 102093.29 | W38: =$I$9*AB38*AC38/SUMPRODUCT($AC$25:$AC$55,$AB$25:$AB$55) -> 14.062436 | X38: =IF($I$12="","",W38/$I$12) -> 7.6426285 | Y38: =IF(AC38<>"",IF(D38<>"",D38,($I$8-SUM($Y$25:Y37))*AB38*AC38/SUMPRODUCT($AC38:$AC$55,$AB38:$AB$55)),"") -> 38589 | Z38: =IF(AC38<>"",IF(E38<>"",E38,($I$9-SUM($Z$25:Z37))*AB38*AC38/SUMPRODUCT($AC38:$AC$55,$AB38:$AB$55)),"") -> 4 | AA38: =IF(AC38<>"",IF($I$12<>"",IF(G38<>"",G38,($I$9/$I$12-SUM($AA$25:AA37))*AB38*AC38/SUMPRODUCT($AC38:$AC$55,$AB38:$AB$55)),""),"") -> 3 | AB38: 1.1 | AC38: 1.1
A39: Корж, Сейтджелилова | B39: 46068 | C39: вс | D39: 3193 | E39: 1 | F39: =IF(AND(E39<>"",E39<>0),D39/E39,"") -> 3193 | G39: 1 | H39: =IF(AND(G39<>"",G39<>0),D39/G39,"") -> 3193 | I39: 67 | J39: =IF(AND(G39<>"",G39<>0),E39/G39,"") -> 1 | T39: =IF(AND(I39<>"",I39<>0),G39/I39,"") -> 0.014925373 | U39: =D39/V39 -> 0.04269604 | V39: =$I$8*AB39*AC39/SUMPRODUCT($AC$25:$AC$55,$AB$25:$AB$55) -> 74784.453 | W39: =$I$9*AB39*AC39/SUMPRODUCT($AC$25:$AC$55,$AB$25:$AB$55) -> 10.300889 | X39: =IF($I$12="","",W39/$I$12) -> 5.5983092 | Y39: =IF(AC39<>"",IF(D39<>"",D39,($I$8-SUM($Y$25:Y38))*AB39*AC39/SUMPRODUCT($AC39:$AC$55,$AB39:$AB$55)),"") -> 3193 | Z39: =IF(AC39<>"",IF(E39<>"",E39,($I$9-SUM($Z$25:Z38))*AB39*AC39/SUMPRODUCT($AC39:$AC$55,$AB39:$AB$55)),"") -> 1 | AA39: =IF(AC39<>"",IF($I$12<>"",IF(G39<>"",G39,($I$9/$I$12-SUM($AA$25:AA38))*AB39*AC39/SUMPRODUCT($AC39:$AC$55,$AB39:$AB$55)),""),"") -> 1 | AB39: 0.9414554 | AC39: 0.9414554
A40: Свидовская, Сейтджелилова | B40: 46069 | C40: пн | D40: 32673 | E40: 3 | F40: =IF(AND(E40<>"",E40<>0),D40/E40,"") -> 10891 | G40: 2 | H40: =IF(AND(G40<>"",G40<>0),D40/G40,"") -> 16336.5 | I40: 42 | J40: =IF(AND(G40<>"",G40<>0),E40/G40,"") -> 1.5 | M40: 27672 | T40: =IF(AND(I40<>"",I40<>0),G40/I40,"") -> 0.047619048 | U40: =D40/V40 -> 0.68842188 | V40: =$I$8*AB40*AC40/SUMPRODUCT($AC$25:$AC$55,$AB$25:$AB$55) -> 47460.723 | W40: =$I$9*AB40*AC40/SUMPRODUCT($AC$25:$AC$55,$AB$25:$AB$55) -> 6.5372896 | X40: =IF($I$12="","",W40/$I$12) -> 3.5528748 | Y40: =IF(AC40<>"",IF(D40<>"",D40,($I$8-SUM($Y$25:Y39))*AB40*AC40/SUMPRODUCT($AC40:$AC$55,$AB40:$AB$55)),"") -> 32673 | Z40: =IF(AC40<>"",IF(E40<>"",E40,($I$9-SUM($Z$25:Z39))*AB40*AC40/SUMPRODUCT($AC40:$AC$55,$AB40:$AB$55)),"") -> 3 | AA40: =IF(AC40<>"",IF($I$12<>"",IF(G40<>"",G40,($I$9/$I$12-SUM($AA$25:AA39))*AB40*AC40/SUMPRODUCT($AC40:$AC$55,$AB40:$AB$55)),""),"") -> 2 | AB40: 0.75 | AC40: 0.75
A41: Свидовская, Сейтджелилова | B41: 46070 | C41: вт | D41: 21121 | E41: 3 | F41: =IF(AND(E41<>"",E41<>0),D41/E41,"") -> 7040.3333 | G41: 2 | H41: =IF(AND(G41<>"",G41<>0),D41/G41,"") -> 10560.5 | I41: 35 | J41: =IF(AND(G41<>"",G41<>0),E41/G41,"") -> 1.5 | Q41: 7605 | T41: =IF(AND(I41<>"",I41<>0),G41/I41,"") -> 0.057142857 | U41: =D41/V41 -> 0.3911314 | V41: =$I$8*AB41*AC41/SUMPRODUCT($AC$25:$AC$55,$AB$25:$AB$55) -> 53999.756 | W41: =$I$9*AB41*AC41/SUMPRODUCT($AC$25:$AC$55,$AB$25:$AB$55) -> 7.4379829 | X41: =IF($I$12="","",W41/$I$12) -> 4.042382 | Y41: =IF(AC41<>"",IF(D41<>"",D41,($I$8-SUM($Y$25:Y40))*AB41*AC41/SUMPRODUCT($AC41:$AC$55,$AB41:$AB$55)),"") -> 21121 | Z41: =IF(AC41<>"",IF(E41<>"",E41,($I$9-SUM($Z$25:Z40))*AB41*AC41/SUMPRODUCT($AC41:$AC$55,$AB41:$AB$55)),"") -> 3 | AA41: =IF(AC41<>"",IF($I$12<>"",IF(G41<>"",G41,($I$9/$I$12-SUM($AA$25:AA40))*AB41*AC41/SUMPRODUCT($AC41:$AC$55,$AB41:$AB$55)),""),"") -> 2 | AB41: 0.8 | AC41: 0.8
A42: Свидовская, Корж | B42: 46071 | C42: ср | D42: 0 | E42: 0 | F42: =IF(AND(E42<>"",E42<>0),D42/E42,"") | G42: 0 | H42: =IF(AND(G42<>"",G42<>0),D42/G42,"") | I42: 49 | J42: =IF(AND(G42<>"",G42<>0),E42/G42,"") | T42: =IF(AND(I42<>"",I42<>0),G42/I42,"") -> 0 | U42: =D42/V42 -> 0 | V42: =$I$8*AB42*AC42/SUMPRODUCT($AC$25:$AC$55,$AB$25:$AB$55) -> 61406.463 | W42: =$I$9*AB42*AC42/SUMPRODUCT($AC$25:$AC$55,$AB$25:$AB$55) -> 8.4581905 | X42: =IF($I$12="","",W42/$I$12) -> 4.5968427 | Y42: =IF(AC42<>"",IF(D42<>"",D42,($I$8-SUM($Y$25:Y41))*AB42*AC42/SUMPRODUCT($AC42:$AC$55,$AB42:$AB$55)),"") -> 0 | Z42: =IF(AC42<>"",IF(E42<>"",E42,($I$9-SUM($Z$25:Z41))*AB42*AC42/SUMPRODUCT($AC42:$AC$55,$AB42:$AB$55)),"") -> 0 | AA42: =IF(AC42<>"",IF($I$12<>"",IF(G42<>"",G42,($I$9/$I$12-SUM($AA$25:AA41))*AB42*AC42/SUMPRODUCT($AC42:$AC$55,$AB42:$AB$55)),""),"") -> 0 | AB42: 0.85310234 | AC42: 0.85310234
...

Sheet Сводная
A1: Сводная по показателям
A2: Показатель | D2: =Центрум!I3 -> ТРК Центрум | G2: =График!B27 -> Свидовская София | J2: =График!B25 -> Корж Анастасия | M2: =График!B26 -> Козлова Валерия | P2: =График!B28 -> Сейтджелилова Алина
D3: Факт | F3: Прогноз | G3: Факт | I3: Прогноз | J3: Факт | L3: Прогноз | M3: Факт | O3: Прогноз | P3: Факт | R3: Прогноз
A4: Выручка | D4: =Центрум!K8 -> 0.45158263 | E4: =Центрум!J8 -> 844539 | F4: =Центрум!M8 -> 0.45158263 | G4: ='Свидовская С. А.'!K8 -> 0.54678117 | H4: ='Свидовская С. А.'!J8 -> 248592 | I4: ='Свидовская С. А.'!M8 -> 0.57304159 | J4: ='Корж А. А.'!K8 -> 0.5188328 | K4: ='Корж А. А.'!J8 -> 309495 | L4: ='Корж А. А.'!M8 -> 0.53771899 | M4: ='Козлова В. Э.'!K8 -> 0.26437681 | N4: ='Козлова В. Э.'!J8 -> 65640 | O4: ='Козлова В. Э.'!M8 -> 0.30839097 | P4: =ПК4!K8 -> 0 | Q4: =ПК4!J8 -> 0 | R4: =ПК4!M8 -> 0
A5: Кол-во изделий | D5: =Центрум!K9 -> 0.41149068 | E5: =Центрум!J9 -> 106 | F5: =Центрум!M9 -> 0.41149068 | G5: ='Свидовская С. А.'!K9 -> 0.52695916 | H5: ='Свидовская С. А.'!J9 -> 33 | I5: ='Свидовская С. А.'!M9 -> 0.5339265 | J5: ='Корж А. А.'!K9 -> 0.35294611 | K5: ='Корж А. А.'!J9 -> 29 | L5: ='Корж А. А.'!M9 -> 0.35656212 | M5: ='Козлова В. Э.'!K9 -> 0.23392756 | N5: ='Козлова В. Э.'!J9 -> 8 | O5: ='Козлова В. Э.'!M9 -> 0.27287245 | P5: =ПК4!K9 -> 0 | Q5: =ПК4!J9 -> 0 | R5: =ПК4!M9
A6: Средний чек | D6: =Центрум!K10 -> 0.91625462 | E6: =Центрум!J10 -> 12239.696 | F6: =Центрум!M10 -> 0.91625462 | G6: ='Свидовская С. А.'!K10 -> 0.80910497 | H6: ='Свидовская С. А.'!J10 -> 10808.348 | I6: ='Свидовская С. А.'!M10 -> 0.80910497 | J6: ='Корж А. А.'!K10 -> 1.2871427 | K6: ='Корж А. А.'!J10 -> 17194.167 | L6: ='Корж А. А.'!M10 -> 1.2871427 | M6: ='Козлова В. Э.'!K10 -> 0.81896035 | N6: ='Козлова В. Э.'!J10 -> 10940 | O6: ='Козлова В. Э.'!M10 -> 0.81896035 | P6: =ПК4!K10 | Q6: =ПК4!J10 | R6: =ПК4!M10
A7: Средняя стоимость изделия | D7: =Центрум!K11 -> 1.097431 | E7: =Центрум!J11 -> 7967.3491 | F7: =Центрум!M11 -> 1.097431 | G7: ='Свидовская С. А.'!K11 -> 1.0376158 | H7: ='Свидовская С. А.'!J11 -> 7533.0909 | I7: ='Свидовская С. А.'!M11 -> 1.0376158 | J7: ='Корж А. А.'!K11 -> 1.4700057 | K7: ='Корж А. А.'!J11 -> 10672.241 | L7: ='Корж А. А.'!M11 -> 1.4700057 | M7: ='Козлова В. Э.'!K11 -> 1.1301653 | N7: ='Козлова В. Э.'!J11 -> 8205 | O7: ='Козлова В. Э.'!M11 -> 1.1301653 | P7: =ПК4!K11 | Q7: =ПК4!J11 | R7: =ПК4!M11
A8: Длина чека | D8: =Центрум!K12 -> 0.83490863 | E8: =Центрум!J12 -> 1.5362319 | F8: =Центрум!M12 -> 0.83490863 | G8: ='Свидовская С. А.'!K12 -> 0.77977316 | H8: ='Свидовская С. А.'!J12 -> 1.4347826 | I8: ='Свидовская С. А.'!M12 -> 0.77977316 | J8: ='Корж А. А.'!K12 -> 0.87560386 | K8: ='Корж А. А.'!J12 -> 1.6111111 | L8: ='Корж А. А.'!M12 -> 0.87560386 | M8: ='Козлова В. Э.'!K12 -> 0.72463768 | N8: ='Козлова В. Э.'!J12 -> 1.3333333 | O8: ='Козлова В. Э.'!M12 -> 0.72463768 | P8: =ПК4!K12 | Q8: =ПК4!J12 | R8: =ПК4!M12
A9: Кол-во чеков | D9: =Центрум!K13 -> 0.49285714 | E9: =Центрум!J13 -> 69 | F9: =Центрум!M13 -> 0.49285714 | G9: ='Свидовская С. А.'!K13 -> 0.67578521 | H9: ='Свидовская С. А.'!J13 -> 23 | I9: ='Свидовская С. А.'!M13 -> 0.68828385 | J9: ='Корж А. А.'!K13 -> 0.4030888 | K9: ='Корж А. А.'!J13 -> 18 | L9: ='Корж А. А.'!M13 -> 0.40882705 | M9: ='Козлова В. Э.'!K13 -> 0.32282004 | N9: ='Козлова В. Э.'!J13 -> 6 | O9: ='Козлова В. Э.'!M13 -> 0.37656398 | P9: =ПК4!K13 -> 0 | Q9: =ПК4!J13 -> 0 | R9: =ПК4!M13
A10: Кол-во смен план/отработано | D10: =Центрум!K14 -> 1 | E10: =Центрум!J14 -> 28 | G10: ='Свидовская С. А.'!K14 -> 1 | H10: ='Свидовская С. А.'!J14 -> 13 | J10: ='Корж А. А.'!K14 -> 1 | K10: ='Корж А. А.'!J14 -> 17 | M10: ='Козлова В. Э.'!K14 -> 1 | N10: ='Козлова В. Э.'!J14 -> 7 | P10: =ПК4!K14 -> 0.25 | Q10: =ПК4!J14 -> 5
A11: Средние продажи в смену | D11: =Центрум!K15 -> 0.45158263 | E11: =Центрум!J15 -> 30162.107 | F11: =Центрум!M15 -> 0.45158263 | G11: ='Свидовская С. А.'!K15 -> 0.57259736 | H11: ='Свидовская С. А.'!J15 -> 19122.462 | I11: ='Свидовская С. А.'!M15 -> 0.57259736 | J11: ='Корж А. А.'!K15 -> 0.54514278 | K11: ='Корж А. А.'!J15 -> 18205.588 | L11: ='Корж А. А.'!M15 -> 0.54514278 | M11: ='Козлова В. Э.'!K15 -> 0.28078641 | N11: ='Козлова В. Э.'!J15 -> 9377.1429 | O11: ='Козлова В. Э.'!M15 -> 0.28078641 | P11: =ПК4!K15 -> 0 | Q11: =ПК4!J15 -> 0 | R11: =ПК4!M15
A12: Отставание/Перевыполнение | D12: =Центрум!J16 -> -1025637 | G12: ='Свидовская С. А.'!N8 -> -194115.03 | J12: ='Корж А. А.'!N8 -> -275760.63 | M12: ='Козлова В. Э.'!N8 -> -171714.06 | P12: =ПК4!N8

Sheet Справочник магазинов
A1: МЕГА Белая Дача
A2: Гагаринский
A3: Марфино

Sheet План на день
A1: Выручка | D1: =86000 -> 86000
A2: Кол-во изделий | D2: =D1/D4 -> 11.84573
A3: Средний чек | D3: =D4*D5 -> 13358.4
A4: Средняя стоимость изделия | D4: =Центрум!I11 -> 7260
A5: Длина чека | D5: =Центрум!I12 -> 1.84
A6: Кол-во чеков | D6: =IF(D5<>0,D2/D5,"") -> 6.4378968
A7: Конверсия | D7: =Центрум!I20 -> 0.1

Sheet Сейтджелилова А.Э.
B1: =TODAY()-1 -> 46171
B2: (отчетная дата) | J2: ЕЖЕДНЕВНЫЙ ОТЧЕТ О ПРОДАЖАХ
B3: Осталось до выполнения плана!!! | J3: =График!B28 -> Сейтджелилова Алина
C4: =I8-D49 -> 357334.12 | E4: =IF(I8<>0,C4/I8,0) -> 0.62610438
F6: Целевые показатели
F7: Показатель | I7: План | J7: Факт | K7: % выполнения | L7: Прогноз выполнения | M7: % выполнения по прогнозу | N7: Отклонение | O7: Факт аналогичного месяца прошлого года | P7: Отклонение LFL
F8: Выручка | I8: =Центрум!I8/График!AJ29*График!AJ28 -> 570726.12 | J8: =D49 -> 213392 | K8: =IF(AND(I8<>"",I8<>0,J8<>""),J8/I8,"") -> 0.37389562 | L8: =IF(SUMIF($D$25:$D$47,">=0",$V$25:$V$47)<>0,I8*D49/SUMIF($D$25:$D$47,">=0",$V$25:$V$47),0) -> 213392 | M8: =L8/I8 -> 0.37389562 | N8: =IF(AND(J8<>0,J8<>"",I8<>0,I8<>""),L8-I8,"") -> -357334.12 | P8: =IF(AND(O8<>"",O8<>0,L8<>"",L8<>0),-O8+L8,"") | Q8: =IF(AND(P8<>"",P8<>0,O8<>0,O8<>""),P8/O8,"")
F9: Кол-во изделий | I9: =I8/I11 -> 78.612414 | J9: =E49 -> 35 | K9: =IF(AND(I9<>"",I9<>0,J9<>""),J9/I9,"") -> 0.4452223 | L9: =IF(SUMIF($E$25:$E$47,">=0",$W$25:$W$47)<>0,I9*E49/SUMIF($E$25:$E$47,">=0",$W$25:$W$47),0) -> 35 | M9: =IF(AND(I9<>"",I9<>0,L9<>"",L9<>0),L9/I9,"") -> 0.4452223 | N9: =IF(AND(J9<>0,J9<>"",I9<>0,I9<>""),L9-I9,"") -> -43.612414 | O9: =O8/O11 -> #DIV/0! | P9: =IF(AND(O9<>"",O9<>0,L9<>"",L9<>0),-O9+L9,"") -> #DIV/0! | Q9: =IF(AND(P9<>"",P9<>0,O9<>0,O9<>""),P9/O9,"") -> #DIV/0!
F10: Средний чек | I10: =I11*I12 -> 13358.4 | J10: =H49 -> 9277.913 | K10: =IF(AND(I10<>"",I10<>0,J10<>""),J10/I10,"") -> 0.69453775 | L10: =J10 -> 9277.913 | M10: =IF(AND(I10<>"",I10<>0,L10<>"",L10<>0),L10/I10,"") -> 0.69453775 | N10: =IF(AND(J10<>0,J10<>"",I10<>0,I10<>""),L10-I10,"") -> -4080.487 | O10: =O11*O12 -> 0 | P10: =IF(AND(O10<>"",O10<>0,L10<>"",L10<>0),-O10+L10,"") | Q10: =IF(AND(P10<>"",P10<>0,O10<>0,O10<>""),P10/O10,"")
F11: Средняя стоимость изделия | I11: =Центрум!I11 -> 7260 | J11: =F49 -> 6096.9143 | K11: =IF(AND(I11<>"",I11<>0,J11<>""),J11/I11,"") -> 0.83979536 | L11: =J11 -> 6096.9143 | M11: =IF(AND(I11<>"",I11<>0,L11<>"",L11<>0),L11/I11,"") -> 0.83979536 | N11: =IF(AND(J11<>0,J11<>"",I11<>0,I11<>""),L11-I11,"") -> -1163.0857 | P11: =IF(AND(O11<>"",O11<>0,L11<>"",L11<>0),-O11+L11,"") | Q11: =IF(AND(P11<>"",P11<>0,O11<>0,O11<>""),P11/O11,"")
F12: Длина чека | I12: =Центрум!I12 -> 1.84 | J12: =J49 -> 1.5217391 | K12: =IF(AND(I12<>"",I12<>0,J12<>""),J12/I12,"") -> 0.82703214 | L12: =J12 -> 1.5217391 | M12: =IF(AND(I12<>"",I12<>0,L12<>"",L12<>0),L12/I12,"") -> 0.82703214 | N12: =IF(AND(J12<>0,J12<>"",I12<>0,I12<>""),L12-I12,"") -> -0.31826087 | P12: =IF(AND(O12<>"",O12<>0,L12<>"",L12<>0),-O12+L12,"") | Q12: =IF(AND(P12<>"",P12<>0,O12<>0,O12<>""),P12/O12,"")
F13: Кол-во чеков | I13: =IF(I12<>0,I9/I12,"") -> 42.724138 | J13: =G49 -> 23 | K13: =IF(AND(I13<>"",I13<>0,J13<>""),J13/I13,"") -> 0.53833737 | L13: =IF(SUMIF($G$25:$G$47,">=0",$X$25:$X$47)<>0,I13*G49/SUMIF($G$25:$G$47,">=0",$X$25:$X$47),"") -> 23 | M13: =IF(AND(I13<>"",I13<>0,L13<>"",L13<>0),L13/I13,"") -> 0.53833737 | N13: =IF(AND(J13<>0,J13<>"",I13<>0,I13<>""),L13-I13,"") -> -19.724138 | P13: =IF(AND(O13<>"",O13<>0,L13<>"",L13<>0),-O13+L13,"") | Q13: =IF(AND(P13<>"",P13<>0,O13<>0,O13<>""),P13/O13,"")
F14: Кол-во смен план/отработано | I14: =График!AI28 -> 20 | J14: 20 | K14: =IF(AND(I14<>"",I14<>0,J14<>""),J14/I14,"") -> 1 | L14: =IF(SUMIF($D$25:$D$47,">=0",$V$25:$V$47),I49*I8/SUMIF($D$25:$D$47,">=0",$V$25:$V$47),"") -> 280 | N14: =IF(AND(J14<>0,J14<>"",I14<>0,I14<>""),L14-I14,"") -> 260 | P14: =IF(AND(O14<>"",O14<>0,L14<>"",L14<>0),-O14+L14,"") | Q14: =IF(AND(P14<>"",P14<>0,O14<>0,O14<>""),P14/O14,"")
F15: Средние продажи в смену | I15: =Центрум!I15/2 -> 33396 | J15: =J8/J14 -> 10669.6 | K15: =IF(AND(I15<>"",I15<>0,J15<>""),J15/I15,"") -> 0.31948736 | L15: =J15 -> 10669.6 | M15: =IF(AND(I15<>"",I15<>0,L15<>"",L15<>0),L15/I15,"") -> 0.31948736 | N15: =IF(AND(J15<>0,J15<>"",I15<>0,I15<>""),L15-I15,"") -> -22726.4 | P15: =IF(AND(O15<>"",O15<>0,L15<>"",L15<>0),-O15+L15,"") | Q15: =IF(AND(P15<>"",P15<>0,O15<>0,O15<>""),P15/O15,"")
F16: Отставание/Перевыполнение | J16: =J8-I15*J14 -> -454528 | K16: =IF(AND(I16<>"",I16<>0,J16<>""),J16/I16,"") | L16: =J16 -> -454528 | M16: =IF(AND(I16<>"",I16<>0,L16<>"",L16<>0),L16/I16,"") | N16: =IF(AND(J16<>0,J16<>"",I16<>0,I16<>""),L16-I16,"") | P16: =IF(AND(O16<>"",O16<>0,L16<>"",L16<>0),-O16+L16,"") | Q16: =IF(AND(P16<>"",P16<>0,O16<>0,O16<>""),P16/O16,"") | U16: Подарочные сертификаты
F17: Трафик | I17: =Центрум!I17/График!AJ29*График!AJ23 -> 0 | J17: =I49 -> 280 | K17: =IF(AND(I17<>"",I17<>0,J17<>""),J17/I17,"") | L17: =J17/J14*I14 -> 280 | M17: =IF(AND(I17<>"",I17<>0,L17<>"",L17<>0),L17/I17,"") | N17: =IF(AND(J17<>0,J17<>"",I17<>0,I17<>""),L17-I17,"") | P17: =IF(AND(O17<>"",O17<>0,L17<>"",L17<>0),-O17+L17,"") | Q17: =IF(AND(P17<>"",P17<>0,O17<>0,O17<>""),P17/O17,"")
K18: =IF(AND(I18<>"",I18<>0,J18<>""),J18/I18,"") | L18: =J18 -> 0 | M18: =IF(AND(I18<>"",I18<>0,L18<>"",L18<>0),L18/I18,"") | N18: =IF(AND(J18<>0,J18<>"",I18<>0,I18<>""),L18-I18,"") | O18: 0 | P18: =IF(AND(O18<>"",O18<>0,L18<>"",L18<>0),-O18+L18,"") | Q18: =IF(AND(P18<>"",P18<>0,O18<>0,O18<>""),P18/O18,"")
J19: =P49 -> 0 | K19: =IF(AND(I19<>"",I19<>0,J19<>""),J19/I19,"") | L19: =J19 -> 0 | M19: =IF(AND(I19<>"",I19<>0,L19<>"",L19<>0),L19/I19,"") | N19: =IF(AND(J19<>0,J19<>"",I19<>0,I19<>""),L19-I19,"") | O19: 0 | P19: =IF(AND(O19<>"",O19<>0,L19<>"",L19<>0),-O19+L19,"") | Q19: =IF(AND(P19<>"",P19<>0,O19<>0,O19<>""),P19/O19,"") | U19: =U18/I16 -> #DIV/0!
F20: Конверсия план/факт | I20: =Центрум!I20 -> 0.1 | J20: =T49 -> 0.082142857 | K20: =J20/I20 -> 0.82142857 | L20: =IF(AND(K8<>0,I14<>0,I49<>0),(I49*T49+(I49/K8-I49)*I20)/(I49/K8),0) -> 0.093323292 | M20: =IF(AND(I20<>"",I20<>0,L20<>"",L20<>0),L20/I20,"") -> 0.93323292 | N20: =IF(AND(J20<>0,J20<>"",I20<>0,I20<>""),L20-I20,"") -> -0.0066767076 | P20: =IF(AND(O20<>"",O20<>0,L20<>"",L20<>0),-O20+L20,"") | Q20: =IF(AND(P20<>"",P20<>0,O20<>0,O20<>""),P20/O20,"")
B22: Факт продаж за месяц | U22: % выполнения дневного плана | V22: Раcпределение плана по дням
B23: Дата | C23: День недели | D23: Выручка (руб) | E23: Кол-во единиц (шт.) | F23: Средняя стоимость изделия (руб.) | G23: Количество чеков (шт.) | H23: Средняя сумма чека (руб.) | I23: Трафик | J23: Длина чека (шт.) | K23: UNOde50 | L23: IS | M23: Agafi | N23: Kalliope | O23: Raganella | P23: CC/MP | Q23: Eva Rites | R23: Antura | S23: SALE | T23: Конверсия (%) | V23: выручка, план | W23: кол-во ед, план | X23: Кол-во чеков, план | Y23: выручка, скорректир.план | Z23: кол-во ед, скорр. план | AA23: кол-во чеков, скорр. план | AB23: Коэфф. Дня Недели | AC23: Специфика месяца
B24: 1 | C24: 2 | D24: 3 | E24: в | F24: 5 | G24: 6 | H24: 7 | I24: 8 | J24: 9 | K24: 10 | L24: 11 | M24: 12 | N24: 13 | O24: 14 | P24: 15 | Q24: 16 | R24: 17 | T24: 18 | V24: 1 | W24: 2 | X24: 3 | Y24: 4 | Z24: 5 | AA24: 6 | AB24: 10 | AC24: 11
A25: 1 | B25: 46054 | C25: вс | D25: =-10892+28117+7503 -> 24728 | E25: 6 | F25: =IF(AND(E25<>"",E25<>0),D25/E25,"") -> 4121.3333 | G25: 4 | H25: =IF(AND(G25<>"",G25<>0),D25/G25,"") -> 6182 | I25: 28 | J25: =IF(AND(G25<>"",G25<>0),E25/G25,"") -> 1.5 | L25: 7503 | M25: 8592 | T25: =IF(AND(I25<>"",I25<>0),G25/I25,"") -> 0.14285714 | U25: =D25/V25 -> 0.77989071 | V25: =$I$8*AB25*AC25/SUMPRODUCT($AC$25:$AC$56,$AB$25:$AB$56) -> 31707.007 | W25: =$I$9*AB25*AC25/SUMPRODUCT($AC$25:$AC$56,$AB$25:$AB$56) -> 4.3673563 | X25: =IF($I$12="","",W25/$I$12) -> 2.3735632 | Y25: =IF(AC25<>"",IF(D25<>"",D25,($I$8-SUM($Y24:Y$25))*AB25*AC25/SUMPRODUCT($AC25:$AC$56,$AB25:$AB$56)),"") -> 24728 | Z25: =IF(AC25<>"",IF(E25<>"",E25,($I$9-SUM($Z24:Z$25))*AB25*AC25/SUMPRODUCT($AC25:$AC$56,$AB25:$AB$56)),"") -> 6 | AA25: =IF(AC25<>"",IF($I$12<>"",IF(G25<>"",G25,($I$9/$I$12-SUM($AA24:AA$25))*AB25*AC25/SUMPRODUCT($AC25:$AC$56,$AB25:$AB$56)),""),"") -> 4 | AB25: 1 | AC25: 1
A26: 2 | B26: 46055 | C26: пн | D26: 0 | E26: 0 | F26: =IF(AND(E26<>"",E26<>0),D26/E26,"") | G26: 0 | H26: =IF(AND(G26<>"",G26<>0),D26/G26,"") | I26: 17 | J26: =IF(AND(G26<>"",G26<>0),E26/G26,"") | T26: =IF(AND(I26<>"",I26<>0),G26/I26,"") -> 0 | U26: =D26/V26 -> 0 | V26: =$I$8*AB26*AC26/SUMPRODUCT($AC$25:$AC$56,$AB$25:$AB$56) -> 31707.007 | W26: =$I$9*AB26*AC26/SUMPRODUCT($AC$25:$AC$56,$AB$25:$AB$56) -> 4.3673563 | X26: =IF($I$12="","",W26/$I$12) -> 2.3735632 | Y26: =IF(AC26<>"",IF(D26<>"",D26,($I$8-SUM($Y25:Y$25))*AB26*AC26/SUMPRODUCT($AC26:$AC$56,$AB26:$AB$56)),"") -> 0 | Z26: =IF(AC26<>"",IF(E26<>"",E26,($I$9-SUM($Z25:Z$25))*AB26*AC26/SUMPRODUCT($AC26:$AC$56,$AB26:$AB$56)),"") -> 0 | AA26: =IF(AC26<>"",IF($I$12<>"",IF(G26<>"",G26,($I$9/$I$12-SUM($AA25:AA$25))*AB26*AC26/SUMPRODUCT($AC26:$AC$56,$AB26:$AB$56)),""),"") -> 0 | AB26: 1 | AC26: 1
A27: 3 | B27: 46056 | C27: вт | D27: 30122 | E27: 5 | F27: =IF(AND(E27<>"",E27<>0),D27/E27,"") -> 6024.4 | G27: 3 | H27: =IF(AND(G27<>"",G27<>0),D27/G27,"") -> 10040.667 | I27: 18 | J27: =IF(AND(G27<>"",G27<>0),E27/G27,"") -> 1.6666667 | M27: 23903 | S27: 6219 | T27: =IF(AND(I27<>"",I27<>0),G27/I27,"") -> 0.16666667 | U27: =D27/V27 -> 0.95001083 | V27: =$I$8*AB27*AC27/SUMPRODUCT($AC$25:$AC$56,$AB$25:$AB$56) -> 31707.007 | W27: =$I$9*AB27*AC27/SUMPRODUCT($AC$25:$AC$56,$AB$25:$AB$56) -> 4.3673563 | X27: =IF($I$12="","",W27/$I$12) -> 2.3735632 | Y27: =IF(AC27<>"",IF(D27<>"",D27,($I$8-SUM($Y$25:Y26))*AB27*AC27/SUMPRODUCT($AC27:$AC$56,$AB27:$AB$56)),"") -> 30122 | Z27: =IF(AC27<>"",IF(E27<>"",E27,($I$9-SUM($Z$25:Z26))*AB27*AC27/SUMPRODUCT($AC27:$AC$56,$AB27:$AB$56)),"") -> 5 | AA27: =IF(AC27<>"",IF($I$12<>"",IF(G27<>"",G27,($I$9/$I$12-SUM($AA$25:AA26))*AB27*AC27/SUMPRODUCT($AC27:$AC$56,$AB27:$AB$56)),""),"") -> 3 | AB27: 1 | AC27: 1
A28: 4 | B28: 46059 | C28: пт | D28: 0 | E28: 0 | F28: =IF(AND(E28<>"",E28<>0),D28/E28,"") | G28: 0 | H28: =IF(AND(G28<>"",G28<>0),D28/G28,"") | I28: 25 | J28: =IF(AND(G28<>"",G28<>0),E28/G28,"") | T28: =IF(AND(I28<>"",I28<>0),G28/I28,"") -> 0 | U28: =D28/V28 -> 0 | V28: =$I$8*AB28*AC28/SUMPRODUCT($AC$25:$AC$56,$AB$25:$AB$56) -> 31707.007 | W28: =$I$9*AB28*AC28/SUMPRODUCT($AC$25:$AC$56,$AB$25:$AB$56) -> 4.3673563 | X28: =IF($I$12="","",W28/$I$12) -> 2.3735632 | Y28: =IF(AC28<>"",IF(D28<>"",D28,($I$8-SUM($Y$25:Y27))*AB28*AC28/SUMPRODUCT($AC28:$AC$56,$AB28:$AB$56)),"") -> 0 | Z28: =IF(AC28<>"",IF(E28<>"",E28,($I$9-SUM($Z$25:Z27))*AB28*AC28/SUMPRODUCT($AC28:$AC$56,$AB28:$AB$56)),"") -> 0 | AA28: =IF(AC28<>"",IF($I$12<>"",IF(G28<>"",G28,($I$9/$I$12-SUM($AA$25:AA27))*AB28*AC28/SUMPRODUCT($AC28:$AC$56,$AB28:$AB$56)),""),"") -> 0 | AB28: 1 | AC28: 1
A29: 5 | B29: 46060 | C29: сб | D29: 30068 | E29: 4 | F29: =IF(AND(E29<>"",E29<>0),D29/E29,"") -> 7517 | G29: 2 | H29: =IF(AND(G29<>"",G29<>0),D29/G29,"") -> 15034 | I29: 28 | J29: =IF(AND(G29<>"",G29<>0),E29/G29,"") -> 2 | M29: 15984 | T29: =IF(AND(I29<>"",I29<>0),G29/I29,"") -> 0.071428571 | U29: =D29/V29 -> 0.94830774 | V29: =$I$8*AB29*AC29/SUMPRODUCT($AC$25:$AC$56,$AB$25:$AB$56) -> 31707.007 | W29: =$I$9*AB29*AC29/SUMPRODUCT($AC$25:$AC$56,$AB$25:$AB$56) -> 4.3673563 | X29: =IF($I$12="","",W29/$I$12) -> 2.3735632 | Y29: =IF(AC29<>"",IF(D29<>"",D29,($I$8-SUM($Y$25:Y28))*AB29*AC29/SUMPRODUCT($AC29:$AC$56,$AB29:$AB$56)),"") -> 30068 | Z29: =IF(AC29<>"",IF(E29<>"",E29,($I$9-SUM($Z$25:Z28))*AB29*AC29/SUMPRODUCT($AC29:$AC$56,$AB29:$AB$56)),"") -> 4 | AA29: =IF(AC29<>"",IF($I$12<>"",IF(G29<>"",G29,($I$9/$I$12-SUM($AA$25:AA28))*AB29*AC29/SUMPRODUCT($AC29:$AC$56,$AB29:$AB$56)),""),"") -> 2 | AB29: 1 | AC29: 1
A30: 6 | B30: 46061 | C30: вс | D30: 31503 | E30: 5 | F30: =IF(AND(E30<>"",E30<>0),D30/E30,"") -> 6300.6 | G30: 3 | H30: =IF(AND(G30<>"",G30<>0),D30/G30,"") -> 10501 | I30: 30 | J30: =IF(AND(G30<>"",G30<>0),E30/G30,"") -> 1.6666667 | T30: =IF(AND(I30<>"",I30<>0),G30/I30,"") -> 0.1 | U30: =D30/V30 -> 0.99356587 | V30: =$I$8*AB30*AC30/SUMPRODUCT($AC$25:$AC$56,$AB$25:$AB$56) -> 31707.007 | W30: =$I$9*AB30*AC30/SUMPRODUCT($AC$25:$AC$56,$AB$25:$AB$56) -> 4.3673563 | X30: =IF($I$12="","",W30/$I$12) -> 2.3735632 | Y30: =IF(AC30<>"",IF(D30<>"",D30,($I$8-SUM($Y$25:Y29))*AB30*AC30/SUMPRODUCT($AC30:$AC$56,$AB30:$AB$56)),"") -> 31503 | Z30: =IF(AC30<>"",IF(E30<>"",E30,($I$9-SUM($Z$25:Z29))*AB30*AC30/SUMPRODUCT($AC30:$AC$56,$AB30:$AB$56)),"") -> 5 | AA30: =IF(AC30<>"",IF($I$12<>"",IF(G30<>"",G30,($I$9/$I$12-SUM($AA$25:AA29))*AB30*AC30/SUMPRODUCT($AC30:$AC$56,$AB30:$AB$56)),""),"") -> 3 | AB30: 1 | AC30: 1
A31: 7 | B31: 46063 | C31: вт | D31: 5098 | E31: 1 | F31: =IF(AND(E31<>"",E31<>0),D31/E31,"") -> 5098 | G31: 1 | H31: =IF(AND(G31<>"",G31<>0),D31/G31,"") -> 5098 | I31: 25 | J31: =IF(AND(G31<>"",G31<>0),E31/G31,"") -> 1 | T31: =IF(AND(I31<>"",I31<>0),G31/I31,"") -> 0.04 | U31: =D31/V31 -> 0.16078465 | V31: =$I$8*AB31*AC31/SUMPRODUCT($AC$25:$AC$56,$AB$25:$AB$56) -> 31707.007 | W31: =$I$9*AB31*AC31/SUMPRODUCT($AC$25:$AC$56,$AB$25:$AB$56) -> 4.3673563 | X31: =IF($I$12="","",W31/$I$12) -> 2.3735632 | Y31: =IF(AC31<>"",IF(D31<>"",D31,($I$8-SUM($Y$25:Y30))*AB31*AC31/SUMPRODUCT($AC31:$AC$56,$AB31:$AB$56)),"") -> 5098 | Z31: =IF(AC31<>"",IF(E31<>"",E31,($I$9-SUM($Z$25:Z30))*AB31*AC31/SUMPRODUCT($AC31:$AC$56,$AB31:$AB$56)),"") -> 1 | AA31: =IF(AC31<>"",IF($I$12<>"",IF(G31<>"",G31,($I$9/$I$12-SUM($AA$25:AA30))*AB31*AC31/SUMPRODUCT($AC31:$AC$56,$AB31:$AB$56)),""),"") -> 1 | AB31: 1 | AC31: 1
A32: 8 | B32: 46064 | C32: ср | D32: 5692 | E32: 1 | F32: =IF(AND(E32<>"",E32<>0),D32/E32,"") -> 5692 | G32: 1 | H32: =IF(AND(G32<>"",G32<>0),D32/G32,"") -> 5692 | I32: 27 | J32: =IF(AND(G32<>"",G32<>0),E32/G32,"") -> 1 | T32: =IF(AND(I32<>"",I32<>0),G32/I32,"") -> 0.037037037 | U32: =D32/V32 -> 0.17951868 | V32: =$I$8*AB32*AC32/SUMPRODUCT($AC$25:$AC$56,$AB$25:$AB$56) -> 31707.007 | W32: =$I$9*AB32*AC32/SUMPRODUCT($AC$25:$AC$56,$AB$25:$AB$56) -> 4.3673563 | X32: =IF($I$12="","",W32/$I$12) -> 2.3735632 | Y32: =IF(AC32<>"",IF(D32<>"",D32,($I$8-SUM($Y$25:Y31))*AB32*AC32/SUMPRODUCT($AC32:$AC$56,$AB32:$AB$56)),"") -> 5692 | Z32: =IF(AC32<>"",IF(E32<>"",E32,($I$9-SUM($Z$25:Z31))*AB32*AC32/SUMPRODUCT($AC32:$AC$56,$AB32:$AB$56)),"") -> 1 | AA32: =IF(AC32<>"",IF($I$12<>"",IF(G32<>"",G32,($I$9/$I$12-SUM($AA$25:AA31))*AB32*AC32/SUMPRODUCT($AC32:$AC$56,$AB32:$AB$56)),""),"") -> 1 | AB32: 1 | AC32: 1
A33: 9 | B33: 46067 | C33: сб | D33: 26506 | E33: 2 | F33: =IF(AND(E33<>"",E33<>0),D33/E33,"") -> 13253 | G33: 1 | H33: =IF(AND(G33<>"",G33<>0),D33/G33,"") -> 26506 | I33: 25 | J33: =IF(AND(G33<>"",G33<>0),E33/G33,"") -> 2 | T33: =IF(AND(I33<>"",I33<>0),G33/I33,"") -> 0.04 | U33: =D33/V33 -> 0.83596664 | V33: =$I$8*AB33*AC33/SUMPRODUCT($AC$25:$AC$56,$AB$25:$AB$56) -> 31707.007 | W33: =$I$9*AB33*AC33/SUMPRODUCT($AC$25:$AC$56,$AB$25:$AB$56) -> 4.3673563 | X33: =IF($I$12="","",W33/$I$12) -> 2.3735632 | Y33: =IF(AC33<>"",IF(D33<>"",D33,($I$8-SUM($Y$25:Y32))*AB33*AC33/SUMPRODUCT($AC33:$AC$56,$AB33:$AB$56)),"") -> 26506 | Z33: =IF(AC33<>"",IF(E33<>"",E33,($I$9-SUM($Z$25:Z32))*AB33*AC33/SUMPRODUCT($AC33:$AC$56,$AB33:$AB$56)),"") -> 2 | AA33: =IF(AC33<>"",IF($I$12<>"",IF(G33<>"",G33,($I$9/$I$12-SUM($AA$25:AA32))*AB33*AC33/SUMPRODUCT($AC33:$AC$56,$AB33:$AB$56)),""),"") -> 1 | AB33: 1 | AC33: 1
A34: 10 | B34: 46068 | C34: вс | D34: 0 | E34: 0 | F34: =IF(AND(E34<>"",E34<>0),D34/E34,"") | G34: 0 | H34: =IF(AND(G34<>"",G34<>0),D34/G34,"") | I34: 33 | J34: =IF(AND(G34<>"",G34<>0),E34/G34,"") | T34: =IF(AND(I34<>"",I34<>0),G34/I34,"") -> 0 | U34: =D34/V34 -> 0 | V34: =$I$8*AB34*AC34/SUMPRODUCT($AC$25:$AC$56,$AB$25:$AB$56) -> 31707.007 | W34: =$I$9*AB34*AC34/SUMPRODUCT($AC$25:$AC$56,$AB$25:$AB$56) -> 4.3673563 | X34: =IF($I$12="","",W34/$I$12) -> 2.3735632 | Y34: =IF(AC34<>"",IF(D34<>"",D34,($I$8-SUM($Y$25:Y33))*AB34*AC34/SUMPRODUCT($AC34:$AC$56,$AB34:$AB$56)),"") -> 0 | Z34: =IF(AC34<>"",IF(E34<>"",E34,($I$9-SUM($Z$25:Z33))*AB34*AC34/SUMPRODUCT($AC34:$AC$56,$AB34:$AB$56)),"") -> 0 | AA34: =IF(AC34<>"",IF($I$12<>"",IF(G34<>"",G34,($I$9/$I$12-SUM($AA$25:AA33))*AB34*AC34/SUMPRODUCT($AC34:$AC$56,$AB34:$AB$56)),""),"") -> 0 | AB34: 1 | AC34: 1
A35: 11 | B35: 46069 | C35: пн | D35: 0 | E35: 0 | F35: =IF(AND(E35<>"",E35<>0),D35/E35,"") | G35: 0 | H35: =IF(AND(G35<>"",G35<>0),D35/G35,"") | I35: 21 | J35: =IF(AND(G35<>"",G35<>0),E35/G35,"") | T35: =IF(AND(I35<>"",I35<>0),G35/I35,"") -> 0 | U35: =D35/V35 -> 0 | V35: =$I$8*AB35*AC35/SUMPRODUCT($AC$25:$AC$56,$AB$25:$AB$56) -> 31707.007 | W35: =$I$9*AB35*AC35/SUMPRODUCT($AC$25:$AC$56,$AB$25:$AB$56) -> 4.3673563 | X35: =IF($I$12="","",W35/$I$12) -> 2.3735632 | Y35: =IF(AC35<>"",IF(D35<>"",D35,($I$8-SUM($Y$25:Y34))*AB35*AC35/SUMPRODUCT($AC35:$AC$56,$AB35:$AB$56)),"") -> 0 | Z35: =IF(AC35<>"",IF(E35<>"",E35,($I$9-SUM($Z$25:Z34))*AB35*AC35/SUMPRODUCT($AC35:$AC$56,$AB35:$AB$56)),"") -> 0 | AA35: =IF(AC35<>"",IF($I$12<>"",IF(G35<>"",G35,($I$9/$I$12-SUM($AA$25:AA34))*AB35*AC35/SUMPRODUCT($AC35:$AC$56,$AB35:$AB$56)),""),"") -> 0 | AB35: 1 | AC35: 1
A36: 12 | B36: 46070 | C36: вт | D36: 0 | E36: 0 | F36: =IF(AND(E36<>"",E36<>0),D36/E36,"") | G36: 0 | H36: =IF(AND(G36<>"",G36<>0),D36/G36,"") | I36: 17 | J36: =IF(AND(G36<>"",G36<>0),E36/G36,"") | T36: =IF(AND(I36<>"",I36<>0),G36/I36,"") -> 0 | U36: =D36/V36 -> 0 | V36: =$I$8*AB36*AC36/SUMPRODUCT($AC$25:$AC$56,$AB$25:$AB$56) -> 31707.007 | W36: =$I$9*AB36*AC36/SUMPRODUCT($AC$25:$AC$56,$AB$25:$AB$56) -> 4.3673563 | X36: =IF($I$12="","",W36/$I$12) -> 2.3735632 | Y36: =IF(AC36<>"",IF(D36<>"",D36,($I$8-SUM($Y$25:Y35))*AB36*AC36/SUMPRODUCT($AC36:$AC$56,$AB36:$AB$56)),"") -> 0 | Z36: =IF(AC36<>"",IF(E36<>"",E36,($I$9-SUM($Z$25:Z35))*AB36*AC36/SUMPRODUCT($AC36:$AC$56,$AB36:$AB$56)),"") -> 0 | AA36: =IF(AC36<>"",IF($I$12<>"",IF(G36<>"",G36,($I$9/$I$12-SUM($AA$25:AA35))*AB36*AC36/SUMPRODUCT($AC36:$AC$56,$AB36:$AB$56)),""),"") -> 0 | AB36: 1 | AC36: 1
A37: 13 | B37: 46073 | C37: пт | D37: =11384+5690 -> 17074 | E37: 3 | F37: =IF(AND(E37<>"",E37<>0),D37/E37,"") -> 5691.3333 | G37: 2 | H37: =IF(AND(G37<>"",G37<>0),D37/G37,"") -> 8537 | I37: 31 | J37: =IF(AND(G37<>"",G37<>0),E37/G37,"") -> 1.5 | T37: =IF(AND(I37<>"",I37<>0),G37/I37,"") -> 0.064516129 | U37: =D37/V37 -> 0.53849296 | V37: =$I$8*AB37*AC37/SUMPRODUCT($AC$25:$AC$56,$AB$25:$AB$56) -> 31707.007 | W37: =$I$9*AB37*AC37/SUMPRODUCT($AC$25:$AC$56,$AB$25:$AB$56) -> 4.3673563 | X37: =IF($I$12="","",W37/$I$12) -> 2.3735632 | Y37: =IF(AC37<>"",IF(D37<>"",D37,($I$8-SUM($Y$25:Y36))*AB37*AC37/SUMPRODUCT($AC37:$AC$56,$AB37:$AB$56)),"") -> 17074 | Z37: =IF(AC37<>"",IF(E37<>"",E37,($I$9-SUM($Z$25:Z36))*AB37*AC37/SUMPRODUCT($AC37:$AC$56,$AB37:$AB$56)),"") -> 3 | AA37: =IF(AC37<>"",IF($I$12<>"",IF(G37<>"",G37,($I$9/$I$12-SUM($AA$25:AA36))*AB37*AC37/SUMPRODUCT($AC37:$AC$56,$AB37:$AB$56)),""),"") -> 2 | AB37: 1 | AC37: 1
A38: 14 | B38: 46074 | C38: сб | D38: 2147 | E38: 1 | F38: =IF(AND(E38<>"",E38<>0),D38/E38,"") -> 2147 | G38: 1 | H38: =IF(AND(G38<>"",G38<>0),D38/G38,"") -> 2147 | I38: 25 | J38: =IF(AND(G38<>"",G38<>0),E38/G38,"") -> 1 | S38: 2147 | T38: =IF(AND(I38<>"",I38<>0),G38/I38,"") -> 0.04 | U38: =D38/V38 -> 0.067713739 | V38: =$I$8*AB38*AC38/SUMPRODUCT($AC$25:$AC$46,$AB$25:$AB$46) -> 31707.007 | W38: =$I$9*AB38*AC38/SUMPRODUCT($AC$25:$AC$46,$AB$25:$AB$46) -> 4.3673563 | X38: =IF($I$12="","",W38/$I$12) -> 2.3735632 | Y38: =IF(AC38<>"",IF(D38<>"",D38,($I$8-SUM($Y$25:Y37))*AB38*AC38/SUMPRODUCT($AC38:$AC$56,$AB38:$AB$56)),"") -> 2147 | Z38: =IF(AC38<>"",IF(E38<>"",E38,($I$9-SUM($Z$25:Z37))*AB38*AC38/SUMPRODUCT($AC38:$AC$56,$AB38:$AB$56)),"") -> 1 | AA38: =IF(AC38<>"",IF($I$12<>"",IF(G38<>"",G38,($I$9/$I$12-SUM($AA$25:AA37))*AB38*AC38/SUMPRODUCT($AC38:$AC$56,$AB38:$AB$56)),""),"") -> 1 | AB38: 1 | AC38: 1
A39: 15 | B39: 46075 | C39: вс | D39: 7491 | E39: 2 | F39: =IF(AND(E39<>"",E39<>0),D39/E39,"") -> 3745.5 | G39: 1 | H39: =IF(AND(G39<>"",G39<>0),D39/G39,"") -> 7491 | J39: =IF(AND(G39<>"",G39<>0),E39/G39,"") -> 2 | T39: =IF(AND(I39<>"",I39<>0),G39/I39,"") | U39: =D39/V39 -> 0.23625693 | V39: =$I$8*AB39*AC39/SUMPRODUCT($AC$25:$AC$46,$AB$25:$AB$46) -> 31707.007 | W39: =$I$9*AB39*AC39/SUMPRODUCT($AC$25:$AC$46,$AB$25:$AB$46) -> 4.3673563 | X39: =IF($I$12="","",W39/$I$12) -> 2.3735632 | Y39: =IF(AC39<>"",IF(D39<>"",D39,($I$8-SUM($Y$25:Y38))*AB39*AC39/SUMPRODUCT($AC39:$AC$56,$AB39:$AB$56)),"") -> 7491 | Z39: =IF(AC39<>"",IF(E39<>"",E39,($I$9-SUM($Z$25:Z38))*AB39*AC39/SUMPRODUCT($AC39:$AC$56,$AB39:$AB$56)),"") -> 2 | AA39: =IF(AC39<>"",IF($I$12<>"",IF(G39<>"",G39,($I$9/$I$12-SUM($AA$25:AA38))*AB39*AC39/SUMPRODUCT($AC39:$AC$56,$AB39:$AB$56)),""),"") -> 1 | AB39: 1 | AC39: 1
A40: 16 | B40: 46076 | C40: пн | D40: 0 | E40: 0 | F40: =IF(AND(E40<>"",E40<>0),D40/E40,"") | G40: 0 | H40: =IF(AND(G40<>"",G40<>0),D40/G40,"") | J40: =IF(AND(G40<>"",G40<>0),E40/G40,"") | T40: =IF(AND(I40<>"",I40<>0),G40/I40,"") | U40: =D40/V40 -> 0 | V40: =$I$8*AB40*AC40/SUMPRODUCT($AC$25:$AC$46,$AB$25:$AB$46) -> 31707.007 | W40: =$I$9*AB40*AC40/SUMPRODUCT($AC$25:$AC$46,$AB$25:$AB$46) -> 4.3673563 | X40: =IF($I$12="","",W40/$I$12) -> 2.3735632 | Y40: =IF(AC40<>"",IF(D40<>"",D40,($I$8-SUM($Y$25:Y39))*AB40*AC40/SUMPRODUCT($AC40:$AC$56,$AB40:$AB$56)),"") -> 0 | Z40: =IF(AC40<>"",IF(E40<>"",E40,($I$9-SUM($Z$25:Z39))*AB40*AC40/SUMPRODUCT($AC40:$AC$56,$AB40:$AB$56)),"") -> 0 | AA40: =IF(AC40<>"",IF($I$12<>"",IF(G40<>"",G40,($I$9/$I$12-SUM($AA$25:AA39))*AB40*AC40/SUMPRODUCT($AC40:$AC$56,$AB40:$AB$56)),""),"") -> 0 | AB40: 1 | AC40: 1
A41: 17 | B41: 46077 | C41: вт | D41: 0 | E41: 0 | F41: =IF(AND(E41<>"",E41<>0),D41/E41,"") | G41: 0 | H41: =IF(AND(G41<>"",G41<>0),D41/G41,"") | J41: =IF(AND(G41<>"",G41<>0),E41/G41,"") | T41: =IF(AND(I41<>"",I41<>0),G41/I41,"") | U41: =D41/V41 -> 0 | V41: =$I$8*AB41*AC41/SUMPRODUCT($AC$25:$AC$46,$AB$25:$AB$46) -> 31707.007 | W41: =$I$9*AB41*AC41/SUMPRODUCT($AC$25:$AC$46,$AB$25:$AB$46) -> 4.3673563 | X41: =IF($I$12="","",W41/$I$12) -> 2.3735632 | Y41: =IF(AC41<>"",IF(D41<>"",D41,($I$8-SUM($Y$25:Y40))*AB41*AC41/SUMPRODUCT($AC41:$AC$56,$AB41:$AB$56)),"") -> 0 | Z41: =IF(AC41<>"",IF(E41<>"",E41,($I$9-SUM($Z$25:Z40))*AB41*AC41/SUMPRODUCT($AC41:$AC$56,$AB41:$AB$56)),"") -> 0 | AA41: =IF(AC41<>"",IF($I$12<>"",IF(G41<>"",G41,($I$9/$I$12-SUM($AA$25:AA40))*AB41*AC41/SUMPRODUCT($AC41:$AC$56,$AB41:$AB$56)),""),"") -> 0 | AB41: 1 | AC41: 1
A42: 18 | B42: 46079 | C42: чт | D42: 0 | E42: 0 | F42: =IF(AND(E42<>"",E42<>0),D42/E42,"") | G42: 0 | H42: =IF(AND(G42<>"",G42<>0),D42/G42,"") | J42: =IF(AND(G42<>"",G42<>0),E42/G42,"") | T42: =IF(AND(I42<>"",I42<>0),G42/I42,"") | U42: =D42/V42 -> 0 | V42: =$I$8*AB42*AC42/SUMPRODUCT($AC$25:$AC$46,$AB$25:$AB$46) -> 31707.007 | W42: =$I$9*AB42*AC42/SUMPRODUCT($AC$25:$AC$46,$AB$25:$AB$46) -> 4.3673563 | X42: =IF($I$12="","",W42/$I$12) -> 2.3735632 | Y42: =IF(AC42<>"",IF(D42<>"",D42,($I$8-SUM($Y$25:Y41))*AB42*AC42/SUMPRODUCT($AC42:$AC$56,$AB42:$AB$56)),"") -> 0 | Z42: =IF(AC42<>"",IF(E42<>"",E42,($I$9-SUM($Z$25:Z41))*AB42*AC42/SUMPRODUCT($AC42:$AC$56,$AB42:$AB$56)),"") -> 0 | AA42: =IF(AC42<>"",IF($I$12<>"",IF(G42<>"",G42,($I$9/$I$12-SUM($AA$25:AA41))*AB42*AC42/SUMPRODUCT($AC42:$AC$56,$AB42:$AB$56)),""),"") -> 0 | AB42: 1 | AC42: 1
...

Sheet Корж А. А.
B1: =TODAY()-1 -> 46171
B2: (отчетная дата) | J2: ЕЖЕДНЕВНЫЙ ОТЧЕТ О ПРОДАЖАХ
B3: Осталось до выполнения плана!!! | J3: =График!B25 -> Корж Анастасия
C4: =I8-D48 -> 287026.66 | E4: =IF(I8<>0,C4/I8,0) -> 0.4811672
F6: Целевые показатели
F7: Показатель | I7: План | J7: Факт | K7: % выполнения | L7: Прогноз выполнения | M7: % выполнения по прогнозу | N7: Отклонение | O7: Факт аналогичного месяца прошлого года | P7: Отклонение LFL
F8: Выручка | I8: =Центрум!I8/График!AJ29*График!AJ25 -> 596521.66 | J8: =D48 -> 309495 | K8: =IF(AND(I8<>"",I8<>0,J8<>""),J8/I8,"") -> 0.5188328 | L8: =IF(SUMIF($D$25:$D$47,">=0",$V$25:$V$47)<>0,I8*D48/SUMIF($D$25:$D$47,">=0",$V$25:$V$47),0) -> 320761.02 | M8: =L8/I8 -> 0.53771899 | N8: =IF(AND(J8<>0,J8<>"",I8<>0,I8<>""),L8-I8,"") -> -275760.63 | P8: =IF(AND(O8<>"",O8<>0,L8<>"",L8<>0),-O8+L8,"") | Q8: =IF(AND(P8<>"",P8<>0,O8<>0,O8<>""),P8/O8,"")
F9: Кол-во изделий | I9: =I8/I11 -> 82.165517 | J9: =E48 -> 29 | K9: =IF(AND(I9<>"",I9<>0,J9<>""),J9/I9,"") -> 0.35294611 | L9: =IF(SUMIF($E$25:$E$47,">=0",$W$25:$W$47)<>0,I9*E48/SUMIF($E$25:$E$47,">=0",$W$25:$W$47),0) -> 29.297111 | M9: =IF(AND(I9<>"",I9<>0,L9<>"",L9<>0),L9/I9,"") -> 0.35656212 | N9: =IF(AND(J9<>0,J9<>"",I9<>0,I9<>""),L9-I9,"") -> -52.868406 | O9: =O8/O11 -> #DIV/0! | P9: =IF(AND(O9<>"",O9<>0,L9<>"",L9<>0),-O9+L9,"") -> #DIV/0! | Q9: =IF(AND(P9<>"",P9<>0,O9<>0,O9<>""),P9/O9,"") -> #DIV/0!
F10: Средний чек | I10: =I11*I12 -> 13358.4 | J10: =H48 -> 17194.167 | K10: =IF(AND(I10<>"",I10<>0,J10<>""),J10/I10,"") -> 1.2871427 | L10: =J10 -> 17194.167 | M10: =IF(AND(I10<>"",I10<>0,L10<>"",L10<>0),L10/I10,"") -> 1.2871427 | N10: =IF(AND(J10<>0,J10<>"",I10<>0,I10<>""),L10-I10,"") -> 3835.7667 | O10: =O11*O12 -> 0 | P10: =IF(AND(O10<>"",O10<>0,L10<>"",L10<>0),-O10+L10,"") | Q10: =IF(AND(P10<>"",P10<>0,O10<>0,O10<>""),P10/O10,"")
F11: Средняя стоимость изделия | I11: =Центрум!I11 -> 7260 | J11: =F48 -> 10672.241 | K11: =IF(AND(I11<>"",I11<>0,J11<>""),J11/I11,"") -> 1.4700057 | L11: =J11 -> 10672.241 | M11: =IF(AND(I11<>"",I11<>0,L11<>"",L11<>0),L11/I11,"") -> 1.4700057 | N11: =IF(AND(J11<>0,J11<>"",I11<>0,I11<>""),L11-I11,"") -> 3412.2414 | P11: =IF(AND(O11<>"",O11<>0,L11<>"",L11<>0),-O11+L11,"") | Q11: =IF(AND(P11<>"",P11<>0,O11<>0,O11<>""),P11/O11,"")
F12: Длина чека | I12: =Центрум!I12 -> 1.84 | J12: =J48 -> 1.6111111 | K12: =IF(AND(I12<>"",I12<>0,J12<>""),J12/I12,"") -> 0.87560386 | L12: =J12 -> 1.6111111 | M12: =IF(AND(I12<>"",I12<>0,L12<>"",L12<>0),L12/I12,"") -> 0.87560386 | N12: =IF(AND(J12<>0,J12<>"",I12<>0,I12<>""),L12-I12,"") -> -0.22888889 | P12: =IF(AND(O12<>"",O12<>0,L12<>"",L12<>0),-O12+L12,"") | Q12: =IF(AND(P12<>"",P12<>0,O12<>0,O12<>""),P12/O12,"")
F13: Кол-во чеков | I13: =IF(I12<>0,I9/I12,"") -> 44.655172 | J13: =G48 -> 18 | K13: =IF(AND(I13<>"",I13<>0,J13<>""),J13/I13,"") -> 0.4030888 | L13: =IF(SUMIF($G$25:$G$47,">=0",$X$25:$X$47)<>0,I13*G48/SUMIF($G$25:$G$47,">=0",$X$25:$X$47),"") -> 18.256243 | M13: =IF(AND(I13<>"",I13<>0,L13<>"",L13<>0),L13/I13,"") -> 0.40882705 | N13: =IF(AND(J13<>0,J13<>"",I13<>0,I13<>""),L13-I13,"") -> -26.39893 | P13: =IF(AND(O13<>"",O13<>0,L13<>"",L13<>0),-O13+L13,"") | Q13: =IF(AND(P13<>"",P13<>0,O13<>0,O13<>""),P13/O13,"")
F14: Кол-во смен план/отработано | I14: =График!AI25 -> 17 | J14: 17 | K14: =IF(AND(I14<>"",I14<>0,J14<>""),J14/I14,"") -> 1 | L14: =IF(SUMIF($D$25:$D$47,">=0",$V$25:$V$47),I48*I8/SUMIF($D$25:$D$47,">=0",$V$25:$V$47),"") -> 232.98302 | N14: =IF(AND(J14<>0,J14<>"",I14<>0,I14<>""),L14-I14,"") -> 215.98302 | P14: =IF(AND(O14<>"",O14<>0,L14<>"",L14<>0),-O14+L14,"") | Q14: =IF(AND(P14<>"",P14<>0,O14<>0,O14<>""),P14/O14,"")
F15: Средние продажи в смену | I15: =Центрум!I15/2 -> 33396 | J15: =J8/J14 -> 18205.588 | K15: =IF(AND(I15<>"",I15<>0,J15<>""),J15/I15,"") -> 0.54514278 | L15: =J15 -> 18205.588 | M15: =IF(AND(I15<>"",I15<>0,L15<>"",L15<>0),L15/I15,"") -> 0.54514278 | N15: =IF(AND(J15<>0,J15<>"",I15<>0,I15<>""),L15-I15,"") -> -15190.412 | P15: =IF(AND(O15<>"",O15<>0,L15<>"",L15<>0),-O15+L15,"") | Q15: =IF(AND(P15<>"",P15<>0,O15<>0,O15<>""),P15/O15,"")
F16: Отставание/Перевыполнение | J16: =J8-I15*J14 -> -258237 | K16: =IF(AND(I16<>"",I16<>0,J16<>""),J16/I16,"") | L16: =J16 -> -258237 | M16: =IF(AND(I16<>"",I16<>0,L16<>"",L16<>0),L16/I16,"") | N16: =IF(AND(J16<>0,J16<>"",I16<>0,I16<>""),L16-I16,"") | P16: =IF(AND(O16<>"",O16<>0,L16<>"",L16<>0),-O16+L16,"") | Q16: =IF(AND(P16<>"",P16<>0,O16<>0,O16<>""),P16/O16,"") | V16: Подарочные сертификаты
F17: Трафик | I17: =Центрум!I17/График!AJ29*График!AJ25 -> 446.55172 | J17: =I48 -> 224.8 | K17: =IF(AND(I17<>"",I17<>0,J17<>""),J17/I17,"") -> 0.50341313 | L17: =J17/J14*I14 -> 224.8 | M17: =IF(AND(I17<>"",I17<>0,L17<>"",L17<>0),L17/I17,"") -> 0.50341313 | N17: =IF(AND(J17<>0,J17<>"",I17<>0,I17<>""),L17-I17,"") -> -221.75172 | P17: =IF(AND(O17<>"",O17<>0,L17<>"",L17<>0),-O17+L17,"") | Q17: =IF(AND(P17<>"",P17<>0,O17<>0,O17<>""),P17/O17,"")
K18: =IF(AND(I18<>"",I18<>0,J18<>""),J18/I18,"") | L18: =J18 -> 0 | M18: =IF(AND(I18<>"",I18<>0,L18<>"",L18<>0),L18/I18,"") | N18: =IF(AND(J18<>0,J18<>"",I18<>0,I18<>""),L18-I18,"") | O18: 0 | P18: =IF(AND(O18<>"",O18<>0,L18<>"",L18<>0),-O18+L18,"") | Q18: =IF(AND(P18<>"",P18<>0,O18<>0,O18<>""),P18/O18,"")
J19: =P48 -> 0 | K19: =IF(AND(I19<>"",I19<>0,J19<>""),J19/I19,"") | L19: =J19 -> 0 | M19: =IF(AND(I19<>"",I19<>0,L19<>"",L19<>0),L19/I19,"") | N19: =IF(AND(J19<>0,J19<>"",I19<>0,I19<>""),L19-I19,"") | O19: 0 | P19: =IF(AND(O19<>"",O19<>0,L19<>"",L19<>0),-O19+L19,"") | Q19: =IF(AND(P19<>"",P19<>0,O19<>0,O19<>""),P19/O19,"") | V19: =V18/I16 -> #DIV/0!
F20: Конверсия план/факт | I20: =Центрум!I20 -> 0.1 | J20: =T48 -> 0.080071174 | K20: =J20/I20 -> 0.80071174 | L20: =IF(AND(K8<>0,I14<>0,I48<>0),(I48*T48+(I48/K8-I48)*I20)/(I48/K8),0) -> 0.089660272 | M20: =IF(AND(I20<>"",I20<>0,L20<>"",L20<>0),L20/I20,"") -> 0.89660272 | N20: =IF(AND(J20<>0,J20<>"",I20<>0,I20<>""),L20-I20,"") -> -0.010339728 | P20: =IF(AND(O20<>"",O20<>0,L20<>"",L20<>0),-O20+L20,"") | Q20: =IF(AND(P20<>"",P20<>0,O20<>0,O20<>""),P20/O20,"")
B22: Факт продаж за месяц | U22: % выполнения дневного плана | V22: Раcпределение плана по дням
B23: Дата | C23: День недели | D23: Выручка (руб) | E23: Кол-во единиц (шт.) | F23: Средняя стоимость изделия (руб.) | G23: Количество чеков (шт.) | H23: Средняя сумма чека (руб.) | I23: Трафик | J23: Длина чека (шт.) | K23: UNOde50 | L23: IS | M23: Agafi | N23: Kalliope | O23: Raganella | P23: CC/MP | Q23: Eva Rites | R23: Antura | S23: SALE | T23: Конверсия (%) | V23: выручка, план | W23: кол-во ед, план | X23: Кол-во чеков, план | Y23: выручка, скорректир.план | Z23: кол-во ед, скорр. план | AA23: кол-во чеков, скорр. план | AB23: Коэфф. Дня Недели | AC23: Специфика месяца
B24: 1 | C24: 2 | D24: 3 | E24: в | F24: 5 | G24: 6 | H24: 7 | I24: 8 | J24: 9 | K24: 10 | L24: 11 | M24: 12 | N24: 13 | O24: 14 | P24: 15 | Q24: 16 | R24: 17 | T24: 18 | V24: 1 | W24: 2 | X24: 3 | Y24: 4 | Z24: 5 | AA24: 6 | AB24: 10 | AC24: 11
A25: 1 | B25: 46056 | C25: вт | D25: 0 | E25: 0 | G25: 0 | H25: =IF(AND(G25<>"",G25<>0),D25/G25,"") | I25: 18 | J25: =IF(AND(G25<>"",G25<>0),E25/G25,"") | T25: =IF(AND(I25<>"",I25<>0),G25/I25,"") -> 0 | U25: =D25/V25 -> 0 | V25: =$I$8*AB25*AC25/SUMPRODUCT($AC$25:$AC$55,$AB$25:$AB$55) -> 35089.509 | W25: =$I$9*AB25*AC25/SUMPRODUCT($AC$25:$AC$55,$AB$25:$AB$55) -> 4.8332657 | X25: =IF($I$12="","",W25/$I$12) -> 2.6267748 | Y25: =IF(AC25<>"",IF(D25<>"",D25,($I$8-SUM($Y24:Y$25))*AB25*AC25/SUMPRODUCT($AC25:$AC$55,$AB25:$AB$55)),"") -> 0 | Z25: =IF(AC25<>"",IF(E25<>"",E25,($I$9-SUM($Z24:Z$25))*AB25*AC25/SUMPRODUCT($AC25:$AC$55,$AB25:$AB$55)),"") -> 0 | AA25: =IF(AC25<>"",IF($I$12<>"",IF(G25<>"",G25,($I$9/$I$12-SUM($AA24:AA$25))*AB25*AC25/SUMPRODUCT($AC25:$AC$55,$AB25:$AB$55)),""),"") -> 0 | AB25: 1 | AC25: 1
A26: 2 | B26: 46057 | C26: ср | D26: 22340 | E26: 2 | F26: =IF(AND(E26<>"",E26<>0),D26/E26,"") -> 11170 | G26: 2 | H26: =IF(AND(G26<>"",G26<>0),D26/G26,"") -> 11170 | I26: 18 | J26: =IF(AND(G26<>"",G26<>0),E26/G26,"") -> 1 | R26: 14445 | T26: =IF(AND(I26<>"",I26<>0),G26/I26,"") -> 0.11111111 | U26: =D26/V26 -> 0.63665752 | V26: =$I$8*AB26*AC26/SUMPRODUCT($AC$25:$AC$55,$AB$25:$AB$55) -> 35089.509 | W26: =$I$9*AB26*AC26/SUMPRODUCT($AC$25:$AC$55,$AB$25:$AB$55) -> 4.8332657 | X26: =IF($I$12="","",W26/$I$12) -> 2.6267748 | Y26: =IF(AC26<>"",IF(D26<>"",D26,($I$8-SUM($Y$25:Y25))*AB26*AC26/SUMPRODUCT($AC26:$AC$55,$AB26:$AB$55)),"") -> 22340 | Z26: =IF(AC26<>"",IF(E26<>"",E26,($I$9-SUM($Z$25:Z25))*AB26*AC26/SUMPRODUCT($AC26:$AC$55,$AB26:$AB$55)),"") -> 2 | AA26: =IF(AC26<>"",IF($I$12<>"",IF(G26<>"",G26,($I$9/$I$12-SUM($AA$25:AA25))*AB26*AC26/SUMPRODUCT($AC26:$AC$55,$AB26:$AB$55)),""),"") -> 2 | AB26: 1 | AC26: 1
